{"market":"0x38f3050258345e9cf363d1c8cc302f08c65b96ba1a4669d81e07ed69708344df", "asset_id":"81916206347121459497221114766050949090435061493822476265356047392175668050706", "bids":[{"price":"0.01", "size":"1684.92"}, {"price":"0.02", "size":"151.55"}], "asks":[{"price":"0.99", "size":"5019.91"}, {"price":"0.98", "size":"3034.23"}, {"price":"0.97", "size":"3172"}, {"price":"0.96", "size":"3012"}, {"price":"0.95", "size":"3032"}, {"price":"0.94", "size":"3012"}, {"price":"0.93", "size":"3126.28"}, {"price":"0.92", "size":"3012"}, {"price":"0.91", "size":"3012"}, {"price":"0.9", "size":"3087"}, {"price":"0.89", "size":"12"}, {"price":"0.88", "size":"12"}, {"price":"0.87", "size":"12"}, {"price":"0.86", "size":"12"}, {"price":"0.85", "size":"12"}, {"price":"0.84", "size":"12"}, {"price":"0.83", "size":"12"}, {"price":"0.82", "size":"12"}, {"price":"0.81", "size":"12"}, {"price":"0.8", "size":"12"}, {"price":"0.79", "size":"12"}, {"price":"0.78", "size":"12"}, {"price":"0.77", "size":"12"}, {"price":"0.76", "size":"112"}, {"price":"0.75", "size":"40.57"}, {"price":"0.74", "size":"12"}, {"price":"0.73", "size":"293.25"}, {"price":"0.72", "size":"22"}, {"price":"0.71", "size":"12"}, {"price":"0.7", "size":"18"}, {"price":"0.69", "size":"12"}, {"price":"0.68", "size":"12"}, {"price":"0.67", "size":"12"}, {"price":"0.66", "size":"160.89"}, {"price":"0.65", "size":"12"}, {"price":"0.64", "size":"12"}, {"price":"0.63", "size":"12"}, {"price":"0.62", "size":"19.39"}, {"price":"0.61", "size":"18.04"}, {"price":"0.6", "size":"12"}, {"price":"0.59", "size":"94.31"}, {"price":"0.58", "size":"5450.54"}, {"price":"0.57", "size":"12"}, {"price":"0.56", "size":"12"}, {"price":"0.55", "size":"12"}, {"price":"0.54", "size":"22"}, {"price":"0.53", "size":"12"}, {"price":"0.52", "size":"12"}, {"price":"0.51", "size":"12"}, {"price":"0.5", "size":"12"}, {"price":"0.49", "size":"12"}, {"price":"0.48", "size":"12"}, {"price":"0.47", "size":"12"}, {"price":"0.46", "size":"485.56"}, {"price":"0.45", "size":"31"}, {"price":"0.44", "size":"17"}, {"price":"0.43", "size":"12"}, {"price":"0.42", "size":"12"}, {"price":"0.41", "size":"12"}, {"price":"0.4", "size":"127"}, {"price":"0.39", "size":"12"}, {"price":"0.38", "size":"114.5"}, {"price":"0.37", "size":"12"}, {"price":"0.36", "size":"12"}, {"price":"0.35", "size":"37"}, {"price":"0.34", "size":"12"}, {"price":"0.33", "size":"12"}, {"price":"0.32", "size":"12"}, {"price":"0.31", "size":"12"}, {"price":"0.3", "size":"31.9"}, {"price":"0.29", "size":"344"}, {"price":"0.28", "size":"3288.99"}, {"price":"0.27", "size":"212"}, {"price":"0.26", "size":"218"}, {"price":"0.25", "size":"212"}, {"price":"0.24", "size":"212"}, {"price":"0.23", "size":"212"}, {"price":"0.22", "size":"1223.14"}, {"price":"0.21", "size":"712"}, {"price":"0.2", "size":"472.99"}, {"price":"0.19", "size":"212"}, {"price":"0.18", "size":"212"}, {"price":"0.17", "size":"212"}, {"price":"0.16", "size":"812"}, {"price":"0.15", "size":"231.08"}, {"price":"0.14", "size":"283.65"}, {"price":"0.13", "size":"212"}, {"price":"0.12", "size":"212"}, {"price":"0.11", "size":"212"}, {"price":"0.1", "size":"706.71"}, {"price":"0.09", "size":"221"}, {"price":"0.08", "size":"804.68"}, {"price":"0.07", "size":"286"}, {"price":"0.06", "size":"918"}, {"price":"0.05", "size":"609"}, {"price":"0.04", "size":"695.73"}, {"price":"0.03", "size":"214.18"}], "hash":"627c810941db22c443e72f6bdf896b5df18059f9", "timestamp":"1770241492199", "event_type":"book"}
{"market":"0x38f3050258345e9cf363d1c8cc302f08c65b96ba1a4669d81e07ed69708344df", "price_changes":[{"asset_id":"96888240988495161476033313796107536512663280794332045579302109906525918376981", "price":"0.94", "size":"945", "side":"BUY", "hash":"7a5061f8e5c2d739cf77a6a4ccc783f3f9050cde", "best_bid":"0.97", "best_ask":"0.98"}, {"asset_id":"81916206347121459497221114766050949090435061493822476265356047392175668050706", "price":"0.06", "size":"945", "side":"SELL", "hash":"a89a24c9b535247636af9068144e7813f924196f", "best_bid":"0.02", "best_ask":"0.03"}], "timestamp":"1770241492226", "event_type":"price_change"}
{"market":"0x38f3050258345e9cf363d1c8cc302f08c65b96ba1a4669d81e07ed69708344df", "price_changes":[{"asset_id":"96888240988495161476033313796107536512663280794332045579302109906525918376981", "price":"0.95", "size":"582", "side":"BUY", "hash":"60d32da4352485870702417811b5bd0da2687657", "best_bid":"0.97", "best_ask":"0.98"}, {"asset_id":"81916206347121459497221114766050949090435061493822476265356047392175668050706", "price":"0.05", "size":"582", "side":"SELL", "hash":"7540edf17a4afef74f1d8ae2803dd6a7d6d2c614", "best_bid":"0.02", "best_ask":"0.03"}], "timestamp":"1770241492227", "event_type":"price_change"}
{"market":"0x38f3050258345e9cf363d1c8cc302f08c65b96ba1a4669d81e07ed69708344df", "price_changes":[{"asset_id":"96888240988495161476033313796107536512663280794332045579302109906525918376981", "price":"0.94", "size":"918", "side":"BUY", "hash":"2b7d9f28be99d1c3e1276ed896f324370eddfe8e", "best_bid":"0.97", "best_ask":"0.98"}, {"asset_id":"81916206347121459497221114766050949090435061493822476265356047392175668050706", "price":"0.06", "size":"918", "side":"SELL", "hash":"c0d6d2a687a4f28fdf195f2a318c9185d15a4de9", "best_bid":"0.02", "best_ask":"0.03"}], "timestamp":"1770241492373", "event_type":"price_change"}
{"market":"0x38f3050258345e9cf363d1c8cc302f08c65b96ba1a4669d81e07ed69708344df", "price_changes":[{"asset_id":"96888240988495161476033313796107536512663280794332045579302109906525918376981", "price":"0.94", "size":"945", "side":"BUY", "hash":"50b7776be269573492fd642bffae20f861afc34a", "best_bid":"0.97", "best_ask":"0.98"}, {"asset_id":"81916206347121459497221114766050949090435061493822476265356047392175668050706", "price":"0.06", "size":"945", "side":"SELL", "hash":"bc17499fffa01c4572d0e0214bfa7aed66cdc022", "best_bid":"0.02", "best_ask":"0.03"}], "timestamp":"1770241492374", "event_type":"price_change"}
{"market":"0x38f3050258345e9cf363d1c8cc302f08c65b96ba1a4669d81e07ed69708344df", "price_changes":[{"asset_id":"81916206347121459497221114766050949090435061493822476265356047392175668050706", "price":"0.01", "size":"1711.92", "side":"BUY", "hash":"cac25af595780f78c96c1dcabb31c8cc719c19b0", "best_bid":"0.02", "best_ask":"0.03"}, {"asset_id":"96888240988495161476033313796107536512663280794332045579302109906525918376981", "price":"0.99", "size":"1711.92", "side":"SELL", "hash":"28713d52f4cfdcf001414ec204a52bdf788c67e9", "best_bid":"0.97", "best_ask":"0.98"}], "timestamp":"1770241492375", "event_type":"price_change"}
{"market":"0x38f3050258345e9cf363d1c8cc302f08c65b96ba1a4669d81e07ed69708344df", "price_changes":[{"asset_id":"81916206347121459497221114766050949090435061493822476265356047392175668050706", "price":"0.01", "size":"1684.92", "side":"BUY", "hash":"9084ebbc017d1ca24aa298e0a3512bd14006b12e", "best_bid":"0.02", "best_ask":"0.03"}, {"asset_id":"96888240988495161476033313796107536512663280794332045579302109906525918376981", "price":"0.99", "size":"1684.92", "side":"SELL", "hash":"577bb880f10de9d651e28214279a47a67f186078", "best_bid":"0.97", "best_ask":"0.98"}], "timestamp":"1770241492378", "event_type":"price_change"}
{"market":"0x38f3050258345e9cf363d1c8cc302f08c65b96ba1a4669d81e07ed69708344df", "price_changes":[{"asset_id":"96888240988495161476033313796107536512663280794332045579302109906525918376981", "price":"0.94", "size":"972", "side":"BUY", "hash":"5bfe12aaec54b4c82d667e941c95abba41d84b36", "best_bid":"0.97", "best_ask":"0.98"}, {"asset_id":"81916206347121459497221114766050949090435061493822476265356047392175668050706", "price":"0.06", "size":"972", "side":"SELL", "hash":"a42853ac62f22daee908df2ce87b61aa529b4501", "best_bid":"0.02", "best_ask":"0.03"}], "timestamp":"1770241492382", "event_type":"price_change"}
{"market":"0x38f3050258345e9cf363d1c8cc302f08c65b96ba1a4669d81e07ed69708344df", "price_changes":[{"asset_id":"96888240988495161476033313796107536512663280794332045579302109906525918376981", "price":"0.94", "size":"945", "side":"BUY", "hash":"5f4fafe103cd32223d2c5d46cc5e1edfb25b59d4", "best_bid":"0.97", "best_ask":"0.98"}, {"asset_id":"81916206347121459497221114766050949090435061493822476265356047392175668050706", "price":"0.06", "size":"945", "side":"SELL", "hash":"b5447bf91379adb80ac0277ff297c8319801612d", "best_bid":"0.02", "best_ask":"0.03"}], "timestamp":"1770241492385", "event_type":"price_change"}
{"market":"0x38f3050258345e9cf363d1c8cc302f08c65b96ba1a4669d81e07ed69708344df", "price_changes":[{"asset_id":"81916206347121459497221114766050949090435061493822476265356047392175668050706", "price":"0.01", "size":"1711.92", "side":"BUY", "hash":"9edb98d00968eb33e619626230b530a8db48d7be", "best_bid":"0.02", "best_ask":"0.03"}, {"asset_id":"96888240988495161476033313796107536512663280794332045579302109906525918376981", "price":"0.99", "size":"1711.92", "side":"SELL", "hash":"a3a46cc7bae79e11475fda70451da1ed52ba3dcf", "best_bid":"0.97", "best_ask":"0.98"}], "timestamp":"1770241492388", "event_type":"price_change"}
{"market":"0x38f3050258345e9cf363d1c8cc302f08c65b96ba1a4669d81e07ed69708344df", "price_changes":[{"asset_id":"81916206347121459497221114766050949090435061493822476265356047392175668050706", "price":"0.01", "size":"1684.92", "side":"BUY", "hash":"a059cc264a01ca0be00602ebcad4ab5609ea265a", "best_bid":"0.02", "best_ask":"0.03"}, {"asset_id":"96888240988495161476033313796107536512663280794332045579302109906525918376981", "price":"0.99", "size":"1684.92", "side":"SELL", "hash":"62bf23cf31e9580b747022e261f49ae76c9d2523", "best_bid":"0.97", "best_ask":"0.98"}], "timestamp":"1770241492390", "event_type":"price_change"}
{"market":"0x38f3050258345e9cf363d1c8cc302f08c65b96ba1a4669d81e07ed69708344df", "price_changes":[{"asset_id":"81916206347121459497221114766050949090435061493822476265356047392175668050706", "price":"0.01", "size":"1657.92", "side":"BUY", "hash":"4659b26ff26e8a8a9d98c561c18bda0f5f31ba69", "best_bid":"0.02", "best_ask":"0.03"}, {"asset_id":"96888240988495161476033313796107536512663280794332045579302109906525918376981", "price":"0.99", "size":"1657.92", "side":"SELL", "hash":"7189fe2d20f49014a75f8494e422d71de2b69161", "best_bid":"0.97", "best_ask":"0.98"}], "timestamp":"1770241492393", "event_type":"price_change"}
{"market":"0x38f3050258345e9cf363d1c8cc302f08c65b96ba1a4669d81e07ed69708344df", "price_changes":[{"asset_id":"81916206347121459497221114766050949090435061493822476265356047392175668050706", "price":"0.01", "size":"1684.92", "side":"BUY", "hash":"5e3731aea534136532aeb58d7d80cd25ccf31be4", "best_bid":"0.02", "best_ask":"0.03"}, {"asset_id":"96888240988495161476033313796107536512663280794332045579302109906525918376981", "price":"0.99", "size":"1684.92", "side":"SELL", "hash":"c8c72dbc84eecb7c28f4f4643628e35fea7e97ae", "best_bid":"0.97", "best_ask":"0.98"}], "timestamp":"1770241492394", "event_type":"price_change"}
{"market":"0x38f3050258345e9cf363d1c8cc302f08c65b96ba1a4669d81e07ed69708344df", "price_changes":[{"asset_id":"96888240988495161476033313796107536512663280794332045579302109906525918376981", "price":"0.96", "size":"668.73", "side":"BUY", "hash":"a976bff6202bd32abf501e267a178eeddb0bb3e4", "best_bid":"0.97", "best_ask":"0.98"}, {"asset_id":"81916206347121459497221114766050949090435061493822476265356047392175668050706", "price":"0.04", "size":"668.73", "side":"SELL", "hash":"77c869dbbb09951d54568aa84ebff7d318ee8452", "best_bid":"0.02", "best_ask":"0.03"}], "timestamp":"1770241492396", "event_type":"price_change"}
{"market":"0x38f3050258345e9cf363d1c8cc302f08c65b96ba1a4669d81e07ed69708344df", "price_changes":[{"asset_id":"96888240988495161476033313796107536512663280794332045579302109906525918376981", "price":"0.96", "size":"695.73", "side":"BUY", "hash":"bf10be68344d5e2f8ab9026cdd236fc5f1c07890", "best_bid":"0.97", "best_ask":"0.98"}, {"asset_id":"81916206347121459497221114766050949090435061493822476265356047392175668050706", "price":"0.04", "size":"695.73", "side":"SELL", "hash":"a942aba8fcc0a7be81f475d54d387e79dc613622", "best_bid":"0.02", "best_ask":"0.03"}], "timestamp":"1770241492400", "event_type":"price_change"}
{"market":"0x38f3050258345e9cf363d1c8cc302f08c65b96ba1a4669d81e07ed69708344df", "price_changes":[{"asset_id":"96888240988495161476033313796107536512663280794332045579302109906525918376981", "price":"0.95", "size":"602", "side":"BUY", "hash":"7425101099b85bc7536fe41b85e35386f3ecc795", "best_bid":"0.97", "best_ask":"0.98"}, {"asset_id":"81916206347121459497221114766050949090435061493822476265356047392175668050706", "price":"0.05", "size":"602", "side":"SELL", "hash":"f47adcf4e9fbe4a06414d256f1a9a1cfb4566390", "best_bid":"0.02", "best_ask":"0.03"}], "timestamp":"1770241492439", "event_type":"price_change"}
{"market":"0x38f3050258345e9cf363d1c8cc302f08c65b96ba1a4669d81e07ed69708344df", "price_changes":[{"asset_id":"96888240988495161476033313796107536512663280794332045579302109906525918376981", "price":"0.97", "size":"214.14", "side":"BUY", "hash":"78f2f224b042e362c86583622e6e1a169d67e03b", "best_bid":"0.97", "best_ask":"0.98"}, {"asset_id":"81916206347121459497221114766050949090435061493822476265356047392175668050706", "price":"0.03", "size":"214.14", "side":"SELL", "hash":"2b1267cb3aca354004abc67579fff6cc8791ee48", "best_bid":"0.02", "best_ask":"0.03"}], "timestamp":"1770241492567", "event_type":"price_change"}
{"market":"0x38f3050258345e9cf363d1c8cc302f08c65b96ba1a4669d81e07ed69708344df", "asset_id":"81916206347121459497221114766050949090435061493822476265356047392175668050706", "bids":[{"price":"0.01", "size":"1684.92"}, {"price":"0.02", "size":"151.55"}], "asks":[{"price":"0.99", "size":"5019.91"}, {"price":"0.98", "size":"3034.23"}, {"price":"0.97", "size":"3172"}, {"price":"0.96", "size":"3012"}, {"price":"0.95", "size":"3032"}, {"price":"0.94", "size":"3012"}, {"price":"0.93", "size":"3126.28"}, {"price":"0.92", "size":"3012"}, {"price":"0.91", "size":"3012"}, {"price":"0.9", "size":"3087"}, {"price":"0.89", "size":"12"}, {"price":"0.88", "size":"12"}, {"price":"0.87", "size":"12"}, {"price":"0.86", "size":"12"}, {"price":"0.85", "size":"12"}, {"price":"0.84", "size":"12"}, {"price":"0.83", "size":"12"}, {"price":"0.82", "size":"12"}, {"price":"0.81", "size":"12"}, {"price":"0.8", "size":"12"}, {"price":"0.79", "size":"12"}, {"price":"0.78", "size":"12"}, {"price":"0.77", "size":"12"}, {"price":"0.76", "size":"112"}, {"price":"0.75", "size":"40.57"}, {"price":"0.74", "size":"12"}, {"price":"0.73", "size":"293.25"}, {"price":"0.72", "size":"22"}, {"price":"0.71", "size":"12"}, {"price":"0.7", "size":"18"}, {"price":"0.69", "size":"12"}, {"price":"0.68", "size":"12"}, {"price":"0.67", "size":"12"}, {"price":"0.66", "size":"160.89"}, {"price":"0.65", "size":"12"}, {"price":"0.64", "size":"12"}, {"price":"0.63", "size":"12"}, {"price":"0.62", "size":"19.39"}, {"price":"0.61", "size":"18.04"}, {"price":"0.6", "size":"12"}, {"price":"0.59", "size":"94.31"}, {"price":"0.58", "size":"5450.54"}, {"price":"0.57", "size":"12"}, {"price":"0.56", "size":"12"}, {"price":"0.55", "size":"12"}, {"price":"0.54", "size":"22"}, {"price":"0.53", "size":"12"}, {"price":"0.52", "size":"12"}, {"price":"0.51", "size":"12"}, {"price":"0.5", "size":"12"}, {"price":"0.49", "size":"12"}, {"price":"0.48", "size":"12"}, {"price":"0.47", "size":"12"}, {"price":"0.46", "size":"485.56"}, {"price":"0.45", "size":"31"}, {"price":"0.44", "size":"17"}, {"price":"0.43", "size":"12"}, {"price":"0.42", "size":"12"}, {"price":"0.41", "size":"12"}, {"price":"0.4", "size":"127"}, {"price":"0.39", "size":"12"}, {"price":"0.38", "size":"114.5"}, {"price":"0.37", "size":"12"}, {"price":"0.36", "size":"12"}, {"price":"0.35", "size":"37"}, {"price":"0.34", "size":"12"}, {"price":"0.33", "size":"12"}, {"price":"0.32", "size":"12"}, {"price":"0.31", "size":"12"}, {"price":"0.3", "size":"31.9"}, {"price":"0.29", "size":"344"}, {"price":"0.28", "size":"3288.99"}, {"price":"0.27", "size":"212"}, {"price":"0.26", "size":"218"}, {"price":"0.25", "size":"212"}, {"price":"0.24", "size":"212"}, {"price":"0.23", "size":"212"}, {"price":"0.22", "size":"1223.14"}, {"price":"0.21", "size":"712"}, {"price":"0.2", "size":"472.99"}, {"price":"0.19", "size":"212"}, {"price":"0.18", "size":"212"}, {"price":"0.17", "size":"212"}, {"price":"0.16", "size":"812"}, {"price":"0.15", "size":"231.08"}, {"price":"0.14", "size":"283.65"}, {"price":"0.13", "size":"212"}, {"price":"0.12", "size":"212"}, {"price":"0.11", "size":"212"}, {"price":"0.1", "size":"706.71"}, {"price":"0.09", "size":"221"}, {"price":"0.08", "size":"804.68"}, {"price":"0.07", "size":"286"}, {"price":"0.06", "size":"945"}, {"price":"0.05", "size":"602"}, {"price":"0.04", "size":"695.73"}, {"price":"0.03", "size":"214.14"}], "hash":"2b1267cb3aca354004abc67579fff6cc8791ee48", "timestamp":"1770241492567", "event_type":"book"}
{"market":"0x38f3050258345e9cf363d1c8cc302f08c65b96ba1a4669d81e07ed69708344df", "price_changes":[{"asset_id":"81916206347121459497221114766050949090435061493822476265356047392175668050706", "price":"0.01", "size":"1657.92", "side":"BUY", "hash":"9b85c838054483e834e9a5b8e81b596f618dfe82", "best_bid":"0.02", "best_ask":"0.03"}, {"asset_id":"96888240988495161476033313796107536512663280794332045579302109906525918376981", "price":"0.99", "size":"1657.92", "side":"SELL", "hash":"1830976464cf1c39222c1dc69bdce5d64bf1ec61", "best_bid":"0.97", "best_ask":"0.98"}], "timestamp":"1770241492582", "event_type":"price_change"}
{"market":"0x38f3050258345e9cf363d1c8cc302f08c65b96ba1a4669d81e07ed69708344df", "price_changes":[{"asset_id":"96888240988495161476033313796107536512663280794332045579302109906525918376981", "price":"0.94", "size":"972", "side":"BUY", "hash":"294961df7f764cf70d530bbf7aec4549ac4c706a", "best_bid":"0.97", "best_ask":"0.98"}, {"asset_id":"81916206347121459497221114766050949090435061493822476265356047392175668050706", "price":"0.06", "size":"972", "side":"SELL", "hash":"bada037961686a193dc949aa45f225ab8d8c4008", "best_bid":"0.02", "best_ask":"0.03"}], "timestamp":"1770241492584", "event_type":"price_change"}
{"market":"0x38f3050258345e9cf363d1c8cc302f08c65b96ba1a4669d81e07ed69708344df", "price_changes":[{"asset_id":"96888240988495161476033313796107536512663280794332045579302109906525918376981", "price":"0.94", "size":"945", "side":"BUY", "hash":"9fec4b5f86a37e3f869a30231b3f206494fb4ad9", "best_bid":"0.97", "best_ask":"0.98"}, {"asset_id":"81916206347121459497221114766050949090435061493822476265356047392175668050706", "price":"0.06", "size":"945", "side":"SELL", "hash":"2120eb03daebc91207175f617724d57b69903e03", "best_bid":"0.02", "best_ask":"0.03"}], "timestamp":"1770241492584", "event_type":"price_change"}
{"market":"0x38f3050258345e9cf363d1c8cc302f08c65b96ba1a4669d81e07ed69708344df", "price_changes":[{"asset_id":"81916206347121459497221114766050949090435061493822476265356047392175668050706", "price":"0.01", "size":"1684.92", "side":"BUY", "hash":"adf2e22854d1409699b2b88358d6d93dac770e64", "best_bid":"0.02", "best_ask":"0.03"}, {"asset_id":"96888240988495161476033313796107536512663280794332045579302109906525918376981", "price":"0.99", "size":"1684.92", "side":"SELL", "hash":"9d17069e659a44f4e851d33ab69b477de43961ba", "best_bid":"0.97", "best_ask":"0.98"}], "timestamp":"1770241492587", "event_type":"price_change"}
{"market":"0x38f3050258345e9cf363d1c8cc302f08c65b96ba1a4669d81e07ed69708344df", "price_changes":[{"asset_id":"81916206347121459497221114766050949090435061493822476265356047392175668050706", "price":"0.01", "size":"1657.92", "side":"BUY", "hash":"1c525c0d7a47c729707a231f95d7f2a240dff864", "best_bid":"0.02", "best_ask":"0.03"}, {"asset_id":"96888240988495161476033313796107536512663280794332045579302109906525918376981", "price":"0.99", "size":"1657.92", "side":"SELL", "hash":"131e527a6c3a5740d748d57be946e8c995993c84", "best_bid":"0.97", "best_ask":"0.98"}], "timestamp":"1770241492592", "event_type":"price_change"}
{"market":"0x38f3050258345e9cf363d1c8cc302f08c65b96ba1a4669d81e07ed69708344df", "price_changes":[{"asset_id":"96888240988495161476033313796107536512663280794332045579302109906525918376981", "price":"0.94", "size":"918", "side":"BUY", "hash":"fb3af850de2eea10f2b56a6e6cea6d3dffaaa41a", "best_bid":"0.97", "best_ask":"0.98"}, {"asset_id":"81916206347121459497221114766050949090435061493822476265356047392175668050706", "price":"0.06", "size":"918", "side":"SELL", "hash":"db192db957a734e00cb27a7412a9ceabaaf55e87", "best_bid":"0.02", "best_ask":"0.03"}], "timestamp":"1770241492596", "event_type":"price_change"}
{"market":"0x38f3050258345e9cf363d1c8cc302f08c65b96ba1a4669d81e07ed69708344df", "price_changes":[{"asset_id":"81916206347121459497221114766050949090435061493822476265356047392175668050706", "price":"0.01", "size":"1684.92", "side":"BUY", "hash":"43dbc6a4d70401dec4a48b4095e2d77ab6772a5b", "best_bid":"0.02", "best_ask":"0.03"}, {"asset_id":"96888240988495161476033313796107536512663280794332045579302109906525918376981", "price":"0.99", "size":"1684.92", "side":"SELL", "hash":"d1859351389abd668d984995fee06da389e4613b", "best_bid":"0.97", "best_ask":"0.98"}], "timestamp":"1770241492598", "event_type":"price_change"}
{"market":"0x38f3050258345e9cf363d1c8cc302f08c65b96ba1a4669d81e07ed69708344df", "price_changes":[{"asset_id":"96888240988495161476033313796107536512663280794332045579302109906525918376981", "price":"0.94", "size":"945", "side":"BUY", "hash":"e50ef08264573a85c9039daa582a2e070aec2bc2", "best_bid":"0.97", "best_ask":"0.98"}, {"asset_id":"81916206347121459497221114766050949090435061493822476265356047392175668050706", "price":"0.06", "size":"945", "side":"SELL", "hash":"8a3c34a06bfc3ffe7ce11941f6e36312fd977634", "best_bid":"0.02", "best_ask":"0.03"}], "timestamp":"1770241492599", "event_type":"price_change"}
{"market":"0x38f3050258345e9cf363d1c8cc302f08c65b96ba1a4669d81e07ed69708344df", "price_changes":[{"asset_id":"81916206347121459497221114766050949090435061493822476265356047392175668050706", "price":"0.01", "size":"1707.92", "side":"BUY", "hash":"f44ed5ac21f7452541a29454509d4d8d05d739c7", "best_bid":"0.02", "best_ask":"0.03"}, {"asset_id":"96888240988495161476033313796107536512663280794332045579302109906525918376981", "price":"0.99", "size":"1707.92", "side":"SELL", "hash":"fa4fff6d13081e909336cc81148e1946b6e52bb0", "best_bid":"0.97", "best_ask":"0.98"}], "timestamp":"1770241492684", "event_type":"price_change"}
{"market":"0x38f3050258345e9cf363d1c8cc302f08c65b96ba1a4669d81e07ed69708344df", "price_changes":[{"asset_id":"96888240988495161476033313796107536512663280794332045579302109906525918376981", "price":"0.96", "size":"668.73", "side":"BUY", "hash":"786aa71de18c7ca5efe2fc8b812df114b2d561b3", "best_bid":"0.97", "best_ask":"0.98"}, {"asset_id":"81916206347121459497221114766050949090435061493822476265356047392175668050706", "price":"0.04", "size":"668.73", "side":"SELL", "hash":"703fcf58650fbf0009bda6c6fb11ca90d5444028", "best_bid":"0.02", "best_ask":"0.03"}], "timestamp":"1770241492700", "event_type":"price_change"}
{"market":"0x38f3050258345e9cf363d1c8cc302f08c65b96ba1a4669d81e07ed69708344df", "price_changes":[{"asset_id":"81916206347121459497221114766050949090435061493822476265356047392175668050706", "price":"0.01", "size":"1734.92", "side":"BUY", "hash":"cd78e602bf39a93bd56095c8554ab64e084d3218", "best_bid":"0.02", "best_ask":"0.03"}, {"asset_id":"96888240988495161476033313796107536512663280794332045579302109906525918376981", "price":"0.99", "size":"1734.92", "side":"SELL", "hash":"00c9ba7957d98bab2607d1ac209649cf25e96d94", "best_bid":"0.97", "best_ask":"0.98"}], "timestamp":"1770241492701", "event_type":"price_change"}
{"market":"0x38f3050258345e9cf363d1c8cc302f08c65b96ba1a4669d81e07ed69708344df", "price_changes":[{"asset_id":"96888240988495161476033313796107536512663280794332045579302109906525918376981", "price":"0.96", "size":"695.73", "side":"BUY", "hash":"6d97987fdaa8fb3fa09cd8bc117ce8c4f5cdb17e", "best_bid":"0.97", "best_ask":"0.98"}, {"asset_id":"81916206347121459497221114766050949090435061493822476265356047392175668050706", "price":"0.04", "size":"695.73", "side":"SELL", "hash":"f72b8b42d23d3b7541a4693910883a3dd5b341a4", "best_bid":"0.02", "best_ask":"0.03"}], "timestamp":"1770241492707", "event_type":"price_change"}
{"market":"0x38f3050258345e9cf363d1c8cc302f08c65b96ba1a4669d81e07ed69708344df", "price_changes":[{"asset_id":"81916206347121459497221114766050949090435061493822476265356047392175668050706", "price":"0.01", "size":"1707.92", "side":"BUY", "hash":"ac4f55e3c43f0cc5ab7e053ef91f1327089718f6", "best_bid":"0.02", "best_ask":"0.03"}, {"asset_id":"96888240988495161476033313796107536512663280794332045579302109906525918376981", "price":"0.99", "size":"1707.92", "side":"SELL", "hash":"98c3b8f96e573a54d52624043105d1b2e1731f94", "best_bid":"0.97", "best_ask":"0.98"}], "timestamp":"1770241492712", "event_type":"price_change"}
{"market":"0x38f3050258345e9cf363d1c8cc302f08c65b96ba1a4669d81e07ed69708344df", "price_changes":[{"asset_id":"96888240988495161476033313796107536512663280794332045579302109906525918376981", "price":"0.95", "size":"629", "side":"BUY", "hash":"116009b4606b335e10fd376bd5d52773174a7734", "best_bid":"0.97", "best_ask":"0.98"}, {"asset_id":"81916206347121459497221114766050949090435061493822476265356047392175668050706", "price":"0.05", "size":"629", "side":"SELL", "hash":"acfff443a844e7d7fd3ef420d1256574f8b63c7a", "best_bid":"0.02", "best_ask":"0.03"}], "timestamp":"1770241492732", "event_type":"price_change"}
{"market":"0x38f3050258345e9cf363d1c8cc302f08c65b96ba1a4669d81e07ed69708344df", "price_changes":[{"asset_id":"96888240988495161476033313796107536512663280794332045579302109906525918376981", "price":"0.94", "size":"918", "side":"BUY", "hash":"97dfe3037c51f500a553a55171324fc41153d8e5", "best_bid":"0.97", "best_ask":"0.98"}, {"asset_id":"81916206347121459497221114766050949090435061493822476265356047392175668050706", "price":"0.06", "size":"918", "side":"SELL", "hash":"122514a0860664803f45d86d60cab91813be1122", "best_bid":"0.02", "best_ask":"0.03"}], "timestamp":"1770241492733", "event_type":"price_change"}
{"market":"0x38f3050258345e9cf363d1c8cc302f08c65b96ba1a4669d81e07ed69708344df", "price_changes":[{"asset_id":"96888240988495161476033313796107536512663280794332045579302109906525918376981", "price":"0.94", "size":"891", "side":"BUY", "hash":"ddd1e035a2af5282dda2e6a5c2d5837ae7e348e0", "best_bid":"0.97", "best_ask":"0.98"}, {"asset_id":"81916206347121459497221114766050949090435061493822476265356047392175668050706", "price":"0.06", "size":"891", "side":"SELL", "hash":"782a9f7f45081f38df96a509d62837af7be33ec7", "best_bid":"0.02", "best_ask":"0.03"}], "timestamp":"1770241492743", "event_type":"price_change"}
{"market":"0x38f3050258345e9cf363d1c8cc302f08c65b96ba1a4669d81e07ed69708344df", "price_changes":[{"asset_id":"96888240988495161476033313796107536512663280794332045579302109906525918376981", "price":"0.95", "size":"656", "side":"BUY", "hash":"c0394b6487162fb8a0cdc4bdb56d3a7487443979", "best_bid":"0.97", "best_ask":"0.98"}, {"asset_id":"81916206347121459497221114766050949090435061493822476265356047392175668050706", "price":"0.05", "size":"656", "side":"SELL", "hash":"afcd0202eff37fd4f18010ef1eef75f9ca94273a", "best_bid":"0.02", "best_ask":"0.03"}], "timestamp":"1770241492747", "event_type":"price_change"}
{"market":"0x38f3050258345e9cf363d1c8cc302f08c65b96ba1a4669d81e07ed69708344df", "price_changes":[{"asset_id":"81916206347121459497221114766050949090435061493822476265356047392175668050706", "price":"0.01", "size":"1734.92", "side":"BUY", "hash":"09b88978b7faa1c49f617939ad8690375cc01f2e", "best_bid":"0.02", "best_ask":"0.03"}, {"asset_id":"96888240988495161476033313796107536512663280794332045579302109906525918376981", "price":"0.99", "size":"1734.92", "side":"SELL", "hash":"057fa3c77360167ba2f7ea94adbafdd098039a78", "best_bid":"0.97", "best_ask":"0.98"}], "timestamp":"1770241492781", "event_type":"price_change"}
{"market":"0x38f3050258345e9cf363d1c8cc302f08c65b96ba1a4669d81e07ed69708344df", "price_changes":[{"asset_id":"81916206347121459497221114766050949090435061493822476265356047392175668050706", "price":"0.01", "size":"1707.92", "side":"BUY", "hash":"8e2a95d798e0e2e540b7b5174f5d275379f2d34d", "best_bid":"0.02", "best_ask":"0.03"}, {"asset_id":"96888240988495161476033313796107536512663280794332045579302109906525918376981", "price":"0.99", "size":"1707.92", "side":"SELL", "hash":"291e97ad7eee265f4eb965e6525c4006039e15ae", "best_bid":"0.97", "best_ask":"0.98"}], "timestamp":"1770241492782", "event_type":"price_change"}
{"market":"0x38f3050258345e9cf363d1c8cc302f08c65b96ba1a4669d81e07ed69708344df", "price_changes":[{"asset_id":"96888240988495161476033313796107536512663280794332045579302109906525918376981", "price":"0.95", "size":"636", "side":"BUY", "hash":"04242cdc4e264f8a91f17775f06a627b6b8a5ed3", "best_bid":"0.97", "best_ask":"0.98"}, {"asset_id":"81916206347121459497221114766050949090435061493822476265356047392175668050706", "price":"0.05", "size":"636", "side":"SELL", "hash":"f29bc8d0561c4a896c8dd2faf8efd9fed7b97262", "best_bid":"0.02", "best_ask":"0.03"}], "timestamp":"1770241492819", "event_type":"price_change"}
{"market":"0x38f3050258345e9cf363d1c8cc302f08c65b96ba1a4669d81e07ed69708344df", "price_changes":[{"asset_id":"81916206347121459497221114766050949090435061493822476265356047392175668050706", "price":"0.01", "size":"1684.92", "side":"BUY", "hash":"c7a5a2fc94ba3bf43e666caf55916f1f566e9822", "best_bid":"0.02", "best_ask":"0.03"}, {"asset_id":"96888240988495161476033313796107536512663280794332045579302109906525918376981", "price":"0.99", "size":"1684.92", "side":"SELL", "hash":"e90893c42d76ff9e749e9595312ba184dc7a2e24", "best_bid":"0.97", "best_ask":"0.98"}], "timestamp":"1770241492838", "event_type":"price_change"}
{"market":"0x38f3050258345e9cf363d1c8cc302f08c65b96ba1a4669d81e07ed69708344df", "price_changes":[{"asset_id":"81916206347121459497221114766050949090435061493822476265356047392175668050706", "price":"0.02", "size":"174.55", "side":"BUY", "hash":"a0c4c9ca12298664e0ffaddc7969657b7bb23052", "best_bid":"0.02", "best_ask":"0.03"}, {"asset_id":"96888240988495161476033313796107536512663280794332045579302109906525918376981", "price":"0.98", "size":"174.55", "side":"SELL", "hash":"970c5f24a43b08d2bb32f17cc444b7ae81c95f70", "best_bid":"0.97", "best_ask":"0.98"}], "timestamp":"1770241492847", "event_type":"price_change"}
{"market":"0x38f3050258345e9cf363d1c8cc302f08c65b96ba1a4669d81e07ed69708344df", "price_changes":[{"asset_id":"81916206347121459497221114766050949090435061493822476265356047392175668050706", "price":"0.01", "size":"1657.92", "side":"BUY", "hash":"f6d0e8efdcd8b28a73ec822475cf9e6d2ca9cc5d", "best_bid":"0.02", "best_ask":"0.03"}, {"asset_id":"96888240988495161476033313796107536512663280794332045579302109906525918376981", "price":"0.99", "size":"1657.92", "side":"SELL", "hash":"2255d7e5dcb9e9bc832b3ab7f3f623e0afc1907c", "best_bid":"0.97", "best_ask":"0.98"}], "timestamp":"1770241492849", "event_type":"price_change"}
{"market":"0x38f3050258345e9cf363d1c8cc302f08c65b96ba1a4669d81e07ed69708344df", "price_changes":[{"asset_id":"96888240988495161476033313796107536512663280794332045579302109906525918376981", "price":"0.97", "size":"241.14", "side":"BUY", "hash":"45e77232f39439d1a4fdfaa59b8e15d81f1bc8b1", "best_bid":"0.97", "best_ask":"0.98"}, {"asset_id":"81916206347121459497221114766050949090435061493822476265356047392175668050706", "price":"0.03", "size":"241.14", "side":"SELL", "hash":"f8ecd79af877faa20736bd3e98c0f42ab0820a90", "best_bid":"0.02", "best_ask":"0.03"}], "timestamp":"1770241492850", "event_type":"price_change"}
{"market":"0x38f3050258345e9cf363d1c8cc302f08c65b96ba1a4669d81e07ed69708344df", "price_changes":[{"asset_id":"81916206347121459497221114766050949090435061493822476265356047392175668050706", "price":"0.01", "size":"1684.92", "side":"BUY", "hash":"c8c75ccf848fc5e12f8f259f33b02739c6581056", "best_bid":"0.02", "best_ask":"0.03"}, {"asset_id":"96888240988495161476033313796107536512663280794332045579302109906525918376981", "price":"0.99", "size":"1684.92", "side":"SELL", "hash":"88d9076aace7c5e8a8cd59645a5fc3232e2ae4a9", "best_bid":"0.97", "best_ask":"0.98"}], "timestamp":"1770241492852", "event_type":"price_change"}
{"market":"0x38f3050258345e9cf363d1c8cc302f08c65b96ba1a4669d81e07ed69708344df", "price_changes":[{"asset_id":"96888240988495161476033313796107536512663280794332045579302109906525918376981", "price":"0.96", "size":"668.73", "side":"BUY", "hash":"d86e4f8a227a677ba84edb9b56219ef3d3055ac7", "best_bid":"0.97", "best_ask":"0.98"}, {"asset_id":"81916206347121459497221114766050949090435061493822476265356047392175668050706", "price":"0.04", "size":"668.73", "side":"SELL", "hash":"4e516185a059addb7ada8ffae7e002f5eac54d24", "best_bid":"0.02", "best_ask":"0.03"}], "timestamp":"1770241492863", "event_type":"price_change"}
{"market":"0x38f3050258345e9cf363d1c8cc302f08c65b96ba1a4669d81e07ed69708344df", "price_changes":[{"asset_id":"81916206347121459497221114766050949090435061493822476265356047392175668050706", "price":"0.01", "size":"1657.92", "side":"BUY", "hash":"7ff3d5dec4e6dccf58f701e2790e6f4727e87ded", "best_bid":"0.02", "best_ask":"0.03"}, {"asset_id":"96888240988495161476033313796107536512663280794332045579302109906525918376981", "price":"0.99", "size":"1657.92", "side":"SELL", "hash":"bbad9e5f4a2a6a560646415b48722da946230c49", "best_bid":"0.97", "best_ask":"0.98"}], "timestamp":"1770241492867", "event_type":"price_change"}
{"market":"0x38f3050258345e9cf363d1c8cc302f08c65b96ba1a4669d81e07ed69708344df", "price_changes":[{"asset_id":"81916206347121459497221114766050949090435061493822476265356047392175668050706", "price":"0.01", "size":"1684.92", "side":"BUY", "hash":"abddc3c5b8d063e87b9f63ec1a05a0fd8ded40f2", "best_bid":"0.02", "best_ask":"0.03"}, {"asset_id":"96888240988495161476033313796107536512663280794332045579302109906525918376981", "price":"0.99", "size":"1684.92", "side":"SELL", "hash":"f92d8ec593d772207357e72810573a8561786457", "best_bid":"0.97", "best_ask":"0.98"}], "timestamp":"1770241492868", "event_type":"price_change"}
{"market":"0x38f3050258345e9cf363d1c8cc302f08c65b96ba1a4669d81e07ed69708344df", "price_changes":[{"asset_id":"96888240988495161476033313796107536512663280794332045579302109906525918376981", "price":"0.95", "size":"663", "side":"BUY", "hash":"11100c093d68ee4b66f134f892951a81726c5a74", "best_bid":"0.97", "best_ask":"0.98"}, {"asset_id":"81916206347121459497221114766050949090435061493822476265356047392175668050706", "price":"0.05", "size":"663", "side":"SELL", "hash":"ef62feea8cc86b789fec51954fb7d4f571b50e79", "best_bid":"0.02", "best_ask":"0.03"}], "timestamp":"1770241492868", "event_type":"price_change"}
{"market":"0x38f3050258345e9cf363d1c8cc302f08c65b96ba1a4669d81e07ed69708344df", "price_changes":[{"asset_id":"96888240988495161476033313796107536512663280794332045579302109906525918376981", "price":"0.95", "size":"636", "side":"BUY", "hash":"66aa2825c6027675324c75b594cde8eca5ce3a42", "best_bid":"0.97", "best_ask":"0.98"}, {"asset_id":"81916206347121459497221114766050949090435061493822476265356047392175668050706", "price":"0.05", "size":"636", "side":"SELL", "hash":"fc9fb3d093bc6102e6bc47c63bcb5ba75bc4d7e6", "best_bid":"0.02", "best_ask":"0.03"}], "timestamp":"1770241492869", "event_type":"price_change"}
{"market":"0x38f3050258345e9cf363d1c8cc302f08c65b96ba1a4669d81e07ed69708344df", "price_changes":[{"asset_id":"96888240988495161476033313796107536512663280794332045579302109906525918376981", "price":"0.95", "size":"663", "side":"BUY", "hash":"360c619ab2c5bfefd997316f4769f4cf5d2c94fc", "best_bid":"0.97", "best_ask":"0.98"}, {"asset_id":"81916206347121459497221114766050949090435061493822476265356047392175668050706", "price":"0.05", "size":"663", "side":"SELL", "hash":"08dc5428bc5ecbb3d0ad60492f7267c4ba8aae4f", "best_bid":"0.02", "best_ask":"0.03"}], "timestamp":"1770241492871", "event_type":"price_change"}
{"market":"0x38f3050258345e9cf363d1c8cc302f08c65b96ba1a4669d81e07ed69708344df", "price_changes":[{"asset_id":"96888240988495161476033313796107536512663280794332045579302109906525918376981", "price":"0.95", "size":"636", "side":"BUY", "hash":"720a71e4130a20321699f4155c8584897154d449", "best_bid":"0.97", "best_ask":"0.98"}, {"asset_id":"81916206347121459497221114766050949090435061493822476265356047392175668050706", "price":"0.05", "size":"636", "side":"SELL", "hash":"1a3783a921a48180618b811cd4dd90d65622b488", "best_bid":"0.02", "best_ask":"0.03"}], "timestamp":"1770241492872", "event_type":"price_change"}
{"market":"0x38f3050258345e9cf363d1c8cc302f08c65b96ba1a4669d81e07ed69708344df", "price_changes":[{"asset_id":"81916206347121459497221114766050949090435061493822476265356047392175668050706", "price":"0.01", "size":"1657.92", "side":"BUY", "hash":"6ca02726a9c6baa37a28a00fc574372dea4fa8b8", "best_bid":"0.02", "best_ask":"0.03"}, {"asset_id":"96888240988495161476033313796107536512663280794332045579302109906525918376981", "price":"0.99", "size":"1657.92", "side":"SELL", "hash":"1821943ce0ddd3b52e2f267f32ad0ed27f8f7af1", "best_bid":"0.97", "best_ask":"0.98"}], "timestamp":"1770241493021", "event_type":"price_change"}
{"market":"0x38f3050258345e9cf363d1c8cc302f08c65b96ba1a4669d81e07ed69708344df", "price_changes":[{"asset_id":"81916206347121459497221114766050949090435061493822476265356047392175668050706", "price":"0.01", "size":"1684.92", "side":"BUY", "hash":"ee7e829cb01ed2bdc47b0b4e9cfe7bff27adb1ed", "best_bid":"0.02", "best_ask":"0.03"}, {"asset_id":"96888240988495161476033313796107536512663280794332045579302109906525918376981", "price":"0.99", "size":"1684.92", "side":"SELL", "hash":"29100f551e792f5e4cf32cd68b6e1f1a5146d46d", "best_bid":"0.97", "best_ask":"0.98"}], "timestamp":"1770241493023", "event_type":"price_change"}
{"market":"0x38f3050258345e9cf363d1c8cc302f08c65b96ba1a4669d81e07ed69708344df", "price_changes":[{"asset_id":"96888240988495161476033313796107536512663280794332045579302109906525918376981", "price":"0.95", "size":"609", "side":"BUY", "hash":"6ad1b62866dd5b84e6ab997612cea8914228cd20", "best_bid":"0.97", "best_ask":"0.98"}, {"asset_id":"81916206347121459497221114766050949090435061493822476265356047392175668050706", "price":"0.05", "size":"609", "side":"SELL", "hash":"c03ddbee990dabee9c91b4eb7c92586d80b46dfb", "best_bid":"0.02", "best_ask":"0.03"}], "timestamp":"1770241493023", "event_type":"price_change"}
{"market":"0x38f3050258345e9cf363d1c8cc302f08c65b96ba1a4669d81e07ed69708344df", "price_changes":[{"asset_id":"96888240988495161476033313796107536512663280794332045579302109906525918376981", "price":"0.95", "size":"636", "side":"BUY", "hash":"edd4c23351cc24a1bba09a80f9965741a40c21fc", "best_bid":"0.97", "best_ask":"0.98"}, {"asset_id":"81916206347121459497221114766050949090435061493822476265356047392175668050706", "price":"0.05", "size":"636", "side":"SELL", "hash":"125f76d7ee90ab68cefef774acd2885ffb71b5ce", "best_bid":"0.02", "best_ask":"0.03"}], "timestamp":"1770241493024", "event_type":"price_change"}
{"market":"0x38f3050258345e9cf363d1c8cc302f08c65b96ba1a4669d81e07ed69708344df", "price_changes":[{"asset_id":"96888240988495161476033313796107536512663280794332045579302109906525918376981", "price":"0.97", "size":"264.14", "side":"BUY", "hash":"de8e3d24236a7733a9db80f8a5c3c4dc67edf956", "best_bid":"0.97", "best_ask":"0.98"}, {"asset_id":"81916206347121459497221114766050949090435061493822476265356047392175668050706", "price":"0.03", "size":"264.14", "side":"SELL", "hash":"698e76e82afad83a6731738e7f90d115356aaae7", "best_bid":"0.02", "best_ask":"0.03"}], "timestamp":"1770241493025", "event_type":"price_change"}
{"market":"0x38f3050258345e9cf363d1c8cc302f08c65b96ba1a4669d81e07ed69708344df", "price_changes":[{"asset_id":"96888240988495161476033313796107536512663280794332045579302109906525918376981", "price":"0.96", "size":"645.73", "side":"BUY", "hash":"79ba7589e60332fe5ba8e377c8a8206533c7ba42", "best_bid":"0.97", "best_ask":"0.98"}, {"asset_id":"81916206347121459497221114766050949090435061493822476265356047392175668050706", "price":"0.04", "size":"645.73", "side":"SELL", "hash":"208669be9f9ead9a1640eadb1974fcf4c41bbad0", "best_bid":"0.02", "best_ask":"0.03"}], "timestamp":"1770241493026", "event_type":"price_change"}
