{"market":"0x38f3050258345e9cf363d1c8cc302f08c65b96ba1a4669d81e07ed69708344df", "asset_id":"81916206347121459497221114766050949090435061493822476265356047392175668050706", "bids":[{"price":"0.01", "size":"1693.08"}], "asks":[{"price":"0.99", "size":"5019.91"}, {"price":"0.98", "size":"3034.23"}, {"price":"0.97", "size":"3172"}, {"price":"0.96", "size":"3012"}, {"price":"0.95", "size":"3032"}, {"price":"0.94", "size":"3012"}, {"price":"0.93", "size":"3126.28"}, {"price":"0.92", "size":"3012"}, {"price":"0.91", "size":"3012"}, {"price":"0.9", "size":"3087"}, {"price":"0.89", "size":"12"}, {"price":"0.88", "size":"12"}, {"price":"0.87", "size":"12"}, {"price":"0.86", "size":"12"}, {"price":"0.85", "size":"12"}, {"price":"0.84", "size":"12"}, {"price":"0.83", "size":"12"}, {"price":"0.82", "size":"12"}, {"price":"0.81", "size":"12"}, {"price":"0.8", "size":"12"}, {"price":"0.79", "size":"12"}, {"price":"0.78", "size":"12"}, {"price":"0.77", "size":"12"}, {"price":"0.76", "size":"112"}, {"price":"0.75", "size":"40.57"}, {"price":"0.74", "size":"12"}, {"price":"0.73", "size":"293.25"}, {"price":"0.72", "size":"22"}, {"price":"0.71", "size":"12"}, {"price":"0.7", "size":"18"}, {"price":"0.69", "size":"12"}, {"price":"0.68", "size":"12"}, {"price":"0.67", "size":"12"}, {"price":"0.66", "size":"160.89"}, {"price":"0.65", "size":"12"}, {"price":"0.64", "size":"12"}, {"price":"0.63", "size":"12"}, {"price":"0.62", "size":"19.39"}, {"price":"0.61", "size":"18.04"}, {"price":"0.6", "size":"12"}, {"price":"0.59", "size":"94.31"}, {"price":"0.58", "size":"5450.54"}, {"price":"0.57", "size":"12"}, {"price":"0.56", "size":"12"}, {"price":"0.55", "size":"12"}, {"price":"0.54", "size":"22"}, {"price":"0.53", "size":"12"}, {"price":"0.52", "size":"12"}, {"price":"0.51", "size":"12"}, {"price":"0.5", "size":"12"}, {"price":"0.49", "size":"12"}, {"price":"0.48", "size":"12"}, {"price":"0.47", "size":"12"}, {"price":"0.46", "size":"485.56"}, {"price":"0.45", "size":"31"}, {"price":"0.44", "size":"17"}, {"price":"0.43", "size":"12"}, {"price":"0.42", "size":"12"}, {"price":"0.41", "size":"12"}, {"price":"0.4", "size":"127"}, {"price":"0.39", "size":"12"}, {"price":"0.38", "size":"94.51"}, {"price":"0.37", "size":"31.99"}, {"price":"0.36", "size":"12"}, {"price":"0.35", "size":"37"}, {"price":"0.34", "size":"12"}, {"price":"0.33", "size":"12"}, {"price":"0.32", "size":"12"}, {"price":"0.31", "size":"12"}, {"price":"0.3", "size":"31.9"}, {"price":"0.29", "size":"344"}, {"price":"0.28", "size":"3288.99"}, {"price":"0.27", "size":"212"}, {"price":"0.26", "size":"218"}, {"price":"0.25", "size":"212"}, {"price":"0.24", "size":"212"}, {"price":"0.23", "size":"212"}, {"price":"0.22", "size":"1223.14"}, {"price":"0.21", "size":"712"}, {"price":"0.2", "size":"472.99"}, {"price":"0.19", "size":"212"}, {"price":"0.18", "size":"212"}, {"price":"0.17", "size":"212"}, {"price":"0.16", "size":"812"}, {"price":"0.15", "size":"231.08"}, {"price":"0.14", "size":"283.65"}, {"price":"0.13", "size":"212"}, {"price":"0.12", "size":"252"}, {"price":"0.11", "size":"252"}, {"price":"0.1", "size":"737.71"}, {"price":"0.09", "size":"261"}, {"price":"0.08", "size":"844.68"}, {"price":"0.07", "size":"326"}, {"price":"0.06", "size":"931"}, {"price":"0.05", "size":"685"}, {"price":"0.04", "size":"673.73"}, {"price":"0.03", "size":"622.32"}, {"price":"0.02", "size":"583.97"}], "hash":"bccd3d131fd601b840a50528398e5dd18843f150", "timestamp":"1770241485369", "event_type":"book"}
{"market":"0x38f3050258345e9cf363d1c8cc302f08c65b96ba1a4669d81e07ed69708344df", "price_changes":[{"asset_id":"96888240988495161476033313796107536512663280794332045579302109906525918376981", "price":"0.97", "size":"645.32", "side":"BUY", "hash":"a38c599579eefcacc94d8a62b2076e77eebdd885", "best_bid":"0.98", "best_ask":"0.99"}, {"asset_id":"81916206347121459497221114766050949090435061493822476265356047392175668050706", "price":"0.03", "size":"645.32", "side":"SELL", "hash":"fee7d3b574b6bf3ace85f46a17980a3ba2a4a47e", "best_bid":"0.01", "best_ask":"0.02"}], "timestamp":"1770241485391", "event_type":"price_change"}
{"market":"0x38f3050258345e9cf363d1c8cc302f08c65b96ba1a4669d81e07ed69708344df", "price_changes":[{"asset_id":"96888240988495161476033313796107536512663280794332045579302109906525918376981", "price":"0.96", "size":"650.73", "side":"BUY", "hash":"8e9ad67dc061b9c5c71d75a9c8cdeb2c9f13dcc7", "best_bid":"0.98", "best_ask":"0.99"}, {"asset_id":"81916206347121459497221114766050949090435061493822476265356047392175668050706", "price":"0.04", "size":"650.73", "side":"SELL", "hash":"310384ed3a4b2a56ce5dbfee0bdfdd04fa447af7", "best_bid":"0.01", "best_ask":"0.02"}], "timestamp":"1770241485393", "event_type":"price_change"}
{"market":"0x38f3050258345e9cf363d1c8cc302f08c65b96ba1a4669d81e07ed69708344df", "price_changes":[{"asset_id":"96888240988495161476033313796107536512663280794332045579302109906525918376981", "price":"0.98", "size":"577.8", "side":"BUY", "hash":"d36fdde472f75b0c879cd9417ea068aedb831cd5", "best_bid":"0.98", "best_ask":"0.99"}, {"asset_id":"81916206347121459497221114766050949090435061493822476265356047392175668050706", "price":"0.02", "size":"577.8", "side":"SELL", "hash":"0d21c21da1b79cd36c2b1aa54dd292dd39f3af5e", "best_bid":"0.01", "best_ask":"0.02"}], "timestamp":"1770241485414", "event_type":"price_change"}
{"market":"0x38f3050258345e9cf363d1c8cc302f08c65b96ba1a4669d81e07ed69708344df", "asset_id":"81916206347121459497221114766050949090435061493822476265356047392175668050706", "bids":[{"price":"0.01", "size":"1693.08"}], "asks":[{"price":"0.99", "size":"5019.91"}, {"price":"0.98", "size":"3034.23"}, {"price":"0.97", "size":"3172"}, {"price":"0.96", "size":"3012"}, {"price":"0.95", "size":"3032"}, {"price":"0.94", "size":"3012"}, {"price":"0.93", "size":"3126.28"}, {"price":"0.92", "size":"3012"}, {"price":"0.91", "size":"3012"}, {"price":"0.9", "size":"3087"}, {"price":"0.89", "size":"12"}, {"price":"0.88", "size":"12"}, {"price":"0.87", "size":"12"}, {"price":"0.86", "size":"12"}, {"price":"0.85", "size":"12"}, {"price":"0.84", "size":"12"}, {"price":"0.83", "size":"12"}, {"price":"0.82", "size":"12"}, {"price":"0.81", "size":"12"}, {"price":"0.8", "size":"12"}, {"price":"0.79", "size":"12"}, {"price":"0.78", "size":"12"}, {"price":"0.77", "size":"12"}, {"price":"0.76", "size":"112"}, {"price":"0.75", "size":"40.57"}, {"price":"0.74", "size":"12"}, {"price":"0.73", "size":"293.25"}, {"price":"0.72", "size":"22"}, {"price":"0.71", "size":"12"}, {"price":"0.7", "size":"18"}, {"price":"0.69", "size":"12"}, {"price":"0.68", "size":"12"}, {"price":"0.67", "size":"12"}, {"price":"0.66", "size":"160.89"}, {"price":"0.65", "size":"12"}, {"price":"0.64", "size":"12"}, {"price":"0.63", "size":"12"}, {"price":"0.62", "size":"19.39"}, {"price":"0.61", "size":"18.04"}, {"price":"0.6", "size":"12"}, {"price":"0.59", "size":"94.31"}, {"price":"0.58", "size":"5450.54"}, {"price":"0.57", "size":"12"}, {"price":"0.56", "size":"12"}, {"price":"0.55", "size":"12"}, {"price":"0.54", "size":"22"}, {"price":"0.53", "size":"12"}, {"price":"0.52", "size":"12"}, {"price":"0.51", "size":"12"}, {"price":"0.5", "size":"12"}, {"price":"0.49", "size":"12"}, {"price":"0.48", "size":"12"}, {"price":"0.47", "size":"12"}, {"price":"0.46", "size":"485.56"}, {"price":"0.45", "size":"31"}, {"price":"0.44", "size":"17"}, {"price":"0.43", "size":"12"}, {"price":"0.42", "size":"12"}, {"price":"0.41", "size":"12"}, {"price":"0.4", "size":"127"}, {"price":"0.39", "size":"12"}, {"price":"0.38", "size":"94.51"}, {"price":"0.37", "size":"31.99"}, {"price":"0.36", "size":"12"}, {"price":"0.35", "size":"37"}, {"price":"0.34", "size":"12"}, {"price":"0.33", "size":"12"}, {"price":"0.32", "size":"12"}, {"price":"0.31", "size":"12"}, {"price":"0.3", "size":"31.9"}, {"price":"0.29", "size":"344"}, {"price":"0.28", "size":"3288.99"}, {"price":"0.27", "size":"212"}, {"price":"0.26", "size":"218"}, {"price":"0.25", "size":"212"}, {"price":"0.24", "size":"212"}, {"price":"0.23", "size":"212"}, {"price":"0.22", "size":"1223.14"}, {"price":"0.21", "size":"712"}, {"price":"0.2", "size":"472.99"}, {"price":"0.19", "size":"212"}, {"price":"0.18", "size":"212"}, {"price":"0.17", "size":"212"}, {"price":"0.16", "size":"812"}, {"price":"0.15", "size":"231.08"}, {"price":"0.14", "size":"283.65"}, {"price":"0.13", "size":"212"}, {"price":"0.12", "size":"252"}, {"price":"0.11", "size":"252"}, {"price":"0.1", "size":"737.71"}, {"price":"0.09", "size":"261"}, {"price":"0.08", "size":"844.68"}, {"price":"0.07", "size":"326"}, {"price":"0.06", "size":"931"}, {"price":"0.05", "size":"685"}, {"price":"0.04", "size":"650.73"}, {"price":"0.03", "size":"645.32"}, {"price":"0.02", "size":"577.8"}], "hash":"0d21c21da1b79cd36c2b1aa54dd292dd39f3af5e", "timestamp":"1770241485414", "event_type":"book"}
{"market":"0x38f3050258345e9cf363d1c8cc302f08c65b96ba1a4669d81e07ed69708344df", "asset_id":"81916206347121459497221114766050949090435061493822476265356047392175668050706", "price":"0.01", "size":"1882.62", "fee_rate_bps":"0", "side":"SELL", "timestamp":"1770241485417", "event_type":"last_trade_price", "transaction_hash":"0x70a69c3c220ab0480ee97ef055a823cb0809fddd70b28300e43c4e4fc7934d7e"}
{"market":"0x38f3050258345e9cf363d1c8cc302f08c65b96ba1a4669d81e07ed69708344df", "price_changes":[{"asset_id":"96888240988495161476033313796107536512663280794332045579302109906525918376981", "price":"0.97", "size":"619.32", "side":"BUY", "hash":"d15fb04bcab8d4cb552618c13af7c821c5d65d00", "best_bid":"0.98", "best_ask":"0.99"}, {"asset_id":"81916206347121459497221114766050949090435061493822476265356047392175668050706", "price":"0.03", "size":"619.32", "side":"SELL", "hash":"530a36fa24c1e9d95aff8cb556fb8d34591e1a11", "best_bid":"0.01", "best_ask":"0.02"}], "timestamp":"1770241485444", "event_type":"price_change"}
{"market":"0x38f3050258345e9cf363d1c8cc302f08c65b96ba1a4669d81e07ed69708344df", "price_changes":[{"asset_id":"96888240988495161476033313796107536512663280794332045579302109906525918376981", "price":"0.97", "size":"593.32", "side":"BUY", "hash":"456221df8ea9c27f46b3c44c73b6676db0fa8bd0", "best_bid":"0.98", "best_ask":"0.99"}, {"asset_id":"81916206347121459497221114766050949090435061493822476265356047392175668050706", "price":"0.03", "size":"593.32", "side":"SELL", "hash":"679dc1af04e21c638e189de49e2e4e7be452f73b", "best_bid":"0.01", "best_ask":"0.02"}], "timestamp":"1770241485448", "event_type":"price_change"}
{"market":"0x38f3050258345e9cf363d1c8cc302f08c65b96ba1a4669d81e07ed69708344df", "price_changes":[{"asset_id":"96888240988495161476033313796107536512663280794332045579302109906525918376981", "price":"0.97", "size":"567.32", "side":"BUY", "hash":"6e3658bf84cdda96e8b0626290a2e23aa50e758c", "best_bid":"0.98", "best_ask":"0.99"}, {"asset_id":"81916206347121459497221114766050949090435061493822476265356047392175668050706", "price":"0.03", "size":"567.32", "side":"SELL", "hash":"77572a58b5102237678e883a6d50c3832ed43e78", "best_bid":"0.01", "best_ask":"0.02"}], "timestamp":"1770241485457", "event_type":"price_change"}
{"market":"0x38f3050258345e9cf363d1c8cc302f08c65b96ba1a4669d81e07ed69708344df", "price_changes":[{"asset_id":"96888240988495161476033313796107536512663280794332045579302109906525918376981", "price":"0.96", "size":"623.73", "side":"BUY", "hash":"8e9cb9d4842e772472e1b929c3ffda55c6cf6b70", "best_bid":"0.98", "best_ask":"0.99"}, {"asset_id":"81916206347121459497221114766050949090435061493822476265356047392175668050706", "price":"0.04", "size":"623.73", "side":"SELL", "hash":"5143871d6c7866d24600de19d4d4eb2e9b001696", "best_bid":"0.01", "best_ask":"0.02"}], "timestamp":"1770241485487", "event_type":"price_change"}
{"market":"0x38f3050258345e9cf363d1c8cc302f08c65b96ba1a4669d81e07ed69708344df", "price_changes":[{"asset_id":"96888240988495161476033313796107536512663280794332045579302109906525918376981", "price":"0.97", "size":"594.32", "side":"BUY", "hash":"491fa45b558a3783bb969d30cb926f81a532f9a3", "best_bid":"0.98", "best_ask":"0.99"}, {"asset_id":"81916206347121459497221114766050949090435061493822476265356047392175668050706", "price":"0.03", "size":"594.32", "side":"SELL", "hash":"2d6713872c9199ed742ca94d2743ec6a37db51d4", "best_bid":"0.01", "best_ask":"0.02"}], "timestamp":"1770241485490", "event_type":"price_change"}
{"market":"0x38f3050258345e9cf363d1c8cc302f08c65b96ba1a4669d81e07ed69708344df", "price_changes":[{"asset_id":"96888240988495161476033313796107536512663280794332045579302109906525918376981", "price":"0.98", "size":"603.8", "side":"BUY", "hash":"d2fd228b708801fc224e45b29f25051d773137d5", "best_bid":"0.98", "best_ask":"0.99"}, {"asset_id":"81916206347121459497221114766050949090435061493822476265356047392175668050706", "price":"0.02", "size":"603.8", "side":"SELL", "hash":"850d2b9d49507ceac41657e42833e009129cd171", "best_bid":"0.01", "best_ask":"0.02"}], "timestamp":"1770241485550", "event_type":"price_change"}
{"market":"0x38f3050258345e9cf363d1c8cc302f08c65b96ba1a4669d81e07ed69708344df", "price_changes":[{"asset_id":"96888240988495161476033313796107536512663280794332045579302109906525918376981", "price":"0.98", "size":"629.8", "side":"BUY", "hash":"e61461622bfacb2b2e9c8c02e7bcee4e37879d59", "best_bid":"0.98", "best_ask":"0.99"}, {"asset_id":"81916206347121459497221114766050949090435061493822476265356047392175668050706", "price":"0.02", "size":"629.8", "side":"SELL", "hash":"e53689f30f5eaec444d608958611e6badcc7511d", "best_bid":"0.01", "best_ask":"0.02"}], "timestamp":"1770241485553", "event_type":"price_change"}
{"market":"0x38f3050258345e9cf363d1c8cc302f08c65b96ba1a4669d81e07ed69708344df", "price_changes":[{"asset_id":"96888240988495161476033313796107536512663280794332045579302109906525918376981", "price":"0.98", "size":"655.8", "side":"BUY", "hash":"4e4bff9bfda26a71a145249a34b3529a2ed247fe", "best_bid":"0.98", "best_ask":"0.99"}, {"asset_id":"81916206347121459497221114766050949090435061493822476265356047392175668050706", "price":"0.02", "size":"655.8", "side":"SELL", "hash":"623151df7219592b559fd2e22aacd5d6fc86322f", "best_bid":"0.01", "best_ask":"0.02"}], "timestamp":"1770241485558", "event_type":"price_change"}
{"market":"0x38f3050258345e9cf363d1c8cc302f08c65b96ba1a4669d81e07ed69708344df", "price_changes":[{"asset_id":"96888240988495161476033313796107536512663280794332045579302109906525918376981", "price":"0.96", "size":"603.73", "side":"BUY", "hash":"6707d2e61a3f20427a824d8017bb2ce372dc7901", "best_bid":"0.98", "best_ask":"0.99"}, {"asset_id":"81916206347121459497221114766050949090435061493822476265356047392175668050706", "price":"0.04", "size":"603.73", "side":"SELL", "hash":"b64ac939ed25018c7bb4f6bb057676e815cd2142", "best_bid":"0.01", "best_ask":"0.02"}], "timestamp":"1770241485573", "event_type":"price_change"}
{"market":"0x38f3050258345e9cf363d1c8cc302f08c65b96ba1a4669d81e07ed69708344df", "price_changes":[{"asset_id":"96888240988495161476033313796107536512663280794332045579302109906525918376981", "price":"0.97", "size":"568.32", "side":"BUY", "hash":"37b03a24d067bb28d855b3abd6f35437cb2be7e1", "best_bid":"0.98", "best_ask":"0.99"}, {"asset_id":"81916206347121459497221114766050949090435061493822476265356047392175668050706", "price":"0.03", "size":"568.32", "side":"SELL", "hash":"161be0d2f66240a808dc37be7b1a6c4aefa992e9", "best_bid":"0.01", "best_ask":"0.02"}], "timestamp":"1770241485580", "event_type":"price_change"}
{"market":"0x38f3050258345e9cf363d1c8cc302f08c65b96ba1a4669d81e07ed69708344df", "price_changes":[{"asset_id":"96888240988495161476033313796107536512663280794332045579302109906525918376981", "price":"0.98", "size":"681.8", "side":"BUY", "hash":"d5a20dbb18923d28dcaab02c2aeada71f910d67b", "best_bid":"0.98", "best_ask":"0.99"}, {"asset_id":"81916206347121459497221114766050949090435061493822476265356047392175668050706", "price":"0.02", "size":"681.8", "side":"SELL", "hash":"231367ef7be8dcdb8232951106479899e4647566", "best_bid":"0.01", "best_ask":"0.02"}], "timestamp":"1770241485715", "event_type":"price_change"}
{"market":"0x38f3050258345e9cf363d1c8cc302f08c65b96ba1a4669d81e07ed69708344df", "price_changes":[{"asset_id":"96888240988495161476033313796107536512663280794332045579302109906525918376981", "price":"0.96", "size":"626.73", "side":"BUY", "hash":"4a8be52a226df6e2e8d933cf05e2c01cef5de39e", "best_bid":"0.98", "best_ask":"0.99"}, {"asset_id":"81916206347121459497221114766050949090435061493822476265356047392175668050706", "price":"0.04", "size":"626.73", "side":"SELL", "hash":"37df19ed5bee9c25df90a97bddd5fa7207222e43", "best_bid":"0.01", "best_ask":"0.02"}], "timestamp":"1770241485938", "event_type":"price_change"}
{"market":"0x38f3050258345e9cf363d1c8cc302f08c65b96ba1a4669d81e07ed69708344df", "price_changes":[{"asset_id":"96888240988495161476033313796107536512663280794332045579302109906525918376981", "price":"0.97", "size":"545.32", "side":"BUY", "hash":"19b7e1db55a8538d2fb741fafd794bff820e11d0", "best_bid":"0.98", "best_ask":"0.99"}, {"asset_id":"81916206347121459497221114766050949090435061493822476265356047392175668050706", "price":"0.03", "size":"545.32", "side":"SELL", "hash":"ae8e3b593e454e3a52b719b25b59b3628d0b57dc", "best_bid":"0.01", "best_ask":"0.02"}], "timestamp":"1770241485939", "event_type":"price_change"}
{"market":"0x38f3050258345e9cf363d1c8cc302f08c65b96ba1a4669d81e07ed69708344df", "price_changes":[{"asset_id":"96888240988495161476033313796107536512663280794332045579302109906525918376981", "price":"0.98", "size":"701.8", "side":"BUY", "hash":"5a1522dd18851393cf73f3505babe65c15a82d22", "best_bid":"0.98", "best_ask":"0.99"}, {"asset_id":"81916206347121459497221114766050949090435061493822476265356047392175668050706", "price":"0.02", "size":"701.8", "side":"SELL", "hash":"9d9692af2f6a76109d190ff2515377644c39181a", "best_bid":"0.01", "best_ask":"0.02"}], "timestamp":"1770241485980", "event_type":"price_change"}
{"market":"0x38f3050258345e9cf363d1c8cc302f08c65b96ba1a4669d81e07ed69708344df", "price_changes":[{"asset_id":"96888240988495161476033313796107536512663280794332045579302109906525918376981", "price":"0.99", "size":"1733.08", "side":"SELL", "hash":"1d1204e4676321671599b01f941f4f769ef20513", "best_bid":"0.98", "best_ask":"0.99"}, {"asset_id":"81916206347121459497221114766050949090435061493822476265356047392175668050706", "price":"0.01", "size":"1733.08", "side":"BUY", "hash":"fcbd48dd48510dfbce000689ec20a5d8b2dfd9e7", "best_bid":"0.01", "best_ask":"0.02"}], "timestamp":"1770241486192", "event_type":"price_change"}
{"market":"0x38f3050258345e9cf363d1c8cc302f08c65b96ba1a4669d81e07ed69708344df", "price_changes":[{"asset_id":"81916206347121459497221114766050949090435061493822476265356047392175668050706", "price":"0.01", "size":"1706.08", "side":"BUY", "hash":"042381c3c143ae7839ab509465c8bf5731e0b81d", "best_bid":"0.01", "best_ask":"0.02"}, {"asset_id":"96888240988495161476033313796107536512663280794332045579302109906525918376981", "price":"0.99", "size":"1706.08", "side":"SELL", "hash":"8449cfabd85787a90db6e8343160580d68468106", "best_bid":"0.98", "best_ask":"0.99"}], "timestamp":"1770241486358", "event_type":"price_change"}
{"market":"0x38f3050258345e9cf363d1c8cc302f08c65b96ba1a4669d81e07ed69708344df", "price_changes":[{"asset_id":"81916206347121459497221114766050949090435061493822476265356047392175668050706", "price":"0.01", "size":"1733.08", "side":"BUY", "hash":"9d86caad409cbfa10e771cb7ad27536006ad4c54", "best_bid":"0.01", "best_ask":"0.02"}, {"asset_id":"96888240988495161476033313796107536512663280794332045579302109906525918376981", "price":"0.99", "size":"1733.08", "side":"SELL", "hash":"c53c1937486f7c61553fae87f64ff3d91a7acdb8", "best_bid":"0.98", "best_ask":"0.99"}], "timestamp":"1770241486358", "event_type":"price_change"}
{"market":"0x38f3050258345e9cf363d1c8cc302f08c65b96ba1a4669d81e07ed69708344df", "price_changes":[{"asset_id":"96888240988495161476033313796107536512663280794332045579302109906525918376981", "price":"0.97", "size":"518.32", "side":"BUY", "hash":"bd1d33faebd2dda0135e32f343c182b5169a3f0d", "best_bid":"0.98", "best_ask":"0.99"}, {"asset_id":"81916206347121459497221114766050949090435061493822476265356047392175668050706", "price":"0.03", "size":"518.32", "side":"SELL", "hash":"5046b5e45f07102fccbec00165f2bbd45bddb511", "best_bid":"0.01", "best_ask":"0.02"}], "timestamp":"1770241486361", "event_type":"price_change"}
{"market":"0x38f3050258345e9cf363d1c8cc302f08c65b96ba1a4669d81e07ed69708344df", "price_changes":[{"asset_id":"96888240988495161476033313796107536512663280794332045579302109906525918376981", "price":"0.97", "size":"545.32", "side":"BUY", "hash":"4a43e1a94c628cc172afffc0065197d22d3581e4", "best_bid":"0.98", "best_ask":"0.99"}, {"asset_id":"81916206347121459497221114766050949090435061493822476265356047392175668050706", "price":"0.03", "size":"545.32", "side":"SELL", "hash":"36c41800fc1c077ab6ba2061c3cb427607cf367e", "best_bid":"0.01", "best_ask":"0.02"}], "timestamp":"1770241486364", "event_type":"price_change"}
{"market":"0x38f3050258345e9cf363d1c8cc302f08c65b96ba1a4669d81e07ed69708344df", "price_changes":[{"asset_id":"81916206347121459497221114766050949090435061493822476265356047392175668050706", "price":"0.01", "size":"1706.08", "side":"BUY", "hash":"4784337494343cd5f69650648d45c2c90ed11f48", "best_bid":"0.01", "best_ask":"0.02"}, {"asset_id":"96888240988495161476033313796107536512663280794332045579302109906525918376981", "price":"0.99", "size":"1706.08", "side":"SELL", "hash":"7dc9590ae101fed04937299ac4a1252732d42200", "best_bid":"0.98", "best_ask":"0.99"}], "timestamp":"1770241486364", "event_type":"price_change"}
{"market":"0x38f3050258345e9cf363d1c8cc302f08c65b96ba1a4669d81e07ed69708344df", "price_changes":[{"asset_id":"81916206347121459497221114766050949090435061493822476265356047392175668050706", "price":"0.01", "size":"1733.08", "side":"BUY", "hash":"5b7fd4a043a6dceec252a3c5093aad0f24f56ec1", "best_bid":"0.01", "best_ask":"0.02"}, {"asset_id":"96888240988495161476033313796107536512663280794332045579302109906525918376981", "price":"0.99", "size":"1733.08", "side":"SELL", "hash":"e2be2c1a2d79c77f93a9935619d644ec214b646c", "best_bid":"0.98", "best_ask":"0.99"}], "timestamp":"1770241486365", "event_type":"price_change"}
{"market":"0x38f3050258345e9cf363d1c8cc302f08c65b96ba1a4669d81e07ed69708344df", "price_changes":[{"asset_id":"96888240988495161476033313796107536512663280794332045579302109906525918376981", "price":"0.95", "size":"658", "side":"BUY", "hash":"fa77234b1aa2713cc501ad6fbf7c1600199e73b9", "best_bid":"0.98", "best_ask":"0.99"}, {"asset_id":"81916206347121459497221114766050949090435061493822476265356047392175668050706", "price":"0.05", "size":"658", "side":"SELL", "hash":"c124903395e78ab1976451164215b0f210fff592", "best_bid":"0.01", "best_ask":"0.02"}], "timestamp":"1770241486365", "event_type":"price_change"}
{"market":"0x38f3050258345e9cf363d1c8cc302f08c65b96ba1a4669d81e07ed69708344df", "price_changes":[{"asset_id":"96888240988495161476033313796107536512663280794332045579302109906525918376981", "price":"0.95", "size":"685", "side":"BUY", "hash":"7fa6bd8b4bbd5feeb91582d230ef84b54e87787a", "best_bid":"0.98", "best_ask":"0.99"}, {"asset_id":"81916206347121459497221114766050949090435061493822476265356047392175668050706", "price":"0.05", "size":"685", "side":"SELL", "hash":"0557167282597e7abd620f679ae48ddb1c5c9627", "best_bid":"0.01", "best_ask":"0.02"}], "timestamp":"1770241486367", "event_type":"price_change"}
{"market":"0x38f3050258345e9cf363d1c8cc302f08c65b96ba1a4669d81e07ed69708344df", "price_changes":[{"asset_id":"81916206347121459497221114766050949090435061493822476265356047392175668050706", "price":"0.01", "size":"1706.08", "side":"BUY", "hash":"920d9ed108b2c017050f55f7b5199535b858a88f", "best_bid":"0.01", "best_ask":"0.02"}, {"asset_id":"96888240988495161476033313796107536512663280794332045579302109906525918376981", "price":"0.99", "size":"1706.08", "side":"SELL", "hash":"494ca2e1212b9e5568403b6672992e5617f13359", "best_bid":"0.98", "best_ask":"0.99"}], "timestamp":"1770241486373", "event_type":"price_change"}
{"market":"0x38f3050258345e9cf363d1c8cc302f08c65b96ba1a4669d81e07ed69708344df", "price_changes":[{"asset_id":"81916206347121459497221114766050949090435061493822476265356047392175668050706", "price":"0.01", "size":"1733.08", "side":"BUY", "hash":"378e71d955f2e8ff52728a1f9da99a23aa62089d", "best_bid":"0.01", "best_ask":"0.02"}, {"asset_id":"96888240988495161476033313796107536512663280794332045579302109906525918376981", "price":"0.99", "size":"1733.08", "side":"SELL", "hash":"3825717c6dc309f0828595f4bc5fe548d5f18920", "best_bid":"0.98", "best_ask":"0.99"}], "timestamp":"1770241486374", "event_type":"price_change"}
{"market":"0x38f3050258345e9cf363d1c8cc302f08c65b96ba1a4669d81e07ed69708344df", "price_changes":[{"asset_id":"96888240988495161476033313796107536512663280794332045579302109906525918376981", "price":"0.95", "size":"658", "side":"BUY", "hash":"452ae09aed98723abf3e01f5a820b9337e4ae605", "best_bid":"0.98", "best_ask":"0.99"}, {"asset_id":"81916206347121459497221114766050949090435061493822476265356047392175668050706", "price":"0.05", "size":"658", "side":"SELL", "hash":"28ff8fc8445b29e11a1a1a1fca2658275ee08099", "best_bid":"0.01", "best_ask":"0.02"}], "timestamp":"1770241486374", "event_type":"price_change"}
{"market":"0x38f3050258345e9cf363d1c8cc302f08c65b96ba1a4669d81e07ed69708344df", "price_changes":[{"asset_id":"96888240988495161476033313796107536512663280794332045579302109906525918376981", "price":"0.95", "size":"685", "side":"BUY", "hash":"da01728f32e54300f8624ccee568daf07349413c", "best_bid":"0.98", "best_ask":"0.99"}, {"asset_id":"81916206347121459497221114766050949090435061493822476265356047392175668050706", "price":"0.05", "size":"685", "side":"SELL", "hash":"bc3ec406bb48356a3995bafa458daa024439eca6", "best_bid":"0.01", "best_ask":"0.02"}], "timestamp":"1770241486379", "event_type":"price_change"}
{"market":"0x38f3050258345e9cf363d1c8cc302f08c65b96ba1a4669d81e07ed69708344df", "price_changes":[{"asset_id":"96888240988495161476033313796107536512663280794332045579302109906525918376981", "price":"0.96", "size":"603.73", "side":"BUY", "hash":"0d6566771cab47f80bca8390e0b397f417c77ce3", "best_bid":"0.98", "best_ask":"0.99"}, {"asset_id":"81916206347121459497221114766050949090435061493822476265356047392175668050706", "price":"0.04", "size":"603.73", "side":"SELL", "hash":"8a0347207edbde170448af134c95e5b8062c2e6e", "best_bid":"0.01", "best_ask":"0.02"}], "timestamp":"1770241486393", "event_type":"price_change"}
{"market":"0x38f3050258345e9cf363d1c8cc302f08c65b96ba1a4669d81e07ed69708344df", "price_changes":[{"asset_id":"96888240988495161476033313796107536512663280794332045579302109906525918376981", "price":"0.95", "size":"658", "side":"BUY", "hash":"f1380db00600e04f24890a7ca07e532e7dfab83e", "best_bid":"0.98", "best_ask":"0.99"}, {"asset_id":"81916206347121459497221114766050949090435061493822476265356047392175668050706", "price":"0.05", "size":"658", "side":"SELL", "hash":"975b77ecd11ed8f48d4a32cd3ba5bbd263be54ea", "best_bid":"0.01", "best_ask":"0.02"}], "timestamp":"1770241486395", "event_type":"price_change"}
{"market":"0x38f3050258345e9cf363d1c8cc302f08c65b96ba1a4669d81e07ed69708344df", "price_changes":[{"asset_id":"96888240988495161476033313796107536512663280794332045579302109906525918376981", "price":"0.95", "size":"631", "side":"BUY", "hash":"b6a27d0cf9e8bf281add4cb53cbc8b6b57d56d46", "best_bid":"0.98", "best_ask":"0.99"}, {"asset_id":"81916206347121459497221114766050949090435061493822476265356047392175668050706", "price":"0.05", "size":"631", "side":"SELL", "hash":"4e5f43a0a510e1093a94981352498f8723ffe093", "best_bid":"0.01", "best_ask":"0.02"}], "timestamp":"1770241486402", "event_type":"price_change"}
{"market":"0x38f3050258345e9cf363d1c8cc302f08c65b96ba1a4669d81e07ed69708344df", "price_changes":[{"asset_id":"96888240988495161476033313796107536512663280794332045579302109906525918376981", "price":"0.97", "size":"518.32", "side":"BUY", "hash":"393e771de611b63085346c455a775633578aa950", "best_bid":"0.98", "best_ask":"0.99"}, {"asset_id":"81916206347121459497221114766050949090435061493822476265356047392175668050706", "price":"0.03", "size":"518.32", "side":"SELL", "hash":"748c3c810027ca9cc14e836eb3f07c6e566f6efb", "best_bid":"0.01", "best_ask":"0.02"}], "timestamp":"1770241486415", "event_type":"price_change"}
{"market":"0x38f3050258345e9cf363d1c8cc302f08c65b96ba1a4669d81e07ed69708344df", "price_changes":[{"asset_id":"96888240988495161476033313796107536512663280794332045579302109906525918376981", "price":"0.98", "size":"681.8", "side":"BUY", "hash":"e4b6081173e1df86390e4ab273e256d1fdc3d39c", "best_bid":"0.98", "best_ask":"0.99"}, {"asset_id":"81916206347121459497221114766050949090435061493822476265356047392175668050706", "price":"0.02", "size":"681.8", "side":"SELL", "hash":"4fc5d61e6a8e02f6975e0f291953346fa3f9aa70", "best_bid":"0.01", "best_ask":"0.02"}], "timestamp":"1770241486442", "event_type":"price_change"}
{"market":"0x38f3050258345e9cf363d1c8cc302f08c65b96ba1a4669d81e07ed69708344df", "price_changes":[{"asset_id":"96888240988495161476033313796107536512663280794332045579302109906525918376981", "price":"0.99", "size":"1745.08", "side":"SELL", "hash":"65c2e45bd8f4dd91c3d10292d2e72b69d5c85eea", "best_bid":"0.98", "best_ask":"0.99"}, {"asset_id":"81916206347121459497221114766050949090435061493822476265356047392175668050706", "price":"0.01", "size":"1745.08", "side":"BUY", "hash":"0d916fcbb3fc7565460294b9f721a27d42ea1c35", "best_bid":"0.01", "best_ask":"0.02"}], "timestamp":"1770241486452", "event_type":"price_change"}
{"market":"0x38f3050258345e9cf363d1c8cc302f08c65b96ba1a4669d81e07ed69708344df", "price_changes":[{"asset_id":"81916206347121459497221114766050949090435061493822476265356047392175668050706", "price":"0.01", "size":"1718.08", "side":"BUY", "hash":"8caf10173dd612c8cc99e950f2769f6fb38a8f7d", "best_bid":"0.01", "best_ask":"0.02"}, {"asset_id":"96888240988495161476033313796107536512663280794332045579302109906525918376981", "price":"0.99", "size":"1718.08", "side":"SELL", "hash":"d6cda805495e0b450cff8f6f49d59e4e7373d086", "best_bid":"0.98", "best_ask":"0.99"}], "timestamp":"1770241486480", "event_type":"price_change"}
{"market":"0x38f3050258345e9cf363d1c8cc302f08c65b96ba1a4669d81e07ed69708344df", "price_changes":[{"asset_id":"81916206347121459497221114766050949090435061493822476265356047392175668050706", "price":"0.01", "size":"1745.08", "side":"BUY", "hash":"97d37c07a001ec42143681bdd3df6cb54a83d0d4", "best_bid":"0.01", "best_ask":"0.02"}, {"asset_id":"96888240988495161476033313796107536512663280794332045579302109906525918376981", "price":"0.99", "size":"1745.08", "side":"SELL", "hash":"118b02133c93137a579d55a2beb489f70b4d3647", "best_bid":"0.98", "best_ask":"0.99"}], "timestamp":"1770241486482", "event_type":"price_change"}
{"market":"0x38f3050258345e9cf363d1c8cc302f08c65b96ba1a4669d81e07ed69708344df", "price_changes":[{"asset_id":"81916206347121459497221114766050949090435061493822476265356047392175668050706", "price":"0.01", "size":"1718.08", "side":"BUY", "hash":"3f7c05d723d857595e6e2debb51357d953b4f3bb", "best_bid":"0.01", "best_ask":"0.02"}, {"asset_id":"96888240988495161476033313796107536512663280794332045579302109906525918376981", "price":"0.99", "size":"1718.08", "side":"SELL", "hash":"b09bcdc0a0d49ace0b905a4871cfe057ca0b5566", "best_bid":"0.98", "best_ask":"0.99"}], "timestamp":"1770241486490", "event_type":"price_change"}
{"market":"0x38f3050258345e9cf363d1c8cc302f08c65b96ba1a4669d81e07ed69708344df", "price_changes":[{"asset_id":"81916206347121459497221114766050949090435061493822476265356047392175668050706", "price":"0.01", "size":"1745.08", "side":"BUY", "hash":"b3f92337dd2d98f10c9aa384ecf396c2c43a0b75", "best_bid":"0.01", "best_ask":"0.02"}, {"asset_id":"96888240988495161476033313796107536512663280794332045579302109906525918376981", "price":"0.99", "size":"1745.08", "side":"SELL", "hash":"1329ebd4ed0a4fd0b53a8b795a1230adbcd743ce", "best_bid":"0.98", "best_ask":"0.99"}], "timestamp":"1770241486490", "event_type":"price_change"}
{"market":"0x38f3050258345e9cf363d1c8cc302f08c65b96ba1a4669d81e07ed69708344df", "price_changes":[{"asset_id":"81916206347121459497221114766050949090435061493822476265356047392175668050706", "price":"0.01", "size":"1772.08", "side":"BUY", "hash":"c8d004b122a96214ed1f4798f83299641276d822", "best_bid":"0.01", "best_ask":"0.02"}, {"asset_id":"96888240988495161476033313796107536512663280794332045579302109906525918376981", "price":"0.99", "size":"1772.08", "side":"SELL", "hash":"30822c3f23b2e0df6622a70f93252a10b68f9e49", "best_bid":"0.98", "best_ask":"0.99"}], "timestamp":"1770241486495", "event_type":"price_change"}
{"market":"0x38f3050258345e9cf363d1c8cc302f08c65b96ba1a4669d81e07ed69708344df", "price_changes":[{"asset_id":"81916206347121459497221114766050949090435061493822476265356047392175668050706", "price":"0.01", "size":"1745.08", "side":"BUY", "hash":"67f8d89481e9e5ddb9ea6c85587305c190a202f2", "best_bid":"0.01", "best_ask":"0.02"}, {"asset_id":"96888240988495161476033313796107536512663280794332045579302109906525918376981", "price":"0.99", "size":"1745.08", "side":"SELL", "hash":"d3348ad5bd0033d61daa7501e2de066f9b0fae6f", "best_bid":"0.98", "best_ask":"0.99"}], "timestamp":"1770241486495", "event_type":"price_change"}
{"market":"0x38f3050258345e9cf363d1c8cc302f08c65b96ba1a4669d81e07ed69708344df", "price_changes":[{"asset_id":"96888240988495161476033313796107536512663280794332045579302109906525918376981", "price":"0.99", "size":"1754.08", "side":"SELL", "hash":"b6681d69bdd3766f2a7c82c7f3d2b1bd4242c03a", "best_bid":"0.98", "best_ask":"0.99"}, {"asset_id":"81916206347121459497221114766050949090435061493822476265356047392175668050706", "price":"0.01", "size":"1754.08", "side":"BUY", "hash":"e58dcd10b690cc921e0d56a438c47516113911a0", "best_bid":"0.01", "best_ask":"0.02"}], "timestamp":"1770241486557", "event_type":"price_change"}
{"market":"0x38f3050258345e9cf363d1c8cc302f08c65b96ba1a4669d81e07ed69708344df", "price_changes":[{"asset_id":"81916206347121459497221114766050949090435061493822476265356047392175668050706", "price":"0.01", "size":"1727.08", "side":"BUY", "hash":"abe41a6af64e44ae16f351c4c8d5584954e2b3e1", "best_bid":"0.01", "best_ask":"0.02"}, {"asset_id":"96888240988495161476033313796107536512663280794332045579302109906525918376981", "price":"0.99", "size":"1727.08", "side":"SELL", "hash":"4a716f5668f5906dba7183b8a04b9359ac477296", "best_bid":"0.98", "best_ask":"0.99"}], "timestamp":"1770241486693", "event_type":"price_change"}
{"market":"0x38f3050258345e9cf363d1c8cc302f08c65b96ba1a4669d81e07ed69708344df", "price_changes":[{"asset_id":"81916206347121459497221114766050949090435061493822476265356047392175668050706", "price":"0.01", "size":"1754.08", "side":"BUY", "hash":"3247b98ef91d429b32df9e7d2c816bc19d1f1115", "best_bid":"0.01", "best_ask":"0.02"}, {"asset_id":"96888240988495161476033313796107536512663280794332045579302109906525918376981", "price":"0.99", "size":"1754.08", "side":"SELL", "hash":"e685825f59ca62ee7d41305bd540bf4ff570bc48", "best_bid":"0.98", "best_ask":"0.99"}], "timestamp":"1770241486695", "event_type":"price_change"}
{"market":"0x38f3050258345e9cf363d1c8cc302f08c65b96ba1a4669d81e07ed69708344df", "price_changes":[{"asset_id":"81916206347121459497221114766050949090435061493822476265356047392175668050706", "price":"0.01", "size":"1781.08", "side":"BUY", "hash":"4b41c68c8df5c91468c5cecf3f805749e34bc130", "best_bid":"0.01", "best_ask":"0.02"}, {"asset_id":"96888240988495161476033313796107536512663280794332045579302109906525918376981", "price":"0.99", "size":"1781.08", "side":"SELL", "hash":"9ec71ccdd896633e3a81884f4f11ad9b81ab6f8e", "best_bid":"0.98", "best_ask":"0.99"}], "timestamp":"1770241486704", "event_type":"price_change"}
{"market":"0x38f3050258345e9cf363d1c8cc302f08c65b96ba1a4669d81e07ed69708344df", "price_changes":[{"asset_id":"81916206347121459497221114766050949090435061493822476265356047392175668050706", "price":"0.01", "size":"1754.08", "side":"BUY", "hash":"ae6a05c93f4d2884987850dc395269360b8bcaef", "best_bid":"0.01", "best_ask":"0.02"}, {"asset_id":"96888240988495161476033313796107536512663280794332045579302109906525918376981", "price":"0.99", "size":"1754.08", "side":"SELL", "hash":"9d171539f4d61d439ddebb43ae896cefe930d513", "best_bid":"0.98", "best_ask":"0.99"}], "timestamp":"1770241486706", "event_type":"price_change"}
{"market":"0x38f3050258345e9cf363d1c8cc302f08c65b96ba1a4669d81e07ed69708344df", "price_changes":[{"asset_id":"81916206347121459497221114766050949090435061493822476265356047392175668050706", "price":"0.01", "size":"1781.08", "side":"BUY", "hash":"a4eb5a89a2edaba4265637c6f791e295cdc1cb34", "best_bid":"0.01", "best_ask":"0.02"}, {"asset_id":"96888240988495161476033313796107536512663280794332045579302109906525918376981", "price":"0.99", "size":"1781.08", "side":"SELL", "hash":"12a678e7cf5517bdb9e1b2263704e2a7252ad00c", "best_bid":"0.98", "best_ask":"0.99"}], "timestamp":"1770241486716", "event_type":"price_change"}
{"market":"0x38f3050258345e9cf363d1c8cc302f08c65b96ba1a4669d81e07ed69708344df", "price_changes":[{"asset_id":"81916206347121459497221114766050949090435061493822476265356047392175668050706", "price":"0.01", "size":"1754.08", "side":"BUY", "hash":"480f75e4af9c0c27819739d612bcf0f516d06307", "best_bid":"0.01", "best_ask":"0.02"}, {"asset_id":"96888240988495161476033313796107536512663280794332045579302109906525918376981", "price":"0.99", "size":"1754.08", "side":"SELL", "hash":"60c4e1e9904a38b89ebd33a8dd37e10cab10d564", "best_bid":"0.98", "best_ask":"0.99"}], "timestamp":"1770241486724", "event_type":"price_change"}
{"market":"0x38f3050258345e9cf363d1c8cc302f08c65b96ba1a4669d81e07ed69708344df", "price_changes":[{"asset_id":"96888240988495161476033313796107536512663280794332045579302109906525918376981", "price":"0.99", "size":"1745.08", "side":"SELL", "hash":"a6ff2a0b375ae31880d3ba6de5dd7e171a76c888", "best_bid":"0.98", "best_ask":"0.99"}, {"asset_id":"81916206347121459497221114766050949090435061493822476265356047392175668050706", "price":"0.01", "size":"1745.08", "side":"BUY", "hash":"553eed5a5ce19f8d703a0460ab5fe8247c786feb", "best_bid":"0.01", "best_ask":"0.02"}], "timestamp":"1770241486769", "event_type":"price_change"}
{"market":"0x38f3050258345e9cf363d1c8cc302f08c65b96ba1a4669d81e07ed69708344df", "price_changes":[{"asset_id":"96888240988495161476033313796107536512663280794332045579302109906525918376981", "price":"0.96", "size":"623.73", "side":"BUY", "hash":"5ba8f9a94e975b4a7a79828b5f2b062d1fb49dd6", "best_bid":"0.98", "best_ask":"0.99"}, {"asset_id":"81916206347121459497221114766050949090435061493822476265356047392175668050706", "price":"0.04", "size":"623.73", "side":"SELL", "hash":"05c4197a0086fb21ac4dc25e9dec2c30884f5604", "best_bid":"0.01", "best_ask":"0.02"}], "timestamp":"1770241486806", "event_type":"price_change"}
{"market":"0x38f3050258345e9cf363d1c8cc302f08c65b96ba1a4669d81e07ed69708344df", "price_changes":[{"asset_id":"81916206347121459497221114766050949090435061493822476265356047392175668050706", "price":"0.01", "size":"1718.08", "side":"BUY", "hash":"60a9c6feb90903714f392c8d7f744e432c0925e9", "best_bid":"0.01", "best_ask":"0.02"}, {"asset_id":"96888240988495161476033313796107536512663280794332045579302109906525918376981", "price":"0.99", "size":"1718.08", "side":"SELL", "hash":"c399b5e74c6d77582f5ce78eeb376bb77d59221f", "best_bid":"0.98", "best_ask":"0.99"}], "timestamp":"1770241486826", "event_type":"price_change"}
{"market":"0x38f3050258345e9cf363d1c8cc302f08c65b96ba1a4669d81e07ed69708344df", "price_changes":[{"asset_id":"81916206347121459497221114766050949090435061493822476265356047392175668050706", "price":"0.01", "size":"1691.08", "side":"BUY", "hash":"4cc6ca30722181cc4a4b6fab0f5c67d962b40e94", "best_bid":"0.01", "best_ask":"0.02"}, {"asset_id":"96888240988495161476033313796107536512663280794332045579302109906525918376981", "price":"0.99", "size":"1691.08", "side":"SELL", "hash":"71fbfb2fd668a0113120f05b96b42608ae9b9f8b", "best_bid":"0.98", "best_ask":"0.99"}], "timestamp":"1770241486826", "event_type":"price_change"}
{"market":"0x38f3050258345e9cf363d1c8cc302f08c65b96ba1a4669d81e07ed69708344df", "price_changes":[{"asset_id":"81916206347121459497221114766050949090435061493822476265356047392175668050706", "price":"0.01", "size":"1718.08", "side":"BUY", "hash":"d52ce5ecaa5294892609366d346881e30190f4b3", "best_bid":"0.01", "best_ask":"0.02"}, {"asset_id":"96888240988495161476033313796107536512663280794332045579302109906525918376981", "price":"0.99", "size":"1718.08", "side":"SELL", "hash":"6fa013f418d3a0d8137bf73692478cddcccd6dc8", "best_bid":"0.98", "best_ask":"0.99"}], "timestamp":"1770241486828", "event_type":"price_change"}
{"market":"0x38f3050258345e9cf363d1c8cc302f08c65b96ba1a4669d81e07ed69708344df", "price_changes":[{"asset_id":"81916206347121459497221114766050949090435061493822476265356047392175668050706", "price":"0.01", "size":"1745.08", "side":"BUY", "hash":"20ddb43ba59c9ebdb12c7d61231100c408e46eda", "best_bid":"0.01", "best_ask":"0.02"}, {"asset_id":"96888240988495161476033313796107536512663280794332045579302109906525918376981", "price":"0.99", "size":"1745.08", "side":"SELL", "hash":"274d4be133e355d730c148dfbdea4ab875d54e12", "best_bid":"0.98", "best_ask":"0.99"}], "timestamp":"1770241486829", "event_type":"price_change"}
{"market":"0x38f3050258345e9cf363d1c8cc302f08c65b96ba1a4669d81e07ed69708344df", "price_changes":[{"asset_id":"81916206347121459497221114766050949090435061493822476265356047392175668050706", "price":"0.01", "size":"1718.08", "side":"BUY", "hash":"b8b9291e57cd43f796ecf1d377fc057f744147b9", "best_bid":"0.01", "best_ask":"0.02"}, {"asset_id":"96888240988495161476033313796107536512663280794332045579302109906525918376981", "price":"0.99", "size":"1718.08", "side":"SELL", "hash":"c37d4a5777e463dfd30d823f36b49b8c82d4aebc", "best_bid":"0.98", "best_ask":"0.99"}], "timestamp":"1770241486849", "event_type":"price_change"}
{"market":"0x38f3050258345e9cf363d1c8cc302f08c65b96ba1a4669d81e07ed69708344df", "price_changes":[{"asset_id":"81916206347121459497221114766050949090435061493822476265356047392175668050706", "price":"0.01", "size":"1745.08", "side":"BUY", "hash":"85b87e2b73e82092bb2f14a1e6ff3aecfddec949", "best_bid":"0.01", "best_ask":"0.02"}, {"asset_id":"96888240988495161476033313796107536512663280794332045579302109906525918376981", "price":"0.99", "size":"1745.08", "side":"SELL", "hash":"d930d61a4edec07d7f5590f280379115d334089a", "best_bid":"0.98", "best_ask":"0.99"}], "timestamp":"1770241486849", "event_type":"price_change"}
{"market":"0x38f3050258345e9cf363d1c8cc302f08c65b96ba1a4669d81e07ed69708344df", "price_changes":[{"asset_id":"96888240988495161476033313796107536512663280794332045579302109906525918376981", "price":"0.99", "size":"1754.08", "side":"SELL", "hash":"bf8d2e58a7c644003ef9725312873d7e83b0d209", "best_bid":"0.98", "best_ask":"0.99"}, {"asset_id":"81916206347121459497221114766050949090435061493822476265356047392175668050706", "price":"0.01", "size":"1754.08", "side":"BUY", "hash":"755e195e0f21bf096599cced8ac705e56b6a391a", "best_bid":"0.01", "best_ask":"0.02"}], "timestamp":"1770241486916", "event_type":"price_change"}
{"market":"0x38f3050258345e9cf363d1c8cc302f08c65b96ba1a4669d81e07ed69708344df", "price_changes":[{"asset_id":"81916206347121459497221114766050949090435061493822476265356047392175668050706", "price":"0.01", "size":"1727.08", "side":"BUY", "hash":"a46dd752c663631e777402cd905d9a08794c1ecb", "best_bid":"0.01", "best_ask":"0.02"}, {"asset_id":"96888240988495161476033313796107536512663280794332045579302109906525918376981", "price":"0.99", "size":"1727.08", "side":"SELL", "hash":"829c2e7593d41390fedec02e11d310be0495193d", "best_bid":"0.98", "best_ask":"0.99"}], "timestamp":"1770241486946", "event_type":"price_change"}
{"market":"0x38f3050258345e9cf363d1c8cc302f08c65b96ba1a4669d81e07ed69708344df", "price_changes":[{"asset_id":"81916206347121459497221114766050949090435061493822476265356047392175668050706", "price":"0.01", "size":"1754.08", "side":"BUY", "hash":"73ff6aea1bc9995268d96651462e24033bfebd0f", "best_bid":"0.01", "best_ask":"0.02"}, {"asset_id":"96888240988495161476033313796107536512663280794332045579302109906525918376981", "price":"0.99", "size":"1754.08", "side":"SELL", "hash":"bc2b8665fd19ed890d57b28c6fb0e0e14196652c", "best_bid":"0.98", "best_ask":"0.99"}], "timestamp":"1770241486947", "event_type":"price_change"}
{"market":"0x38f3050258345e9cf363d1c8cc302f08c65b96ba1a4669d81e07ed69708344df", "price_changes":[{"asset_id":"81916206347121459497221114766050949090435061493822476265356047392175668050706", "price":"0.01", "size":"1727.08", "side":"BUY", "hash":"3aec84db412a4c7505d4bb1ab72007e42ade5dcc", "best_bid":"0.01", "best_ask":"0.02"}, {"asset_id":"96888240988495161476033313796107536512663280794332045579302109906525918376981", "price":"0.99", "size":"1727.08", "side":"SELL", "hash":"297b886b006baf29a8bd20fc891699095febb5f0", "best_bid":"0.98", "best_ask":"0.99"}], "timestamp":"1770241486947", "event_type":"price_change"}
{"market":"0x38f3050258345e9cf363d1c8cc302f08c65b96ba1a4669d81e07ed69708344df", "price_changes":[{"asset_id":"81916206347121459497221114766050949090435061493822476265356047392175668050706", "price":"0.01", "size":"1754.08", "side":"BUY", "hash":"b1c56543123efbf69da601737b0f0f33d2c3487e", "best_bid":"0.01", "best_ask":"0.02"}, {"asset_id":"96888240988495161476033313796107536512663280794332045579302109906525918376981", "price":"0.99", "size":"1754.08", "side":"SELL", "hash":"e1246dd2a45877c9a7286299aeac5cc425a83598", "best_bid":"0.98", "best_ask":"0.99"}], "timestamp":"1770241486949", "event_type":"price_change"}
{"market":"0x38f3050258345e9cf363d1c8cc302f08c65b96ba1a4669d81e07ed69708344df", "price_changes":[{"asset_id":"81916206347121459497221114766050949090435061493822476265356047392175668050706", "price":"0.01", "size":"1727.08", "side":"BUY", "hash":"6c768f61c5283939909366c3dd4350a774b501f2", "best_bid":"0.01", "best_ask":"0.02"}, {"asset_id":"96888240988495161476033313796107536512663280794332045579302109906525918376981", "price":"0.99", "size":"1727.08", "side":"SELL", "hash":"630977fb850bc13b6b0ed293acd0b529b8a2513b", "best_bid":"0.98", "best_ask":"0.99"}], "timestamp":"1770241486969", "event_type":"price_change"}
{"market":"0x38f3050258345e9cf363d1c8cc302f08c65b96ba1a4669d81e07ed69708344df", "price_changes":[{"asset_id":"81916206347121459497221114766050949090435061493822476265356047392175668050706", "price":"0.01", "size":"1754.08", "side":"BUY", "hash":"d8c1c0452bd13050e034c33ea341b133aef35a7a", "best_bid":"0.01", "best_ask":"0.02"}, {"asset_id":"96888240988495161476033313796107536512663280794332045579302109906525918376981", "price":"0.99", "size":"1754.08", "side":"SELL", "hash":"07c63509d1f2d618c8b435430aa8dbca8478adf3", "best_bid":"0.98", "best_ask":"0.99"}], "timestamp":"1770241486969", "event_type":"price_change"}
{"market":"0x38f3050258345e9cf363d1c8cc302f08c65b96ba1a4669d81e07ed69708344df", "price_changes":[{"asset_id":"81916206347121459497221114766050949090435061493822476265356047392175668050706", "price":"0.01", "size":"1727.08", "side":"BUY", "hash":"5268802cdf8de02f5a61173f305b8a6fc1b15a77", "best_bid":"0.01", "best_ask":"0.02"}, {"asset_id":"96888240988495161476033313796107536512663280794332045579302109906525918376981", "price":"0.99", "size":"1727.08", "side":"SELL", "hash":"f037c7de9d4f5616a5c9f0c211ceded75b30062a", "best_bid":"0.98", "best_ask":"0.99"}], "timestamp":"1770241487066", "event_type":"price_change"}
{"market":"0x38f3050258345e9cf363d1c8cc302f08c65b96ba1a4669d81e07ed69708344df", "price_changes":[{"asset_id":"81916206347121459497221114766050949090435061493822476265356047392175668050706", "price":"0.01", "size":"1754.08", "side":"BUY", "hash":"574b87119233e6ff765c5f4f51f5655ebc810bde", "best_bid":"0.01", "best_ask":"0.02"}, {"asset_id":"96888240988495161476033313796107536512663280794332045579302109906525918376981", "price":"0.99", "size":"1754.08", "side":"SELL", "hash":"aff07e8088384c6c8d9cac302332dee0e1ed57bf", "best_bid":"0.98", "best_ask":"0.99"}], "timestamp":"1770241487067", "event_type":"price_change"}
{"market":"0x38f3050258345e9cf363d1c8cc302f08c65b96ba1a4669d81e07ed69708344df", "price_changes":[{"asset_id":"81916206347121459497221114766050949090435061493822476265356047392175668050706", "price":"0.01", "size":"1727.08", "side":"BUY", "hash":"a0e5c53746cfd9bcf87695d081cf527f251c5912", "best_bid":"0.01", "best_ask":"0.02"}, {"asset_id":"96888240988495161476033313796107536512663280794332045579302109906525918376981", "price":"0.99", "size":"1727.08", "side":"SELL", "hash":"2aca2585935122e75206eca488c4a0ef15c5fca8", "best_bid":"0.98", "best_ask":"0.99"}], "timestamp":"1770241487086", "event_type":"price_change"}
{"market":"0x38f3050258345e9cf363d1c8cc302f08c65b96ba1a4669d81e07ed69708344df", "price_changes":[{"asset_id":"81916206347121459497221114766050949090435061493822476265356047392175668050706", "price":"0.01", "size":"1754.08", "side":"BUY", "hash":"50d3f422d3f464139c6729893cf26104191d57dc", "best_bid":"0.01", "best_ask":"0.02"}, {"asset_id":"96888240988495161476033313796107536512663280794332045579302109906525918376981", "price":"0.99", "size":"1754.08", "side":"SELL", "hash":"ae7839d73bbb254176c97cee989375d6c8148f59", "best_bid":"0.98", "best_ask":"0.99"}], "timestamp":"1770241487088", "event_type":"price_change"}
{"market":"0x38f3050258345e9cf363d1c8cc302f08c65b96ba1a4669d81e07ed69708344df", "price_changes":[{"asset_id":"81916206347121459497221114766050949090435061493822476265356047392175668050706", "price":"0.01", "size":"1727.08", "side":"BUY", "hash":"59ad17215152b60406bd4f19ec06a00876590c55", "best_bid":"0.01", "best_ask":"0.02"}, {"asset_id":"96888240988495161476033313796107536512663280794332045579302109906525918376981", "price":"0.99", "size":"1727.08", "side":"SELL", "hash":"af74ac2829bab02a914337035f9696c35c529be4", "best_bid":"0.98", "best_ask":"0.99"}], "timestamp":"1770241487089", "event_type":"price_change"}
{"market":"0x38f3050258345e9cf363d1c8cc302f08c65b96ba1a4669d81e07ed69708344df", "price_changes":[{"asset_id":"81916206347121459497221114766050949090435061493822476265356047392175668050706", "price":"0.01", "size":"1754.08", "side":"BUY", "hash":"01f7d54d93f0f7c04d5be0bf3f401e1c4c3a7278", "best_bid":"0.01", "best_ask":"0.02"}, {"asset_id":"96888240988495161476033313796107536512663280794332045579302109906525918376981", "price":"0.99", "size":"1754.08", "side":"SELL", "hash":"7d3cacfb6d68c2819986d8781c235c273a3ffd43", "best_bid":"0.98", "best_ask":"0.99"}], "timestamp":"1770241487095", "event_type":"price_change"}
{"market":"0x38f3050258345e9cf363d1c8cc302f08c65b96ba1a4669d81e07ed69708344df", "price_changes":[{"asset_id":"81916206347121459497221114766050949090435061493822476265356047392175668050706", "price":"0.01", "size":"1781.08", "side":"BUY", "hash":"c69eeba182965430c15d8181dfbf3581c87889ad", "best_bid":"0.01", "best_ask":"0.02"}, {"asset_id":"96888240988495161476033313796107536512663280794332045579302109906525918376981", "price":"0.99", "size":"1781.08", "side":"SELL", "hash":"b6d568a83869d791e1efd75d7244cac40b0d99bb", "best_bid":"0.98", "best_ask":"0.99"}], "timestamp":"1770241487186", "event_type":"price_change"}
{"market":"0x38f3050258345e9cf363d1c8cc302f08c65b96ba1a4669d81e07ed69708344df", "price_changes":[{"asset_id":"81916206347121459497221114766050949090435061493822476265356047392175668050706", "price":"0.01", "size":"1754.08", "side":"BUY", "hash":"c096612262eb769beabc60f557ec8f940ead8f22", "best_bid":"0.01", "best_ask":"0.02"}, {"asset_id":"96888240988495161476033313796107536512663280794332045579302109906525918376981", "price":"0.99", "size":"1754.08", "side":"SELL", "hash":"9e6972db51a9f8b677f959f9fb509b17d7d276ad", "best_bid":"0.98", "best_ask":"0.99"}], "timestamp":"1770241487189", "event_type":"price_change"}
{"market":"0x38f3050258345e9cf363d1c8cc302f08c65b96ba1a4669d81e07ed69708344df", "price_changes":[{"asset_id":"81916206347121459497221114766050949090435061493822476265356047392175668050706", "price":"0.01", "size":"1727.08", "side":"BUY", "hash":"35b2fee22f3a07579bfb82920ee2111e5e22a575", "best_bid":"0.01", "best_ask":"0.02"}, {"asset_id":"96888240988495161476033313796107536512663280794332045579302109906525918376981", "price":"0.99", "size":"1727.08", "side":"SELL", "hash":"000d978cbb0631790942719421bf299c33889c54", "best_bid":"0.98", "best_ask":"0.99"}], "timestamp":"1770241487212", "event_type":"price_change"}
{"market":"0x38f3050258345e9cf363d1c8cc302f08c65b96ba1a4669d81e07ed69708344df", "price_changes":[{"asset_id":"81916206347121459497221114766050949090435061493822476265356047392175668050706", "price":"0.01", "size":"1754.08", "side":"BUY", "hash":"7a3b6288e6b581be32915fa720ba91711e5306d8", "best_bid":"0.01", "best_ask":"0.02"}, {"asset_id":"96888240988495161476033313796107536512663280794332045579302109906525918376981", "price":"0.99", "size":"1754.08", "side":"SELL", "hash":"fec29b77465b8dbda7ec767b7b856ac52e7abd3b", "best_bid":"0.98", "best_ask":"0.99"}], "timestamp":"1770241487215", "event_type":"price_change"}
{"market":"0x38f3050258345e9cf363d1c8cc302f08c65b96ba1a4669d81e07ed69708344df", "price_changes":[{"asset_id":"81916206347121459497221114766050949090435061493822476265356047392175668050706", "price":"0.01", "size":"1727.08", "side":"BUY", "hash":"d016e5cd30f581ffd9bc3448eb53ed06198120fb", "best_bid":"0.01", "best_ask":"0.02"}, {"asset_id":"96888240988495161476033313796107536512663280794332045579302109906525918376981", "price":"0.99", "size":"1727.08", "side":"SELL", "hash":"82943782eb1e7d53954fd62580e9520a6dad1155", "best_bid":"0.98", "best_ask":"0.99"}], "timestamp":"1770241487226", "event_type":"price_change"}
{"market":"0x38f3050258345e9cf363d1c8cc302f08c65b96ba1a4669d81e07ed69708344df", "price_changes":[{"asset_id":"81916206347121459497221114766050949090435061493822476265356047392175668050706", "price":"0.01", "size":"1754.08", "side":"BUY", "hash":"58b7986dad872e79a8318b6e524a2ccba9ce1d07", "best_bid":"0.01", "best_ask":"0.02"}, {"asset_id":"96888240988495161476033313796107536512663280794332045579302109906525918376981", "price":"0.99", "size":"1754.08", "side":"SELL", "hash":"b4b53f69f7268064bb33645f943f727ea1cf792b", "best_bid":"0.98", "best_ask":"0.99"}], "timestamp":"1770241487227", "event_type":"price_change"}
{"market":"0x38f3050258345e9cf363d1c8cc302f08c65b96ba1a4669d81e07ed69708344df", "price_changes":[{"asset_id":"96888240988495161476033313796107536512663280794332045579302109906525918376981", "price":"0.99", "size":"1745.08", "side":"SELL", "hash":"06c0b5dfc86c1459125a7361355ae16224fbb450", "best_bid":"0.98", "best_ask":"0.99"}, {"asset_id":"81916206347121459497221114766050949090435061493822476265356047392175668050706", "price":"0.01", "size":"1745.08", "side":"BUY", "hash":"dd78276bdfe4cfb4f271aa3eb161628a64ef1bee", "best_bid":"0.01", "best_ask":"0.02"}], "timestamp":"1770241487279", "event_type":"price_change"}
{"market":"0x38f3050258345e9cf363d1c8cc302f08c65b96ba1a4669d81e07ed69708344df", "price_changes":[{"asset_id":"96888240988495161476033313796107536512663280794332045579302109906525918376981", "price":"0.95", "size":"658", "side":"BUY", "hash":"975cf1588284b5c8da9f751df082adc847081d05", "best_bid":"0.98", "best_ask":"0.99"}, {"asset_id":"81916206347121459497221114766050949090435061493822476265356047392175668050706", "price":"0.05", "size":"658", "side":"SELL", "hash":"b96848d2442d9cb25ccecbd9002528313a2cc484", "best_bid":"0.01", "best_ask":"0.02"}], "timestamp":"1770241487607", "event_type":"price_change"}
{"market":"0x38f3050258345e9cf363d1c8cc302f08c65b96ba1a4669d81e07ed69708344df", "price_changes":[{"asset_id":"96888240988495161476033313796107536512663280794332045579302109906525918376981", "price":"0.95", "size":"685", "side":"BUY", "hash":"878e4e90c36fd2ba029fd637144726178ba33599", "best_bid":"0.98", "best_ask":"0.99"}, {"asset_id":"81916206347121459497221114766050949090435061493822476265356047392175668050706", "price":"0.05", "size":"685", "side":"SELL", "hash":"3607566a126a5726fd7087aba3b7e50101232383", "best_bid":"0.01", "best_ask":"0.02"}], "timestamp":"1770241487609", "event_type":"price_change"}
{"market":"0x38f3050258345e9cf363d1c8cc302f08c65b96ba1a4669d81e07ed69708344df", "price_changes":[{"asset_id":"96888240988495161476033313796107536512663280794332045579302109906525918376981", "price":"0.97", "size":"541.32", "side":"BUY", "hash":"88872556ad26cc0f90343c35996518f8ebaaa005", "best_bid":"0.98", "best_ask":"0.99"}, {"asset_id":"81916206347121459497221114766050949090435061493822476265356047392175668050706", "price":"0.03", "size":"541.32", "side":"SELL", "hash":"8de75056fee750c37452e0cd04c1508c341abb54", "best_bid":"0.01", "best_ask":"0.02"}], "timestamp":"1770241487610", "event_type":"price_change"}
{"market":"0x38f3050258345e9cf363d1c8cc302f08c65b96ba1a4669d81e07ed69708344df", "price_changes":[{"asset_id":"96888240988495161476033313796107536512663280794332045579302109906525918376981", "price":"0.97", "size":"568.32", "side":"BUY", "hash":"0136c0603458207421833af423a0345d744df4f7", "best_bid":"0.98", "best_ask":"0.99"}, {"asset_id":"81916206347121459497221114766050949090435061493822476265356047392175668050706", "price":"0.03", "size":"568.32", "side":"SELL", "hash":"c0cb8e580b79a7549ca6eeefca34d29eadaf6cf1", "best_bid":"0.01", "best_ask":"0.02"}], "timestamp":"1770241487630", "event_type":"price_change"}
{"market":"0x38f3050258345e9cf363d1c8cc302f08c65b96ba1a4669d81e07ed69708344df", "price_changes":[{"asset_id":"81916206347121459497221114766050949090435061493822476265356047392175668050706", "price":"0.01", "size":"1772.08", "side":"BUY", "hash":"32ae7bf2eaff06fd22c9bd945d2fa13f241ae517", "best_bid":"0.01", "best_ask":"0.02"}, {"asset_id":"96888240988495161476033313796107536512663280794332045579302109906525918376981", "price":"0.99", "size":"1772.08", "side":"SELL", "hash":"1c110a8b0e2eaa21501217be84662b0627c0c83e", "best_bid":"0.98", "best_ask":"0.99"}], "timestamp":"1770241487636", "event_type":"price_change"}
{"market":"0x38f3050258345e9cf363d1c8cc302f08c65b96ba1a4669d81e07ed69708344df", "price_changes":[{"asset_id":"81916206347121459497221114766050949090435061493822476265356047392175668050706", "price":"0.01", "size":"1745.08", "side":"BUY", "hash":"9cecc96207b95e8d15c89a9a6ed1f678c701984d", "best_bid":"0.01", "best_ask":"0.02"}, {"asset_id":"96888240988495161476033313796107536512663280794332045579302109906525918376981", "price":"0.99", "size":"1745.08", "side":"SELL", "hash":"1c7ffbb4183cac2a8d036eac2e92874e1a30abef", "best_bid":"0.98", "best_ask":"0.99"}], "timestamp":"1770241487637", "event_type":"price_change"}
{"market":"0x38f3050258345e9cf363d1c8cc302f08c65b96ba1a4669d81e07ed69708344df", "price_changes":[{"asset_id":"81916206347121459497221114766050949090435061493822476265356047392175668050706", "price":"0.01", "size":"1718.08", "side":"BUY", "hash":"3cc95fb39bf722425c6e7557e72b8f8520e83335", "best_bid":"0.01", "best_ask":"0.02"}, {"asset_id":"96888240988495161476033313796107536512663280794332045579302109906525918376981", "price":"0.99", "size":"1718.08", "side":"SELL", "hash":"f7a91897b22d95228b2d817d4fa95b1142e644b8", "best_bid":"0.98", "best_ask":"0.99"}], "timestamp":"1770241487644", "event_type":"price_change"}
{"market":"0x38f3050258345e9cf363d1c8cc302f08c65b96ba1a4669d81e07ed69708344df", "price_changes":[{"asset_id":"81916206347121459497221114766050949090435061493822476265356047392175668050706", "price":"0.01", "size":"1745.08", "side":"BUY", "hash":"5357632fc95a1201cf7986a7ab865ca3f2209c3f", "best_bid":"0.01", "best_ask":"0.02"}, {"asset_id":"96888240988495161476033313796107536512663280794332045579302109906525918376981", "price":"0.99", "size":"1745.08", "side":"SELL", "hash":"c2cba8d4f5c780086756218fd184819d60d80291", "best_bid":"0.98", "best_ask":"0.99"}], "timestamp":"1770241487646", "event_type":"price_change"}
{"market":"0x38f3050258345e9cf363d1c8cc302f08c65b96ba1a4669d81e07ed69708344df", "price_changes":[{"asset_id":"81916206347121459497221114766050949090435061493822476265356047392175668050706", "price":"0.01", "size":"1718.08", "side":"BUY", "hash":"901bffd6deec42db9232c35219a37c5dfb14b0ac", "best_bid":"0.01", "best_ask":"0.02"}, {"asset_id":"96888240988495161476033313796107536512663280794332045579302109906525918376981", "price":"0.99", "size":"1718.08", "side":"SELL", "hash":"885d1f44118b7fcf17488dd2a79578600197bffb", "best_bid":"0.98", "best_ask":"0.99"}], "timestamp":"1770241487657", "event_type":"price_change"}
{"market":"0x38f3050258345e9cf363d1c8cc302f08c65b96ba1a4669d81e07ed69708344df", "price_changes":[{"asset_id":"81916206347121459497221114766050949090435061493822476265356047392175668050706", "price":"0.01", "size":"1745.08", "side":"BUY", "hash":"5c8a65ba62f6a702685e905890e4567bb4631541", "best_bid":"0.01", "best_ask":"0.02"}, {"asset_id":"96888240988495161476033313796107536512663280794332045579302109906525918376981", "price":"0.99", "size":"1745.08", "side":"SELL", "hash":"5de0546309fd4ce22f1f65bf5f1a4eea9bde7546", "best_bid":"0.98", "best_ask":"0.99"}], "timestamp":"1770241487663", "event_type":"price_change"}
{"market":"0x38f3050258345e9cf363d1c8cc302f08c65b96ba1a4669d81e07ed69708344df", "price_changes":[{"asset_id":"96888240988495161476033313796107536512663280794332045579302109906525918376981", "price":"0.95", "size":"658", "side":"BUY", "hash":"5e97062d5dfe991156aa7e82aa18db901905c9dd", "best_bid":"0.98", "best_ask":"0.99"}, {"asset_id":"81916206347121459497221114766050949090435061493822476265356047392175668050706", "price":"0.05", "size":"658", "side":"SELL", "hash":"90bec3532eca84670f0999b6b054737fa6339244", "best_bid":"0.01", "best_ask":"0.02"}], "timestamp":"1770241487787", "event_type":"price_change"}
{"market":"0x38f3050258345e9cf363d1c8cc302f08c65b96ba1a4669d81e07ed69708344df", "price_changes":[{"asset_id":"81916206347121459497221114766050949090435061493822476265356047392175668050706", "price":"0.01", "size":"1772.08", "side":"BUY", "hash":"a9c5991d83da2beaa51d84618baee3762969209d", "best_bid":"0.01", "best_ask":"0.02"}, {"asset_id":"96888240988495161476033313796107536512663280794332045579302109906525918376981", "price":"0.99", "size":"1772.08", "side":"SELL", "hash":"d9bceaae776247ff6d9d418bb28df9b2407db936", "best_bid":"0.98", "best_ask":"0.99"}], "timestamp":"1770241487788", "event_type":"price_change"}
{"market":"0x38f3050258345e9cf363d1c8cc302f08c65b96ba1a4669d81e07ed69708344df", "price_changes":[{"asset_id":"81916206347121459497221114766050949090435061493822476265356047392175668050706", "price":"0.01", "size":"1745.08", "side":"BUY", "hash":"f9c1c3505c670fe82adb97745c900d93cfe86e2c", "best_bid":"0.01", "best_ask":"0.02"}, {"asset_id":"96888240988495161476033313796107536512663280794332045579302109906525918376981", "price":"0.99", "size":"1745.08", "side":"SELL", "hash":"6e56685c2b31886e5b422def8de7bc3b59834114", "best_bid":"0.98", "best_ask":"0.99"}], "timestamp":"1770241487789", "event_type":"price_change"}
{"market":"0x38f3050258345e9cf363d1c8cc302f08c65b96ba1a4669d81e07ed69708344df", "price_changes":[{"asset_id":"96888240988495161476033313796107536512663280794332045579302109906525918376981", "price":"0.96", "size":"650.73", "side":"BUY", "hash":"6b102c07cdfa2c8183e8da62ea80cc20b6ea61b1", "best_bid":"0.98", "best_ask":"0.99"}, {"asset_id":"81916206347121459497221114766050949090435061493822476265356047392175668050706", "price":"0.04", "size":"650.73", "side":"SELL", "hash":"35a2995cb00ad4112d518bf7b78585dc87cf14c8", "best_bid":"0.01", "best_ask":"0.02"}], "timestamp":"1770241487789", "event_type":"price_change"}
{"market":"0x38f3050258345e9cf363d1c8cc302f08c65b96ba1a4669d81e07ed69708344df", "price_changes":[{"asset_id":"81916206347121459497221114766050949090435061493822476265356047392175668050706", "price":"0.01", "size":"1718.08", "side":"BUY", "hash":"5efa57b39e09b7dc7b84ebe25aa5d0935b4cb175", "best_bid":"0.01", "best_ask":"0.02"}, {"asset_id":"96888240988495161476033313796107536512663280794332045579302109906525918376981", "price":"0.99", "size":"1718.08", "side":"SELL", "hash":"1c3ac8c5fb333f41de6730bda5191308e7c6a8a9", "best_bid":"0.98", "best_ask":"0.99"}], "timestamp":"1770241487795", "event_type":"price_change"}
{"market":"0x38f3050258345e9cf363d1c8cc302f08c65b96ba1a4669d81e07ed69708344df", "price_changes":[{"asset_id":"96888240988495161476033313796107536512663280794332045579302109906525918376981", "price":"0.95", "size":"631", "side":"BUY", "hash":"e1b9efa0ea1462631da6abfe2491211faaad6970", "best_bid":"0.98", "best_ask":"0.99"}, {"asset_id":"81916206347121459497221114766050949090435061493822476265356047392175668050706", "price":"0.05", "size":"631", "side":"SELL", "hash":"10a51397cdb467692544940582898b4ecbff6849", "best_bid":"0.01", "best_ask":"0.02"}], "timestamp":"1770241487796", "event_type":"price_change"}
{"market":"0x38f3050258345e9cf363d1c8cc302f08c65b96ba1a4669d81e07ed69708344df", "price_changes":[{"asset_id":"96888240988495161476033313796107536512663280794332045579302109906525918376981", "price":"0.96", "size":"677.73", "side":"BUY", "hash":"427d4f28549e6ea995100e6dc4ed96910b14bb44", "best_bid":"0.98", "best_ask":"0.99"}, {"asset_id":"81916206347121459497221114766050949090435061493822476265356047392175668050706", "price":"0.04", "size":"677.73", "side":"SELL", "hash":"0fe9acc9fec5b477844bcb1885baea725e35efbe", "best_bid":"0.01", "best_ask":"0.02"}], "timestamp":"1770241487798", "event_type":"price_change"}
{"market":"0x38f3050258345e9cf363d1c8cc302f08c65b96ba1a4669d81e07ed69708344df", "price_changes":[{"asset_id":"81916206347121459497221114766050949090435061493822476265356047392175668050706", "price":"0.01", "size":"1745.08", "side":"BUY", "hash":"34c933aa0b878461429d5091e484818d46f9ecf7", "best_bid":"0.01", "best_ask":"0.02"}, {"asset_id":"96888240988495161476033313796107536512663280794332045579302109906525918376981", "price":"0.99", "size":"1745.08", "side":"SELL", "hash":"265ae1061d0c47fc142b7e952975ec71385bb63a", "best_bid":"0.98", "best_ask":"0.99"}], "timestamp":"1770241487799", "event_type":"price_change"}
{"market":"0x38f3050258345e9cf363d1c8cc302f08c65b96ba1a4669d81e07ed69708344df", "price_changes":[{"asset_id":"81916206347121459497221114766050949090435061493822476265356047392175668050706", "price":"0.01", "size":"1772.08", "side":"BUY", "hash":"1875ba34b260cb71be6bbfe6a70ef1672d4bb626", "best_bid":"0.01", "best_ask":"0.02"}, {"asset_id":"96888240988495161476033313796107536512663280794332045579302109906525918376981", "price":"0.99", "size":"1772.08", "side":"SELL", "hash":"1356593864ffd62967b20103d4d2518fd71c7d79", "best_bid":"0.98", "best_ask":"0.99"}], "timestamp":"1770241487800", "event_type":"price_change"}
{"market":"0x38f3050258345e9cf363d1c8cc302f08c65b96ba1a4669d81e07ed69708344df", "price_changes":[{"asset_id":"81916206347121459497221114766050949090435061493822476265356047392175668050706", "price":"0.01", "size":"1745.08", "side":"BUY", "hash":"db8acc9f42d45741799b82801084d86c916691f8", "best_bid":"0.01", "best_ask":"0.02"}, {"asset_id":"96888240988495161476033313796107536512663280794332045579302109906525918376981", "price":"0.99", "size":"1745.08", "side":"SELL", "hash":"483b57a04348446f464f067504b3fe5417b330f7", "best_bid":"0.98", "best_ask":"0.99"}], "timestamp":"1770241487802", "event_type":"price_change"}
{"market":"0x38f3050258345e9cf363d1c8cc302f08c65b96ba1a4669d81e07ed69708344df", "price_changes":[{"asset_id":"96888240988495161476033313796107536512663280794332045579302109906525918376981", "price":"0.97", "size":"541.32", "side":"BUY", "hash":"30f0319ef4de4ca425dca846b10d4b67374e6926", "best_bid":"0.98", "best_ask":"0.99"}, {"asset_id":"81916206347121459497221114766050949090435061493822476265356047392175668050706", "price":"0.03", "size":"541.32", "side":"SELL", "hash":"cab51b5c07b19bb5b9e8830bdeda74ae6ae25ae8", "best_bid":"0.01", "best_ask":"0.02"}], "timestamp":"1770241487805", "event_type":"price_change"}
{"market":"0x38f3050258345e9cf363d1c8cc302f08c65b96ba1a4669d81e07ed69708344df", "price_changes":[{"asset_id":"96888240988495161476033313796107536512663280794332045579302109906525918376981", "price":"0.98", "size":"708.8", "side":"BUY", "hash":"f6566c3d1c3536b8cb41468393934b742a44f2fc", "best_bid":"0.98", "best_ask":"0.99"}, {"asset_id":"81916206347121459497221114766050949090435061493822476265356047392175668050706", "price":"0.02", "size":"708.8", "side":"SELL", "hash":"4a75eb2adbb6ca985aef22bc744da32327112092", "best_bid":"0.01", "best_ask":"0.02"}], "timestamp":"1770241487808", "event_type":"price_change"}
{"market":"0x38f3050258345e9cf363d1c8cc302f08c65b96ba1a4669d81e07ed69708344df", "price_changes":[{"asset_id":"81916206347121459497221114766050949090435061493822476265356047392175668050706", "price":"0.01", "size":"1718.08", "side":"BUY", "hash":"74a7ac8840c4da96397fb606a71f9d355043718a", "best_bid":"0.01", "best_ask":"0.02"}, {"asset_id":"96888240988495161476033313796107536512663280794332045579302109906525918376981", "price":"0.99", "size":"1718.08", "side":"SELL", "hash":"a3473ecbbde9cd5f73019ed8a255b4872eab9d70", "best_bid":"0.98", "best_ask":"0.99"}], "timestamp":"1770241487825", "event_type":"price_change"}
{"market":"0x38f3050258345e9cf363d1c8cc302f08c65b96ba1a4669d81e07ed69708344df", "price_changes":[{"asset_id":"81916206347121459497221114766050949090435061493822476265356047392175668050706", "price":"0.01", "size":"1695.08", "side":"BUY", "hash":"e7db79bd6ce62b05fd00bff69cd290c5fdf7a966", "best_bid":"0.01", "best_ask":"0.02"}, {"asset_id":"96888240988495161476033313796107536512663280794332045579302109906525918376981", "price":"0.99", "size":"1695.08", "side":"SELL", "hash":"3d5f54198a27a59fe58118e7b54862c00a25769b", "best_bid":"0.98", "best_ask":"0.99"}], "timestamp":"1770241487826", "event_type":"price_change"}
{"market":"0x38f3050258345e9cf363d1c8cc302f08c65b96ba1a4669d81e07ed69708344df", "price_changes":[{"asset_id":"81916206347121459497221114766050949090435061493822476265356047392175668050706", "price":"0.01", "size":"1668.08", "side":"BUY", "hash":"61f5150e2ffc6f980988ea7f1073c54d14e379bc", "best_bid":"0.01", "best_ask":"0.02"}, {"asset_id":"96888240988495161476033313796107536512663280794332045579302109906525918376981", "price":"0.99", "size":"1668.08", "side":"SELL", "hash":"663daa6130d7d56d9b0edc07da23f9d56b3ddbee", "best_bid":"0.98", "best_ask":"0.99"}], "timestamp":"1770241487834", "event_type":"price_change"}
{"market":"0x38f3050258345e9cf363d1c8cc302f08c65b96ba1a4669d81e07ed69708344df", "price_changes":[{"asset_id":"81916206347121459497221114766050949090435061493822476265356047392175668050706", "price":"0.01", "size":"1641.08", "side":"BUY", "hash":"5778296a45375995e6dc9a681aae480466088ce5", "best_bid":"0.01", "best_ask":"0.02"}, {"asset_id":"96888240988495161476033313796107536512663280794332045579302109906525918376981", "price":"0.99", "size":"1641.08", "side":"SELL", "hash":"b8b0a9efc1cacd02277f0b447c13b034ea6c1528", "best_bid":"0.98", "best_ask":"0.99"}], "timestamp":"1770241487843", "event_type":"price_change"}
{"market":"0x38f3050258345e9cf363d1c8cc302f08c65b96ba1a4669d81e07ed69708344df", "price_changes":[{"asset_id":"96888240988495161476033313796107536512663280794332045579302109906525918376981", "price":"0.96", "size":"657.73", "side":"BUY", "hash":"0da406598066128ae5903570eb74e8a3934aedb1", "best_bid":"0.98", "best_ask":"0.99"}, {"asset_id":"81916206347121459497221114766050949090435061493822476265356047392175668050706", "price":"0.04", "size":"657.73", "side":"SELL", "hash":"e5318dfd47827d0bb729a6d755d9c49ba92019b2", "best_bid":"0.01", "best_ask":"0.02"}], "timestamp":"1770241487880", "event_type":"price_change"}
{"market":"0x38f3050258345e9cf363d1c8cc302f08c65b96ba1a4669d81e07ed69708344df", "price_changes":[{"asset_id":"96888240988495161476033313796107536512663280794332045579302109906525918376981", "price":"0.96", "size":"630.73", "side":"BUY", "hash":"ea3f4c460373979b7fe62146aed5d24bc1d4b50c", "best_bid":"0.98", "best_ask":"0.99"}, {"asset_id":"81916206347121459497221114766050949090435061493822476265356047392175668050706", "price":"0.04", "size":"630.73", "side":"SELL", "hash":"4f2f4bb77e12ca24af9a698b15c2640b58f1f26f", "best_bid":"0.01", "best_ask":"0.02"}], "timestamp":"1770241487910", "event_type":"price_change"}
{"market":"0x38f3050258345e9cf363d1c8cc302f08c65b96ba1a4669d81e07ed69708344df", "price_changes":[{"asset_id":"96888240988495161476033313796107536512663280794332045579302109906525918376981", "price":"0.95", "size":"658", "side":"BUY", "hash":"16d9a188eaa3e03be5500b77ff7bb84cf607e492", "best_bid":"0.98", "best_ask":"0.99"}, {"asset_id":"81916206347121459497221114766050949090435061493822476265356047392175668050706", "price":"0.05", "size":"658", "side":"SELL", "hash":"40165b1147828cb58a418b983308e4ac711d558a", "best_bid":"0.01", "best_ask":"0.02"}], "timestamp":"1770241487912", "event_type":"price_change"}
{"market":"0x38f3050258345e9cf363d1c8cc302f08c65b96ba1a4669d81e07ed69708344df", "price_changes":[{"asset_id":"96888240988495161476033313796107536512663280794332045579302109906525918376981", "price":"0.96", "size":"603.73", "side":"BUY", "hash":"8f6665b14a52de85539a0c51c5b955ee8e5abcc4", "best_bid":"0.98", "best_ask":"0.99"}, {"asset_id":"81916206347121459497221114766050949090435061493822476265356047392175668050706", "price":"0.04", "size":"603.73", "side":"SELL", "hash":"868d735c1404c836f8be33947de5436bdd5414db", "best_bid":"0.01", "best_ask":"0.02"}], "timestamp":"1770241487918", "event_type":"price_change"}
{"market":"0x38f3050258345e9cf363d1c8cc302f08c65b96ba1a4669d81e07ed69708344df", "price_changes":[{"asset_id":"96888240988495161476033313796107536512663280794332045579302109906525918376981", "price":"0.95", "size":"685", "side":"BUY", "hash":"a12d55596973021a8b843bab1d3d070787dd01cd", "best_bid":"0.98", "best_ask":"0.99"}, {"asset_id":"81916206347121459497221114766050949090435061493822476265356047392175668050706", "price":"0.05", "size":"685", "side":"SELL", "hash":"f0892dce76e6b6c8fc2326126d0fe835608d7521", "best_bid":"0.01", "best_ask":"0.02"}], "timestamp":"1770241487920", "event_type":"price_change"}
{"market":"0x38f3050258345e9cf363d1c8cc302f08c65b96ba1a4669d81e07ed69708344df", "price_changes":[{"asset_id":"96888240988495161476033313796107536512663280794332045579302109906525918376981", "price":"0.97", "size":"568.32", "side":"BUY", "hash":"c6bcddd91368375e98690168a8411d61f70ac4c2", "best_bid":"0.98", "best_ask":"0.99"}, {"asset_id":"81916206347121459497221114766050949090435061493822476265356047392175668050706", "price":"0.03", "size":"568.32", "side":"SELL", "hash":"3b4706eda10dd1e4633ecf148fff58017085ee4e", "best_bid":"0.01", "best_ask":"0.02"}], "timestamp":"1770241487928", "event_type":"price_change"}
{"market":"0x38f3050258345e9cf363d1c8cc302f08c65b96ba1a4669d81e07ed69708344df", "price_changes":[{"asset_id":"96888240988495161476033313796107536512663280794332045579302109906525918376981", "price":"0.98", "size":"681.8", "side":"BUY", "hash":"785070fe0f80a7c333004685f75db6393c25aad5", "best_bid":"0.98", "best_ask":"0.99"}, {"asset_id":"81916206347121459497221114766050949090435061493822476265356047392175668050706", "price":"0.02", "size":"681.8", "side":"SELL", "hash":"57d828c92bfdc74d5e9066b14bc07780d4891d6e", "best_bid":"0.01", "best_ask":"0.02"}], "timestamp":"1770241487928", "event_type":"price_change"}
{"market":"0x38f3050258345e9cf363d1c8cc302f08c65b96ba1a4669d81e07ed69708344df", "price_changes":[{"asset_id":"96888240988495161476033313796107536512663280794332045579302109906525918376981", "price":"0.63", "size":"12", "side":"BUY", "hash":"9e70426f5cd023ceeca21a8971e96ee81952be45", "best_bid":"0.98", "best_ask":"0.99"}, {"asset_id":"81916206347121459497221114766050949090435061493822476265356047392175668050706", "price":"0.37", "size":"12", "side":"SELL", "hash":"e2f1565723cdaa51602104a7f2ade0902b0f5401", "best_bid":"0.01", "best_ask":"0.02"}], "timestamp":"1770241487957", "event_type":"price_change"}
{"market":"0x38f3050258345e9cf363d1c8cc302f08c65b96ba1a4669d81e07ed69708344df", "price_changes":[{"asset_id":"96888240988495161476033313796107536512663280794332045579302109906525918376981", "price":"0.62", "size":"114.5", "side":"BUY", "hash":"6a28ec77c17e872182f6daef95aff1280f4f007a", "best_bid":"0.98", "best_ask":"0.99"}, {"asset_id":"81916206347121459497221114766050949090435061493822476265356047392175668050706", "price":"0.38", "size":"114.5", "side":"SELL", "hash":"0085a54e538da3c3653572aeaa26a99ba9dc32cd", "best_bid":"0.01", "best_ask":"0.02"}], "timestamp":"1770241488122", "event_type":"price_change"}
{"market":"0x38f3050258345e9cf363d1c8cc302f08c65b96ba1a4669d81e07ed69708344df", "price_changes":[{"asset_id":"96888240988495161476033313796107536512663280794332045579302109906525918376981", "price":"0.95", "size":"712", "side":"BUY", "hash":"55c070f620cd9c276be50a19c00ec70e7ba8b8ac", "best_bid":"0.98", "best_ask":"0.99"}, {"asset_id":"81916206347121459497221114766050949090435061493822476265356047392175668050706", "price":"0.05", "size":"712", "side":"SELL", "hash":"36b69107178cdd977416958aa972f77abe90d59a", "best_bid":"0.01", "best_ask":"0.02"}], "timestamp":"1770241488320", "event_type":"price_change"}
{"market":"0x38f3050258345e9cf363d1c8cc302f08c65b96ba1a4669d81e07ed69708344df", "price_changes":[{"asset_id":"96888240988495161476033313796107536512663280794332045579302109906525918376981", "price":"0.95", "size":"685", "side":"BUY", "hash":"cfd3ac93fdbc73e76ecc98204331ea4edd779481", "best_bid":"0.98", "best_ask":"0.99"}, {"asset_id":"81916206347121459497221114766050949090435061493822476265356047392175668050706", "price":"0.05", "size":"685", "side":"SELL", "hash":"6fb0372b11972ad332438e4b9dde4c7a6efa8570", "best_bid":"0.01", "best_ask":"0.02"}], "timestamp":"1770241488322", "event_type":"price_change"}
{"market":"0x38f3050258345e9cf363d1c8cc302f08c65b96ba1a4669d81e07ed69708344df", "price_changes":[{"asset_id":"96888240988495161476033313796107536512663280794332045579302109906525918376981", "price":"0.96", "size":"630.73", "side":"BUY", "hash":"d1e2e38a268697c78d2c68a8efc99e3907761d9e", "best_bid":"0.98", "best_ask":"0.99"}, {"asset_id":"81916206347121459497221114766050949090435061493822476265356047392175668050706", "price":"0.04", "size":"630.73", "side":"SELL", "hash":"464f58bfe3e4fe5e227fbfe048565dec569e19bd", "best_bid":"0.01", "best_ask":"0.02"}], "timestamp":"1770241488327", "event_type":"price_change"}
{"market":"0x38f3050258345e9cf363d1c8cc302f08c65b96ba1a4669d81e07ed69708344df", "price_changes":[{"asset_id":"96888240988495161476033313796107536512663280794332045579302109906525918376981", "price":"0.95", "size":"658", "side":"BUY", "hash":"4fff4707bbdaa701b229058b392c70ea8a39e1f4", "best_bid":"0.98", "best_ask":"0.99"}, {"asset_id":"81916206347121459497221114766050949090435061493822476265356047392175668050706", "price":"0.05", "size":"658", "side":"SELL", "hash":"ac8edfd679440d38026ccd858aa298b1236c6e1d", "best_bid":"0.01", "best_ask":"0.02"}], "timestamp":"1770241488335", "event_type":"price_change"}
{"market":"0x38f3050258345e9cf363d1c8cc302f08c65b96ba1a4669d81e07ed69708344df", "price_changes":[{"asset_id":"96888240988495161476033313796107536512663280794332045579302109906525918376981", "price":"0.97", "size":"595.32", "side":"BUY", "hash":"a25e5afe53a3a257f099af8effa3690fbad0ad65", "best_bid":"0.98", "best_ask":"0.99"}, {"asset_id":"81916206347121459497221114766050949090435061493822476265356047392175668050706", "price":"0.03", "size":"595.32", "side":"SELL", "hash":"d43dead76c21f6170f89c55795e5bafd24f205f6", "best_bid":"0.01", "best_ask":"0.02"}], "timestamp":"1770241488341", "event_type":"price_change"}
{"market":"0x38f3050258345e9cf363d1c8cc302f08c65b96ba1a4669d81e07ed69708344df", "price_changes":[{"asset_id":"96888240988495161476033313796107536512663280794332045579302109906525918376981", "price":"0.97", "size":"568.32", "side":"BUY", "hash":"d0bf78116c393880c90a9e90297a970267f2583d", "best_bid":"0.98", "best_ask":"0.99"}, {"asset_id":"81916206347121459497221114766050949090435061493822476265356047392175668050706", "price":"0.03", "size":"568.32", "side":"SELL", "hash":"9fd09a8d8cd10c88e1c2b6ba6b8e61870104510d", "best_bid":"0.01", "best_ask":"0.02"}], "timestamp":"1770241488342", "event_type":"price_change"}
{"market":"0x38f3050258345e9cf363d1c8cc302f08c65b96ba1a4669d81e07ed69708344df", "price_changes":[{"asset_id":"96888240988495161476033313796107536512663280794332045579302109906525918376981", "price":"0.98", "size":"701.8", "side":"BUY", "hash":"9c8504b3ed6c463852291cb3f4868c856bbd19bc", "best_bid":"0.98", "best_ask":"0.99"}, {"asset_id":"81916206347121459497221114766050949090435061493822476265356047392175668050706", "price":"0.02", "size":"701.8", "side":"SELL", "hash":"570227ed4efa24792009dc8bc08aaff35c4bd477", "best_bid":"0.01", "best_ask":"0.02"}], "timestamp":"1770241488363", "event_type":"price_change"}
{"market":"0x38f3050258345e9cf363d1c8cc302f08c65b96ba1a4669d81e07ed69708344df", "price_changes":[{"asset_id":"96888240988495161476033313796107536512663280794332045579302109906525918376981", "price":"0.96", "size":"603.73", "side":"BUY", "hash":"093efdc47baf6a7cff7146b80bf8ecf311eb5bae", "best_bid":"0.98", "best_ask":"0.99"}, {"asset_id":"81916206347121459497221114766050949090435061493822476265356047392175668050706", "price":"0.04", "size":"603.73", "side":"SELL", "hash":"25a98fdb96bed3e663bcbc337cbf24e404f02be0", "best_bid":"0.01", "best_ask":"0.02"}], "timestamp":"1770241488445", "event_type":"price_change"}
{"market":"0x38f3050258345e9cf363d1c8cc302f08c65b96ba1a4669d81e07ed69708344df", "price_changes":[{"asset_id":"96888240988495161476033313796107536512663280794332045579302109906525918376981", "price":"0.95", "size":"631", "side":"BUY", "hash":"d7499c186ca7f8edb53415467eb0bc12297ffdf7", "best_bid":"0.98", "best_ask":"0.99"}, {"asset_id":"81916206347121459497221114766050949090435061493822476265356047392175668050706", "price":"0.05", "size":"631", "side":"SELL", "hash":"88c39ba228587092260807f4e6d4b10d29f9b165", "best_bid":"0.01", "best_ask":"0.02"}], "timestamp":"1770241488446", "event_type":"price_change"}
{"market":"0x38f3050258345e9cf363d1c8cc302f08c65b96ba1a4669d81e07ed69708344df", "price_changes":[{"asset_id":"96888240988495161476033313796107536512663280794332045579302109906525918376981", "price":"0.96", "size":"630.73", "side":"BUY", "hash":"a2ae522179699b43288a8c69122b9847e14a25d8", "best_bid":"0.98", "best_ask":"0.99"}, {"asset_id":"81916206347121459497221114766050949090435061493822476265356047392175668050706", "price":"0.04", "size":"630.73", "side":"SELL", "hash":"ac0d3d4683cdf4fabf16f4af83a72a8c88091f53", "best_bid":"0.01", "best_ask":"0.02"}], "timestamp":"1770241488447", "event_type":"price_change"}
{"market":"0x38f3050258345e9cf363d1c8cc302f08c65b96ba1a4669d81e07ed69708344df", "price_changes":[{"asset_id":"96888240988495161476033313796107536512663280794332045579302109906525918376981", "price":"0.96", "size":"657.73", "side":"BUY", "hash":"a44b6227f8fbf831912882501a43048b8e4fd90f", "best_bid":"0.98", "best_ask":"0.99"}, {"asset_id":"81916206347121459497221114766050949090435061493822476265356047392175668050706", "price":"0.04", "size":"657.73", "side":"SELL", "hash":"249d73e313ae1e27e818a9ea445100c5f61d95e9", "best_bid":"0.01", "best_ask":"0.02"}], "timestamp":"1770241488448", "event_type":"price_change"}
{"market":"0x38f3050258345e9cf363d1c8cc302f08c65b96ba1a4669d81e07ed69708344df", "price_changes":[{"asset_id":"96888240988495161476033313796107536512663280794332045579302109906525918376981", "price":"0.98", "size":"728.8", "side":"BUY", "hash":"0e6ea11792d55527a3499743be822cb410c333b7", "best_bid":"0.98", "best_ask":"0.99"}, {"asset_id":"81916206347121459497221114766050949090435061493822476265356047392175668050706", "price":"0.02", "size":"728.8", "side":"SELL", "hash":"822681350777956561f913a4da5d831d9c181338", "best_bid":"0.01", "best_ask":"0.02"}], "timestamp":"1770241488470", "event_type":"price_change"}
{"market":"0x38f3050258345e9cf363d1c8cc302f08c65b96ba1a4669d81e07ed69708344df", "price_changes":[{"asset_id":"96888240988495161476033313796107536512663280794332045579302109906525918376981", "price":"0.97", "size":"541.32", "side":"BUY", "hash":"4b4a11fc4f95c5cfe345b712689c15c0aa6f6b76", "best_bid":"0.98", "best_ask":"0.99"}, {"asset_id":"81916206347121459497221114766050949090435061493822476265356047392175668050706", "price":"0.03", "size":"541.32", "side":"SELL", "hash":"72662a82b348c1dce0ff071656d8ebcbf772989b", "best_bid":"0.01", "best_ask":"0.02"}], "timestamp":"1770241488473", "event_type":"price_change"}
{"market":"0x38f3050258345e9cf363d1c8cc302f08c65b96ba1a4669d81e07ed69708344df", "price_changes":[{"asset_id":"96888240988495161476033313796107536512663280794332045579302109906525918376981", "price":"0.95", "size":"658", "side":"BUY", "hash":"6661b9c583660c0f1dbae1ed7ae97c7344495b9d", "best_bid":"0.98", "best_ask":"0.99"}, {"asset_id":"81916206347121459497221114766050949090435061493822476265356047392175668050706", "price":"0.05", "size":"658", "side":"SELL", "hash":"328104cb1dc735129e58c9beceb0790c12e73584", "best_bid":"0.01", "best_ask":"0.02"}], "timestamp":"1770241488634", "event_type":"price_change"}
{"market":"0x38f3050258345e9cf363d1c8cc302f08c65b96ba1a4669d81e07ed69708344df", "price_changes":[{"asset_id":"96888240988495161476033313796107536512663280794332045579302109906525918376981", "price":"0.96", "size":"630.73", "side":"BUY", "hash":"16106eb2d1e250a8f2969f857d7dd51c3b26a4b0", "best_bid":"0.98", "best_ask":"0.99"}, {"asset_id":"81916206347121459497221114766050949090435061493822476265356047392175668050706", "price":"0.04", "size":"630.73", "side":"SELL", "hash":"04d137f0c9b4e78ef0f55b2c0830206253f4065a", "best_bid":"0.01", "best_ask":"0.02"}], "timestamp":"1770241488635", "event_type":"price_change"}
{"market":"0x38f3050258345e9cf363d1c8cc302f08c65b96ba1a4669d81e07ed69708344df", "price_changes":[{"asset_id":"96888240988495161476033313796107536512663280794332045579302109906525918376981", "price":"0.95", "size":"685", "side":"BUY", "hash":"54ebd98a6d37376d86b96e4af1cf914ee1304e05", "best_bid":"0.98", "best_ask":"0.99"}, {"asset_id":"81916206347121459497221114766050949090435061493822476265356047392175668050706", "price":"0.05", "size":"685", "side":"SELL", "hash":"1c2785f76b9f3772d3ee9a3525103e0a65085a34", "best_bid":"0.01", "best_ask":"0.02"}], "timestamp":"1770241488644", "event_type":"price_change"}
{"market":"0x38f3050258345e9cf363d1c8cc302f08c65b96ba1a4669d81e07ed69708344df", "price_changes":[{"asset_id":"96888240988495161476033313796107536512663280794332045579302109906525918376981", "price":"0.99", "size":"1636.08", "side":"SELL", "hash":"87410c410cded13963c97b92eccf41c5e139ba2c", "best_bid":"0.98", "best_ask":"0.99"}, {"asset_id":"81916206347121459497221114766050949090435061493822476265356047392175668050706", "price":"0.01", "size":"1636.08", "side":"BUY", "hash":"7b20a163fe2f1a0f35de00c0850a5df9b9eb29cd", "best_bid":"0.01", "best_ask":"0.02"}], "timestamp":"1770241488649", "event_type":"price_change"}
{"market":"0x38f3050258345e9cf363d1c8cc302f08c65b96ba1a4669d81e07ed69708344df", "asset_id":"81916206347121459497221114766050949090435061493822476265356047392175668050706", "bids":[{"price":"0.01", "size":"1636.08"}], "asks":[{"price":"0.99", "size":"5019.91"}, {"price":"0.98", "size":"3034.23"}, {"price":"0.97", "size":"3172"}, {"price":"0.96", "size":"3012"}, {"price":"0.95", "size":"3032"}, {"price":"0.94", "size":"3012"}, {"price":"0.93", "size":"3126.28"}, {"price":"0.92", "size":"3012"}, {"price":"0.91", "size":"3012"}, {"price":"0.9", "size":"3087"}, {"price":"0.89", "size":"12"}, {"price":"0.88", "size":"12"}, {"price":"0.87", "size":"12"}, {"price":"0.86", "size":"12"}, {"price":"0.85", "size":"12"}, {"price":"0.84", "size":"12"}, {"price":"0.83", "size":"12"}, {"price":"0.82", "size":"12"}, {"price":"0.81", "size":"12"}, {"price":"0.8", "size":"12"}, {"price":"0.79", "size":"12"}, {"price":"0.78", "size":"12"}, {"price":"0.77", "size":"12"}, {"price":"0.76", "size":"112"}, {"price":"0.75", "size":"40.57"}, {"price":"0.74", "size":"12"}, {"price":"0.73", "size":"293.25"}, {"price":"0.72", "size":"22"}, {"price":"0.71", "size":"12"}, {"price":"0.7", "size":"18"}, {"price":"0.69", "size":"12"}, {"price":"0.68", "size":"12"}, {"price":"0.67", "size":"12"}, {"price":"0.66", "size":"160.89"}, {"price":"0.65", "size":"12"}, {"price":"0.64", "size":"12"}, {"price":"0.63", "size":"12"}, {"price":"0.62", "size":"19.39"}, {"price":"0.61", "size":"18.04"}, {"price":"0.6", "size":"12"}, {"price":"0.59", "size":"94.31"}, {"price":"0.58", "size":"5450.54"}, {"price":"0.57", "size":"12"}, {"price":"0.56", "size":"12"}, {"price":"0.55", "size":"12"}, {"price":"0.54", "size":"22"}, {"price":"0.53", "size":"12"}, {"price":"0.52", "size":"12"}, {"price":"0.51", "size":"12"}, {"price":"0.5", "size":"12"}, {"price":"0.49", "size":"12"}, {"price":"0.48", "size":"12"}, {"price":"0.47", "size":"12"}, {"price":"0.46", "size":"485.56"}, {"price":"0.45", "size":"31"}, {"price":"0.44", "size":"17"}, {"price":"0.43", "size":"12"}, {"price":"0.42", "size":"12"}, {"price":"0.41", "size":"12"}, {"price":"0.4", "size":"127"}, {"price":"0.39", "size":"12"}, {"price":"0.38", "size":"114.5"}, {"price":"0.37", "size":"12"}, {"price":"0.36", "size":"12"}, {"price":"0.35", "size":"37"}, {"price":"0.34", "size":"12"}, {"price":"0.33", "size":"12"}, {"price":"0.32", "size":"12"}, {"price":"0.31", "size":"12"}, {"price":"0.3", "size":"31.9"}, {"price":"0.29", "size":"344"}, {"price":"0.28", "size":"3288.99"}, {"price":"0.27", "size":"212"}, {"price":"0.26", "size":"218"}, {"price":"0.25", "size":"212"}, {"price":"0.24", "size":"212"}, {"price":"0.23", "size":"212"}, {"price":"0.22", "size":"1223.14"}, {"price":"0.21", "size":"712"}, {"price":"0.2", "size":"472.99"}, {"price":"0.19", "size":"212"}, {"price":"0.18", "size":"212"}, {"price":"0.17", "size":"212"}, {"price":"0.16", "size":"812"}, {"price":"0.15", "size":"231.08"}, {"price":"0.14", "size":"283.65"}, {"price":"0.13", "size":"212"}, {"price":"0.12", "size":"252"}, {"price":"0.11", "size":"252"}, {"price":"0.1", "size":"737.71"}, {"price":"0.09", "size":"261"}, {"price":"0.08", "size":"844.68"}, {"price":"0.07", "size":"326"}, {"price":"0.06", "size":"931"}, {"price":"0.05", "size":"685"}, {"price":"0.04", "size":"630.73"}, {"price":"0.03", "size":"541.32"}, {"price":"0.02", "size":"728.8"}], "hash":"7b20a163fe2f1a0f35de00c0850a5df9b9eb29cd", "timestamp":"1770241488649", "event_type":"book"}
{"market":"0x38f3050258345e9cf363d1c8cc302f08c65b96ba1a4669d81e07ed69708344df", "price_changes":[{"asset_id":"96888240988495161476033313796107536512663280794332045579302109906525918376981", "price":"0.98", "size":"701.8", "side":"BUY", "hash":"e1b4695f44e63806da3555868d94be5ca471e9c9", "best_bid":"0.98", "best_ask":"0.99"}, {"asset_id":"81916206347121459497221114766050949090435061493822476265356047392175668050706", "price":"0.02", "size":"701.8", "side":"SELL", "hash":"2f53e538d608b873d02370efea9ba29ed871b28b", "best_bid":"0.01", "best_ask":"0.02"}], "timestamp":"1770241488653", "event_type":"price_change"}
{"market":"0x38f3050258345e9cf363d1c8cc302f08c65b96ba1a4669d81e07ed69708344df", "price_changes":[{"asset_id":"96888240988495161476033313796107536512663280794332045579302109906525918376981", "price":"0.97", "size":"568.32", "side":"BUY", "hash":"9b1c7b774c51d159f2b2326094199d4e87b661f9", "best_bid":"0.98", "best_ask":"0.99"}, {"asset_id":"81916206347121459497221114766050949090435061493822476265356047392175668050706", "price":"0.03", "size":"568.32", "side":"SELL", "hash":"7a48c686e7b4895d7ffcaff6a8ca1236300a9b82", "best_bid":"0.01", "best_ask":"0.02"}], "timestamp":"1770241488657", "event_type":"price_change"}
{"market":"0x38f3050258345e9cf363d1c8cc302f08c65b96ba1a4669d81e07ed69708344df", "price_changes":[{"asset_id":"96888240988495161476033313796107536512663280794332045579302109906525918376981", "price":"0.96", "size":"603.73", "side":"BUY", "hash":"7ef1042d153f182b56cbc7a100f7f2bd6fcc1a5c", "best_bid":"0.98", "best_ask":"0.99"}, {"asset_id":"81916206347121459497221114766050949090435061493822476265356047392175668050706", "price":"0.04", "size":"603.73", "side":"SELL", "hash":"e5499ce91a302f2e7805baa7120109c7047483eb", "best_bid":"0.01", "best_ask":"0.02"}], "timestamp":"1770241488676", "event_type":"price_change"}
{"market":"0x38f3050258345e9cf363d1c8cc302f08c65b96ba1a4669d81e07ed69708344df", "price_changes":[{"asset_id":"81916206347121459497221114766050949090435061493822476265356047392175668050706", "price":"0.01", "size":"1663.08", "side":"BUY", "hash":"87c3c991175c716b4972a44ab66a275eccfad853", "best_bid":"0.01", "best_ask":"0.02"}, {"asset_id":"96888240988495161476033313796107536512663280794332045579302109906525918376981", "price":"0.99", "size":"1663.08", "side":"SELL", "hash":"6a6d62cc486bbf5f870ce399820e3ac840efd2b5", "best_bid":"0.98", "best_ask":"0.99"}], "timestamp":"1770241488825", "event_type":"price_change"}
{"market":"0x38f3050258345e9cf363d1c8cc302f08c65b96ba1a4669d81e07ed69708344df", "price_changes":[{"asset_id":"81916206347121459497221114766050949090435061493822476265356047392175668050706", "price":"0.01", "size":"1686.08", "side":"BUY", "hash":"4f9a92f7ecb3ed518d84c81470b4e236556295f3", "best_bid":"0.01", "best_ask":"0.02"}, {"asset_id":"96888240988495161476033313796107536512663280794332045579302109906525918376981", "price":"0.99", "size":"1686.08", "side":"SELL", "hash":"81df579f228f4c187be5d2dc09682b04273a6b72", "best_bid":"0.98", "best_ask":"0.99"}], "timestamp":"1770241488829", "event_type":"price_change"}
{"market":"0x38f3050258345e9cf363d1c8cc302f08c65b96ba1a4669d81e07ed69708344df", "price_changes":[{"asset_id":"81916206347121459497221114766050949090435061493822476265356047392175668050706", "price":"0.01", "size":"1713.08", "side":"BUY", "hash":"b79174e834ee06dc0a3d7db19e575a76c90a4e93", "best_bid":"0.01", "best_ask":"0.02"}, {"asset_id":"96888240988495161476033313796107536512663280794332045579302109906525918376981", "price":"0.99", "size":"1713.08", "side":"SELL", "hash":"796d167eba797e1dec7f89c36ae9228ae91331d9", "best_bid":"0.98", "best_ask":"0.99"}], "timestamp":"1770241488836", "event_type":"price_change"}
{"market":"0x38f3050258345e9cf363d1c8cc302f08c65b96ba1a4669d81e07ed69708344df", "price_changes":[{"asset_id":"81916206347121459497221114766050949090435061493822476265356047392175668050706", "price":"0.01", "size":"1740.08", "side":"BUY", "hash":"f5fe7e3c3f60c2ef4d47203d299b01af0013706e", "best_bid":"0.01", "best_ask":"0.02"}, {"asset_id":"96888240988495161476033313796107536512663280794332045579302109906525918376981", "price":"0.99", "size":"1740.08", "side":"SELL", "hash":"3f2d4b64cf0686c2401f6d10446b50740ac0eb0c", "best_bid":"0.98", "best_ask":"0.99"}], "timestamp":"1770241488850", "event_type":"price_change"}
{"market":"0x38f3050258345e9cf363d1c8cc302f08c65b96ba1a4669d81e07ed69708344df", "price_changes":[{"asset_id":"96888240988495161476033313796107536512663280794332045579302109906525918376981", "price":"0.98", "size":"681.8", "side":"BUY", "hash":"0aeb567543b8788afc53cbdfb8717387a9a06135", "best_bid":"0.98", "best_ask":"0.99"}, {"asset_id":"81916206347121459497221114766050949090435061493822476265356047392175668050706", "price":"0.02", "size":"681.8", "side":"SELL", "hash":"f74242a4a0100f8b5ef47b55608ccb6472f32211", "best_bid":"0.01", "best_ask":"0.02"}], "timestamp":"1770241488909", "event_type":"price_change"}
{"market":"0x38f3050258345e9cf363d1c8cc302f08c65b96ba1a4669d81e07ed69708344df", "price_changes":[{"asset_id":"96888240988495161476033313796107536512663280794332045579302109906525918376981", "price":"0.97", "size":"545.32", "side":"BUY", "hash":"73f4c0ce4872973992708fb3f8a8af30678a2870", "best_bid":"0.98", "best_ask":"0.99"}, {"asset_id":"81916206347121459497221114766050949090435061493822476265356047392175668050706", "price":"0.03", "size":"545.32", "side":"SELL", "hash":"74817b52bc79e11b90aa6bcc417f284c620a7d63", "best_bid":"0.01", "best_ask":"0.02"}], "timestamp":"1770241489289", "event_type":"price_change"}
{"market":"0x38f3050258345e9cf363d1c8cc302f08c65b96ba1a4669d81e07ed69708344df", "price_changes":[{"asset_id":"96888240988495161476033313796107536512663280794332045579302109906525918376981", "price":"0.96", "size":"626.73", "side":"BUY", "hash":"d1f98f6917616e6cd206c754217ee649cbfc2c24", "best_bid":"0.98", "best_ask":"0.99"}, {"asset_id":"81916206347121459497221114766050949090435061493822476265356047392175668050706", "price":"0.04", "size":"626.73", "side":"SELL", "hash":"dadcc346e4070800a3a5325c3477160aaf28c24e", "best_bid":"0.01", "best_ask":"0.02"}], "timestamp":"1770241489290", "event_type":"price_change"}
{"market":"0x38f3050258345e9cf363d1c8cc302f08c65b96ba1a4669d81e07ed69708344df", "price_changes":[{"asset_id":"81916206347121459497221114766050949090435061493822476265356047392175668050706", "price":"0.01", "size":"1713.08", "side":"BUY", "hash":"08191d2abffa956cdd99d4365efe7cae9ecb8cf1", "best_bid":"0.01", "best_ask":"0.02"}, {"asset_id":"96888240988495161476033313796107536512663280794332045579302109906525918376981", "price":"0.99", "size":"1713.08", "side":"SELL", "hash":"a344ad405baf6431542140456e64cb09416ad426", "best_bid":"0.98", "best_ask":"0.99"}], "timestamp":"1770241489296", "event_type":"price_change"}
{"market":"0x38f3050258345e9cf363d1c8cc302f08c65b96ba1a4669d81e07ed69708344df", "price_changes":[{"asset_id":"81916206347121459497221114766050949090435061493822476265356047392175668050706", "price":"0.01", "size":"1740.08", "side":"BUY", "hash":"c649bfd8f5ee882bd7c25bf23ea6b463d3eeafbf", "best_bid":"0.01", "best_ask":"0.02"}, {"asset_id":"96888240988495161476033313796107536512663280794332045579302109906525918376981", "price":"0.99", "size":"1740.08", "side":"SELL", "hash":"0ee43c53acba11ac1f9734c656c58d3035760548", "best_bid":"0.98", "best_ask":"0.99"}], "timestamp":"1770241489297", "event_type":"price_change"}
{"market":"0x38f3050258345e9cf363d1c8cc302f08c65b96ba1a4669d81e07ed69708344df", "price_changes":[{"asset_id":"96888240988495161476033313796107536512663280794332045579302109906525918376981", "price":"0.95", "size":"658", "side":"BUY", "hash":"c59496f898ccb7d28f5d77598b6e885732e2f34b", "best_bid":"0.98", "best_ask":"0.99"}, {"asset_id":"81916206347121459497221114766050949090435061493822476265356047392175668050706", "price":"0.05", "size":"658", "side":"SELL", "hash":"4d49ffacd9e79379adbbfefccafa5f9428cbb63e", "best_bid":"0.01", "best_ask":"0.02"}], "timestamp":"1770241489303", "event_type":"price_change"}
{"market":"0x38f3050258345e9cf363d1c8cc302f08c65b96ba1a4669d81e07ed69708344df", "price_changes":[{"asset_id":"81916206347121459497221114766050949090435061493822476265356047392175668050706", "price":"0.01", "size":"1767.08", "side":"BUY", "hash":"67c422a9b5086be4044e45ea0b1cab6109591da3", "best_bid":"0.01", "best_ask":"0.02"}, {"asset_id":"96888240988495161476033313796107536512663280794332045579302109906525918376981", "price":"0.99", "size":"1767.08", "side":"SELL", "hash":"eb1ac144d177d7d4f66def720705f630b37cf303", "best_bid":"0.98", "best_ask":"0.99"}], "timestamp":"1770241489304", "event_type":"price_change"}
{"market":"0x38f3050258345e9cf363d1c8cc302f08c65b96ba1a4669d81e07ed69708344df", "price_changes":[{"asset_id":"96888240988495161476033313796107536512663280794332045579302109906525918376981", "price":"0.95", "size":"685", "side":"BUY", "hash":"8ec881ad7fb0a9117f240f70d079fdb21807e5b4", "best_bid":"0.98", "best_ask":"0.99"}, {"asset_id":"81916206347121459497221114766050949090435061493822476265356047392175668050706", "price":"0.05", "size":"685", "side":"SELL", "hash":"30f9d36297305e7dabd0c0ea3ed01b1eb685e551", "best_bid":"0.01", "best_ask":"0.02"}], "timestamp":"1770241489305", "event_type":"price_change"}
{"market":"0x38f3050258345e9cf363d1c8cc302f08c65b96ba1a4669d81e07ed69708344df", "price_changes":[{"asset_id":"81916206347121459497221114766050949090435061493822476265356047392175668050706", "price":"0.01", "size":"1740.08", "side":"BUY", "hash":"aa3531514ed1da647058db072c252d84cc8043e3", "best_bid":"0.01", "best_ask":"0.02"}, {"asset_id":"96888240988495161476033313796107536512663280794332045579302109906525918376981", "price":"0.99", "size":"1740.08", "side":"SELL", "hash":"60103b2330bf89d4d3c453f3510f5aeb9905c72f", "best_bid":"0.98", "best_ask":"0.99"}], "timestamp":"1770241489305", "event_type":"price_change"}
{"market":"0x38f3050258345e9cf363d1c8cc302f08c65b96ba1a4669d81e07ed69708344df", "price_changes":[{"asset_id":"96888240988495161476033313796107536512663280794332045579302109906525918376981", "price":"0.97", "size":"518.32", "side":"BUY", "hash":"38fa4ff390ca596bec1c689be8a7d49ff1d03b77", "best_bid":"0.98", "best_ask":"0.99"}, {"asset_id":"81916206347121459497221114766050949090435061493822476265356047392175668050706", "price":"0.03", "size":"518.32", "side":"SELL", "hash":"e09ff2a2ea222d3d4f3f0e3e04b4475ce1af6617", "best_bid":"0.01", "best_ask":"0.02"}], "timestamp":"1770241489307", "event_type":"price_change"}
{"market":"0x38f3050258345e9cf363d1c8cc302f08c65b96ba1a4669d81e07ed69708344df", "price_changes":[{"asset_id":"96888240988495161476033313796107536512663280794332045579302109906525918376981", "price":"0.96", "size":"653.73", "side":"BUY", "hash":"68e1db01f198cc2f20a5c7973e7880d2e28232d1", "best_bid":"0.98", "best_ask":"0.99"}, {"asset_id":"81916206347121459497221114766050949090435061493822476265356047392175668050706", "price":"0.04", "size":"653.73", "side":"SELL", "hash":"849fd7c604633f6cf83dc284d7be4e3fa50b2fb1", "best_bid":"0.01", "best_ask":"0.02"}], "timestamp":"1770241489308", "event_type":"price_change"}
{"market":"0x38f3050258345e9cf363d1c8cc302f08c65b96ba1a4669d81e07ed69708344df", "price_changes":[{"asset_id":"96888240988495161476033313796107536512663280794332045579302109906525918376981", "price":"0.95", "size":"658", "side":"BUY", "hash":"a448bc9b9ce37ae3bdc12e4c20d1caf886bc8fab", "best_bid":"0.98", "best_ask":"0.99"}, {"asset_id":"81916206347121459497221114766050949090435061493822476265356047392175668050706", "price":"0.05", "size":"658", "side":"SELL", "hash":"1063a5413f6e95602a8a119f7da478309cf2083a", "best_bid":"0.01", "best_ask":"0.02"}], "timestamp":"1770241489338", "event_type":"price_change"}
{"market":"0x38f3050258345e9cf363d1c8cc302f08c65b96ba1a4669d81e07ed69708344df", "price_changes":[{"asset_id":"96888240988495161476033313796107536512663280794332045579302109906525918376981", "price":"0.95", "size":"685", "side":"BUY", "hash":"af22fc9cf490f948d21523918e954115b128d895", "best_bid":"0.98", "best_ask":"0.99"}, {"asset_id":"81916206347121459497221114766050949090435061493822476265356047392175668050706", "price":"0.05", "size":"685", "side":"SELL", "hash":"df3613e23e9a55c42db8a4cb29f3bae65e2a6575", "best_bid":"0.01", "best_ask":"0.02"}], "timestamp":"1770241489343", "event_type":"price_change"}
{"market":"0x38f3050258345e9cf363d1c8cc302f08c65b96ba1a4669d81e07ed69708344df", "price_changes":[{"asset_id":"96888240988495161476033313796107536512663280794332045579302109906525918376981", "price":"0.97", "size":"538.32", "side":"BUY", "hash":"465bf9bf02b7de9f65e864f965280818a4412931", "best_bid":"0.98", "best_ask":"0.99"}, {"asset_id":"81916206347121459497221114766050949090435061493822476265356047392175668050706", "price":"0.03", "size":"538.32", "side":"SELL", "hash":"41c08f95211065c37d23bfe8699f00aab501408d", "best_bid":"0.01", "best_ask":"0.02"}], "timestamp":"1770241489380", "event_type":"price_change"}
{"market":"0x38f3050258345e9cf363d1c8cc302f08c65b96ba1a4669d81e07ed69708344df", "price_changes":[{"asset_id":"96888240988495161476033313796107536512663280794332045579302109906525918376981", "price":"0.97", "size":"565.32", "side":"BUY", "hash":"84bf46d6f1567daf1a849374ab2c60e9fd8b9d44", "best_bid":"0.98", "best_ask":"0.99"}, {"asset_id":"81916206347121459497221114766050949090435061493822476265356047392175668050706", "price":"0.03", "size":"565.32", "side":"SELL", "hash":"ae5e42cbdc73b032032ebae9d9bbc3619f71a31b", "best_bid":"0.01", "best_ask":"0.02"}], "timestamp":"1770241489468", "event_type":"price_change"}
{"market":"0x38f3050258345e9cf363d1c8cc302f08c65b96ba1a4669d81e07ed69708344df", "price_changes":[{"asset_id":"96888240988495161476033313796107536512663280794332045579302109906525918376981", "price":"0.96", "size":"626.73", "side":"BUY", "hash":"7d62726771e8ebe7baacd6e1d8bcb4aee161e6fe", "best_bid":"0.98", "best_ask":"0.99"}, {"asset_id":"81916206347121459497221114766050949090435061493822476265356047392175668050706", "price":"0.04", "size":"626.73", "side":"SELL", "hash":"48fbc107dcd0a328dece7490080fd71ccbc4d1c1", "best_bid":"0.01", "best_ask":"0.02"}], "timestamp":"1770241489469", "event_type":"price_change"}
{"market":"0x38f3050258345e9cf363d1c8cc302f08c65b96ba1a4669d81e07ed69708344df", "price_changes":[{"asset_id":"96888240988495161476033313796107536512663280794332045579302109906525918376981", "price":"0.96", "size":"603.73", "side":"BUY", "hash":"f834a2db03946a3b59188755e97883650de612c1", "best_bid":"0.98", "best_ask":"0.99"}, {"asset_id":"81916206347121459497221114766050949090435061493822476265356047392175668050706", "price":"0.04", "size":"603.73", "side":"SELL", "hash":"c48da140144fc9342024862532fe348700134aa3", "best_bid":"0.01", "best_ask":"0.02"}], "timestamp":"1770241489539", "event_type":"price_change"}
{"market":"0x38f3050258345e9cf363d1c8cc302f08c65b96ba1a4669d81e07ed69708344df", "price_changes":[{"asset_id":"96888240988495161476033313796107536512663280794332045579302109906525918376981", "price":"0.97", "size":"588.32", "side":"BUY", "hash":"254c6d03f461406f5d8bc1737d4c6ff72f50896d", "best_bid":"0.98", "best_ask":"0.99"}, {"asset_id":"81916206347121459497221114766050949090435061493822476265356047392175668050706", "price":"0.03", "size":"588.32", "side":"SELL", "hash":"cd61d1106df79288e12f23612003830dff6df551", "best_bid":"0.01", "best_ask":"0.02"}], "timestamp":"1770241489544", "event_type":"price_change"}
{"market":"0x38f3050258345e9cf363d1c8cc302f08c65b96ba1a4669d81e07ed69708344df", "price_changes":[{"asset_id":"96888240988495161476033313796107536512663280794332045579302109906525918376981", "price":"0.93", "size":"286", "side":"BUY", "hash":"b6ee38e10924e7dc3d5bcab92804c5ba063b702e", "best_bid":"0.98", "best_ask":"0.99"}, {"asset_id":"81916206347121459497221114766050949090435061493822476265356047392175668050706", "price":"0.07", "size":"286", "side":"SELL", "hash":"3ab66e1ea383c738e04d34d4c51505f4a74455bc", "best_bid":"0.01", "best_ask":"0.02"}], "timestamp":"1770241489777", "event_type":"price_change"}
{"market":"0x38f3050258345e9cf363d1c8cc302f08c65b96ba1a4669d81e07ed69708344df", "price_changes":[{"asset_id":"96888240988495161476033313796107536512663280794332045579302109906525918376981", "price":"0.88", "size":"212", "side":"BUY", "hash":"b6ee38e10924e7dc3d5bcab92804c5ba063b702e", "best_bid":"0.98", "best_ask":"0.99"}, {"asset_id":"81916206347121459497221114766050949090435061493822476265356047392175668050706", "price":"0.12", "size":"212", "side":"SELL", "hash":"3ab66e1ea383c738e04d34d4c51505f4a74455bc", "best_bid":"0.01", "best_ask":"0.02"}], "timestamp":"1770241489777", "event_type":"price_change"}
{"market":"0x38f3050258345e9cf363d1c8cc302f08c65b96ba1a4669d81e07ed69708344df", "price_changes":[{"asset_id":"96888240988495161476033313796107536512663280794332045579302109906525918376981", "price":"0.92", "size":"804.68", "side":"BUY", "hash":"b6ee38e10924e7dc3d5bcab92804c5ba063b702e", "best_bid":"0.98", "best_ask":"0.99"}, {"asset_id":"81916206347121459497221114766050949090435061493822476265356047392175668050706", "price":"0.08", "size":"804.68", "side":"SELL", "hash":"3ab66e1ea383c738e04d34d4c51505f4a74455bc", "best_bid":"0.01", "best_ask":"0.02"}], "timestamp":"1770241489777", "event_type":"price_change"}
{"market":"0x38f3050258345e9cf363d1c8cc302f08c65b96ba1a4669d81e07ed69708344df", "price_changes":[{"asset_id":"96888240988495161476033313796107536512663280794332045579302109906525918376981", "price":"0.96", "size":"563.73", "side":"BUY", "hash":"b6ee38e10924e7dc3d5bcab92804c5ba063b702e", "best_bid":"0.98", "best_ask":"0.99"}, {"asset_id":"81916206347121459497221114766050949090435061493822476265356047392175668050706", "price":"0.04", "size":"563.73", "side":"SELL", "hash":"3ab66e1ea383c738e04d34d4c51505f4a74455bc", "best_bid":"0.01", "best_ask":"0.02"}], "timestamp":"1770241489777", "event_type":"price_change"}
{"market":"0x38f3050258345e9cf363d1c8cc302f08c65b96ba1a4669d81e07ed69708344df", "price_changes":[{"asset_id":"96888240988495161476033313796107536512663280794332045579302109906525918376981", "price":"0.95", "size":"645", "side":"BUY", "hash":"b6ee38e10924e7dc3d5bcab92804c5ba063b702e", "best_bid":"0.98", "best_ask":"0.99"}, {"asset_id":"81916206347121459497221114766050949090435061493822476265356047392175668050706", "price":"0.05", "size":"645", "side":"SELL", "hash":"3ab66e1ea383c738e04d34d4c51505f4a74455bc", "best_bid":"0.01", "best_ask":"0.02"}], "timestamp":"1770241489777", "event_type":"price_change"}
{"market":"0x38f3050258345e9cf363d1c8cc302f08c65b96ba1a4669d81e07ed69708344df", "price_changes":[{"asset_id":"96888240988495161476033313796107536512663280794332045579302109906525918376981", "price":"0.94", "size":"891", "side":"BUY", "hash":"b6ee38e10924e7dc3d5bcab92804c5ba063b702e", "best_bid":"0.98", "best_ask":"0.99"}, {"asset_id":"81916206347121459497221114766050949090435061493822476265356047392175668050706", "price":"0.06", "size":"891", "side":"SELL", "hash":"3ab66e1ea383c738e04d34d4c51505f4a74455bc", "best_bid":"0.01", "best_ask":"0.02"}], "timestamp":"1770241489777", "event_type":"price_change"}
{"market":"0x38f3050258345e9cf363d1c8cc302f08c65b96ba1a4669d81e07ed69708344df", "price_changes":[{"asset_id":"96888240988495161476033313796107536512663280794332045579302109906525918376981", "price":"0.9", "size":"697.71", "side":"BUY", "hash":"b6ee38e10924e7dc3d5bcab92804c5ba063b702e", "best_bid":"0.98", "best_ask":"0.99"}, {"asset_id":"81916206347121459497221114766050949090435061493822476265356047392175668050706", "price":"0.1", "size":"697.71", "side":"SELL", "hash":"3ab66e1ea383c738e04d34d4c51505f4a74455bc", "best_bid":"0.01", "best_ask":"0.02"}], "timestamp":"1770241489777", "event_type":"price_change"}
{"market":"0x38f3050258345e9cf363d1c8cc302f08c65b96ba1a4669d81e07ed69708344df", "price_changes":[{"asset_id":"96888240988495161476033313796107536512663280794332045579302109906525918376981", "price":"0.97", "size":"548.32", "side":"BUY", "hash":"b6ee38e10924e7dc3d5bcab92804c5ba063b702e", "best_bid":"0.98", "best_ask":"0.99"}, {"asset_id":"81916206347121459497221114766050949090435061493822476265356047392175668050706", "price":"0.03", "size":"548.32", "side":"SELL", "hash":"3ab66e1ea383c738e04d34d4c51505f4a74455bc", "best_bid":"0.01", "best_ask":"0.02"}], "timestamp":"1770241489777", "event_type":"price_change"}
{"market":"0x38f3050258345e9cf363d1c8cc302f08c65b96ba1a4669d81e07ed69708344df", "price_changes":[{"asset_id":"96888240988495161476033313796107536512663280794332045579302109906525918376981", "price":"0.89", "size":"212", "side":"BUY", "hash":"b6ee38e10924e7dc3d5bcab92804c5ba063b702e", "best_bid":"0.98", "best_ask":"0.99"}, {"asset_id":"81916206347121459497221114766050949090435061493822476265356047392175668050706", "price":"0.11", "size":"212", "side":"SELL", "hash":"3ab66e1ea383c738e04d34d4c51505f4a74455bc", "best_bid":"0.01", "best_ask":"0.02"}], "timestamp":"1770241489777", "event_type":"price_change"}
{"market":"0x38f3050258345e9cf363d1c8cc302f08c65b96ba1a4669d81e07ed69708344df", "price_changes":[{"asset_id":"96888240988495161476033313796107536512663280794332045579302109906525918376981", "price":"0.91", "size":"221", "side":"BUY", "hash":"b6ee38e10924e7dc3d5bcab92804c5ba063b702e", "best_bid":"0.98", "best_ask":"0.99"}, {"asset_id":"81916206347121459497221114766050949090435061493822476265356047392175668050706", "price":"0.09", "size":"221", "side":"SELL", "hash":"3ab66e1ea383c738e04d34d4c51505f4a74455bc", "best_bid":"0.01", "best_ask":"0.02"}], "timestamp":"1770241489777", "event_type":"price_change"}
{"market":"0x38f3050258345e9cf363d1c8cc302f08c65b96ba1a4669d81e07ed69708344df", "price_changes":[{"asset_id":"96888240988495161476033313796107536512663280794332045579302109906525918376981", "price":"0.99", "size":"1700.08", "side":"SELL", "hash":"80959c402918ec036a25dcf1c3718e97fba9601e", "best_bid":"0.98", "best_ask":"0.99"}, {"asset_id":"81916206347121459497221114766050949090435061493822476265356047392175668050706", "price":"0.01", "size":"1700.08", "side":"BUY", "hash":"260c5ed33184a870cd931ce0db9a4b44006fb3ba", "best_bid":"0.01", "best_ask":"0.02"}], "timestamp":"1770241489786", "event_type":"price_change"}
{"market":"0x38f3050258345e9cf363d1c8cc302f08c65b96ba1a4669d81e07ed69708344df", "price_changes":[{"asset_id":"96888240988495161476033313796107536512663280794332045579302109906525918376981", "price":"0.96", "size":"586.73", "side":"BUY", "hash":"89f69116891fb4b49c524f9e1e8471694bc994c4", "best_bid":"0.98", "best_ask":"0.99"}, {"asset_id":"81916206347121459497221114766050949090435061493822476265356047392175668050706", "price":"0.04", "size":"586.73", "side":"SELL", "hash":"0fa11381e37044273e8c16fcdb97748166be2b4a", "best_bid":"0.01", "best_ask":"0.02"}], "timestamp":"1770241489788", "event_type":"price_change"}
{"market":"0x38f3050258345e9cf363d1c8cc302f08c65b96ba1a4669d81e07ed69708344df", "price_changes":[{"asset_id":"96888240988495161476033313796107536512663280794332045579302109906525918376981", "price":"0.97", "size":"525.32", "side":"BUY", "hash":"4f57d8261970b7a82173d2e703ec728a29086d03", "best_bid":"0.98", "best_ask":"0.99"}, {"asset_id":"81916206347121459497221114766050949090435061493822476265356047392175668050706", "price":"0.03", "size":"525.32", "side":"SELL", "hash":"ee2807ab73b0f9f1b1ccd1846c7bda0cf7b36ac8", "best_bid":"0.01", "best_ask":"0.02"}], "timestamp":"1770241489789", "event_type":"price_change"}
{"market":"0x38f3050258345e9cf363d1c8cc302f08c65b96ba1a4669d81e07ed69708344df", "price_changes":[{"asset_id":"96888240988495161476033313796107536512663280794332045579302109906525918376981", "price":"0.95", "size":"618", "side":"BUY", "hash":"206c897a6d454b687f1a158b4dac56633ca52299", "best_bid":"0.98", "best_ask":"0.99"}, {"asset_id":"81916206347121459497221114766050949090435061493822476265356047392175668050706", "price":"0.05", "size":"618", "side":"SELL", "hash":"8dbdcafe74b1205dfd06fb2432dc21901a8ed91e", "best_bid":"0.01", "best_ask":"0.02"}], "timestamp":"1770241489833", "event_type":"price_change"}
{"market":"0x38f3050258345e9cf363d1c8cc302f08c65b96ba1a4669d81e07ed69708344df", "price_changes":[{"asset_id":"96888240988495161476033313796107536512663280794332045579302109906525918376981", "price":"0.95", "size":"645", "side":"BUY", "hash":"071d316ad288eff8e6271f4b92466a2812e2697a", "best_bid":"0.98", "best_ask":"0.99"}, {"asset_id":"81916206347121459497221114766050949090435061493822476265356047392175668050706", "price":"0.05", "size":"645", "side":"SELL", "hash":"f3e76c2618d696fda134b140dfafdc9d6a6d6b69", "best_bid":"0.01", "best_ask":"0.02"}], "timestamp":"1770241489835", "event_type":"price_change"}
{"market":"0x38f3050258345e9cf363d1c8cc302f08c65b96ba1a4669d81e07ed69708344df", "price_changes":[{"asset_id":"96888240988495161476033313796107536512663280794332045579302109906525918376981", "price":"0.95", "size":"618", "side":"BUY", "hash":"ddd1de21f8020781c7a82b3a1ce1a393b95e13dc", "best_bid":"0.98", "best_ask":"0.99"}, {"asset_id":"81916206347121459497221114766050949090435061493822476265356047392175668050706", "price":"0.05", "size":"618", "side":"SELL", "hash":"5e42d3ce053d3952dd303b0fd05d354fa0797fad", "best_bid":"0.01", "best_ask":"0.02"}], "timestamp":"1770241489842", "event_type":"price_change"}
{"market":"0x38f3050258345e9cf363d1c8cc302f08c65b96ba1a4669d81e07ed69708344df", "price_changes":[{"asset_id":"96888240988495161476033313796107536512663280794332045579302109906525918376981", "price":"0.95", "size":"645", "side":"BUY", "hash":"8618048be42b5c56d831c07aab5922ab89b78caa", "best_bid":"0.98", "best_ask":"0.99"}, {"asset_id":"81916206347121459497221114766050949090435061493822476265356047392175668050706", "price":"0.05", "size":"645", "side":"SELL", "hash":"eae96efad8af06c82cd5b533a791653f6e59ccd4", "best_bid":"0.01", "best_ask":"0.02"}], "timestamp":"1770241489843", "event_type":"price_change"}
{"market":"0x38f3050258345e9cf363d1c8cc302f08c65b96ba1a4669d81e07ed69708344df", "price_changes":[{"asset_id":"96888240988495161476033313796107536512663280794332045579302109906525918376981", "price":"0.97", "size":"505.32", "side":"BUY", "hash":"397449e4823bd3962f7203b1c3d4c64a4b343dee", "best_bid":"0.98", "best_ask":"0.99"}, {"asset_id":"81916206347121459497221114766050949090435061493822476265356047392175668050706", "price":"0.03", "size":"505.32", "side":"SELL", "hash":"ec4c0f332a51f0bd7b092c9556ae839629adc568", "best_bid":"0.01", "best_ask":"0.02"}], "timestamp":"1770241489862", "event_type":"price_change"}
{"market":"0x38f3050258345e9cf363d1c8cc302f08c65b96ba1a4669d81e07ed69708344df", "price_changes":[{"asset_id":"96888240988495161476033313796107536512663280794332045579302109906525918376981", "price":"0.96", "size":"563.73", "side":"BUY", "hash":"ca55114e80e078cbf7d6e9dbff274ba22ff3047b", "best_bid":"0.98", "best_ask":"0.99"}, {"asset_id":"81916206347121459497221114766050949090435061493822476265356047392175668050706", "price":"0.04", "size":"563.73", "side":"SELL", "hash":"7ccaa6a10616fb84fb62ef8ee9341059f6607a34", "best_bid":"0.01", "best_ask":"0.02"}], "timestamp":"1770241490040", "event_type":"price_change"}
{"market":"0x38f3050258345e9cf363d1c8cc302f08c65b96ba1a4669d81e07ed69708344df", "price_changes":[{"asset_id":"96888240988495161476033313796107536512663280794332045579302109906525918376981", "price":"0.97", "size":"528.32", "side":"BUY", "hash":"b9d371e4974038a8dea0cf7ece2e96c629ffeb49", "best_bid":"0.98", "best_ask":"0.99"}, {"asset_id":"81916206347121459497221114766050949090435061493822476265356047392175668050706", "price":"0.03", "size":"528.32", "side":"SELL", "hash":"e0853c834e2631e9da0ea76bda1a565f3f2f5eda", "best_bid":"0.01", "best_ask":"0.02"}], "timestamp":"1770241490043", "event_type":"price_change"}
{"market":"0x38f3050258345e9cf363d1c8cc302f08c65b96ba1a4669d81e07ed69708344df", "price_changes":[{"asset_id":"96888240988495161476033313796107536512663280794332045579302109906525918376981", "price":"0.97", "size":"505.32", "side":"BUY", "hash":"83ff7c0fcff4de8ef3761f4f52a96b89977cfdc6", "best_bid":"0.98", "best_ask":"0.99"}, {"asset_id":"81916206347121459497221114766050949090435061493822476265356047392175668050706", "price":"0.03", "size":"505.32", "side":"SELL", "hash":"c1daa762715ee47dcc9c55df0a108288f7624406", "best_bid":"0.01", "best_ask":"0.02"}], "timestamp":"1770241490293", "event_type":"price_change"}
{"market":"0x38f3050258345e9cf363d1c8cc302f08c65b96ba1a4669d81e07ed69708344df", "price_changes":[{"asset_id":"96888240988495161476033313796107536512663280794332045579302109906525918376981", "price":"0.96", "size":"586.73", "side":"BUY", "hash":"eafe006948ae913f42be4dbe2b577c80fa596a64", "best_bid":"0.98", "best_ask":"0.99"}, {"asset_id":"81916206347121459497221114766050949090435061493822476265356047392175668050706", "price":"0.04", "size":"586.73", "side":"SELL", "hash":"271bc14b086f915f34d8e3b2e2c96fdf2a6e2aac", "best_bid":"0.01", "best_ask":"0.02"}], "timestamp":"1770241490298", "event_type":"price_change"}
{"market":"0x38f3050258345e9cf363d1c8cc302f08c65b96ba1a4669d81e07ed69708344df", "price_changes":[{"asset_id":"96888240988495161476033313796107536512663280794332045579302109906525918376981", "price":"0.96", "size":"606.73", "side":"BUY", "hash":"faf7c5b6dfb549522560e08ed493f624c1bc03f2", "best_bid":"0.98", "best_ask":"0.99"}, {"asset_id":"81916206347121459497221114766050949090435061493822476265356047392175668050706", "price":"0.04", "size":"606.73", "side":"SELL", "hash":"e6e06fffe545b8af35fe19ca6f9f3bd131136b53", "best_bid":"0.01", "best_ask":"0.02"}], "timestamp":"1770241490333", "event_type":"price_change"}
{"market":"0x38f3050258345e9cf363d1c8cc302f08c65b96ba1a4669d81e07ed69708344df", "price_changes":[{"asset_id":"81916206347121459497221114766050949090435061493822476265356047392175668050706", "price":"0.01", "size":"1727.08", "side":"BUY", "hash":"edf82dce3ce10101e651e20d2b387cb9a907d1c7", "best_bid":"0.01", "best_ask":"0.02"}, {"asset_id":"96888240988495161476033313796107536512663280794332045579302109906525918376981", "price":"0.99", "size":"1727.08", "side":"SELL", "hash":"77856cea0428bb6f308b6d727a60e81100381d4e", "best_bid":"0.98", "best_ask":"0.99"}], "timestamp":"1770241490348", "event_type":"price_change"}
{"market":"0x38f3050258345e9cf363d1c8cc302f08c65b96ba1a4669d81e07ed69708344df", "price_changes":[{"asset_id":"81916206347121459497221114766050949090435061493822476265356047392175668050706", "price":"0.01", "size":"1700.08", "side":"BUY", "hash":"dc14a86e99c01371f5b77c6d8d2e282041b29ff5", "best_bid":"0.01", "best_ask":"0.02"}, {"asset_id":"96888240988495161476033313796107536512663280794332045579302109906525918376981", "price":"0.99", "size":"1700.08", "side":"SELL", "hash":"95de12d0a09644f1b1139167654a3132e887722c", "best_bid":"0.98", "best_ask":"0.99"}], "timestamp":"1770241490349", "event_type":"price_change"}
{"market":"0x38f3050258345e9cf363d1c8cc302f08c65b96ba1a4669d81e07ed69708344df", "price_changes":[{"asset_id":"96888240988495161476033313796107536512663280794332045579302109906525918376981", "price":"0.95", "size":"672", "side":"BUY", "hash":"daa35f6bb1671890fe963f0e71237e33aedf9bc1", "best_bid":"0.98", "best_ask":"0.99"}, {"asset_id":"81916206347121459497221114766050949090435061493822476265356047392175668050706", "price":"0.05", "size":"672", "side":"SELL", "hash":"742672d43987e0e5495d706bcfddc25061e6dcc6", "best_bid":"0.01", "best_ask":"0.02"}], "timestamp":"1770241490350", "event_type":"price_change"}
{"market":"0x38f3050258345e9cf363d1c8cc302f08c65b96ba1a4669d81e07ed69708344df", "price_changes":[{"asset_id":"96888240988495161476033313796107536512663280794332045579302109906525918376981", "price":"0.95", "size":"645", "side":"BUY", "hash":"499d8e92f12c30addb6bd6eb5a6e7a972dd58dc1", "best_bid":"0.98", "best_ask":"0.99"}, {"asset_id":"81916206347121459497221114766050949090435061493822476265356047392175668050706", "price":"0.05", "size":"645", "side":"SELL", "hash":"dce276bda28d434d28baf2240246045dd81cc3e5", "best_bid":"0.01", "best_ask":"0.02"}], "timestamp":"1770241490350", "event_type":"price_change"}
{"market":"0x38f3050258345e9cf363d1c8cc302f08c65b96ba1a4669d81e07ed69708344df", "price_changes":[{"asset_id":"96888240988495161476033313796107536512663280794332045579302109906525918376981", "price":"0.95", "size":"672", "side":"BUY", "hash":"bd0c30d59886d685fc996f3ef99e74d8288397d7", "best_bid":"0.98", "best_ask":"0.99"}, {"asset_id":"81916206347121459497221114766050949090435061493822476265356047392175668050706", "price":"0.05", "size":"672", "side":"SELL", "hash":"b5fe3ebcc909e677d9e081965d0d814a0f3525df", "best_bid":"0.01", "best_ask":"0.02"}], "timestamp":"1770241490361", "event_type":"price_change"}
{"market":"0x38f3050258345e9cf363d1c8cc302f08c65b96ba1a4669d81e07ed69708344df", "price_changes":[{"asset_id":"96888240988495161476033313796107536512663280794332045579302109906525918376981", "price":"0.95", "size":"645", "side":"BUY", "hash":"423f374b624e5c23d71af16d73a935fccc66eae4", "best_bid":"0.98", "best_ask":"0.99"}, {"asset_id":"81916206347121459497221114766050949090435061493822476265356047392175668050706", "price":"0.05", "size":"645", "side":"SELL", "hash":"a28a77b8b0c951ed440df1afb8030b023e848555", "best_bid":"0.01", "best_ask":"0.02"}], "timestamp":"1770241490367", "event_type":"price_change"}
{"market":"0x38f3050258345e9cf363d1c8cc302f08c65b96ba1a4669d81e07ed69708344df", "price_changes":[{"asset_id":"96888240988495161476033313796107536512663280794332045579302109906525918376981", "price":"0.96", "size":"633.73", "side":"BUY", "hash":"cc926490c79e4e0e59404126125470bbda77b213", "best_bid":"0.98", "best_ask":"0.99"}, {"asset_id":"81916206347121459497221114766050949090435061493822476265356047392175668050706", "price":"0.04", "size":"633.73", "side":"SELL", "hash":"ac890b3fbd4658f17d66eb50648d74311651e5d4", "best_bid":"0.01", "best_ask":"0.02"}], "timestamp":"1770241490431", "event_type":"price_change"}
{"market":"0x38f3050258345e9cf363d1c8cc302f08c65b96ba1a4669d81e07ed69708344df", "price_changes":[{"asset_id":"96888240988495161476033313796107536512663280794332045579302109906525918376981", "price":"0.97", "size":"478.32", "side":"BUY", "hash":"cd7ac1fd8df523d05421031f6899e2ea6bdaf621", "best_bid":"0.98", "best_ask":"0.99"}, {"asset_id":"81916206347121459497221114766050949090435061493822476265356047392175668050706", "price":"0.03", "size":"478.32", "side":"SELL", "hash":"fea53251fcea7375e12323a8775db5fb24f7b228", "best_bid":"0.01", "best_ask":"0.02"}], "timestamp":"1770241490432", "event_type":"price_change"}
{"market":"0x38f3050258345e9cf363d1c8cc302f08c65b96ba1a4669d81e07ed69708344df", "price_changes":[{"asset_id":"81916206347121459497221114766050949090435061493822476265356047392175668050706", "price":"0.01", "size":"1673.08", "side":"BUY", "hash":"c025ad308608777940e639395cfe6384b5498379", "best_bid":"0.01", "best_ask":"0.02"}, {"asset_id":"96888240988495161476033313796107536512663280794332045579302109906525918376981", "price":"0.99", "size":"1673.08", "side":"SELL", "hash":"51bdb1a42f10ae9c1dd5169623d27bc849b8dc7e", "best_bid":"0.98", "best_ask":"0.99"}], "timestamp":"1770241490463", "event_type":"price_change"}
{"market":"0x38f3050258345e9cf363d1c8cc302f08c65b96ba1a4669d81e07ed69708344df", "price_changes":[{"asset_id":"81916206347121459497221114766050949090435061493822476265356047392175668050706", "price":"0.01", "size":"1700.08", "side":"BUY", "hash":"3ee6ce718d3ac69f3a24e2b5fb65c6b779f9b6f6", "best_bid":"0.01", "best_ask":"0.02"}, {"asset_id":"96888240988495161476033313796107536512663280794332045579302109906525918376981", "price":"0.99", "size":"1700.08", "side":"SELL", "hash":"39ede2d2ee61ae82b05dcc8e6c2e1299a7f92650", "best_bid":"0.98", "best_ask":"0.99"}], "timestamp":"1770241490463", "event_type":"price_change"}
{"market":"0x38f3050258345e9cf363d1c8cc302f08c65b96ba1a4669d81e07ed69708344df", "price_changes":[{"asset_id":"81916206347121459497221114766050949090435061493822476265356047392175668050706", "price":"0.01", "size":"1727.08", "side":"BUY", "hash":"89f4142155a18ac0c2ad0d5a7fb3960fa5079be5", "best_bid":"0.01", "best_ask":"0.02"}, {"asset_id":"96888240988495161476033313796107536512663280794332045579302109906525918376981", "price":"0.99", "size":"1727.08", "side":"SELL", "hash":"abd9976e2533367d4e9ed1ce494f19a9535c01c0", "best_bid":"0.98", "best_ask":"0.99"}], "timestamp":"1770241490470", "event_type":"price_change"}
{"market":"0x38f3050258345e9cf363d1c8cc302f08c65b96ba1a4669d81e07ed69708344df", "price_changes":[{"asset_id":"81916206347121459497221114766050949090435061493822476265356047392175668050706", "price":"0.01", "size":"1700.08", "side":"BUY", "hash":"f64b33a5388714d7b608e6f3519fc19ac280b8d9", "best_bid":"0.01", "best_ask":"0.02"}, {"asset_id":"96888240988495161476033313796107536512663280794332045579302109906525918376981", "price":"0.99", "size":"1700.08", "side":"SELL", "hash":"2036210c9061ba32f5c2c18736b46b811c7e2520", "best_bid":"0.98", "best_ask":"0.99"}], "timestamp":"1770241490472", "event_type":"price_change"}
{"market":"0x38f3050258345e9cf363d1c8cc302f08c65b96ba1a4669d81e07ed69708344df", "price_changes":[{"asset_id":"96888240988495161476033313796107536512663280794332045579302109906525918376981", "price":"0.96", "size":"610.73", "side":"BUY", "hash":"0b6c3713c33aa9416ade218880ba63c62e480aa8", "best_bid":"0.98", "best_ask":"0.99"}, {"asset_id":"81916206347121459497221114766050949090435061493822476265356047392175668050706", "price":"0.04", "size":"610.73", "side":"SELL", "hash":"9f6742886479ed4e2ada8f03de51729b8cf82f92", "best_bid":"0.01", "best_ask":"0.02"}], "timestamp":"1770241490545", "event_type":"price_change"}
{"market":"0x38f3050258345e9cf363d1c8cc302f08c65b96ba1a4669d81e07ed69708344df", "price_changes":[{"asset_id":"96888240988495161476033313796107536512663280794332045579302109906525918376981", "price":"0.97", "size":"501.32", "side":"BUY", "hash":"0e7c6e9493464ca6bf7f6eaab6c0ba7f4d80e671", "best_bid":"0.98", "best_ask":"0.99"}, {"asset_id":"81916206347121459497221114766050949090435061493822476265356047392175668050706", "price":"0.03", "size":"501.32", "side":"SELL", "hash":"67e69f8b8936bd2cba57e6a0c3353c333bf58840", "best_bid":"0.01", "best_ask":"0.02"}], "timestamp":"1770241490551", "event_type":"price_change"}
{"market":"0x38f3050258345e9cf363d1c8cc302f08c65b96ba1a4669d81e07ed69708344df", "price_changes":[{"asset_id":"96888240988495161476033313796107536512663280794332045579302109906525918376981", "price":"0.96", "size":"583.73", "side":"BUY", "hash":"179e7c34258402768e03fe8ac4a81fe49ee10073", "best_bid":"0.98", "best_ask":"0.99"}, {"asset_id":"81916206347121459497221114766050949090435061493822476265356047392175668050706", "price":"0.04", "size":"583.73", "side":"SELL", "hash":"fea84e0c5b9a48f7ea69e1c51dba6ac04ff95865", "best_bid":"0.01", "best_ask":"0.02"}], "timestamp":"1770241490576", "event_type":"price_change"}
{"market":"0x38f3050258345e9cf363d1c8cc302f08c65b96ba1a4669d81e07ed69708344df", "price_changes":[{"asset_id":"96888240988495161476033313796107536512663280794332045579302109906525918376981", "price":"0.97", "size":"528.32", "side":"BUY", "hash":"237a18059ce02822ae05c91093f2b2b48effc443", "best_bid":"0.98", "best_ask":"0.99"}, {"asset_id":"81916206347121459497221114766050949090435061493822476265356047392175668050706", "price":"0.03", "size":"528.32", "side":"SELL", "hash":"33c667cbeae9477b70dc52bcf9ea2ab0c11af50c", "best_bid":"0.01", "best_ask":"0.02"}], "timestamp":"1770241490581", "event_type":"price_change"}
{"market":"0x38f3050258345e9cf363d1c8cc302f08c65b96ba1a4669d81e07ed69708344df", "price_changes":[{"asset_id":"81916206347121459497221114766050949090435061493822476265356047392175668050706", "price":"0.01", "size":"1727.08", "side":"BUY", "hash":"7ee847f0603f912b31c0f0bf75f303b9eb3aba5a", "best_bid":"0.01", "best_ask":"0.02"}, {"asset_id":"96888240988495161476033313796107536512663280794332045579302109906525918376981", "price":"0.99", "size":"1727.08", "side":"SELL", "hash":"d3d0ec251fdad1e2c4f728f518886df32d7d9902", "best_bid":"0.98", "best_ask":"0.99"}], "timestamp":"1770241490586", "event_type":"price_change"}
{"market":"0x38f3050258345e9cf363d1c8cc302f08c65b96ba1a4669d81e07ed69708344df", "price_changes":[{"asset_id":"81916206347121459497221114766050949090435061493822476265356047392175668050706", "price":"0.01", "size":"1700.08", "side":"BUY", "hash":"9fce1a63098c46623a08c83d971f0fb5d085fcdf", "best_bid":"0.01", "best_ask":"0.02"}, {"asset_id":"96888240988495161476033313796107536512663280794332045579302109906525918376981", "price":"0.99", "size":"1700.08", "side":"SELL", "hash":"17ace1808ebd180ee488d7384774dbd6151f3344", "best_bid":"0.98", "best_ask":"0.99"}], "timestamp":"1770241490587", "event_type":"price_change"}
{"market":"0x38f3050258345e9cf363d1c8cc302f08c65b96ba1a4669d81e07ed69708344df", "price_changes":[{"asset_id":"81916206347121459497221114766050949090435061493822476265356047392175668050706", "price":"0.01", "size":"1673.08", "side":"BUY", "hash":"101c3395a2c04b70eb3375e1875e2eab8a8c87ae", "best_bid":"0.01", "best_ask":"0.02"}, {"asset_id":"96888240988495161476033313796107536512663280794332045579302109906525918376981", "price":"0.99", "size":"1673.08", "side":"SELL", "hash":"a079324fe7a10f60eb1895f1af36f8e7e7f4f706", "best_bid":"0.98", "best_ask":"0.99"}], "timestamp":"1770241490601", "event_type":"price_change"}
{"market":"0x38f3050258345e9cf363d1c8cc302f08c65b96ba1a4669d81e07ed69708344df", "price_changes":[{"asset_id":"81916206347121459497221114766050949090435061493822476265356047392175668050706", "price":"0.01", "size":"1700.08", "side":"BUY", "hash":"4202b3c7b77ff9e6127262005bca57855588d986", "best_bid":"0.01", "best_ask":"0.02"}, {"asset_id":"96888240988495161476033313796107536512663280794332045579302109906525918376981", "price":"0.99", "size":"1700.08", "side":"SELL", "hash":"4fe74d832cb68c6d4ecd481cad9e9af03fc48c1b", "best_bid":"0.98", "best_ask":"0.99"}], "timestamp":"1770241490603", "event_type":"price_change"}
{"market":"0x38f3050258345e9cf363d1c8cc302f08c65b96ba1a4669d81e07ed69708344df", "price_changes":[{"asset_id":"96888240988495161476033313796107536512663280794332045579302109906525918376981", "price":"0.97", "size":"505.32", "side":"BUY", "hash":"4ef904a214a4ab1124050d97b62fd1db72fbd675", "best_bid":"0.98", "best_ask":"0.99"}, {"asset_id":"81916206347121459497221114766050949090435061493822476265356047392175668050706", "price":"0.03", "size":"505.32", "side":"SELL", "hash":"9f8605ecc817b5fde6ddcc1a2641ce44c2b6b273", "best_bid":"0.01", "best_ask":"0.02"}], "timestamp":"1770241490812", "event_type":"price_change"}
{"market":"0x38f3050258345e9cf363d1c8cc302f08c65b96ba1a4669d81e07ed69708344df", "price_changes":[{"asset_id":"96888240988495161476033313796107536512663280794332045579302109906525918376981", "price":"0.96", "size":"606.73", "side":"BUY", "hash":"499fe87997c7a4d05a540ab58ec5c9ad91f45711", "best_bid":"0.98", "best_ask":"0.99"}, {"asset_id":"81916206347121459497221114766050949090435061493822476265356047392175668050706", "price":"0.04", "size":"606.73", "side":"SELL", "hash":"3d45ed69375b546adbbc36492d589401f019e8b1", "best_bid":"0.01", "best_ask":"0.02"}], "timestamp":"1770241490818", "event_type":"price_change"}
{"market":"0x38f3050258345e9cf363d1c8cc302f08c65b96ba1a4669d81e07ed69708344df", "price_changes":[{"asset_id":"96888240988495161476033313796107536512663280794332045579302109906525918376981", "price":"0.96", "size":"586.73", "side":"BUY", "hash":"bdb33813da4dc65adb548191cac03989a966904d", "best_bid":"0.98", "best_ask":"0.99"}, {"asset_id":"81916206347121459497221114766050949090435061493822476265356047392175668050706", "price":"0.04", "size":"586.73", "side":"SELL", "hash":"784bd77930981cad35a0d749ff0e32513f9a2bc7", "best_bid":"0.01", "best_ask":"0.02"}], "timestamp":"1770241490839", "event_type":"price_change"}
{"market":"0x38f3050258345e9cf363d1c8cc302f08c65b96ba1a4669d81e07ed69708344df", "price_changes":[{"asset_id":"81916206347121459497221114766050949090435061493822476265356047392175668050706", "price":"0.01", "size":"1673.08", "side":"BUY", "hash":"e53b5c8d1f6b7024b4ea215d6edd231a965e39d2", "best_bid":"0.01", "best_ask":"0.02"}, {"asset_id":"96888240988495161476033313796107536512663280794332045579302109906525918376981", "price":"0.99", "size":"1673.08", "side":"SELL", "hash":"f583740f4d22a9542c6f436c80b1fc8dfb249e84", "best_bid":"0.98", "best_ask":"0.99"}], "timestamp":"1770241490925", "event_type":"price_change"}
{"market":"0x38f3050258345e9cf363d1c8cc302f08c65b96ba1a4669d81e07ed69708344df", "price_changes":[{"asset_id":"81916206347121459497221114766050949090435061493822476265356047392175668050706", "price":"0.01", "size":"1700.08", "side":"BUY", "hash":"0ad8991d5ebb28e47d61c55cd67e0d4bad5fed05", "best_bid":"0.01", "best_ask":"0.02"}, {"asset_id":"96888240988495161476033313796107536512663280794332045579302109906525918376981", "price":"0.99", "size":"1700.08", "side":"SELL", "hash":"bf02eed9cc19f20f18cac2e708dce2482f2c8ad5", "best_bid":"0.98", "best_ask":"0.99"}], "timestamp":"1770241490928", "event_type":"price_change"}
{"market":"0x38f3050258345e9cf363d1c8cc302f08c65b96ba1a4669d81e07ed69708344df", "price_changes":[{"asset_id":"81916206347121459497221114766050949090435061493822476265356047392175668050706", "price":"0.01", "size":"1673.08", "side":"BUY", "hash":"a41765c9b2e5d1a726bc5102ca5f2e8c8ec854d9", "best_bid":"0.01", "best_ask":"0.02"}, {"asset_id":"96888240988495161476033313796107536512663280794332045579302109906525918376981", "price":"0.99", "size":"1673.08", "side":"SELL", "hash":"da559c458bb68fc8fe71bbbf8695e07191c3eea9", "best_bid":"0.98", "best_ask":"0.99"}], "timestamp":"1770241490933", "event_type":"price_change"}
{"market":"0x38f3050258345e9cf363d1c8cc302f08c65b96ba1a4669d81e07ed69708344df", "price_changes":[{"asset_id":"81916206347121459497221114766050949090435061493822476265356047392175668050706", "price":"0.01", "size":"1700.08", "side":"BUY", "hash":"b7cb34c328ae1e66ffb9f94bdd42c662ff186df5", "best_bid":"0.01", "best_ask":"0.02"}, {"asset_id":"96888240988495161476033313796107536512663280794332045579302109906525918376981", "price":"0.99", "size":"1700.08", "side":"SELL", "hash":"b941ed96222de3effb944732a06a52bf84c42883", "best_bid":"0.98", "best_ask":"0.99"}], "timestamp":"1770241490935", "event_type":"price_change"}
{"market":"0x38f3050258345e9cf363d1c8cc302f08c65b96ba1a4669d81e07ed69708344df", "price_changes":[{"asset_id":"96888240988495161476033313796107536512663280794332045579302109906525918376981", "price":"0.96", "size":"613.73", "side":"BUY", "hash":"9517701d7631ab48f323b9df1f53dd72fa8e1aa5", "best_bid":"0.98", "best_ask":"0.99"}, {"asset_id":"81916206347121459497221114766050949090435061493822476265356047392175668050706", "price":"0.04", "size":"613.73", "side":"SELL", "hash":"8ac12c3052509fe697be3d4f6d74256b7634b190", "best_bid":"0.01", "best_ask":"0.02"}], "timestamp":"1770241490936", "event_type":"price_change"}
{"market":"0x38f3050258345e9cf363d1c8cc302f08c65b96ba1a4669d81e07ed69708344df", "price_changes":[{"asset_id":"96888240988495161476033313796107536512663280794332045579302109906525918376981", "price":"0.97", "size":"478.32", "side":"BUY", "hash":"fd7cab304d5ca21a99f470f0a0fe6fd6a36a1e1c", "best_bid":"0.98", "best_ask":"0.99"}, {"asset_id":"81916206347121459497221114766050949090435061493822476265356047392175668050706", "price":"0.03", "size":"478.32", "side":"SELL", "hash":"7b41fe659454a834d1c528f5709c1c48f2eebe89", "best_bid":"0.01", "best_ask":"0.02"}], "timestamp":"1770241490937", "event_type":"price_change"}
{"market":"0x38f3050258345e9cf363d1c8cc302f08c65b96ba1a4669d81e07ed69708344df", "price_changes":[{"asset_id":"96888240988495161476033313796107536512663280794332045579302109906525918376981", "price":"0.99", "size":"1709.08", "side":"SELL", "hash":"bde97c1f04adb5201e36209e5e8d73b2b8858844", "best_bid":"0.98", "best_ask":"0.99"}, {"asset_id":"81916206347121459497221114766050949090435061493822476265356047392175668050706", "price":"0.01", "size":"1709.08", "side":"BUY", "hash":"0988d0acc0d8dd1e8f3cd4cfe40ce692512f6225", "best_bid":"0.01", "best_ask":"0.02"}], "timestamp":"1770241490968", "event_type":"price_change"}
{"market":"0x38f3050258345e9cf363d1c8cc302f08c65b96ba1a4669d81e07ed69708344df", "price_changes":[{"asset_id":"96888240988495161476033313796107536512663280794332045579302109906525918376981", "price":"0.99", "size":"1704.92", "side":"SELL", "hash":"d720c0188271ac10b285d2c79ccc188d4b465cad", "best_bid":"0.98", "best_ask":"0.99"}, {"asset_id":"81916206347121459497221114766050949090435061493822476265356047392175668050706", "price":"0.01", "size":"1704.92", "side":"BUY", "hash":"7bfc2e2d15293d9d2d4b04ea0071214fc82cfee8", "best_bid":"0.01", "best_ask":"0.02"}], "timestamp":"1770241490992", "event_type":"price_change"}
{"market":"0x38f3050258345e9cf363d1c8cc302f08c65b96ba1a4669d81e07ed69708344df", "asset_id":"81916206347121459497221114766050949090435061493822476265356047392175668050706", "bids":[{"price":"0.01", "size":"1704.92"}], "asks":[{"price":"0.99", "size":"5019.91"}, {"price":"0.98", "size":"3034.23"}, {"price":"0.97", "size":"3172"}, {"price":"0.96", "size":"3012"}, {"price":"0.95", "size":"3032"}, {"price":"0.94", "size":"3012"}, {"price":"0.93", "size":"3126.28"}, {"price":"0.92", "size":"3012"}, {"price":"0.91", "size":"3012"}, {"price":"0.9", "size":"3087"}, {"price":"0.89", "size":"12"}, {"price":"0.88", "size":"12"}, {"price":"0.87", "size":"12"}, {"price":"0.86", "size":"12"}, {"price":"0.85", "size":"12"}, {"price":"0.84", "size":"12"}, {"price":"0.83", "size":"12"}, {"price":"0.82", "size":"12"}, {"price":"0.81", "size":"12"}, {"price":"0.8", "size":"12"}, {"price":"0.79", "size":"12"}, {"price":"0.78", "size":"12"}, {"price":"0.77", "size":"12"}, {"price":"0.76", "size":"112"}, {"price":"0.75", "size":"40.57"}, {"price":"0.74", "size":"12"}, {"price":"0.73", "size":"293.25"}, {"price":"0.72", "size":"22"}, {"price":"0.71", "size":"12"}, {"price":"0.7", "size":"18"}, {"price":"0.69", "size":"12"}, {"price":"0.68", "size":"12"}, {"price":"0.67", "size":"12"}, {"price":"0.66", "size":"160.89"}, {"price":"0.65", "size":"12"}, {"price":"0.64", "size":"12"}, {"price":"0.63", "size":"12"}, {"price":"0.62", "size":"19.39"}, {"price":"0.61", "size":"18.04"}, {"price":"0.6", "size":"12"}, {"price":"0.59", "size":"94.31"}, {"price":"0.58", "size":"5450.54"}, {"price":"0.57", "size":"12"}, {"price":"0.56", "size":"12"}, {"price":"0.55", "size":"12"}, {"price":"0.54", "size":"22"}, {"price":"0.53", "size":"12"}, {"price":"0.52", "size":"12"}, {"price":"0.51", "size":"12"}, {"price":"0.5", "size":"12"}, {"price":"0.49", "size":"12"}, {"price":"0.48", "size":"12"}, {"price":"0.47", "size":"12"}, {"price":"0.46", "size":"485.56"}, {"price":"0.45", "size":"31"}, {"price":"0.44", "size":"17"}, {"price":"0.43", "size":"12"}, {"price":"0.42", "size":"12"}, {"price":"0.41", "size":"12"}, {"price":"0.4", "size":"127"}, {"price":"0.39", "size":"12"}, {"price":"0.38", "size":"114.5"}, {"price":"0.37", "size":"12"}, {"price":"0.36", "size":"12"}, {"price":"0.35", "size":"37"}, {"price":"0.34", "size":"12"}, {"price":"0.33", "size":"12"}, {"price":"0.32", "size":"12"}, {"price":"0.31", "size":"12"}, {"price":"0.3", "size":"31.9"}, {"price":"0.29", "size":"344"}, {"price":"0.28", "size":"3288.99"}, {"price":"0.27", "size":"212"}, {"price":"0.26", "size":"218"}, {"price":"0.25", "size":"212"}, {"price":"0.24", "size":"212"}, {"price":"0.23", "size":"212"}, {"price":"0.22", "size":"1223.14"}, {"price":"0.21", "size":"712"}, {"price":"0.2", "size":"472.99"}, {"price":"0.19", "size":"212"}, {"price":"0.18", "size":"212"}, {"price":"0.17", "size":"212"}, {"price":"0.16", "size":"812"}, {"price":"0.15", "size":"231.08"}, {"price":"0.14", "size":"283.65"}, {"price":"0.13", "size":"212"}, {"price":"0.12", "size":"212"}, {"price":"0.11", "size":"212"}, {"price":"0.1", "size":"697.71"}, {"price":"0.09", "size":"221"}, {"price":"0.08", "size":"804.68"}, {"price":"0.07", "size":"286"}, {"price":"0.06", "size":"891"}, {"price":"0.05", "size":"645"}, {"price":"0.04", "size":"613.73"}, {"price":"0.03", "size":"478.32"}, {"price":"0.02", "size":"681.8"}], "hash":"7bfc2e2d15293d9d2d4b04ea0071214fc82cfee8", "timestamp":"1770241490992", "event_type":"book"}
{"market":"0x38f3050258345e9cf363d1c8cc302f08c65b96ba1a4669d81e07ed69708344df", "price_changes":[{"asset_id":"96888240988495161476033313796107536512663280794332045579302109906525918376981", "price":"0.96", "size":"590.73", "side":"BUY", "hash":"6eba3033a7cd50e3101ac3e48f5f035d80785598", "best_bid":"0.98", "best_ask":"0.99"}, {"asset_id":"81916206347121459497221114766050949090435061493822476265356047392175668050706", "price":"0.04", "size":"590.73", "side":"SELL", "hash":"c85bcb1f3dc2437e117429caf4bffe939a216d86", "best_bid":"0.01", "best_ask":"0.02"}], "timestamp":"1770241491057", "event_type":"price_change"}
{"market":"0x38f3050258345e9cf363d1c8cc302f08c65b96ba1a4669d81e07ed69708344df", "price_changes":[{"asset_id":"96888240988495161476033313796107536512663280794332045579302109906525918376981", "price":"0.97", "size":"501.32", "side":"BUY", "hash":"e5d3a8bc0be46cc391de221762b18b736f1abfdb", "best_bid":"0.98", "best_ask":"0.99"}, {"asset_id":"81916206347121459497221114766050949090435061493822476265356047392175668050706", "price":"0.03", "size":"501.32", "side":"SELL", "hash":"96ca65b58d0085a3945db2aa9d616ff75917e1f8", "best_bid":"0.01", "best_ask":"0.02"}], "timestamp":"1770241491058", "event_type":"price_change"}
{"market":"0x38f3050258345e9cf363d1c8cc302f08c65b96ba1a4669d81e07ed69708344df", "price_changes":[{"asset_id":"96888240988495161476033313796107536512663280794332045579302109906525918376981", "price":"0.96", "size":"563.73", "side":"BUY", "hash":"08b6a4c76e9cd81a916b2071ec6424adaa9c61bb", "best_bid":"0.98", "best_ask":"0.99"}, {"asset_id":"81916206347121459497221114766050949090435061493822476265356047392175668050706", "price":"0.04", "size":"563.73", "side":"SELL", "hash":"b5674863f46b5dbabb260bc2040f9be9da25cf93", "best_bid":"0.01", "best_ask":"0.02"}], "timestamp":"1770241491091", "event_type":"price_change"}
{"market":"0x38f3050258345e9cf363d1c8cc302f08c65b96ba1a4669d81e07ed69708344df", "price_changes":[{"asset_id":"96888240988495161476033313796107536512663280794332045579302109906525918376981", "price":"0.97", "size":"528.32", "side":"BUY", "hash":"399a1244627d7d6051d43482c0c390a078390790", "best_bid":"0.98", "best_ask":"0.99"}, {"asset_id":"81916206347121459497221114766050949090435061493822476265356047392175668050706", "price":"0.03", "size":"528.32", "side":"SELL", "hash":"848782f5937833740f94975ea5ed76381b80efbc", "best_bid":"0.01", "best_ask":"0.02"}], "timestamp":"1770241491095", "event_type":"price_change"}
{"market":"0x38f3050258345e9cf363d1c8cc302f08c65b96ba1a4669d81e07ed69708344df", "price_changes":[{"asset_id":"96888240988495161476033313796107536512663280794332045579302109906525918376981", "price":"0.97", "size":"505.32", "side":"BUY", "hash":"ae157441769dedb1297d2cf319ba3dcd1ff360b8", "best_bid":"0.98", "best_ask":"0.99"}, {"asset_id":"81916206347121459497221114766050949090435061493822476265356047392175668050706", "price":"0.03", "size":"505.32", "side":"SELL", "hash":"f9eb608ca00a8ffa6bcc3a05dfcc2d9f245ec777", "best_bid":"0.01", "best_ask":"0.02"}], "timestamp":"1770241491341", "event_type":"price_change"}
{"market":"0x38f3050258345e9cf363d1c8cc302f08c65b96ba1a4669d81e07ed69708344df", "price_changes":[{"asset_id":"96888240988495161476033313796107536512663280794332045579302109906525918376981", "price":"0.96", "size":"586.73", "side":"BUY", "hash":"5f87fabd1334763c559d975b1d5fa7892a4cdb2b", "best_bid":"0.98", "best_ask":"0.99"}, {"asset_id":"81916206347121459497221114766050949090435061493822476265356047392175668050706", "price":"0.04", "size":"586.73", "side":"SELL", "hash":"78c6e7d167e510efdf7d66814bb777c34d725f47", "best_bid":"0.01", "best_ask":"0.02"}], "timestamp":"1770241491342", "event_type":"price_change"}
{"market":"0x38f3050258345e9cf363d1c8cc302f08c65b96ba1a4669d81e07ed69708344df", "price_changes":[{"asset_id":"96888240988495161476033313796107536512663280794332045579302109906525918376981", "price":"0.97", "size":"293.18", "side":"BUY", "hash":"e29e3a2dd165e639f9cadbe9470ecc6affb57a0a", "best_bid":"0.97", "best_ask":"0.99"}, {"asset_id":"81916206347121459497221114766050949090435061493822476265356047392175668050706", "price":"0.03", "size":"293.18", "side":"SELL", "hash":"0e88667677a8b64ceed86b5391bbbcf6edb7f2b2", "best_bid":"0.01", "best_ask":"0.03"}], "timestamp":"1770241491361", "event_type":"price_change"}
{"market":"0x38f3050258345e9cf363d1c8cc302f08c65b96ba1a4669d81e07ed69708344df", "price_changes":[{"asset_id":"96888240988495161476033313796107536512663280794332045579302109906525918376981", "price":"0.98", "size":"0", "side":"BUY", "hash":"e29e3a2dd165e639f9cadbe9470ecc6affb57a0a", "best_bid":"0.97", "best_ask":"0.99"}, {"asset_id":"81916206347121459497221114766050949090435061493822476265356047392175668050706", "price":"0.02", "size":"0", "side":"SELL", "hash":"0e88667677a8b64ceed86b5391bbbcf6edb7f2b2", "best_bid":"0.01", "best_ask":"0.03"}], "timestamp":"1770241491361", "event_type":"price_change"}
{"market":"0x38f3050258345e9cf363d1c8cc302f08c65b96ba1a4669d81e07ed69708344df", "asset_id":"81916206347121459497221114766050949090435061493822476265356047392175668050706", "bids":[{"price":"0.01", "size":"1704.92"}], "asks":[{"price":"0.99", "size":"5019.91"}, {"price":"0.98", "size":"3034.23"}, {"price":"0.97", "size":"3172"}, {"price":"0.96", "size":"3012"}, {"price":"0.95", "size":"3032"}, {"price":"0.94", "size":"3012"}, {"price":"0.93", "size":"3126.28"}, {"price":"0.92", "size":"3012"}, {"price":"0.91", "size":"3012"}, {"price":"0.9", "size":"3087"}, {"price":"0.89", "size":"12"}, {"price":"0.88", "size":"12"}, {"price":"0.87", "size":"12"}, {"price":"0.86", "size":"12"}, {"price":"0.85", "size":"12"}, {"price":"0.84", "size":"12"}, {"price":"0.83", "size":"12"}, {"price":"0.82", "size":"12"}, {"price":"0.81", "size":"12"}, {"price":"0.8", "size":"12"}, {"price":"0.79", "size":"12"}, {"price":"0.78", "size":"12"}, {"price":"0.77", "size":"12"}, {"price":"0.76", "size":"112"}, {"price":"0.75", "size":"40.57"}, {"price":"0.74", "size":"12"}, {"price":"0.73", "size":"293.25"}, {"price":"0.72", "size":"22"}, {"price":"0.71", "size":"12"}, {"price":"0.7", "size":"18"}, {"price":"0.69", "size":"12"}, {"price":"0.68", "size":"12"}, {"price":"0.67", "size":"12"}, {"price":"0.66", "size":"160.89"}, {"price":"0.65", "size":"12"}, {"price":"0.64", "size":"12"}, {"price":"0.63", "size":"12"}, {"price":"0.62", "size":"19.39"}, {"price":"0.61", "size":"18.04"}, {"price":"0.6", "size":"12"}, {"price":"0.59", "size":"94.31"}, {"price":"0.58", "size":"5450.54"}, {"price":"0.57", "size":"12"}, {"price":"0.56", "size":"12"}, {"price":"0.55", "size":"12"}, {"price":"0.54", "size":"22"}, {"price":"0.53", "size":"12"}, {"price":"0.52", "size":"12"}, {"price":"0.51", "size":"12"}, {"price":"0.5", "size":"12"}, {"price":"0.49", "size":"12"}, {"price":"0.48", "size":"12"}, {"price":"0.47", "size":"12"}, {"price":"0.46", "size":"485.56"}, {"price":"0.45", "size":"31"}, {"price":"0.44", "size":"17"}, {"price":"0.43", "size":"12"}, {"price":"0.42", "size":"12"}, {"price":"0.41", "size":"12"}, {"price":"0.4", "size":"127"}, {"price":"0.39", "size":"12"}, {"price":"0.38", "size":"114.5"}, {"price":"0.37", "size":"12"}, {"price":"0.36", "size":"12"}, {"price":"0.35", "size":"37"}, {"price":"0.34", "size":"12"}, {"price":"0.33", "size":"12"}, {"price":"0.32", "size":"12"}, {"price":"0.31", "size":"12"}, {"price":"0.3", "size":"31.9"}, {"price":"0.29", "size":"344"}, {"price":"0.28", "size":"3288.99"}, {"price":"0.27", "size":"212"}, {"price":"0.26", "size":"218"}, {"price":"0.25", "size":"212"}, {"price":"0.24", "size":"212"}, {"price":"0.23", "size":"212"}, {"price":"0.22", "size":"1223.14"}, {"price":"0.21", "size":"712"}, {"price":"0.2", "size":"472.99"}, {"price":"0.19", "size":"212"}, {"price":"0.18", "size":"212"}, {"price":"0.17", "size":"212"}, {"price":"0.16", "size":"812"}, {"price":"0.15", "size":"231.08"}, {"price":"0.14", "size":"283.65"}, {"price":"0.13", "size":"212"}, {"price":"0.12", "size":"212"}, {"price":"0.11", "size":"212"}, {"price":"0.1", "size":"697.71"}, {"price":"0.09", "size":"221"}, {"price":"0.08", "size":"804.68"}, {"price":"0.07", "size":"286"}, {"price":"0.06", "size":"891"}, {"price":"0.05", "size":"645"}, {"price":"0.04", "size":"586.73"}, {"price":"0.03", "size":"293.18"}], "hash":"0e88667677a8b64ceed86b5391bbbcf6edb7f2b2", "timestamp":"1770241491361", "event_type":"book"}
{"market":"0x38f3050258345e9cf363d1c8cc302f08c65b96ba1a4669d81e07ed69708344df", "price_changes":[{"asset_id":"96888240988495161476033313796107536512663280794332045579302109906525918376981", "price":"0.95", "size":"618", "side":"BUY", "hash":"ed10973336a3b4bc07f5eebc71886d6bc385e50f", "best_bid":"0.97", "best_ask":"0.99"}, {"asset_id":"81916206347121459497221114766050949090435061493822476265356047392175668050706", "price":"0.05", "size":"618", "side":"SELL", "hash":"e8db7434778bf70108cbec998a834d7458062ae0", "best_bid":"0.01", "best_ask":"0.03"}], "timestamp":"1770241491386", "event_type":"price_change"}
{"market":"0x38f3050258345e9cf363d1c8cc302f08c65b96ba1a4669d81e07ed69708344df", "price_changes":[{"asset_id":"81916206347121459497221114766050949090435061493822476265356047392175668050706", "price":"0.01", "size":"1677.92", "side":"BUY", "hash":"fe784d3acd752e99eee214f62544949f807fec75", "best_bid":"0.01", "best_ask":"0.03"}, {"asset_id":"96888240988495161476033313796107536512663280794332045579302109906525918376981", "price":"0.99", "size":"1677.92", "side":"SELL", "hash":"d11c616f136f2bcbd8c9cbe67634525ab863576f", "best_bid":"0.97", "best_ask":"0.99"}], "timestamp":"1770241491387", "event_type":"price_change"}
{"market":"0x38f3050258345e9cf363d1c8cc302f08c65b96ba1a4669d81e07ed69708344df", "price_changes":[{"asset_id":"96888240988495161476033313796107536512663280794332045579302109906525918376981", "price":"0.95", "size":"645", "side":"BUY", "hash":"5fc9c256211e186c8d96c13f8265e457766b4045", "best_bid":"0.97", "best_ask":"0.99"}, {"asset_id":"81916206347121459497221114766050949090435061493822476265356047392175668050706", "price":"0.05", "size":"645", "side":"SELL", "hash":"8930930df9a1d430c04de0db9afbf50a4f5a9c9f", "best_bid":"0.01", "best_ask":"0.03"}], "timestamp":"1770241491388", "event_type":"price_change"}
{"market":"0x38f3050258345e9cf363d1c8cc302f08c65b96ba1a4669d81e07ed69708344df", "price_changes":[{"asset_id":"96888240988495161476033313796107536512663280794332045579302109906525918376981", "price":"0.97", "size":"266.18", "side":"BUY", "hash":"c927754e80563f12acc46752dbd4cbfbf95b1b87", "best_bid":"0.97", "best_ask":"0.99"}, {"asset_id":"81916206347121459497221114766050949090435061493822476265356047392175668050706", "price":"0.03", "size":"266.18", "side":"SELL", "hash":"14a39ce9f0a8e4c522e44ecb95267db7e8d5647b", "best_bid":"0.01", "best_ask":"0.03"}], "timestamp":"1770241491388", "event_type":"price_change"}
{"market":"0x38f3050258345e9cf363d1c8cc302f08c65b96ba1a4669d81e07ed69708344df", "price_changes":[{"asset_id":"96888240988495161476033313796107536512663280794332045579302109906525918376981", "price":"0.96", "size":"613.73", "side":"BUY", "hash":"2f71ebb5ae034a62852bd16798f80118d80ace04", "best_bid":"0.97", "best_ask":"0.99"}, {"asset_id":"81916206347121459497221114766050949090435061493822476265356047392175668050706", "price":"0.04", "size":"613.73", "side":"SELL", "hash":"a5b07545bf07173e09f1daf9d0867f66389383a9", "best_bid":"0.01", "best_ask":"0.03"}], "timestamp":"1770241491389", "event_type":"price_change"}
{"market":"0x38f3050258345e9cf363d1c8cc302f08c65b96ba1a4669d81e07ed69708344df", "price_changes":[{"asset_id":"81916206347121459497221114766050949090435061493822476265356047392175668050706", "price":"0.01", "size":"1704.92", "side":"BUY", "hash":"e04c6aac1ef33fd02dfa4d625ce277b03ab45278", "best_bid":"0.01", "best_ask":"0.03"}, {"asset_id":"96888240988495161476033313796107536512663280794332045579302109906525918376981", "price":"0.99", "size":"1704.92", "side":"SELL", "hash":"fd5bcaedfe1e689fe845ba2931442202bba7f2f8", "best_bid":"0.97", "best_ask":"0.99"}], "timestamp":"1770241491390", "event_type":"price_change"}
{"market":"0x38f3050258345e9cf363d1c8cc302f08c65b96ba1a4669d81e07ed69708344df", "price_changes":[{"asset_id":"96888240988495161476033313796107536512663280794332045579302109906525918376981", "price":"0.95", "size":"672", "side":"BUY", "hash":"7ea37bfe5696b215140e232ec9ce0707acdf0c09", "best_bid":"0.97", "best_ask":"0.99"}, {"asset_id":"81916206347121459497221114766050949090435061493822476265356047392175668050706", "price":"0.05", "size":"672", "side":"SELL", "hash":"d021b25c0ea3dfeda7c62f0244fb088f3569ded2", "best_bid":"0.01", "best_ask":"0.03"}], "timestamp":"1770241491390", "event_type":"price_change"}
{"market":"0x38f3050258345e9cf363d1c8cc302f08c65b96ba1a4669d81e07ed69708344df", "price_changes":[{"asset_id":"81916206347121459497221114766050949090435061493822476265356047392175668050706", "price":"0.01", "size":"1677.92", "side":"BUY", "hash":"e855ab0ce829db1bfdd02078523514ec1b5f387c", "best_bid":"0.01", "best_ask":"0.03"}, {"asset_id":"96888240988495161476033313796107536512663280794332045579302109906525918376981", "price":"0.99", "size":"1677.92", "side":"SELL", "hash":"379a111aba28bd8802104dde7b7d85018bba8d65", "best_bid":"0.97", "best_ask":"0.99"}], "timestamp":"1770241491391", "event_type":"price_change"}
{"market":"0x38f3050258345e9cf363d1c8cc302f08c65b96ba1a4669d81e07ed69708344df", "price_changes":[{"asset_id":"81916206347121459497221114766050949090435061493822476265356047392175668050706", "price":"0.01", "size":"1650.92", "side":"BUY", "hash":"f006ea4c5f2cafbc58f853014d0ecc25acbe08df", "best_bid":"0.01", "best_ask":"0.03"}, {"asset_id":"96888240988495161476033313796107536512663280794332045579302109906525918376981", "price":"0.99", "size":"1650.92", "side":"SELL", "hash":"7505e7e0d971f5a27fc71970bbae1007cf79cf37", "best_bid":"0.97", "best_ask":"0.99"}], "timestamp":"1770241491391", "event_type":"price_change"}
{"market":"0x38f3050258345e9cf363d1c8cc302f08c65b96ba1a4669d81e07ed69708344df", "price_changes":[{"asset_id":"96888240988495161476033313796107536512663280794332045579302109906525918376981", "price":"0.95", "size":"645", "side":"BUY", "hash":"d9565158fc58722105596f3341be3b5a9d9f204a", "best_bid":"0.97", "best_ask":"0.99"}, {"asset_id":"81916206347121459497221114766050949090435061493822476265356047392175668050706", "price":"0.05", "size":"645", "side":"SELL", "hash":"5e5568d840e6ec3fe8fe6ab389d213fe7816e08e", "best_bid":"0.01", "best_ask":"0.03"}], "timestamp":"1770241491391", "event_type":"price_change"}
{"market":"0x38f3050258345e9cf363d1c8cc302f08c65b96ba1a4669d81e07ed69708344df", "price_changes":[{"asset_id":"81916206347121459497221114766050949090435061493822476265356047392175668050706", "price":"0.01", "size":"1677.92", "side":"BUY", "hash":"0989176b775970bf583849c9a22a085439f7dcf9", "best_bid":"0.01", "best_ask":"0.03"}, {"asset_id":"96888240988495161476033313796107536512663280794332045579302109906525918376981", "price":"0.99", "size":"1677.92", "side":"SELL", "hash":"776d21d746de42e3853174150a8c33226716b326", "best_bid":"0.97", "best_ask":"0.99"}], "timestamp":"1770241491392", "event_type":"price_change"}
{"market":"0x38f3050258345e9cf363d1c8cc302f08c65b96ba1a4669d81e07ed69708344df", "price_changes":[{"asset_id":"96888240988495161476033313796107536512663280794332045579302109906525918376981", "price":"0.98", "size":"12", "side":"SELL", "hash":"e0a631585318c5bc256dbf47773c5916fa95aa2e", "best_bid":"0.97", "best_ask":"0.98"}, {"asset_id":"81916206347121459497221114766050949090435061493822476265356047392175668050706", "price":"0.02", "size":"12", "side":"BUY", "hash":"2357c418733c5163531befc3924dfdd066204c51", "best_bid":"0.02", "best_ask":"0.03"}], "timestamp":"1770241491393", "event_type":"price_change"}
{"market":"0x38f3050258345e9cf363d1c8cc302f08c65b96ba1a4669d81e07ed69708344df", "price_changes":[{"asset_id":"81916206347121459497221114766050949090435061493822476265356047392175668050706", "price":"0.01", "size":"1704.92", "side":"BUY", "hash":"06b705425c59274512a9b5159555d5257071d35f", "best_bid":"0.02", "best_ask":"0.03"}, {"asset_id":"96888240988495161476033313796107536512663280794332045579302109906525918376981", "price":"0.99", "size":"1704.92", "side":"SELL", "hash":"d11331767ed9d87141a40a96b834eeac8f0d6bc7", "best_bid":"0.97", "best_ask":"0.98"}], "timestamp":"1770241491394", "event_type":"price_change"}
{"market":"0x38f3050258345e9cf363d1c8cc302f08c65b96ba1a4669d81e07ed69708344df", "asset_id":"81916206347121459497221114766050949090435061493822476265356047392175668050706", "price":"0.02", "size":"893.933332", "fee_rate_bps":"0", "side":"BUY", "timestamp":"1770241491405", "event_type":"last_trade_price", "transaction_hash":"0xe00e38b9931554d440301ced20c92675303bb79201b10498614c4f340603d928"}
{"market":"0x38f3050258345e9cf363d1c8cc302f08c65b96ba1a4669d81e07ed69708344df", "price_changes":[{"asset_id":"96888240988495161476033313796107536512663280794332045579302109906525918376981", "price":"0.97", "size":"286.18", "side":"BUY", "hash":"1c3acf0031e1ed5a07f4fd3fdbc5cb3a88758264", "best_bid":"0.97", "best_ask":"0.98"}, {"asset_id":"81916206347121459497221114766050949090435061493822476265356047392175668050706", "price":"0.03", "size":"286.18", "side":"SELL", "hash":"4abe241e43bc693918417d64b587eab7479901e2", "best_bid":"0.02", "best_ask":"0.03"}], "timestamp":"1770241491417", "event_type":"price_change"}
{"market":"0x38f3050258345e9cf363d1c8cc302f08c65b96ba1a4669d81e07ed69708344df", "price_changes":[{"asset_id":"81916206347121459497221114766050949090435061493822476265356047392175668050706", "price":"0.01", "size":"1681.92", "side":"BUY", "hash":"d8cfdcc740d8b07511153f472903708ed5d32d49", "best_bid":"0.02", "best_ask":"0.03"}, {"asset_id":"96888240988495161476033313796107536512663280794332045579302109906525918376981", "price":"0.99", "size":"1681.92", "side":"SELL", "hash":"085fa26e76f68f5319273e14dc044a11977e7fdf", "best_bid":"0.97", "best_ask":"0.98"}], "timestamp":"1770241491424", "event_type":"price_change"}
{"market":"0x38f3050258345e9cf363d1c8cc302f08c65b96ba1a4669d81e07ed69708344df", "price_changes":[{"asset_id":"81916206347121459497221114766050949090435061493822476265356047392175668050706", "price":"0.1", "size":"706.71", "side":"SELL", "hash":"56bd4f45c4d3cd804d1de306c7b8001deb6e5257", "best_bid":"0.02", "best_ask":"0.03"}, {"asset_id":"96888240988495161476033313796107536512663280794332045579302109906525918376981", "price":"0.9", "size":"706.71", "side":"BUY", "hash":"4bcde356424542f71f2151fbd36b3b2df36f9ee7", "best_bid":"0.97", "best_ask":"0.98"}], "timestamp":"1770241491426", "event_type":"price_change"}
{"market":"0x38f3050258345e9cf363d1c8cc302f08c65b96ba1a4669d81e07ed69708344df", "price_changes":[{"asset_id":"81916206347121459497221114766050949090435061493822476265356047392175668050706", "price":"0.01", "size":"1707.92", "side":"BUY", "hash":"4d925be16b880bf43aaf6b15b6c6785d9a15b42d", "best_bid":"0.02", "best_ask":"0.03"}, {"asset_id":"96888240988495161476033313796107536512663280794332045579302109906525918376981", "price":"0.99", "size":"1707.92", "side":"SELL", "hash":"e9eb4f13b8bb723cfdcf49842ca951497cac4565", "best_bid":"0.97", "best_ask":"0.98"}], "timestamp":"1770241491434", "event_type":"price_change"}
{"market":"0x38f3050258345e9cf363d1c8cc302f08c65b96ba1a4669d81e07ed69708344df", "price_changes":[{"asset_id":"81916206347121459497221114766050949090435061493822476265356047392175668050706", "price":"0.05", "size":"636", "side":"SELL", "hash":"fa24432a1707aabe8366f1fdbd07c17e520b2eb1", "best_bid":"0.02", "best_ask":"0.03"}, {"asset_id":"96888240988495161476033313796107536512663280794332045579302109906525918376981", "price":"0.95", "size":"636", "side":"BUY", "hash":"733618ef158f364a706b46419c48e2b2eca1daaf", "best_bid":"0.97", "best_ask":"0.98"}], "timestamp":"1770241491435", "event_type":"price_change"}
{"market":"0x38f3050258345e9cf363d1c8cc302f08c65b96ba1a4669d81e07ed69708344df", "price_changes":[{"asset_id":"81916206347121459497221114766050949090435061493822476265356047392175668050706", "price":"0.01", "size":"1733.92", "side":"BUY", "hash":"1c2f076ddc04a74961525a75841f1e83ecbfa12b", "best_bid":"0.02", "best_ask":"0.03"}, {"asset_id":"96888240988495161476033313796107536512663280794332045579302109906525918376981", "price":"0.99", "size":"1733.92", "side":"SELL", "hash":"6dab6d8a32410cf2e8e3e4fe5d2d01103279e71d", "best_bid":"0.97", "best_ask":"0.98"}], "timestamp":"1770241491444", "event_type":"price_change"}
{"market":"0x38f3050258345e9cf363d1c8cc302f08c65b96ba1a4669d81e07ed69708344df", "price_changes":[{"asset_id":"81916206347121459497221114766050949090435061493822476265356047392175668050706", "price":"0.02", "size":"38", "side":"BUY", "hash":"3fffb1ddaf97e3895fb84b704e61534802f9af5d", "best_bid":"0.02", "best_ask":"0.03"}, {"asset_id":"96888240988495161476033313796107536512663280794332045579302109906525918376981", "price":"0.98", "size":"38", "side":"SELL", "hash":"82932fb03df1993535199d5adb2b42a1710cfaa4", "best_bid":"0.97", "best_ask":"0.98"}], "timestamp":"1770241491457", "event_type":"price_change"}
{"market":"0x38f3050258345e9cf363d1c8cc302f08c65b96ba1a4669d81e07ed69708344df", "price_changes":[{"asset_id":"81916206347121459497221114766050949090435061493822476265356047392175668050706", "price":"0.02", "size":"64", "side":"BUY", "hash":"4d16f2076df786246213c0ed7f0908811931e961", "best_bid":"0.02", "best_ask":"0.03"}, {"asset_id":"96888240988495161476033313796107536512663280794332045579302109906525918376981", "price":"0.98", "size":"64", "side":"SELL", "hash":"0b83cbf1698486f90cb3b85771da8d154dc8dfb4", "best_bid":"0.97", "best_ask":"0.98"}], "timestamp":"1770241491471", "event_type":"price_change"}
{"market":"0x38f3050258345e9cf363d1c8cc302f08c65b96ba1a4669d81e07ed69708344df", "price_changes":[{"asset_id":"81916206347121459497221114766050949090435061493822476265356047392175668050706", "price":"0.02", "size":"90", "side":"BUY", "hash":"bc4f08af535691ff7ced049924d8d4ad226a9ed4", "best_bid":"0.02", "best_ask":"0.03"}, {"asset_id":"96888240988495161476033313796107536512663280794332045579302109906525918376981", "price":"0.98", "size":"90", "side":"SELL", "hash":"7fb2891d23c7fc9b94c732f0d889e1c7efa8d93f", "best_bid":"0.97", "best_ask":"0.98"}], "timestamp":"1770241491472", "event_type":"price_change"}
{"market":"0x38f3050258345e9cf363d1c8cc302f08c65b96ba1a4669d81e07ed69708344df", "price_changes":[{"asset_id":"96888240988495161476033313796107536512663280794332045579302109906525918376981", "price":"0.99", "size":"1724.92", "side":"SELL", "hash":"28cac017c9e6672faf75eaf263136bf7d067ce6a", "best_bid":"0.97", "best_ask":"0.98"}, {"asset_id":"81916206347121459497221114766050949090435061493822476265356047392175668050706", "price":"0.01", "size":"1724.92", "side":"BUY", "hash":"3aa3b777fad1fc6cc21cc4cb245d483f2b389c18", "best_bid":"0.02", "best_ask":"0.03"}], "timestamp":"1770241491479", "event_type":"price_change"}
{"market":"0x38f3050258345e9cf363d1c8cc302f08c65b96ba1a4669d81e07ed69708344df", "price_changes":[{"asset_id":"96888240988495161476033313796107536512663280794332045579302109906525918376981", "price":"0.97", "size":"260.18", "side":"BUY", "hash":"8f44a4c230c89e23a3cb886a7b6ea48ab8740ee6", "best_bid":"0.97", "best_ask":"0.98"}, {"asset_id":"81916206347121459497221114766050949090435061493822476265356047392175668050706", "price":"0.03", "size":"260.18", "side":"SELL", "hash":"f9a15cd1b2ecc70b643896b0a141c423c629134d", "best_bid":"0.02", "best_ask":"0.03"}], "timestamp":"1770241491489", "event_type":"price_change"}
{"market":"0x38f3050258345e9cf363d1c8cc302f08c65b96ba1a4669d81e07ed69708344df", "price_changes":[{"asset_id":"96888240988495161476033313796107536512663280794332045579302109906525918376981", "price":"0.97", "size":"234.18", "side":"BUY", "hash":"ca6aa738a2d75768cca2b33ffdb48e648e8cd2bd", "best_bid":"0.97", "best_ask":"0.98"}, {"asset_id":"81916206347121459497221114766050949090435061493822476265356047392175668050706", "price":"0.03", "size":"234.18", "side":"SELL", "hash":"d7aef06a103f07fac2d316373abf3371cc50ff2b", "best_bid":"0.02", "best_ask":"0.03"}], "timestamp":"1770241491491", "event_type":"price_change"}
{"market":"0x38f3050258345e9cf363d1c8cc302f08c65b96ba1a4669d81e07ed69708344df", "price_changes":[{"asset_id":"81916206347121459497221114766050949090435061493822476265356047392175668050706", "price":"0.02", "size":"116", "side":"BUY", "hash":"ad39a130ef684b882ae9278e22e6b064f0338622", "best_bid":"0.02", "best_ask":"0.03"}, {"asset_id":"96888240988495161476033313796107536512663280794332045579302109906525918376981", "price":"0.98", "size":"116", "side":"SELL", "hash":"dd712ea8b5713b7de76aeae104b2b806c86b4334", "best_bid":"0.97", "best_ask":"0.98"}], "timestamp":"1770241491494", "event_type":"price_change"}
{"market":"0x38f3050258345e9cf363d1c8cc302f08c65b96ba1a4669d81e07ed69708344df", "price_changes":[{"asset_id":"81916206347121459497221114766050949090435061493822476265356047392175668050706", "price":"0.01", "size":"1697.92", "side":"BUY", "hash":"fea444ac43aa15161bb1aa70e9a827915d322697", "best_bid":"0.02", "best_ask":"0.03"}, {"asset_id":"96888240988495161476033313796107536512663280794332045579302109906525918376981", "price":"0.99", "size":"1697.92", "side":"SELL", "hash":"5834d5889d1203894454dce3cbbc1b14eaeb2634", "best_bid":"0.97", "best_ask":"0.98"}], "timestamp":"1770241491505", "event_type":"price_change"}
{"market":"0x38f3050258345e9cf363d1c8cc302f08c65b96ba1a4669d81e07ed69708344df", "price_changes":[{"asset_id":"96888240988495161476033313796107536512663280794332045579302109906525918376981", "price":"0.95", "size":"609", "side":"BUY", "hash":"e8a457497531566aa69e07c2a9f9df14c1aea9c2", "best_bid":"0.97", "best_ask":"0.98"}, {"asset_id":"81916206347121459497221114766050949090435061493822476265356047392175668050706", "price":"0.05", "size":"609", "side":"SELL", "hash":"3ae6afde2b9e8ebd08bb620242eb8e55675c7e2f", "best_bid":"0.02", "best_ask":"0.03"}], "timestamp":"1770241491506", "event_type":"price_change"}
{"market":"0x38f3050258345e9cf363d1c8cc302f08c65b96ba1a4669d81e07ed69708344df", "price_changes":[{"asset_id":"81916206347121459497221114766050949090435061493822476265356047392175668050706", "price":"0.01", "size":"1724.92", "side":"BUY", "hash":"67fa82e456518119adbfd1ad8431d8723bb2623a", "best_bid":"0.02", "best_ask":"0.03"}, {"asset_id":"96888240988495161476033313796107536512663280794332045579302109906525918376981", "price":"0.99", "size":"1724.92", "side":"SELL", "hash":"87e71de1e1b2d7d1309571dcc67b145740cff7e0", "best_bid":"0.97", "best_ask":"0.98"}], "timestamp":"1770241491508", "event_type":"price_change"}
{"market":"0x38f3050258345e9cf363d1c8cc302f08c65b96ba1a4669d81e07ed69708344df", "price_changes":[{"asset_id":"96888240988495161476033313796107536512663280794332045579302109906525918376981", "price":"0.95", "size":"636", "side":"BUY", "hash":"fe1fd29731ca477daaffb27a5ebd144b0547c31a", "best_bid":"0.97", "best_ask":"0.98"}, {"asset_id":"81916206347121459497221114766050949090435061493822476265356047392175668050706", "price":"0.05", "size":"636", "side":"SELL", "hash":"3e7374da57d557655d721cbb18e24d042c41ea0c", "best_bid":"0.02", "best_ask":"0.03"}], "timestamp":"1770241491509", "event_type":"price_change"}
{"market":"0x38f3050258345e9cf363d1c8cc302f08c65b96ba1a4669d81e07ed69708344df", "price_changes":[{"asset_id":"81916206347121459497221114766050949090435061493822476265356047392175668050706", "price":"0.01", "size":"1751.92", "side":"BUY", "hash":"9c5c9d1abd93dce39614f0bca8b2b3f1e53a9b04", "best_bid":"0.02", "best_ask":"0.03"}, {"asset_id":"96888240988495161476033313796107536512663280794332045579302109906525918376981", "price":"0.99", "size":"1751.92", "side":"SELL", "hash":"a2166dd566db730bb6ac4ebf8a0120470d736ddf", "best_bid":"0.97", "best_ask":"0.98"}], "timestamp":"1770241491510", "event_type":"price_change"}
{"market":"0x38f3050258345e9cf363d1c8cc302f08c65b96ba1a4669d81e07ed69708344df", "price_changes":[{"asset_id":"81916206347121459497221114766050949090435061493822476265356047392175668050706", "price":"0.01", "size":"1724.92", "side":"BUY", "hash":"888de8625d8d36afc2ac86a80bd7de62cb756313", "best_bid":"0.02", "best_ask":"0.03"}, {"asset_id":"96888240988495161476033313796107536512663280794332045579302109906525918376981", "price":"0.99", "size":"1724.92", "side":"SELL", "hash":"d84e748e1077762bc38d396365605374031c1507", "best_bid":"0.97", "best_ask":"0.98"}], "timestamp":"1770241491511", "event_type":"price_change"}
{"market":"0x38f3050258345e9cf363d1c8cc302f08c65b96ba1a4669d81e07ed69708344df", "price_changes":[{"asset_id":"96888240988495161476033313796107536512663280794332045579302109906525918376981", "price":"0.97", "size":"261.18", "side":"BUY", "hash":"9ef68976dc8d40ab832cd2b2170aa890ea31d14a", "best_bid":"0.97", "best_ask":"0.98"}, {"asset_id":"81916206347121459497221114766050949090435061493822476265356047392175668050706", "price":"0.03", "size":"261.18", "side":"SELL", "hash":"16ed3c211c62767910e3398bccdadbd7316e270b", "best_bid":"0.02", "best_ask":"0.03"}], "timestamp":"1770241491512", "event_type":"price_change"}
{"market":"0x38f3050258345e9cf363d1c8cc302f08c65b96ba1a4669d81e07ed69708344df", "price_changes":[{"asset_id":"96888240988495161476033313796107536512663280794332045579302109906525918376981", "price":"0.96", "size":"586.73", "side":"BUY", "hash":"3265424b8e6c293b2f86ca2b33d8ac7ac60a3525", "best_bid":"0.97", "best_ask":"0.98"}, {"asset_id":"81916206347121459497221114766050949090435061493822476265356047392175668050706", "price":"0.04", "size":"586.73", "side":"SELL", "hash":"04d6fb483f94a6ecbe7d3d828be941ebc1725ca7", "best_bid":"0.02", "best_ask":"0.03"}], "timestamp":"1770241491513", "event_type":"price_change"}
{"market":"0x38f3050258345e9cf363d1c8cc302f08c65b96ba1a4669d81e07ed69708344df", "price_changes":[{"asset_id":"96888240988495161476033313796107536512663280794332045579302109906525918376981", "price":"0.95", "size":"609", "side":"BUY", "hash":"91b9b15484b5cf70db25fdba2bf801cdb285c4de", "best_bid":"0.97", "best_ask":"0.98"}, {"asset_id":"81916206347121459497221114766050949090435061493822476265356047392175668050706", "price":"0.05", "size":"609", "side":"SELL", "hash":"db5fde444d0275eb77cbe182767f1b5f28d9c766", "best_bid":"0.02", "best_ask":"0.03"}], "timestamp":"1770241491526", "event_type":"price_change"}
{"market":"0x38f3050258345e9cf363d1c8cc302f08c65b96ba1a4669d81e07ed69708344df", "price_changes":[{"asset_id":"81916206347121459497221114766050949090435061493822476265356047392175668050706", "price":"0.01", "size":"1751.92", "side":"BUY", "hash":"afc1463abbc017b3abf02d4150b9a96dd2d2e985", "best_bid":"0.02", "best_ask":"0.03"}, {"asset_id":"96888240988495161476033313796107536512663280794332045579302109906525918376981", "price":"0.99", "size":"1751.92", "side":"SELL", "hash":"2a60afb8ab3553855dce0f291fc01abf43a03423", "best_bid":"0.97", "best_ask":"0.98"}], "timestamp":"1770241491527", "event_type":"price_change"}
{"market":"0x38f3050258345e9cf363d1c8cc302f08c65b96ba1a4669d81e07ed69708344df", "price_changes":[{"asset_id":"96888240988495161476033313796107536512663280794332045579302109906525918376981", "price":"0.96", "size":"563.73", "side":"BUY", "hash":"77ad714f6abba867ade8996268890a945032b791", "best_bid":"0.97", "best_ask":"0.98"}, {"asset_id":"81916206347121459497221114766050949090435061493822476265356047392175668050706", "price":"0.04", "size":"563.73", "side":"SELL", "hash":"1aff2a1a62431c97510bb2bc3bc9f06f5b46752a", "best_bid":"0.02", "best_ask":"0.03"}], "timestamp":"1770241491527", "event_type":"price_change"}
{"market":"0x38f3050258345e9cf363d1c8cc302f08c65b96ba1a4669d81e07ed69708344df", "price_changes":[{"asset_id":"96888240988495161476033313796107536512663280794332045579302109906525918376981", "price":"0.95", "size":"632", "side":"BUY", "hash":"cab784f0f2ba6c825aa6bec743273740a7f70902", "best_bid":"0.97", "best_ask":"0.98"}, {"asset_id":"81916206347121459497221114766050949090435061493822476265356047392175668050706", "price":"0.05", "size":"632", "side":"SELL", "hash":"5382bce1c963ab0ab744c3121e0cbca28fbaea3e", "best_bid":"0.02", "best_ask":"0.03"}], "timestamp":"1770241491529", "event_type":"price_change"}
{"market":"0x38f3050258345e9cf363d1c8cc302f08c65b96ba1a4669d81e07ed69708344df", "price_changes":[{"asset_id":"96888240988495161476033313796107536512663280794332045579302109906525918376981", "price":"0.95", "size":"659", "side":"BUY", "hash":"48aae67675ce9bb2f3fe90cf2a705811131e5a49", "best_bid":"0.97", "best_ask":"0.98"}, {"asset_id":"81916206347121459497221114766050949090435061493822476265356047392175668050706", "price":"0.05", "size":"659", "side":"SELL", "hash":"5374a56aa0c19022047702285030e799d9e6d746", "best_bid":"0.02", "best_ask":"0.03"}], "timestamp":"1770241491533", "event_type":"price_change"}
{"market":"0x38f3050258345e9cf363d1c8cc302f08c65b96ba1a4669d81e07ed69708344df", "price_changes":[{"asset_id":"81916206347121459497221114766050949090435061493822476265356047392175668050706", "price":"0.01", "size":"1724.92", "side":"BUY", "hash":"b709e91ec4b4960cb557ca5aa2ef23f5dd6b0ee8", "best_bid":"0.02", "best_ask":"0.03"}, {"asset_id":"96888240988495161476033313796107536512663280794332045579302109906525918376981", "price":"0.99", "size":"1724.92", "side":"SELL", "hash":"d01d632688b183a8d72c71b4b113458129ce5438", "best_bid":"0.97", "best_ask":"0.98"}], "timestamp":"1770241491540", "event_type":"price_change"}
{"market":"0x38f3050258345e9cf363d1c8cc302f08c65b96ba1a4669d81e07ed69708344df", "price_changes":[{"asset_id":"96888240988495161476033313796107536512663280794332045579302109906525918376981", "price":"0.96", "size":"589.73", "side":"BUY", "hash":"9506c4665c353ae58bf934e96dc66f20348c086a", "best_bid":"0.97", "best_ask":"0.98"}, {"asset_id":"81916206347121459497221114766050949090435061493822476265356047392175668050706", "price":"0.04", "size":"589.73", "side":"SELL", "hash":"7c3e279c52247d973b504380bacf9317f82ab28d", "best_bid":"0.02", "best_ask":"0.03"}], "timestamp":"1770241491550", "event_type":"price_change"}
{"market":"0x38f3050258345e9cf363d1c8cc302f08c65b96ba1a4669d81e07ed69708344df", "price_changes":[{"asset_id":"96888240988495161476033313796107536512663280794332045579302109906525918376981", "price":"0.96", "size":"615.73", "side":"BUY", "hash":"0a1f88aa0fdda444900aaf77aa9bb0971b2b5439", "best_bid":"0.97", "best_ask":"0.98"}, {"asset_id":"81916206347121459497221114766050949090435061493822476265356047392175668050706", "price":"0.04", "size":"615.73", "side":"SELL", "hash":"243f1a8af6924a638f8cb8d7019e4b22cf06e3f3", "best_bid":"0.02", "best_ask":"0.03"}], "timestamp":"1770241491556", "event_type":"price_change"}
{"market":"0x38f3050258345e9cf363d1c8cc302f08c65b96ba1a4669d81e07ed69708344df", "price_changes":[{"asset_id":"96888240988495161476033313796107536512663280794332045579302109906525918376981", "price":"0.99", "size":"1684.92", "side":"SELL", "hash":"afaa4fbbf22f367e5e3060b7acb59d95f907b5ad", "best_bid":"0.97", "best_ask":"0.98"}, {"asset_id":"81916206347121459497221114766050949090435061493822476265356047392175668050706", "price":"0.01", "size":"1684.92", "side":"BUY", "hash":"1990a87a928737536aa6da6f074c525db69cb17f", "best_bid":"0.02", "best_ask":"0.03"}], "timestamp":"1770241491570", "event_type":"price_change"}
{"market":"0x38f3050258345e9cf363d1c8cc302f08c65b96ba1a4669d81e07ed69708344df", "price_changes":[{"asset_id":"96888240988495161476033313796107536512663280794332045579302109906525918376981", "price":"0.98", "size":"157", "side":"SELL", "hash":"8485fd557db0db685421438b354aca3cfc314b35", "best_bid":"0.97", "best_ask":"0.98"}, {"asset_id":"81916206347121459497221114766050949090435061493822476265356047392175668050706", "price":"0.02", "size":"157", "side":"BUY", "hash":"cad23031ef17f6e72b4616e7b617ce99dddce5ad", "best_bid":"0.02", "best_ask":"0.03"}], "timestamp":"1770241491596", "event_type":"price_change"}
{"market":"0x38f3050258345e9cf363d1c8cc302f08c65b96ba1a4669d81e07ed69708344df", "price_changes":[{"asset_id":"96888240988495161476033313796107536512663280794332045579302109906525918376981", "price":"0.95", "size":"636", "side":"BUY", "hash":"a088cb85cb38c6cba0e377d5968c90fce1929d85", "best_bid":"0.97", "best_ask":"0.98"}, {"asset_id":"81916206347121459497221114766050949090435061493822476265356047392175668050706", "price":"0.05", "size":"636", "side":"SELL", "hash":"2f65d6aa56832f2eda0345f46d38f60ed2d44b2d", "best_bid":"0.02", "best_ask":"0.03"}], "timestamp":"1770241491682", "event_type":"price_change"}
{"market":"0x38f3050258345e9cf363d1c8cc302f08c65b96ba1a4669d81e07ed69708344df", "price_changes":[{"asset_id":"96888240988495161476033313796107536512663280794332045579302109906525918376981", "price":"0.96", "size":"638.73", "side":"BUY", "hash":"910c1b7db3701938d8ada1d6b12e351305a04050", "best_bid":"0.97", "best_ask":"0.98"}, {"asset_id":"81916206347121459497221114766050949090435061493822476265356047392175668050706", "price":"0.04", "size":"638.73", "side":"SELL", "hash":"a37d4b8077ce1a8ae4a4d9af0f1b538838d9d0f0", "best_bid":"0.02", "best_ask":"0.03"}], "timestamp":"1770241491683", "event_type":"price_change"}
{"market":"0x38f3050258345e9cf363d1c8cc302f08c65b96ba1a4669d81e07ed69708344df", "price_changes":[{"asset_id":"96888240988495161476033313796107536512663280794332045579302109906525918376981", "price":"0.96", "size":"668.73", "side":"BUY", "hash":"7b58fa6a98e07a139f9b1567aaa86279da96a499", "best_bid":"0.97", "best_ask":"0.98"}, {"asset_id":"81916206347121459497221114766050949090435061493822476265356047392175668050706", "price":"0.04", "size":"668.73", "side":"SELL", "hash":"448385c24148178774d9544632162cab9a31e9f2", "best_bid":"0.02", "best_ask":"0.03"}], "timestamp":"1770241491703", "event_type":"price_change"}
{"market":"0x38f3050258345e9cf363d1c8cc302f08c65b96ba1a4669d81e07ed69708344df", "price_changes":[{"asset_id":"96888240988495161476033313796107536512663280794332045579302109906525918376981", "price":"0.95", "size":"609", "side":"BUY", "hash":"f830795a1f6ff41bcf516d0fef7084e00e3492a2", "best_bid":"0.97", "best_ask":"0.98"}, {"asset_id":"81916206347121459497221114766050949090435061493822476265356047392175668050706", "price":"0.05", "size":"609", "side":"SELL", "hash":"6f4909dd5f884d2930755363f48aae1105051b6a", "best_bid":"0.02", "best_ask":"0.03"}], "timestamp":"1770241491933", "event_type":"price_change"}
{"market":"0x38f3050258345e9cf363d1c8cc302f08c65b96ba1a4669d81e07ed69708344df", "price_changes":[{"asset_id":"96888240988495161476033313796107536512663280794332045579302109906525918376981", "price":"0.94", "size":"918", "side":"BUY", "hash":"e178869bb5442fe64d79dd691fcf88932da9fcbc", "best_bid":"0.97", "best_ask":"0.98"}, {"asset_id":"81916206347121459497221114766050949090435061493822476265356047392175668050706", "price":"0.06", "size":"918", "side":"SELL", "hash":"e5282790486810736e023af1eeb34600c5cc1c8d", "best_bid":"0.02", "best_ask":"0.03"}], "timestamp":"1770241491934", "event_type":"price_change"}
{"market":"0x38f3050258345e9cf363d1c8cc302f08c65b96ba1a4669d81e07ed69708344df", "price_changes":[{"asset_id":"81916206347121459497221114766050949090435061493822476265356047392175668050706", "price":"0.01", "size":"1711.92", "side":"BUY", "hash":"d27d2b79b4de395ccc099f70ac1dd2da6dcf8239", "best_bid":"0.02", "best_ask":"0.03"}, {"asset_id":"96888240988495161476033313796107536512663280794332045579302109906525918376981", "price":"0.99", "size":"1711.92", "side":"SELL", "hash":"3152b7b916640613ed49ef9d7ec0a4dc5ab6e516", "best_bid":"0.97", "best_ask":"0.98"}], "timestamp":"1770241491936", "event_type":"price_change"}
{"market":"0x38f3050258345e9cf363d1c8cc302f08c65b96ba1a4669d81e07ed69708344df", "price_changes":[{"asset_id":"81916206347121459497221114766050949090435061493822476265356047392175668050706", "price":"0.01", "size":"1684.92", "side":"BUY", "hash":"21fa57a97098bae0aa3a156bb5706fcb2cc0a64a", "best_bid":"0.02", "best_ask":"0.03"}, {"asset_id":"96888240988495161476033313796107536512663280794332045579302109906525918376981", "price":"0.99", "size":"1684.92", "side":"SELL", "hash":"34cc916d8d3fe695505419cb7f5836f4ce840e6e", "best_bid":"0.97", "best_ask":"0.98"}], "timestamp":"1770241491936", "event_type":"price_change"}
{"market":"0x38f3050258345e9cf363d1c8cc302f08c65b96ba1a4669d81e07ed69708344df", "price_changes":[{"asset_id":"81916206347121459497221114766050949090435061493822476265356047392175668050706", "price":"0.01", "size":"1711.92", "side":"BUY", "hash":"97e59bc2dac6c816dad4269969e1f6f5ca748031", "best_bid":"0.02", "best_ask":"0.03"}, {"asset_id":"96888240988495161476033313796107536512663280794332045579302109906525918376981", "price":"0.99", "size":"1711.92", "side":"SELL", "hash":"f7fafb954e8ebcb50a65e8562e3c27779cea5cda", "best_bid":"0.97", "best_ask":"0.98"}], "timestamp":"1770241491943", "event_type":"price_change"}
{"market":"0x38f3050258345e9cf363d1c8cc302f08c65b96ba1a4669d81e07ed69708344df", "price_changes":[{"asset_id":"96888240988495161476033313796107536512663280794332045579302109906525918376981", "price":"0.97", "size":"241.18", "side":"BUY", "hash":"72a532e13382b6a128ed88d3bfd863ceaf2600af", "best_bid":"0.97", "best_ask":"0.98"}, {"asset_id":"81916206347121459497221114766050949090435061493822476265356047392175668050706", "price":"0.03", "size":"241.18", "side":"SELL", "hash":"6e65d49932e7133324e3e7bfa329395ba161bda1", "best_bid":"0.02", "best_ask":"0.03"}], "timestamp":"1770241491944", "event_type":"price_change"}
{"market":"0x38f3050258345e9cf363d1c8cc302f08c65b96ba1a4669d81e07ed69708344df", "price_changes":[{"asset_id":"96888240988495161476033313796107536512663280794332045579302109906525918376981", "price":"0.95", "size":"582", "side":"BUY", "hash":"78824ce760dabf188c17bdf444c9d6bb0031647d", "best_bid":"0.97", "best_ask":"0.98"}, {"asset_id":"81916206347121459497221114766050949090435061493822476265356047392175668050706", "price":"0.05", "size":"582", "side":"SELL", "hash":"1f11a44c07879789da47ac59e6dd9128328e67dd", "best_bid":"0.02", "best_ask":"0.03"}], "timestamp":"1770241491944", "event_type":"price_change"}
{"market":"0x38f3050258345e9cf363d1c8cc302f08c65b96ba1a4669d81e07ed69708344df", "price_changes":[{"asset_id":"96888240988495161476033313796107536512663280794332045579302109906525918376981", "price":"0.94", "size":"945", "side":"BUY", "hash":"b4f68010b35147d68b6c7266e2edcbdeb8f39871", "best_bid":"0.97", "best_ask":"0.98"}, {"asset_id":"81916206347121459497221114766050949090435061493822476265356047392175668050706", "price":"0.06", "size":"945", "side":"SELL", "hash":"5cf4585bb65a37f93380ba5f9a78dc0881fefc02", "best_bid":"0.02", "best_ask":"0.03"}], "timestamp":"1770241491946", "event_type":"price_change"}
{"market":"0x38f3050258345e9cf363d1c8cc302f08c65b96ba1a4669d81e07ed69708344df", "price_changes":[{"asset_id":"81916206347121459497221114766050949090435061493822476265356047392175668050706", "price":"0.01", "size":"1684.92", "side":"BUY", "hash":"fe07af2f5a0d2eccf0487acbf140c7b2ba0a09e5", "best_bid":"0.02", "best_ask":"0.03"}, {"asset_id":"96888240988495161476033313796107536512663280794332045579302109906525918376981", "price":"0.99", "size":"1684.92", "side":"SELL", "hash":"42dc1b1ac8e51cee0911443fae596f4fc226447a", "best_bid":"0.97", "best_ask":"0.98"}], "timestamp":"1770241491947", "event_type":"price_change"}
{"market":"0x38f3050258345e9cf363d1c8cc302f08c65b96ba1a4669d81e07ed69708344df", "price_changes":[{"asset_id":"81916206347121459497221114766050949090435061493822476265356047392175668050706", "price":"0.01", "size":"1711.92", "side":"BUY", "hash":"a2b5780f090b0329eaa6f480b1401cd2a76e0282", "best_bid":"0.02", "best_ask":"0.03"}, {"asset_id":"96888240988495161476033313796107536512663280794332045579302109906525918376981", "price":"0.99", "size":"1711.92", "side":"SELL", "hash":"282f9d9526cf8394e1882150a8aa434bcf700e0d", "best_bid":"0.97", "best_ask":"0.98"}], "timestamp":"1770241491951", "event_type":"price_change"}
{"market":"0x38f3050258345e9cf363d1c8cc302f08c65b96ba1a4669d81e07ed69708344df", "price_changes":[{"asset_id":"96888240988495161476033313796107536512663280794332045579302109906525918376981", "price":"0.96", "size":"695.73", "side":"BUY", "hash":"cea8fb6a9284414297f4126972c178e22dfb840e", "best_bid":"0.97", "best_ask":"0.98"}, {"asset_id":"81916206347121459497221114766050949090435061493822476265356047392175668050706", "price":"0.04", "size":"695.73", "side":"SELL", "hash":"5ec09dfb799923351b9f08557739c4ccd3d47efc", "best_bid":"0.02", "best_ask":"0.03"}], "timestamp":"1770241491952", "event_type":"price_change"}
{"market":"0x38f3050258345e9cf363d1c8cc302f08c65b96ba1a4669d81e07ed69708344df", "price_changes":[{"asset_id":"96888240988495161476033313796107536512663280794332045579302109906525918376981", "price":"0.97", "size":"214.18", "side":"BUY", "hash":"91f6df2aee738cc1e87da245fdd178af11e0f19a", "best_bid":"0.97", "best_ask":"0.98"}, {"asset_id":"81916206347121459497221114766050949090435061493822476265356047392175668050706", "price":"0.03", "size":"214.18", "side":"SELL", "hash":"1c58e31ca15757f904933501c77fdf61a8cb6e2b", "best_bid":"0.02", "best_ask":"0.03"}], "timestamp":"1770241491953", "event_type":"price_change"}
{"market":"0x38f3050258345e9cf363d1c8cc302f08c65b96ba1a4669d81e07ed69708344df", "price_changes":[{"asset_id":"81916206347121459497221114766050949090435061493822476265356047392175668050706", "price":"0.01", "size":"1684.92", "side":"BUY", "hash":"eda1b222b7f3144b82957a3f6ef8f385a9ee8deb", "best_bid":"0.02", "best_ask":"0.03"}, {"asset_id":"96888240988495161476033313796107536512663280794332045579302109906525918376981", "price":"0.99", "size":"1684.92", "side":"SELL", "hash":"1f799d9d7b69d837143380e7b3a506819a591173", "best_bid":"0.97", "best_ask":"0.98"}], "timestamp":"1770241491956", "event_type":"price_change"}
{"market":"0x38f3050258345e9cf363d1c8cc302f08c65b96ba1a4669d81e07ed69708344df", "price_changes":[{"asset_id":"96888240988495161476033313796107536512663280794332045579302109906525918376981", "price":"0.94", "size":"918", "side":"BUY", "hash":"db45278cf43e71b2c3e06bdc02fd384d7e6ed2cd", "best_bid":"0.97", "best_ask":"0.98"}, {"asset_id":"81916206347121459497221114766050949090435061493822476265356047392175668050706", "price":"0.06", "size":"918", "side":"SELL", "hash":"b0f514d54ec4b952191053728fe9ec85744fe451", "best_bid":"0.02", "best_ask":"0.03"}], "timestamp":"1770241492090", "event_type":"price_change"}
{"market":"0x38f3050258345e9cf363d1c8cc302f08c65b96ba1a4669d81e07ed69708344df", "price_changes":[{"asset_id":"96888240988495161476033313796107536512663280794332045579302109906525918376981", "price":"0.95", "size":"609", "side":"BUY", "hash":"f3e59a9542046f0fef7ff4f9b07928d7820a9dcb", "best_bid":"0.97", "best_ask":"0.98"}, {"asset_id":"81916206347121459497221114766050949090435061493822476265356047392175668050706", "price":"0.05", "size":"609", "side":"SELL", "hash":"d8ffbcf0bd2f6ff5d6edfe8e44592a4b54b2e3a1", "best_bid":"0.02", "best_ask":"0.03"}], "timestamp":"1770241492091", "event_type":"price_change"}
{"market":"0x38f3050258345e9cf363d1c8cc302f08c65b96ba1a4669d81e07ed69708344df", "price_changes":[{"asset_id":"81916206347121459497221114766050949090435061493822476265356047392175668050706", "price":"0.02", "size":"151.55", "side":"BUY", "hash":"627c810941db22c443e72f6bdf896b5df18059f9", "best_bid":"0.02", "best_ask":"0.03"}, {"asset_id":"96888240988495161476033313796107536512663280794332045579302109906525918376981", "price":"0.98", "size":"151.55", "side":"SELL", "hash":"aff520193ba17f30633c6fbf9e5b920a40481402", "best_bid":"0.97", "best_ask":"0.98"}], "timestamp":"1770241492199", "event_type":"price_change"}
