{"market":"0x38f3050258345e9cf363d1c8cc302f08c65b96ba1a4669d81e07ed69708344df", "asset_id":"81916206347121459497221114766050949090435061493822476265356047392175668050706", "bids":[{"price":"0.01", "size":"4099"}], "asks":[{"price":"0.99", "size":"5019.91"}, {"price":"0.98", "size":"3034.23"}, {"price":"0.97", "size":"3172"}, {"price":"0.96", "size":"3012"}, {"price":"0.95", "size":"3032"}, {"price":"0.94", "size":"3012"}, {"price":"0.93", "size":"3126.28"}, {"price":"0.92", "size":"3012"}, {"price":"0.91", "size":"3012"}, {"price":"0.9", "size":"3087"}, {"price":"0.89", "size":"12"}, {"price":"0.88", "size":"12"}, {"price":"0.87", "size":"12"}, {"price":"0.86", "size":"12"}, {"price":"0.85", "size":"12"}, {"price":"0.84", "size":"12"}, {"price":"0.83", "size":"12"}, {"price":"0.82", "size":"12"}, {"price":"0.81", "size":"12"}, {"price":"0.8", "size":"12"}, {"price":"0.79", "size":"12"}, {"price":"0.78", "size":"12"}, {"price":"0.77", "size":"12"}, {"price":"0.76", "size":"112"}, {"price":"0.75", "size":"40.57"}, {"price":"0.74", "size":"12"}, {"price":"0.73", "size":"293.25"}, {"price":"0.72", "size":"22"}, {"price":"0.71", "size":"12"}, {"price":"0.7", "size":"18"}, {"price":"0.69", "size":"12"}, {"price":"0.68", "size":"12"}, {"price":"0.67", "size":"12"}, {"price":"0.66", "size":"160.89"}, {"price":"0.65", "size":"12"}, {"price":"0.64", "size":"12"}, {"price":"0.63", "size":"12"}, {"price":"0.62", "size":"19.39"}, {"price":"0.61", "size":"18.04"}, {"price":"0.6", "size":"12"}, {"price":"0.59", "size":"94.31"}, {"price":"0.58", "size":"5450.54"}, {"price":"0.57", "size":"12"}, {"price":"0.56", "size":"12"}, {"price":"0.55", "size":"12"}, {"price":"0.54", "size":"22"}, {"price":"0.53", "size":"12"}, {"price":"0.52", "size":"12"}, {"price":"0.51", "size":"12"}, {"price":"0.5", "size":"12"}, {"price":"0.49", "size":"12"}, {"price":"0.48", "size":"12"}, {"price":"0.47", "size":"12"}, {"price":"0.46", "size":"485.56"}, {"price":"0.45", "size":"31"}, {"price":"0.44", "size":"17"}, {"price":"0.43", "size":"12"}, {"price":"0.42", "size":"12"}, {"price":"0.41", "size":"12"}, {"price":"0.4", "size":"127"}, {"price":"0.39", "size":"12"}, {"price":"0.38", "size":"94.51"}, {"price":"0.37", "size":"31.99"}, {"price":"0.36", "size":"12"}, {"price":"0.35", "size":"37"}, {"price":"0.34", "size":"12"}, {"price":"0.33", "size":"12"}, {"price":"0.32", "size":"12"}, {"price":"0.31", "size":"12"}, {"price":"0.3", "size":"31.9"}, {"price":"0.29", "size":"344"}, {"price":"0.28", "size":"3288.99"}, {"price":"0.27", "size":"212"}, {"price":"0.26", "size":"218"}, {"price":"0.25", "size":"212"}, {"price":"0.24", "size":"212"}, {"price":"0.23", "size":"712"}, {"price":"0.22", "size":"1223.14"}, {"price":"0.21", "size":"212"}, {"price":"0.2", "size":"272.99"}, {"price":"0.19", "size":"212"}, {"price":"0.18", "size":"212"}, {"price":"0.17", "size":"212"}, {"price":"0.16", "size":"812"}, {"price":"0.15", "size":"231.08"}, {"price":"0.14", "size":"283.65"}, {"price":"0.13", "size":"212"}, {"price":"0.12", "size":"252"}, {"price":"0.11", "size":"252"}, {"price":"0.1", "size":"737.71"}, {"price":"0.09", "size":"326"}, {"price":"0.08", "size":"844.68"}, {"price":"0.07", "size":"826"}, {"price":"0.06", "size":"726"}, {"price":"0.05", "size":"680"}, {"price":"0.04", "size":"705.73"}, {"price":"0.03", "size":"505.32"}, {"price":"0.02", "size":"138.98"}], "hash":"ef34b2fd56c6923bce71605b5ce19b6ab5210425", "timestamp":"1770241473983", "event_type":"book"}
{"market":"0x38f3050258345e9cf363d1c8cc302f08c65b96ba1a4669d81e07ed69708344df", "price_changes":[{"asset_id":"96888240988495161476033313796107536512663280794332045579302109906525918376981", "price":"0.97", "size":"528.32", "side":"BUY", "hash":"00c3496edb518e6c5916f76c65c5da647f3f703d", "best_bid":"0.98", "best_ask":"0.99"}, {"asset_id":"81916206347121459497221114766050949090435061493822476265356047392175668050706", "price":"0.03", "size":"528.32", "side":"SELL", "hash":"26cfd9a6d5ab934cebd27ffc27166cfc38fe3289", "best_bid":"0.01", "best_ask":"0.02"}], "timestamp":"1770241474087", "event_type":"price_change"}
{"market":"0x38f3050258345e9cf363d1c8cc302f08c65b96ba1a4669d81e07ed69708344df", "price_changes":[{"asset_id":"96888240988495161476033313796107536512663280794332045579302109906525918376981", "price":"0.96", "size":"682.73", "side":"BUY", "hash":"083c7d8808fd54b498268530755cb6f730613992", "best_bid":"0.98", "best_ask":"0.99"}, {"asset_id":"81916206347121459497221114766050949090435061493822476265356047392175668050706", "price":"0.04", "size":"682.73", "side":"SELL", "hash":"b3acd5d941d3ea54d83b06b5b187d379438a79ad", "best_bid":"0.01", "best_ask":"0.02"}], "timestamp":"1770241474089", "event_type":"price_change"}
{"market":"0x38f3050258345e9cf363d1c8cc302f08c65b96ba1a4669d81e07ed69708344df", "price_changes":[{"asset_id":"96888240988495161476033313796107536512663280794332045579302109906525918376981", "price":"0.96", "size":"702.73", "side":"BUY", "hash":"6232e0e5cb44e30aa4243a01f1ad9ca2b01554fb", "best_bid":"0.98", "best_ask":"0.99"}, {"asset_id":"81916206347121459497221114766050949090435061493822476265356047392175668050706", "price":"0.04", "size":"702.73", "side":"SELL", "hash":"2646e48bbbd168d089dd391235ca5907f209de75", "best_bid":"0.01", "best_ask":"0.02"}], "timestamp":"1770241474145", "event_type":"price_change"}
{"market":"0x38f3050258345e9cf363d1c8cc302f08c65b96ba1a4669d81e07ed69708344df", "price_changes":[{"asset_id":"96888240988495161476033313796107536512663280794332045579302109906525918376981", "price":"0.99", "size":"4139", "side":"SELL", "hash":"0e4597afb40e6c1235d588a258ceeef0241bcbe1", "best_bid":"0.98", "best_ask":"0.99"}, {"asset_id":"81916206347121459497221114766050949090435061493822476265356047392175668050706", "price":"0.01", "size":"4139", "side":"BUY", "hash":"76caed66dd57668d8a1839504d8cb678d644ac59", "best_bid":"0.01", "best_ask":"0.02"}], "timestamp":"1770241474162", "event_type":"price_change"}
{"market":"0x38f3050258345e9cf363d1c8cc302f08c65b96ba1a4669d81e07ed69708344df", "price_changes":[{"asset_id":"81916206347121459497221114766050949090435061493822476265356047392175668050706", "price":"0.01", "size":"4166", "side":"BUY", "hash":"afe181cbb48345e4e784ecf099f406f411002b50", "best_bid":"0.01", "best_ask":"0.02"}, {"asset_id":"96888240988495161476033313796107536512663280794332045579302109906525918376981", "price":"0.99", "size":"4166", "side":"SELL", "hash":"72fbb84d7769b493c315d3ff4a5c038938e3e76a", "best_bid":"0.98", "best_ask":"0.99"}], "timestamp":"1770241474177", "event_type":"price_change"}
{"market":"0x38f3050258345e9cf363d1c8cc302f08c65b96ba1a4669d81e07ed69708344df", "price_changes":[{"asset_id":"81916206347121459497221114766050949090435061493822476265356047392175668050706", "price":"0.01", "size":"4139", "side":"BUY", "hash":"735353e7604f43c47e36c7868ce9ca36c8f3e950", "best_bid":"0.01", "best_ask":"0.02"}, {"asset_id":"96888240988495161476033313796107536512663280794332045579302109906525918376981", "price":"0.99", "size":"4139", "side":"SELL", "hash":"faeb05704d3495984c31064f750d8b54cd675ece", "best_bid":"0.98", "best_ask":"0.99"}], "timestamp":"1770241474179", "event_type":"price_change"}
{"market":"0x38f3050258345e9cf363d1c8cc302f08c65b96ba1a4669d81e07ed69708344df", "price_changes":[{"asset_id":"96888240988495161476033313796107536512663280794332045579302109906525918376981", "price":"0.96", "size":"729.73", "side":"BUY", "hash":"1ff8973c69fa5034498b3d32ad0bec9e162dde9a", "best_bid":"0.98", "best_ask":"0.99"}, {"asset_id":"81916206347121459497221114766050949090435061493822476265356047392175668050706", "price":"0.04", "size":"729.73", "side":"SELL", "hash":"032eb34e78eb842a0ee851f5801ad2391e001a62", "best_bid":"0.01", "best_ask":"0.02"}], "timestamp":"1770241474184", "event_type":"price_change"}
{"market":"0x38f3050258345e9cf363d1c8cc302f08c65b96ba1a4669d81e07ed69708344df", "price_changes":[{"asset_id":"96888240988495161476033313796107536512663280794332045579302109906525918376981", "price":"0.95", "size":"653", "side":"BUY", "hash":"9dc67d00e0c87d407df86b5bff098f8621ff6a26", "best_bid":"0.98", "best_ask":"0.99"}, {"asset_id":"81916206347121459497221114766050949090435061493822476265356047392175668050706", "price":"0.05", "size":"653", "side":"SELL", "hash":"8734781c865bc9aa2c347a20af0b27a8b212800a", "best_bid":"0.01", "best_ask":"0.02"}], "timestamp":"1770241474186", "event_type":"price_change"}
{"market":"0x38f3050258345e9cf363d1c8cc302f08c65b96ba1a4669d81e07ed69708344df", "price_changes":[{"asset_id":"81916206347121459497221114766050949090435061493822476265356047392175668050706", "price":"0.01", "size":"4112", "side":"BUY", "hash":"2cbf0eefc8287714cd0b600e194e3193469ba45b", "best_bid":"0.01", "best_ask":"0.02"}, {"asset_id":"96888240988495161476033313796107536512663280794332045579302109906525918376981", "price":"0.99", "size":"4112", "side":"SELL", "hash":"c6b361e68948b919eb594bdcce425b880935c86a", "best_bid":"0.98", "best_ask":"0.99"}], "timestamp":"1770241474189", "event_type":"price_change"}
{"market":"0x38f3050258345e9cf363d1c8cc302f08c65b96ba1a4669d81e07ed69708344df", "price_changes":[{"asset_id":"81916206347121459497221114766050949090435061493822476265356047392175668050706", "price":"0.01", "size":"4139", "side":"BUY", "hash":"0921463606ece4780f84eb8e35af33610de0e844", "best_bid":"0.01", "best_ask":"0.02"}, {"asset_id":"96888240988495161476033313796107536512663280794332045579302109906525918376981", "price":"0.99", "size":"4139", "side":"SELL", "hash":"b335eb4262d2a97926d100e5b2ce53ca8bcd8384", "best_bid":"0.98", "best_ask":"0.99"}], "timestamp":"1770241474190", "event_type":"price_change"}
{"market":"0x38f3050258345e9cf363d1c8cc302f08c65b96ba1a4669d81e07ed69708344df", "price_changes":[{"asset_id":"96888240988495161476033313796107536512663280794332045579302109906525918376981", "price":"0.95", "size":"626", "side":"BUY", "hash":"7eadbe69d7bde3186a4b762c9a4897eaa0d57f27", "best_bid":"0.98", "best_ask":"0.99"}, {"asset_id":"81916206347121459497221114766050949090435061493822476265356047392175668050706", "price":"0.05", "size":"626", "side":"SELL", "hash":"3f03d2e4c3ac17f74e98923481a96b8776553a09", "best_bid":"0.01", "best_ask":"0.02"}], "timestamp":"1770241474191", "event_type":"price_change"}
{"market":"0x38f3050258345e9cf363d1c8cc302f08c65b96ba1a4669d81e07ed69708344df", "price_changes":[{"asset_id":"96888240988495161476033313796107536512663280794332045579302109906525918376981", "price":"0.96", "size":"756.73", "side":"BUY", "hash":"000213e95c49b933000f3fd9ca44142ad7053b7f", "best_bid":"0.98", "best_ask":"0.99"}, {"asset_id":"81916206347121459497221114766050949090435061493822476265356047392175668050706", "price":"0.04", "size":"756.73", "side":"SELL", "hash":"224213d0097eaa52f87a6165339a5d48ac7cf500", "best_bid":"0.01", "best_ask":"0.02"}], "timestamp":"1770241474197", "event_type":"price_change"}
{"market":"0x38f3050258345e9cf363d1c8cc302f08c65b96ba1a4669d81e07ed69708344df", "price_changes":[{"asset_id":"81916206347121459497221114766050949090435061493822476265356047392175668050706", "price":"0.01", "size":"4112", "side":"BUY", "hash":"cfd954699c87e34db0ffceac380c2538dd53a905", "best_bid":"0.01", "best_ask":"0.02"}, {"asset_id":"96888240988495161476033313796107536512663280794332045579302109906525918376981", "price":"0.99", "size":"4112", "side":"SELL", "hash":"47a48d9fa70956146fa773d0e2ea5c878ebe3ca0", "best_bid":"0.98", "best_ask":"0.99"}], "timestamp":"1770241474197", "event_type":"price_change"}
{"market":"0x38f3050258345e9cf363d1c8cc302f08c65b96ba1a4669d81e07ed69708344df", "price_changes":[{"asset_id":"96888240988495161476033313796107536512663280794332045579302109906525918376981", "price":"0.96", "size":"729.73", "side":"BUY", "hash":"22969a1d3fc1a87d23529bc14c21de945825def4", "best_bid":"0.98", "best_ask":"0.99"}, {"asset_id":"81916206347121459497221114766050949090435061493822476265356047392175668050706", "price":"0.04", "size":"729.73", "side":"SELL", "hash":"5412a7de7f9e0fbaa1ddbb885bf4f8d271cf7dcb", "best_bid":"0.01", "best_ask":"0.02"}], "timestamp":"1770241474199", "event_type":"price_change"}
{"market":"0x38f3050258345e9cf363d1c8cc302f08c65b96ba1a4669d81e07ed69708344df", "price_changes":[{"asset_id":"81916206347121459497221114766050949090435061493822476265356047392175668050706", "price":"0.01", "size":"4139", "side":"BUY", "hash":"135558022b108ad174a4fab1999be9e12218ffda", "best_bid":"0.01", "best_ask":"0.02"}, {"asset_id":"96888240988495161476033313796107536512663280794332045579302109906525918376981", "price":"0.99", "size":"4139", "side":"SELL", "hash":"0779649876e8c67de899e627fb0a7c8fb052fad6", "best_bid":"0.98", "best_ask":"0.99"}], "timestamp":"1770241474200", "event_type":"price_change"}
{"market":"0x38f3050258345e9cf363d1c8cc302f08c65b96ba1a4669d81e07ed69708344df", "price_changes":[{"asset_id":"96888240988495161476033313796107536512663280794332045579302109906525918376981", "price":"0.97", "size":"555.32", "side":"BUY", "hash":"f1cad823a154c3d0fe7f466bea7e34d265ffa5a0", "best_bid":"0.98", "best_ask":"0.99"}, {"asset_id":"81916206347121459497221114766050949090435061493822476265356047392175668050706", "price":"0.03", "size":"555.32", "side":"SELL", "hash":"d6a7ec8e02d84cfb7af5f37aec661ca993eb7178", "best_bid":"0.01", "best_ask":"0.02"}], "timestamp":"1770241474201", "event_type":"price_change"}
{"market":"0x38f3050258345e9cf363d1c8cc302f08c65b96ba1a4669d81e07ed69708344df", "price_changes":[{"asset_id":"96888240988495161476033313796107536512663280794332045579302109906525918376981", "price":"0.99", "size":"4099", "side":"SELL", "hash":"bec86a51cf982e17916f3ad37ceabed293a6f89d", "best_bid":"0.98", "best_ask":"0.99"}, {"asset_id":"81916206347121459497221114766050949090435061493822476265356047392175668050706", "price":"0.01", "size":"4099", "side":"BUY", "hash":"0fa6e4e9f18915e8e6aa8a01fec2e8cf67277c5e", "best_bid":"0.01", "best_ask":"0.02"}], "timestamp":"1770241474202", "event_type":"price_change"}
{"market":"0x38f3050258345e9cf363d1c8cc302f08c65b96ba1a4669d81e07ed69708344df", "price_changes":[{"asset_id":"96888240988495161476033313796107536512663280794332045579302109906525918376981", "price":"0.98", "size":"138.97", "side":"BUY", "hash":"20e39954bc4389c62195b5edc104d623f1fe88c6", "best_bid":"0.98", "best_ask":"0.99"}, {"asset_id":"81916206347121459497221114766050949090435061493822476265356047392175668050706", "price":"0.02", "size":"138.97", "side":"SELL", "hash":"147ed9a01717e2fa53e4c5e8decbba0b74e193ff", "best_bid":"0.01", "best_ask":"0.02"}], "timestamp":"1770241474230", "event_type":"price_change"}
{"market":"0x38f3050258345e9cf363d1c8cc302f08c65b96ba1a4669d81e07ed69708344df", "asset_id":"81916206347121459497221114766050949090435061493822476265356047392175668050706", "bids":[{"price":"0.01", "size":"4099"}], "asks":[{"price":"0.99", "size":"5019.91"}, {"price":"0.98", "size":"3034.23"}, {"price":"0.97", "size":"3172"}, {"price":"0.96", "size":"3012"}, {"price":"0.95", "size":"3032"}, {"price":"0.94", "size":"3012"}, {"price":"0.93", "size":"3126.28"}, {"price":"0.92", "size":"3012"}, {"price":"0.91", "size":"3012"}, {"price":"0.9", "size":"3087"}, {"price":"0.89", "size":"12"}, {"price":"0.88", "size":"12"}, {"price":"0.87", "size":"12"}, {"price":"0.86", "size":"12"}, {"price":"0.85", "size":"12"}, {"price":"0.84", "size":"12"}, {"price":"0.83", "size":"12"}, {"price":"0.82", "size":"12"}, {"price":"0.81", "size":"12"}, {"price":"0.8", "size":"12"}, {"price":"0.79", "size":"12"}, {"price":"0.78", "size":"12"}, {"price":"0.77", "size":"12"}, {"price":"0.76", "size":"112"}, {"price":"0.75", "size":"40.57"}, {"price":"0.74", "size":"12"}, {"price":"0.73", "size":"293.25"}, {"price":"0.72", "size":"22"}, {"price":"0.71", "size":"12"}, {"price":"0.7", "size":"18"}, {"price":"0.69", "size":"12"}, {"price":"0.68", "size":"12"}, {"price":"0.67", "size":"12"}, {"price":"0.66", "size":"160.89"}, {"price":"0.65", "size":"12"}, {"price":"0.64", "size":"12"}, {"price":"0.63", "size":"12"}, {"price":"0.62", "size":"19.39"}, {"price":"0.61", "size":"18.04"}, {"price":"0.6", "size":"12"}, {"price":"0.59", "size":"94.31"}, {"price":"0.58", "size":"5450.54"}, {"price":"0.57", "size":"12"}, {"price":"0.56", "size":"12"}, {"price":"0.55", "size":"12"}, {"price":"0.54", "size":"22"}, {"price":"0.53", "size":"12"}, {"price":"0.52", "size":"12"}, {"price":"0.51", "size":"12"}, {"price":"0.5", "size":"12"}, {"price":"0.49", "size":"12"}, {"price":"0.48", "size":"12"}, {"price":"0.47", "size":"12"}, {"price":"0.46", "size":"485.56"}, {"price":"0.45", "size":"31"}, {"price":"0.44", "size":"17"}, {"price":"0.43", "size":"12"}, {"price":"0.42", "size":"12"}, {"price":"0.41", "size":"12"}, {"price":"0.4", "size":"127"}, {"price":"0.39", "size":"12"}, {"price":"0.38", "size":"94.51"}, {"price":"0.37", "size":"31.99"}, {"price":"0.36", "size":"12"}, {"price":"0.35", "size":"37"}, {"price":"0.34", "size":"12"}, {"price":"0.33", "size":"12"}, {"price":"0.32", "size":"12"}, {"price":"0.31", "size":"12"}, {"price":"0.3", "size":"31.9"}, {"price":"0.29", "size":"344"}, {"price":"0.28", "size":"3288.99"}, {"price":"0.27", "size":"212"}, {"price":"0.26", "size":"218"}, {"price":"0.25", "size":"212"}, {"price":"0.24", "size":"212"}, {"price":"0.23", "size":"712"}, {"price":"0.22", "size":"1223.14"}, {"price":"0.21", "size":"212"}, {"price":"0.2", "size":"272.99"}, {"price":"0.19", "size":"212"}, {"price":"0.18", "size":"212"}, {"price":"0.17", "size":"212"}, {"price":"0.16", "size":"812"}, {"price":"0.15", "size":"231.08"}, {"price":"0.14", "size":"283.65"}, {"price":"0.13", "size":"212"}, {"price":"0.12", "size":"252"}, {"price":"0.11", "size":"252"}, {"price":"0.1", "size":"737.71"}, {"price":"0.09", "size":"326"}, {"price":"0.08", "size":"844.68"}, {"price":"0.07", "size":"826"}, {"price":"0.06", "size":"726"}, {"price":"0.05", "size":"626"}, {"price":"0.04", "size":"729.73"}, {"price":"0.03", "size":"555.32"}, {"price":"0.02", "size":"138.97"}], "hash":"147ed9a01717e2fa53e4c5e8decbba0b74e193ff", "timestamp":"1770241474230", "event_type":"book"}
{"market":"0x38f3050258345e9cf363d1c8cc302f08c65b96ba1a4669d81e07ed69708344df", "price_changes":[{"asset_id":"81916206347121459497221114766050949090435061493822476265356047392175668050706", "price":"0.01", "size":"4126", "side":"BUY", "hash":"df54a33b4d3a88094145ed7e97b0034c8b28a138", "best_bid":"0.01", "best_ask":"0.02"}, {"asset_id":"96888240988495161476033313796107536512663280794332045579302109906525918376981", "price":"0.99", "size":"4126", "side":"SELL", "hash":"24462d560b7905413f8723aa7dc1b10c810b88c6", "best_bid":"0.98", "best_ask":"0.99"}], "timestamp":"1770241474298", "event_type":"price_change"}
{"market":"0x38f3050258345e9cf363d1c8cc302f08c65b96ba1a4669d81e07ed69708344df", "price_changes":[{"asset_id":"81916206347121459497221114766050949090435061493822476265356047392175668050706", "price":"0.01", "size":"4099", "side":"BUY", "hash":"a09e833e849a59f2f3c9f45f5038829fbf6df4f0", "best_bid":"0.01", "best_ask":"0.02"}, {"asset_id":"96888240988495161476033313796107536512663280794332045579302109906525918376981", "price":"0.99", "size":"4099", "side":"SELL", "hash":"c7b5f3463c29f8477cee1cf29fd8a6e2cc5188f8", "best_bid":"0.98", "best_ask":"0.99"}], "timestamp":"1770241474302", "event_type":"price_change"}
{"market":"0x38f3050258345e9cf363d1c8cc302f08c65b96ba1a4669d81e07ed69708344df", "price_changes":[{"asset_id":"96888240988495161476033313796107536512663280794332045579302109906525918376981", "price":"0.96", "size":"702.73", "side":"BUY", "hash":"6012099f433f039a0d45f1cbc8dd0e0c8cacbba3", "best_bid":"0.98", "best_ask":"0.99"}, {"asset_id":"81916206347121459497221114766050949090435061493822476265356047392175668050706", "price":"0.04", "size":"702.73", "side":"SELL", "hash":"5bf525f804f13831b275f1b822a1911194c141f6", "best_bid":"0.01", "best_ask":"0.02"}], "timestamp":"1770241474303", "event_type":"price_change"}
{"market":"0x38f3050258345e9cf363d1c8cc302f08c65b96ba1a4669d81e07ed69708344df", "price_changes":[{"asset_id":"96888240988495161476033313796107536512663280794332045579302109906525918376981", "price":"0.95", "size":"653", "side":"BUY", "hash":"65a945d3579de8aeea42d5709da27f177b912593", "best_bid":"0.98", "best_ask":"0.99"}, {"asset_id":"81916206347121459497221114766050949090435061493822476265356047392175668050706", "price":"0.05", "size":"653", "side":"SELL", "hash":"500de7fac7bfc4e853f69ba6774407ece4d07763", "best_bid":"0.01", "best_ask":"0.02"}], "timestamp":"1770241474305", "event_type":"price_change"}
{"market":"0x38f3050258345e9cf363d1c8cc302f08c65b96ba1a4669d81e07ed69708344df", "price_changes":[{"asset_id":"96888240988495161476033313796107536512663280794332045579302109906525918376981", "price":"0.96", "size":"675.73", "side":"BUY", "hash":"77529fb981fc2bc32ce8d828526d2db3aa3145e2", "best_bid":"0.98", "best_ask":"0.99"}, {"asset_id":"81916206347121459497221114766050949090435061493822476265356047392175668050706", "price":"0.04", "size":"675.73", "side":"SELL", "hash":"12c42ef775e1ea0cae354ab3e21ac18220a19ae5", "best_bid":"0.01", "best_ask":"0.02"}], "timestamp":"1770241474309", "event_type":"price_change"}
{"market":"0x38f3050258345e9cf363d1c8cc302f08c65b96ba1a4669d81e07ed69708344df", "price_changes":[{"asset_id":"96888240988495161476033313796107536512663280794332045579302109906525918376981", "price":"0.95", "size":"680", "side":"BUY", "hash":"9ddb536b9f147f3a69cbe7181db652fa7250e065", "best_bid":"0.98", "best_ask":"0.99"}, {"asset_id":"81916206347121459497221114766050949090435061493822476265356047392175668050706", "price":"0.05", "size":"680", "side":"SELL", "hash":"4379184810c17788a95de671b3215e5b38a3ae15", "best_bid":"0.01", "best_ask":"0.02"}], "timestamp":"1770241474310", "event_type":"price_change"}
{"market":"0x38f3050258345e9cf363d1c8cc302f08c65b96ba1a4669d81e07ed69708344df", "price_changes":[{"asset_id":"81916206347121459497221114766050949090435061493822476265356047392175668050706", "price":"0.01", "size":"4072", "side":"BUY", "hash":"7f9c5d8a8ca67381b5b992b67bb695d0471b8913", "best_bid":"0.01", "best_ask":"0.02"}, {"asset_id":"96888240988495161476033313796107536512663280794332045579302109906525918376981", "price":"0.99", "size":"4072", "side":"SELL", "hash":"b2404e0e3413f88ec8216a69acce87f64c09f8bc", "best_bid":"0.98", "best_ask":"0.99"}], "timestamp":"1770241474310", "event_type":"price_change"}
{"market":"0x38f3050258345e9cf363d1c8cc302f08c65b96ba1a4669d81e07ed69708344df", "price_changes":[{"asset_id":"81916206347121459497221114766050949090435061493822476265356047392175668050706", "price":"0.01", "size":"4099", "side":"BUY", "hash":"9c357a314f77826db0fcfe1b6552eab9e6b3d9e8", "best_bid":"0.01", "best_ask":"0.02"}, {"asset_id":"96888240988495161476033313796107536512663280794332045579302109906525918376981", "price":"0.99", "size":"4099", "side":"SELL", "hash":"a23625caf44d8c83a0332df15e9d399bdccc324a", "best_bid":"0.98", "best_ask":"0.99"}], "timestamp":"1770241474313", "event_type":"price_change"}
{"market":"0x38f3050258345e9cf363d1c8cc302f08c65b96ba1a4669d81e07ed69708344df", "price_changes":[{"asset_id":"81916206347121459497221114766050949090435061493822476265356047392175668050706", "price":"0.01", "size":"4126", "side":"BUY", "hash":"e33051635a7b2a98ad6f97112fe0aef63b2db857", "best_bid":"0.01", "best_ask":"0.02"}, {"asset_id":"96888240988495161476033313796107536512663280794332045579302109906525918376981", "price":"0.99", "size":"4126", "side":"SELL", "hash":"f1df1271aa4bd912b04c6ec4d04896d269b4e444", "best_bid":"0.98", "best_ask":"0.99"}], "timestamp":"1770241474319", "event_type":"price_change"}
{"market":"0x38f3050258345e9cf363d1c8cc302f08c65b96ba1a4669d81e07ed69708344df", "price_changes":[{"asset_id":"81916206347121459497221114766050949090435061493822476265356047392175668050706", "price":"0.01", "size":"4099", "side":"BUY", "hash":"6a27621c73a72cd1b07b3842920f1ae66558dffe", "best_bid":"0.01", "best_ask":"0.02"}, {"asset_id":"96888240988495161476033313796107536512663280794332045579302109906525918376981", "price":"0.99", "size":"4099", "side":"SELL", "hash":"2305895922ea790e5f0c4b1eace648ecab040d6a", "best_bid":"0.98", "best_ask":"0.99"}], "timestamp":"1770241474319", "event_type":"price_change"}
{"market":"0x38f3050258345e9cf363d1c8cc302f08c65b96ba1a4669d81e07ed69708344df", "price_changes":[{"asset_id":"96888240988495161476033313796107536512663280794332045579302109906525918376981", "price":"0.97", "size":"528.32", "side":"BUY", "hash":"3776de1294167dc01f8e21f8ba107f8f66abb9fe", "best_bid":"0.98", "best_ask":"0.99"}, {"asset_id":"81916206347121459497221114766050949090435061493822476265356047392175668050706", "price":"0.03", "size":"528.32", "side":"SELL", "hash":"e8867f5480eb268035d99f9829955a5b1b29edd5", "best_bid":"0.01", "best_ask":"0.02"}], "timestamp":"1770241474320", "event_type":"price_change"}
{"market":"0x38f3050258345e9cf363d1c8cc302f08c65b96ba1a4669d81e07ed69708344df", "price_changes":[{"asset_id":"96888240988495161476033313796107536512663280794332045579302109906525918376981", "price":"0.96", "size":"702.73", "side":"BUY", "hash":"60ed641d7cf6e0c4472e579e9ed7c85a56edb2ff", "best_bid":"0.98", "best_ask":"0.99"}, {"asset_id":"81916206347121459497221114766050949090435061493822476265356047392175668050706", "price":"0.04", "size":"702.73", "side":"SELL", "hash":"9a6110b6eea186eb8c20a6cc163382748456ca3e", "best_bid":"0.01", "best_ask":"0.02"}], "timestamp":"1770241474323", "event_type":"price_change"}
{"market":"0x38f3050258345e9cf363d1c8cc302f08c65b96ba1a4669d81e07ed69708344df", "price_changes":[{"asset_id":"81916206347121459497221114766050949090435061493822476265356047392175668050706", "price":"0.01", "size":"4072", "side":"BUY", "hash":"036da06f21b27ab7a0115832e773a2673b761935", "best_bid":"0.01", "best_ask":"0.02"}, {"asset_id":"96888240988495161476033313796107536512663280794332045579302109906525918376981", "price":"0.99", "size":"4072", "side":"SELL", "hash":"ab8a07d347707a0693b4d88dc9764030dbdfe346", "best_bid":"0.98", "best_ask":"0.99"}], "timestamp":"1770241474497", "event_type":"price_change"}
{"market":"0x38f3050258345e9cf363d1c8cc302f08c65b96ba1a4669d81e07ed69708344df", "price_changes":[{"asset_id":"96888240988495161476033313796107536512663280794332045579302109906525918376981", "price":"0.94", "size":"753", "side":"BUY", "hash":"b05c2753f152ff4acf57d70be67dbf66c543e48b", "best_bid":"0.98", "best_ask":"0.99"}, {"asset_id":"81916206347121459497221114766050949090435061493822476265356047392175668050706", "price":"0.06", "size":"753", "side":"SELL", "hash":"d806801b184aa74753613f2ad577ab45c39c6e79", "best_bid":"0.01", "best_ask":"0.02"}], "timestamp":"1770241474499", "event_type":"price_change"}
{"market":"0x38f3050258345e9cf363d1c8cc302f08c65b96ba1a4669d81e07ed69708344df", "price_changes":[{"asset_id":"81916206347121459497221114766050949090435061493822476265356047392175668050706", "price":"0.01", "size":"4099", "side":"BUY", "hash":"59d013324cd0e064e44437748e1b5656d5ff8c10", "best_bid":"0.01", "best_ask":"0.02"}, {"asset_id":"96888240988495161476033313796107536512663280794332045579302109906525918376981", "price":"0.99", "size":"4099", "side":"SELL", "hash":"12300326114e6834dddcf60e7493bfd237d4006e", "best_bid":"0.98", "best_ask":"0.99"}], "timestamp":"1770241474500", "event_type":"price_change"}
{"market":"0x38f3050258345e9cf363d1c8cc302f08c65b96ba1a4669d81e07ed69708344df", "price_changes":[{"asset_id":"96888240988495161476033313796107536512663280794332045579302109906525918376981", "price":"0.95", "size":"653", "side":"BUY", "hash":"f6343345046645abf8b57262f01ac2b3b243954e", "best_bid":"0.98", "best_ask":"0.99"}, {"asset_id":"81916206347121459497221114766050949090435061493822476265356047392175668050706", "price":"0.05", "size":"653", "side":"SELL", "hash":"369db413cd81f9501127cad7c6a300016a452bb5", "best_bid":"0.01", "best_ask":"0.02"}], "timestamp":"1770241474500", "event_type":"price_change"}
{"market":"0x38f3050258345e9cf363d1c8cc302f08c65b96ba1a4669d81e07ed69708344df", "price_changes":[{"asset_id":"81916206347121459497221114766050949090435061493822476265356047392175668050706", "price":"0.01", "size":"4072", "side":"BUY", "hash":"c718454f782f14db7b800af632dc1493dd35b05a", "best_bid":"0.01", "best_ask":"0.02"}, {"asset_id":"96888240988495161476033313796107536512663280794332045579302109906525918376981", "price":"0.99", "size":"4072", "side":"SELL", "hash":"fd9b98cdbc73a3b5414c841cd999908d37fd02f9", "best_bid":"0.98", "best_ask":"0.99"}], "timestamp":"1770241474509", "event_type":"price_change"}
{"market":"0x38f3050258345e9cf363d1c8cc302f08c65b96ba1a4669d81e07ed69708344df", "price_changes":[{"asset_id":"81916206347121459497221114766050949090435061493822476265356047392175668050706", "price":"0.01", "size":"4099", "side":"BUY", "hash":"3c9ede3bcfd530f7aa46da53c661e0c7c3f65833", "best_bid":"0.01", "best_ask":"0.02"}, {"asset_id":"96888240988495161476033313796107536512663280794332045579302109906525918376981", "price":"0.99", "size":"4099", "side":"SELL", "hash":"77cf813783cc776aa60b9bab0a296c5e7d59e960", "best_bid":"0.98", "best_ask":"0.99"}], "timestamp":"1770241474510", "event_type":"price_change"}
{"market":"0x38f3050258345e9cf363d1c8cc302f08c65b96ba1a4669d81e07ed69708344df", "price_changes":[{"asset_id":"96888240988495161476033313796107536512663280794332045579302109906525918376981", "price":"0.95", "size":"626", "side":"BUY", "hash":"0abfaf4521db6cd1a0faeadb306738abeb4cfaa5", "best_bid":"0.98", "best_ask":"0.99"}, {"asset_id":"81916206347121459497221114766050949090435061493822476265356047392175668050706", "price":"0.05", "size":"626", "side":"SELL", "hash":"9a77bd019ee0580852234df475811369882cdd1b", "best_bid":"0.01", "best_ask":"0.02"}], "timestamp":"1770241474513", "event_type":"price_change"}
{"market":"0x38f3050258345e9cf363d1c8cc302f08c65b96ba1a4669d81e07ed69708344df", "price_changes":[{"asset_id":"81916206347121459497221114766050949090435061493822476265356047392175668050706", "price":"0.01", "size":"4072", "side":"BUY", "hash":"513485101c928b0208bfc2eab16efbe486a75212", "best_bid":"0.01", "best_ask":"0.02"}, {"asset_id":"96888240988495161476033313796107536512663280794332045579302109906525918376981", "price":"0.99", "size":"4072", "side":"SELL", "hash":"bcaa62253e6db0a3a34730b2746c2d3df069aeea", "best_bid":"0.98", "best_ask":"0.99"}], "timestamp":"1770241474515", "event_type":"price_change"}
{"market":"0x38f3050258345e9cf363d1c8cc302f08c65b96ba1a4669d81e07ed69708344df", "price_changes":[{"asset_id":"96888240988495161476033313796107536512663280794332045579302109906525918376981", "price":"0.96", "size":"675.73", "side":"BUY", "hash":"8b3585e7be9a21bf291286a9ac7a85d6cf5fd967", "best_bid":"0.98", "best_ask":"0.99"}, {"asset_id":"81916206347121459497221114766050949090435061493822476265356047392175668050706", "price":"0.04", "size":"675.73", "side":"SELL", "hash":"d7ec2265d38623172b7920322e8cab4f7e0a132b", "best_bid":"0.01", "best_ask":"0.02"}], "timestamp":"1770241474518", "event_type":"price_change"}
{"market":"0x38f3050258345e9cf363d1c8cc302f08c65b96ba1a4669d81e07ed69708344df", "price_changes":[{"asset_id":"96888240988495161476033313796107536512663280794332045579302109906525918376981", "price":"0.95", "size":"653", "side":"BUY", "hash":"85d2a6837f41e23f736e31df5068f2d386b49601", "best_bid":"0.98", "best_ask":"0.99"}, {"asset_id":"81916206347121459497221114766050949090435061493822476265356047392175668050706", "price":"0.05", "size":"653", "side":"SELL", "hash":"e746867262d1edc68b1a6d98e97ab3efbb825293", "best_bid":"0.01", "best_ask":"0.02"}], "timestamp":"1770241474519", "event_type":"price_change"}
{"market":"0x38f3050258345e9cf363d1c8cc302f08c65b96ba1a4669d81e07ed69708344df", "price_changes":[{"asset_id":"81916206347121459497221114766050949090435061493822476265356047392175668050706", "price":"0.01", "size":"4099", "side":"BUY", "hash":"85e05da1a64fe2ab84e52c32f84f26c7ce6b1c83", "best_bid":"0.01", "best_ask":"0.02"}, {"asset_id":"96888240988495161476033313796107536512663280794332045579302109906525918376981", "price":"0.99", "size":"4099", "side":"SELL", "hash":"13cd39938f8a0e240181f4ff98108bfd633dc25d", "best_bid":"0.98", "best_ask":"0.99"}], "timestamp":"1770241474520", "event_type":"price_change"}
{"market":"0x38f3050258345e9cf363d1c8cc302f08c65b96ba1a4669d81e07ed69708344df", "price_changes":[{"asset_id":"96888240988495161476033313796107536512663280794332045579302109906525918376981", "price":"0.94", "size":"780", "side":"BUY", "hash":"4cff61674eb57b38199e43c32e3fd3fbb9cbef91", "best_bid":"0.98", "best_ask":"0.99"}, {"asset_id":"81916206347121459497221114766050949090435061493822476265356047392175668050706", "price":"0.06", "size":"780", "side":"SELL", "hash":"65b4bd9de9c288d00673835f68e9542512acf097", "best_bid":"0.01", "best_ask":"0.02"}], "timestamp":"1770241474520", "event_type":"price_change"}
{"market":"0x38f3050258345e9cf363d1c8cc302f08c65b96ba1a4669d81e07ed69708344df", "price_changes":[{"asset_id":"96888240988495161476033313796107536512663280794332045579302109906525918376981", "price":"0.94", "size":"753", "side":"BUY", "hash":"1cfa0ac5c49a90c9e497639bf2c52758b1098de8", "best_bid":"0.98", "best_ask":"0.99"}, {"asset_id":"81916206347121459497221114766050949090435061493822476265356047392175668050706", "price":"0.06", "size":"753", "side":"SELL", "hash":"43337b2a9187960fa1b136c6956d21dec7210fe4", "best_bid":"0.01", "best_ask":"0.02"}], "timestamp":"1770241474678", "event_type":"price_change"}
{"market":"0x38f3050258345e9cf363d1c8cc302f08c65b96ba1a4669d81e07ed69708344df", "price_changes":[{"asset_id":"81916206347121459497221114766050949090435061493822476265356047392175668050706", "price":"0.01", "size":"4126", "side":"BUY", "hash":"6c81b2613190a9178f0af955544557ae8e28a527", "best_bid":"0.01", "best_ask":"0.02"}, {"asset_id":"96888240988495161476033313796107536512663280794332045579302109906525918376981", "price":"0.99", "size":"4126", "side":"SELL", "hash":"d68d4fb41f891463e4f4c4ec50beabc1116095c7", "best_bid":"0.98", "best_ask":"0.99"}], "timestamp":"1770241474679", "event_type":"price_change"}
{"market":"0x38f3050258345e9cf363d1c8cc302f08c65b96ba1a4669d81e07ed69708344df", "price_changes":[{"asset_id":"81916206347121459497221114766050949090435061493822476265356047392175668050706", "price":"0.01", "size":"4099", "side":"BUY", "hash":"ec3b90ffcf5b3814981af80ae880f76b5ff8fbbe", "best_bid":"0.01", "best_ask":"0.02"}, {"asset_id":"96888240988495161476033313796107536512663280794332045579302109906525918376981", "price":"0.99", "size":"4099", "side":"SELL", "hash":"f2040dc510e092c1c00acd031fec16a02dc16f65", "best_bid":"0.98", "best_ask":"0.99"}], "timestamp":"1770241474681", "event_type":"price_change"}
{"market":"0x38f3050258345e9cf363d1c8cc302f08c65b96ba1a4669d81e07ed69708344df", "price_changes":[{"asset_id":"96888240988495161476033313796107536512663280794332045579302109906525918376981", "price":"0.95", "size":"680", "side":"BUY", "hash":"11eac443d54829a9c3f4bfd86fbb8838297eb7c3", "best_bid":"0.98", "best_ask":"0.99"}, {"asset_id":"81916206347121459497221114766050949090435061493822476265356047392175668050706", "price":"0.05", "size":"680", "side":"SELL", "hash":"ac86ad5974b95dbb7376e893fc2c4701d3aba66e", "best_bid":"0.01", "best_ask":"0.02"}], "timestamp":"1770241474682", "event_type":"price_change"}
{"market":"0x38f3050258345e9cf363d1c8cc302f08c65b96ba1a4669d81e07ed69708344df", "price_changes":[{"asset_id":"81916206347121459497221114766050949090435061493822476265356047392175668050706", "price":"0.01", "size":"4126", "side":"BUY", "hash":"b1c53a659c94f9674d8a8ab7b6888a9104b28205", "best_bid":"0.01", "best_ask":"0.02"}, {"asset_id":"96888240988495161476033313796107536512663280794332045579302109906525918376981", "price":"0.99", "size":"4126", "side":"SELL", "hash":"bd89685833de99e3d461e5e1c80f16cb3aaef4f1", "best_bid":"0.98", "best_ask":"0.99"}], "timestamp":"1770241474689", "event_type":"price_change"}
{"market":"0x38f3050258345e9cf363d1c8cc302f08c65b96ba1a4669d81e07ed69708344df", "price_changes":[{"asset_id":"96888240988495161476033313796107536512663280794332045579302109906525918376981", "price":"0.95", "size":"707", "side":"BUY", "hash":"cad352145e4f62786d0a70d882645366dc7edf2d", "best_bid":"0.98", "best_ask":"0.99"}, {"asset_id":"81916206347121459497221114766050949090435061493822476265356047392175668050706", "price":"0.05", "size":"707", "side":"SELL", "hash":"630fafa616d925e07fdf700a3fab088cc09aa1e9", "best_bid":"0.01", "best_ask":"0.02"}], "timestamp":"1770241474691", "event_type":"price_change"}
{"market":"0x38f3050258345e9cf363d1c8cc302f08c65b96ba1a4669d81e07ed69708344df", "price_changes":[{"asset_id":"96888240988495161476033313796107536512663280794332045579302109906525918376981", "price":"0.94", "size":"726", "side":"BUY", "hash":"736a5db353c37239e09d50e9db0030221347e3a3", "best_bid":"0.98", "best_ask":"0.99"}, {"asset_id":"81916206347121459497221114766050949090435061493822476265356047392175668050706", "price":"0.06", "size":"726", "side":"SELL", "hash":"a6f4daf1ab28d7a38980193cbccb493171031f8b", "best_bid":"0.01", "best_ask":"0.02"}], "timestamp":"1770241474692", "event_type":"price_change"}
{"market":"0x38f3050258345e9cf363d1c8cc302f08c65b96ba1a4669d81e07ed69708344df", "price_changes":[{"asset_id":"81916206347121459497221114766050949090435061493822476265356047392175668050706", "price":"0.01", "size":"4099", "side":"BUY", "hash":"22f4839749554429573c1c1c346dd2d825d04fa8", "best_bid":"0.01", "best_ask":"0.02"}, {"asset_id":"96888240988495161476033313796107536512663280794332045579302109906525918376981", "price":"0.99", "size":"4099", "side":"SELL", "hash":"a42fd1c8a5aca40debaac29ac42d51e1e9f500c6", "best_bid":"0.98", "best_ask":"0.99"}], "timestamp":"1770241474693", "event_type":"price_change"}
{"market":"0x38f3050258345e9cf363d1c8cc302f08c65b96ba1a4669d81e07ed69708344df", "price_changes":[{"asset_id":"81916206347121459497221114766050949090435061493822476265356047392175668050706", "price":"0.01", "size":"4126", "side":"BUY", "hash":"d9e67704d0038cc2294458388fc06313adb5fec7", "best_bid":"0.01", "best_ask":"0.02"}, {"asset_id":"96888240988495161476033313796107536512663280794332045579302109906525918376981", "price":"0.99", "size":"4126", "side":"SELL", "hash":"be931d95b81aca6f037709f6ea7c2a6d152a3a67", "best_bid":"0.98", "best_ask":"0.99"}], "timestamp":"1770241474697", "event_type":"price_change"}
{"market":"0x38f3050258345e9cf363d1c8cc302f08c65b96ba1a4669d81e07ed69708344df", "price_changes":[{"asset_id":"96888240988495161476033313796107536512663280794332045579302109906525918376981", "price":"0.95", "size":"680", "side":"BUY", "hash":"2d0f85f4f89b79d6258c15685fb872637dc0dd14", "best_bid":"0.98", "best_ask":"0.99"}, {"asset_id":"81916206347121459497221114766050949090435061493822476265356047392175668050706", "price":"0.05", "size":"680", "side":"SELL", "hash":"8b7a6544184bd25af5f0ec2680aa6f30c6f2a7e1", "best_bid":"0.01", "best_ask":"0.02"}], "timestamp":"1770241474698", "event_type":"price_change"}
{"market":"0x38f3050258345e9cf363d1c8cc302f08c65b96ba1a4669d81e07ed69708344df", "price_changes":[{"asset_id":"81916206347121459497221114766050949090435061493822476265356047392175668050706", "price":"0.01", "size":"4099", "side":"BUY", "hash":"5cc1afc8fc77707025dab32e036bfa7070485eac", "best_bid":"0.01", "best_ask":"0.02"}, {"asset_id":"96888240988495161476033313796107536512663280794332045579302109906525918376981", "price":"0.99", "size":"4099", "side":"SELL", "hash":"0931973eef7c445fb0a2ccb0e451a4c9e977be9b", "best_bid":"0.98", "best_ask":"0.99"}], "timestamp":"1770241474699", "event_type":"price_change"}
{"market":"0x38f3050258345e9cf363d1c8cc302f08c65b96ba1a4669d81e07ed69708344df", "price_changes":[{"asset_id":"96888240988495161476033313796107536512663280794332045579302109906525918376981", "price":"0.96", "size":"702.73", "side":"BUY", "hash":"c40899b40540e136984d1c9e8df0c807e152a78d", "best_bid":"0.98", "best_ask":"0.99"}, {"asset_id":"81916206347121459497221114766050949090435061493822476265356047392175668050706", "price":"0.04", "size":"702.73", "side":"SELL", "hash":"0636ca7da949ab083b4901aea9b4aad617f37562", "best_bid":"0.01", "best_ask":"0.02"}], "timestamp":"1770241474700", "event_type":"price_change"}
{"market":"0x38f3050258345e9cf363d1c8cc302f08c65b96ba1a4669d81e07ed69708344df", "price_changes":[{"asset_id":"81916206347121459497221114766050949090435061493822476265356047392175668050706", "price":"0.01", "size":"4072", "side":"BUY", "hash":"be0c3e688334ee180e37f706768872ed814cc9bf", "best_bid":"0.01", "best_ask":"0.02"}, {"asset_id":"96888240988495161476033313796107536512663280794332045579302109906525918376981", "price":"0.99", "size":"4072", "side":"SELL", "hash":"2cc5fb485461dc6a8a546b541969d510c6352940", "best_bid":"0.98", "best_ask":"0.99"}], "timestamp":"1770241474864", "event_type":"price_change"}
{"market":"0x38f3050258345e9cf363d1c8cc302f08c65b96ba1a4669d81e07ed69708344df", "price_changes":[{"asset_id":"96888240988495161476033313796107536512663280794332045579302109906525918376981", "price":"0.94", "size":"753", "side":"BUY", "hash":"72f7af9c098723219ae932bd73cd1b6d7e26c1a2", "best_bid":"0.98", "best_ask":"0.99"}, {"asset_id":"81916206347121459497221114766050949090435061493822476265356047392175668050706", "price":"0.06", "size":"753", "side":"SELL", "hash":"fa5c671dd7905b116041d79df5351952e80305a3", "best_bid":"0.01", "best_ask":"0.02"}], "timestamp":"1770241474865", "event_type":"price_change"}
{"market":"0x38f3050258345e9cf363d1c8cc302f08c65b96ba1a4669d81e07ed69708344df", "price_changes":[{"asset_id":"81916206347121459497221114766050949090435061493822476265356047392175668050706", "price":"0.01", "size":"4099", "side":"BUY", "hash":"043f102fec814f3620c0d0dcb1c900b7d21aea87", "best_bid":"0.01", "best_ask":"0.02"}, {"asset_id":"96888240988495161476033313796107536512663280794332045579302109906525918376981", "price":"0.99", "size":"4099", "side":"SELL", "hash":"aa5ffbccbc355f6bbad9d5e50648ec757a0f01eb", "best_bid":"0.98", "best_ask":"0.99"}], "timestamp":"1770241474865", "event_type":"price_change"}
{"market":"0x38f3050258345e9cf363d1c8cc302f08c65b96ba1a4669d81e07ed69708344df", "price_changes":[{"asset_id":"96888240988495161476033313796107536512663280794332045579302109906525918376981", "price":"0.95", "size":"653", "side":"BUY", "hash":"9d37c8c4fc0eee546ea47dc089ab7a80758186e3", "best_bid":"0.98", "best_ask":"0.99"}, {"asset_id":"81916206347121459497221114766050949090435061493822476265356047392175668050706", "price":"0.05", "size":"653", "side":"SELL", "hash":"40bb0830ee75819b509cfcc3938bd43723482e61", "best_bid":"0.01", "best_ask":"0.02"}], "timestamp":"1770241474866", "event_type":"price_change"}
{"market":"0x38f3050258345e9cf363d1c8cc302f08c65b96ba1a4669d81e07ed69708344df", "price_changes":[{"asset_id":"96888240988495161476033313796107536512663280794332045579302109906525918376981", "price":"0.79", "size":"412", "side":"BUY", "hash":"008b6c251a9520d576898308218877760fc41e48", "best_bid":"0.98", "best_ask":"0.99"}, {"asset_id":"81916206347121459497221114766050949090435061493822476265356047392175668050706", "price":"0.21", "size":"412", "side":"SELL", "hash":"9ce6b8d70ceb4c18fc4d5a71df287342f0a1288d", "best_bid":"0.01", "best_ask":"0.02"}], "timestamp":"1770241474869", "event_type":"price_change"}
{"market":"0x38f3050258345e9cf363d1c8cc302f08c65b96ba1a4669d81e07ed69708344df", "price_changes":[{"asset_id":"96888240988495161476033313796107536512663280794332045579302109906525918376981", "price":"0.95", "size":"626", "side":"BUY", "hash":"242725e5005ffb4be321c70b969307d682b8fa95", "best_bid":"0.98", "best_ask":"0.99"}, {"asset_id":"81916206347121459497221114766050949090435061493822476265356047392175668050706", "price":"0.05", "size":"626", "side":"SELL", "hash":"2b9ed8dccea2306981e684a27f74d8e8fc58cc6e", "best_bid":"0.01", "best_ask":"0.02"}], "timestamp":"1770241474874", "event_type":"price_change"}
{"market":"0x38f3050258345e9cf363d1c8cc302f08c65b96ba1a4669d81e07ed69708344df", "price_changes":[{"asset_id":"81916206347121459497221114766050949090435061493822476265356047392175668050706", "price":"0.01", "size":"4126", "side":"BUY", "hash":"1dcf791bf6d5d76138de4114cf53f2baa3703513", "best_bid":"0.01", "best_ask":"0.02"}, {"asset_id":"96888240988495161476033313796107536512663280794332045579302109906525918376981", "price":"0.99", "size":"4126", "side":"SELL", "hash":"9d6aaa66a5904eaad6d6826709c8222d2435d761", "best_bid":"0.98", "best_ask":"0.99"}], "timestamp":"1770241474881", "event_type":"price_change"}
{"market":"0x38f3050258345e9cf363d1c8cc302f08c65b96ba1a4669d81e07ed69708344df", "price_changes":[{"asset_id":"96888240988495161476033313796107536512663280794332045579302109906525918376981", "price":"0.94", "size":"780", "side":"BUY", "hash":"f7618c91af790dae7bbc1270406a5d49e22e5469", "best_bid":"0.98", "best_ask":"0.99"}, {"asset_id":"81916206347121459497221114766050949090435061493822476265356047392175668050706", "price":"0.06", "size":"780", "side":"SELL", "hash":"45af04c5cd0c259ade70e95b1b091d682410d62a", "best_bid":"0.01", "best_ask":"0.02"}], "timestamp":"1770241474882", "event_type":"price_change"}
{"market":"0x38f3050258345e9cf363d1c8cc302f08c65b96ba1a4669d81e07ed69708344df", "price_changes":[{"asset_id":"81916206347121459497221114766050949090435061493822476265356047392175668050706", "price":"0.01", "size":"4099", "side":"BUY", "hash":"62802c3eb5e476e29b1cea31bbe657287e730be3", "best_bid":"0.01", "best_ask":"0.02"}, {"asset_id":"96888240988495161476033313796107536512663280794332045579302109906525918376981", "price":"0.99", "size":"4099", "side":"SELL", "hash":"4446b8942d35e145cdd81872ff5c41ba78b4d3bb", "best_bid":"0.98", "best_ask":"0.99"}], "timestamp":"1770241474891", "event_type":"price_change"}
{"market":"0x38f3050258345e9cf363d1c8cc302f08c65b96ba1a4669d81e07ed69708344df", "price_changes":[{"asset_id":"81916206347121459497221114766050949090435061493822476265356047392175668050706", "price":"0.01", "size":"4126", "side":"BUY", "hash":"f0adcce713da82eb342a549bfbbd4d2aa709ad75", "best_bid":"0.01", "best_ask":"0.02"}, {"asset_id":"96888240988495161476033313796107536512663280794332045579302109906525918376981", "price":"0.99", "size":"4126", "side":"SELL", "hash":"b3fef869f49534885ec4af34d432396aeb520842", "best_bid":"0.98", "best_ask":"0.99"}], "timestamp":"1770241474995", "event_type":"price_change"}
{"market":"0x38f3050258345e9cf363d1c8cc302f08c65b96ba1a4669d81e07ed69708344df", "price_changes":[{"asset_id":"96888240988495161476033313796107536512663280794332045579302109906525918376981", "price":"0.96", "size":"675.73", "side":"BUY", "hash":"1cffe5a4864e770901b4666d8fe6ef3ee71c7762", "best_bid":"0.98", "best_ask":"0.99"}, {"asset_id":"81916206347121459497221114766050949090435061493822476265356047392175668050706", "price":"0.04", "size":"675.73", "side":"SELL", "hash":"770bedfedfb17d3649603c666aa2d4b298392678", "best_bid":"0.01", "best_ask":"0.02"}], "timestamp":"1770241474997", "event_type":"price_change"}
{"market":"0x38f3050258345e9cf363d1c8cc302f08c65b96ba1a4669d81e07ed69708344df", "price_changes":[{"asset_id":"81916206347121459497221114766050949090435061493822476265356047392175668050706", "price":"0.01", "size":"4099", "side":"BUY", "hash":"90f3a86902b6d32abc503a9cabede33338a2942e", "best_bid":"0.01", "best_ask":"0.02"}, {"asset_id":"96888240988495161476033313796107536512663280794332045579302109906525918376981", "price":"0.99", "size":"4099", "side":"SELL", "hash":"0b3a7faaa9058eace6e5f6f5c7474aeb2fc7488c", "best_bid":"0.98", "best_ask":"0.99"}], "timestamp":"1770241474997", "event_type":"price_change"}
{"market":"0x38f3050258345e9cf363d1c8cc302f08c65b96ba1a4669d81e07ed69708344df", "price_changes":[{"asset_id":"96888240988495161476033313796107536512663280794332045579302109906525918376981", "price":"0.95", "size":"653", "side":"BUY", "hash":"b650669a3a0cdb4f872525392a7ab659a8bbeba8", "best_bid":"0.98", "best_ask":"0.99"}, {"asset_id":"81916206347121459497221114766050949090435061493822476265356047392175668050706", "price":"0.05", "size":"653", "side":"SELL", "hash":"7b2f1d937ff6e5ed951da9689e191a789404728d", "best_bid":"0.01", "best_ask":"0.02"}], "timestamp":"1770241475004", "event_type":"price_change"}
{"market":"0x38f3050258345e9cf363d1c8cc302f08c65b96ba1a4669d81e07ed69708344df", "price_changes":[{"asset_id":"96888240988495161476033313796107536512663280794332045579302109906525918376981", "price":"0.91", "size":"281", "side":"BUY", "hash":"8f5dfdbf73f7e1ffd2276559a92ae0da6c860b6e", "best_bid":"0.98", "best_ask":"0.99"}, {"asset_id":"81916206347121459497221114766050949090435061493822476265356047392175668050706", "price":"0.09", "size":"281", "side":"SELL", "hash":"69ba5459e74b671065de8495e0cc0981e4a6fb5f", "best_bid":"0.01", "best_ask":"0.02"}], "timestamp":"1770241475013", "event_type":"price_change"}
{"market":"0x38f3050258345e9cf363d1c8cc302f08c65b96ba1a4669d81e07ed69708344df", "price_changes":[{"asset_id":"96888240988495161476033313796107536512663280794332045579302109906525918376981", "price":"0.97", "size":"573.32", "side":"BUY", "hash":"f6c1b36fd43a6a27692c502059d34219a7263ea0", "best_bid":"0.98", "best_ask":"0.99"}, {"asset_id":"81916206347121459497221114766050949090435061493822476265356047392175668050706", "price":"0.03", "size":"573.32", "side":"SELL", "hash":"76125377fcf269d1a5c387db51a2b75a9122a11d", "best_bid":"0.01", "best_ask":"0.02"}], "timestamp":"1770241475016", "event_type":"price_change"}
{"market":"0x38f3050258345e9cf363d1c8cc302f08c65b96ba1a4669d81e07ed69708344df", "price_changes":[{"asset_id":"81916206347121459497221114766050949090435061493822476265356047392175668050706", "price":"0.01", "size":"4072", "side":"BUY", "hash":"42d8e26a45e42afd942807c3cbb9f7d0715f478b", "best_bid":"0.01", "best_ask":"0.02"}, {"asset_id":"96888240988495161476033313796107536512663280794332045579302109906525918376981", "price":"0.99", "size":"4072", "side":"SELL", "hash":"0b5bb1564cff04e3f8ad3b7bdd1280326ad377d0", "best_bid":"0.98", "best_ask":"0.99"}], "timestamp":"1770241475023", "event_type":"price_change"}
{"market":"0x38f3050258345e9cf363d1c8cc302f08c65b96ba1a4669d81e07ed69708344df", "price_changes":[{"asset_id":"81916206347121459497221114766050949090435061493822476265356047392175668050706", "price":"0.01", "size":"4099", "side":"BUY", "hash":"e868c11d1d2593bae3c0e4de53d4b9072ca8c600", "best_bid":"0.01", "best_ask":"0.02"}, {"asset_id":"96888240988495161476033313796107536512663280794332045579302109906525918376981", "price":"0.99", "size":"4099", "side":"SELL", "hash":"6b55c86649d7bb0652721796b568820b8ed8d27e", "best_bid":"0.98", "best_ask":"0.99"}], "timestamp":"1770241475023", "event_type":"price_change"}
{"market":"0x38f3050258345e9cf363d1c8cc302f08c65b96ba1a4669d81e07ed69708344df", "price_changes":[{"asset_id":"96888240988495161476033313796107536512663280794332045579302109906525918376981", "price":"0.97", "size":"593.32", "side":"BUY", "hash":"960ad5554d8a33f620e4e1049b6811d374c856ac", "best_bid":"0.98", "best_ask":"0.99"}, {"asset_id":"81916206347121459497221114766050949090435061493822476265356047392175668050706", "price":"0.03", "size":"593.32", "side":"SELL", "hash":"5b824eb61544a68e909d75f5e0a9431da2295a9a", "best_bid":"0.01", "best_ask":"0.02"}], "timestamp":"1770241475024", "event_type":"price_change"}
{"market":"0x38f3050258345e9cf363d1c8cc302f08c65b96ba1a4669d81e07ed69708344df", "price_changes":[{"asset_id":"96888240988495161476033313796107536512663280794332045579302109906525918376981", "price":"0.94", "size":"753", "side":"BUY", "hash":"23af47220f67a76f3470e8e58c49d8bda942818c", "best_bid":"0.98", "best_ask":"0.99"}, {"asset_id":"81916206347121459497221114766050949090435061493822476265356047392175668050706", "price":"0.06", "size":"753", "side":"SELL", "hash":"2ec0548f90bd892af71ecaed5ec20eb227c7fc4f", "best_bid":"0.01", "best_ask":"0.02"}], "timestamp":"1770241475024", "event_type":"price_change"}
{"market":"0x38f3050258345e9cf363d1c8cc302f08c65b96ba1a4669d81e07ed69708344df", "price_changes":[{"asset_id":"96888240988495161476033313796107536512663280794332045579302109906525918376981", "price":"0.95", "size":"680", "side":"BUY", "hash":"1ac30080a52a34f193014b93ea531c1dc191be1e", "best_bid":"0.98", "best_ask":"0.99"}, {"asset_id":"81916206347121459497221114766050949090435061493822476265356047392175668050706", "price":"0.05", "size":"680", "side":"SELL", "hash":"e48ee6cc714cbf66a35a7630defe26fd29011ec5", "best_bid":"0.01", "best_ask":"0.02"}], "timestamp":"1770241475025", "event_type":"price_change"}
{"market":"0x38f3050258345e9cf363d1c8cc302f08c65b96ba1a4669d81e07ed69708344df", "price_changes":[{"asset_id":"96888240988495161476033313796107536512663280794332045579302109906525918376981", "price":"0.91", "size":"261", "side":"BUY", "hash":"38581481ef8534599ef404995684adc7be58e799", "best_bid":"0.98", "best_ask":"0.99"}, {"asset_id":"81916206347121459497221114766050949090435061493822476265356047392175668050706", "price":"0.09", "size":"261", "side":"SELL", "hash":"870682d3be9437a7ef73c52e2ecdaebe8f6fadf3", "best_bid":"0.01", "best_ask":"0.02"}], "timestamp":"1770241475026", "event_type":"price_change"}
{"market":"0x38f3050258345e9cf363d1c8cc302f08c65b96ba1a4669d81e07ed69708344df", "price_changes":[{"asset_id":"96888240988495161476033313796107536512663280794332045579302109906525918376981", "price":"0.94", "size":"726", "side":"BUY", "hash":"b05ef2fd0d0d1712476acf52158e1372f7dd889d", "best_bid":"0.98", "best_ask":"0.99"}, {"asset_id":"81916206347121459497221114766050949090435061493822476265356047392175668050706", "price":"0.06", "size":"726", "side":"SELL", "hash":"12b733ade306418333a167787d47575b8eadb346", "best_bid":"0.01", "best_ask":"0.02"}], "timestamp":"1770241475033", "event_type":"price_change"}
{"market":"0x38f3050258345e9cf363d1c8cc302f08c65b96ba1a4669d81e07ed69708344df", "price_changes":[{"asset_id":"81916206347121459497221114766050949090435061493822476265356047392175668050706", "price":"0.01", "size":"4126", "side":"BUY", "hash":"0776d760f018b4b8a154ee9fbd600d6a375a827c", "best_bid":"0.01", "best_ask":"0.02"}, {"asset_id":"96888240988495161476033313796107536512663280794332045579302109906525918376981", "price":"0.99", "size":"4126", "side":"SELL", "hash":"2e21861f8ce46ed969b998a1f03d305797af3a5a", "best_bid":"0.98", "best_ask":"0.99"}], "timestamp":"1770241475035", "event_type":"price_change"}
{"market":"0x38f3050258345e9cf363d1c8cc302f08c65b96ba1a4669d81e07ed69708344df", "price_changes":[{"asset_id":"96888240988495161476033313796107536512663280794332045579302109906525918376981", "price":"0.95", "size":"707", "side":"BUY", "hash":"071836e70a615fe70940a20d8c401aa09a92d254", "best_bid":"0.98", "best_ask":"0.99"}, {"asset_id":"81916206347121459497221114766050949090435061493822476265356047392175668050706", "price":"0.05", "size":"707", "side":"SELL", "hash":"6367d6796f7829aee8bde6800ac9074387ae4eb8", "best_bid":"0.01", "best_ask":"0.02"}], "timestamp":"1770241475036", "event_type":"price_change"}
{"market":"0x38f3050258345e9cf363d1c8cc302f08c65b96ba1a4669d81e07ed69708344df", "price_changes":[{"asset_id":"81916206347121459497221114766050949090435061493822476265356047392175668050706", "price":"0.01", "size":"4099", "side":"BUY", "hash":"4ee5c770ad4d335d3f222987f1aecf308694dc76", "best_bid":"0.01", "best_ask":"0.02"}, {"asset_id":"96888240988495161476033313796107536512663280794332045579302109906525918376981", "price":"0.99", "size":"4099", "side":"SELL", "hash":"7783dc881af527c793e47e43519b994dabe80bee", "best_bid":"0.98", "best_ask":"0.99"}], "timestamp":"1770241475036", "event_type":"price_change"}
{"market":"0x38f3050258345e9cf363d1c8cc302f08c65b96ba1a4669d81e07ed69708344df", "price_changes":[{"asset_id":"81916206347121459497221114766050949090435061493822476265356047392175668050706", "price":"0.01", "size":"4072", "side":"BUY", "hash":"7cec20c4b9a792a4defa1bab554c6d2e3810abd2", "best_bid":"0.01", "best_ask":"0.02"}, {"asset_id":"96888240988495161476033313796107536512663280794332045579302109906525918376981", "price":"0.99", "size":"4072", "side":"SELL", "hash":"c2b872db4afe101d09716f1b4428ed614864860b", "best_bid":"0.98", "best_ask":"0.99"}], "timestamp":"1770241475141", "event_type":"price_change"}
{"market":"0x38f3050258345e9cf363d1c8cc302f08c65b96ba1a4669d81e07ed69708344df", "price_changes":[{"asset_id":"96888240988495161476033313796107536512663280794332045579302109906525918376981", "price":"0.95", "size":"680", "side":"BUY", "hash":"abddd2234a8dd2680283d2287e85e67ed84baa52", "best_bid":"0.98", "best_ask":"0.99"}, {"asset_id":"81916206347121459497221114766050949090435061493822476265356047392175668050706", "price":"0.05", "size":"680", "side":"SELL", "hash":"84a4524886fd7c76fcffe3604ef756fcea670f30", "best_bid":"0.01", "best_ask":"0.02"}], "timestamp":"1770241475142", "event_type":"price_change"}
{"market":"0x38f3050258345e9cf363d1c8cc302f08c65b96ba1a4669d81e07ed69708344df", "price_changes":[{"asset_id":"96888240988495161476033313796107536512663280794332045579302109906525918376981", "price":"0.94", "size":"753", "side":"BUY", "hash":"1efc4f854db472fbd5032bb0ae8b5d1cba0c4d08", "best_bid":"0.98", "best_ask":"0.99"}, {"asset_id":"81916206347121459497221114766050949090435061493822476265356047392175668050706", "price":"0.06", "size":"753", "side":"SELL", "hash":"7e5257d60bca2bd407d4e80f06ec6789ab054dbf", "best_bid":"0.01", "best_ask":"0.02"}], "timestamp":"1770241475143", "event_type":"price_change"}
{"market":"0x38f3050258345e9cf363d1c8cc302f08c65b96ba1a4669d81e07ed69708344df", "price_changes":[{"asset_id":"81916206347121459497221114766050949090435061493822476265356047392175668050706", "price":"0.01", "size":"4099", "side":"BUY", "hash":"1f373d29de882837a883d79e2a845e7e87d5092d", "best_bid":"0.01", "best_ask":"0.02"}, {"asset_id":"96888240988495161476033313796107536512663280794332045579302109906525918376981", "price":"0.99", "size":"4099", "side":"SELL", "hash":"ce62a0318ada644ae4cbfeb1e775ed7176379d1e", "best_bid":"0.98", "best_ask":"0.99"}], "timestamp":"1770241475144", "event_type":"price_change"}
{"market":"0x38f3050258345e9cf363d1c8cc302f08c65b96ba1a4669d81e07ed69708344df", "price_changes":[{"asset_id":"96888240988495161476033313796107536512663280794332045579302109906525918376981", "price":"0.97", "size":"570.32", "side":"BUY", "hash":"a39e5f8aa1d6de571becc68de6ce1b2f540b6361", "best_bid":"0.98", "best_ask":"0.99"}, {"asset_id":"81916206347121459497221114766050949090435061493822476265356047392175668050706", "price":"0.03", "size":"570.32", "side":"SELL", "hash":"bd8594c39d79e5c01e51ae0a4ced5f6d99b226af", "best_bid":"0.01", "best_ask":"0.02"}], "timestamp":"1770241475144", "event_type":"price_change"}
{"market":"0x38f3050258345e9cf363d1c8cc302f08c65b96ba1a4669d81e07ed69708344df", "price_changes":[{"asset_id":"96888240988495161476033313796107536512663280794332045579302109906525918376981", "price":"0.96", "size":"698.73", "side":"BUY", "hash":"768111cdd8b9c00ea60fb287e2488820dd4e41c2", "best_bid":"0.98", "best_ask":"0.99"}, {"asset_id":"81916206347121459497221114766050949090435061493822476265356047392175668050706", "price":"0.04", "size":"698.73", "side":"SELL", "hash":"8ff5c2ba3443d03cf403a77a476e8992d99be0ab", "best_bid":"0.01", "best_ask":"0.02"}], "timestamp":"1770241475145", "event_type":"price_change"}
{"market":"0x38f3050258345e9cf363d1c8cc302f08c65b96ba1a4669d81e07ed69708344df", "price_changes":[{"asset_id":"96888240988495161476033313796107536512663280794332045579302109906525918376981", "price":"0.95", "size":"653", "side":"BUY", "hash":"2f76263f3b32ff563d803a295442d9633387cff9", "best_bid":"0.98", "best_ask":"0.99"}, {"asset_id":"81916206347121459497221114766050949090435061493822476265356047392175668050706", "price":"0.05", "size":"653", "side":"SELL", "hash":"e8f71c59b9821aa379a71c5d384cd87aa124d6f0", "best_bid":"0.01", "best_ask":"0.02"}], "timestamp":"1770241475154", "event_type":"price_change"}
{"market":"0x38f3050258345e9cf363d1c8cc302f08c65b96ba1a4669d81e07ed69708344df", "price_changes":[{"asset_id":"81916206347121459497221114766050949090435061493822476265356047392175668050706", "price":"0.01", "size":"4126", "side":"BUY", "hash":"8cbc60f46ffb9184588bf28a0e821754bd60df2c", "best_bid":"0.01", "best_ask":"0.02"}, {"asset_id":"96888240988495161476033313796107536512663280794332045579302109906525918376981", "price":"0.99", "size":"4126", "side":"SELL", "hash":"279430a655896b93bb3367664e720dc016e8d31a", "best_bid":"0.98", "best_ask":"0.99"}], "timestamp":"1770241475155", "event_type":"price_change"}
{"market":"0x38f3050258345e9cf363d1c8cc302f08c65b96ba1a4669d81e07ed69708344df", "price_changes":[{"asset_id":"81916206347121459497221114766050949090435061493822476265356047392175668050706", "price":"0.01", "size":"4099", "side":"BUY", "hash":"99b4351c5378920ea3edeb0d0e1258e1a85375c1", "best_bid":"0.01", "best_ask":"0.02"}, {"asset_id":"96888240988495161476033313796107536512663280794332045579302109906525918376981", "price":"0.99", "size":"4099", "side":"SELL", "hash":"d863fdec6a751d461047f9e38d7bd7b5abec969d", "best_bid":"0.98", "best_ask":"0.99"}], "timestamp":"1770241475156", "event_type":"price_change"}
{"market":"0x38f3050258345e9cf363d1c8cc302f08c65b96ba1a4669d81e07ed69708344df", "price_changes":[{"asset_id":"96888240988495161476033313796107536512663280794332045579302109906525918376981", "price":"0.94", "size":"780", "side":"BUY", "hash":"56894c0887ab8bab2c41a9703631446c7e29b270", "best_bid":"0.98", "best_ask":"0.99"}, {"asset_id":"81916206347121459497221114766050949090435061493822476265356047392175668050706", "price":"0.06", "size":"780", "side":"SELL", "hash":"0d2ed67c129d66ba43b3bd8fe3e6dfbdf5fc51f3", "best_bid":"0.01", "best_ask":"0.02"}], "timestamp":"1770241475159", "event_type":"price_change"}
{"market":"0x38f3050258345e9cf363d1c8cc302f08c65b96ba1a4669d81e07ed69708344df", "price_changes":[{"asset_id":"96888240988495161476033313796107536512663280794332045579302109906525918376981", "price":"0.99", "size":"4139", "side":"SELL", "hash":"1f1e1d871de776aff83ed9ec9d92a80972f295fb", "best_bid":"0.98", "best_ask":"0.99"}, {"asset_id":"81916206347121459497221114766050949090435061493822476265356047392175668050706", "price":"0.01", "size":"4139", "side":"BUY", "hash":"5049548663b579ffc32dd959951af198216678c0", "best_bid":"0.01", "best_ask":"0.02"}], "timestamp":"1770241475167", "event_type":"price_change"}
{"market":"0x38f3050258345e9cf363d1c8cc302f08c65b96ba1a4669d81e07ed69708344df", "price_changes":[{"asset_id":"96888240988495161476033313796107536512663280794332045579302109906525918376981", "price":"0.96", "size":"675.73", "side":"BUY", "hash":"385d8163fded994e6fbd77f908d197e4c733699d", "best_bid":"0.98", "best_ask":"0.99"}, {"asset_id":"81916206347121459497221114766050949090435061493822476265356047392175668050706", "price":"0.04", "size":"675.73", "side":"SELL", "hash":"3c4372f557907e72138c6bc4ea19f7e580b72f8e", "best_bid":"0.01", "best_ask":"0.02"}], "timestamp":"1770241475169", "event_type":"price_change"}
{"market":"0x38f3050258345e9cf363d1c8cc302f08c65b96ba1a4669d81e07ed69708344df", "price_changes":[{"asset_id":"96888240988495161476033313796107536512663280794332045579302109906525918376981", "price":"0.77", "size":"212", "side":"BUY", "hash":"08de95ccfd8c2131a7547b4135afee9663727a33", "best_bid":"0.98", "best_ask":"0.99"}, {"asset_id":"81916206347121459497221114766050949090435061493822476265356047392175668050706", "price":"0.23", "size":"212", "side":"SELL", "hash":"50ba614ea70e3f7a96d46aeac382358de4f777d7", "best_bid":"0.01", "best_ask":"0.02"}], "timestamp":"1770241475521", "event_type":"price_change"}
{"market":"0x38f3050258345e9cf363d1c8cc302f08c65b96ba1a4669d81e07ed69708344df", "price_changes":[{"asset_id":"96888240988495161476033313796107536512663280794332045579302109906525918376981", "price":"0.96", "size":"655.73", "side":"BUY", "hash":"4ab2c87d804a2581f42f03ae8b58994cc79718d2", "best_bid":"0.98", "best_ask":"0.99"}, {"asset_id":"81916206347121459497221114766050949090435061493822476265356047392175668050706", "price":"0.04", "size":"655.73", "side":"SELL", "hash":"967d87a83443c7ef348ce73552dd0f06366b3717", "best_bid":"0.01", "best_ask":"0.02"}], "timestamp":"1770241475552", "event_type":"price_change"}
{"market":"0x38f3050258345e9cf363d1c8cc302f08c65b96ba1a4669d81e07ed69708344df", "price_changes":[{"asset_id":"96888240988495161476033313796107536512663280794332045579302109906525918376981", "price":"0.95", "size":"680", "side":"BUY", "hash":"42aa6d37d3c30961cd3aff311539336e978d0158", "best_bid":"0.98", "best_ask":"0.99"}, {"asset_id":"81916206347121459497221114766050949090435061493822476265356047392175668050706", "price":"0.05", "size":"680", "side":"SELL", "hash":"ea40e6675d07e4716ebeeac3a3858aac4553a228", "best_bid":"0.01", "best_ask":"0.02"}], "timestamp":"1770241475581", "event_type":"price_change"}
{"market":"0x38f3050258345e9cf363d1c8cc302f08c65b96ba1a4669d81e07ed69708344df", "price_changes":[{"asset_id":"96888240988495161476033313796107536512663280794332045579302109906525918376981", "price":"0.94", "size":"753", "side":"BUY", "hash":"b69661c007fe1a97eff2374b60db1d4e1c52c691", "best_bid":"0.98", "best_ask":"0.99"}, {"asset_id":"81916206347121459497221114766050949090435061493822476265356047392175668050706", "price":"0.06", "size":"753", "side":"SELL", "hash":"cef097f683e577d73ca5dc819edd581bdc04edcd", "best_bid":"0.01", "best_ask":"0.02"}], "timestamp":"1770241475582", "event_type":"price_change"}
{"market":"0x38f3050258345e9cf363d1c8cc302f08c65b96ba1a4669d81e07ed69708344df", "price_changes":[{"asset_id":"81916206347121459497221114766050949090435061493822476265356047392175668050706", "price":"0.01", "size":"4166", "side":"BUY", "hash":"a9f6743b981a9e078762bc42e8200e8a0c644c40", "best_bid":"0.01", "best_ask":"0.02"}, {"asset_id":"96888240988495161476033313796107536512663280794332045579302109906525918376981", "price":"0.99", "size":"4166", "side":"SELL", "hash":"a4c1a5a0a5a91b6c06515c3b619155cf83fc1ff7", "best_bid":"0.98", "best_ask":"0.99"}], "timestamp":"1770241475583", "event_type":"price_change"}
{"market":"0x38f3050258345e9cf363d1c8cc302f08c65b96ba1a4669d81e07ed69708344df", "price_changes":[{"asset_id":"81916206347121459497221114766050949090435061493822476265356047392175668050706", "price":"0.01", "size":"4139", "side":"BUY", "hash":"dc7f6191ca4108fec6e8a0f879b16368d26f82d3", "best_bid":"0.01", "best_ask":"0.02"}, {"asset_id":"96888240988495161476033313796107536512663280794332045579302109906525918376981", "price":"0.99", "size":"4139", "side":"SELL", "hash":"76ebd4dbebb2c97217185f2df264fe933c9466d0", "best_bid":"0.98", "best_ask":"0.99"}], "timestamp":"1770241475584", "event_type":"price_change"}
{"market":"0x38f3050258345e9cf363d1c8cc302f08c65b96ba1a4669d81e07ed69708344df", "price_changes":[{"asset_id":"81916206347121459497221114766050949090435061493822476265356047392175668050706", "price":"0.01", "size":"4112", "side":"BUY", "hash":"f98806972aef478aec3e443277c7d63a38e4c4d9", "best_bid":"0.01", "best_ask":"0.02"}, {"asset_id":"96888240988495161476033313796107536512663280794332045579302109906525918376981", "price":"0.99", "size":"4112", "side":"SELL", "hash":"45ff5cb769a9dec64251943872d6a92d545ca73a", "best_bid":"0.98", "best_ask":"0.99"}], "timestamp":"1770241475593", "event_type":"price_change"}
{"market":"0x38f3050258345e9cf363d1c8cc302f08c65b96ba1a4669d81e07ed69708344df", "price_changes":[{"asset_id":"81916206347121459497221114766050949090435061493822476265356047392175668050706", "price":"0.01", "size":"4139", "side":"BUY", "hash":"e32a34f9e75b5f0ea3b232e451dc0e6871aacf64", "best_bid":"0.01", "best_ask":"0.02"}, {"asset_id":"96888240988495161476033313796107536512663280794332045579302109906525918376981", "price":"0.99", "size":"4139", "side":"SELL", "hash":"a936853e839cabb000b46e46c967e77dfa7e5b26", "best_bid":"0.98", "best_ask":"0.99"}], "timestamp":"1770241475594", "event_type":"price_change"}
{"market":"0x38f3050258345e9cf363d1c8cc302f08c65b96ba1a4669d81e07ed69708344df", "price_changes":[{"asset_id":"96888240988495161476033313796107536512663280794332045579302109906525918376981", "price":"0.94", "size":"726", "side":"BUY", "hash":"38bc23ead75929915401c0930b5e03fbba099f47", "best_bid":"0.98", "best_ask":"0.99"}, {"asset_id":"81916206347121459497221114766050949090435061493822476265356047392175668050706", "price":"0.06", "size":"726", "side":"SELL", "hash":"2206654c607f74bf314775aa735f57132a622fce", "best_bid":"0.01", "best_ask":"0.02"}], "timestamp":"1770241475595", "event_type":"price_change"}
{"market":"0x38f3050258345e9cf363d1c8cc302f08c65b96ba1a4669d81e07ed69708344df", "price_changes":[{"asset_id":"96888240988495161476033313796107536512663280794332045579302109906525918376981", "price":"0.95", "size":"707", "side":"BUY", "hash":"be597449fe3d6d8182dceac058229de3ec709a3a", "best_bid":"0.98", "best_ask":"0.99"}, {"asset_id":"81916206347121459497221114766050949090435061493822476265356047392175668050706", "price":"0.05", "size":"707", "side":"SELL", "hash":"e8c3000d40f01453c93a619d364b7b0026e214fa", "best_bid":"0.01", "best_ask":"0.02"}], "timestamp":"1770241475596", "event_type":"price_change"}
{"market":"0x38f3050258345e9cf363d1c8cc302f08c65b96ba1a4669d81e07ed69708344df", "price_changes":[{"asset_id":"81916206347121459497221114766050949090435061493822476265356047392175668050706", "price":"0.01", "size":"4112", "side":"BUY", "hash":"7da446bfa6efbbfd2c96d38f6c3f01a00e218b29", "best_bid":"0.01", "best_ask":"0.02"}, {"asset_id":"96888240988495161476033313796107536512663280794332045579302109906525918376981", "price":"0.99", "size":"4112", "side":"SELL", "hash":"97a18a0e56a016ecf7b481d8b6bbd45361cefd45", "best_bid":"0.98", "best_ask":"0.99"}], "timestamp":"1770241475603", "event_type":"price_change"}
{"market":"0x38f3050258345e9cf363d1c8cc302f08c65b96ba1a4669d81e07ed69708344df", "price_changes":[{"asset_id":"81916206347121459497221114766050949090435061493822476265356047392175668050706", "price":"0.01", "size":"4139", "side":"BUY", "hash":"e4b6b87dfe4dc68371bb928c8d90bec9150a60d6", "best_bid":"0.01", "best_ask":"0.02"}, {"asset_id":"96888240988495161476033313796107536512663280794332045579302109906525918376981", "price":"0.99", "size":"4139", "side":"SELL", "hash":"c575698649597b09a4822709062019419d42bef7", "best_bid":"0.98", "best_ask":"0.99"}], "timestamp":"1770241475609", "event_type":"price_change"}
{"market":"0x38f3050258345e9cf363d1c8cc302f08c65b96ba1a4669d81e07ed69708344df", "price_changes":[{"asset_id":"96888240988495161476033313796107536512663280794332045579302109906525918376981", "price":"0.95", "size":"680", "side":"BUY", "hash":"20eb4172e60f34334b8989d5651039e00186703c", "best_bid":"0.98", "best_ask":"0.99"}, {"asset_id":"81916206347121459497221114766050949090435061493822476265356047392175668050706", "price":"0.05", "size":"680", "side":"SELL", "hash":"e6de2c461cd2831365df210f106a6221351cc427", "best_bid":"0.01", "best_ask":"0.02"}], "timestamp":"1770241475618", "event_type":"price_change"}
{"market":"0x38f3050258345e9cf363d1c8cc302f08c65b96ba1a4669d81e07ed69708344df", "price_changes":[{"asset_id":"96888240988495161476033313796107536512663280794332045579302109906525918376981", "price":"0.96", "size":"682.73", "side":"BUY", "hash":"74be6258eff72dcefb0792c2d3adc7bebbbbaf87", "best_bid":"0.98", "best_ask":"0.99"}, {"asset_id":"81916206347121459497221114766050949090435061493822476265356047392175668050706", "price":"0.04", "size":"682.73", "side":"SELL", "hash":"250724fbde03e8784bfca83d8d9e5e324c6a596d", "best_bid":"0.01", "best_ask":"0.02"}], "timestamp":"1770241475625", "event_type":"price_change"}
{"market":"0x38f3050258345e9cf363d1c8cc302f08c65b96ba1a4669d81e07ed69708344df", "price_changes":[{"asset_id":"81916206347121459497221114766050949090435061493822476265356047392175668050706", "price":"0.01", "size":"4166", "side":"BUY", "hash":"fda5803efb6f2a2b197dd823c9423d2406702317", "best_bid":"0.01", "best_ask":"0.02"}, {"asset_id":"96888240988495161476033313796107536512663280794332045579302109906525918376981", "price":"0.99", "size":"4166", "side":"SELL", "hash":"40c74b6dafb03e72bb0632deefbdf5567b7cdd44", "best_bid":"0.98", "best_ask":"0.99"}], "timestamp":"1770241475706", "event_type":"price_change"}
{"market":"0x38f3050258345e9cf363d1c8cc302f08c65b96ba1a4669d81e07ed69708344df", "price_changes":[{"asset_id":"96888240988495161476033313796107536512663280794332045579302109906525918376981", "price":"0.94", "size":"753", "side":"BUY", "hash":"5f5d5f3b320f28f9e2f7c8f06a2ccbba35fd5a0c", "best_bid":"0.98", "best_ask":"0.99"}, {"asset_id":"81916206347121459497221114766050949090435061493822476265356047392175668050706", "price":"0.06", "size":"753", "side":"SELL", "hash":"4bc91699ae99a76bcf084f2b8aa2bcf451da3b51", "best_bid":"0.01", "best_ask":"0.02"}], "timestamp":"1770241475707", "event_type":"price_change"}
{"market":"0x38f3050258345e9cf363d1c8cc302f08c65b96ba1a4669d81e07ed69708344df", "price_changes":[{"asset_id":"81916206347121459497221114766050949090435061493822476265356047392175668050706", "price":"0.01", "size":"4139", "side":"BUY", "hash":"91e6a6cef55af5d568b2176d2baa95e9eb9232b0", "best_bid":"0.01", "best_ask":"0.02"}, {"asset_id":"96888240988495161476033313796107536512663280794332045579302109906525918376981", "price":"0.99", "size":"4139", "side":"SELL", "hash":"3289e74e75946fe2dc779b1999e44e411784598c", "best_bid":"0.98", "best_ask":"0.99"}], "timestamp":"1770241475708", "event_type":"price_change"}
{"market":"0x38f3050258345e9cf363d1c8cc302f08c65b96ba1a4669d81e07ed69708344df", "price_changes":[{"asset_id":"96888240988495161476033313796107536512663280794332045579302109906525918376981", "price":"0.95", "size":"653", "side":"BUY", "hash":"5b665f62d498f0bb7b38095cd7187b711c32e175", "best_bid":"0.98", "best_ask":"0.99"}, {"asset_id":"81916206347121459497221114766050949090435061493822476265356047392175668050706", "price":"0.05", "size":"653", "side":"SELL", "hash":"535b27753074926b3225770c4cee108577fcb964", "best_bid":"0.01", "best_ask":"0.02"}], "timestamp":"1770241475718", "event_type":"price_change"}
{"market":"0x38f3050258345e9cf363d1c8cc302f08c65b96ba1a4669d81e07ed69708344df", "price_changes":[{"asset_id":"81916206347121459497221114766050949090435061493822476265356047392175668050706", "price":"0.01", "size":"4112", "side":"BUY", "hash":"651b8656f3ab1dc608d93f4e71b390e52730f373", "best_bid":"0.01", "best_ask":"0.02"}, {"asset_id":"96888240988495161476033313796107536512663280794332045579302109906525918376981", "price":"0.99", "size":"4112", "side":"SELL", "hash":"33496cc1f4466dcd85aed325082afb654d6056ae", "best_bid":"0.98", "best_ask":"0.99"}], "timestamp":"1770241475723", "event_type":"price_change"}
{"market":"0x38f3050258345e9cf363d1c8cc302f08c65b96ba1a4669d81e07ed69708344df", "price_changes":[{"asset_id":"81916206347121459497221114766050949090435061493822476265356047392175668050706", "price":"0.01", "size":"4139", "side":"BUY", "hash":"b431f402651ec370367ac972231ee5a33990aa3f", "best_bid":"0.01", "best_ask":"0.02"}, {"asset_id":"96888240988495161476033313796107536512663280794332045579302109906525918376981", "price":"0.99", "size":"4139", "side":"SELL", "hash":"7173a63cf27ebf447201c324500b05bb9304a319", "best_bid":"0.98", "best_ask":"0.99"}], "timestamp":"1770241475725", "event_type":"price_change"}
{"market":"0x38f3050258345e9cf363d1c8cc302f08c65b96ba1a4669d81e07ed69708344df", "price_changes":[{"asset_id":"96888240988495161476033313796107536512663280794332045579302109906525918376981", "price":"0.94", "size":"780", "side":"BUY", "hash":"07f8e5dcee8f5ea36cc4572af398864d9f4c97bb", "best_bid":"0.98", "best_ask":"0.99"}, {"asset_id":"81916206347121459497221114766050949090435061493822476265356047392175668050706", "price":"0.06", "size":"780", "side":"SELL", "hash":"6ff0730a4a2047901582abfaa2ccc08dacafa2d8", "best_bid":"0.01", "best_ask":"0.02"}], "timestamp":"1770241475726", "event_type":"price_change"}
{"market":"0x38f3050258345e9cf363d1c8cc302f08c65b96ba1a4669d81e07ed69708344df", "price_changes":[{"asset_id":"96888240988495161476033313796107536512663280794332045579302109906525918376981", "price":"0.95", "size":"626", "side":"BUY", "hash":"39a50cf92c816bb1f3fb61cefb882d1daba56f2c", "best_bid":"0.98", "best_ask":"0.99"}, {"asset_id":"81916206347121459497221114766050949090435061493822476265356047392175668050706", "price":"0.05", "size":"626", "side":"SELL", "hash":"28c4873f62735ee161c54599c5fdddb55cb1eb48", "best_bid":"0.01", "best_ask":"0.02"}], "timestamp":"1770241475727", "event_type":"price_change"}
{"market":"0x38f3050258345e9cf363d1c8cc302f08c65b96ba1a4669d81e07ed69708344df", "price_changes":[{"asset_id":"81916206347121459497221114766050949090435061493822476265356047392175668050706", "price":"0.01", "size":"4112", "side":"BUY", "hash":"98970f14d8d1c607ddbd4b288891371c97c7335d", "best_bid":"0.01", "best_ask":"0.02"}, {"asset_id":"96888240988495161476033313796107536512663280794332045579302109906525918376981", "price":"0.99", "size":"4112", "side":"SELL", "hash":"0b001d69a772b1c53927867b81c3c3a8ba1259ff", "best_bid":"0.98", "best_ask":"0.99"}], "timestamp":"1770241475729", "event_type":"price_change"}
{"market":"0x38f3050258345e9cf363d1c8cc302f08c65b96ba1a4669d81e07ed69708344df", "price_changes":[{"asset_id":"96888240988495161476033313796107536512663280794332045579302109906525918376981", "price":"0.96", "size":"655.73", "side":"BUY", "hash":"620980f5587142f366b8f58539782f7271ac1693", "best_bid":"0.98", "best_ask":"0.99"}, {"asset_id":"81916206347121459497221114766050949090435061493822476265356047392175668050706", "price":"0.04", "size":"655.73", "side":"SELL", "hash":"03a308fb9513f656643b4f7d9b7f0da1dbb3730a", "best_bid":"0.01", "best_ask":"0.02"}], "timestamp":"1770241475730", "event_type":"price_change"}
{"market":"0x38f3050258345e9cf363d1c8cc302f08c65b96ba1a4669d81e07ed69708344df", "price_changes":[{"asset_id":"96888240988495161476033313796107536512663280794332045579302109906525918376981", "price":"0.95", "size":"653", "side":"BUY", "hash":"27b80e88158264d828cc8e97b485ae0bc1df33fc", "best_bid":"0.98", "best_ask":"0.99"}, {"asset_id":"81916206347121459497221114766050949090435061493822476265356047392175668050706", "price":"0.05", "size":"653", "side":"SELL", "hash":"46d446fdca3747bce7be57f576361c01af1f2924", "best_bid":"0.01", "best_ask":"0.02"}], "timestamp":"1770241475731", "event_type":"price_change"}
{"market":"0x38f3050258345e9cf363d1c8cc302f08c65b96ba1a4669d81e07ed69708344df", "price_changes":[{"asset_id":"81916206347121459497221114766050949090435061493822476265356047392175668050706", "price":"0.01", "size":"4139", "side":"BUY", "hash":"d0fc5f4f109129eacb2ed82f5fbd6983089d4208", "best_bid":"0.01", "best_ask":"0.02"}, {"asset_id":"96888240988495161476033313796107536512663280794332045579302109906525918376981", "price":"0.99", "size":"4139", "side":"SELL", "hash":"dd7cc5fd9ec980a30b202330fee139bb8b379558", "best_bid":"0.98", "best_ask":"0.99"}], "timestamp":"1770241475732", "event_type":"price_change"}
{"market":"0x38f3050258345e9cf363d1c8cc302f08c65b96ba1a4669d81e07ed69708344df", "price_changes":[{"asset_id":"81916206347121459497221114766050949090435061493822476265356047392175668050706", "price":"0.01", "size":"4128.89", "side":"BUY", "hash":"bd91124748ec5e6d30b085af73b6216fe66ddeda", "best_bid":"0.01", "best_ask":"0.02"}, {"asset_id":"96888240988495161476033313796107536512663280794332045579302109906525918376981", "price":"0.99", "size":"4128.89", "side":"SELL", "hash":"d817faca3d0370a3389e83f29df71c802e4d998d", "best_bid":"0.98", "best_ask":"0.99"}], "timestamp":"1770241476042", "event_type":"price_change"}
{"market":"0x38f3050258345e9cf363d1c8cc302f08c65b96ba1a4669d81e07ed69708344df", "asset_id":"81916206347121459497221114766050949090435061493822476265356047392175668050706", "bids":[{"price":"0.01", "size":"4128.89"}], "asks":[{"price":"0.99", "size":"5019.91"}, {"price":"0.98", "size":"3034.23"}, {"price":"0.97", "size":"3172"}, {"price":"0.96", "size":"3012"}, {"price":"0.95", "size":"3032"}, {"price":"0.94", "size":"3012"}, {"price":"0.93", "size":"3126.28"}, {"price":"0.92", "size":"3012"}, {"price":"0.91", "size":"3012"}, {"price":"0.9", "size":"3087"}, {"price":"0.89", "size":"12"}, {"price":"0.88", "size":"12"}, {"price":"0.87", "size":"12"}, {"price":"0.86", "size":"12"}, {"price":"0.85", "size":"12"}, {"price":"0.84", "size":"12"}, {"price":"0.83", "size":"12"}, {"price":"0.82", "size":"12"}, {"price":"0.81", "size":"12"}, {"price":"0.8", "size":"12"}, {"price":"0.79", "size":"12"}, {"price":"0.78", "size":"12"}, {"price":"0.77", "size":"12"}, {"price":"0.76", "size":"112"}, {"price":"0.75", "size":"40.57"}, {"price":"0.74", "size":"12"}, {"price":"0.73", "size":"293.25"}, {"price":"0.72", "size":"22"}, {"price":"0.71", "size":"12"}, {"price":"0.7", "size":"18"}, {"price":"0.69", "size":"12"}, {"price":"0.68", "size":"12"}, {"price":"0.67", "size":"12"}, {"price":"0.66", "size":"160.89"}, {"price":"0.65", "size":"12"}, {"price":"0.64", "size":"12"}, {"price":"0.63", "size":"12"}, {"price":"0.62", "size":"19.39"}, {"price":"0.61", "size":"18.04"}, {"price":"0.6", "size":"12"}, {"price":"0.59", "size":"94.31"}, {"price":"0.58", "size":"5450.54"}, {"price":"0.57", "size":"12"}, {"price":"0.56", "size":"12"}, {"price":"0.55", "size":"12"}, {"price":"0.54", "size":"22"}, {"price":"0.53", "size":"12"}, {"price":"0.52", "size":"12"}, {"price":"0.51", "size":"12"}, {"price":"0.5", "size":"12"}, {"price":"0.49", "size":"12"}, {"price":"0.48", "size":"12"}, {"price":"0.47", "size":"12"}, {"price":"0.46", "size":"485.56"}, {"price":"0.45", "size":"31"}, {"price":"0.44", "size":"17"}, {"price":"0.43", "size":"12"}, {"price":"0.42", "size":"12"}, {"price":"0.41", "size":"12"}, {"price":"0.4", "size":"127"}, {"price":"0.39", "size":"12"}, {"price":"0.38", "size":"94.51"}, {"price":"0.37", "size":"31.99"}, {"price":"0.36", "size":"12"}, {"price":"0.35", "size":"37"}, {"price":"0.34", "size":"12"}, {"price":"0.33", "size":"12"}, {"price":"0.32", "size":"12"}, {"price":"0.31", "size":"12"}, {"price":"0.3", "size":"31.9"}, {"price":"0.29", "size":"344"}, {"price":"0.28", "size":"3288.99"}, {"price":"0.27", "size":"212"}, {"price":"0.26", "size":"218"}, {"price":"0.25", "size":"212"}, {"price":"0.24", "size":"212"}, {"price":"0.23", "size":"212"}, {"price":"0.22", "size":"1223.14"}, {"price":"0.21", "size":"412"}, {"price":"0.2", "size":"272.99"}, {"price":"0.19", "size":"212"}, {"price":"0.18", "size":"212"}, {"price":"0.17", "size":"212"}, {"price":"0.16", "size":"812"}, {"price":"0.15", "size":"231.08"}, {"price":"0.14", "size":"283.65"}, {"price":"0.13", "size":"212"}, {"price":"0.12", "size":"252"}, {"price":"0.11", "size":"252"}, {"price":"0.1", "size":"737.71"}, {"price":"0.09", "size":"261"}, {"price":"0.08", "size":"844.68"}, {"price":"0.07", "size":"826"}, {"price":"0.06", "size":"780"}, {"price":"0.05", "size":"653"}, {"price":"0.04", "size":"655.73"}, {"price":"0.03", "size":"570.32"}, {"price":"0.02", "size":"138.97"}], "hash":"bd91124748ec5e6d30b085af73b6216fe66ddeda", "timestamp":"1770241476042", "event_type":"book"}
{"market":"0x38f3050258345e9cf363d1c8cc302f08c65b96ba1a4669d81e07ed69708344df", "price_changes":[{"asset_id":"81916206347121459497221114766050949090435061493822476265356047392175668050706", "price":"0.01", "size":"4101.89", "side":"BUY", "hash":"78ae2012cd49f55d7e212e59114d8af7a308e7cd", "best_bid":"0.01", "best_ask":"0.02"}, {"asset_id":"96888240988495161476033313796107536512663280794332045579302109906525918376981", "price":"0.99", "size":"4101.89", "side":"SELL", "hash":"722d9f44cce9099e2ab17a4e6097b41d721ec3c0", "best_bid":"0.98", "best_ask":"0.99"}], "timestamp":"1770241476070", "event_type":"price_change"}
{"market":"0x38f3050258345e9cf363d1c8cc302f08c65b96ba1a4669d81e07ed69708344df", "price_changes":[{"asset_id":"96888240988495161476033313796107536512663280794332045579302109906525918376981", "price":"0.95", "size":"626", "side":"BUY", "hash":"4d86cfe6777f868b482c0daea946611847880993", "best_bid":"0.98", "best_ask":"0.99"}, {"asset_id":"81916206347121459497221114766050949090435061493822476265356047392175668050706", "price":"0.05", "size":"626", "side":"SELL", "hash":"83270561d60f616c2f4561963fccd6d98c21bd41", "best_bid":"0.01", "best_ask":"0.02"}], "timestamp":"1770241476071", "event_type":"price_change"}
{"market":"0x38f3050258345e9cf363d1c8cc302f08c65b96ba1a4669d81e07ed69708344df", "price_changes":[{"asset_id":"81916206347121459497221114766050949090435061493822476265356047392175668050706", "price":"0.01", "size":"4128.89", "side":"BUY", "hash":"6faf323f7661adba8c73f89cf523f0bd474a0751", "best_bid":"0.01", "best_ask":"0.02"}, {"asset_id":"96888240988495161476033313796107536512663280794332045579302109906525918376981", "price":"0.99", "size":"4128.89", "side":"SELL", "hash":"7da67bb4edcbab8e7d409425b10e27f7e374d3cd", "best_bid":"0.98", "best_ask":"0.99"}], "timestamp":"1770241476072", "event_type":"price_change"}
{"market":"0x38f3050258345e9cf363d1c8cc302f08c65b96ba1a4669d81e07ed69708344df", "price_changes":[{"asset_id":"96888240988495161476033313796107536512663280794332045579302109906525918376981", "price":"0.96", "size":"682.73", "side":"BUY", "hash":"251a8984add3d2a595236e47c616add00c1b4646", "best_bid":"0.98", "best_ask":"0.99"}, {"asset_id":"81916206347121459497221114766050949090435061493822476265356047392175668050706", "price":"0.04", "size":"682.73", "side":"SELL", "hash":"0220c0d8c41141c4f746447673c2651e9aa444e5", "best_bid":"0.01", "best_ask":"0.02"}], "timestamp":"1770241476073", "event_type":"price_change"}
{"market":"0x38f3050258345e9cf363d1c8cc302f08c65b96ba1a4669d81e07ed69708344df", "price_changes":[{"asset_id":"81916206347121459497221114766050949090435061493822476265356047392175668050706", "price":"0.01", "size":"4155.89", "side":"BUY", "hash":"2740e8930cab2dbd677111d8507210dd6f91a6c6", "best_bid":"0.01", "best_ask":"0.02"}, {"asset_id":"96888240988495161476033313796107536512663280794332045579302109906525918376981", "price":"0.99", "size":"4155.89", "side":"SELL", "hash":"54723487e04bc1427c980be29e4eec088c6b4454", "best_bid":"0.98", "best_ask":"0.99"}], "timestamp":"1770241476077", "event_type":"price_change"}
{"market":"0x38f3050258345e9cf363d1c8cc302f08c65b96ba1a4669d81e07ed69708344df", "price_changes":[{"asset_id":"81916206347121459497221114766050949090435061493822476265356047392175668050706", "price":"0.01", "size":"4128.89", "side":"BUY", "hash":"4ebe220e59d1d40ee8cf37004c0c256297d4db79", "best_bid":"0.01", "best_ask":"0.02"}, {"asset_id":"96888240988495161476033313796107536512663280794332045579302109906525918376981", "price":"0.99", "size":"4128.89", "side":"SELL", "hash":"f5035998a21c4af1e9af218eba1ff4cf50016fac", "best_bid":"0.98", "best_ask":"0.99"}], "timestamp":"1770241476078", "event_type":"price_change"}
{"market":"0x38f3050258345e9cf363d1c8cc302f08c65b96ba1a4669d81e07ed69708344df", "price_changes":[{"asset_id":"96888240988495161476033313796107536512663280794332045579302109906525918376981", "price":"0.94", "size":"753", "side":"BUY", "hash":"2f1c56bf787d56e2aff50da579fabb9f9be56b7c", "best_bid":"0.98", "best_ask":"0.99"}, {"asset_id":"81916206347121459497221114766050949090435061493822476265356047392175668050706", "price":"0.06", "size":"753", "side":"SELL", "hash":"7424952bf5142b5534492e683ac898f6de554152", "best_bid":"0.01", "best_ask":"0.02"}], "timestamp":"1770241476080", "event_type":"price_change"}
{"market":"0x38f3050258345e9cf363d1c8cc302f08c65b96ba1a4669d81e07ed69708344df", "price_changes":[{"asset_id":"96888240988495161476033313796107536512663280794332045579302109906525918376981", "price":"0.94", "size":"726", "side":"BUY", "hash":"5e9ba07b0e255fc6a7f1afaac0fe193912284b45", "best_bid":"0.98", "best_ask":"0.99"}, {"asset_id":"81916206347121459497221114766050949090435061493822476265356047392175668050706", "price":"0.06", "size":"726", "side":"SELL", "hash":"b5ec364d67df63ba48857f74e4bc931be6a8f22b", "best_bid":"0.01", "best_ask":"0.02"}], "timestamp":"1770241476081", "event_type":"price_change"}
{"market":"0x38f3050258345e9cf363d1c8cc302f08c65b96ba1a4669d81e07ed69708344df", "price_changes":[{"asset_id":"81916206347121459497221114766050949090435061493822476265356047392175668050706", "price":"0.01", "size":"4101.89", "side":"BUY", "hash":"92e560949187fe34db93d1cfce494ae8ce4f79fe", "best_bid":"0.01", "best_ask":"0.02"}, {"asset_id":"96888240988495161476033313796107536512663280794332045579302109906525918376981", "price":"0.99", "size":"4101.89", "side":"SELL", "hash":"569c34834bc8f256759564547da4e03d17c96033", "best_bid":"0.98", "best_ask":"0.99"}], "timestamp":"1770241476082", "event_type":"price_change"}
{"market":"0x38f3050258345e9cf363d1c8cc302f08c65b96ba1a4669d81e07ed69708344df", "price_changes":[{"asset_id":"96888240988495161476033313796107536512663280794332045579302109906525918376981", "price":"0.95", "size":"653", "side":"BUY", "hash":"0c4bddb069f7ffb958a87f885d8969aa21dd5408", "best_bid":"0.98", "best_ask":"0.99"}, {"asset_id":"81916206347121459497221114766050949090435061493822476265356047392175668050706", "price":"0.05", "size":"653", "side":"SELL", "hash":"c000ab7a62e5d2ba7afb934ae28ada698782c91c", "best_bid":"0.01", "best_ask":"0.02"}], "timestamp":"1770241476083", "event_type":"price_change"}
{"market":"0x38f3050258345e9cf363d1c8cc302f08c65b96ba1a4669d81e07ed69708344df", "price_changes":[{"asset_id":"81916206347121459497221114766050949090435061493822476265356047392175668050706", "price":"0.01", "size":"4128.89", "side":"BUY", "hash":"4799856760b877d893d031478e1cb44ed7787c27", "best_bid":"0.01", "best_ask":"0.02"}, {"asset_id":"96888240988495161476033313796107536512663280794332045579302109906525918376981", "price":"0.99", "size":"4128.89", "side":"SELL", "hash":"136cbceb99cc1b68eeff4db51c4ee9389715ea50", "best_bid":"0.98", "best_ask":"0.99"}], "timestamp":"1770241476084", "event_type":"price_change"}
{"market":"0x38f3050258345e9cf363d1c8cc302f08c65b96ba1a4669d81e07ed69708344df", "price_changes":[{"asset_id":"96888240988495161476033313796107536512663280794332045579302109906525918376981", "price":"0.95", "size":"680", "side":"BUY", "hash":"bbe60f4b5a698b58501e17ce74b1e5cdd6dbc4a0", "best_bid":"0.98", "best_ask":"0.99"}, {"asset_id":"81916206347121459497221114766050949090435061493822476265356047392175668050706", "price":"0.05", "size":"680", "side":"SELL", "hash":"40b87b117991b01d1c09a62f99f0e74e1c18cdee", "best_bid":"0.01", "best_ask":"0.02"}], "timestamp":"1770241476086", "event_type":"price_change"}
{"market":"0x38f3050258345e9cf363d1c8cc302f08c65b96ba1a4669d81e07ed69708344df", "price_changes":[{"asset_id":"96888240988495161476033313796107536512663280794332045579302109906525918376981", "price":"0.96", "size":"702.73", "side":"BUY", "hash":"c3d312076c2843f8ab59b6d0d6836d554565826b", "best_bid":"0.98", "best_ask":"0.99"}, {"asset_id":"81916206347121459497221114766050949090435061493822476265356047392175668050706", "price":"0.04", "size":"702.73", "side":"SELL", "hash":"d833e28784265fbaaa065f83d43179d122047ed7", "best_bid":"0.01", "best_ask":"0.02"}], "timestamp":"1770241476096", "event_type":"price_change"}
{"market":"0x38f3050258345e9cf363d1c8cc302f08c65b96ba1a4669d81e07ed69708344df", "price_changes":[{"asset_id":"81916206347121459497221114766050949090435061493822476265356047392175668050706", "price":"0.01", "size":"4155.89", "side":"BUY", "hash":"802a151d3f54fc105e6d1265ba706cd01d2e738a", "best_bid":"0.01", "best_ask":"0.02"}, {"asset_id":"96888240988495161476033313796107536512663280794332045579302109906525918376981", "price":"0.99", "size":"4155.89", "side":"SELL", "hash":"ffd5625dac44a29b83cf10fb065f9b22a0fd752b", "best_bid":"0.98", "best_ask":"0.99"}], "timestamp":"1770241476299", "event_type":"price_change"}
{"market":"0x38f3050258345e9cf363d1c8cc302f08c65b96ba1a4669d81e07ed69708344df", "price_changes":[{"asset_id":"96888240988495161476033313796107536512663280794332045579302109906525918376981", "price":"0.95", "size":"653", "side":"BUY", "hash":"41df1916f6c3562d9ff0b1275b04e8927e5eca8b", "best_bid":"0.98", "best_ask":"0.99"}, {"asset_id":"81916206347121459497221114766050949090435061493822476265356047392175668050706", "price":"0.05", "size":"653", "side":"SELL", "hash":"21aef27d7ac1b3df138f623b461ee179baa0cbeb", "best_bid":"0.01", "best_ask":"0.02"}], "timestamp":"1770241476300", "event_type":"price_change"}
{"market":"0x38f3050258345e9cf363d1c8cc302f08c65b96ba1a4669d81e07ed69708344df", "price_changes":[{"asset_id":"81916206347121459497221114766050949090435061493822476265356047392175668050706", "price":"0.01", "size":"4128.89", "side":"BUY", "hash":"d7cf0d01d50c8f5f4ad69a1f512fec28dcff7c2e", "best_bid":"0.01", "best_ask":"0.02"}, {"asset_id":"96888240988495161476033313796107536512663280794332045579302109906525918376981", "price":"0.99", "size":"4128.89", "side":"SELL", "hash":"9e7defe8b354e713e5031fd4345861cdaf60e5b5", "best_bid":"0.98", "best_ask":"0.99"}], "timestamp":"1770241476301", "event_type":"price_change"}
{"market":"0x38f3050258345e9cf363d1c8cc302f08c65b96ba1a4669d81e07ed69708344df", "price_changes":[{"asset_id":"96888240988495161476033313796107536512663280794332045579302109906525918376981", "price":"0.94", "size":"753", "side":"BUY", "hash":"b572e0433c17b832baa94071245027009757ef74", "best_bid":"0.98", "best_ask":"0.99"}, {"asset_id":"81916206347121459497221114766050949090435061493822476265356047392175668050706", "price":"0.06", "size":"753", "side":"SELL", "hash":"52b436e2de832b0f4f0ff7e629c7b272a87a2741", "best_bid":"0.01", "best_ask":"0.02"}], "timestamp":"1770241476303", "event_type":"price_change"}
{"market":"0x38f3050258345e9cf363d1c8cc302f08c65b96ba1a4669d81e07ed69708344df", "price_changes":[{"asset_id":"96888240988495161476033313796107536512663280794332045579302109906525918376981", "price":"0.95", "size":"626", "side":"BUY", "hash":"ca8cfe93551ea2132b9a64ca92f0a4e826207dca", "best_bid":"0.98", "best_ask":"0.99"}, {"asset_id":"81916206347121459497221114766050949090435061493822476265356047392175668050706", "price":"0.05", "size":"626", "side":"SELL", "hash":"b7d34ea83fcdcad4ad539caf67bf5b9664c404ab", "best_bid":"0.01", "best_ask":"0.02"}], "timestamp":"1770241476310", "event_type":"price_change"}
{"market":"0x38f3050258345e9cf363d1c8cc302f08c65b96ba1a4669d81e07ed69708344df", "price_changes":[{"asset_id":"96888240988495161476033313796107536512663280794332045579302109906525918376981", "price":"0.94", "size":"780", "side":"BUY", "hash":"6e2a520828b727015d71d238b7d9c73182fb08f2", "best_bid":"0.98", "best_ask":"0.99"}, {"asset_id":"81916206347121459497221114766050949090435061493822476265356047392175668050706", "price":"0.06", "size":"780", "side":"SELL", "hash":"163bb426d290d2c1d0ddae7de69bed6901c88627", "best_bid":"0.01", "best_ask":"0.02"}], "timestamp":"1770241476312", "event_type":"price_change"}
{"market":"0x38f3050258345e9cf363d1c8cc302f08c65b96ba1a4669d81e07ed69708344df", "price_changes":[{"asset_id":"81916206347121459497221114766050949090435061493822476265356047392175668050706", "price":"0.01", "size":"4155.89", "side":"BUY", "hash":"6438b574b0d53fc9a812d61efab21e854a3b39f3", "best_bid":"0.01", "best_ask":"0.02"}, {"asset_id":"96888240988495161476033313796107536512663280794332045579302109906525918376981", "price":"0.99", "size":"4155.89", "side":"SELL", "hash":"4ba38f258fbeff5c3899460fb717e817f4ab0f82", "best_bid":"0.98", "best_ask":"0.99"}], "timestamp":"1770241476313", "event_type":"price_change"}
{"market":"0x38f3050258345e9cf363d1c8cc302f08c65b96ba1a4669d81e07ed69708344df", "price_changes":[{"asset_id":"81916206347121459497221114766050949090435061493822476265356047392175668050706", "price":"0.01", "size":"4128.89", "side":"BUY", "hash":"06503c05028dc011f51c8f2e55bde48ae21a1ec7", "best_bid":"0.01", "best_ask":"0.02"}, {"asset_id":"96888240988495161476033313796107536512663280794332045579302109906525918376981", "price":"0.99", "size":"4128.89", "side":"SELL", "hash":"6bd5be8617810e605368adf9c954b8e951c5af10", "best_bid":"0.98", "best_ask":"0.99"}], "timestamp":"1770241476314", "event_type":"price_change"}
{"market":"0x38f3050258345e9cf363d1c8cc302f08c65b96ba1a4669d81e07ed69708344df", "price_changes":[{"asset_id":"81916206347121459497221114766050949090435061493822476265356047392175668050706", "price":"0.01", "size":"4155.89", "side":"BUY", "hash":"49667750909a2861c5f57330eb8f9f0839405a1c", "best_bid":"0.01", "best_ask":"0.02"}, {"asset_id":"96888240988495161476033313796107536512663280794332045579302109906525918376981", "price":"0.99", "size":"4155.89", "side":"SELL", "hash":"e42797cc6ca184e9481ddb7bfabaed7580cd4839", "best_bid":"0.98", "best_ask":"0.99"}], "timestamp":"1770241476320", "event_type":"price_change"}
{"market":"0x38f3050258345e9cf363d1c8cc302f08c65b96ba1a4669d81e07ed69708344df", "price_changes":[{"asset_id":"81916206347121459497221114766050949090435061493822476265356047392175668050706", "price":"0.01", "size":"4128.89", "side":"BUY", "hash":"0635f8305601c51658a9feb4b38a24b398347c54", "best_bid":"0.01", "best_ask":"0.02"}, {"asset_id":"96888240988495161476033313796107536512663280794332045579302109906525918376981", "price":"0.99", "size":"4128.89", "side":"SELL", "hash":"e9020c4b95f1c31f7ba36b0f635eb159ff0686b1", "best_bid":"0.98", "best_ask":"0.99"}], "timestamp":"1770241476321", "event_type":"price_change"}
{"market":"0x38f3050258345e9cf363d1c8cc302f08c65b96ba1a4669d81e07ed69708344df", "price_changes":[{"asset_id":"96888240988495161476033313796107536512663280794332045579302109906525918376981", "price":"0.95", "size":"653", "side":"BUY", "hash":"c39c3ccaf73847f789216dc884012d7b9bb680cf", "best_bid":"0.98", "best_ask":"0.99"}, {"asset_id":"81916206347121459497221114766050949090435061493822476265356047392175668050706", "price":"0.05", "size":"653", "side":"SELL", "hash":"7950e0c69ca45afd99adeab5ee395e75130c26ad", "best_bid":"0.01", "best_ask":"0.02"}], "timestamp":"1770241476322", "event_type":"price_change"}
{"market":"0x38f3050258345e9cf363d1c8cc302f08c65b96ba1a4669d81e07ed69708344df", "price_changes":[{"asset_id":"96888240988495161476033313796107536512663280794332045579302109906525918376981", "price":"0.96", "size":"675.73", "side":"BUY", "hash":"c6bd28c0b75cddec1327e8cace834583dd0e65e4", "best_bid":"0.98", "best_ask":"0.99"}, {"asset_id":"81916206347121459497221114766050949090435061493822476265356047392175668050706", "price":"0.04", "size":"675.73", "side":"SELL", "hash":"b903c79f06285ef60179f961db329aac9759a0d1", "best_bid":"0.01", "best_ask":"0.02"}], "timestamp":"1770241476331", "event_type":"price_change"}
{"market":"0x38f3050258345e9cf363d1c8cc302f08c65b96ba1a4669d81e07ed69708344df", "price_changes":[{"asset_id":"96888240988495161476033313796107536512663280794332045579302109906525918376981", "price":"0.78", "size":"1723.14", "side":"BUY", "hash":"d4b7bff50a5973d67c0db1e8628cad55b277b8b2", "best_bid":"0.98", "best_ask":"0.99"}, {"asset_id":"81916206347121459497221114766050949090435061493822476265356047392175668050706", "price":"0.22", "size":"1723.14", "side":"SELL", "hash":"6ac70193a22ce18eda4457f157a8f24e028b9796", "best_bid":"0.01", "best_ask":"0.02"}], "timestamp":"1770241476333", "event_type":"price_change"}
{"market":"0x38f3050258345e9cf363d1c8cc302f08c65b96ba1a4669d81e07ed69708344df", "price_changes":[{"asset_id":"96888240988495161476033313796107536512663280794332045579302109906525918376981", "price":"0.99", "size":"4088.89", "side":"SELL", "hash":"17569a2e5b4b546d43c61f030b704b1087454a1d", "best_bid":"0.98", "best_ask":"0.99"}, {"asset_id":"81916206347121459497221114766050949090435061493822476265356047392175668050706", "price":"0.01", "size":"4088.89", "side":"BUY", "hash":"aac6085e3e85d4cb05b817794a93d7a40f7942e2", "best_bid":"0.01", "best_ask":"0.02"}], "timestamp":"1770241476355", "event_type":"price_change"}
{"market":"0x38f3050258345e9cf363d1c8cc302f08c65b96ba1a4669d81e07ed69708344df", "price_changes":[{"asset_id":"81916206347121459497221114766050949090435061493822476265356047392175668050706", "price":"0.01", "size":"4061.89", "side":"BUY", "hash":"93fbbed792c800d18bce2dfb844fbd8d2f8812a0", "best_bid":"0.01", "best_ask":"0.02"}, {"asset_id":"96888240988495161476033313796107536512663280794332045579302109906525918376981", "price":"0.99", "size":"4061.89", "side":"SELL", "hash":"d166953fa5bf8b6683f1c7521210f979e2e79ec6", "best_bid":"0.98", "best_ask":"0.99"}], "timestamp":"1770241476357", "event_type":"price_change"}
{"market":"0x38f3050258345e9cf363d1c8cc302f08c65b96ba1a4669d81e07ed69708344df", "price_changes":[{"asset_id":"81916206347121459497221114766050949090435061493822476265356047392175668050706", "price":"0.01", "size":"4038.89", "side":"BUY", "hash":"b1c4103b5c83003b55d2278f0d52a47b3fd758c0", "best_bid":"0.01", "best_ask":"0.02"}, {"asset_id":"96888240988495161476033313796107536512663280794332045579302109906525918376981", "price":"0.99", "size":"4038.89", "side":"SELL", "hash":"37c0888155274a34f6284351d0f09db311f66132", "best_bid":"0.98", "best_ask":"0.99"}], "timestamp":"1770241476361", "event_type":"price_change"}
{"market":"0x38f3050258345e9cf363d1c8cc302f08c65b96ba1a4669d81e07ed69708344df", "price_changes":[{"asset_id":"81916206347121459497221114766050949090435061493822476265356047392175668050706", "price":"0.01", "size":"4011.89", "side":"BUY", "hash":"172e546565065b9370436ebcd4a94a95b46c9b1f", "best_bid":"0.01", "best_ask":"0.02"}, {"asset_id":"96888240988495161476033313796107536512663280794332045579302109906525918376981", "price":"0.99", "size":"4011.89", "side":"SELL", "hash":"09063a8a82138096080f58e0c55b16714ec07868", "best_bid":"0.98", "best_ask":"0.99"}], "timestamp":"1770241476372", "event_type":"price_change"}
{"market":"0x38f3050258345e9cf363d1c8cc302f08c65b96ba1a4669d81e07ed69708344df", "price_changes":[{"asset_id":"81916206347121459497221114766050949090435061493822476265356047392175668050706", "price":"0.01", "size":"3984.89", "side":"BUY", "hash":"4d2e29acac95cc584456ed16b9a2c163d585369f", "best_bid":"0.01", "best_ask":"0.02"}, {"asset_id":"96888240988495161476033313796107536512663280794332045579302109906525918376981", "price":"0.99", "size":"3984.89", "side":"SELL", "hash":"42e86dae0d59105b2374f913a09f0436150dbea8", "best_bid":"0.98", "best_ask":"0.99"}], "timestamp":"1770241476379", "event_type":"price_change"}
{"market":"0x38f3050258345e9cf363d1c8cc302f08c65b96ba1a4669d81e07ed69708344df", "price_changes":[{"asset_id":"96888240988495161476033313796107536512663280794332045579302109906525918376981", "price":"0.94", "size":"753", "side":"BUY", "hash":"eece34ae03e5cc67a7330241baa61628f9fde8b2", "best_bid":"0.98", "best_ask":"0.99"}, {"asset_id":"81916206347121459497221114766050949090435061493822476265356047392175668050706", "price":"0.06", "size":"753", "side":"SELL", "hash":"21d8c8fc150830e8f310dce37d12211282c775fb", "best_bid":"0.01", "best_ask":"0.02"}], "timestamp":"1770241476437", "event_type":"price_change"}
{"market":"0x38f3050258345e9cf363d1c8cc302f08c65b96ba1a4669d81e07ed69708344df", "price_changes":[{"asset_id":"96888240988495161476033313796107536512663280794332045579302109906525918376981", "price":"0.95", "size":"680", "side":"BUY", "hash":"0fba8b141df2838943931b1489e25958b1979d22", "best_bid":"0.98", "best_ask":"0.99"}, {"asset_id":"81916206347121459497221114766050949090435061493822476265356047392175668050706", "price":"0.05", "size":"680", "side":"SELL", "hash":"7f84fef29018773b7fd8dc2983d37e99dda6378c", "best_bid":"0.01", "best_ask":"0.02"}], "timestamp":"1770241476441", "event_type":"price_change"}
{"market":"0x38f3050258345e9cf363d1c8cc302f08c65b96ba1a4669d81e07ed69708344df", "price_changes":[{"asset_id":"96888240988495161476033313796107536512663280794332045579302109906525918376981", "price":"0.95", "size":"707", "side":"BUY", "hash":"a576f19e2fe58a8bae9383c89c50755b20d0d9af", "best_bid":"0.98", "best_ask":"0.99"}, {"asset_id":"81916206347121459497221114766050949090435061493822476265356047392175668050706", "price":"0.05", "size":"707", "side":"SELL", "hash":"cd4c03a8ab236b0ba8015db540e02b4cbfba9d56", "best_bid":"0.01", "best_ask":"0.02"}], "timestamp":"1770241476450", "event_type":"price_change"}
{"market":"0x38f3050258345e9cf363d1c8cc302f08c65b96ba1a4669d81e07ed69708344df", "price_changes":[{"asset_id":"96888240988495161476033313796107536512663280794332045579302109906525918376981", "price":"0.96", "size":"655.73", "side":"BUY", "hash":"86163db80c60760c7b150981d2f02fb2cbc35b56", "best_bid":"0.98", "best_ask":"0.99"}, {"asset_id":"81916206347121459497221114766050949090435061493822476265356047392175668050706", "price":"0.04", "size":"655.73", "side":"SELL", "hash":"d905f85b144b5b2a43957250e62115da5af4d162", "best_bid":"0.01", "best_ask":"0.02"}], "timestamp":"1770241476452", "event_type":"price_change"}
{"market":"0x38f3050258345e9cf363d1c8cc302f08c65b96ba1a4669d81e07ed69708344df", "price_changes":[{"asset_id":"96888240988495161476033313796107536512663280794332045579302109906525918376981", "price":"0.94", "size":"726", "side":"BUY", "hash":"8fc5aca3bc21085b1b7363af774e5221781724e1", "best_bid":"0.98", "best_ask":"0.99"}, {"asset_id":"81916206347121459497221114766050949090435061493822476265356047392175668050706", "price":"0.06", "size":"726", "side":"SELL", "hash":"f74ef9adab4b653bbbbe3ada5861f668e3ecfebe", "best_bid":"0.01", "best_ask":"0.02"}], "timestamp":"1770241476454", "event_type":"price_change"}
{"market":"0x38f3050258345e9cf363d1c8cc302f08c65b96ba1a4669d81e07ed69708344df", "price_changes":[{"asset_id":"96888240988495161476033313796107536512663280794332045579302109906525918376981", "price":"0.95", "size":"680", "side":"BUY", "hash":"09cb9ed3987cb0dbfb5d967559cb254d49eaa0af", "best_bid":"0.98", "best_ask":"0.99"}, {"asset_id":"81916206347121459497221114766050949090435061493822476265356047392175668050706", "price":"0.05", "size":"680", "side":"SELL", "hash":"debc3e340a8c8caa60902854db3e355b264d3f7d", "best_bid":"0.01", "best_ask":"0.02"}], "timestamp":"1770241476456", "event_type":"price_change"}
{"market":"0x38f3050258345e9cf363d1c8cc302f08c65b96ba1a4669d81e07ed69708344df", "price_changes":[{"asset_id":"96888240988495161476033313796107536512663280794332045579302109906525918376981", "price":"0.96", "size":"682.73", "side":"BUY", "hash":"5b5fff546a3ca6863c51a26bdc3aee2c44e80851", "best_bid":"0.98", "best_ask":"0.99"}, {"asset_id":"81916206347121459497221114766050949090435061493822476265356047392175668050706", "price":"0.04", "size":"682.73", "side":"SELL", "hash":"3908f9d77e26441b849f7093066f7f30841c0100", "best_bid":"0.01", "best_ask":"0.02"}], "timestamp":"1770241476458", "event_type":"price_change"}
{"market":"0x38f3050258345e9cf363d1c8cc302f08c65b96ba1a4669d81e07ed69708344df", "price_changes":[{"asset_id":"96888240988495161476033313796107536512663280794332045579302109906525918376981", "price":"0.98", "size":"88.97", "side":"BUY", "hash":"7c76f4e9e1d6dd40cf455b551db72852afc52718", "best_bid":"0.98", "best_ask":"0.99"}, {"asset_id":"81916206347121459497221114766050949090435061493822476265356047392175668050706", "price":"0.02", "size":"88.97", "side":"SELL", "hash":"72aa7091577c1e6183cc420bc92be194a6b0e711", "best_bid":"0.01", "best_ask":"0.02"}], "timestamp":"1770241476465", "event_type":"price_change"}
{"market":"0x38f3050258345e9cf363d1c8cc302f08c65b96ba1a4669d81e07ed69708344df", "asset_id":"81916206347121459497221114766050949090435061493822476265356047392175668050706", "bids":[{"price":"0.01", "size":"3984.89"}], "asks":[{"price":"0.99", "size":"5019.91"}, {"price":"0.98", "size":"3034.23"}, {"price":"0.97", "size":"3172"}, {"price":"0.96", "size":"3012"}, {"price":"0.95", "size":"3032"}, {"price":"0.94", "size":"3012"}, {"price":"0.93", "size":"3126.28"}, {"price":"0.92", "size":"3012"}, {"price":"0.91", "size":"3012"}, {"price":"0.9", "size":"3087"}, {"price":"0.89", "size":"12"}, {"price":"0.88", "size":"12"}, {"price":"0.87", "size":"12"}, {"price":"0.86", "size":"12"}, {"price":"0.85", "size":"12"}, {"price":"0.84", "size":"12"}, {"price":"0.83", "size":"12"}, {"price":"0.82", "size":"12"}, {"price":"0.81", "size":"12"}, {"price":"0.8", "size":"12"}, {"price":"0.79", "size":"12"}, {"price":"0.78", "size":"12"}, {"price":"0.77", "size":"12"}, {"price":"0.76", "size":"112"}, {"price":"0.75", "size":"40.57"}, {"price":"0.74", "size":"12"}, {"price":"0.73", "size":"293.25"}, {"price":"0.72", "size":"22"}, {"price":"0.71", "size":"12"}, {"price":"0.7", "size":"18"}, {"price":"0.69", "size":"12"}, {"price":"0.68", "size":"12"}, {"price":"0.67", "size":"12"}, {"price":"0.66", "size":"160.89"}, {"price":"0.65", "size":"12"}, {"price":"0.64", "size":"12"}, {"price":"0.63", "size":"12"}, {"price":"0.62", "size":"19.39"}, {"price":"0.61", "size":"18.04"}, {"price":"0.6", "size":"12"}, {"price":"0.59", "size":"94.31"}, {"price":"0.58", "size":"5450.54"}, {"price":"0.57", "size":"12"}, {"price":"0.56", "size":"12"}, {"price":"0.55", "size":"12"}, {"price":"0.54", "size":"22"}, {"price":"0.53", "size":"12"}, {"price":"0.52", "size":"12"}, {"price":"0.51", "size":"12"}, {"price":"0.5", "size":"12"}, {"price":"0.49", "size":"12"}, {"price":"0.48", "size":"12"}, {"price":"0.47", "size":"12"}, {"price":"0.46", "size":"485.56"}, {"price":"0.45", "size":"31"}, {"price":"0.44", "size":"17"}, {"price":"0.43", "size":"12"}, {"price":"0.42", "size":"12"}, {"price":"0.41", "size":"12"}, {"price":"0.4", "size":"127"}, {"price":"0.39", "size":"12"}, {"price":"0.38", "size":"94.51"}, {"price":"0.37", "size":"31.99"}, {"price":"0.36", "size":"12"}, {"price":"0.35", "size":"37"}, {"price":"0.34", "size":"12"}, {"price":"0.33", "size":"12"}, {"price":"0.32", "size":"12"}, {"price":"0.31", "size":"12"}, {"price":"0.3", "size":"31.9"}, {"price":"0.29", "size":"344"}, {"price":"0.28", "size":"3288.99"}, {"price":"0.27", "size":"212"}, {"price":"0.26", "size":"218"}, {"price":"0.25", "size":"212"}, {"price":"0.24", "size":"212"}, {"price":"0.23", "size":"212"}, {"price":"0.22", "size":"1723.14"}, {"price":"0.21", "size":"412"}, {"price":"0.2", "size":"272.99"}, {"price":"0.19", "size":"212"}, {"price":"0.18", "size":"212"}, {"price":"0.17", "size":"212"}, {"price":"0.16", "size":"812"}, {"price":"0.15", "size":"231.08"}, {"price":"0.14", "size":"283.65"}, {"price":"0.13", "size":"212"}, {"price":"0.12", "size":"252"}, {"price":"0.11", "size":"252"}, {"price":"0.1", "size":"737.71"}, {"price":"0.09", "size":"261"}, {"price":"0.08", "size":"844.68"}, {"price":"0.07", "size":"826"}, {"price":"0.06", "size":"726"}, {"price":"0.05", "size":"680"}, {"price":"0.04", "size":"682.73"}, {"price":"0.03", "size":"570.32"}, {"price":"0.02", "size":"88.97"}], "hash":"72aa7091577c1e6183cc420bc92be194a6b0e711", "timestamp":"1770241476465", "event_type":"book"}
{"market":"0x38f3050258345e9cf363d1c8cc302f08c65b96ba1a4669d81e07ed69708344df", "asset_id":"81916206347121459497221114766050949090435061493822476265356047392175668050706", "price":"0.02", "size":"50", "fee_rate_bps":"0", "side":"BUY", "timestamp":"1770241476493", "event_type":"last_trade_price", "transaction_hash":"0x43ef1d828829d2d0635d29cd91c425b7c8c4a3f869faf652990512e3c73be1a4"}
{"market":"0x38f3050258345e9cf363d1c8cc302f08c65b96ba1a4669d81e07ed69708344df", "price_changes":[{"asset_id":"96888240988495161476033313796107536512663280794332045579302109906525918376981", "price":"0.95", "size":"653", "side":"BUY", "hash":"eaa3d802fae78b7a43869d5444c67e86d0df950f", "best_bid":"0.98", "best_ask":"0.99"}, {"asset_id":"81916206347121459497221114766050949090435061493822476265356047392175668050706", "price":"0.05", "size":"653", "side":"SELL", "hash":"00ab1950f81787e2c8c5f718f0d852db286815a1", "best_bid":"0.01", "best_ask":"0.02"}], "timestamp":"1770241476563", "event_type":"price_change"}
{"market":"0x38f3050258345e9cf363d1c8cc302f08c65b96ba1a4669d81e07ed69708344df", "price_changes":[{"asset_id":"96888240988495161476033313796107536512663280794332045579302109906525918376981", "price":"0.94", "size":"753", "side":"BUY", "hash":"498d1e078177116b1a1ef2691ce4630009fc2269", "best_bid":"0.98", "best_ask":"0.99"}, {"asset_id":"81916206347121459497221114766050949090435061493822476265356047392175668050706", "price":"0.06", "size":"753", "side":"SELL", "hash":"f65b14c0439a0d5ad56f97019ccf4f0064d011a7", "best_bid":"0.01", "best_ask":"0.02"}], "timestamp":"1770241476564", "event_type":"price_change"}
{"market":"0x38f3050258345e9cf363d1c8cc302f08c65b96ba1a4669d81e07ed69708344df", "price_changes":[{"asset_id":"96888240988495161476033313796107536512663280794332045579302109906525918376981", "price":"0.96", "size":"705.73", "side":"BUY", "hash":"67475ce52065568e3ffa2433564bbaa9165402b8", "best_bid":"0.98", "best_ask":"0.99"}, {"asset_id":"81916206347121459497221114766050949090435061493822476265356047392175668050706", "price":"0.04", "size":"705.73", "side":"SELL", "hash":"0d8dfd3cf6496c8ee127b9686cd80fe4dd1c8df7", "best_bid":"0.01", "best_ask":"0.02"}], "timestamp":"1770241476565", "event_type":"price_change"}
{"market":"0x38f3050258345e9cf363d1c8cc302f08c65b96ba1a4669d81e07ed69708344df", "price_changes":[{"asset_id":"96888240988495161476033313796107536512663280794332045579302109906525918376981", "price":"0.95", "size":"626", "side":"BUY", "hash":"db325085b13a3d4144107d5569a0eab5a1069abe", "best_bid":"0.98", "best_ask":"0.99"}, {"asset_id":"81916206347121459497221114766050949090435061493822476265356047392175668050706", "price":"0.05", "size":"626", "side":"SELL", "hash":"2cd4d796ef2572eac40044844c57128da8266ca2", "best_bid":"0.01", "best_ask":"0.02"}], "timestamp":"1770241476573", "event_type":"price_change"}
{"market":"0x38f3050258345e9cf363d1c8cc302f08c65b96ba1a4669d81e07ed69708344df", "price_changes":[{"asset_id":"96888240988495161476033313796107536512663280794332045579302109906525918376981", "price":"0.94", "size":"780", "side":"BUY", "hash":"4c32983d159108240a081ec4baeec19bad0499e0", "best_bid":"0.98", "best_ask":"0.99"}, {"asset_id":"81916206347121459497221114766050949090435061493822476265356047392175668050706", "price":"0.06", "size":"780", "side":"SELL", "hash":"992e3f7997f16620eaaa3969504044f65bd8185a", "best_bid":"0.01", "best_ask":"0.02"}], "timestamp":"1770241476574", "event_type":"price_change"}
{"market":"0x38f3050258345e9cf363d1c8cc302f08c65b96ba1a4669d81e07ed69708344df", "price_changes":[{"asset_id":"96888240988495161476033313796107536512663280794332045579302109906525918376981", "price":"0.96", "size":"678.73", "side":"BUY", "hash":"27353c4dd73cbd96fba854e2ecc02daa10aedb2a", "best_bid":"0.98", "best_ask":"0.99"}, {"asset_id":"81916206347121459497221114766050949090435061493822476265356047392175668050706", "price":"0.04", "size":"678.73", "side":"SELL", "hash":"ae841a150d9d3d8a583502cdf495c1483642d0c2", "best_bid":"0.01", "best_ask":"0.02"}], "timestamp":"1770241476583", "event_type":"price_change"}
{"market":"0x38f3050258345e9cf363d1c8cc302f08c65b96ba1a4669d81e07ed69708344df", "price_changes":[{"asset_id":"96888240988495161476033313796107536512663280794332045579302109906525918376981", "price":"0.95", "size":"653", "side":"BUY", "hash":"c7eb693d8970172e7a16d41cfce59365b5f0836d", "best_bid":"0.98", "best_ask":"0.99"}, {"asset_id":"81916206347121459497221114766050949090435061493822476265356047392175668050706", "price":"0.05", "size":"653", "side":"SELL", "hash":"86a0c3a01d728b96519525996fff9f237e9ce0a3", "best_bid":"0.01", "best_ask":"0.02"}], "timestamp":"1770241476585", "event_type":"price_change"}
{"market":"0x38f3050258345e9cf363d1c8cc302f08c65b96ba1a4669d81e07ed69708344df", "price_changes":[{"asset_id":"96888240988495161476033313796107536512663280794332045579302109906525918376981", "price":"0.94", "size":"980", "side":"BUY", "hash":"b0d5aa0438e68762788a4e279041b42f8f0842b0", "best_bid":"0.98", "best_ask":"0.99"}, {"asset_id":"81916206347121459497221114766050949090435061493822476265356047392175668050706", "price":"0.06", "size":"980", "side":"SELL", "hash":"4ff97900f65a2d85cf055edcdf736c9695044762", "best_bid":"0.01", "best_ask":"0.02"}], "timestamp":"1770241476684", "event_type":"price_change"}
{"market":"0x38f3050258345e9cf363d1c8cc302f08c65b96ba1a4669d81e07ed69708344df", "price_changes":[{"asset_id":"96888240988495161476033313796107536512663280794332045579302109906525918376981", "price":"0.96", "size":"655.73", "side":"BUY", "hash":"989683b1e903f176aea03e3a1e0b5a6e7cd2cc88", "best_bid":"0.98", "best_ask":"0.99"}, {"asset_id":"81916206347121459497221114766050949090435061493822476265356047392175668050706", "price":"0.04", "size":"655.73", "side":"SELL", "hash":"1f4e4eb5df5ee5ae39b9beb7b41e2b123a02f583", "best_bid":"0.01", "best_ask":"0.02"}], "timestamp":"1770241476717", "event_type":"price_change"}
{"market":"0x38f3050258345e9cf363d1c8cc302f08c65b96ba1a4669d81e07ed69708344df", "price_changes":[{"asset_id":"96888240988495161476033313796107536512663280794332045579302109906525918376981", "price":"0.97", "size":"593.32", "side":"BUY", "hash":"8111ffc69c2e23d4c71a92f9c75feafd8ea47be3", "best_bid":"0.98", "best_ask":"0.99"}, {"asset_id":"81916206347121459497221114766050949090435061493822476265356047392175668050706", "price":"0.03", "size":"593.32", "side":"SELL", "hash":"2eb5a6f541354561a87afb8feb9cacf376875c41", "best_bid":"0.01", "best_ask":"0.02"}], "timestamp":"1770241476718", "event_type":"price_change"}
{"market":"0x38f3050258345e9cf363d1c8cc302f08c65b96ba1a4669d81e07ed69708344df", "price_changes":[{"asset_id":"96888240988495161476033313796107536512663280794332045579302109906525918376981", "price":"0.96", "size":"678.73", "side":"BUY", "hash":"78d8cbe641d685ad88e0dc005bef7755d6288f7a", "best_bid":"0.98", "best_ask":"0.99"}, {"asset_id":"81916206347121459497221114766050949090435061493822476265356047392175668050706", "price":"0.04", "size":"678.73", "side":"SELL", "hash":"b7eb5193f6a064774736ebff3ea3f8852bc1d731", "best_bid":"0.01", "best_ask":"0.02"}], "timestamp":"1770241476879", "event_type":"price_change"}
{"market":"0x38f3050258345e9cf363d1c8cc302f08c65b96ba1a4669d81e07ed69708344df", "price_changes":[{"asset_id":"96888240988495161476033313796107536512663280794332045579302109906525918376981", "price":"0.97", "size":"570.32", "side":"BUY", "hash":"69b04d8217be04ef12ced3e3f6e7ed5195abe25d", "best_bid":"0.98", "best_ask":"0.99"}, {"asset_id":"81916206347121459497221114766050949090435061493822476265356047392175668050706", "price":"0.03", "size":"570.32", "side":"SELL", "hash":"84bdd2ad42233557f00735cd9418760e8afbf3fc", "best_bid":"0.01", "best_ask":"0.02"}], "timestamp":"1770241476879", "event_type":"price_change"}
{"market":"0x38f3050258345e9cf363d1c8cc302f08c65b96ba1a4669d81e07ed69708344df", "price_changes":[{"asset_id":"96888240988495161476033313796107536512663280794332045579302109906525918376981", "price":"0.96", "size":"698.73", "side":"BUY", "hash":"acf98e27c933d19b2ad5e1e9bd8d54108e008ed6", "best_bid":"0.98", "best_ask":"0.99"}, {"asset_id":"81916206347121459497221114766050949090435061493822476265356047392175668050706", "price":"0.04", "size":"698.73", "side":"SELL", "hash":"76ce0fb9525a8fba024d5e76c1288c33e761a025", "best_bid":"0.01", "best_ask":"0.02"}], "timestamp":"1770241476944", "event_type":"price_change"}
{"market":"0x38f3050258345e9cf363d1c8cc302f08c65b96ba1a4669d81e07ed69708344df", "price_changes":[{"asset_id":"96888240988495161476033313796107536512663280794332045579302109906525918376981", "price":"0.96", "size":"675.73", "side":"BUY", "hash":"d31e221f19c7e840eaa8a087bb9a93e5aaed51bb", "best_bid":"0.98", "best_ask":"0.99"}, {"asset_id":"81916206347121459497221114766050949090435061493822476265356047392175668050706", "price":"0.04", "size":"675.73", "side":"SELL", "hash":"b1df872ff2b6bd34495fe764575a3076f0a24c35", "best_bid":"0.01", "best_ask":"0.02"}], "timestamp":"1770241477035", "event_type":"price_change"}
{"market":"0x38f3050258345e9cf363d1c8cc302f08c65b96ba1a4669d81e07ed69708344df", "price_changes":[{"asset_id":"96888240988495161476033313796107536512663280794332045579302109906525918376981", "price":"0.97", "size":"593.32", "side":"BUY", "hash":"25c83785d1fe1514c967599b91edd1b9d01cc9a8", "best_bid":"0.98", "best_ask":"0.99"}, {"asset_id":"81916206347121459497221114766050949090435061493822476265356047392175668050706", "price":"0.03", "size":"593.32", "side":"SELL", "hash":"fe0c9e27228c9495e5578563db137b8ba609bd90", "best_bid":"0.01", "best_ask":"0.02"}], "timestamp":"1770241477041", "event_type":"price_change"}
{"market":"0x38f3050258345e9cf363d1c8cc302f08c65b96ba1a4669d81e07ed69708344df", "price_changes":[{"asset_id":"96888240988495161476033313796107536512663280794332045579302109906525918376981", "price":"0.99", "size":"4024.89", "side":"SELL", "hash":"f78b637c200965011e097fa5f7f73fe6c7d12b47", "best_bid":"0.98", "best_ask":"0.99"}, {"asset_id":"81916206347121459497221114766050949090435061493822476265356047392175668050706", "price":"0.01", "size":"4024.89", "side":"BUY", "hash":"8a6892f87cdbe70592e8ab924f00e7e5f2f62397", "best_bid":"0.01", "best_ask":"0.02"}], "timestamp":"1770241477184", "event_type":"price_change"}
{"market":"0x38f3050258345e9cf363d1c8cc302f08c65b96ba1a4669d81e07ed69708344df", "price_changes":[{"asset_id":"96888240988495161476033313796107536512663280794332045579302109906525918376981", "price":"0.94", "size":"953", "side":"BUY", "hash":"bdfe04e90861ab89b65cf3fd6f8247b14b5e92e2", "best_bid":"0.98", "best_ask":"0.99"}, {"asset_id":"81916206347121459497221114766050949090435061493822476265356047392175668050706", "price":"0.06", "size":"953", "side":"SELL", "hash":"6323d72a8f35f69b166b813e0ada68de09bab895", "best_bid":"0.01", "best_ask":"0.02"}], "timestamp":"1770241477209", "event_type":"price_change"}
{"market":"0x38f3050258345e9cf363d1c8cc302f08c65b96ba1a4669d81e07ed69708344df", "price_changes":[{"asset_id":"96888240988495161476033313796107536512663280794332045579302109906525918376981", "price":"0.95", "size":"680", "side":"BUY", "hash":"ceb242aa390dc4abc320fa0aca17574fe627967a", "best_bid":"0.98", "best_ask":"0.99"}, {"asset_id":"81916206347121459497221114766050949090435061493822476265356047392175668050706", "price":"0.05", "size":"680", "side":"SELL", "hash":"d4bc2443ea37015d14cc7906dc05540930cb7224", "best_bid":"0.01", "best_ask":"0.02"}], "timestamp":"1770241477210", "event_type":"price_change"}
{"market":"0x38f3050258345e9cf363d1c8cc302f08c65b96ba1a4669d81e07ed69708344df", "price_changes":[{"asset_id":"96888240988495161476033313796107536512663280794332045579302109906525918376981", "price":"0.96", "size":"702.73", "side":"BUY", "hash":"837f188040374a4a7931b8b70481b333c8cef0d8", "best_bid":"0.98", "best_ask":"0.99"}, {"asset_id":"81916206347121459497221114766050949090435061493822476265356047392175668050706", "price":"0.04", "size":"702.73", "side":"SELL", "hash":"0cacdd1cfc3c7fd86e7556e5f8a369ed29bd8406", "best_bid":"0.01", "best_ask":"0.02"}], "timestamp":"1770241477217", "event_type":"price_change"}
{"market":"0x38f3050258345e9cf363d1c8cc302f08c65b96ba1a4669d81e07ed69708344df", "price_changes":[{"asset_id":"96888240988495161476033313796107536512663280794332045579302109906525918376981", "price":"0.95", "size":"653", "side":"BUY", "hash":"2907bf71fce923d8736ae13ca2d2476c5304c7ce", "best_bid":"0.98", "best_ask":"0.99"}, {"asset_id":"81916206347121459497221114766050949090435061493822476265356047392175668050706", "price":"0.05", "size":"653", "side":"SELL", "hash":"ccf77c71222c3dcf472053db509f62c0063f5702", "best_bid":"0.01", "best_ask":"0.02"}], "timestamp":"1770241477220", "event_type":"price_change"}
{"market":"0x38f3050258345e9cf363d1c8cc302f08c65b96ba1a4669d81e07ed69708344df", "price_changes":[{"asset_id":"96888240988495161476033313796107536512663280794332045579302109906525918376981", "price":"0.94", "size":"926", "side":"BUY", "hash":"4641341ee12fd1c5d160156071235dc7b0a9b20a", "best_bid":"0.98", "best_ask":"0.99"}, {"asset_id":"81916206347121459497221114766050949090435061493822476265356047392175668050706", "price":"0.06", "size":"926", "side":"SELL", "hash":"c1cf577cb64d5f10f5e71b19bfa6bdb32ae81b5e", "best_bid":"0.01", "best_ask":"0.02"}], "timestamp":"1770241477221", "event_type":"price_change"}
{"market":"0x38f3050258345e9cf363d1c8cc302f08c65b96ba1a4669d81e07ed69708344df", "price_changes":[{"asset_id":"96888240988495161476033313796107536512663280794332045579302109906525918376981", "price":"0.95", "size":"680", "side":"BUY", "hash":"d56e57479a3f5ca1f80ba109e7661a8ad1c0802c", "best_bid":"0.98", "best_ask":"0.99"}, {"asset_id":"81916206347121459497221114766050949090435061493822476265356047392175668050706", "price":"0.05", "size":"680", "side":"SELL", "hash":"711fe6bcc1fab994828543d410e5254bbefdff1b", "best_bid":"0.01", "best_ask":"0.02"}], "timestamp":"1770241477222", "event_type":"price_change"}
{"market":"0x38f3050258345e9cf363d1c8cc302f08c65b96ba1a4669d81e07ed69708344df", "price_changes":[{"asset_id":"96888240988495161476033313796107536512663280794332045579302109906525918376981", "price":"0.79", "size":"212", "side":"BUY", "hash":"95fed564f912e827461393977ec2a6006753b807", "best_bid":"0.98", "best_ask":"0.99"}, {"asset_id":"81916206347121459497221114766050949090435061493822476265356047392175668050706", "price":"0.21", "size":"212", "side":"SELL", "hash":"2a832f8975026af25c4ebe5c449dcaffe8138efb", "best_bid":"0.01", "best_ask":"0.02"}], "timestamp":"1770241477288", "event_type":"price_change"}
{"market":"0x38f3050258345e9cf363d1c8cc302f08c65b96ba1a4669d81e07ed69708344df", "price_changes":[{"asset_id":"96888240988495161476033313796107536512663280794332045579302109906525918376981", "price":"0.95", "size":"707", "side":"BUY", "hash":"a07b04033e64ebb4b0c2ed75e061f0b594ac5298", "best_bid":"0.98", "best_ask":"0.99"}, {"asset_id":"81916206347121459497221114766050949090435061493822476265356047392175668050706", "price":"0.05", "size":"707", "side":"SELL", "hash":"42c7c481bf34547bfe21a9e5eb902ed42c678c1a", "best_bid":"0.01", "best_ask":"0.02"}], "timestamp":"1770241477351", "event_type":"price_change"}
{"market":"0x38f3050258345e9cf363d1c8cc302f08c65b96ba1a4669d81e07ed69708344df", "price_changes":[{"asset_id":"96888240988495161476033313796107536512663280794332045579302109906525918376981", "price":"0.96", "size":"675.73", "side":"BUY", "hash":"b1aabb20eb94d413259410a500ad8f6b1fb021cf", "best_bid":"0.98", "best_ask":"0.99"}, {"asset_id":"81916206347121459497221114766050949090435061493822476265356047392175668050706", "price":"0.04", "size":"675.73", "side":"SELL", "hash":"d11ee694512fb19e7eabd8a01db80c7d7bb87876", "best_bid":"0.01", "best_ask":"0.02"}], "timestamp":"1770241477355", "event_type":"price_change"}
{"market":"0x38f3050258345e9cf363d1c8cc302f08c65b96ba1a4669d81e07ed69708344df", "price_changes":[{"asset_id":"81916206347121459497221114766050949090435061493822476265356047392175668050706", "price":"0.01", "size":"4051.89", "side":"BUY", "hash":"29e8c9a6bb7d352a917f334221d834b13b7975f9", "best_bid":"0.01", "best_ask":"0.02"}, {"asset_id":"96888240988495161476033313796107536512663280794332045579302109906525918376981", "price":"0.99", "size":"4051.89", "side":"SELL", "hash":"e5f1d9217f1c8e6788c671eae0cd80092a6c7c79", "best_bid":"0.98", "best_ask":"0.99"}], "timestamp":"1770241477367", "event_type":"price_change"}
{"market":"0x38f3050258345e9cf363d1c8cc302f08c65b96ba1a4669d81e07ed69708344df", "price_changes":[{"asset_id":"81916206347121459497221114766050949090435061493822476265356047392175668050706", "price":"0.01", "size":"4078.89", "side":"BUY", "hash":"5dcb43a09f31346967270ea1647f07b78c06264c", "best_bid":"0.01", "best_ask":"0.02"}, {"asset_id":"96888240988495161476033313796107536512663280794332045579302109906525918376981", "price":"0.99", "size":"4078.89", "side":"SELL", "hash":"08e89fd8fa3a53407b8c023dba699f541b4529bd", "best_bid":"0.98", "best_ask":"0.99"}], "timestamp":"1770241477367", "event_type":"price_change"}
{"market":"0x38f3050258345e9cf363d1c8cc302f08c65b96ba1a4669d81e07ed69708344df", "price_changes":[{"asset_id":"81916206347121459497221114766050949090435061493822476265356047392175668050706", "price":"0.01", "size":"4101.89", "side":"BUY", "hash":"144baf6f9aa2599259339397692f7224cf30dbed", "best_bid":"0.01", "best_ask":"0.02"}, {"asset_id":"96888240988495161476033313796107536512663280794332045579302109906525918376981", "price":"0.99", "size":"4101.89", "side":"SELL", "hash":"e7c945470deb1263fbe2e709ce1d0d2b49d10876", "best_bid":"0.98", "best_ask":"0.99"}], "timestamp":"1770241477373", "event_type":"price_change"}
{"market":"0x38f3050258345e9cf363d1c8cc302f08c65b96ba1a4669d81e07ed69708344df", "price_changes":[{"asset_id":"81916206347121459497221114766050949090435061493822476265356047392175668050706", "price":"0.01", "size":"4128.89", "side":"BUY", "hash":"3c33feb6abe42dfe32b59d7286d2e591ab5bca3e", "best_bid":"0.01", "best_ask":"0.02"}, {"asset_id":"96888240988495161476033313796107536512663280794332045579302109906525918376981", "price":"0.99", "size":"4128.89", "side":"SELL", "hash":"2446fd80b492d15ec812129c501203bf7d25e1f3", "best_bid":"0.98", "best_ask":"0.99"}], "timestamp":"1770241477390", "event_type":"price_change"}
{"market":"0x38f3050258345e9cf363d1c8cc302f08c65b96ba1a4669d81e07ed69708344df", "price_changes":[{"asset_id":"96888240988495161476033313796107536512663280794332045579302109906525918376981", "price":"0.95", "size":"680", "side":"BUY", "hash":"b42a8e4a2df30dc4dd27e0665eaa2df3ef719fda", "best_bid":"0.98", "best_ask":"0.99"}, {"asset_id":"81916206347121459497221114766050949090435061493822476265356047392175668050706", "price":"0.05", "size":"680", "side":"SELL", "hash":"114e8a6771da2fef60fb9e9ce7d87bc886db9e21", "best_bid":"0.01", "best_ask":"0.02"}], "timestamp":"1770241477420", "event_type":"price_change"}
{"market":"0x38f3050258345e9cf363d1c8cc302f08c65b96ba1a4669d81e07ed69708344df", "price_changes":[{"asset_id":"96888240988495161476033313796107536512663280794332045579302109906525918376981", "price":"0.94", "size":"953", "side":"BUY", "hash":"991de8eff2fcc9e7b154e438f09a8a66131f0435", "best_bid":"0.98", "best_ask":"0.99"}, {"asset_id":"81916206347121459497221114766050949090435061493822476265356047392175668050706", "price":"0.06", "size":"953", "side":"SELL", "hash":"4bda239b6e9073e3fc7c6d416a54e61942d3a23f", "best_bid":"0.01", "best_ask":"0.02"}], "timestamp":"1770241477421", "event_type":"price_change"}
{"market":"0x38f3050258345e9cf363d1c8cc302f08c65b96ba1a4669d81e07ed69708344df", "price_changes":[{"asset_id":"96888240988495161476033313796107536512663280794332045579302109906525918376981", "price":"0.94", "size":"980", "side":"BUY", "hash":"f97f30cfe6fdd17860487976f13e5fc851a12b7e", "best_bid":"0.98", "best_ask":"0.99"}, {"asset_id":"81916206347121459497221114766050949090435061493822476265356047392175668050706", "price":"0.06", "size":"980", "side":"SELL", "hash":"da2b6a9231fe5711aea4c970cf092b2db5c3b1a0", "best_bid":"0.01", "best_ask":"0.02"}], "timestamp":"1770241477433", "event_type":"price_change"}
{"market":"0x38f3050258345e9cf363d1c8cc302f08c65b96ba1a4669d81e07ed69708344df", "price_changes":[{"asset_id":"96888240988495161476033313796107536512663280794332045579302109906525918376981", "price":"0.95", "size":"653", "side":"BUY", "hash":"21364c8425c84a6a3ef4e477c06c618f2d33659c", "best_bid":"0.98", "best_ask":"0.99"}, {"asset_id":"81916206347121459497221114766050949090435061493822476265356047392175668050706", "price":"0.05", "size":"653", "side":"SELL", "hash":"1b91bcd6582ad1d50a05eaa5bf87a489a75ef37f", "best_bid":"0.01", "best_ask":"0.02"}], "timestamp":"1770241477434", "event_type":"price_change"}
{"market":"0x38f3050258345e9cf363d1c8cc302f08c65b96ba1a4669d81e07ed69708344df", "price_changes":[{"asset_id":"81916206347121459497221114766050949090435061493822476265356047392175668050706", "price":"0.01", "size":"4123.89", "side":"BUY", "hash":"a7f66ab0377a847dad276b56baa5a87e2f13d73a", "best_bid":"0.01", "best_ask":"0.02"}, {"asset_id":"96888240988495161476033313796107536512663280794332045579302109906525918376981", "price":"0.99", "size":"4123.89", "side":"SELL", "hash":"777ac38fabfbb98afbe59eca010002f89c09cbbb", "best_bid":"0.98", "best_ask":"0.99"}], "timestamp":"1770241477464", "event_type":"price_change"}
{"market":"0x38f3050258345e9cf363d1c8cc302f08c65b96ba1a4669d81e07ed69708344df", "asset_id":"81916206347121459497221114766050949090435061493822476265356047392175668050706", "bids":[{"price":"0.01", "size":"4123.89"}], "asks":[{"price":"0.99", "size":"5019.91"}, {"price":"0.98", "size":"3034.23"}, {"price":"0.97", "size":"3172"}, {"price":"0.96", "size":"3012"}, {"price":"0.95", "size":"3032"}, {"price":"0.94", "size":"3012"}, {"price":"0.93", "size":"3126.28"}, {"price":"0.92", "size":"3012"}, {"price":"0.91", "size":"3012"}, {"price":"0.9", "size":"3087"}, {"price":"0.89", "size":"12"}, {"price":"0.88", "size":"12"}, {"price":"0.87", "size":"12"}, {"price":"0.86", "size":"12"}, {"price":"0.85", "size":"12"}, {"price":"0.84", "size":"12"}, {"price":"0.83", "size":"12"}, {"price":"0.82", "size":"12"}, {"price":"0.81", "size":"12"}, {"price":"0.8", "size":"12"}, {"price":"0.79", "size":"12"}, {"price":"0.78", "size":"12"}, {"price":"0.77", "size":"12"}, {"price":"0.76", "size":"112"}, {"price":"0.75", "size":"40.57"}, {"price":"0.74", "size":"12"}, {"price":"0.73", "size":"293.25"}, {"price":"0.72", "size":"22"}, {"price":"0.71", "size":"12"}, {"price":"0.7", "size":"18"}, {"price":"0.69", "size":"12"}, {"price":"0.68", "size":"12"}, {"price":"0.67", "size":"12"}, {"price":"0.66", "size":"160.89"}, {"price":"0.65", "size":"12"}, {"price":"0.64", "size":"12"}, {"price":"0.63", "size":"12"}, {"price":"0.62", "size":"19.39"}, {"price":"0.61", "size":"18.04"}, {"price":"0.6", "size":"12"}, {"price":"0.59", "size":"94.31"}, {"price":"0.58", "size":"5450.54"}, {"price":"0.57", "size":"12"}, {"price":"0.56", "size":"12"}, {"price":"0.55", "size":"12"}, {"price":"0.54", "size":"22"}, {"price":"0.53", "size":"12"}, {"price":"0.52", "size":"12"}, {"price":"0.51", "size":"12"}, {"price":"0.5", "size":"12"}, {"price":"0.49", "size":"12"}, {"price":"0.48", "size":"12"}, {"price":"0.47", "size":"12"}, {"price":"0.46", "size":"485.56"}, {"price":"0.45", "size":"31"}, {"price":"0.44", "size":"17"}, {"price":"0.43", "size":"12"}, {"price":"0.42", "size":"12"}, {"price":"0.41", "size":"12"}, {"price":"0.4", "size":"127"}, {"price":"0.39", "size":"12"}, {"price":"0.38", "size":"94.51"}, {"price":"0.37", "size":"31.99"}, {"price":"0.36", "size":"12"}, {"price":"0.35", "size":"37"}, {"price":"0.34", "size":"12"}, {"price":"0.33", "size":"12"}, {"price":"0.32", "size":"12"}, {"price":"0.31", "size":"12"}, {"price":"0.3", "size":"31.9"}, {"price":"0.29", "size":"344"}, {"price":"0.28", "size":"3288.99"}, {"price":"0.27", "size":"212"}, {"price":"0.26", "size":"218"}, {"price":"0.25", "size":"212"}, {"price":"0.24", "size":"212"}, {"price":"0.23", "size":"212"}, {"price":"0.22", "size":"1723.14"}, {"price":"0.21", "size":"212"}, {"price":"0.2", "size":"272.99"}, {"price":"0.19", "size":"212"}, {"price":"0.18", "size":"212"}, {"price":"0.17", "size":"212"}, {"price":"0.16", "size":"812"}, {"price":"0.15", "size":"231.08"}, {"price":"0.14", "size":"283.65"}, {"price":"0.13", "size":"212"}, {"price":"0.12", "size":"252"}, {"price":"0.11", "size":"252"}, {"price":"0.1", "size":"737.71"}, {"price":"0.09", "size":"261"}, {"price":"0.08", "size":"844.68"}, {"price":"0.07", "size":"826"}, {"price":"0.06", "size":"980"}, {"price":"0.05", "size":"653"}, {"price":"0.04", "size":"675.73"}, {"price":"0.03", "size":"593.32"}, {"price":"0.02", "size":"88.97"}], "hash":"a7f66ab0377a847dad276b56baa5a87e2f13d73a", "timestamp":"1770241477464", "event_type":"book"}
{"market":"0x38f3050258345e9cf363d1c8cc302f08c65b96ba1a4669d81e07ed69708344df", "price_changes":[{"asset_id":"81916206347121459497221114766050949090435061493822476265356047392175668050706", "price":"0.01", "size":"4096.89", "side":"BUY", "hash":"670e3e73c79f4f3675c0cf3ec6a73c15b64a627a", "best_bid":"0.01", "best_ask":"0.02"}, {"asset_id":"96888240988495161476033313796107536512663280794332045579302109906525918376981", "price":"0.99", "size":"4096.89", "side":"SELL", "hash":"cc69af2e6337059ce3645121ccf468987114776d", "best_bid":"0.98", "best_ask":"0.99"}], "timestamp":"1770241477487", "event_type":"price_change"}
{"market":"0x38f3050258345e9cf363d1c8cc302f08c65b96ba1a4669d81e07ed69708344df", "price_changes":[{"asset_id":"81916206347121459497221114766050949090435061493822476265356047392175668050706", "price":"0.01", "size":"4123.89", "side":"BUY", "hash":"1fd92266717cc8dce9b9a6c9621630c6581ada2f", "best_bid":"0.01", "best_ask":"0.02"}, {"asset_id":"96888240988495161476033313796107536512663280794332045579302109906525918376981", "price":"0.99", "size":"4123.89", "side":"SELL", "hash":"c2c11eb49434e740c6fc0e1d6e78e96cb77a5060", "best_bid":"0.98", "best_ask":"0.99"}], "timestamp":"1770241477494", "event_type":"price_change"}
{"market":"0x38f3050258345e9cf363d1c8cc302f08c65b96ba1a4669d81e07ed69708344df", "price_changes":[{"asset_id":"81916206347121459497221114766050949090435061493822476265356047392175668050706", "price":"0.01", "size":"4150.89", "side":"BUY", "hash":"10b351c2c73d5e54cfb4bfe11e59d76359eb7492", "best_bid":"0.01", "best_ask":"0.02"}, {"asset_id":"96888240988495161476033313796107536512663280794332045579302109906525918376981", "price":"0.99", "size":"4150.89", "side":"SELL", "hash":"69f2027146e1f4a54da9cafd418412e4935c67df", "best_bid":"0.98", "best_ask":"0.99"}], "timestamp":"1770241477508", "event_type":"price_change"}
{"market":"0x38f3050258345e9cf363d1c8cc302f08c65b96ba1a4669d81e07ed69708344df", "price_changes":[{"asset_id":"81916206347121459497221114766050949090435061493822476265356047392175668050706", "price":"0.01", "size":"4177.89", "side":"BUY", "hash":"4e769fc90df5f06f4fb909877e3606a104666e37", "best_bid":"0.01", "best_ask":"0.02"}, {"asset_id":"96888240988495161476033313796107536512663280794332045579302109906525918376981", "price":"0.99", "size":"4177.89", "side":"SELL", "hash":"f3b271741d28a82ce4171f69b5669b1a03d42b9b", "best_bid":"0.98", "best_ask":"0.99"}], "timestamp":"1770241477509", "event_type":"price_change"}
{"market":"0x38f3050258345e9cf363d1c8cc302f08c65b96ba1a4669d81e07ed69708344df", "price_changes":[{"asset_id":"81916206347121459497221114766050949090435061493822476265356047392175668050706", "price":"0.01", "size":"4150.89", "side":"BUY", "hash":"f44f4c669149a89fdb01bbc888573175dd458a83", "best_bid":"0.01", "best_ask":"0.02"}, {"asset_id":"96888240988495161476033313796107536512663280794332045579302109906525918376981", "price":"0.99", "size":"4150.89", "side":"SELL", "hash":"9d31ac417db191d42af4855ada1f85cc57c3772d", "best_bid":"0.98", "best_ask":"0.99"}], "timestamp":"1770241477510", "event_type":"price_change"}
{"market":"0x38f3050258345e9cf363d1c8cc302f08c65b96ba1a4669d81e07ed69708344df", "price_changes":[{"asset_id":"81916206347121459497221114766050949090435061493822476265356047392175668050706", "price":"0.01", "size":"4123.89", "side":"BUY", "hash":"ebe82c9c855b8d6fd177f967dd7b1bfff49ad59c", "best_bid":"0.01", "best_ask":"0.02"}, {"asset_id":"96888240988495161476033313796107536512663280794332045579302109906525918376981", "price":"0.99", "size":"4123.89", "side":"SELL", "hash":"d29a14cf8b984f256388b465f84552278fe0fccb", "best_bid":"0.98", "best_ask":"0.99"}], "timestamp":"1770241477514", "event_type":"price_change"}
{"market":"0x38f3050258345e9cf363d1c8cc302f08c65b96ba1a4669d81e07ed69708344df", "price_changes":[{"asset_id":"81916206347121459497221114766050949090435061493822476265356047392175668050706", "price":"0.01", "size":"4096.89", "side":"BUY", "hash":"801bb179011d56a9adceeb26d48059d49bbe2438", "best_bid":"0.01", "best_ask":"0.02"}, {"asset_id":"96888240988495161476033313796107536512663280794332045579302109906525918376981", "price":"0.99", "size":"4096.89", "side":"SELL", "hash":"0f02b1e91fd81cf781a17be3913bec2623755825", "best_bid":"0.98", "best_ask":"0.99"}], "timestamp":"1770241477682", "event_type":"price_change"}
{"market":"0x38f3050258345e9cf363d1c8cc302f08c65b96ba1a4669d81e07ed69708344df", "price_changes":[{"asset_id":"96888240988495161476033313796107536512663280794332045579302109906525918376981", "price":"0.94", "size":"953", "side":"BUY", "hash":"7288d694a51af3e40fd8819743d1921a26b99292", "best_bid":"0.98", "best_ask":"0.99"}, {"asset_id":"81916206347121459497221114766050949090435061493822476265356047392175668050706", "price":"0.06", "size":"953", "side":"SELL", "hash":"2da1f63bc66f590000be101a3362886a45e2ffd8", "best_bid":"0.01", "best_ask":"0.02"}], "timestamp":"1770241477682", "event_type":"price_change"}
{"market":"0x38f3050258345e9cf363d1c8cc302f08c65b96ba1a4669d81e07ed69708344df", "price_changes":[{"asset_id":"81916206347121459497221114766050949090435061493822476265356047392175668050706", "price":"0.01", "size":"4123.89", "side":"BUY", "hash":"a56fc3f1750360dec901edba48af0ab519c1fc87", "best_bid":"0.01", "best_ask":"0.02"}, {"asset_id":"96888240988495161476033313796107536512663280794332045579302109906525918376981", "price":"0.99", "size":"4123.89", "side":"SELL", "hash":"07a73726ef4de90620db8b58ad4de30b9fef5c36", "best_bid":"0.98", "best_ask":"0.99"}], "timestamp":"1770241477683", "event_type":"price_change"}
{"market":"0x38f3050258345e9cf363d1c8cc302f08c65b96ba1a4669d81e07ed69708344df", "price_changes":[{"asset_id":"96888240988495161476033313796107536512663280794332045579302109906525918376981", "price":"0.95", "size":"680", "side":"BUY", "hash":"2c1b5e88c510b9173215a1358adedff4f32bbe08", "best_bid":"0.98", "best_ask":"0.99"}, {"asset_id":"81916206347121459497221114766050949090435061493822476265356047392175668050706", "price":"0.05", "size":"680", "side":"SELL", "hash":"8f35bc9f7c3b3ed05303f3f6630c58415ead609a", "best_bid":"0.01", "best_ask":"0.02"}], "timestamp":"1770241477685", "event_type":"price_change"}
{"market":"0x38f3050258345e9cf363d1c8cc302f08c65b96ba1a4669d81e07ed69708344df", "price_changes":[{"asset_id":"96888240988495161476033313796107536512663280794332045579302109906525918376981", "price":"0.94", "size":"926", "side":"BUY", "hash":"0e45219521ce4fe6b5460af596d2980b7c50e9da", "best_bid":"0.98", "best_ask":"0.99"}, {"asset_id":"81916206347121459497221114766050949090435061493822476265356047392175668050706", "price":"0.06", "size":"926", "side":"SELL", "hash":"92761b7636f655f651dfb4b527a967060a45fb2f", "best_bid":"0.01", "best_ask":"0.02"}], "timestamp":"1770241477692", "event_type":"price_change"}
{"market":"0x38f3050258345e9cf363d1c8cc302f08c65b96ba1a4669d81e07ed69708344df", "price_changes":[{"asset_id":"81916206347121459497221114766050949090435061493822476265356047392175668050706", "price":"0.01", "size":"4150.89", "side":"BUY", "hash":"52c8f062beae9a557c957f815fb00336fa4230c1", "best_bid":"0.01", "best_ask":"0.02"}, {"asset_id":"96888240988495161476033313796107536512663280794332045579302109906525918376981", "price":"0.99", "size":"4150.89", "side":"SELL", "hash":"7448ddfe4e90e6b2e3ff2627ad44e693ac3f9865", "best_bid":"0.98", "best_ask":"0.99"}], "timestamp":"1770241477693", "event_type":"price_change"}
{"market":"0x38f3050258345e9cf363d1c8cc302f08c65b96ba1a4669d81e07ed69708344df", "price_changes":[{"asset_id":"96888240988495161476033313796107536512663280794332045579302109906525918376981", "price":"0.95", "size":"707", "side":"BUY", "hash":"acecbb67faaca5dcf039416a7db153b72ff4b5bc", "best_bid":"0.98", "best_ask":"0.99"}, {"asset_id":"81916206347121459497221114766050949090435061493822476265356047392175668050706", "price":"0.05", "size":"707", "side":"SELL", "hash":"a14333916b4c7e21f565de1858d911b77e6a37f6", "best_bid":"0.01", "best_ask":"0.02"}], "timestamp":"1770241477697", "event_type":"price_change"}
{"market":"0x38f3050258345e9cf363d1c8cc302f08c65b96ba1a4669d81e07ed69708344df", "price_changes":[{"asset_id":"81916206347121459497221114766050949090435061493822476265356047392175668050706", "price":"0.01", "size":"4123.89", "side":"BUY", "hash":"28ecd3dbd3333463f92209f09324bd8acb368f74", "best_bid":"0.01", "best_ask":"0.02"}, {"asset_id":"96888240988495161476033313796107536512663280794332045579302109906525918376981", "price":"0.99", "size":"4123.89", "side":"SELL", "hash":"d7bbcb61b5363b79d205b6c8afcb41db4e001087", "best_bid":"0.98", "best_ask":"0.99"}], "timestamp":"1770241477699", "event_type":"price_change"}
{"market":"0x38f3050258345e9cf363d1c8cc302f08c65b96ba1a4669d81e07ed69708344df", "price_changes":[{"asset_id":"81916206347121459497221114766050949090435061493822476265356047392175668050706", "price":"0.01", "size":"4096.89", "side":"BUY", "hash":"41d5c8e54c41b6ba5c423e697c9440c3f8341dfb", "best_bid":"0.01", "best_ask":"0.02"}, {"asset_id":"96888240988495161476033313796107536512663280794332045579302109906525918376981", "price":"0.99", "size":"4096.89", "side":"SELL", "hash":"d200f87a587309c11dc96095efcceb5185c63fc4", "best_bid":"0.98", "best_ask":"0.99"}], "timestamp":"1770241477703", "event_type":"price_change"}
{"market":"0x38f3050258345e9cf363d1c8cc302f08c65b96ba1a4669d81e07ed69708344df", "price_changes":[{"asset_id":"96888240988495161476033313796107536512663280794332045579302109906525918376981", "price":"0.95", "size":"680", "side":"BUY", "hash":"2a2989b590e17efc41cc84648feebb4e440615e1", "best_bid":"0.98", "best_ask":"0.99"}, {"asset_id":"81916206347121459497221114766050949090435061493822476265356047392175668050706", "price":"0.05", "size":"680", "side":"SELL", "hash":"99f741f73f245ea668c737757db42eb98bb050f3", "best_bid":"0.01", "best_ask":"0.02"}], "timestamp":"1770241477704", "event_type":"price_change"}
{"market":"0x38f3050258345e9cf363d1c8cc302f08c65b96ba1a4669d81e07ed69708344df", "price_changes":[{"asset_id":"81916206347121459497221114766050949090435061493822476265356047392175668050706", "price":"0.01", "size":"4123.89", "side":"BUY", "hash":"28b82e896d57b18ed10896016f9e680d3d9ff4c0", "best_bid":"0.01", "best_ask":"0.02"}, {"asset_id":"96888240988495161476033313796107536512663280794332045579302109906525918376981", "price":"0.99", "size":"4123.89", "side":"SELL", "hash":"e8530bda643cf8ee8e321242c1c7bb61bb6a2466", "best_bid":"0.98", "best_ask":"0.99"}], "timestamp":"1770241477705", "event_type":"price_change"}
{"market":"0x38f3050258345e9cf363d1c8cc302f08c65b96ba1a4669d81e07ed69708344df", "price_changes":[{"asset_id":"96888240988495161476033313796107536512663280794332045579302109906525918376981", "price":"0.96", "size":"702.73", "side":"BUY", "hash":"bf90c12c187864162c853dbc9d4b451f80bd8f58", "best_bid":"0.98", "best_ask":"0.99"}, {"asset_id":"81916206347121459497221114766050949090435061493822476265356047392175668050706", "price":"0.04", "size":"702.73", "side":"SELL", "hash":"5b4db0509d43b9f9617b4e4a2b021fc7dc70e629", "best_bid":"0.01", "best_ask":"0.02"}], "timestamp":"1770241477706", "event_type":"price_change"}
{"market":"0x38f3050258345e9cf363d1c8cc302f08c65b96ba1a4669d81e07ed69708344df", "price_changes":[{"asset_id":"96888240988495161476033313796107536512663280794332045579302109906525918376981", "price":"0.93", "size":"326", "side":"BUY", "hash":"c367ce3e1c7f20e5f71aabc1b5d95090806580a2", "best_bid":"0.98", "best_ask":"0.99"}, {"asset_id":"81916206347121459497221114766050949090435061493822476265356047392175668050706", "price":"0.07", "size":"326", "side":"SELL", "hash":"8935443c02b33c4bbd0160623e25236a7da552e8", "best_bid":"0.01", "best_ask":"0.02"}], "timestamp":"1770241477802", "event_type":"price_change"}
{"market":"0x38f3050258345e9cf363d1c8cc302f08c65b96ba1a4669d81e07ed69708344df", "price_changes":[{"asset_id":"96888240988495161476033313796107536512663280794332045579302109906525918376981", "price":"0.98", "size":"588.97", "side":"BUY", "hash":"142a72c23e1c73625d19ac8b375d7b16dcb7b6ad", "best_bid":"0.98", "best_ask":"0.99"}, {"asset_id":"81916206347121459497221114766050949090435061493822476265356047392175668050706", "price":"0.02", "size":"588.97", "side":"SELL", "hash":"3cb4ca1c8ef4e373e272bde11c950ea526b847ea", "best_bid":"0.01", "best_ask":"0.02"}], "timestamp":"1770241477857", "event_type":"price_change"}
{"market":"0x38f3050258345e9cf363d1c8cc302f08c65b96ba1a4669d81e07ed69708344df", "price_changes":[{"asset_id":"81916206347121459497221114766050949090435061493822476265356047392175668050706", "price":"0.01", "size":"4096.89", "side":"BUY", "hash":"cb7b5c9042466af2639025a0cf74b99f3f9911a2", "best_bid":"0.01", "best_ask":"0.02"}, {"asset_id":"96888240988495161476033313796107536512663280794332045579302109906525918376981", "price":"0.99", "size":"4096.89", "side":"SELL", "hash":"88ec976f9a583dd39e34ef2f4cdce4e6754e31f7", "best_bid":"0.98", "best_ask":"0.99"}], "timestamp":"1770241477884", "event_type":"price_change"}
{"market":"0x38f3050258345e9cf363d1c8cc302f08c65b96ba1a4669d81e07ed69708344df", "price_changes":[{"asset_id":"81916206347121459497221114766050949090435061493822476265356047392175668050706", "price":"0.01", "size":"4069.89", "side":"BUY", "hash":"894d38269fe7c354535cccb79c139cc9a374846a", "best_bid":"0.01", "best_ask":"0.02"}, {"asset_id":"96888240988495161476033313796107536512663280794332045579302109906525918376981", "price":"0.99", "size":"4069.89", "side":"SELL", "hash":"50f3ebc8540c843dd1e0fdbcf67af6a32693e775", "best_bid":"0.98", "best_ask":"0.99"}], "timestamp":"1770241477885", "event_type":"price_change"}
{"market":"0x38f3050258345e9cf363d1c8cc302f08c65b96ba1a4669d81e07ed69708344df", "price_changes":[{"asset_id":"81916206347121459497221114766050949090435061493822476265356047392175668050706", "price":"0.01", "size":"4096.89", "side":"BUY", "hash":"4914af6780164fd31105afc9bfd7c79b451341ad", "best_bid":"0.01", "best_ask":"0.02"}, {"asset_id":"96888240988495161476033313796107536512663280794332045579302109906525918376981", "price":"0.99", "size":"4096.89", "side":"SELL", "hash":"ae6ed30dad42c667737b18c83905c19a06a02778", "best_bid":"0.98", "best_ask":"0.99"}], "timestamp":"1770241477887", "event_type":"price_change"}
{"market":"0x38f3050258345e9cf363d1c8cc302f08c65b96ba1a4669d81e07ed69708344df", "price_changes":[{"asset_id":"96888240988495161476033313796107536512663280794332045579302109906525918376981", "price":"0.96", "size":"729.73", "side":"BUY", "hash":"fe3f51ba9008e37c44effa606b4f996b6b6e57d7", "best_bid":"0.98", "best_ask":"0.99"}, {"asset_id":"81916206347121459497221114766050949090435061493822476265356047392175668050706", "price":"0.04", "size":"729.73", "side":"SELL", "hash":"c8b14377043704ab639fa7d2093487139c7952c9", "best_bid":"0.01", "best_ask":"0.02"}], "timestamp":"1770241477888", "event_type":"price_change"}
{"market":"0x38f3050258345e9cf363d1c8cc302f08c65b96ba1a4669d81e07ed69708344df", "price_changes":[{"asset_id":"96888240988495161476033313796107536512663280794332045579302109906525918376981", "price":"0.95", "size":"653", "side":"BUY", "hash":"d7368a211e405db309c01b3176d78d3362d97cc1", "best_bid":"0.98", "best_ask":"0.99"}, {"asset_id":"81916206347121459497221114766050949090435061493822476265356047392175668050706", "price":"0.05", "size":"653", "side":"SELL", "hash":"8091dc28a32014959c0fac7fe1dd3240c2366cc5", "best_bid":"0.01", "best_ask":"0.02"}], "timestamp":"1770241477890", "event_type":"price_change"}
{"market":"0x38f3050258345e9cf363d1c8cc302f08c65b96ba1a4669d81e07ed69708344df", "price_changes":[{"asset_id":"96888240988495161476033313796107536512663280794332045579302109906525918376981", "price":"0.95", "size":"626", "side":"BUY", "hash":"8893c32cb419efd926b897f728a650355cf7f9a3", "best_bid":"0.98", "best_ask":"0.99"}, {"asset_id":"81916206347121459497221114766050949090435061493822476265356047392175668050706", "price":"0.05", "size":"626", "side":"SELL", "hash":"30c6d50d3e4b38d0ccd1fdf75efb71b95195fbee", "best_bid":"0.01", "best_ask":"0.02"}], "timestamp":"1770241477891", "event_type":"price_change"}
{"market":"0x38f3050258345e9cf363d1c8cc302f08c65b96ba1a4669d81e07ed69708344df", "price_changes":[{"asset_id":"96888240988495161476033313796107536512663280794332045579302109906525918376981", "price":"0.95", "size":"653", "side":"BUY", "hash":"a28ac1e0400c70a03638353b2735825fd207920d", "best_bid":"0.98", "best_ask":"0.99"}, {"asset_id":"81916206347121459497221114766050949090435061493822476265356047392175668050706", "price":"0.05", "size":"653", "side":"SELL", "hash":"1d7c841df68865cd00906973848ca05dc716dd82", "best_bid":"0.01", "best_ask":"0.02"}], "timestamp":"1770241477893", "event_type":"price_change"}
{"market":"0x38f3050258345e9cf363d1c8cc302f08c65b96ba1a4669d81e07ed69708344df", "price_changes":[{"asset_id":"96888240988495161476033313796107536512663280794332045579302109906525918376981", "price":"0.95", "size":"680", "side":"BUY", "hash":"6b69fe7b37689f3c4525f2d54b7e8d7fe38e6b48", "best_bid":"0.98", "best_ask":"0.99"}, {"asset_id":"81916206347121459497221114766050949090435061493822476265356047392175668050706", "price":"0.05", "size":"680", "side":"SELL", "hash":"8613260eb6b630289df952674c0c26e2cf31513c", "best_bid":"0.01", "best_ask":"0.02"}], "timestamp":"1770241477895", "event_type":"price_change"}
{"market":"0x38f3050258345e9cf363d1c8cc302f08c65b96ba1a4669d81e07ed69708344df", "price_changes":[{"asset_id":"96888240988495161476033313796107536512663280794332045579302109906525918376981", "price":"0.96", "size":"702.73", "side":"BUY", "hash":"7070ce00d137758977ef616f57f3513ee35485f1", "best_bid":"0.98", "best_ask":"0.99"}, {"asset_id":"81916206347121459497221114766050949090435061493822476265356047392175668050706", "price":"0.04", "size":"702.73", "side":"SELL", "hash":"e4debc4d5f0b7cd4417baef01042272b64e50e3c", "best_bid":"0.01", "best_ask":"0.02"}], "timestamp":"1770241477896", "event_type":"price_change"}
{"market":"0x38f3050258345e9cf363d1c8cc302f08c65b96ba1a4669d81e07ed69708344df", "price_changes":[{"asset_id":"81916206347121459497221114766050949090435061493822476265356047392175668050706", "price":"0.01", "size":"4069.89", "side":"BUY", "hash":"05d5715e060c8ce2b36e1c76774ae68b4615eb0e", "best_bid":"0.01", "best_ask":"0.02"}, {"asset_id":"96888240988495161476033313796107536512663280794332045579302109906525918376981", "price":"0.99", "size":"4069.89", "side":"SELL", "hash":"cb6cb391a12c32a2b6b79f3106463c4fe2d9e763", "best_bid":"0.98", "best_ask":"0.99"}], "timestamp":"1770241477897", "event_type":"price_change"}
{"market":"0x38f3050258345e9cf363d1c8cc302f08c65b96ba1a4669d81e07ed69708344df", "price_changes":[{"asset_id":"81916206347121459497221114766050949090435061493822476265356047392175668050706", "price":"0.01", "size":"4096.89", "side":"BUY", "hash":"af84a9910a654e1132cf73d0d0aaf68ef49bdce4", "best_bid":"0.01", "best_ask":"0.02"}, {"asset_id":"96888240988495161476033313796107536512663280794332045579302109906525918376981", "price":"0.99", "size":"4096.89", "side":"SELL", "hash":"934b523cc3c93a5e47677e907e80e1dfe3b36300", "best_bid":"0.98", "best_ask":"0.99"}], "timestamp":"1770241477897", "event_type":"price_change"}
{"market":"0x38f3050258345e9cf363d1c8cc302f08c65b96ba1a4669d81e07ed69708344df", "price_changes":[{"asset_id":"81916206347121459497221114766050949090435061493822476265356047392175668050706", "price":"0.01", "size":"4123.89", "side":"BUY", "hash":"93dd5bdd99f3792bdf8ca30fbffdd4aa2eb27274", "best_bid":"0.01", "best_ask":"0.02"}, {"asset_id":"96888240988495161476033313796107536512663280794332045579302109906525918376981", "price":"0.99", "size":"4123.89", "side":"SELL", "hash":"6b5d4df9a5c67bb6ef5f16cc5a2bcc571e02329a", "best_bid":"0.98", "best_ask":"0.99"}], "timestamp":"1770241477898", "event_type":"price_change"}
{"market":"0x38f3050258345e9cf363d1c8cc302f08c65b96ba1a4669d81e07ed69708344df", "price_changes":[{"asset_id":"96888240988495161476033313796107536512663280794332045579302109906525918376981", "price":"0.96", "size":"676.73", "side":"BUY", "hash":"b2c4a5cab14b0b7fe25040eb15ba50d80c51ecab", "best_bid":"0.98", "best_ask":"0.99"}, {"asset_id":"81916206347121459497221114766050949090435061493822476265356047392175668050706", "price":"0.04", "size":"676.73", "side":"SELL", "hash":"0987c479806ec895dcb3e3f9d0d56c65ebb2f6d8", "best_bid":"0.01", "best_ask":"0.02"}], "timestamp":"1770241477946", "event_type":"price_change"}
{"market":"0x38f3050258345e9cf363d1c8cc302f08c65b96ba1a4669d81e07ed69708344df", "price_changes":[{"asset_id":"96888240988495161476033313796107536512663280794332045579302109906525918376981", "price":"0.96", "size":"650.73", "side":"BUY", "hash":"f04d61364c80baaa8404b3315f9a2111ccf3192c", "best_bid":"0.98", "best_ask":"0.99"}, {"asset_id":"81916206347121459497221114766050949090435061493822476265356047392175668050706", "price":"0.04", "size":"650.73", "side":"SELL", "hash":"94c6436e8340bb716a94de55d1be72c14991aefd", "best_bid":"0.01", "best_ask":"0.02"}], "timestamp":"1770241477950", "event_type":"price_change"}
{"market":"0x38f3050258345e9cf363d1c8cc302f08c65b96ba1a4669d81e07ed69708344df", "price_changes":[{"asset_id":"81916206347121459497221114766050949090435061493822476265356047392175668050706", "price":"0.01", "size":"3997.89", "side":"BUY", "hash":"78a216d6066ac243965c9b71e5af6105b93a0b86", "best_bid":"0.01", "best_ask":"0.02"}, {"asset_id":"96888240988495161476033313796107536512663280794332045579302109906525918376981", "price":"0.99", "size":"3997.89", "side":"SELL", "hash":"ff61dc1f2fbffda3fe206c455144cc42aa3d4593", "best_bid":"0.98", "best_ask":"0.99"}], "timestamp":"1770241477982", "event_type":"price_change"}
{"market":"0x38f3050258345e9cf363d1c8cc302f08c65b96ba1a4669d81e07ed69708344df", "asset_id":"81916206347121459497221114766050949090435061493822476265356047392175668050706", "bids":[{"price":"0.01", "size":"3997.89"}], "asks":[{"price":"0.99", "size":"5019.91"}, {"price":"0.98", "size":"3034.23"}, {"price":"0.97", "size":"3172"}, {"price":"0.96", "size":"3012"}, {"price":"0.95", "size":"3032"}, {"price":"0.94", "size":"3012"}, {"price":"0.93", "size":"3126.28"}, {"price":"0.92", "size":"3012"}, {"price":"0.91", "size":"3012"}, {"price":"0.9", "size":"3087"}, {"price":"0.89", "size":"12"}, {"price":"0.88", "size":"12"}, {"price":"0.87", "size":"12"}, {"price":"0.86", "size":"12"}, {"price":"0.85", "size":"12"}, {"price":"0.84", "size":"12"}, {"price":"0.83", "size":"12"}, {"price":"0.82", "size":"12"}, {"price":"0.81", "size":"12"}, {"price":"0.8", "size":"12"}, {"price":"0.79", "size":"12"}, {"price":"0.78", "size":"12"}, {"price":"0.77", "size":"12"}, {"price":"0.76", "size":"112"}, {"price":"0.75", "size":"40.57"}, {"price":"0.74", "size":"12"}, {"price":"0.73", "size":"293.25"}, {"price":"0.72", "size":"22"}, {"price":"0.71", "size":"12"}, {"price":"0.7", "size":"18"}, {"price":"0.69", "size":"12"}, {"price":"0.68", "size":"12"}, {"price":"0.67", "size":"12"}, {"price":"0.66", "size":"160.89"}, {"price":"0.65", "size":"12"}, {"price":"0.64", "size":"12"}, {"price":"0.63", "size":"12"}, {"price":"0.62", "size":"19.39"}, {"price":"0.61", "size":"18.04"}, {"price":"0.6", "size":"12"}, {"price":"0.59", "size":"94.31"}, {"price":"0.58", "size":"5450.54"}, {"price":"0.57", "size":"12"}, {"price":"0.56", "size":"12"}, {"price":"0.55", "size":"12"}, {"price":"0.54", "size":"22"}, {"price":"0.53", "size":"12"}, {"price":"0.52", "size":"12"}, {"price":"0.51", "size":"12"}, {"price":"0.5", "size":"12"}, {"price":"0.49", "size":"12"}, {"price":"0.48", "size":"12"}, {"price":"0.47", "size":"12"}, {"price":"0.46", "size":"485.56"}, {"price":"0.45", "size":"31"}, {"price":"0.44", "size":"17"}, {"price":"0.43", "size":"12"}, {"price":"0.42", "size":"12"}, {"price":"0.41", "size":"12"}, {"price":"0.4", "size":"127"}, {"price":"0.39", "size":"12"}, {"price":"0.38", "size":"94.51"}, {"price":"0.37", "size":"31.99"}, {"price":"0.36", "size":"12"}, {"price":"0.35", "size":"37"}, {"price":"0.34", "size":"12"}, {"price":"0.33", "size":"12"}, {"price":"0.32", "size":"12"}, {"price":"0.31", "size":"12"}, {"price":"0.3", "size":"31.9"}, {"price":"0.29", "size":"344"}, {"price":"0.28", "size":"3288.99"}, {"price":"0.27", "size":"212"}, {"price":"0.26", "size":"218"}, {"price":"0.25", "size":"212"}, {"price":"0.24", "size":"212"}, {"price":"0.23", "size":"212"}, {"price":"0.22", "size":"1723.14"}, {"price":"0.21", "size":"212"}, {"price":"0.2", "size":"272.99"}, {"price":"0.19", "size":"212"}, {"price":"0.18", "size":"212"}, {"price":"0.17", "size":"212"}, {"price":"0.16", "size":"812"}, {"price":"0.15", "size":"231.08"}, {"price":"0.14", "size":"283.65"}, {"price":"0.13", "size":"212"}, {"price":"0.12", "size":"252"}, {"price":"0.11", "size":"252"}, {"price":"0.1", "size":"737.71"}, {"price":"0.09", "size":"261"}, {"price":"0.08", "size":"844.68"}, {"price":"0.07", "size":"326"}, {"price":"0.06", "size":"926"}, {"price":"0.05", "size":"680"}, {"price":"0.04", "size":"650.73"}, {"price":"0.03", "size":"593.32"}, {"price":"0.02", "size":"588.97"}], "hash":"78a216d6066ac243965c9b71e5af6105b93a0b86", "timestamp":"1770241477982", "event_type":"book"}
{"market":"0x38f3050258345e9cf363d1c8cc302f08c65b96ba1a4669d81e07ed69708344df", "price_changes":[{"asset_id":"96888240988495161476033313796107536512663280794332045579302109906525918376981", "price":"0.97", "size":"619.32", "side":"BUY", "hash":"c3949d9a345fab891968612b135610d75844f9e9", "best_bid":"0.98", "best_ask":"0.99"}, {"asset_id":"81916206347121459497221114766050949090435061493822476265356047392175668050706", "price":"0.03", "size":"619.32", "side":"SELL", "hash":"eb8f0ec038e13c4ba385587348a6b3e8b99f8d6e", "best_bid":"0.01", "best_ask":"0.02"}], "timestamp":"1770241478045", "event_type":"price_change"}
{"market":"0x38f3050258345e9cf363d1c8cc302f08c65b96ba1a4669d81e07ed69708344df", "price_changes":[{"asset_id":"96888240988495161476033313796107536512663280794332045579302109906525918376981", "price":"0.97", "size":"645.32", "side":"BUY", "hash":"7f589bcd2fa4d570cee3147e3d4553f27c00c61d", "best_bid":"0.98", "best_ask":"0.99"}, {"asset_id":"81916206347121459497221114766050949090435061493822476265356047392175668050706", "price":"0.03", "size":"645.32", "side":"SELL", "hash":"8c2dc32aa7e9ef43c3e7fd86fcf0acf853b2360a", "best_bid":"0.01", "best_ask":"0.02"}], "timestamp":"1770241478047", "event_type":"price_change"}
{"market":"0x38f3050258345e9cf363d1c8cc302f08c65b96ba1a4669d81e07ed69708344df", "price_changes":[{"asset_id":"81916206347121459497221114766050949090435061493822476265356047392175668050706", "price":"0.01", "size":"3871.89", "side":"BUY", "hash":"9f2da986fca5306795210919df89a91b03e4eccf", "best_bid":"0.01", "best_ask":"0.02"}, {"asset_id":"96888240988495161476033313796107536512663280794332045579302109906525918376981", "price":"0.99", "size":"3871.89", "side":"SELL", "hash":"00e0547dd42b20a4a5509416721a387b5434c579", "best_bid":"0.98", "best_ask":"0.99"}], "timestamp":"1770241478144", "event_type":"price_change"}
{"market":"0x38f3050258345e9cf363d1c8cc302f08c65b96ba1a4669d81e07ed69708344df", "asset_id":"81916206347121459497221114766050949090435061493822476265356047392175668050706", "bids":[{"price":"0.01", "size":"3871.89"}], "asks":[{"price":"0.99", "size":"5019.91"}, {"price":"0.98", "size":"3034.23"}, {"price":"0.97", "size":"3172"}, {"price":"0.96", "size":"3012"}, {"price":"0.95", "size":"3032"}, {"price":"0.94", "size":"3012"}, {"price":"0.93", "size":"3126.28"}, {"price":"0.92", "size":"3012"}, {"price":"0.91", "size":"3012"}, {"price":"0.9", "size":"3087"}, {"price":"0.89", "size":"12"}, {"price":"0.88", "size":"12"}, {"price":"0.87", "size":"12"}, {"price":"0.86", "size":"12"}, {"price":"0.85", "size":"12"}, {"price":"0.84", "size":"12"}, {"price":"0.83", "size":"12"}, {"price":"0.82", "size":"12"}, {"price":"0.81", "size":"12"}, {"price":"0.8", "size":"12"}, {"price":"0.79", "size":"12"}, {"price":"0.78", "size":"12"}, {"price":"0.77", "size":"12"}, {"price":"0.76", "size":"112"}, {"price":"0.75", "size":"40.57"}, {"price":"0.74", "size":"12"}, {"price":"0.73", "size":"293.25"}, {"price":"0.72", "size":"22"}, {"price":"0.71", "size":"12"}, {"price":"0.7", "size":"18"}, {"price":"0.69", "size":"12"}, {"price":"0.68", "size":"12"}, {"price":"0.67", "size":"12"}, {"price":"0.66", "size":"160.89"}, {"price":"0.65", "size":"12"}, {"price":"0.64", "size":"12"}, {"price":"0.63", "size":"12"}, {"price":"0.62", "size":"19.39"}, {"price":"0.61", "size":"18.04"}, {"price":"0.6", "size":"12"}, {"price":"0.59", "size":"94.31"}, {"price":"0.58", "size":"5450.54"}, {"price":"0.57", "size":"12"}, {"price":"0.56", "size":"12"}, {"price":"0.55", "size":"12"}, {"price":"0.54", "size":"22"}, {"price":"0.53", "size":"12"}, {"price":"0.52", "size":"12"}, {"price":"0.51", "size":"12"}, {"price":"0.5", "size":"12"}, {"price":"0.49", "size":"12"}, {"price":"0.48", "size":"12"}, {"price":"0.47", "size":"12"}, {"price":"0.46", "size":"485.56"}, {"price":"0.45", "size":"31"}, {"price":"0.44", "size":"17"}, {"price":"0.43", "size":"12"}, {"price":"0.42", "size":"12"}, {"price":"0.41", "size":"12"}, {"price":"0.4", "size":"127"}, {"price":"0.39", "size":"12"}, {"price":"0.38", "size":"94.51"}, {"price":"0.37", "size":"31.99"}, {"price":"0.36", "size":"12"}, {"price":"0.35", "size":"37"}, {"price":"0.34", "size":"12"}, {"price":"0.33", "size":"12"}, {"price":"0.32", "size":"12"}, {"price":"0.31", "size":"12"}, {"price":"0.3", "size":"31.9"}, {"price":"0.29", "size":"344"}, {"price":"0.28", "size":"3288.99"}, {"price":"0.27", "size":"212"}, {"price":"0.26", "size":"218"}, {"price":"0.25", "size":"212"}, {"price":"0.24", "size":"212"}, {"price":"0.23", "size":"212"}, {"price":"0.22", "size":"1723.14"}, {"price":"0.21", "size":"212"}, {"price":"0.2", "size":"272.99"}, {"price":"0.19", "size":"212"}, {"price":"0.18", "size":"212"}, {"price":"0.17", "size":"212"}, {"price":"0.16", "size":"812"}, {"price":"0.15", "size":"231.08"}, {"price":"0.14", "size":"283.65"}, {"price":"0.13", "size":"212"}, {"price":"0.12", "size":"252"}, {"price":"0.11", "size":"252"}, {"price":"0.1", "size":"737.71"}, {"price":"0.09", "size":"261"}, {"price":"0.08", "size":"844.68"}, {"price":"0.07", "size":"326"}, {"price":"0.06", "size":"926"}, {"price":"0.05", "size":"680"}, {"price":"0.04", "size":"650.73"}, {"price":"0.03", "size":"645.32"}, {"price":"0.02", "size":"588.97"}], "hash":"9f2da986fca5306795210919df89a91b03e4eccf", "timestamp":"1770241478144", "event_type":"book"}
{"market":"0x38f3050258345e9cf363d1c8cc302f08c65b96ba1a4669d81e07ed69708344df", "price_changes":[{"asset_id":"96888240988495161476033313796107536512663280794332045579302109906525918376981", "price":"0.95", "size":"653", "side":"BUY", "hash":"d7e9bb11942a18d4d2b0016b5c9273f46a7b5e49", "best_bid":"0.98", "best_ask":"0.99"}, {"asset_id":"81916206347121459497221114766050949090435061493822476265356047392175668050706", "price":"0.05", "size":"653", "side":"SELL", "hash":"118f782d0480dc3625be26154b9beb2ec1d3b5eb", "best_bid":"0.01", "best_ask":"0.02"}], "timestamp":"1770241478164", "event_type":"price_change"}
{"market":"0x38f3050258345e9cf363d1c8cc302f08c65b96ba1a4669d81e07ed69708344df", "price_changes":[{"asset_id":"81916206347121459497221114766050949090435061493822476265356047392175668050706", "price":"0.01", "size":"3898.89", "side":"BUY", "hash":"27f72a2ffd77436a9be922d15c47750bc19be23a", "best_bid":"0.01", "best_ask":"0.02"}, {"asset_id":"96888240988495161476033313796107536512663280794332045579302109906525918376981", "price":"0.99", "size":"3898.89", "side":"SELL", "hash":"b147ca922e20df721561581d884c0793cd0c0c0c", "best_bid":"0.98", "best_ask":"0.99"}], "timestamp":"1770241478167", "event_type":"price_change"}
{"market":"0x38f3050258345e9cf363d1c8cc302f08c65b96ba1a4669d81e07ed69708344df", "price_changes":[{"asset_id":"81916206347121459497221114766050949090435061493822476265356047392175668050706", "price":"0.01", "size":"3871.89", "side":"BUY", "hash":"9b7c6e5e50d14f12e23e89eaffd53e69c1ed94a7", "best_bid":"0.01", "best_ask":"0.02"}, {"asset_id":"96888240988495161476033313796107536512663280794332045579302109906525918376981", "price":"0.99", "size":"3871.89", "side":"SELL", "hash":"c4445df8641a404ccee8d27701662c56487c9f2d", "best_bid":"0.98", "best_ask":"0.99"}], "timestamp":"1770241478168", "event_type":"price_change"}
{"market":"0x38f3050258345e9cf363d1c8cc302f08c65b96ba1a4669d81e07ed69708344df", "price_changes":[{"asset_id":"96888240988495161476033313796107536512663280794332045579302109906525918376981", "price":"0.96", "size":"677.73", "side":"BUY", "hash":"870dd30a80e1c3d672f5a2661171a8de23acb93f", "best_bid":"0.98", "best_ask":"0.99"}, {"asset_id":"81916206347121459497221114766050949090435061493822476265356047392175668050706", "price":"0.04", "size":"677.73", "side":"SELL", "hash":"f93363e0f6901fcc41b723a5f98e40e8a1291546", "best_bid":"0.01", "best_ask":"0.02"}], "timestamp":"1770241478173", "event_type":"price_change"}
{"market":"0x38f3050258345e9cf363d1c8cc302f08c65b96ba1a4669d81e07ed69708344df", "price_changes":[{"asset_id":"81916206347121459497221114766050949090435061493822476265356047392175668050706", "price":"0.01", "size":"3844.89", "side":"BUY", "hash":"2a9517011548ea4caa72855a8a0d3e5af2a80279", "best_bid":"0.01", "best_ask":"0.02"}, {"asset_id":"96888240988495161476033313796107536512663280794332045579302109906525918376981", "price":"0.99", "size":"3844.89", "side":"SELL", "hash":"776106c5ca30f3fe84ba2307f40e17f540a26577", "best_bid":"0.98", "best_ask":"0.99"}], "timestamp":"1770241478175", "event_type":"price_change"}
{"market":"0x38f3050258345e9cf363d1c8cc302f08c65b96ba1a4669d81e07ed69708344df", "price_changes":[{"asset_id":"96888240988495161476033313796107536512663280794332045579302109906525918376981", "price":"0.95", "size":"626", "side":"BUY", "hash":"bfb271996df19ed111b0f4e3337aa1aa03c82578", "best_bid":"0.98", "best_ask":"0.99"}, {"asset_id":"81916206347121459497221114766050949090435061493822476265356047392175668050706", "price":"0.05", "size":"626", "side":"SELL", "hash":"e435656bfa52a5b5d74a3277b6570500634184e7", "best_bid":"0.01", "best_ask":"0.02"}], "timestamp":"1770241478175", "event_type":"price_change"}
{"market":"0x38f3050258345e9cf363d1c8cc302f08c65b96ba1a4669d81e07ed69708344df", "price_changes":[{"asset_id":"81916206347121459497221114766050949090435061493822476265356047392175668050706", "price":"0.01", "size":"3871.89", "side":"BUY", "hash":"890d2a68a1051a55a4bdb69d6b10c5345cfdbbd9", "best_bid":"0.01", "best_ask":"0.02"}, {"asset_id":"96888240988495161476033313796107536512663280794332045579302109906525918376981", "price":"0.99", "size":"3871.89", "side":"SELL", "hash":"f6d63fd324505c21be862ef33ac71fae5a8ef711", "best_bid":"0.98", "best_ask":"0.99"}], "timestamp":"1770241478177", "event_type":"price_change"}
{"market":"0x38f3050258345e9cf363d1c8cc302f08c65b96ba1a4669d81e07ed69708344df", "price_changes":[{"asset_id":"96888240988495161476033313796107536512663280794332045579302109906525918376981", "price":"0.96", "size":"704.73", "side":"BUY", "hash":"b587fa05cea8ff5069581d2bfc36d3470deb68cb", "best_bid":"0.98", "best_ask":"0.99"}, {"asset_id":"81916206347121459497221114766050949090435061493822476265356047392175668050706", "price":"0.04", "size":"704.73", "side":"SELL", "hash":"3177c6d43facf17b37d3025ae9699dfdb4acfdb4", "best_bid":"0.01", "best_ask":"0.02"}], "timestamp":"1770241478178", "event_type":"price_change"}
{"market":"0x38f3050258345e9cf363d1c8cc302f08c65b96ba1a4669d81e07ed69708344df", "price_changes":[{"asset_id":"81916206347121459497221114766050949090435061493822476265356047392175668050706", "price":"0.01", "size":"3844.89", "side":"BUY", "hash":"fe953b61c8c20ad8478756522db58d1064f81725", "best_bid":"0.01", "best_ask":"0.02"}, {"asset_id":"96888240988495161476033313796107536512663280794332045579302109906525918376981", "price":"0.99", "size":"3844.89", "side":"SELL", "hash":"f32a6a68dabef1b2c1521c3a879e908ae783308c", "best_bid":"0.98", "best_ask":"0.99"}], "timestamp":"1770241478187", "event_type":"price_change"}
{"market":"0x38f3050258345e9cf363d1c8cc302f08c65b96ba1a4669d81e07ed69708344df", "price_changes":[{"asset_id":"96888240988495161476033313796107536512663280794332045579302109906525918376981", "price":"0.96", "size":"677.73", "side":"BUY", "hash":"6f1231e4507d9e2ace099bbb4e82fb18a7371ed2", "best_bid":"0.98", "best_ask":"0.99"}, {"asset_id":"81916206347121459497221114766050949090435061493822476265356047392175668050706", "price":"0.04", "size":"677.73", "side":"SELL", "hash":"05330097b72798a6df3f6ed3b6fd9e2fd41835bf", "best_bid":"0.01", "best_ask":"0.02"}], "timestamp":"1770241478187", "event_type":"price_change"}
{"market":"0x38f3050258345e9cf363d1c8cc302f08c65b96ba1a4669d81e07ed69708344df", "price_changes":[{"asset_id":"96888240988495161476033313796107536512663280794332045579302109906525918376981", "price":"0.97", "size":"672.32", "side":"BUY", "hash":"1ae2907b34b82c890385398159a1710da0b3773e", "best_bid":"0.98", "best_ask":"0.99"}, {"asset_id":"81916206347121459497221114766050949090435061493822476265356047392175668050706", "price":"0.03", "size":"672.32", "side":"SELL", "hash":"0a3000e734d6aaaf4074adec8beb0b6a2017ea0c", "best_bid":"0.01", "best_ask":"0.02"}], "timestamp":"1770241478189", "event_type":"price_change"}
{"market":"0x38f3050258345e9cf363d1c8cc302f08c65b96ba1a4669d81e07ed69708344df", "price_changes":[{"asset_id":"81916206347121459497221114766050949090435061493822476265356047392175668050706", "price":"0.01", "size":"3871.89", "side":"BUY", "hash":"703c285a9751e4b65801dec5aa4742778e96f8ca", "best_bid":"0.01", "best_ask":"0.02"}, {"asset_id":"96888240988495161476033313796107536512663280794332045579302109906525918376981", "price":"0.99", "size":"3871.89", "side":"SELL", "hash":"156e9bed7ae64e3c601cea7e3b259d7edf4a8c0a", "best_bid":"0.98", "best_ask":"0.99"}], "timestamp":"1770241478198", "event_type":"price_change"}
{"market":"0x38f3050258345e9cf363d1c8cc302f08c65b96ba1a4669d81e07ed69708344df", "price_changes":[{"asset_id":"81916206347121459497221114766050949090435061493822476265356047392175668050706", "price":"0.01", "size":"3844.89", "side":"BUY", "hash":"fc2ebeb4cd6424b64adbb138ddb80c3440fcf8f0", "best_bid":"0.01", "best_ask":"0.02"}, {"asset_id":"96888240988495161476033313796107536512663280794332045579302109906525918376981", "price":"0.99", "size":"3844.89", "side":"SELL", "hash":"40d96b59b11ece6cd9173ebb73b5b786cc720a9c", "best_bid":"0.98", "best_ask":"0.99"}], "timestamp":"1770241478284", "event_type":"price_change"}
{"market":"0x38f3050258345e9cf363d1c8cc302f08c65b96ba1a4669d81e07ed69708344df", "price_changes":[{"asset_id":"96888240988495161476033313796107536512663280794332045579302109906525918376981", "price":"0.96", "size":"650.73", "side":"BUY", "hash":"ffbaad7cc2f6034bb4bc8da8204ad938932643b5", "best_bid":"0.98", "best_ask":"0.99"}, {"asset_id":"81916206347121459497221114766050949090435061493822476265356047392175668050706", "price":"0.04", "size":"650.73", "side":"SELL", "hash":"9e1921a2cd1c0ce7f81f99d125e24298e126b422", "best_bid":"0.01", "best_ask":"0.02"}], "timestamp":"1770241478285", "event_type":"price_change"}
{"market":"0x38f3050258345e9cf363d1c8cc302f08c65b96ba1a4669d81e07ed69708344df", "price_changes":[{"asset_id":"81916206347121459497221114766050949090435061493822476265356047392175668050706", "price":"0.01", "size":"3871.89", "side":"BUY", "hash":"592452f033d2cb12c4e7bd51f65f586bc2cb13d9", "best_bid":"0.01", "best_ask":"0.02"}, {"asset_id":"96888240988495161476033313796107536512663280794332045579302109906525918376981", "price":"0.99", "size":"3871.89", "side":"SELL", "hash":"f16c8d712a2b421e3fb27626317c16c496dc86ca", "best_bid":"0.98", "best_ask":"0.99"}], "timestamp":"1770241478287", "event_type":"price_change"}
{"market":"0x38f3050258345e9cf363d1c8cc302f08c65b96ba1a4669d81e07ed69708344df", "price_changes":[{"asset_id":"96888240988495161476033313796107536512663280794332045579302109906525918376981", "price":"0.95", "size":"653", "side":"BUY", "hash":"b1ac35ceb826204163a20c7112fdc37a3b4ffff5", "best_bid":"0.98", "best_ask":"0.99"}, {"asset_id":"81916206347121459497221114766050949090435061493822476265356047392175668050706", "price":"0.05", "size":"653", "side":"SELL", "hash":"32b6905b3171950a6dcfb675edfc74c4e951bd29", "best_bid":"0.01", "best_ask":"0.02"}], "timestamp":"1770241478288", "event_type":"price_change"}
{"market":"0x38f3050258345e9cf363d1c8cc302f08c65b96ba1a4669d81e07ed69708344df", "price_changes":[{"asset_id":"96888240988495161476033313796107536512663280794332045579302109906525918376981", "price":"0.8", "size":"472.99", "side":"BUY", "hash":"f4634992c8ebd22522a21e6360185fa9737f02b8", "best_bid":"0.98", "best_ask":"0.99"}, {"asset_id":"81916206347121459497221114766050949090435061493822476265356047392175668050706", "price":"0.2", "size":"472.99", "side":"SELL", "hash":"c11fb2f5598f72cfcdca5abcdc8936040d680f9c", "best_bid":"0.01", "best_ask":"0.02"}], "timestamp":"1770241478290", "event_type":"price_change"}
{"market":"0x38f3050258345e9cf363d1c8cc302f08c65b96ba1a4669d81e07ed69708344df", "price_changes":[{"asset_id":"81916206347121459497221114766050949090435061493822476265356047392175668050706", "price":"0.01", "size":"3898.89", "side":"BUY", "hash":"97b49e11b7855e5288cf075d4ceceee32f604a68", "best_bid":"0.01", "best_ask":"0.02"}, {"asset_id":"96888240988495161476033313796107536512663280794332045579302109906525918376981", "price":"0.99", "size":"3898.89", "side":"SELL", "hash":"bdf9f3f185356c2aa2832ceb3a31946462778ffd", "best_bid":"0.98", "best_ask":"0.99"}], "timestamp":"1770241478306", "event_type":"price_change"}
{"market":"0x38f3050258345e9cf363d1c8cc302f08c65b96ba1a4669d81e07ed69708344df", "price_changes":[{"asset_id":"96888240988495161476033313796107536512663280794332045579302109906525918376981", "price":"0.96", "size":"623.73", "side":"BUY", "hash":"7a76bf1d31973869733292cf92a6d1b8339b1be8", "best_bid":"0.98", "best_ask":"0.99"}, {"asset_id":"81916206347121459497221114766050949090435061493822476265356047392175668050706", "price":"0.04", "size":"623.73", "side":"SELL", "hash":"c75eddff5828692cccafb6401b401ba97d8e04fc", "best_bid":"0.01", "best_ask":"0.02"}], "timestamp":"1770241478307", "event_type":"price_change"}
{"market":"0x38f3050258345e9cf363d1c8cc302f08c65b96ba1a4669d81e07ed69708344df", "price_changes":[{"asset_id":"81916206347121459497221114766050949090435061493822476265356047392175668050706", "price":"0.01", "size":"3871.89", "side":"BUY", "hash":"62eeeeb92602dc4ba13a6a79655fe9f1a6e664ae", "best_bid":"0.01", "best_ask":"0.02"}, {"asset_id":"96888240988495161476033313796107536512663280794332045579302109906525918376981", "price":"0.99", "size":"3871.89", "side":"SELL", "hash":"eea99a691fde21642177d082f36e60d946923ac7", "best_bid":"0.98", "best_ask":"0.99"}], "timestamp":"1770241478308", "event_type":"price_change"}
{"market":"0x38f3050258345e9cf363d1c8cc302f08c65b96ba1a4669d81e07ed69708344df", "price_changes":[{"asset_id":"96888240988495161476033313796107536512663280794332045579302109906525918376981", "price":"0.95", "size":"680", "side":"BUY", "hash":"6f6a0916a6c94df44af87fb45591c1d551de1bf3", "best_bid":"0.98", "best_ask":"0.99"}, {"asset_id":"81916206347121459497221114766050949090435061493822476265356047392175668050706", "price":"0.05", "size":"680", "side":"SELL", "hash":"e76c1d3bd5830cc676c5a8cd6d48a32720b76a02", "best_bid":"0.01", "best_ask":"0.02"}], "timestamp":"1770241478309", "event_type":"price_change"}
{"market":"0x38f3050258345e9cf363d1c8cc302f08c65b96ba1a4669d81e07ed69708344df", "price_changes":[{"asset_id":"81916206347121459497221114766050949090435061493822476265356047392175668050706", "price":"0.01", "size":"3844.89", "side":"BUY", "hash":"1eb8d545c0e657230f2ad0d07e056f9235c3d870", "best_bid":"0.01", "best_ask":"0.02"}, {"asset_id":"96888240988495161476033313796107536512663280794332045579302109906525918376981", "price":"0.99", "size":"3844.89", "side":"SELL", "hash":"c6bf41fa2d67f50aecc3d75ad3fec7b223e95131", "best_bid":"0.98", "best_ask":"0.99"}], "timestamp":"1770241478310", "event_type":"price_change"}
{"market":"0x38f3050258345e9cf363d1c8cc302f08c65b96ba1a4669d81e07ed69708344df", "price_changes":[{"asset_id":"96888240988495161476033313796107536512663280794332045579302109906525918376981", "price":"0.97", "size":"645.32", "side":"BUY", "hash":"962743adc917b0c4abec18472a7ed6540cf22c14", "best_bid":"0.98", "best_ask":"0.99"}, {"asset_id":"81916206347121459497221114766050949090435061493822476265356047392175668050706", "price":"0.03", "size":"645.32", "side":"SELL", "hash":"e64d7c3ca049ac291b14f51851e5baff19b18b31", "best_bid":"0.01", "best_ask":"0.02"}], "timestamp":"1770241478310", "event_type":"price_change"}
{"market":"0x38f3050258345e9cf363d1c8cc302f08c65b96ba1a4669d81e07ed69708344df", "price_changes":[{"asset_id":"81916206347121459497221114766050949090435061493822476265356047392175668050706", "price":"0.01", "size":"3871.89", "side":"BUY", "hash":"4ba1087bed994cddf25666d329d657558159fd54", "best_bid":"0.01", "best_ask":"0.02"}, {"asset_id":"96888240988495161476033313796107536512663280794332045579302109906525918376981", "price":"0.99", "size":"3871.89", "side":"SELL", "hash":"2801954fff397c2e5d1260cdcbaee744c8bc0c03", "best_bid":"0.98", "best_ask":"0.99"}], "timestamp":"1770241478314", "event_type":"price_change"}
{"market":"0x38f3050258345e9cf363d1c8cc302f08c65b96ba1a4669d81e07ed69708344df", "price_changes":[{"asset_id":"96888240988495161476033313796107536512663280794332045579302109906525918376981", "price":"0.96", "size":"650.73", "side":"BUY", "hash":"416eae284d02f26924bb8ef86baf89642f1c1251", "best_bid":"0.98", "best_ask":"0.99"}, {"asset_id":"81916206347121459497221114766050949090435061493822476265356047392175668050706", "price":"0.04", "size":"650.73", "side":"SELL", "hash":"31a54ecb92a1fb7a3b9cbbc6670cf71e1c99e6f8", "best_bid":"0.01", "best_ask":"0.02"}], "timestamp":"1770241478327", "event_type":"price_change"}
{"market":"0x38f3050258345e9cf363d1c8cc302f08c65b96ba1a4669d81e07ed69708344df", "price_changes":[{"asset_id":"81916206347121459497221114766050949090435061493822476265356047392175668050706", "price":"0.01", "size":"3866.89", "side":"BUY", "hash":"83b1fdcd9be7814fe959e107f5fdddf49f93fa8c", "best_bid":"0.01", "best_ask":"0.02"}, {"asset_id":"96888240988495161476033313796107536512663280794332045579302109906525918376981", "price":"0.99", "size":"3866.89", "side":"SELL", "hash":"eb3cc675e41cf08b3de41dbaeb90046f3d56968b", "best_bid":"0.98", "best_ask":"0.99"}], "timestamp":"1770241478347", "event_type":"price_change"}
