{"market":"0x38f3050258345e9cf363d1c8cc302f08c65b96ba1a4669d81e07ed69708344df", "price_changes":[{"asset_id":"81916206347121459497221114766050949090435061493822476265356047392175668050706", "price":"0.01", "size":"4230.07", "side":"BUY", "hash":"280fe9e0201f918abdb6609ddc8bff205540c804", "best_bid":"0.02", "best_ask":"0.03"}, {"asset_id":"96888240988495161476033313796107536512663280794332045579302109906525918376981", "price":"0.99", "size":"4230.07", "side":"SELL", "hash":"58d91b9aaf2e80b17b16c4c6f836c391af5acef0", "best_bid":"0.97", "best_ask":"0.98"}], "timestamp":"1770241469451", "event_type":"price_change"}
{"market":"0x38f3050258345e9cf363d1c8cc302f08c65b96ba1a4669d81e07ed69708344df", "price_changes":[{"asset_id":"96888240988495161476033313796107536512663280794332045579302109906525918376981", "price":"0.97", "size":"459", "side":"BUY", "hash":"0364a9f1f089ab717745c1cdbef74f56c94f77d7", "best_bid":"0.97", "best_ask":"0.98"}, {"asset_id":"81916206347121459497221114766050949090435061493822476265356047392175668050706", "price":"0.03", "size":"459", "side":"SELL", "hash":"83695ae08258e0ef5ede20bd572301eb2c6c756a", "best_bid":"0.02", "best_ask":"0.03"}], "timestamp":"1770241469452", "event_type":"price_change"}
{"market":"0x38f3050258345e9cf363d1c8cc302f08c65b96ba1a4669d81e07ed69708344df", "price_changes":[{"asset_id":"81916206347121459497221114766050949090435061493822476265356047392175668050706", "price":"0.01", "size":"4257.07", "side":"BUY", "hash":"ce25e6f856a2e2478d1a1f2aed2b93a761a83e33", "best_bid":"0.02", "best_ask":"0.03"}, {"asset_id":"96888240988495161476033313796107536512663280794332045579302109906525918376981", "price":"0.99", "size":"4257.07", "side":"SELL", "hash":"97becd054a13cfb6bda657e133985e96e4392f97", "best_bid":"0.97", "best_ask":"0.98"}], "timestamp":"1770241469452", "event_type":"price_change"}
{"market":"0x38f3050258345e9cf363d1c8cc302f08c65b96ba1a4669d81e07ed69708344df", "price_changes":[{"asset_id":"96888240988495161476033313796107536512663280794332045579302109906525918376981", "price":"0.96", "size":"776.73", "side":"BUY", "hash":"3a1565be624bfaf240d3447f01194bdc3ee23e2e", "best_bid":"0.97", "best_ask":"0.98"}, {"asset_id":"81916206347121459497221114766050949090435061493822476265356047392175668050706", "price":"0.04", "size":"776.73", "side":"SELL", "hash":"52032a898848dc5b596193df85f12d53c3060cb2", "best_bid":"0.02", "best_ask":"0.03"}], "timestamp":"1770241469455", "event_type":"price_change"}
{"market":"0x38f3050258345e9cf363d1c8cc302f08c65b96ba1a4669d81e07ed69708344df", "price_changes":[{"asset_id":"81916206347121459497221114766050949090435061493822476265356047392175668050706", "price":"0.01", "size":"4230.07", "side":"BUY", "hash":"25889891cf83af0d78dcf939eebf17a1b3ce45b0", "best_bid":"0.02", "best_ask":"0.03"}, {"asset_id":"96888240988495161476033313796107536512663280794332045579302109906525918376981", "price":"0.99", "size":"4230.07", "side":"SELL", "hash":"79c6779895259987d69ac7a8fd98631156b5c8f8", "best_bid":"0.97", "best_ask":"0.98"}], "timestamp":"1770241469545", "event_type":"price_change"}
{"market":"0x38f3050258345e9cf363d1c8cc302f08c65b96ba1a4669d81e07ed69708344df", "price_changes":[{"asset_id":"81916206347121459497221114766050949090435061493822476265356047392175668050706", "price":"0.01", "size":"4257.07", "side":"BUY", "hash":"bb07a299ba7a37285e9925c4522999822d7b40ae", "best_bid":"0.02", "best_ask":"0.03"}, {"asset_id":"96888240988495161476033313796107536512663280794332045579302109906525918376981", "price":"0.99", "size":"4257.07", "side":"SELL", "hash":"1062cc53e2b40533a8316c7d5d1f9ed97ff1e2c0", "best_bid":"0.97", "best_ask":"0.98"}], "timestamp":"1770241469546", "event_type":"price_change"}
{"market":"0x38f3050258345e9cf363d1c8cc302f08c65b96ba1a4669d81e07ed69708344df", "price_changes":[{"asset_id":"96888240988495161476033313796107536512663280794332045579302109906525918376981", "price":"0.95", "size":"650", "side":"BUY", "hash":"2e26b92effb969950267a688defb97c1ca580319", "best_bid":"0.97", "best_ask":"0.98"}, {"asset_id":"81916206347121459497221114766050949090435061493822476265356047392175668050706", "price":"0.05", "size":"650", "side":"SELL", "hash":"17c054fbd7d4ecd833f0d93c9df23b7b53677565", "best_bid":"0.02", "best_ask":"0.03"}], "timestamp":"1770241469546", "event_type":"price_change"}
{"market":"0x38f3050258345e9cf363d1c8cc302f08c65b96ba1a4669d81e07ed69708344df", "price_changes":[{"asset_id":"81916206347121459497221114766050949090435061493822476265356047392175668050706", "price":"0.01", "size":"4230.07", "side":"BUY", "hash":"291f6141073e84af7190cac87fef4a456318a282", "best_bid":"0.02", "best_ask":"0.03"}, {"asset_id":"96888240988495161476033313796107536512663280794332045579302109906525918376981", "price":"0.99", "size":"4230.07", "side":"SELL", "hash":"58856ade08bf2beda32ea166e4b6ae4b0ebb985c", "best_bid":"0.97", "best_ask":"0.98"}], "timestamp":"1770241469547", "event_type":"price_change"}
{"market":"0x38f3050258345e9cf363d1c8cc302f08c65b96ba1a4669d81e07ed69708344df", "price_changes":[{"asset_id":"96888240988495161476033313796107536512663280794332045579302109906525918376981", "price":"0.95", "size":"623", "side":"BUY", "hash":"970fd45d6a0cdbd047aa7abf8b2dcd712ae4b178", "best_bid":"0.97", "best_ask":"0.98"}, {"asset_id":"81916206347121459497221114766050949090435061493822476265356047392175668050706", "price":"0.05", "size":"623", "side":"SELL", "hash":"b0bfb91c792c1d62c299ce99b49323909b6def26", "best_bid":"0.02", "best_ask":"0.03"}], "timestamp":"1770241469547", "event_type":"price_change"}
{"market":"0x38f3050258345e9cf363d1c8cc302f08c65b96ba1a4669d81e07ed69708344df", "price_changes":[{"asset_id":"81916206347121459497221114766050949090435061493822476265356047392175668050706", "price":"0.01", "size":"4257.07", "side":"BUY", "hash":"63a1dec43214f2ad144832e3179737d1e4adaea7", "best_bid":"0.02", "best_ask":"0.03"}, {"asset_id":"96888240988495161476033313796107536512663280794332045579302109906525918376981", "price":"0.99", "size":"4257.07", "side":"SELL", "hash":"887cb201e24e022ea56d07e0b4f8f52e870be8d6", "best_bid":"0.97", "best_ask":"0.98"}], "timestamp":"1770241469548", "event_type":"price_change"}
{"market":"0x38f3050258345e9cf363d1c8cc302f08c65b96ba1a4669d81e07ed69708344df", "price_changes":[{"asset_id":"96888240988495161476033313796107536512663280794332045579302109906525918376981", "price":"0.95", "size":"650", "side":"BUY", "hash":"bb0addfbfec8ca6562b346307722a7282fd3644e", "best_bid":"0.97", "best_ask":"0.98"}, {"asset_id":"81916206347121459497221114766050949090435061493822476265356047392175668050706", "price":"0.05", "size":"650", "side":"SELL", "hash":"271b642e51f0aa80697dc87da2152e7c603fdaad", "best_bid":"0.02", "best_ask":"0.03"}], "timestamp":"1770241469550", "event_type":"price_change"}
{"market":"0x38f3050258345e9cf363d1c8cc302f08c65b96ba1a4669d81e07ed69708344df", "price_changes":[{"asset_id":"96888240988495161476033313796107536512663280794332045579302109906525918376981", "price":"0.95", "size":"677", "side":"BUY", "hash":"8a060eb85d76d964faedf70609cbf7b871a4789b", "best_bid":"0.97", "best_ask":"0.98"}, {"asset_id":"81916206347121459497221114766050949090435061493822476265356047392175668050706", "price":"0.05", "size":"677", "side":"SELL", "hash":"8bfef64edef7a30e560faa0b60d571ff43a6ae77", "best_bid":"0.02", "best_ask":"0.03"}], "timestamp":"1770241469552", "event_type":"price_change"}
{"market":"0x38f3050258345e9cf363d1c8cc302f08c65b96ba1a4669d81e07ed69708344df", "price_changes":[{"asset_id":"96888240988495161476033313796107536512663280794332045579302109906525918376981", "price":"0.96", "size":"803.73", "side":"BUY", "hash":"199130a305d6d298ce5739cff0f2f9783ad4dda3", "best_bid":"0.97", "best_ask":"0.98"}, {"asset_id":"81916206347121459497221114766050949090435061493822476265356047392175668050706", "price":"0.04", "size":"803.73", "side":"SELL", "hash":"fc8f6e64141e5635de2ab30c94169b9243c03eae", "best_bid":"0.02", "best_ask":"0.03"}], "timestamp":"1770241469570", "event_type":"price_change"}
{"market":"0x38f3050258345e9cf363d1c8cc302f08c65b96ba1a4669d81e07ed69708344df", "price_changes":[{"asset_id":"81916206347121459497221114766050949090435061493822476265356047392175668050706", "price":"0.01", "size":"4230.07", "side":"BUY", "hash":"22483952da90b6431192463cffbf11cf962ec8eb", "best_bid":"0.02", "best_ask":"0.03"}, {"asset_id":"96888240988495161476033313796107536512663280794332045579302109906525918376981", "price":"0.99", "size":"4230.07", "side":"SELL", "hash":"7cb2b217bdb798a9799a37d6dadf36d6ac03bd3c", "best_bid":"0.97", "best_ask":"0.98"}], "timestamp":"1770241469570", "event_type":"price_change"}
{"market":"0x38f3050258345e9cf363d1c8cc302f08c65b96ba1a4669d81e07ed69708344df", "price_changes":[{"asset_id":"81916206347121459497221114766050949090435061493822476265356047392175668050706", "price":"0.01", "size":"4257.07", "side":"BUY", "hash":"cbe73663185a20d2b0825131e9edaa92f9b39a0f", "best_bid":"0.02", "best_ask":"0.03"}, {"asset_id":"96888240988495161476033313796107536512663280794332045579302109906525918376981", "price":"0.99", "size":"4257.07", "side":"SELL", "hash":"9d5c93fba23689a0e0087e928799fb185a678667", "best_bid":"0.97", "best_ask":"0.98"}], "timestamp":"1770241469571", "event_type":"price_change"}
{"market":"0x38f3050258345e9cf363d1c8cc302f08c65b96ba1a4669d81e07ed69708344df", "price_changes":[{"asset_id":"96888240988495161476033313796107536512663280794332045579302109906525918376981", "price":"0.97", "size":"432", "side":"BUY", "hash":"c765620c61d7d6fe9fd6f631fc6cd3abc080b579", "best_bid":"0.97", "best_ask":"0.98"}, {"asset_id":"81916206347121459497221114766050949090435061493822476265356047392175668050706", "price":"0.03", "size":"432", "side":"SELL", "hash":"54e492196989fe7d13d62977a029173f7dc3d164", "best_bid":"0.02", "best_ask":"0.03"}], "timestamp":"1770241469574", "event_type":"price_change"}
{"market":"0x38f3050258345e9cf363d1c8cc302f08c65b96ba1a4669d81e07ed69708344df", "price_changes":[{"asset_id":"96888240988495161476033313796107536512663280794332045579302109906525918376981", "price":"0.96", "size":"823.73", "side":"BUY", "hash":"cb068d55c282c4f949bba7b809bae2f5e65c15b9", "best_bid":"0.97", "best_ask":"0.98"}, {"asset_id":"81916206347121459497221114766050949090435061493822476265356047392175668050706", "price":"0.04", "size":"823.73", "side":"SELL", "hash":"09977da4b2702cf1cee748bd9ab7c57cf62ae60e", "best_bid":"0.02", "best_ask":"0.03"}], "timestamp":"1770241469584", "event_type":"price_change"}
{"market":"0x38f3050258345e9cf363d1c8cc302f08c65b96ba1a4669d81e07ed69708344df", "price_changes":[{"asset_id":"96888240988495161476033313796107536512663280794332045579302109906525918376981", "price":"0.94", "size":"753", "side":"BUY", "hash":"09b80eee6550085f9c1f5e27e2a4e4cfed575e26", "best_bid":"0.97", "best_ask":"0.98"}, {"asset_id":"81916206347121459497221114766050949090435061493822476265356047392175668050706", "price":"0.06", "size":"753", "side":"SELL", "hash":"5efadb820804e10d76113ee34b3b212fda5e6840", "best_bid":"0.02", "best_ask":"0.03"}], "timestamp":"1770241469665", "event_type":"price_change"}
{"market":"0x38f3050258345e9cf363d1c8cc302f08c65b96ba1a4669d81e07ed69708344df", "price_changes":[{"asset_id":"96888240988495161476033313796107536512663280794332045579302109906525918376981", "price":"0.95", "size":"650", "side":"BUY", "hash":"2e7190619d1e6859919fdbdd66e84487e52e0009", "best_bid":"0.97", "best_ask":"0.98"}, {"asset_id":"81916206347121459497221114766050949090435061493822476265356047392175668050706", "price":"0.05", "size":"650", "side":"SELL", "hash":"ffb973fc3b73153d70936afcb365a12816b62d66", "best_bid":"0.02", "best_ask":"0.03"}], "timestamp":"1770241469665", "event_type":"price_change"}
{"market":"0x38f3050258345e9cf363d1c8cc302f08c65b96ba1a4669d81e07ed69708344df", "price_changes":[{"asset_id":"96888240988495161476033313796107536512663280794332045579302109906525918376981", "price":"0.94", "size":"780", "side":"BUY", "hash":"353c5c6892e519ce2d7a1ff5d180e0565a18a34f", "best_bid":"0.97", "best_ask":"0.98"}, {"asset_id":"81916206347121459497221114766050949090435061493822476265356047392175668050706", "price":"0.06", "size":"780", "side":"SELL", "hash":"1e70246e7ea0ed36912f22d8e825fcbd9f1e8177", "best_bid":"0.02", "best_ask":"0.03"}], "timestamp":"1770241469682", "event_type":"price_change"}
{"market":"0x38f3050258345e9cf363d1c8cc302f08c65b96ba1a4669d81e07ed69708344df", "price_changes":[{"asset_id":"96888240988495161476033313796107536512663280794332045579302109906525918376981", "price":"0.95", "size":"623", "side":"BUY", "hash":"3525329b0f90e30d76fb9e54b7792dcbd854e124", "best_bid":"0.97", "best_ask":"0.98"}, {"asset_id":"81916206347121459497221114766050949090435061493822476265356047392175668050706", "price":"0.05", "size":"623", "side":"SELL", "hash":"efcfd2389cb7924e2dc72728791b132e568491d4", "best_bid":"0.02", "best_ask":"0.03"}], "timestamp":"1770241469682", "event_type":"price_change"}
{"market":"0x38f3050258345e9cf363d1c8cc302f08c65b96ba1a4669d81e07ed69708344df", "price_changes":[{"asset_id":"81916206347121459497221114766050949090435061493822476265356047392175668050706", "price":"0.02", "size":"481.48", "side":"BUY", "hash":"10e8f74a5d220734e69a4c7dd6154101048608b1", "best_bid":"0.02", "best_ask":"0.03"}, {"asset_id":"96888240988495161476033313796107536512663280794332045579302109906525918376981", "price":"0.98", "size":"481.48", "side":"SELL", "hash":"723a5415b79ad8e22e8dcb903b7b3f90e3b253aa", "best_bid":"0.97", "best_ask":"0.98"}], "timestamp":"1770241469737", "event_type":"price_change"}
{"market":"0x38f3050258345e9cf363d1c8cc302f08c65b96ba1a4669d81e07ed69708344df", "price_changes":[{"asset_id":"81916206347121459497221114766050949090435061493822476265356047392175668050706", "price":"0.01", "size":"4234.07", "side":"BUY", "hash":"49c9db1d3766b7bd7c7c2e564dffe6494106477f", "best_bid":"0.02", "best_ask":"0.03"}, {"asset_id":"96888240988495161476033313796107536512663280794332045579302109906525918376981", "price":"0.99", "size":"4234.07", "side":"SELL", "hash":"fb11d3e6abd6cb6d4f7de8e4634b3c223ec34743", "best_bid":"0.97", "best_ask":"0.98"}], "timestamp":"1770241469740", "event_type":"price_change"}
{"market":"0x38f3050258345e9cf363d1c8cc302f08c65b96ba1a4669d81e07ed69708344df", "price_changes":[{"asset_id":"96888240988495161476033313796107536512663280794332045579302109906525918376981", "price":"0.98", "size":"479.98", "side":"SELL", "hash":"8d6139653e9f4fb43715bf552cebe3a67934ffef", "best_bid":"0.97", "best_ask":"0.98"}, {"asset_id":"81916206347121459497221114766050949090435061493822476265356047392175668050706", "price":"0.02", "size":"479.98", "side":"BUY", "hash":"bcd9c20c0ed5c67000f2a30a93b95ad00d28b173", "best_bid":"0.02", "best_ask":"0.03"}], "timestamp":"1770241469808", "event_type":"price_change"}
{"market":"0x38f3050258345e9cf363d1c8cc302f08c65b96ba1a4669d81e07ed69708344df", "asset_id":"81916206347121459497221114766050949090435061493822476265356047392175668050706", "bids":[{"price":"0.01", "size":"4234.07"}, {"price":"0.02", "size":"479.98"}], "asks":[{"price":"0.99", "size":"5019.91"}, {"price":"0.98", "size":"3034.23"}, {"price":"0.97", "size":"3172"}, {"price":"0.96", "size":"3012"}, {"price":"0.95", "size":"3032"}, {"price":"0.94", "size":"3012"}, {"price":"0.93", "size":"3126.28"}, {"price":"0.92", "size":"3012"}, {"price":"0.91", "size":"3012"}, {"price":"0.9", "size":"3087"}, {"price":"0.89", "size":"12"}, {"price":"0.88", "size":"12"}, {"price":"0.87", "size":"12"}, {"price":"0.86", "size":"12"}, {"price":"0.85", "size":"12"}, {"price":"0.84", "size":"12"}, {"price":"0.83", "size":"12"}, {"price":"0.82", "size":"12"}, {"price":"0.81", "size":"12"}, {"price":"0.8", "size":"12"}, {"price":"0.79", "size":"12"}, {"price":"0.78", "size":"12"}, {"price":"0.77", "size":"12"}, {"price":"0.76", "size":"112"}, {"price":"0.75", "size":"40.57"}, {"price":"0.74", "size":"12"}, {"price":"0.73", "size":"293.25"}, {"price":"0.72", "size":"22"}, {"price":"0.71", "size":"12"}, {"price":"0.7", "size":"18"}, {"price":"0.69", "size":"12"}, {"price":"0.68", "size":"12"}, {"price":"0.67", "size":"12"}, {"price":"0.66", "size":"160.89"}, {"price":"0.65", "size":"12"}, {"price":"0.64", "size":"12"}, {"price":"0.63", "size":"12"}, {"price":"0.62", "size":"19.39"}, {"price":"0.61", "size":"18.04"}, {"price":"0.6", "size":"12"}, {"price":"0.59", "size":"94.31"}, {"price":"0.58", "size":"5450.54"}, {"price":"0.57", "size":"12"}, {"price":"0.56", "size":"12"}, {"price":"0.55", "size":"12"}, {"price":"0.54", "size":"22"}, {"price":"0.53", "size":"12"}, {"price":"0.52", "size":"12"}, {"price":"0.51", "size":"12"}, {"price":"0.5", "size":"12"}, {"price":"0.49", "size":"12"}, {"price":"0.48", "size":"12"}, {"price":"0.47", "size":"12"}, {"price":"0.46", "size":"485.56"}, {"price":"0.45", "size":"31"}, {"price":"0.44", "size":"17"}, {"price":"0.43", "size":"12"}, {"price":"0.42", "size":"12"}, {"price":"0.41", "size":"12"}, {"price":"0.4", "size":"127"}, {"price":"0.39", "size":"12"}, {"price":"0.38", "size":"94.51"}, {"price":"0.37", "size":"31.99"}, {"price":"0.36", "size":"12"}, {"price":"0.35", "size":"37"}, {"price":"0.34", "size":"12"}, {"price":"0.33", "size":"12"}, {"price":"0.32", "size":"12"}, {"price":"0.31", "size":"12"}, {"price":"0.3", "size":"31.9"}, {"price":"0.29", "size":"344"}, {"price":"0.28", "size":"3488.99"}, {"price":"0.27", "size":"212"}, {"price":"0.26", "size":"218"}, {"price":"0.25", "size":"712"}, {"price":"0.24", "size":"412"}, {"price":"0.23", "size":"212"}, {"price":"0.22", "size":"1223.14"}, {"price":"0.21", "size":"212"}, {"price":"0.2", "size":"272.99"}, {"price":"0.19", "size":"212"}, {"price":"0.18", "size":"212"}, {"price":"0.17", "size":"212"}, {"price":"0.16", "size":"812"}, {"price":"0.15", "size":"231.08"}, {"price":"0.14", "size":"283.65"}, {"price":"0.13", "size":"212"}, {"price":"0.12", "size":"252"}, {"price":"0.11", "size":"252"}, {"price":"0.1", "size":"746.71"}, {"price":"0.09", "size":"326"}, {"price":"0.08", "size":"844.68"}, {"price":"0.07", "size":"826"}, {"price":"0.06", "size":"780"}, {"price":"0.05", "size":"623"}, {"price":"0.04", "size":"823.73"}, {"price":"0.03", "size":"432"}], "hash":"bcd9c20c0ed5c67000f2a30a93b95ad00d28b173", "timestamp":"1770241469808", "event_type":"book"}
{"market":"0x38f3050258345e9cf363d1c8cc302f08c65b96ba1a4669d81e07ed69708344df", "price_changes":[{"asset_id":"81916206347121459497221114766050949090435061493822476265356047392175668050706", "price":"0.02", "size":"456.98", "side":"BUY", "hash":"69244b52e6051953e4f8b578d2fb2bb3b4846cf9", "best_bid":"0.02", "best_ask":"0.03"}, {"asset_id":"96888240988495161476033313796107536512663280794332045579302109906525918376981", "price":"0.98", "size":"456.98", "side":"SELL", "hash":"407a667fc4d3b0d0d4e9c2e875a5e19abc0f8a63", "best_bid":"0.97", "best_ask":"0.98"}], "timestamp":"1770241469989", "event_type":"price_change"}
{"market":"0x38f3050258345e9cf363d1c8cc302f08c65b96ba1a4669d81e07ed69708344df", "price_changes":[{"asset_id":"81916206347121459497221114766050949090435061493822476265356047392175668050706", "price":"0.01", "size":"4257.07", "side":"BUY", "hash":"c58bf0b1879dbc46d933b4ceecbf2e1fcde8e2de", "best_bid":"0.02", "best_ask":"0.03"}, {"asset_id":"96888240988495161476033313796107536512663280794332045579302109906525918376981", "price":"0.99", "size":"4257.07", "side":"SELL", "hash":"446e5a3eb12fdfb8fc3fc8fb43f939a23dcbda1b", "best_bid":"0.97", "best_ask":"0.98"}], "timestamp":"1770241469991", "event_type":"price_change"}
{"market":"0x38f3050258345e9cf363d1c8cc302f08c65b96ba1a4669d81e07ed69708344df", "price_changes":[{"asset_id":"81916206347121459497221114766050949090435061493822476265356047392175668050706", "price":"0.01", "size":"4230.07", "side":"BUY", "hash":"c495f5f8976fde06ba154134ee5c6d2e691f8e10", "best_bid":"0.02", "best_ask":"0.03"}, {"asset_id":"96888240988495161476033313796107536512663280794332045579302109906525918376981", "price":"0.99", "size":"4230.07", "side":"SELL", "hash":"c6fce265f0055a55c241b5576e168c0831407662", "best_bid":"0.97", "best_ask":"0.98"}], "timestamp":"1770241470078", "event_type":"price_change"}
{"market":"0x38f3050258345e9cf363d1c8cc302f08c65b96ba1a4669d81e07ed69708344df", "price_changes":[{"asset_id":"81916206347121459497221114766050949090435061493822476265356047392175668050706", "price":"0.01", "size":"4257.07", "side":"BUY", "hash":"d01fafdb5b2cd58416eb29ec14c5bcb0e93f48b5", "best_bid":"0.02", "best_ask":"0.03"}, {"asset_id":"96888240988495161476033313796107536512663280794332045579302109906525918376981", "price":"0.99", "size":"4257.07", "side":"SELL", "hash":"516d0f77685b5563a54565ca1f15dd276f41d574", "best_bid":"0.97", "best_ask":"0.98"}], "timestamp":"1770241470078", "event_type":"price_change"}
{"market":"0x38f3050258345e9cf363d1c8cc302f08c65b96ba1a4669d81e07ed69708344df", "price_changes":[{"asset_id":"96888240988495161476033313796107536512663280794332045579302109906525918376981", "price":"0.94", "size":"753", "side":"BUY", "hash":"7d86f0181e9e18bfb8bfea43bcd29037dc019c2e", "best_bid":"0.97", "best_ask":"0.98"}, {"asset_id":"81916206347121459497221114766050949090435061493822476265356047392175668050706", "price":"0.06", "size":"753", "side":"SELL", "hash":"62ce051edf234f5738ab2a0e1afd1fd609f79c41", "best_bid":"0.02", "best_ask":"0.03"}], "timestamp":"1770241470079", "event_type":"price_change"}
{"market":"0x38f3050258345e9cf363d1c8cc302f08c65b96ba1a4669d81e07ed69708344df", "price_changes":[{"asset_id":"96888240988495161476033313796107536512663280794332045579302109906525918376981", "price":"0.95", "size":"650", "side":"BUY", "hash":"6225712fbe89424cce0282864092372cd361b9a9", "best_bid":"0.97", "best_ask":"0.98"}, {"asset_id":"81916206347121459497221114766050949090435061493822476265356047392175668050706", "price":"0.05", "size":"650", "side":"SELL", "hash":"08db67eb85adb2a0f4a3ab2dbc68fa8a8ad3aebc", "best_bid":"0.02", "best_ask":"0.03"}], "timestamp":"1770241470081", "event_type":"price_change"}
{"market":"0x38f3050258345e9cf363d1c8cc302f08c65b96ba1a4669d81e07ed69708344df", "price_changes":[{"asset_id":"81916206347121459497221114766050949090435061493822476265356047392175668050706", "price":"0.01", "size":"4284.07", "side":"BUY", "hash":"f40136b1e1c10a04797d41e23f0afa49399955f9", "best_bid":"0.02", "best_ask":"0.03"}, {"asset_id":"96888240988495161476033313796107536512663280794332045579302109906525918376981", "price":"0.99", "size":"4284.07", "side":"SELL", "hash":"7f35406903c751156c2fd86232b89fc0c26342eb", "best_bid":"0.97", "best_ask":"0.98"}], "timestamp":"1770241470088", "event_type":"price_change"}
{"market":"0x38f3050258345e9cf363d1c8cc302f08c65b96ba1a4669d81e07ed69708344df", "price_changes":[{"asset_id":"81916206347121459497221114766050949090435061493822476265356047392175668050706", "price":"0.01", "size":"4257.07", "side":"BUY", "hash":"129b608ddc211e7587f408b85309e77c792c40f7", "best_bid":"0.02", "best_ask":"0.03"}, {"asset_id":"96888240988495161476033313796107536512663280794332045579302109906525918376981", "price":"0.99", "size":"4257.07", "side":"SELL", "hash":"f3a4dbcf829398dd7e368b45f938f5ca0776d7db", "best_bid":"0.97", "best_ask":"0.98"}], "timestamp":"1770241470089", "event_type":"price_change"}
{"market":"0x38f3050258345e9cf363d1c8cc302f08c65b96ba1a4669d81e07ed69708344df", "price_changes":[{"asset_id":"96888240988495161476033313796107536512663280794332045579302109906525918376981", "price":"0.94", "size":"726", "side":"BUY", "hash":"a161351689cdc78836d3fe1b188ea5bbf8ecd618", "best_bid":"0.97", "best_ask":"0.98"}, {"asset_id":"81916206347121459497221114766050949090435061493822476265356047392175668050706", "price":"0.06", "size":"726", "side":"SELL", "hash":"4b97f7d04c64d0aaffe3eca8b30b1a353bd34160", "best_bid":"0.02", "best_ask":"0.03"}], "timestamp":"1770241470089", "event_type":"price_change"}
{"market":"0x38f3050258345e9cf363d1c8cc302f08c65b96ba1a4669d81e07ed69708344df", "price_changes":[{"asset_id":"96888240988495161476033313796107536512663280794332045579302109906525918376981", "price":"0.95", "size":"677", "side":"BUY", "hash":"d0ca95d03c55758acb62273f2e61ef52ff72258b", "best_bid":"0.97", "best_ask":"0.98"}, {"asset_id":"81916206347121459497221114766050949090435061493822476265356047392175668050706", "price":"0.05", "size":"677", "side":"SELL", "hash":"d7e24985b746fae76c9fa60a3a0ea20815af89e2", "best_bid":"0.02", "best_ask":"0.03"}], "timestamp":"1770241470092", "event_type":"price_change"}
{"market":"0x38f3050258345e9cf363d1c8cc302f08c65b96ba1a4669d81e07ed69708344df", "price_changes":[{"asset_id":"96888240988495161476033313796107536512663280794332045579302109906525918376981", "price":"0.96", "size":"796.73", "side":"BUY", "hash":"d40ca3afab57cb957c26fc093311edce2ecfdc30", "best_bid":"0.97", "best_ask":"0.98"}, {"asset_id":"81916206347121459497221114766050949090435061493822476265356047392175668050706", "price":"0.04", "size":"796.73", "side":"SELL", "hash":"e3a6b71288269adf54d96804b8cffecd822da824", "best_bid":"0.02", "best_ask":"0.03"}], "timestamp":"1770241470097", "event_type":"price_change"}
{"market":"0x38f3050258345e9cf363d1c8cc302f08c65b96ba1a4669d81e07ed69708344df", "price_changes":[{"asset_id":"81916206347121459497221114766050949090435061493822476265356047392175668050706", "price":"0.01", "size":"4284.07", "side":"BUY", "hash":"189d496ab751dfe6837bab02de3021b88f9557d5", "best_bid":"0.02", "best_ask":"0.03"}, {"asset_id":"96888240988495161476033313796107536512663280794332045579302109906525918376981", "price":"0.99", "size":"4284.07", "side":"SELL", "hash":"41b36e634ed8a1ecf6a7d8a9dbd1362dccd80cb6", "best_bid":"0.97", "best_ask":"0.98"}], "timestamp":"1770241470098", "event_type":"price_change"}
{"market":"0x38f3050258345e9cf363d1c8cc302f08c65b96ba1a4669d81e07ed69708344df", "price_changes":[{"asset_id":"96888240988495161476033313796107536512663280794332045579302109906525918376981", "price":"0.97", "size":"459", "side":"BUY", "hash":"23ae4db47cf32900f292afb5e5e66769d5278ff9", "best_bid":"0.97", "best_ask":"0.98"}, {"asset_id":"81916206347121459497221114766050949090435061493822476265356047392175668050706", "price":"0.03", "size":"459", "side":"SELL", "hash":"9e6853fd755e1b77b06e314dd2dd1864ae848e3b", "best_bid":"0.02", "best_ask":"0.03"}], "timestamp":"1770241470099", "event_type":"price_change"}
{"market":"0x38f3050258345e9cf363d1c8cc302f08c65b96ba1a4669d81e07ed69708344df", "price_changes":[{"asset_id":"81916206347121459497221114766050949090435061493822476265356047392175668050706", "price":"0.01", "size":"4257.07", "side":"BUY", "hash":"dfb52124f36ef2f75ae64060b4e368bf0d034cd3", "best_bid":"0.02", "best_ask":"0.03"}, {"asset_id":"96888240988495161476033313796107536512663280794332045579302109906525918376981", "price":"0.99", "size":"4257.07", "side":"SELL", "hash":"73aeeeae876e5302b4210ab0fe141c5d433fec0c", "best_bid":"0.97", "best_ask":"0.98"}], "timestamp":"1770241470100", "event_type":"price_change"}
{"market":"0x38f3050258345e9cf363d1c8cc302f08c65b96ba1a4669d81e07ed69708344df", "price_changes":[{"asset_id":"96888240988495161476033313796107536512663280794332045579302109906525918376981", "price":"0.97", "size":"432", "side":"BUY", "hash":"a4f79b0af26740b4bef52cb3dd08ebda02b4fef9", "best_bid":"0.97", "best_ask":"0.98"}, {"asset_id":"81916206347121459497221114766050949090435061493822476265356047392175668050706", "price":"0.03", "size":"432", "side":"SELL", "hash":"1e2c92463ae9d64c8c311bb69676365e285fd8e6", "best_bid":"0.02", "best_ask":"0.03"}], "timestamp":"1770241470449", "event_type":"price_change"}
{"market":"0x38f3050258345e9cf363d1c8cc302f08c65b96ba1a4669d81e07ed69708344df", "price_changes":[{"asset_id":"96888240988495161476033313796107536512663280794332045579302109906525918376981", "price":"0.96", "size":"823.73", "side":"BUY", "hash":"27d5eec473c929853b544cdc027be4aa83e5cc6a", "best_bid":"0.97", "best_ask":"0.98"}, {"asset_id":"81916206347121459497221114766050949090435061493822476265356047392175668050706", "price":"0.04", "size":"823.73", "side":"SELL", "hash":"b1c36414609ff9bdfdc4fbf6d0785243fb03c1c9", "best_bid":"0.02", "best_ask":"0.03"}], "timestamp":"1770241470450", "event_type":"price_change"}
{"market":"0x38f3050258345e9cf363d1c8cc302f08c65b96ba1a4669d81e07ed69708344df", "price_changes":[{"asset_id":"81916206347121459497221114766050949090435061493822476265356047392175668050706", "price":"0.01", "size":"4230.07", "side":"BUY", "hash":"d7eddce47dd23027f94a944e9033892d47852068", "best_bid":"0.02", "best_ask":"0.03"}, {"asset_id":"96888240988495161476033313796107536512663280794332045579302109906525918376981", "price":"0.99", "size":"4230.07", "side":"SELL", "hash":"6868db18de177f8e53031c20923fb27330201804", "best_bid":"0.97", "best_ask":"0.98"}], "timestamp":"1770241470480", "event_type":"price_change"}
{"market":"0x38f3050258345e9cf363d1c8cc302f08c65b96ba1a4669d81e07ed69708344df", "price_changes":[{"asset_id":"81916206347121459497221114766050949090435061493822476265356047392175668050706", "price":"0.01", "size":"4257.07", "side":"BUY", "hash":"8d1d9003974ff93ba05c7397c6bbe77fa24b35f5", "best_bid":"0.02", "best_ask":"0.03"}, {"asset_id":"96888240988495161476033313796107536512663280794332045579302109906525918376981", "price":"0.99", "size":"4257.07", "side":"SELL", "hash":"35ee26b2901b47a19310851a23102cbd9e459f51", "best_bid":"0.97", "best_ask":"0.98"}], "timestamp":"1770241470481", "event_type":"price_change"}
{"market":"0x38f3050258345e9cf363d1c8cc302f08c65b96ba1a4669d81e07ed69708344df", "price_changes":[{"asset_id":"96888240988495161476033313796107536512663280794332045579302109906525918376981", "price":"0.95", "size":"650", "side":"BUY", "hash":"43bc98e7a20769369119557cf8c6f95258bdfe19", "best_bid":"0.97", "best_ask":"0.98"}, {"asset_id":"81916206347121459497221114766050949090435061493822476265356047392175668050706", "price":"0.05", "size":"650", "side":"SELL", "hash":"04ce2a544609ab22b04ca6a111d7a324eb6bbf3a", "best_bid":"0.02", "best_ask":"0.03"}], "timestamp":"1770241470482", "event_type":"price_change"}
{"market":"0x38f3050258345e9cf363d1c8cc302f08c65b96ba1a4669d81e07ed69708344df", "price_changes":[{"asset_id":"81916206347121459497221114766050949090435061493822476265356047392175668050706", "price":"0.01", "size":"4284.07", "side":"BUY", "hash":"dfd29522cca67c7615b332251438f930699545a5", "best_bid":"0.02", "best_ask":"0.03"}, {"asset_id":"96888240988495161476033313796107536512663280794332045579302109906525918376981", "price":"0.99", "size":"4284.07", "side":"SELL", "hash":"bc48200fa2edd8a0e9246e0b28b056e4bea84793", "best_bid":"0.97", "best_ask":"0.98"}], "timestamp":"1770241470484", "event_type":"price_change"}
{"market":"0x38f3050258345e9cf363d1c8cc302f08c65b96ba1a4669d81e07ed69708344df", "price_changes":[{"asset_id":"96888240988495161476033313796107536512663280794332045579302109906525918376981", "price":"0.94", "size":"753", "side":"BUY", "hash":"a37abec5ef8cedee2fda18bb0b51d9bd14f9a8f0", "best_bid":"0.97", "best_ask":"0.98"}, {"asset_id":"81916206347121459497221114766050949090435061493822476265356047392175668050706", "price":"0.06", "size":"753", "side":"SELL", "hash":"5b857349aa9a9d126bfc13aa277eda44b9890395", "best_bid":"0.02", "best_ask":"0.03"}], "timestamp":"1770241470485", "event_type":"price_change"}
{"market":"0x38f3050258345e9cf363d1c8cc302f08c65b96ba1a4669d81e07ed69708344df", "price_changes":[{"asset_id":"81916206347121459497221114766050949090435061493822476265356047392175668050706", "price":"0.01", "size":"4257.07", "side":"BUY", "hash":"1c72c95b91aa523b47b3698e611b22122380b59d", "best_bid":"0.02", "best_ask":"0.03"}, {"asset_id":"96888240988495161476033313796107536512663280794332045579302109906525918376981", "price":"0.99", "size":"4257.07", "side":"SELL", "hash":"4f8dfd067be94dcdd33affdd60d68f4aa8a5a479", "best_bid":"0.97", "best_ask":"0.98"}], "timestamp":"1770241470486", "event_type":"price_change"}
{"market":"0x38f3050258345e9cf363d1c8cc302f08c65b96ba1a4669d81e07ed69708344df", "price_changes":[{"asset_id":"96888240988495161476033313796107536512663280794332045579302109906525918376981", "price":"0.95", "size":"623", "side":"BUY", "hash":"82db570d665f8b74d6c842818837c4681078ac64", "best_bid":"0.97", "best_ask":"0.98"}, {"asset_id":"81916206347121459497221114766050949090435061493822476265356047392175668050706", "price":"0.05", "size":"623", "side":"SELL", "hash":"ca246b4a1a1263283ef00a76b94bb1a0e2691477", "best_bid":"0.02", "best_ask":"0.03"}], "timestamp":"1770241470488", "event_type":"price_change"}
{"market":"0x38f3050258345e9cf363d1c8cc302f08c65b96ba1a4669d81e07ed69708344df", "price_changes":[{"asset_id":"96888240988495161476033313796107536512663280794332045579302109906525918376981", "price":"0.94", "size":"780", "side":"BUY", "hash":"429b5d84b31bb21e61298b6a10cfde41d4da4b8c", "best_bid":"0.97", "best_ask":"0.98"}, {"asset_id":"81916206347121459497221114766050949090435061493822476265356047392175668050706", "price":"0.06", "size":"780", "side":"SELL", "hash":"5e0340cda7ddc134b5a5ddfbe0dac61cd44c50f8", "best_bid":"0.02", "best_ask":"0.03"}], "timestamp":"1770241470489", "event_type":"price_change"}
{"market":"0x38f3050258345e9cf363d1c8cc302f08c65b96ba1a4669d81e07ed69708344df", "price_changes":[{"asset_id":"81916206347121459497221114766050949090435061493822476265356047392175668050706", "price":"0.01", "size":"4284.07", "side":"BUY", "hash":"a08f733375ba3eb6dcaae4866efb0179f60a9841", "best_bid":"0.02", "best_ask":"0.03"}, {"asset_id":"96888240988495161476033313796107536512663280794332045579302109906525918376981", "price":"0.99", "size":"4284.07", "side":"SELL", "hash":"c1774b063b4045991f7f048713b47217701a614c", "best_bid":"0.97", "best_ask":"0.98"}], "timestamp":"1770241470490", "event_type":"price_change"}
{"market":"0x38f3050258345e9cf363d1c8cc302f08c65b96ba1a4669d81e07ed69708344df", "price_changes":[{"asset_id":"81916206347121459497221114766050949090435061493822476265356047392175668050706", "price":"0.01", "size":"4261.07", "side":"BUY", "hash":"e53a52c98a39f7309e33fb59516d5807e9c82e10", "best_bid":"0.02", "best_ask":"0.03"}, {"asset_id":"96888240988495161476033313796107536512663280794332045579302109906525918376981", "price":"0.99", "size":"4261.07", "side":"SELL", "hash":"8aa010b58720ce72658144be734a7207bf4c1b94", "best_bid":"0.97", "best_ask":"0.98"}], "timestamp":"1770241470490", "event_type":"price_change"}
{"market":"0x38f3050258345e9cf363d1c8cc302f08c65b96ba1a4669d81e07ed69708344df", "price_changes":[{"asset_id":"81916206347121459497221114766050949090435061493822476265356047392175668050706", "price":"0.02", "size":"479.98", "side":"BUY", "hash":"c3691405238a64faced2ef456463599e08d87555", "best_bid":"0.02", "best_ask":"0.03"}, {"asset_id":"96888240988495161476033313796107536512663280794332045579302109906525918376981", "price":"0.98", "size":"479.98", "side":"SELL", "hash":"14a43d6abd96b22ec99df11d5ebd4b6abdf8a9a7", "best_bid":"0.97", "best_ask":"0.98"}], "timestamp":"1770241470491", "event_type":"price_change"}
{"market":"0x38f3050258345e9cf363d1c8cc302f08c65b96ba1a4669d81e07ed69708344df", "price_changes":[{"asset_id":"81916206347121459497221114766050949090435061493822476265356047392175668050706", "price":"0.01", "size":"4234.07", "side":"BUY", "hash":"6cbf85c993cabbd92f9d5ef81f95339511881911", "best_bid":"0.02", "best_ask":"0.03"}, {"asset_id":"96888240988495161476033313796107536512663280794332045579302109906525918376981", "price":"0.99", "size":"4234.07", "side":"SELL", "hash":"dc7857d5f650f86cea13c5b324dea30f389dbb6d", "best_bid":"0.97", "best_ask":"0.98"}], "timestamp":"1770241470495", "event_type":"price_change"}
{"market":"0x38f3050258345e9cf363d1c8cc302f08c65b96ba1a4669d81e07ed69708344df", "price_changes":[{"asset_id":"96888240988495161476033313796107536512663280794332045579302109906525918376981", "price":"0.96", "size":"850.73", "side":"BUY", "hash":"941e0fae7fc353e4d524ee131147d9f41116d94c", "best_bid":"0.97", "best_ask":"0.98"}, {"asset_id":"81916206347121459497221114766050949090435061493822476265356047392175668050706", "price":"0.04", "size":"850.73", "side":"SELL", "hash":"68502d13bd215964f5756fcd916b032683cb1d27", "best_bid":"0.02", "best_ask":"0.03"}], "timestamp":"1770241470568", "event_type":"price_change"}
{"market":"0x38f3050258345e9cf363d1c8cc302f08c65b96ba1a4669d81e07ed69708344df", "price_changes":[{"asset_id":"96888240988495161476033313796107536512663280794332045579302109906525918376981", "price":"0.96", "size":"823.73", "side":"BUY", "hash":"8c82363b08a1ee562c3bdd5ed584c228a33449c7", "best_bid":"0.97", "best_ask":"0.98"}, {"asset_id":"81916206347121459497221114766050949090435061493822476265356047392175668050706", "price":"0.04", "size":"823.73", "side":"SELL", "hash":"1a60788400ede7775714b37958b023bc52de9ad1", "best_bid":"0.02", "best_ask":"0.03"}], "timestamp":"1770241470569", "event_type":"price_change"}
{"market":"0x38f3050258345e9cf363d1c8cc302f08c65b96ba1a4669d81e07ed69708344df", "price_changes":[{"asset_id":"96888240988495161476033313796107536512663280794332045579302109906525918376981", "price":"0.98", "size":"463.48", "side":"SELL", "hash":"26ceed81f056993664cbb8ad4ecec0fc967d64df", "best_bid":"0.97", "best_ask":"0.98"}, {"asset_id":"81916206347121459497221114766050949090435061493822476265356047392175668050706", "price":"0.02", "size":"463.48", "side":"BUY", "hash":"e5900cee0075818726a140c9687f6d4317770361", "best_bid":"0.02", "best_ask":"0.03"}], "timestamp":"1770241470633", "event_type":"price_change"}
{"market":"0x38f3050258345e9cf363d1c8cc302f08c65b96ba1a4669d81e07ed69708344df", "asset_id":"81916206347121459497221114766050949090435061493822476265356047392175668050706", "bids":[{"price":"0.01", "size":"4234.07"}, {"price":"0.02", "size":"463.48"}], "asks":[{"price":"0.99", "size":"5019.91"}, {"price":"0.98", "size":"3034.23"}, {"price":"0.97", "size":"3172"}, {"price":"0.96", "size":"3012"}, {"price":"0.95", "size":"3032"}, {"price":"0.94", "size":"3012"}, {"price":"0.93", "size":"3126.28"}, {"price":"0.92", "size":"3012"}, {"price":"0.91", "size":"3012"}, {"price":"0.9", "size":"3087"}, {"price":"0.89", "size":"12"}, {"price":"0.88", "size":"12"}, {"price":"0.87", "size":"12"}, {"price":"0.86", "size":"12"}, {"price":"0.85", "size":"12"}, {"price":"0.84", "size":"12"}, {"price":"0.83", "size":"12"}, {"price":"0.82", "size":"12"}, {"price":"0.81", "size":"12"}, {"price":"0.8", "size":"12"}, {"price":"0.79", "size":"12"}, {"price":"0.78", "size":"12"}, {"price":"0.77", "size":"12"}, {"price":"0.76", "size":"112"}, {"price":"0.75", "size":"40.57"}, {"price":"0.74", "size":"12"}, {"price":"0.73", "size":"293.25"}, {"price":"0.72", "size":"22"}, {"price":"0.71", "size":"12"}, {"price":"0.7", "size":"18"}, {"price":"0.69", "size":"12"}, {"price":"0.68", "size":"12"}, {"price":"0.67", "size":"12"}, {"price":"0.66", "size":"160.89"}, {"price":"0.65", "size":"12"}, {"price":"0.64", "size":"12"}, {"price":"0.63", "size":"12"}, {"price":"0.62", "size":"19.39"}, {"price":"0.61", "size":"18.04"}, {"price":"0.6", "size":"12"}, {"price":"0.59", "size":"94.31"}, {"price":"0.58", "size":"5450.54"}, {"price":"0.57", "size":"12"}, {"price":"0.56", "size":"12"}, {"price":"0.55", "size":"12"}, {"price":"0.54", "size":"22"}, {"price":"0.53", "size":"12"}, {"price":"0.52", "size":"12"}, {"price":"0.51", "size":"12"}, {"price":"0.5", "size":"12"}, {"price":"0.49", "size":"12"}, {"price":"0.48", "size":"12"}, {"price":"0.47", "size":"12"}, {"price":"0.46", "size":"485.56"}, {"price":"0.45", "size":"31"}, {"price":"0.44", "size":"17"}, {"price":"0.43", "size":"12"}, {"price":"0.42", "size":"12"}, {"price":"0.41", "size":"12"}, {"price":"0.4", "size":"127"}, {"price":"0.39", "size":"12"}, {"price":"0.38", "size":"94.51"}, {"price":"0.37", "size":"31.99"}, {"price":"0.36", "size":"12"}, {"price":"0.35", "size":"37"}, {"price":"0.34", "size":"12"}, {"price":"0.33", "size":"12"}, {"price":"0.32", "size":"12"}, {"price":"0.31", "size":"12"}, {"price":"0.3", "size":"31.9"}, {"price":"0.29", "size":"344"}, {"price":"0.28", "size":"3488.99"}, {"price":"0.27", "size":"212"}, {"price":"0.26", "size":"218"}, {"price":"0.25", "size":"712"}, {"price":"0.24", "size":"412"}, {"price":"0.23", "size":"212"}, {"price":"0.22", "size":"1223.14"}, {"price":"0.21", "size":"212"}, {"price":"0.2", "size":"272.99"}, {"price":"0.19", "size":"212"}, {"price":"0.18", "size":"212"}, {"price":"0.17", "size":"212"}, {"price":"0.16", "size":"812"}, {"price":"0.15", "size":"231.08"}, {"price":"0.14", "size":"283.65"}, {"price":"0.13", "size":"212"}, {"price":"0.12", "size":"252"}, {"price":"0.11", "size":"252"}, {"price":"0.1", "size":"746.71"}, {"price":"0.09", "size":"326"}, {"price":"0.08", "size":"844.68"}, {"price":"0.07", "size":"826"}, {"price":"0.06", "size":"780"}, {"price":"0.05", "size":"623"}, {"price":"0.04", "size":"823.73"}, {"price":"0.03", "size":"432"}], "hash":"e5900cee0075818726a140c9687f6d4317770361", "timestamp":"1770241470633", "event_type":"book"}
{"market":"0x38f3050258345e9cf363d1c8cc302f08c65b96ba1a4669d81e07ed69708344df", "asset_id":"81916206347121459497221114766050949090435061493822476265356047392175668050706", "price":"0.02", "size":"16.5", "fee_rate_bps":"0", "side":"SELL", "timestamp":"1770241470662", "event_type":"last_trade_price", "transaction_hash":"0xf07aa0e732dd60612c9bd72f6adba9f718f734bfa1df12a0dd9608e92e5eab41"}
{"market":"0x38f3050258345e9cf363d1c8cc302f08c65b96ba1a4669d81e07ed69708344df", "price_changes":[{"asset_id":"81916206347121459497221114766050949090435061493822476265356047392175668050706", "price":"0.02", "size":"440.48", "side":"BUY", "hash":"effbb7a6359e9b223fd2353eaa8838569728b213", "best_bid":"0.02", "best_ask":"0.03"}, {"asset_id":"96888240988495161476033313796107536512663280794332045579302109906525918376981", "price":"0.98", "size":"440.48", "side":"SELL", "hash":"11cfe5a5888a8a6f7bea428ec5bd42d18cb8e556", "best_bid":"0.97", "best_ask":"0.98"}], "timestamp":"1770241470740", "event_type":"price_change"}
{"market":"0x38f3050258345e9cf363d1c8cc302f08c65b96ba1a4669d81e07ed69708344df", "price_changes":[{"asset_id":"81916206347121459497221114766050949090435061493822476265356047392175668050706", "price":"0.01", "size":"4257.07", "side":"BUY", "hash":"e953128760a3cc40f9d36d4a27e159fcba81e565", "best_bid":"0.02", "best_ask":"0.03"}, {"asset_id":"96888240988495161476033313796107536512663280794332045579302109906525918376981", "price":"0.99", "size":"4257.07", "side":"SELL", "hash":"cfa5d8c3402bb7314cb25b8093e8238158c56274", "best_bid":"0.97", "best_ask":"0.98"}], "timestamp":"1770241470750", "event_type":"price_change"}
{"market":"0x38f3050258345e9cf363d1c8cc302f08c65b96ba1a4669d81e07ed69708344df", "price_changes":[{"asset_id":"96888240988495161476033313796107536512663280794332045579302109906525918376981", "price":"0.98", "size":"398.5", "side":"SELL", "hash":"298a8a60617648b9867022ea6b65e141e4d5b04e", "best_bid":"0.97", "best_ask":"0.98"}, {"asset_id":"81916206347121459497221114766050949090435061493822476265356047392175668050706", "price":"0.02", "size":"398.5", "side":"BUY", "hash":"0097b1629d5cc1165e6d2a3aa4d11a9cb2c31f99", "best_bid":"0.02", "best_ask":"0.03"}], "timestamp":"1770241470757", "event_type":"price_change"}
{"market":"0x38f3050258345e9cf363d1c8cc302f08c65b96ba1a4669d81e07ed69708344df", "asset_id":"81916206347121459497221114766050949090435061493822476265356047392175668050706", "bids":[{"price":"0.01", "size":"4257.07"}, {"price":"0.02", "size":"398.5"}], "asks":[{"price":"0.99", "size":"5019.91"}, {"price":"0.98", "size":"3034.23"}, {"price":"0.97", "size":"3172"}, {"price":"0.96", "size":"3012"}, {"price":"0.95", "size":"3032"}, {"price":"0.94", "size":"3012"}, {"price":"0.93", "size":"3126.28"}, {"price":"0.92", "size":"3012"}, {"price":"0.91", "size":"3012"}, {"price":"0.9", "size":"3087"}, {"price":"0.89", "size":"12"}, {"price":"0.88", "size":"12"}, {"price":"0.87", "size":"12"}, {"price":"0.86", "size":"12"}, {"price":"0.85", "size":"12"}, {"price":"0.84", "size":"12"}, {"price":"0.83", "size":"12"}, {"price":"0.82", "size":"12"}, {"price":"0.81", "size":"12"}, {"price":"0.8", "size":"12"}, {"price":"0.79", "size":"12"}, {"price":"0.78", "size":"12"}, {"price":"0.77", "size":"12"}, {"price":"0.76", "size":"112"}, {"price":"0.75", "size":"40.57"}, {"price":"0.74", "size":"12"}, {"price":"0.73", "size":"293.25"}, {"price":"0.72", "size":"22"}, {"price":"0.71", "size":"12"}, {"price":"0.7", "size":"18"}, {"price":"0.69", "size":"12"}, {"price":"0.68", "size":"12"}, {"price":"0.67", "size":"12"}, {"price":"0.66", "size":"160.89"}, {"price":"0.65", "size":"12"}, {"price":"0.64", "size":"12"}, {"price":"0.63", "size":"12"}, {"price":"0.62", "size":"19.39"}, {"price":"0.61", "size":"18.04"}, {"price":"0.6", "size":"12"}, {"price":"0.59", "size":"94.31"}, {"price":"0.58", "size":"5450.54"}, {"price":"0.57", "size":"12"}, {"price":"0.56", "size":"12"}, {"price":"0.55", "size":"12"}, {"price":"0.54", "size":"22"}, {"price":"0.53", "size":"12"}, {"price":"0.52", "size":"12"}, {"price":"0.51", "size":"12"}, {"price":"0.5", "size":"12"}, {"price":"0.49", "size":"12"}, {"price":"0.48", "size":"12"}, {"price":"0.47", "size":"12"}, {"price":"0.46", "size":"485.56"}, {"price":"0.45", "size":"31"}, {"price":"0.44", "size":"17"}, {"price":"0.43", "size":"12"}, {"price":"0.42", "size":"12"}, {"price":"0.41", "size":"12"}, {"price":"0.4", "size":"127"}, {"price":"0.39", "size":"12"}, {"price":"0.38", "size":"94.51"}, {"price":"0.37", "size":"31.99"}, {"price":"0.36", "size":"12"}, {"price":"0.35", "size":"37"}, {"price":"0.34", "size":"12"}, {"price":"0.33", "size":"12"}, {"price":"0.32", "size":"12"}, {"price":"0.31", "size":"12"}, {"price":"0.3", "size":"31.9"}, {"price":"0.29", "size":"344"}, {"price":"0.28", "size":"3488.99"}, {"price":"0.27", "size":"212"}, {"price":"0.26", "size":"218"}, {"price":"0.25", "size":"712"}, {"price":"0.24", "size":"412"}, {"price":"0.23", "size":"212"}, {"price":"0.22", "size":"1223.14"}, {"price":"0.21", "size":"212"}, {"price":"0.2", "size":"272.99"}, {"price":"0.19", "size":"212"}, {"price":"0.18", "size":"212"}, {"price":"0.17", "size":"212"}, {"price":"0.16", "size":"812"}, {"price":"0.15", "size":"231.08"}, {"price":"0.14", "size":"283.65"}, {"price":"0.13", "size":"212"}, {"price":"0.12", "size":"252"}, {"price":"0.11", "size":"252"}, {"price":"0.1", "size":"746.71"}, {"price":"0.09", "size":"326"}, {"price":"0.08", "size":"844.68"}, {"price":"0.07", "size":"826"}, {"price":"0.06", "size":"780"}, {"price":"0.05", "size":"623"}, {"price":"0.04", "size":"823.73"}, {"price":"0.03", "size":"432"}], "hash":"0097b1629d5cc1165e6d2a3aa4d11a9cb2c31f99", "timestamp":"1770241470757", "event_type":"book"}
{"market":"0x38f3050258345e9cf363d1c8cc302f08c65b96ba1a4669d81e07ed69708344df", "price_changes":[{"asset_id":"81916206347121459497221114766050949090435061493822476265356047392175668050706", "price":"0.01", "size":"4230.07", "side":"BUY", "hash":"98488d69a1ff541c0dfe0996afac013cf23a2f04", "best_bid":"0.02", "best_ask":"0.03"}, {"asset_id":"96888240988495161476033313796107536512663280794332045579302109906525918376981", "price":"0.99", "size":"4230.07", "side":"SELL", "hash":"b9480904697e05502dbfc5b2003718bc24ed204a", "best_bid":"0.97", "best_ask":"0.98"}], "timestamp":"1770241470839", "event_type":"price_change"}
{"market":"0x38f3050258345e9cf363d1c8cc302f08c65b96ba1a4669d81e07ed69708344df", "price_changes":[{"asset_id":"81916206347121459497221114766050949090435061493822476265356047392175668050706", "price":"0.01", "size":"4257.07", "side":"BUY", "hash":"3a79c33f58e6f767985b7fe78a378e9fec0ac926", "best_bid":"0.02", "best_ask":"0.03"}, {"asset_id":"96888240988495161476033313796107536512663280794332045579302109906525918376981", "price":"0.99", "size":"4257.07", "side":"SELL", "hash":"0d8a663c0a811da8eebbbb102e06c70141c38b21", "best_bid":"0.97", "best_ask":"0.98"}], "timestamp":"1770241470839", "event_type":"price_change"}
{"market":"0x38f3050258345e9cf363d1c8cc302f08c65b96ba1a4669d81e07ed69708344df", "price_changes":[{"asset_id":"96888240988495161476033313796107536512663280794332045579302109906525918376981", "price":"0.94", "size":"753", "side":"BUY", "hash":"7b61629313628bf7bde982e81d921095a2173912", "best_bid":"0.97", "best_ask":"0.98"}, {"asset_id":"81916206347121459497221114766050949090435061493822476265356047392175668050706", "price":"0.06", "size":"753", "side":"SELL", "hash":"cdd08220047213bdeb9009a7709a4e28cfe667d8", "best_bid":"0.02", "best_ask":"0.03"}], "timestamp":"1770241470841", "event_type":"price_change"}
{"market":"0x38f3050258345e9cf363d1c8cc302f08c65b96ba1a4669d81e07ed69708344df", "price_changes":[{"asset_id":"96888240988495161476033313796107536512663280794332045579302109906525918376981", "price":"0.95", "size":"650", "side":"BUY", "hash":"9a3b87b57450a2ddb4b6cbba5252f6f055494acd", "best_bid":"0.97", "best_ask":"0.98"}, {"asset_id":"81916206347121459497221114766050949090435061493822476265356047392175668050706", "price":"0.05", "size":"650", "side":"SELL", "hash":"9e766e4908062126b2be2f1f0349b57587ef8760", "best_bid":"0.02", "best_ask":"0.03"}], "timestamp":"1770241470844", "event_type":"price_change"}
{"market":"0x38f3050258345e9cf363d1c8cc302f08c65b96ba1a4669d81e07ed69708344df", "price_changes":[{"asset_id":"81916206347121459497221114766050949090435061493822476265356047392175668050706", "price":"0.01", "size":"4284.07", "side":"BUY", "hash":"67adc5ae1d77d83e19476fff2c8e56e311336bba", "best_bid":"0.02", "best_ask":"0.03"}, {"asset_id":"96888240988495161476033313796107536512663280794332045579302109906525918376981", "price":"0.99", "size":"4284.07", "side":"SELL", "hash":"39e91e7eef67d83d528d3523aa6e27ad5fe602c3", "best_bid":"0.97", "best_ask":"0.98"}], "timestamp":"1770241470849", "event_type":"price_change"}
{"market":"0x38f3050258345e9cf363d1c8cc302f08c65b96ba1a4669d81e07ed69708344df", "price_changes":[{"asset_id":"96888240988495161476033313796107536512663280794332045579302109906525918376981", "price":"0.94", "size":"726", "side":"BUY", "hash":"c35d248cce3ee39d73f18c7a3ab3607720ddce77", "best_bid":"0.97", "best_ask":"0.98"}, {"asset_id":"81916206347121459497221114766050949090435061493822476265356047392175668050706", "price":"0.06", "size":"726", "side":"SELL", "hash":"83a41d2848c275f8b9bf63601b37ad460c7fe0aa", "best_bid":"0.02", "best_ask":"0.03"}], "timestamp":"1770241470850", "event_type":"price_change"}
{"market":"0x38f3050258345e9cf363d1c8cc302f08c65b96ba1a4669d81e07ed69708344df", "price_changes":[{"asset_id":"81916206347121459497221114766050949090435061493822476265356047392175668050706", "price":"0.01", "size":"4257.07", "side":"BUY", "hash":"e56c51d0358ef5b51f4c3a16c7376d94a9e8c075", "best_bid":"0.02", "best_ask":"0.03"}, {"asset_id":"96888240988495161476033313796107536512663280794332045579302109906525918376981", "price":"0.99", "size":"4257.07", "side":"SELL", "hash":"e4950c71d3a77ebb6dc13cbc3081387cd66dcf95", "best_bid":"0.97", "best_ask":"0.98"}], "timestamp":"1770241470854", "event_type":"price_change"}
{"market":"0x38f3050258345e9cf363d1c8cc302f08c65b96ba1a4669d81e07ed69708344df", "price_changes":[{"asset_id":"96888240988495161476033313796107536512663280794332045579302109906525918376981", "price":"0.96", "size":"796.73", "side":"BUY", "hash":"45c306581a1a029744f2844d8b25470b8ef1cc96", "best_bid":"0.97", "best_ask":"0.98"}, {"asset_id":"81916206347121459497221114766050949090435061493822476265356047392175668050706", "price":"0.04", "size":"796.73", "side":"SELL", "hash":"74d2abba37abdf4a6db6d9c5d537086037e321dd", "best_bid":"0.02", "best_ask":"0.03"}], "timestamp":"1770241470858", "event_type":"price_change"}
{"market":"0x38f3050258345e9cf363d1c8cc302f08c65b96ba1a4669d81e07ed69708344df", "price_changes":[{"asset_id":"96888240988495161476033313796107536512663280794332045579302109906525918376981", "price":"0.97", "size":"459", "side":"BUY", "hash":"fecb238e1ae55d35b757c0198b398ae08799b953", "best_bid":"0.97", "best_ask":"0.98"}, {"asset_id":"81916206347121459497221114766050949090435061493822476265356047392175668050706", "price":"0.03", "size":"459", "side":"SELL", "hash":"7399e0c200a4cff02c760eb0e8511b5135f82f05", "best_bid":"0.02", "best_ask":"0.03"}], "timestamp":"1770241470860", "event_type":"price_change"}
{"market":"0x38f3050258345e9cf363d1c8cc302f08c65b96ba1a4669d81e07ed69708344df", "price_changes":[{"asset_id":"81916206347121459497221114766050949090435061493822476265356047392175668050706", "price":"0.01", "size":"4230.07", "side":"BUY", "hash":"2c59f937b0b01bf9e36659276c8059425c67d2b4", "best_bid":"0.02", "best_ask":"0.03"}, {"asset_id":"96888240988495161476033313796107536512663280794332045579302109906525918376981", "price":"0.99", "size":"4230.07", "side":"SELL", "hash":"3357b187bd703096d9c119f31fc09a66b0733692", "best_bid":"0.97", "best_ask":"0.98"}], "timestamp":"1770241470862", "event_type":"price_change"}
{"market":"0x38f3050258345e9cf363d1c8cc302f08c65b96ba1a4669d81e07ed69708344df", "price_changes":[{"asset_id":"81916206347121459497221114766050949090435061493822476265356047392175668050706", "price":"0.01", "size":"4257.07", "side":"BUY", "hash":"43748ad7e242a489433511b2240ab14f75268d48", "best_bid":"0.02", "best_ask":"0.03"}, {"asset_id":"96888240988495161476033313796107536512663280794332045579302109906525918376981", "price":"0.99", "size":"4257.07", "side":"SELL", "hash":"d649446fbcb075ca3ddec7020ce6f44d1afe89e2", "best_bid":"0.97", "best_ask":"0.98"}], "timestamp":"1770241470863", "event_type":"price_change"}
{"market":"0x38f3050258345e9cf363d1c8cc302f08c65b96ba1a4669d81e07ed69708344df", "price_changes":[{"asset_id":"96888240988495161476033313796107536512663280794332045579302109906525918376981", "price":"0.95", "size":"677", "side":"BUY", "hash":"07daf1f937da57659d8542ff20ffa0f4650df6da", "best_bid":"0.97", "best_ask":"0.98"}, {"asset_id":"81916206347121459497221114766050949090435061493822476265356047392175668050706", "price":"0.05", "size":"677", "side":"SELL", "hash":"fc1c1cb0ea47a0b9e01e5f06f8d1852b04f3b42c", "best_bid":"0.02", "best_ask":"0.03"}], "timestamp":"1770241470865", "event_type":"price_change"}
{"market":"0x38f3050258345e9cf363d1c8cc302f08c65b96ba1a4669d81e07ed69708344df", "price_changes":[{"asset_id":"81916206347121459497221114766050949090435061493822476265356047392175668050706", "price":"0.05", "size":"671", "side":"SELL", "hash":"7bfa7b63a411b0e6773a577c1c01ffd31e8dacba", "best_bid":"0.02", "best_ask":"0.03"}, {"asset_id":"96888240988495161476033313796107536512663280794332045579302109906525918376981", "price":"0.95", "size":"671", "side":"BUY", "hash":"2973f67a03a789ad9c8fd73fbd09c6207643a133", "best_bid":"0.97", "best_ask":"0.98"}], "timestamp":"1770241470883", "event_type":"price_change"}
{"market":"0x38f3050258345e9cf363d1c8cc302f08c65b96ba1a4669d81e07ed69708344df", "price_changes":[{"asset_id":"81916206347121459497221114766050949090435061493822476265356047392175668050706", "price":"0.04", "size":"802.73", "side":"SELL", "hash":"6bf1132ddeeee7ebe982b8f7d12be279fabed20b", "best_bid":"0.02", "best_ask":"0.03"}, {"asset_id":"96888240988495161476033313796107536512663280794332045579302109906525918376981", "price":"0.96", "size":"802.73", "side":"BUY", "hash":"3824389321c10b5899555b8b5d36add189471a2f", "best_bid":"0.97", "best_ask":"0.98"}], "timestamp":"1770241470907", "event_type":"price_change"}
{"market":"0x38f3050258345e9cf363d1c8cc302f08c65b96ba1a4669d81e07ed69708344df", "price_changes":[{"asset_id":"96888240988495161476033313796107536512663280794332045579302109906525918376981", "price":"0.98", "size":"358.5", "side":"SELL", "hash":"42210f655fd4e9ad82d133da137b30d54a0eaec5", "best_bid":"0.97", "best_ask":"0.98"}, {"asset_id":"81916206347121459497221114766050949090435061493822476265356047392175668050706", "price":"0.02", "size":"358.5", "side":"BUY", "hash":"2fad73073930a7074a02520b875121a8d5af25c7", "best_bid":"0.02", "best_ask":"0.03"}], "timestamp":"1770241470926", "event_type":"price_change"}
{"market":"0x38f3050258345e9cf363d1c8cc302f08c65b96ba1a4669d81e07ed69708344df", "price_changes":[{"asset_id":"96888240988495161476033313796107536512663280794332045579302109906525918376981", "price":"0.95", "size":"644", "side":"BUY", "hash":"662d940c86a31eca82be7ae6545393fb146a9bed", "best_bid":"0.97", "best_ask":"0.98"}, {"asset_id":"81916206347121459497221114766050949090435061493822476265356047392175668050706", "price":"0.05", "size":"644", "side":"SELL", "hash":"f7393abcf63c4a8b2dd230a2f737100bb4b65a71", "best_bid":"0.02", "best_ask":"0.03"}], "timestamp":"1770241470959", "event_type":"price_change"}
{"market":"0x38f3050258345e9cf363d1c8cc302f08c65b96ba1a4669d81e07ed69708344df", "price_changes":[{"asset_id":"81916206347121459497221114766050949090435061493822476265356047392175668050706", "price":"0.01", "size":"4284.07", "side":"BUY", "hash":"c8df985f918697d4ec356b0e34f3d66685b56434", "best_bid":"0.02", "best_ask":"0.03"}, {"asset_id":"96888240988495161476033313796107536512663280794332045579302109906525918376981", "price":"0.99", "size":"4284.07", "side":"SELL", "hash":"5d3e9179084892935949064e115d608f493250bd", "best_bid":"0.97", "best_ask":"0.98"}], "timestamp":"1770241470960", "event_type":"price_change"}
{"market":"0x38f3050258345e9cf363d1c8cc302f08c65b96ba1a4669d81e07ed69708344df", "price_changes":[{"asset_id":"96888240988495161476033313796107536512663280794332045579302109906525918376981", "price":"0.94", "size":"753", "side":"BUY", "hash":"f01d47a2daa16e700e6b71983b081b85c7ef4df4", "best_bid":"0.97", "best_ask":"0.98"}, {"asset_id":"81916206347121459497221114766050949090435061493822476265356047392175668050706", "price":"0.06", "size":"753", "side":"SELL", "hash":"d8c8c6df47fe2d9d6fc34debc0d0356086919685", "best_bid":"0.02", "best_ask":"0.03"}], "timestamp":"1770241470962", "event_type":"price_change"}
{"market":"0x38f3050258345e9cf363d1c8cc302f08c65b96ba1a4669d81e07ed69708344df", "price_changes":[{"asset_id":"81916206347121459497221114766050949090435061493822476265356047392175668050706", "price":"0.01", "size":"4257.07", "side":"BUY", "hash":"01d9f8472327a01c4b529abd951349099d457a83", "best_bid":"0.02", "best_ask":"0.03"}, {"asset_id":"96888240988495161476033313796107536512663280794332045579302109906525918376981", "price":"0.99", "size":"4257.07", "side":"SELL", "hash":"726a3cc358ea78b333f9e274ad0da97b97ef7401", "best_bid":"0.97", "best_ask":"0.98"}], "timestamp":"1770241470964", "event_type":"price_change"}
{"market":"0x38f3050258345e9cf363d1c8cc302f08c65b96ba1a4669d81e07ed69708344df", "price_changes":[{"asset_id":"81916206347121459497221114766050949090435061493822476265356047392175668050706", "price":"0.01", "size":"4230.07", "side":"BUY", "hash":"5fd009845df3c061fbb187cb4cea77e4dd2b09ef", "best_bid":"0.02", "best_ask":"0.03"}, {"asset_id":"96888240988495161476033313796107536512663280794332045579302109906525918376981", "price":"0.99", "size":"4230.07", "side":"SELL", "hash":"982a1cd86a911c7ba4e76109f7ee2c7b5957d8ac", "best_bid":"0.97", "best_ask":"0.98"}], "timestamp":"1770241470969", "event_type":"price_change"}
{"market":"0x38f3050258345e9cf363d1c8cc302f08c65b96ba1a4669d81e07ed69708344df", "price_changes":[{"asset_id":"96888240988495161476033313796107536512663280794332045579302109906525918376981", "price":"0.94", "size":"780", "side":"BUY", "hash":"d19dcd7a24c5fb3a03b2e415db9f02d13c8dd49b", "best_bid":"0.97", "best_ask":"0.98"}, {"asset_id":"81916206347121459497221114766050949090435061493822476265356047392175668050706", "price":"0.06", "size":"780", "side":"SELL", "hash":"d8ed731b92d5833e800b4427932535590a73b79b", "best_bid":"0.02", "best_ask":"0.03"}], "timestamp":"1770241470970", "event_type":"price_change"}
{"market":"0x38f3050258345e9cf363d1c8cc302f08c65b96ba1a4669d81e07ed69708344df", "price_changes":[{"asset_id":"96888240988495161476033313796107536512663280794332045579302109906525918376981", "price":"0.95", "size":"617", "side":"BUY", "hash":"00416c7e8c8895a1891bb8426174399a9e7e7338", "best_bid":"0.97", "best_ask":"0.98"}, {"asset_id":"81916206347121459497221114766050949090435061493822476265356047392175668050706", "price":"0.05", "size":"617", "side":"SELL", "hash":"b097c0a4f391dfdde0957e549f0e2f5a436c9eeb", "best_bid":"0.02", "best_ask":"0.03"}], "timestamp":"1770241470971", "event_type":"price_change"}
{"market":"0x38f3050258345e9cf363d1c8cc302f08c65b96ba1a4669d81e07ed69708344df", "price_changes":[{"asset_id":"81916206347121459497221114766050949090435061493822476265356047392175668050706", "price":"0.01", "size":"4257.07", "side":"BUY", "hash":"ab764b1379ec774095ba398c71824ae11bb115a6", "best_bid":"0.02", "best_ask":"0.03"}, {"asset_id":"96888240988495161476033313796107536512663280794332045579302109906525918376981", "price":"0.99", "size":"4257.07", "side":"SELL", "hash":"13d3a5e347680bed8a8ec5ee382866a588e0f508", "best_bid":"0.97", "best_ask":"0.98"}], "timestamp":"1770241470973", "event_type":"price_change"}
{"market":"0x38f3050258345e9cf363d1c8cc302f08c65b96ba1a4669d81e07ed69708344df", "price_changes":[{"asset_id":"96888240988495161476033313796107536512663280794332045579302109906525918376981", "price":"0.97", "size":"432", "side":"BUY", "hash":"9456311b00f09e7f8d48595aa4c0c7a18637aedf", "best_bid":"0.97", "best_ask":"0.98"}, {"asset_id":"81916206347121459497221114766050949090435061493822476265356047392175668050706", "price":"0.03", "size":"432", "side":"SELL", "hash":"7b2c4d3d0236a25bef12a8322887a81629fe28b3", "best_bid":"0.02", "best_ask":"0.03"}], "timestamp":"1770241470981", "event_type":"price_change"}
{"market":"0x38f3050258345e9cf363d1c8cc302f08c65b96ba1a4669d81e07ed69708344df", "price_changes":[{"asset_id":"81916206347121459497221114766050949090435061493822476265356047392175668050706", "price":"0.01", "size":"4284.07", "side":"BUY", "hash":"d6cf22df7846a295922b3cd9f5792dce6136a79e", "best_bid":"0.02", "best_ask":"0.03"}, {"asset_id":"96888240988495161476033313796107536512663280794332045579302109906525918376981", "price":"0.99", "size":"4284.07", "side":"SELL", "hash":"a8906481113dea8bbb4734886f57bcc46e8c752d", "best_bid":"0.97", "best_ask":"0.98"}], "timestamp":"1770241470983", "event_type":"price_change"}
{"market":"0x38f3050258345e9cf363d1c8cc302f08c65b96ba1a4669d81e07ed69708344df", "price_changes":[{"asset_id":"81916206347121459497221114766050949090435061493822476265356047392175668050706", "price":"0.01", "size":"4257.07", "side":"BUY", "hash":"bcb080b2e2b284953d6d377631e1ce388f917749", "best_bid":"0.02", "best_ask":"0.03"}, {"asset_id":"96888240988495161476033313796107536512663280794332045579302109906525918376981", "price":"0.99", "size":"4257.07", "side":"SELL", "hash":"6d952d520db34a49fd536689bf4d2e9b11d66d43", "best_bid":"0.97", "best_ask":"0.98"}], "timestamp":"1770241470983", "event_type":"price_change"}
{"market":"0x38f3050258345e9cf363d1c8cc302f08c65b96ba1a4669d81e07ed69708344df", "price_changes":[{"asset_id":"96888240988495161476033313796107536512663280794332045579302109906525918376981", "price":"0.96", "size":"829.73", "side":"BUY", "hash":"dc70c4c02cbfac883da1d8d1656c3d59c8ae9b8a", "best_bid":"0.97", "best_ask":"0.98"}, {"asset_id":"81916206347121459497221114766050949090435061493822476265356047392175668050706", "price":"0.04", "size":"829.73", "side":"SELL", "hash":"01f712bcd44dea9b273f4f148880576c715e7a4b", "best_bid":"0.02", "best_ask":"0.03"}], "timestamp":"1770241470984", "event_type":"price_change"}
{"market":"0x38f3050258345e9cf363d1c8cc302f08c65b96ba1a4669d81e07ed69708344df", "price_changes":[{"asset_id":"81916206347121459497221114766050949090435061493822476265356047392175668050706", "price":"0.01", "size":"4230.07", "side":"BUY", "hash":"aeee03bfc5c9bc9773ff214f71ce045c353112b5", "best_bid":"0.02", "best_ask":"0.03"}, {"asset_id":"96888240988495161476033313796107536512663280794332045579302109906525918376981", "price":"0.99", "size":"4230.07", "side":"SELL", "hash":"66b726a4d58f0d31f6254b49a98522b38ba45ed4", "best_bid":"0.97", "best_ask":"0.98"}], "timestamp":"1770241470986", "event_type":"price_change"}
{"market":"0x38f3050258345e9cf363d1c8cc302f08c65b96ba1a4669d81e07ed69708344df", "price_changes":[{"asset_id":"81916206347121459497221114766050949090435061493822476265356047392175668050706", "price":"0.02", "size":"381.5", "side":"BUY", "hash":"334c168858b4dd805ee75b44f67f56e9a02c0df4", "best_bid":"0.02", "best_ask":"0.03"}, {"asset_id":"96888240988495161476033313796107536512663280794332045579302109906525918376981", "price":"0.98", "size":"381.5", "side":"SELL", "hash":"9b935f43120bdfda13071975b05c3568270db9ed", "best_bid":"0.97", "best_ask":"0.98"}], "timestamp":"1770241470991", "event_type":"price_change"}
{"market":"0x38f3050258345e9cf363d1c8cc302f08c65b96ba1a4669d81e07ed69708344df", "price_changes":[{"asset_id":"81916206347121459497221114766050949090435061493822476265356047392175668050706", "price":"0.01", "size":"4207.07", "side":"BUY", "hash":"ec94abaf9a947872de67c9d3ac6d211aa846217d", "best_bid":"0.02", "best_ask":"0.03"}, {"asset_id":"96888240988495161476033313796107536512663280794332045579302109906525918376981", "price":"0.99", "size":"4207.07", "side":"SELL", "hash":"b46c8952a0b0935944b979afef57e5bb9c625395", "best_bid":"0.97", "best_ask":"0.98"}], "timestamp":"1770241470995", "event_type":"price_change"}
{"market":"0x38f3050258345e9cf363d1c8cc302f08c65b96ba1a4669d81e07ed69708344df", "price_changes":[{"asset_id":"81916206347121459497221114766050949090435061493822476265356047392175668050706", "price":"0.01", "size":"4180.07", "side":"BUY", "hash":"085d6e9b2e16156c4ff1d3ce197579bf3e9ebe26", "best_bid":"0.02", "best_ask":"0.03"}, {"asset_id":"96888240988495161476033313796107536512663280794332045579302109906525918376981", "price":"0.99", "size":"4180.07", "side":"SELL", "hash":"3168543157a2e49612113831f12423821c01ce29", "best_bid":"0.97", "best_ask":"0.98"}], "timestamp":"1770241471002", "event_type":"price_change"}
{"market":"0x38f3050258345e9cf363d1c8cc302f08c65b96ba1a4669d81e07ed69708344df", "price_changes":[{"asset_id":"81916206347121459497221114766050949090435061493822476265356047392175668050706", "price":"0.01", "size":"4153.07", "side":"BUY", "hash":"a8ba93c1c714185c0de214abb91e168125c5d3e0", "best_bid":"0.02", "best_ask":"0.03"}, {"asset_id":"96888240988495161476033313796107536512663280794332045579302109906525918376981", "price":"0.99", "size":"4153.07", "side":"SELL", "hash":"7687f2780cc1bb928093f29c5c797ad3eaf759a9", "best_bid":"0.97", "best_ask":"0.98"}], "timestamp":"1770241471006", "event_type":"price_change"}
{"market":"0x38f3050258345e9cf363d1c8cc302f08c65b96ba1a4669d81e07ed69708344df", "price_changes":[{"asset_id":"81916206347121459497221114766050949090435061493822476265356047392175668050706", "price":"0.02", "size":"358.5", "side":"BUY", "hash":"dd6db7cb944b6d5c10573da74296b5487414d684", "best_bid":"0.02", "best_ask":"0.03"}, {"asset_id":"96888240988495161476033313796107536512663280794332045579302109906525918376981", "price":"0.98", "size":"358.5", "side":"SELL", "hash":"23a47603ccb8c6d4c9322bb24b5c1d53a9ab5278", "best_bid":"0.97", "best_ask":"0.98"}], "timestamp":"1770241471014", "event_type":"price_change"}
{"market":"0x38f3050258345e9cf363d1c8cc302f08c65b96ba1a4669d81e07ed69708344df", "price_changes":[{"asset_id":"96888240988495161476033313796107536512663280794332045579302109906525918376981", "price":"0.96", "size":"809.73", "side":"BUY", "hash":"8fe96628cde193a195b67f016a7ac88efc5a46f8", "best_bid":"0.97", "best_ask":"0.98"}, {"asset_id":"81916206347121459497221114766050949090435061493822476265356047392175668050706", "price":"0.04", "size":"809.73", "side":"SELL", "hash":"c1f89540fb53be5cc2240eaccfef35dc67c7dd65", "best_bid":"0.02", "best_ask":"0.03"}], "timestamp":"1770241471058", "event_type":"price_change"}
{"market":"0x38f3050258345e9cf363d1c8cc302f08c65b96ba1a4669d81e07ed69708344df", "price_changes":[{"asset_id":"96888240988495161476033313796107536512663280794332045579302109906525918376981", "price":"0.96", "size":"782.73", "side":"BUY", "hash":"9e9cccad7801aa23f9fdb56bbe44d8086edbdfe5", "best_bid":"0.97", "best_ask":"0.98"}, {"asset_id":"81916206347121459497221114766050949090435061493822476265356047392175668050706", "price":"0.04", "size":"782.73", "side":"SELL", "hash":"47e3ab3a08bfaf0a54a895b70cf1749689a98b4f", "best_bid":"0.02", "best_ask":"0.03"}], "timestamp":"1770241471103", "event_type":"price_change"}
{"market":"0x38f3050258345e9cf363d1c8cc302f08c65b96ba1a4669d81e07ed69708344df", "price_changes":[{"asset_id":"96888240988495161476033313796107536512663280794332045579302109906525918376981", "price":"0.95", "size":"644", "side":"BUY", "hash":"5e9c06924c99a1400726e5cbd351f43eecdfb9f7", "best_bid":"0.97", "best_ask":"0.98"}, {"asset_id":"81916206347121459497221114766050949090435061493822476265356047392175668050706", "price":"0.05", "size":"644", "side":"SELL", "hash":"bef989d5fba8798caf49110811b298492b8e0e6b", "best_bid":"0.02", "best_ask":"0.03"}], "timestamp":"1770241471104", "event_type":"price_change"}
{"market":"0x38f3050258345e9cf363d1c8cc302f08c65b96ba1a4669d81e07ed69708344df", "price_changes":[{"asset_id":"96888240988495161476033313796107536512663280794332045579302109906525918376981", "price":"0.94", "size":"753", "side":"BUY", "hash":"7e72aa395f3969eeb5fd5fe94ad75605a939a2f1", "best_bid":"0.97", "best_ask":"0.98"}, {"asset_id":"81916206347121459497221114766050949090435061493822476265356047392175668050706", "price":"0.06", "size":"753", "side":"SELL", "hash":"84ed3851d5ce943e88c51a4f1e699f3a68a50c1a", "best_bid":"0.02", "best_ask":"0.03"}], "timestamp":"1770241471157", "event_type":"price_change"}
{"market":"0x38f3050258345e9cf363d1c8cc302f08c65b96ba1a4669d81e07ed69708344df", "price_changes":[{"asset_id":"96888240988495161476033313796107536512663280794332045579302109906525918376981", "price":"0.97", "size":"466.49", "side":"BUY", "hash":"4271013e7f526199eda5d3ae140779579d8e7462", "best_bid":"0.97", "best_ask":"0.98"}, {"asset_id":"81916206347121459497221114766050949090435061493822476265356047392175668050706", "price":"0.03", "size":"466.49", "side":"SELL", "hash":"48b6a513ce7e91630081379ebc818fc6656a0d6f", "best_bid":"0.02", "best_ask":"0.03"}], "timestamp":"1770241471162", "event_type":"price_change"}
{"market":"0x38f3050258345e9cf363d1c8cc302f08c65b96ba1a4669d81e07ed69708344df", "price_changes":[{"asset_id":"96888240988495161476033313796107536512663280794332045579302109906525918376981", "price":"0.96", "size":"759.73", "side":"BUY", "hash":"1c2f846c26105f7b052ed876806fd164567e5a43", "best_bid":"0.97", "best_ask":"0.98"}, {"asset_id":"81916206347121459497221114766050949090435061493822476265356047392175668050706", "price":"0.04", "size":"759.73", "side":"SELL", "hash":"73aa2e7f4b237a26ca8b6497df83f93c9e0cfcac", "best_bid":"0.02", "best_ask":"0.03"}], "timestamp":"1770241471163", "event_type":"price_change"}
{"market":"0x38f3050258345e9cf363d1c8cc302f08c65b96ba1a4669d81e07ed69708344df", "price_changes":[{"asset_id":"96888240988495161476033313796107536512663280794332045579302109906525918376981", "price":"0.94", "size":"726", "side":"BUY", "hash":"6eb4a9ca5f7ff4959821e4337e38165e425be0c6", "best_bid":"0.97", "best_ask":"0.98"}, {"asset_id":"81916206347121459497221114766050949090435061493822476265356047392175668050706", "price":"0.06", "size":"726", "side":"SELL", "hash":"78d96d8fb5fa28d69198ec95602dc5b6c98f93ef", "best_bid":"0.02", "best_ask":"0.03"}], "timestamp":"1770241471168", "event_type":"price_change"}
{"market":"0x38f3050258345e9cf363d1c8cc302f08c65b96ba1a4669d81e07ed69708344df", "price_changes":[{"asset_id":"96888240988495161476033313796107536512663280794332045579302109906525918376981", "price":"0.95", "size":"671", "side":"BUY", "hash":"997c63cdf90ebdc78e7853bc3db1b4548d3fed62", "best_bid":"0.97", "best_ask":"0.98"}, {"asset_id":"81916206347121459497221114766050949090435061493822476265356047392175668050706", "price":"0.05", "size":"671", "side":"SELL", "hash":"71ea0edbdda1d58cfac5c5f712fc87ed2170dd37", "best_bid":"0.02", "best_ask":"0.03"}], "timestamp":"1770241471169", "event_type":"price_change"}
{"market":"0x38f3050258345e9cf363d1c8cc302f08c65b96ba1a4669d81e07ed69708344df", "price_changes":[{"asset_id":"96888240988495161476033313796107536512663280794332045579302109906525918376981", "price":"0.95", "size":"698", "side":"BUY", "hash":"80b1374fae04c35290c60dcdbe9c8787e74f4a5a", "best_bid":"0.97", "best_ask":"0.98"}, {"asset_id":"81916206347121459497221114766050949090435061493822476265356047392175668050706", "price":"0.05", "size":"698", "side":"SELL", "hash":"d8e2e42314340c2ac7abb26cc412b06757007bab", "best_bid":"0.02", "best_ask":"0.03"}], "timestamp":"1770241471177", "event_type":"price_change"}
{"market":"0x38f3050258345e9cf363d1c8cc302f08c65b96ba1a4669d81e07ed69708344df", "price_changes":[{"asset_id":"96888240988495161476033313796107536512663280794332045579302109906525918376981", "price":"0.76", "size":"212", "side":"BUY", "hash":"9d933c209e4a3dc9e111fd241cb8c178b9e5875e", "best_bid":"0.97", "best_ask":"0.98"}, {"asset_id":"81916206347121459497221114766050949090435061493822476265356047392175668050706", "price":"0.24", "size":"212", "side":"SELL", "hash":"5680793f0599c79b3dc2bfc3aa3b59be7465be46", "best_bid":"0.02", "best_ask":"0.03"}], "timestamp":"1770241471268", "event_type":"price_change"}
{"market":"0x38f3050258345e9cf363d1c8cc302f08c65b96ba1a4669d81e07ed69708344df", "price_changes":[{"asset_id":"96888240988495161476033313796107536512663280794332045579302109906525918376981", "price":"0.94", "size":"753", "side":"BUY", "hash":"d2f6226c542e2f312a0bb97c5f8bd39dd19a0b6f", "best_bid":"0.97", "best_ask":"0.98"}, {"asset_id":"81916206347121459497221114766050949090435061493822476265356047392175668050706", "price":"0.06", "size":"753", "side":"SELL", "hash":"fe6203d8f64bc1de51bf5e5036b585facbc48eb6", "best_bid":"0.02", "best_ask":"0.03"}], "timestamp":"1770241471281", "event_type":"price_change"}
{"market":"0x38f3050258345e9cf363d1c8cc302f08c65b96ba1a4669d81e07ed69708344df", "price_changes":[{"asset_id":"96888240988495161476033313796107536512663280794332045579302109906525918376981", "price":"0.95", "size":"671", "side":"BUY", "hash":"a1b66f8a81cbbd9d6c0f1169b592b88ab11b0194", "best_bid":"0.97", "best_ask":"0.98"}, {"asset_id":"81916206347121459497221114766050949090435061493822476265356047392175668050706", "price":"0.05", "size":"671", "side":"SELL", "hash":"f23aab7b15192e85a632219bdabdbea10e36cd7c", "best_bid":"0.02", "best_ask":"0.03"}], "timestamp":"1770241471282", "event_type":"price_change"}
{"market":"0x38f3050258345e9cf363d1c8cc302f08c65b96ba1a4669d81e07ed69708344df", "price_changes":[{"asset_id":"96888240988495161476033313796107536512663280794332045579302109906525918376981", "price":"0.95", "size":"644", "side":"BUY", "hash":"c15532248a9ddeddf99df6a83d9673d0854d0e41", "best_bid":"0.97", "best_ask":"0.98"}, {"asset_id":"81916206347121459497221114766050949090435061493822476265356047392175668050706", "price":"0.05", "size":"644", "side":"SELL", "hash":"e3a08f45c61287c9bcff67c516b4c3d76454b7e7", "best_bid":"0.02", "best_ask":"0.03"}], "timestamp":"1770241471292", "event_type":"price_change"}
{"market":"0x38f3050258345e9cf363d1c8cc302f08c65b96ba1a4669d81e07ed69708344df", "price_changes":[{"asset_id":"96888240988495161476033313796107536512663280794332045579302109906525918376981", "price":"0.94", "size":"780", "side":"BUY", "hash":"64881fd4371e91da75d193f2380ae2208d3da0ea", "best_bid":"0.97", "best_ask":"0.98"}, {"asset_id":"81916206347121459497221114766050949090435061493822476265356047392175668050706", "price":"0.06", "size":"780", "side":"SELL", "hash":"5a38d967cc3cc4323f684fde8c1a8c6c5a5b5057", "best_bid":"0.02", "best_ask":"0.03"}], "timestamp":"1770241471293", "event_type":"price_change"}
{"market":"0x38f3050258345e9cf363d1c8cc302f08c65b96ba1a4669d81e07ed69708344df", "price_changes":[{"asset_id":"96888240988495161476033313796107536512663280794332045579302109906525918376981", "price":"0.95", "size":"617", "side":"BUY", "hash":"6c9b32a0db5e50c3e9ead3d8901335bb7b3dd6fd", "best_bid":"0.97", "best_ask":"0.98"}, {"asset_id":"81916206347121459497221114766050949090435061493822476265356047392175668050706", "price":"0.05", "size":"617", "side":"SELL", "hash":"487b85a679f0a16486cf31c24fd314c89ad83797", "best_bid":"0.02", "best_ask":"0.03"}], "timestamp":"1770241471312", "event_type":"price_change"}
{"market":"0x38f3050258345e9cf363d1c8cc302f08c65b96ba1a4669d81e07ed69708344df", "price_changes":[{"asset_id":"96888240988495161476033313796107536512663280794332045579302109906525918376981", "price":"0.97", "size":"432", "side":"BUY", "hash":"40a6ebde4094deb46f48897fa93df06692c8f207", "best_bid":"0.97", "best_ask":"0.98"}, {"asset_id":"81916206347121459497221114766050949090435061493822476265356047392175668050706", "price":"0.03", "size":"432", "side":"SELL", "hash":"fcf83231cdc73e39a1398479ef9c860ccf4b0c76", "best_bid":"0.02", "best_ask":"0.03"}], "timestamp":"1770241471314", "event_type":"price_change"}
{"market":"0x38f3050258345e9cf363d1c8cc302f08c65b96ba1a4669d81e07ed69708344df", "price_changes":[{"asset_id":"96888240988495161476033313796107536512663280794332045579302109906525918376981", "price":"0.96", "size":"782.73", "side":"BUY", "hash":"d3de8fdf385f43db0cfe34eec3d475f1f6b48209", "best_bid":"0.97", "best_ask":"0.98"}, {"asset_id":"81916206347121459497221114766050949090435061493822476265356047392175668050706", "price":"0.04", "size":"782.73", "side":"SELL", "hash":"d7f57f96235e5e5086bc0b041d5afe8320cd5de6", "best_bid":"0.02", "best_ask":"0.03"}], "timestamp":"1770241471315", "event_type":"price_change"}
{"market":"0x38f3050258345e9cf363d1c8cc302f08c65b96ba1a4669d81e07ed69708344df", "price_changes":[{"asset_id":"96888240988495161476033313796107536512663280794332045579302109906525918376981", "price":"0.96", "size":"809.73", "side":"BUY", "hash":"bb00ee4ec098fe0a1296a282d316cb98857a4424", "best_bid":"0.97", "best_ask":"0.98"}, {"asset_id":"81916206347121459497221114766050949090435061493822476265356047392175668050706", "price":"0.04", "size":"809.73", "side":"SELL", "hash":"01cbc957020e4a4749db95bf3d6ddfc0c12112c9", "best_bid":"0.02", "best_ask":"0.03"}], "timestamp":"1770241471320", "event_type":"price_change"}
{"market":"0x38f3050258345e9cf363d1c8cc302f08c65b96ba1a4669d81e07ed69708344df", "price_changes":[{"asset_id":"96888240988495161476033313796107536512663280794332045579302109906525918376981", "price":"0.98", "size":"368.5", "side":"SELL", "hash":"89e049ae6bb589a83bf2bdbbd3412185359d6c46", "best_bid":"0.97", "best_ask":"0.98"}, {"asset_id":"81916206347121459497221114766050949090435061493822476265356047392175668050706", "price":"0.02", "size":"368.5", "side":"BUY", "hash":"31856da8d042ff2eea205d4bc71764021360edf3", "best_bid":"0.02", "best_ask":"0.03"}], "timestamp":"1770241471330", "event_type":"price_change"}
{"market":"0x38f3050258345e9cf363d1c8cc302f08c65b96ba1a4669d81e07ed69708344df", "price_changes":[{"asset_id":"96888240988495161476033313796107536512663280794332045579302109906525918376981", "price":"0.94", "size":"753", "side":"BUY", "hash":"e75a949352f0a2b80029c7bf3255066392d123c8", "best_bid":"0.97", "best_ask":"0.98"}, {"asset_id":"81916206347121459497221114766050949090435061493822476265356047392175668050706", "price":"0.06", "size":"753", "side":"SELL", "hash":"6b3cb913ad6461ade27c551a52c096e1088e5bdf", "best_bid":"0.02", "best_ask":"0.03"}], "timestamp":"1770241471404", "event_type":"price_change"}
{"market":"0x38f3050258345e9cf363d1c8cc302f08c65b96ba1a4669d81e07ed69708344df", "price_changes":[{"asset_id":"96888240988495161476033313796107536512663280794332045579302109906525918376981", "price":"0.95", "size":"644", "side":"BUY", "hash":"6806e99d5a2ef7ed9e0b13d470ee1640d56af2ee", "best_bid":"0.97", "best_ask":"0.98"}, {"asset_id":"81916206347121459497221114766050949090435061493822476265356047392175668050706", "price":"0.05", "size":"644", "side":"SELL", "hash":"fd67d0242eb06d13e2f6d70633f4fe08998f1ef1", "best_bid":"0.02", "best_ask":"0.03"}], "timestamp":"1770241471405", "event_type":"price_change"}
{"market":"0x38f3050258345e9cf363d1c8cc302f08c65b96ba1a4669d81e07ed69708344df", "price_changes":[{"asset_id":"96888240988495161476033313796107536512663280794332045579302109906525918376981", "price":"0.97", "size":"452", "side":"BUY", "hash":"d9f4ddcfe01d1ec64175ccab9dd863713cbfbde9", "best_bid":"0.97", "best_ask":"0.98"}, {"asset_id":"81916206347121459497221114766050949090435061493822476265356047392175668050706", "price":"0.03", "size":"452", "side":"SELL", "hash":"44b33c57e87645aca83ec8f207e65e9b69a2b8ff", "best_bid":"0.02", "best_ask":"0.03"}], "timestamp":"1770241471422", "event_type":"price_change"}
{"market":"0x38f3050258345e9cf363d1c8cc302f08c65b96ba1a4669d81e07ed69708344df", "price_changes":[{"asset_id":"96888240988495161476033313796107536512663280794332045579302109906525918376981", "price":"0.94", "size":"726", "side":"BUY", "hash":"a1f2b1e6575d21495ea8d0ebfb9fc11c28b2977a", "best_bid":"0.97", "best_ask":"0.98"}, {"asset_id":"81916206347121459497221114766050949090435061493822476265356047392175668050706", "price":"0.06", "size":"726", "side":"SELL", "hash":"75d718e741e9f30dd6165f8cd316a5640eed121e", "best_bid":"0.02", "best_ask":"0.03"}], "timestamp":"1770241471426", "event_type":"price_change"}
{"market":"0x38f3050258345e9cf363d1c8cc302f08c65b96ba1a4669d81e07ed69708344df", "price_changes":[{"asset_id":"96888240988495161476033313796107536512663280794332045579302109906525918376981", "price":"0.95", "size":"671", "side":"BUY", "hash":"44bace1ce7b4ba5ece80de7dc74a50b8e757849b", "best_bid":"0.97", "best_ask":"0.98"}, {"asset_id":"81916206347121459497221114766050949090435061493822476265356047392175668050706", "price":"0.05", "size":"671", "side":"SELL", "hash":"a509f835458c28a4bc0acf1e5e9218064d3a8e3e", "best_bid":"0.02", "best_ask":"0.03"}], "timestamp":"1770241471427", "event_type":"price_change"}
{"market":"0x38f3050258345e9cf363d1c8cc302f08c65b96ba1a4669d81e07ed69708344df", "price_changes":[{"asset_id":"96888240988495161476033313796107536512663280794332045579302109906525918376981", "price":"0.98", "size":"367", "side":"SELL", "hash":"87d4c0069669c56c002dc11cc6fa35778b5e497b", "best_bid":"0.97", "best_ask":"0.98"}, {"asset_id":"81916206347121459497221114766050949090435061493822476265356047392175668050706", "price":"0.02", "size":"367", "side":"BUY", "hash":"43ed9a7fe686fe4c5a5e79df27a663de3a98ae36", "best_bid":"0.02", "best_ask":"0.03"}], "timestamp":"1770241471449", "event_type":"price_change"}
{"market":"0x38f3050258345e9cf363d1c8cc302f08c65b96ba1a4669d81e07ed69708344df", "asset_id":"81916206347121459497221114766050949090435061493822476265356047392175668050706", "bids":[{"price":"0.01", "size":"4153.07"}, {"price":"0.02", "size":"367"}], "asks":[{"price":"0.99", "size":"5019.91"}, {"price":"0.98", "size":"3034.23"}, {"price":"0.97", "size":"3172"}, {"price":"0.96", "size":"3012"}, {"price":"0.95", "size":"3032"}, {"price":"0.94", "size":"3012"}, {"price":"0.93", "size":"3126.28"}, {"price":"0.92", "size":"3012"}, {"price":"0.91", "size":"3012"}, {"price":"0.9", "size":"3087"}, {"price":"0.89", "size":"12"}, {"price":"0.88", "size":"12"}, {"price":"0.87", "size":"12"}, {"price":"0.86", "size":"12"}, {"price":"0.85", "size":"12"}, {"price":"0.84", "size":"12"}, {"price":"0.83", "size":"12"}, {"price":"0.82", "size":"12"}, {"price":"0.81", "size":"12"}, {"price":"0.8", "size":"12"}, {"price":"0.79", "size":"12"}, {"price":"0.78", "size":"12"}, {"price":"0.77", "size":"12"}, {"price":"0.76", "size":"112"}, {"price":"0.75", "size":"40.57"}, {"price":"0.74", "size":"12"}, {"price":"0.73", "size":"293.25"}, {"price":"0.72", "size":"22"}, {"price":"0.71", "size":"12"}, {"price":"0.7", "size":"18"}, {"price":"0.69", "size":"12"}, {"price":"0.68", "size":"12"}, {"price":"0.67", "size":"12"}, {"price":"0.66", "size":"160.89"}, {"price":"0.65", "size":"12"}, {"price":"0.64", "size":"12"}, {"price":"0.63", "size":"12"}, {"price":"0.62", "size":"19.39"}, {"price":"0.61", "size":"18.04"}, {"price":"0.6", "size":"12"}, {"price":"0.59", "size":"94.31"}, {"price":"0.58", "size":"5450.54"}, {"price":"0.57", "size":"12"}, {"price":"0.56", "size":"12"}, {"price":"0.55", "size":"12"}, {"price":"0.54", "size":"22"}, {"price":"0.53", "size":"12"}, {"price":"0.52", "size":"12"}, {"price":"0.51", "size":"12"}, {"price":"0.5", "size":"12"}, {"price":"0.49", "size":"12"}, {"price":"0.48", "size":"12"}, {"price":"0.47", "size":"12"}, {"price":"0.46", "size":"485.56"}, {"price":"0.45", "size":"31"}, {"price":"0.44", "size":"17"}, {"price":"0.43", "size":"12"}, {"price":"0.42", "size":"12"}, {"price":"0.41", "size":"12"}, {"price":"0.4", "size":"127"}, {"price":"0.39", "size":"12"}, {"price":"0.38", "size":"94.51"}, {"price":"0.37", "size":"31.99"}, {"price":"0.36", "size":"12"}, {"price":"0.35", "size":"37"}, {"price":"0.34", "size":"12"}, {"price":"0.33", "size":"12"}, {"price":"0.32", "size":"12"}, {"price":"0.31", "size":"12"}, {"price":"0.3", "size":"31.9"}, {"price":"0.29", "size":"344"}, {"price":"0.28", "size":"3488.99"}, {"price":"0.27", "size":"212"}, {"price":"0.26", "size":"218"}, {"price":"0.25", "size":"712"}, {"price":"0.24", "size":"212"}, {"price":"0.23", "size":"212"}, {"price":"0.22", "size":"1223.14"}, {"price":"0.21", "size":"212"}, {"price":"0.2", "size":"272.99"}, {"price":"0.19", "size":"212"}, {"price":"0.18", "size":"212"}, {"price":"0.17", "size":"212"}, {"price":"0.16", "size":"812"}, {"price":"0.15", "size":"231.08"}, {"price":"0.14", "size":"283.65"}, {"price":"0.13", "size":"212"}, {"price":"0.12", "size":"252"}, {"price":"0.11", "size":"252"}, {"price":"0.1", "size":"746.71"}, {"price":"0.09", "size":"326"}, {"price":"0.08", "size":"844.68"}, {"price":"0.07", "size":"826"}, {"price":"0.06", "size":"726"}, {"price":"0.05", "size":"671"}, {"price":"0.04", "size":"809.73"}, {"price":"0.03", "size":"452"}], "hash":"43ed9a7fe686fe4c5a5e79df27a663de3a98ae36", "timestamp":"1770241471449", "event_type":"book"}
{"market":"0x38f3050258345e9cf363d1c8cc302f08c65b96ba1a4669d81e07ed69708344df", "price_changes":[{"asset_id":"96888240988495161476033313796107536512663280794332045579302109906525918376981", "price":"0.95", "size":"698", "side":"BUY", "hash":"12b3998df496bf4a2d4d2dd89e2e8fab765a06e4", "best_bid":"0.97", "best_ask":"0.98"}, {"asset_id":"81916206347121459497221114766050949090435061493822476265356047392175668050706", "price":"0.05", "size":"698", "side":"SELL", "hash":"22e39cfffefd4260d000827c4059ab65f1c4e94c", "best_bid":"0.02", "best_ask":"0.03"}], "timestamp":"1770241471485", "event_type":"price_change"}
{"market":"0x38f3050258345e9cf363d1c8cc302f08c65b96ba1a4669d81e07ed69708344df", "price_changes":[{"asset_id":"96888240988495161476033313796107536512663280794332045579302109906525918376981", "price":"0.96", "size":"782.73", "side":"BUY", "hash":"043a47c98bee6d5d9947cb5efe2c01ba6dde72f2", "best_bid":"0.97", "best_ask":"0.98"}, {"asset_id":"81916206347121459497221114766050949090435061493822476265356047392175668050706", "price":"0.04", "size":"782.73", "side":"SELL", "hash":"da106b385bbdad7c1e25ccdd5126040a5adbd628", "best_bid":"0.02", "best_ask":"0.03"}], "timestamp":"1770241471486", "event_type":"price_change"}
{"market":"0x38f3050258345e9cf363d1c8cc302f08c65b96ba1a4669d81e07ed69708344df", "price_changes":[{"asset_id":"96888240988495161476033313796107536512663280794332045579302109906525918376981", "price":"0.98", "size":"357", "side":"SELL", "hash":"f8cb981dc11142e96e18b97026ef7adcec6f7511", "best_bid":"0.97", "best_ask":"0.98"}, {"asset_id":"81916206347121459497221114766050949090435061493822476265356047392175668050706", "price":"0.02", "size":"357", "side":"BUY", "hash":"f915efc37a72d8b0ec917d6eb22a237d24c8f6b9", "best_bid":"0.02", "best_ask":"0.03"}], "timestamp":"1770241471514", "event_type":"price_change"}
{"market":"0x38f3050258345e9cf363d1c8cc302f08c65b96ba1a4669d81e07ed69708344df", "price_changes":[{"asset_id":"96888240988495161476033313796107536512663280794332045579302109906525918376981", "price":"0.94", "size":"753", "side":"BUY", "hash":"664729c3899ed57d58f12f2544a0b2c7246ce984", "best_bid":"0.97", "best_ask":"0.98"}, {"asset_id":"81916206347121459497221114766050949090435061493822476265356047392175668050706", "price":"0.06", "size":"753", "side":"SELL", "hash":"70a4e40dd8de0ff243c84b5a2111698f27cb8229", "best_bid":"0.02", "best_ask":"0.03"}], "timestamp":"1770241471529", "event_type":"price_change"}
{"market":"0x38f3050258345e9cf363d1c8cc302f08c65b96ba1a4669d81e07ed69708344df", "price_changes":[{"asset_id":"96888240988495161476033313796107536512663280794332045579302109906525918376981", "price":"0.95", "size":"671", "side":"BUY", "hash":"b3f60f57bca9f22ff8f28ee78284eb803495560c", "best_bid":"0.97", "best_ask":"0.98"}, {"asset_id":"81916206347121459497221114766050949090435061493822476265356047392175668050706", "price":"0.05", "size":"671", "side":"SELL", "hash":"26daf969b3961c944e152257970c1b24e48e81cf", "best_bid":"0.02", "best_ask":"0.03"}], "timestamp":"1770241471530", "event_type":"price_change"}
{"market":"0x38f3050258345e9cf363d1c8cc302f08c65b96ba1a4669d81e07ed69708344df", "price_changes":[{"asset_id":"96888240988495161476033313796107536512663280794332045579302109906525918376981", "price":"0.94", "size":"780", "side":"BUY", "hash":"1e8906e4f2b0213308c46a2f91152b1d2ee4e67b", "best_bid":"0.97", "best_ask":"0.98"}, {"asset_id":"81916206347121459497221114766050949090435061493822476265356047392175668050706", "price":"0.06", "size":"780", "side":"SELL", "hash":"2916a678d52e9f9fc10edb827f755b9c4d1d9628", "best_bid":"0.02", "best_ask":"0.03"}], "timestamp":"1770241471548", "event_type":"price_change"}
{"market":"0x38f3050258345e9cf363d1c8cc302f08c65b96ba1a4669d81e07ed69708344df", "price_changes":[{"asset_id":"96888240988495161476033313796107536512663280794332045579302109906525918376981", "price":"0.95", "size":"644", "side":"BUY", "hash":"011c26fb6be3d0098e38c32b6e08cb731022d93b", "best_bid":"0.97", "best_ask":"0.98"}, {"asset_id":"81916206347121459497221114766050949090435061493822476265356047392175668050706", "price":"0.05", "size":"644", "side":"SELL", "hash":"ba7f20fd7ff9487ea2f0e0656c885f7fe0415829", "best_bid":"0.02", "best_ask":"0.03"}], "timestamp":"1770241471556", "event_type":"price_change"}
{"market":"0x38f3050258345e9cf363d1c8cc302f08c65b96ba1a4669d81e07ed69708344df", "price_changes":[{"asset_id":"96888240988495161476033313796107536512663280794332045579302109906525918376981", "price":"0.97", "size":"451.75", "side":"BUY", "hash":"0612a2d477c98e55477dda23f65238d732d88495", "best_bid":"0.97", "best_ask":"0.98"}, {"asset_id":"81916206347121459497221114766050949090435061493822476265356047392175668050706", "price":"0.03", "size":"451.75", "side":"SELL", "hash":"3c0d042deded72536b0979e138911429c5645213", "best_bid":"0.02", "best_ask":"0.03"}], "timestamp":"1770241471599", "event_type":"price_change"}
{"market":"0x38f3050258345e9cf363d1c8cc302f08c65b96ba1a4669d81e07ed69708344df", "asset_id":"81916206347121459497221114766050949090435061493822476265356047392175668050706", "bids":[{"price":"0.01", "size":"4153.07"}, {"price":"0.02", "size":"357"}], "asks":[{"price":"0.99", "size":"5019.91"}, {"price":"0.98", "size":"3034.23"}, {"price":"0.97", "size":"3172"}, {"price":"0.96", "size":"3012"}, {"price":"0.95", "size":"3032"}, {"price":"0.94", "size":"3012"}, {"price":"0.93", "size":"3126.28"}, {"price":"0.92", "size":"3012"}, {"price":"0.91", "size":"3012"}, {"price":"0.9", "size":"3087"}, {"price":"0.89", "size":"12"}, {"price":"0.88", "size":"12"}, {"price":"0.87", "size":"12"}, {"price":"0.86", "size":"12"}, {"price":"0.85", "size":"12"}, {"price":"0.84", "size":"12"}, {"price":"0.83", "size":"12"}, {"price":"0.82", "size":"12"}, {"price":"0.81", "size":"12"}, {"price":"0.8", "size":"12"}, {"price":"0.79", "size":"12"}, {"price":"0.78", "size":"12"}, {"price":"0.77", "size":"12"}, {"price":"0.76", "size":"112"}, {"price":"0.75", "size":"40.57"}, {"price":"0.74", "size":"12"}, {"price":"0.73", "size":"293.25"}, {"price":"0.72", "size":"22"}, {"price":"0.71", "size":"12"}, {"price":"0.7", "size":"18"}, {"price":"0.69", "size":"12"}, {"price":"0.68", "size":"12"}, {"price":"0.67", "size":"12"}, {"price":"0.66", "size":"160.89"}, {"price":"0.65", "size":"12"}, {"price":"0.64", "size":"12"}, {"price":"0.63", "size":"12"}, {"price":"0.62", "size":"19.39"}, {"price":"0.61", "size":"18.04"}, {"price":"0.6", "size":"12"}, {"price":"0.59", "size":"94.31"}, {"price":"0.58", "size":"5450.54"}, {"price":"0.57", "size":"12"}, {"price":"0.56", "size":"12"}, {"price":"0.55", "size":"12"}, {"price":"0.54", "size":"22"}, {"price":"0.53", "size":"12"}, {"price":"0.52", "size":"12"}, {"price":"0.51", "size":"12"}, {"price":"0.5", "size":"12"}, {"price":"0.49", "size":"12"}, {"price":"0.48", "size":"12"}, {"price":"0.47", "size":"12"}, {"price":"0.46", "size":"485.56"}, {"price":"0.45", "size":"31"}, {"price":"0.44", "size":"17"}, {"price":"0.43", "size":"12"}, {"price":"0.42", "size":"12"}, {"price":"0.41", "size":"12"}, {"price":"0.4", "size":"127"}, {"price":"0.39", "size":"12"}, {"price":"0.38", "size":"94.51"}, {"price":"0.37", "size":"31.99"}, {"price":"0.36", "size":"12"}, {"price":"0.35", "size":"37"}, {"price":"0.34", "size":"12"}, {"price":"0.33", "size":"12"}, {"price":"0.32", "size":"12"}, {"price":"0.31", "size":"12"}, {"price":"0.3", "size":"31.9"}, {"price":"0.29", "size":"344"}, {"price":"0.28", "size":"3488.99"}, {"price":"0.27", "size":"212"}, {"price":"0.26", "size":"218"}, {"price":"0.25", "size":"712"}, {"price":"0.24", "size":"212"}, {"price":"0.23", "size":"212"}, {"price":"0.22", "size":"1223.14"}, {"price":"0.21", "size":"212"}, {"price":"0.2", "size":"272.99"}, {"price":"0.19", "size":"212"}, {"price":"0.18", "size":"212"}, {"price":"0.17", "size":"212"}, {"price":"0.16", "size":"812"}, {"price":"0.15", "size":"231.08"}, {"price":"0.14", "size":"283.65"}, {"price":"0.13", "size":"212"}, {"price":"0.12", "size":"252"}, {"price":"0.11", "size":"252"}, {"price":"0.1", "size":"746.71"}, {"price":"0.09", "size":"326"}, {"price":"0.08", "size":"844.68"}, {"price":"0.07", "size":"826"}, {"price":"0.06", "size":"780"}, {"price":"0.05", "size":"644"}, {"price":"0.04", "size":"782.73"}, {"price":"0.03", "size":"451.75"}], "hash":"3c0d042deded72536b0979e138911429c5645213", "timestamp":"1770241471599", "event_type":"book"}
{"market":"0x38f3050258345e9cf363d1c8cc302f08c65b96ba1a4669d81e07ed69708344df", "price_changes":[{"asset_id":"96888240988495161476033313796107536512663280794332045579302109906525918376981", "price":"0.97", "size":"451.32", "side":"BUY", "hash":"eee8a3dd70ec20762b22ee860e25bfb79e9c37ba", "best_bid":"0.97", "best_ask":"0.98"}, {"asset_id":"81916206347121459497221114766050949090435061493822476265356047392175668050706", "price":"0.03", "size":"451.32", "side":"SELL", "hash":"d8e43f2d1d7455f6cff79b380b54854bd2565d0b", "best_bid":"0.02", "best_ask":"0.03"}], "timestamp":"1770241471602", "event_type":"price_change"}
{"market":"0x38f3050258345e9cf363d1c8cc302f08c65b96ba1a4669d81e07ed69708344df", "asset_id":"81916206347121459497221114766050949090435061493822476265356047392175668050706", "bids":[{"price":"0.01", "size":"4153.07"}, {"price":"0.02", "size":"357"}], "asks":[{"price":"0.99", "size":"5019.91"}, {"price":"0.98", "size":"3034.23"}, {"price":"0.97", "size":"3172"}, {"price":"0.96", "size":"3012"}, {"price":"0.95", "size":"3032"}, {"price":"0.94", "size":"3012"}, {"price":"0.93", "size":"3126.28"}, {"price":"0.92", "size":"3012"}, {"price":"0.91", "size":"3012"}, {"price":"0.9", "size":"3087"}, {"price":"0.89", "size":"12"}, {"price":"0.88", "size":"12"}, {"price":"0.87", "size":"12"}, {"price":"0.86", "size":"12"}, {"price":"0.85", "size":"12"}, {"price":"0.84", "size":"12"}, {"price":"0.83", "size":"12"}, {"price":"0.82", "size":"12"}, {"price":"0.81", "size":"12"}, {"price":"0.8", "size":"12"}, {"price":"0.79", "size":"12"}, {"price":"0.78", "size":"12"}, {"price":"0.77", "size":"12"}, {"price":"0.76", "size":"112"}, {"price":"0.75", "size":"40.57"}, {"price":"0.74", "size":"12"}, {"price":"0.73", "size":"293.25"}, {"price":"0.72", "size":"22"}, {"price":"0.71", "size":"12"}, {"price":"0.7", "size":"18"}, {"price":"0.69", "size":"12"}, {"price":"0.68", "size":"12"}, {"price":"0.67", "size":"12"}, {"price":"0.66", "size":"160.89"}, {"price":"0.65", "size":"12"}, {"price":"0.64", "size":"12"}, {"price":"0.63", "size":"12"}, {"price":"0.62", "size":"19.39"}, {"price":"0.61", "size":"18.04"}, {"price":"0.6", "size":"12"}, {"price":"0.59", "size":"94.31"}, {"price":"0.58", "size":"5450.54"}, {"price":"0.57", "size":"12"}, {"price":"0.56", "size":"12"}, {"price":"0.55", "size":"12"}, {"price":"0.54", "size":"22"}, {"price":"0.53", "size":"12"}, {"price":"0.52", "size":"12"}, {"price":"0.51", "size":"12"}, {"price":"0.5", "size":"12"}, {"price":"0.49", "size":"12"}, {"price":"0.48", "size":"12"}, {"price":"0.47", "size":"12"}, {"price":"0.46", "size":"485.56"}, {"price":"0.45", "size":"31"}, {"price":"0.44", "size":"17"}, {"price":"0.43", "size":"12"}, {"price":"0.42", "size":"12"}, {"price":"0.41", "size":"12"}, {"price":"0.4", "size":"127"}, {"price":"0.39", "size":"12"}, {"price":"0.38", "size":"94.51"}, {"price":"0.37", "size":"31.99"}, {"price":"0.36", "size":"12"}, {"price":"0.35", "size":"37"}, {"price":"0.34", "size":"12"}, {"price":"0.33", "size":"12"}, {"price":"0.32", "size":"12"}, {"price":"0.31", "size":"12"}, {"price":"0.3", "size":"31.9"}, {"price":"0.29", "size":"344"}, {"price":"0.28", "size":"3488.99"}, {"price":"0.27", "size":"212"}, {"price":"0.26", "size":"218"}, {"price":"0.25", "size":"712"}, {"price":"0.24", "size":"212"}, {"price":"0.23", "size":"212"}, {"price":"0.22", "size":"1223.14"}, {"price":"0.21", "size":"212"}, {"price":"0.2", "size":"272.99"}, {"price":"0.19", "size":"212"}, {"price":"0.18", "size":"212"}, {"price":"0.17", "size":"212"}, {"price":"0.16", "size":"812"}, {"price":"0.15", "size":"231.08"}, {"price":"0.14", "size":"283.65"}, {"price":"0.13", "size":"212"}, {"price":"0.12", "size":"252"}, {"price":"0.11", "size":"252"}, {"price":"0.1", "size":"746.71"}, {"price":"0.09", "size":"326"}, {"price":"0.08", "size":"844.68"}, {"price":"0.07", "size":"826"}, {"price":"0.06", "size":"780"}, {"price":"0.05", "size":"644"}, {"price":"0.04", "size":"782.73"}, {"price":"0.03", "size":"451.32"}], "hash":"d8e43f2d1d7455f6cff79b380b54854bd2565d0b", "timestamp":"1770241471602", "event_type":"book"}
{"market":"0x38f3050258345e9cf363d1c8cc302f08c65b96ba1a4669d81e07ed69708344df", "price_changes":[{"asset_id":"96888240988495161476033313796107536512663280794332045579302109906525918376981", "price":"0.96", "size":"759.73", "side":"BUY", "hash":"8ff9b0a180e14be18302ea487f8e066c5e77606e", "best_bid":"0.97", "best_ask":"0.98"}, {"asset_id":"81916206347121459497221114766050949090435061493822476265356047392175668050706", "price":"0.04", "size":"759.73", "side":"SELL", "hash":"5434f49ae83d9f470931b2b793dfefa73bd291ac", "best_bid":"0.02", "best_ask":"0.03"}], "timestamp":"1770241471642", "event_type":"price_change"}
{"market":"0x38f3050258345e9cf363d1c8cc302f08c65b96ba1a4669d81e07ed69708344df", "price_changes":[{"asset_id":"96888240988495161476033313796107536512663280794332045579302109906525918376981", "price":"0.97", "size":"474.32", "side":"BUY", "hash":"10faacd7229a2092c5f86a2ba1eef8aff8b04465", "best_bid":"0.97", "best_ask":"0.98"}, {"asset_id":"81916206347121459497221114766050949090435061493822476265356047392175668050706", "price":"0.03", "size":"474.32", "side":"SELL", "hash":"a66b414baf234ec15496ddf2903d581a338503fe", "best_bid":"0.02", "best_ask":"0.03"}], "timestamp":"1770241471643", "event_type":"price_change"}
{"market":"0x38f3050258345e9cf363d1c8cc302f08c65b96ba1a4669d81e07ed69708344df", "price_changes":[{"asset_id":"96888240988495161476033313796107536512663280794332045579302109906525918376981", "price":"0.94", "size":"753", "side":"BUY", "hash":"fdfb09ec67f965eb6b09cce1da3325c0fe3ccdcc", "best_bid":"0.97", "best_ask":"0.98"}, {"asset_id":"81916206347121459497221114766050949090435061493822476265356047392175668050706", "price":"0.06", "size":"753", "side":"SELL", "hash":"bcd7f4d8f6136d3a6d3a8b0719988eab9625c369", "best_bid":"0.02", "best_ask":"0.03"}], "timestamp":"1770241471646", "event_type":"price_change"}
{"market":"0x38f3050258345e9cf363d1c8cc302f08c65b96ba1a4669d81e07ed69708344df", "price_changes":[{"asset_id":"96888240988495161476033313796107536512663280794332045579302109906525918376981", "price":"0.95", "size":"671", "side":"BUY", "hash":"3f6cb58c18b4884911edbbafbb3655d62978b72b", "best_bid":"0.97", "best_ask":"0.98"}, {"asset_id":"81916206347121459497221114766050949090435061493822476265356047392175668050706", "price":"0.05", "size":"671", "side":"SELL", "hash":"b31d40b34a3de880a0112298a737aef76418e95c", "best_bid":"0.02", "best_ask":"0.03"}], "timestamp":"1770241471648", "event_type":"price_change"}
{"market":"0x38f3050258345e9cf363d1c8cc302f08c65b96ba1a4669d81e07ed69708344df", "price_changes":[{"asset_id":"96888240988495161476033313796107536512663280794332045579302109906525918376981", "price":"0.96", "size":"786.73", "side":"BUY", "hash":"d6b844e25a3578d0be3e9ba61e911e99df29e4d8", "best_bid":"0.97", "best_ask":"0.98"}, {"asset_id":"81916206347121459497221114766050949090435061493822476265356047392175668050706", "price":"0.04", "size":"786.73", "side":"SELL", "hash":"61a08aaf17fc2991302544719aec37211f40a217", "best_bid":"0.02", "best_ask":"0.03"}], "timestamp":"1770241471656", "event_type":"price_change"}
{"market":"0x38f3050258345e9cf363d1c8cc302f08c65b96ba1a4669d81e07ed69708344df", "price_changes":[{"asset_id":"96888240988495161476033313796107536512663280794332045579302109906525918376981", "price":"0.95", "size":"644", "side":"BUY", "hash":"5cb0381358b87bdece879f79b1b6440db2cb33d4", "best_bid":"0.97", "best_ask":"0.98"}, {"asset_id":"81916206347121459497221114766050949090435061493822476265356047392175668050706", "price":"0.05", "size":"644", "side":"SELL", "hash":"5587038774b89aa127a0097868baa47e231658f4", "best_bid":"0.02", "best_ask":"0.03"}], "timestamp":"1770241471658", "event_type":"price_change"}
{"market":"0x38f3050258345e9cf363d1c8cc302f08c65b96ba1a4669d81e07ed69708344df", "price_changes":[{"asset_id":"96888240988495161476033313796107536512663280794332045579302109906525918376981", "price":"0.94", "size":"726", "side":"BUY", "hash":"209df879330df9eb368cd12537a5e3311cbab0f4", "best_bid":"0.97", "best_ask":"0.98"}, {"asset_id":"81916206347121459497221114766050949090435061493822476265356047392175668050706", "price":"0.06", "size":"726", "side":"SELL", "hash":"376ba1bb20a28aca27c93bf7796bb1f5244b8fd0", "best_bid":"0.02", "best_ask":"0.03"}], "timestamp":"1770241471680", "event_type":"price_change"}
{"market":"0x38f3050258345e9cf363d1c8cc302f08c65b96ba1a4669d81e07ed69708344df", "price_changes":[{"asset_id":"96888240988495161476033313796107536512663280794332045579302109906525918376981", "price":"0.95", "size":"671", "side":"BUY", "hash":"adf609fad9bcf79c264201a6297d13a73aeebdb8", "best_bid":"0.97", "best_ask":"0.98"}, {"asset_id":"81916206347121459497221114766050949090435061493822476265356047392175668050706", "price":"0.05", "size":"671", "side":"SELL", "hash":"264ce3ee29b614eaeeb52dd2e56747800b9d7071", "best_bid":"0.02", "best_ask":"0.03"}], "timestamp":"1770241471683", "event_type":"price_change"}
{"market":"0x38f3050258345e9cf363d1c8cc302f08c65b96ba1a4669d81e07ed69708344df", "price_changes":[{"asset_id":"96888240988495161476033313796107536512663280794332045579302109906525918376981", "price":"0.97", "size":"454.32", "side":"BUY", "hash":"2c9f01059cb4d17040207296a479edf27860ade2", "best_bid":"0.97", "best_ask":"0.98"}, {"asset_id":"81916206347121459497221114766050949090435061493822476265356047392175668050706", "price":"0.03", "size":"454.32", "side":"SELL", "hash":"5d52ef94195ae9803b0007cf2bd6c0ecd0ac01bb", "best_bid":"0.02", "best_ask":"0.03"}], "timestamp":"1770241471789", "event_type":"price_change"}
{"market":"0x38f3050258345e9cf363d1c8cc302f08c65b96ba1a4669d81e07ed69708344df", "price_changes":[{"asset_id":"96888240988495161476033313796107536512663280794332045579302109906525918376981", "price":"0.97", "size":"431.32", "side":"BUY", "hash":"5c06bee4ac3e0602e160063184a5b6006ec495f2", "best_bid":"0.97", "best_ask":"0.98"}, {"asset_id":"81916206347121459497221114766050949090435061493822476265356047392175668050706", "price":"0.03", "size":"431.32", "side":"SELL", "hash":"afe45c86d535ee756a7951e6869402635c50f90a", "best_bid":"0.02", "best_ask":"0.03"}], "timestamp":"1770241471797", "event_type":"price_change"}
{"market":"0x38f3050258345e9cf363d1c8cc302f08c65b96ba1a4669d81e07ed69708344df", "price_changes":[{"asset_id":"96888240988495161476033313796107536512663280794332045579302109906525918376981", "price":"0.96", "size":"809.73", "side":"BUY", "hash":"a3ba3d14e9223ae63763e2a686eb903a502cea60", "best_bid":"0.97", "best_ask":"0.98"}, {"asset_id":"81916206347121459497221114766050949090435061493822476265356047392175668050706", "price":"0.04", "size":"809.73", "side":"SELL", "hash":"395611a2d8fcc174759c5acc327aacd66c058ba6", "best_bid":"0.02", "best_ask":"0.03"}], "timestamp":"1770241471798", "event_type":"price_change"}
{"market":"0x38f3050258345e9cf363d1c8cc302f08c65b96ba1a4669d81e07ed69708344df", "price_changes":[{"asset_id":"96888240988495161476033313796107536512663280794332045579302109906525918376981", "price":"0.98", "size":"352", "side":"SELL", "hash":"66e338081699ddf20e10386874953564ba40c751", "best_bid":"0.97", "best_ask":"0.98"}, {"asset_id":"81916206347121459497221114766050949090435061493822476265356047392175668050706", "price":"0.02", "size":"352", "side":"BUY", "hash":"710139f41cc65ce3d5c34f28210020d43b7294ec", "best_bid":"0.02", "best_ask":"0.03"}], "timestamp":"1770241471870", "event_type":"price_change"}
{"market":"0x38f3050258345e9cf363d1c8cc302f08c65b96ba1a4669d81e07ed69708344df", "asset_id":"81916206347121459497221114766050949090435061493822476265356047392175668050706", "bids":[{"price":"0.01", "size":"4153.07"}, {"price":"0.02", "size":"352"}], "asks":[{"price":"0.99", "size":"5019.91"}, {"price":"0.98", "size":"3034.23"}, {"price":"0.97", "size":"3172"}, {"price":"0.96", "size":"3012"}, {"price":"0.95", "size":"3032"}, {"price":"0.94", "size":"3012"}, {"price":"0.93", "size":"3126.28"}, {"price":"0.92", "size":"3012"}, {"price":"0.91", "size":"3012"}, {"price":"0.9", "size":"3087"}, {"price":"0.89", "size":"12"}, {"price":"0.88", "size":"12"}, {"price":"0.87", "size":"12"}, {"price":"0.86", "size":"12"}, {"price":"0.85", "size":"12"}, {"price":"0.84", "size":"12"}, {"price":"0.83", "size":"12"}, {"price":"0.82", "size":"12"}, {"price":"0.81", "size":"12"}, {"price":"0.8", "size":"12"}, {"price":"0.79", "size":"12"}, {"price":"0.78", "size":"12"}, {"price":"0.77", "size":"12"}, {"price":"0.76", "size":"112"}, {"price":"0.75", "size":"40.57"}, {"price":"0.74", "size":"12"}, {"price":"0.73", "size":"293.25"}, {"price":"0.72", "size":"22"}, {"price":"0.71", "size":"12"}, {"price":"0.7", "size":"18"}, {"price":"0.69", "size":"12"}, {"price":"0.68", "size":"12"}, {"price":"0.67", "size":"12"}, {"price":"0.66", "size":"160.89"}, {"price":"0.65", "size":"12"}, {"price":"0.64", "size":"12"}, {"price":"0.63", "size":"12"}, {"price":"0.62", "size":"19.39"}, {"price":"0.61", "size":"18.04"}, {"price":"0.6", "size":"12"}, {"price":"0.59", "size":"94.31"}, {"price":"0.58", "size":"5450.54"}, {"price":"0.57", "size":"12"}, {"price":"0.56", "size":"12"}, {"price":"0.55", "size":"12"}, {"price":"0.54", "size":"22"}, {"price":"0.53", "size":"12"}, {"price":"0.52", "size":"12"}, {"price":"0.51", "size":"12"}, {"price":"0.5", "size":"12"}, {"price":"0.49", "size":"12"}, {"price":"0.48", "size":"12"}, {"price":"0.47", "size":"12"}, {"price":"0.46", "size":"485.56"}, {"price":"0.45", "size":"31"}, {"price":"0.44", "size":"17"}, {"price":"0.43", "size":"12"}, {"price":"0.42", "size":"12"}, {"price":"0.41", "size":"12"}, {"price":"0.4", "size":"127"}, {"price":"0.39", "size":"12"}, {"price":"0.38", "size":"94.51"}, {"price":"0.37", "size":"31.99"}, {"price":"0.36", "size":"12"}, {"price":"0.35", "size":"37"}, {"price":"0.34", "size":"12"}, {"price":"0.33", "size":"12"}, {"price":"0.32", "size":"12"}, {"price":"0.31", "size":"12"}, {"price":"0.3", "size":"31.9"}, {"price":"0.29", "size":"344"}, {"price":"0.28", "size":"3488.99"}, {"price":"0.27", "size":"212"}, {"price":"0.26", "size":"218"}, {"price":"0.25", "size":"712"}, {"price":"0.24", "size":"212"}, {"price":"0.23", "size":"212"}, {"price":"0.22", "size":"1223.14"}, {"price":"0.21", "size":"212"}, {"price":"0.2", "size":"272.99"}, {"price":"0.19", "size":"212"}, {"price":"0.18", "size":"212"}, {"price":"0.17", "size":"212"}, {"price":"0.16", "size":"812"}, {"price":"0.15", "size":"231.08"}, {"price":"0.14", "size":"283.65"}, {"price":"0.13", "size":"212"}, {"price":"0.12", "size":"252"}, {"price":"0.11", "size":"252"}, {"price":"0.1", "size":"746.71"}, {"price":"0.09", "size":"326"}, {"price":"0.08", "size":"844.68"}, {"price":"0.07", "size":"826"}, {"price":"0.06", "size":"726"}, {"price":"0.05", "size":"671"}, {"price":"0.04", "size":"809.73"}, {"price":"0.03", "size":"431.32"}], "hash":"710139f41cc65ce3d5c34f28210020d43b7294ec", "timestamp":"1770241471870", "event_type":"book"}
{"market":"0x38f3050258345e9cf363d1c8cc302f08c65b96ba1a4669d81e07ed69708344df", "price_changes":[{"asset_id":"96888240988495161476033313796107536512663280794332045579302109906525918376981", "price":"0.97", "size":"454.32", "side":"BUY", "hash":"0043faba301b643c8efb9a2c7747a6484531e1e3", "best_bid":"0.97", "best_ask":"0.98"}, {"asset_id":"81916206347121459497221114766050949090435061493822476265356047392175668050706", "price":"0.03", "size":"454.32", "side":"SELL", "hash":"99f310bd81c252a7ae3a5ac000fcf15b78184b69", "best_bid":"0.02", "best_ask":"0.03"}], "timestamp":"1770241471990", "event_type":"price_change"}
{"market":"0x38f3050258345e9cf363d1c8cc302f08c65b96ba1a4669d81e07ed69708344df", "price_changes":[{"asset_id":"96888240988495161476033313796107536512663280794332045579302109906525918376981", "price":"0.96", "size":"786.73", "side":"BUY", "hash":"0845607bfab2d39cd6376a787220965d17901f2e", "best_bid":"0.97", "best_ask":"0.98"}, {"asset_id":"81916206347121459497221114766050949090435061493822476265356047392175668050706", "price":"0.04", "size":"786.73", "side":"SELL", "hash":"c50426040e437cc2a82ae00e270fe2683398c4c6", "best_bid":"0.02", "best_ask":"0.03"}], "timestamp":"1770241471991", "event_type":"price_change"}
{"market":"0x38f3050258345e9cf363d1c8cc302f08c65b96ba1a4669d81e07ed69708344df", "price_changes":[{"asset_id":"96888240988495161476033313796107536512663280794332045579302109906525918376981", "price":"0.95", "size":"644", "side":"BUY", "hash":"c2bf81ea1626c3cc7d607815768bf06790461cfc", "best_bid":"0.97", "best_ask":"0.98"}, {"asset_id":"81916206347121459497221114766050949090435061493822476265356047392175668050706", "price":"0.05", "size":"644", "side":"SELL", "hash":"d1ba6c51fc76a7f8704333c6a1b6867ba7930be0", "best_bid":"0.02", "best_ask":"0.03"}], "timestamp":"1770241471991", "event_type":"price_change"}
{"market":"0x38f3050258345e9cf363d1c8cc302f08c65b96ba1a4669d81e07ed69708344df", "price_changes":[{"asset_id":"81916206347121459497221114766050949090435061493822476265356047392175668050706", "price":"0.01", "size":"4179.07", "side":"BUY", "hash":"00cf05be802b24e704cb013e8813813c0e775685", "best_bid":"0.02", "best_ask":"0.03"}, {"asset_id":"96888240988495161476033313796107536512663280794332045579302109906525918376981", "price":"0.99", "size":"4179.07", "side":"SELL", "hash":"244efca95ff6c2c28a76a9e6d78df236b67f6f97", "best_bid":"0.97", "best_ask":"0.98"}], "timestamp":"1770241471996", "event_type":"price_change"}
{"market":"0x38f3050258345e9cf363d1c8cc302f08c65b96ba1a4669d81e07ed69708344df", "price_changes":[{"asset_id":"81916206347121459497221114766050949090435061493822476265356047392175668050706", "price":"0.01", "size":"4205.07", "side":"BUY", "hash":"75e36d8191f45084145a704d4f89e48d31eb6fe1", "best_bid":"0.02", "best_ask":"0.03"}, {"asset_id":"96888240988495161476033313796107536512663280794332045579302109906525918376981", "price":"0.99", "size":"4205.07", "side":"SELL", "hash":"d730ff946cad4f665d41a1d032534bb614425a9f", "best_bid":"0.97", "best_ask":"0.98"}], "timestamp":"1770241471999", "event_type":"price_change"}
{"market":"0x38f3050258345e9cf363d1c8cc302f08c65b96ba1a4669d81e07ed69708344df", "price_changes":[{"asset_id":"96888240988495161476033313796107536512663280794332045579302109906525918376981", "price":"0.94", "size":"753", "side":"BUY", "hash":"2038f79e89b348c601e250d62aba2e4128b4cf6d", "best_bid":"0.97", "best_ask":"0.98"}, {"asset_id":"81916206347121459497221114766050949090435061493822476265356047392175668050706", "price":"0.06", "size":"753", "side":"SELL", "hash":"7b6550b8743bb81d65dc98326b62ebd637660b5d", "best_bid":"0.02", "best_ask":"0.03"}], "timestamp":"1770241472001", "event_type":"price_change"}
{"market":"0x38f3050258345e9cf363d1c8cc302f08c65b96ba1a4669d81e07ed69708344df", "price_changes":[{"asset_id":"96888240988495161476033313796107536512663280794332045579302109906525918376981", "price":"0.94", "size":"780", "side":"BUY", "hash":"5da23ad5dc5302f09f0f0dd67de5f1d884593afc", "best_bid":"0.97", "best_ask":"0.98"}, {"asset_id":"81916206347121459497221114766050949090435061493822476265356047392175668050706", "price":"0.06", "size":"780", "side":"SELL", "hash":"03d135a1c3dae38d963964976abdd7c37a465f06", "best_bid":"0.02", "best_ask":"0.03"}], "timestamp":"1770241472004", "event_type":"price_change"}
{"market":"0x38f3050258345e9cf363d1c8cc302f08c65b96ba1a4669d81e07ed69708344df", "price_changes":[{"asset_id":"96888240988495161476033313796107536512663280794332045579302109906525918376981", "price":"0.95", "size":"617", "side":"BUY", "hash":"1302537486ec3e0793ef283371f343eefcb97c27", "best_bid":"0.97", "best_ask":"0.98"}, {"asset_id":"81916206347121459497221114766050949090435061493822476265356047392175668050706", "price":"0.05", "size":"617", "side":"SELL", "hash":"5fb897e237d2a944b4ed2b5f6dcd6ca36d5d44d2", "best_bid":"0.02", "best_ask":"0.03"}], "timestamp":"1770241472004", "event_type":"price_change"}
{"market":"0x38f3050258345e9cf363d1c8cc302f08c65b96ba1a4669d81e07ed69708344df", "price_changes":[{"asset_id":"81916206347121459497221114766050949090435061493822476265356047392175668050706", "price":"0.01", "size":"4231.07", "side":"BUY", "hash":"4a3e17544deaa8f842e48fb2d7a7e911d0412aa9", "best_bid":"0.02", "best_ask":"0.03"}, {"asset_id":"96888240988495161476033313796107536512663280794332045579302109906525918376981", "price":"0.99", "size":"4231.07", "side":"SELL", "hash":"624c993333740fe551a7eed4c2331c1636335d30", "best_bid":"0.97", "best_ask":"0.98"}], "timestamp":"1770241472007", "event_type":"price_change"}
{"market":"0x38f3050258345e9cf363d1c8cc302f08c65b96ba1a4669d81e07ed69708344df", "price_changes":[{"asset_id":"96888240988495161476033313796107536512663280794332045579302109906525918376981", "price":"0.96", "size":"759.73", "side":"BUY", "hash":"f0e4b73889db39b1a5ff02304a0bbfeb1fec2703", "best_bid":"0.97", "best_ask":"0.98"}, {"asset_id":"81916206347121459497221114766050949090435061493822476265356047392175668050706", "price":"0.04", "size":"759.73", "side":"SELL", "hash":"57820310377b1abfb9deeaac213386814e427e86", "best_bid":"0.02", "best_ask":"0.03"}], "timestamp":"1770241472010", "event_type":"price_change"}
{"market":"0x38f3050258345e9cf363d1c8cc302f08c65b96ba1a4669d81e07ed69708344df", "price_changes":[{"asset_id":"96888240988495161476033313796107536512663280794332045579302109906525918376981", "price":"0.93", "size":"326", "side":"BUY", "hash":"98f73a18d7ffef237059dc60b650675dfb0fd692", "best_bid":"0.97", "best_ask":"0.98"}, {"asset_id":"81916206347121459497221114766050949090435061493822476265356047392175668050706", "price":"0.07", "size":"326", "side":"SELL", "hash":"bf6339bad2d8160226e08ad9fddbfd2d23d4f124", "best_bid":"0.02", "best_ask":"0.03"}], "timestamp":"1770241472011", "event_type":"price_change"}
{"market":"0x38f3050258345e9cf363d1c8cc302f08c65b96ba1a4669d81e07ed69708344df", "price_changes":[{"asset_id":"96888240988495161476033313796107536512663280794332045579302109906525918376981", "price":"0.95", "size":"644", "side":"BUY", "hash":"70eaf25b425c67e8d3e06f41bf6f0ae2add19a79", "best_bid":"0.97", "best_ask":"0.98"}, {"asset_id":"81916206347121459497221114766050949090435061493822476265356047392175668050706", "price":"0.05", "size":"644", "side":"SELL", "hash":"249417f9b9347b6b1cb80691c0bc0c8eee3ef647", "best_bid":"0.02", "best_ask":"0.03"}], "timestamp":"1770241472015", "event_type":"price_change"}
{"market":"0x38f3050258345e9cf363d1c8cc302f08c65b96ba1a4669d81e07ed69708344df", "price_changes":[{"asset_id":"81916206347121459497221114766050949090435061493822476265356047392175668050706", "price":"0.01", "size":"4205.07", "side":"BUY", "hash":"0e667beef1c832b9df345305cd9e3c486c1d5729", "best_bid":"0.02", "best_ask":"0.03"}, {"asset_id":"96888240988495161476033313796107536512663280794332045579302109906525918376981", "price":"0.99", "size":"4205.07", "side":"SELL", "hash":"56109de2d03c481a3d1e137fd206f26ad81cce6f", "best_bid":"0.97", "best_ask":"0.98"}], "timestamp":"1770241472019", "event_type":"price_change"}
{"market":"0x38f3050258345e9cf363d1c8cc302f08c65b96ba1a4669d81e07ed69708344df", "price_changes":[{"asset_id":"81916206347121459497221114766050949090435061493822476265356047392175668050706", "price":"0.01", "size":"4179.07", "side":"BUY", "hash":"f432e010ddec38bfc3229aed2cf4a0621f61375b", "best_bid":"0.02", "best_ask":"0.03"}, {"asset_id":"96888240988495161476033313796107536512663280794332045579302109906525918376981", "price":"0.99", "size":"4179.07", "side":"SELL", "hash":"31a4d887e64f79193caaba43d354473c40d490f3", "best_bid":"0.97", "best_ask":"0.98"}], "timestamp":"1770241472024", "event_type":"price_change"}
{"market":"0x38f3050258345e9cf363d1c8cc302f08c65b96ba1a4669d81e07ed69708344df", "price_changes":[{"asset_id":"81916206347121459497221114766050949090435061493822476265356047392175668050706", "price":"0.01", "size":"4153.07", "side":"BUY", "hash":"1a73399c35098c50f08f5e50c3a008ea57ec2370", "best_bid":"0.02", "best_ask":"0.03"}, {"asset_id":"96888240988495161476033313796107536512663280794332045579302109906525918376981", "price":"0.99", "size":"4153.07", "side":"SELL", "hash":"22cdbaa58d74eade977ffa6502d99082d8fe5ae9", "best_bid":"0.97", "best_ask":"0.98"}], "timestamp":"1770241472029", "event_type":"price_change"}
{"market":"0x38f3050258345e9cf363d1c8cc302f08c65b96ba1a4669d81e07ed69708344df", "price_changes":[{"asset_id":"96888240988495161476033313796107536512663280794332045579302109906525918376981", "price":"0.93", "size":"826", "side":"BUY", "hash":"4d86f780cedb9f6a92d9e24517ef825efe3e94d0", "best_bid":"0.97", "best_ask":"0.98"}, {"asset_id":"81916206347121459497221114766050949090435061493822476265356047392175668050706", "price":"0.07", "size":"826", "side":"SELL", "hash":"293d4ebb5ed4769b256a7fc6af527399aabdf29a", "best_bid":"0.02", "best_ask":"0.03"}], "timestamp":"1770241472107", "event_type":"price_change"}
{"market":"0x38f3050258345e9cf363d1c8cc302f08c65b96ba1a4669d81e07ed69708344df", "price_changes":[{"asset_id":"96888240988495161476033313796107536512663280794332045579302109906525918376981", "price":"0.97", "size":"431.32", "side":"BUY", "hash":"a9878914ac60c194a5693adb15db30c27d478d5a", "best_bid":"0.97", "best_ask":"0.98"}, {"asset_id":"81916206347121459497221114766050949090435061493822476265356047392175668050706", "price":"0.03", "size":"431.32", "side":"SELL", "hash":"3da5ea7ca6d766bf5e967dd8f3b56428b2e0eaac", "best_bid":"0.02", "best_ask":"0.03"}], "timestamp":"1770241472140", "event_type":"price_change"}
{"market":"0x38f3050258345e9cf363d1c8cc302f08c65b96ba1a4669d81e07ed69708344df", "price_changes":[{"asset_id":"96888240988495161476033313796107536512663280794332045579302109906525918376981", "price":"0.96", "size":"782.73", "side":"BUY", "hash":"f581a9793fa0f8c9ed22a2134001a4c1d9bb1095", "best_bid":"0.97", "best_ask":"0.98"}, {"asset_id":"81916206347121459497221114766050949090435061493822476265356047392175668050706", "price":"0.04", "size":"782.73", "side":"SELL", "hash":"87e1a7e92d4a00832bff8a90c8f0bff1f4c82626", "best_bid":"0.02", "best_ask":"0.03"}], "timestamp":"1770241472142", "event_type":"price_change"}
{"market":"0x38f3050258345e9cf363d1c8cc302f08c65b96ba1a4669d81e07ed69708344df", "price_changes":[{"asset_id":"96888240988495161476033313796107536512663280794332045579302109906525918376981", "price":"0.98", "size":"350.5", "side":"SELL", "hash":"812d9745e53ffb93e6760d29cf1724f1e3932c6f", "best_bid":"0.97", "best_ask":"0.98"}, {"asset_id":"81916206347121459497221114766050949090435061493822476265356047392175668050706", "price":"0.02", "size":"350.5", "side":"BUY", "hash":"750553e1875e709b12c87f0abe01f95d187c0348", "best_bid":"0.02", "best_ask":"0.03"}], "timestamp":"1770241472157", "event_type":"price_change"}
{"market":"0x38f3050258345e9cf363d1c8cc302f08c65b96ba1a4669d81e07ed69708344df", "asset_id":"81916206347121459497221114766050949090435061493822476265356047392175668050706", "bids":[{"price":"0.01", "size":"4153.07"}, {"price":"0.02", "size":"350.5"}], "asks":[{"price":"0.99", "size":"5019.91"}, {"price":"0.98", "size":"3034.23"}, {"price":"0.97", "size":"3172"}, {"price":"0.96", "size":"3012"}, {"price":"0.95", "size":"3032"}, {"price":"0.94", "size":"3012"}, {"price":"0.93", "size":"3126.28"}, {"price":"0.92", "size":"3012"}, {"price":"0.91", "size":"3012"}, {"price":"0.9", "size":"3087"}, {"price":"0.89", "size":"12"}, {"price":"0.88", "size":"12"}, {"price":"0.87", "size":"12"}, {"price":"0.86", "size":"12"}, {"price":"0.85", "size":"12"}, {"price":"0.84", "size":"12"}, {"price":"0.83", "size":"12"}, {"price":"0.82", "size":"12"}, {"price":"0.81", "size":"12"}, {"price":"0.8", "size":"12"}, {"price":"0.79", "size":"12"}, {"price":"0.78", "size":"12"}, {"price":"0.77", "size":"12"}, {"price":"0.76", "size":"112"}, {"price":"0.75", "size":"40.57"}, {"price":"0.74", "size":"12"}, {"price":"0.73", "size":"293.25"}, {"price":"0.72", "size":"22"}, {"price":"0.71", "size":"12"}, {"price":"0.7", "size":"18"}, {"price":"0.69", "size":"12"}, {"price":"0.68", "size":"12"}, {"price":"0.67", "size":"12"}, {"price":"0.66", "size":"160.89"}, {"price":"0.65", "size":"12"}, {"price":"0.64", "size":"12"}, {"price":"0.63", "size":"12"}, {"price":"0.62", "size":"19.39"}, {"price":"0.61", "size":"18.04"}, {"price":"0.6", "size":"12"}, {"price":"0.59", "size":"94.31"}, {"price":"0.58", "size":"5450.54"}, {"price":"0.57", "size":"12"}, {"price":"0.56", "size":"12"}, {"price":"0.55", "size":"12"}, {"price":"0.54", "size":"22"}, {"price":"0.53", "size":"12"}, {"price":"0.52", "size":"12"}, {"price":"0.51", "size":"12"}, {"price":"0.5", "size":"12"}, {"price":"0.49", "size":"12"}, {"price":"0.48", "size":"12"}, {"price":"0.47", "size":"12"}, {"price":"0.46", "size":"485.56"}, {"price":"0.45", "size":"31"}, {"price":"0.44", "size":"17"}, {"price":"0.43", "size":"12"}, {"price":"0.42", "size":"12"}, {"price":"0.41", "size":"12"}, {"price":"0.4", "size":"127"}, {"price":"0.39", "size":"12"}, {"price":"0.38", "size":"94.51"}, {"price":"0.37", "size":"31.99"}, {"price":"0.36", "size":"12"}, {"price":"0.35", "size":"37"}, {"price":"0.34", "size":"12"}, {"price":"0.33", "size":"12"}, {"price":"0.32", "size":"12"}, {"price":"0.31", "size":"12"}, {"price":"0.3", "size":"31.9"}, {"price":"0.29", "size":"344"}, {"price":"0.28", "size":"3488.99"}, {"price":"0.27", "size":"212"}, {"price":"0.26", "size":"218"}, {"price":"0.25", "size":"712"}, {"price":"0.24", "size":"212"}, {"price":"0.23", "size":"212"}, {"price":"0.22", "size":"1223.14"}, {"price":"0.21", "size":"212"}, {"price":"0.2", "size":"272.99"}, {"price":"0.19", "size":"212"}, {"price":"0.18", "size":"212"}, {"price":"0.17", "size":"212"}, {"price":"0.16", "size":"812"}, {"price":"0.15", "size":"231.08"}, {"price":"0.14", "size":"283.65"}, {"price":"0.13", "size":"212"}, {"price":"0.12", "size":"252"}, {"price":"0.11", "size":"252"}, {"price":"0.1", "size":"746.71"}, {"price":"0.09", "size":"326"}, {"price":"0.08", "size":"844.68"}, {"price":"0.07", "size":"826"}, {"price":"0.06", "size":"780"}, {"price":"0.05", "size":"644"}, {"price":"0.04", "size":"782.73"}, {"price":"0.03", "size":"431.32"}], "hash":"750553e1875e709b12c87f0abe01f95d187c0348", "timestamp":"1770241472157", "event_type":"book"}
{"market":"0x38f3050258345e9cf363d1c8cc302f08c65b96ba1a4669d81e07ed69708344df", "price_changes":[{"asset_id":"96888240988495161476033313796107536512663280794332045579302109906525918376981", "price":"0.94", "size":"753", "side":"BUY", "hash":"9f2f6eb15fe795b7c6e6676e7c0ec0e37ecf3dc2", "best_bid":"0.97", "best_ask":"0.98"}, {"asset_id":"81916206347121459497221114766050949090435061493822476265356047392175668050706", "price":"0.06", "size":"753", "side":"SELL", "hash":"ac83c8269817aff2664c82b51eb7a198b1ecab04", "best_bid":"0.02", "best_ask":"0.03"}], "timestamp":"1770241472158", "event_type":"price_change"}
{"market":"0x38f3050258345e9cf363d1c8cc302f08c65b96ba1a4669d81e07ed69708344df", "price_changes":[{"asset_id":"96888240988495161476033313796107536512663280794332045579302109906525918376981", "price":"0.95", "size":"671", "side":"BUY", "hash":"8f21816458d2b3be22781490f619ae44ed75e59b", "best_bid":"0.97", "best_ask":"0.98"}, {"asset_id":"81916206347121459497221114766050949090435061493822476265356047392175668050706", "price":"0.05", "size":"671", "side":"SELL", "hash":"0c726a79785a20e4c2724e16773ad78ee41eaa5e", "best_bid":"0.02", "best_ask":"0.03"}], "timestamp":"1770241472159", "event_type":"price_change"}
{"market":"0x38f3050258345e9cf363d1c8cc302f08c65b96ba1a4669d81e07ed69708344df", "price_changes":[{"asset_id":"96888240988495161476033313796107536512663280794332045579302109906525918376981", "price":"0.95", "size":"698", "side":"BUY", "hash":"88ecc7545b548388b27ee9ed60324cbe5ec394e6", "best_bid":"0.97", "best_ask":"0.98"}, {"asset_id":"81916206347121459497221114766050949090435061493822476265356047392175668050706", "price":"0.05", "size":"698", "side":"SELL", "hash":"df1ce1a1dbdf8753618c97f110064e336c48a5b6", "best_bid":"0.02", "best_ask":"0.03"}], "timestamp":"1770241472165", "event_type":"price_change"}
{"market":"0x38f3050258345e9cf363d1c8cc302f08c65b96ba1a4669d81e07ed69708344df", "price_changes":[{"asset_id":"96888240988495161476033313796107536512663280794332045579302109906525918376981", "price":"0.94", "size":"726", "side":"BUY", "hash":"085ebcf39d44b39141b50e46f5a168457abece39", "best_bid":"0.97", "best_ask":"0.98"}, {"asset_id":"81916206347121459497221114766050949090435061493822476265356047392175668050706", "price":"0.06", "size":"726", "side":"SELL", "hash":"5594b213d7142ee9cb25fcc2ae164d0745dd76d3", "best_bid":"0.02", "best_ask":"0.03"}], "timestamp":"1770241472166", "event_type":"price_change"}
{"market":"0x38f3050258345e9cf363d1c8cc302f08c65b96ba1a4669d81e07ed69708344df", "price_changes":[{"asset_id":"96888240988495161476033313796107536512663280794332045579302109906525918376981", "price":"0.96", "size":"802.73", "side":"BUY", "hash":"332106d5a931f84157a2843cdcd6ef3c3c1ddef1", "best_bid":"0.97", "best_ask":"0.98"}, {"asset_id":"81916206347121459497221114766050949090435061493822476265356047392175668050706", "price":"0.04", "size":"802.73", "side":"SELL", "hash":"5be3eea9ba32466e690e39af91314708575b5e49", "best_bid":"0.02", "best_ask":"0.03"}], "timestamp":"1770241472196", "event_type":"price_change"}
{"market":"0x38f3050258345e9cf363d1c8cc302f08c65b96ba1a4669d81e07ed69708344df", "price_changes":[{"asset_id":"96888240988495161476033313796107536512663280794332045579302109906525918376981", "price":"0.97", "size":"401.32", "side":"BUY", "hash":"42e73d6f73467a91742c88e7f95fa0480a9689f7", "best_bid":"0.97", "best_ask":"0.98"}, {"asset_id":"81916206347121459497221114766050949090435061493822476265356047392175668050706", "price":"0.03", "size":"401.32", "side":"SELL", "hash":"444175584f27443fbfbc5b5f725554a987db9101", "best_bid":"0.02", "best_ask":"0.03"}], "timestamp":"1770241472202", "event_type":"price_change"}
{"market":"0x38f3050258345e9cf363d1c8cc302f08c65b96ba1a4669d81e07ed69708344df", "price_changes":[{"asset_id":"96888240988495161476033313796107536512663280794332045579302109906525918376981", "price":"0.98", "size":"362.5", "side":"SELL", "hash":"348d82649f928b508e64ebba75b138c07c8c64be", "best_bid":"0.97", "best_ask":"0.98"}, {"asset_id":"81916206347121459497221114766050949090435061493822476265356047392175668050706", "price":"0.02", "size":"362.5", "side":"BUY", "hash":"f802b4c2c497cf68d2a86b18f7fb79484c9c92c1", "best_bid":"0.02", "best_ask":"0.03"}], "timestamp":"1770241472239", "event_type":"price_change"}
{"market":"0x38f3050258345e9cf363d1c8cc302f08c65b96ba1a4669d81e07ed69708344df", "price_changes":[{"asset_id":"96888240988495161476033313796107536512663280794332045579302109906525918376981", "price":"0.75", "size":"212", "side":"BUY", "hash":"8980750df2064327339b56d46d395aeeb6d5175c", "best_bid":"0.97", "best_ask":"0.98"}, {"asset_id":"81916206347121459497221114766050949090435061493822476265356047392175668050706", "price":"0.25", "size":"212", "side":"SELL", "hash":"4d4416c21ce8ec008298d266589e5672815c44bf", "best_bid":"0.02", "best_ask":"0.03"}], "timestamp":"1770241472261", "event_type":"price_change"}
{"market":"0x38f3050258345e9cf363d1c8cc302f08c65b96ba1a4669d81e07ed69708344df", "price_changes":[{"asset_id":"96888240988495161476033313796107536512663280794332045579302109906525918376981", "price":"0.95", "size":"671", "side":"BUY", "hash":"61b5f5114d6385118d0a72f807def26fbfc5c98e", "best_bid":"0.97", "best_ask":"0.98"}, {"asset_id":"81916206347121459497221114766050949090435061493822476265356047392175668050706", "price":"0.05", "size":"671", "side":"SELL", "hash":"ac645d4cfdf456b8ef1a0cd1a439371db0404506", "best_bid":"0.02", "best_ask":"0.03"}], "timestamp":"1770241472321", "event_type":"price_change"}
{"market":"0x38f3050258345e9cf363d1c8cc302f08c65b96ba1a4669d81e07ed69708344df", "price_changes":[{"asset_id":"96888240988495161476033313796107536512663280794332045579302109906525918376981", "price":"0.94", "size":"753", "side":"BUY", "hash":"7b6606250874ffd1f66f62747cca2bc3a1471991", "best_bid":"0.97", "best_ask":"0.98"}, {"asset_id":"81916206347121459497221114766050949090435061493822476265356047392175668050706", "price":"0.06", "size":"753", "side":"SELL", "hash":"24a3def605a8dc7419f26be9782c54b5456001f4", "best_bid":"0.02", "best_ask":"0.03"}], "timestamp":"1770241472330", "event_type":"price_change"}
{"market":"0x38f3050258345e9cf363d1c8cc302f08c65b96ba1a4669d81e07ed69708344df", "price_changes":[{"asset_id":"96888240988495161476033313796107536512663280794332045579302109906525918376981", "price":"0.95", "size":"644", "side":"BUY", "hash":"5fb5951b6e1cd8b2c2e45c3713755b67cc13fb2d", "best_bid":"0.97", "best_ask":"0.98"}, {"asset_id":"81916206347121459497221114766050949090435061493822476265356047392175668050706", "price":"0.05", "size":"644", "side":"SELL", "hash":"1630b0c27882df5fa6bb90cdda2a0965dc0653a9", "best_bid":"0.02", "best_ask":"0.03"}], "timestamp":"1770241472331", "event_type":"price_change"}
{"market":"0x38f3050258345e9cf363d1c8cc302f08c65b96ba1a4669d81e07ed69708344df", "price_changes":[{"asset_id":"96888240988495161476033313796107536512663280794332045579302109906525918376981", "price":"0.94", "size":"780", "side":"BUY", "hash":"74b6e5307e6b10bc632d8730aabfc417956fbf8b", "best_bid":"0.97", "best_ask":"0.98"}, {"asset_id":"81916206347121459497221114766050949090435061493822476265356047392175668050706", "price":"0.06", "size":"780", "side":"SELL", "hash":"471985bcb534d5f5788e0fac7fc7e0e86b04dcf0", "best_bid":"0.02", "best_ask":"0.03"}], "timestamp":"1770241472337", "event_type":"price_change"}
{"market":"0x38f3050258345e9cf363d1c8cc302f08c65b96ba1a4669d81e07ed69708344df", "price_changes":[{"asset_id":"96888240988495161476033313796107536512663280794332045579302109906525918376981", "price":"0.98", "size":"118.98", "side":"BUY", "hash":"2856b0039b0ee0b9daa0e38110781ccf78f393ba", "best_bid":"0.98", "best_ask":"0.99"}, {"asset_id":"81916206347121459497221114766050949090435061493822476265356047392175668050706", "price":"0.02", "size":"118.98", "side":"SELL", "hash":"8cf9fd652eff204c3119602cdd712bde8fad3b5d", "best_bid":"0.01", "best_ask":"0.02"}], "timestamp":"1770241472371", "event_type":"price_change"}
{"market":"0x38f3050258345e9cf363d1c8cc302f08c65b96ba1a4669d81e07ed69708344df", "price_changes":[{"asset_id":"81916206347121459497221114766050949090435061493822476265356047392175668050706", "price":"0.02", "size":"0", "side":"BUY", "hash":"8cf9fd652eff204c3119602cdd712bde8fad3b5d", "best_bid":"0.01", "best_ask":"0.02"}, {"asset_id":"96888240988495161476033313796107536512663280794332045579302109906525918376981", "price":"0.98", "size":"0", "side":"SELL", "hash":"2856b0039b0ee0b9daa0e38110781ccf78f393ba", "best_bid":"0.98", "best_ask":"0.99"}], "timestamp":"1770241472371", "event_type":"price_change"}
{"market":"0x38f3050258345e9cf363d1c8cc302f08c65b96ba1a4669d81e07ed69708344df", "asset_id":"81916206347121459497221114766050949090435061493822476265356047392175668050706", "bids":[{"price":"0.01", "size":"4153.07"}], "asks":[{"price":"0.99", "size":"5019.91"}, {"price":"0.98", "size":"3034.23"}, {"price":"0.97", "size":"3172"}, {"price":"0.96", "size":"3012"}, {"price":"0.95", "size":"3032"}, {"price":"0.94", "size":"3012"}, {"price":"0.93", "size":"3126.28"}, {"price":"0.92", "size":"3012"}, {"price":"0.91", "size":"3012"}, {"price":"0.9", "size":"3087"}, {"price":"0.89", "size":"12"}, {"price":"0.88", "size":"12"}, {"price":"0.87", "size":"12"}, {"price":"0.86", "size":"12"}, {"price":"0.85", "size":"12"}, {"price":"0.84", "size":"12"}, {"price":"0.83", "size":"12"}, {"price":"0.82", "size":"12"}, {"price":"0.81", "size":"12"}, {"price":"0.8", "size":"12"}, {"price":"0.79", "size":"12"}, {"price":"0.78", "size":"12"}, {"price":"0.77", "size":"12"}, {"price":"0.76", "size":"112"}, {"price":"0.75", "size":"40.57"}, {"price":"0.74", "size":"12"}, {"price":"0.73", "size":"293.25"}, {"price":"0.72", "size":"22"}, {"price":"0.71", "size":"12"}, {"price":"0.7", "size":"18"}, {"price":"0.69", "size":"12"}, {"price":"0.68", "size":"12"}, {"price":"0.67", "size":"12"}, {"price":"0.66", "size":"160.89"}, {"price":"0.65", "size":"12"}, {"price":"0.64", "size":"12"}, {"price":"0.63", "size":"12"}, {"price":"0.62", "size":"19.39"}, {"price":"0.61", "size":"18.04"}, {"price":"0.6", "size":"12"}, {"price":"0.59", "size":"94.31"}, {"price":"0.58", "size":"5450.54"}, {"price":"0.57", "size":"12"}, {"price":"0.56", "size":"12"}, {"price":"0.55", "size":"12"}, {"price":"0.54", "size":"22"}, {"price":"0.53", "size":"12"}, {"price":"0.52", "size":"12"}, {"price":"0.51", "size":"12"}, {"price":"0.5", "size":"12"}, {"price":"0.49", "size":"12"}, {"price":"0.48", "size":"12"}, {"price":"0.47", "size":"12"}, {"price":"0.46", "size":"485.56"}, {"price":"0.45", "size":"31"}, {"price":"0.44", "size":"17"}, {"price":"0.43", "size":"12"}, {"price":"0.42", "size":"12"}, {"price":"0.41", "size":"12"}, {"price":"0.4", "size":"127"}, {"price":"0.39", "size":"12"}, {"price":"0.38", "size":"94.51"}, {"price":"0.37", "size":"31.99"}, {"price":"0.36", "size":"12"}, {"price":"0.35", "size":"37"}, {"price":"0.34", "size":"12"}, {"price":"0.33", "size":"12"}, {"price":"0.32", "size":"12"}, {"price":"0.31", "size":"12"}, {"price":"0.3", "size":"31.9"}, {"price":"0.29", "size":"344"}, {"price":"0.28", "size":"3488.99"}, {"price":"0.27", "size":"212"}, {"price":"0.26", "size":"218"}, {"price":"0.25", "size":"212"}, {"price":"0.24", "size":"212"}, {"price":"0.23", "size":"212"}, {"price":"0.22", "size":"1223.14"}, {"price":"0.21", "size":"212"}, {"price":"0.2", "size":"272.99"}, {"price":"0.19", "size":"212"}, {"price":"0.18", "size":"212"}, {"price":"0.17", "size":"212"}, {"price":"0.16", "size":"812"}, {"price":"0.15", "size":"231.08"}, {"price":"0.14", "size":"283.65"}, {"price":"0.13", "size":"212"}, {"price":"0.12", "size":"252"}, {"price":"0.11", "size":"252"}, {"price":"0.1", "size":"746.71"}, {"price":"0.09", "size":"326"}, {"price":"0.08", "size":"844.68"}, {"price":"0.07", "size":"826"}, {"price":"0.06", "size":"780"}, {"price":"0.05", "size":"644"}, {"price":"0.04", "size":"802.73"}, {"price":"0.03", "size":"401.32"}, {"price":"0.02", "size":"118.98"}], "hash":"8cf9fd652eff204c3119602cdd712bde8fad3b5d", "timestamp":"1770241472371", "event_type":"book"}
{"market":"0x38f3050258345e9cf363d1c8cc302f08c65b96ba1a4669d81e07ed69708344df", "price_changes":[{"asset_id":"96888240988495161476033313796107536512663280794332045579302109906525918376981", "price":"0.95", "size":"617", "side":"BUY", "hash":"be25876276524905e92edb4b7d43268fb02f9b36", "best_bid":"0.98", "best_ask":"0.99"}, {"asset_id":"81916206347121459497221114766050949090435061493822476265356047392175668050706", "price":"0.05", "size":"617", "side":"SELL", "hash":"530a01eb98b0576969598909f4f328e9df15a943", "best_bid":"0.01", "best_ask":"0.02"}], "timestamp":"1770241472396", "event_type":"price_change"}
{"market":"0x38f3050258345e9cf363d1c8cc302f08c65b96ba1a4669d81e07ed69708344df", "price_changes":[{"asset_id":"96888240988495161476033313796107536512663280794332045579302109906525918376981", "price":"0.96", "size":"829.73", "side":"BUY", "hash":"e1ecc7400d98e1bd55a491a492787f3322171f45", "best_bid":"0.98", "best_ask":"0.99"}, {"asset_id":"81916206347121459497221114766050949090435061493822476265356047392175668050706", "price":"0.04", "size":"829.73", "side":"SELL", "hash":"25558fbbae952dc9c6d52d40c6f2b3034d7fe025", "best_bid":"0.01", "best_ask":"0.02"}], "timestamp":"1770241472397", "event_type":"price_change"}
{"market":"0x38f3050258345e9cf363d1c8cc302f08c65b96ba1a4669d81e07ed69708344df", "price_changes":[{"asset_id":"81916206347121459497221114766050949090435061493822476265356047392175668050706", "price":"0.1", "size":"737.71", "side":"SELL", "hash":"c0a4aaa4a4a21c10f35436e96bd33d123cac4dce", "best_bid":"0.01", "best_ask":"0.02"}, {"asset_id":"96888240988495161476033313796107536512663280794332045579302109906525918376981", "price":"0.9", "size":"737.71", "side":"BUY", "hash":"544866c74b757fb9dd9dac8b4d37813368575d51", "best_bid":"0.98", "best_ask":"0.99"}], "timestamp":"1770241472400", "event_type":"price_change"}
{"market":"0x38f3050258345e9cf363d1c8cc302f08c65b96ba1a4669d81e07ed69708344df", "price_changes":[{"asset_id":"96888240988495161476033313796107536512663280794332045579302109906525918376981", "price":"0.96", "size":"806.73", "side":"BUY", "hash":"59d692a38f82d4c86d1660bec75c8463363e7e4b", "best_bid":"0.98", "best_ask":"0.99"}, {"asset_id":"81916206347121459497221114766050949090435061493822476265356047392175668050706", "price":"0.04", "size":"806.73", "side":"SELL", "hash":"159cb9c10b1fd3165f7969e3113299eeff3b0a28", "best_bid":"0.01", "best_ask":"0.02"}], "timestamp":"1770241472401", "event_type":"price_change"}
{"market":"0x38f3050258345e9cf363d1c8cc302f08c65b96ba1a4669d81e07ed69708344df", "price_changes":[{"asset_id":"96888240988495161476033313796107536512663280794332045579302109906525918376981", "price":"0.97", "size":"424.32", "side":"BUY", "hash":"977af7b91b99058124fbf6ad69499e26c30fb02f", "best_bid":"0.98", "best_ask":"0.99"}, {"asset_id":"81916206347121459497221114766050949090435061493822476265356047392175668050706", "price":"0.03", "size":"424.32", "side":"SELL", "hash":"14cbf1739a7062fd35279809d665bf0f2d72ed64", "best_bid":"0.01", "best_ask":"0.02"}], "timestamp":"1770241472404", "event_type":"price_change"}
{"market":"0x38f3050258345e9cf363d1c8cc302f08c65b96ba1a4669d81e07ed69708344df", "price_changes":[{"asset_id":"81916206347121459497221114766050949090435061493822476265356047392175668050706", "price":"0.05", "size":"626", "side":"SELL", "hash":"9a0aec810a9e71116a9ce431bf510294d96f6e43", "best_bid":"0.01", "best_ask":"0.02"}, {"asset_id":"96888240988495161476033313796107536512663280794332045579302109906525918376981", "price":"0.95", "size":"626", "side":"BUY", "hash":"a73f6c09f2cd5a3b65e0c7292ff867e8db0e8b82", "best_bid":"0.98", "best_ask":"0.99"}], "timestamp":"1770241472404", "event_type":"price_change"}
{"market":"0x38f3050258345e9cf363d1c8cc302f08c65b96ba1a4669d81e07ed69708344df", "price_changes":[{"asset_id":"96888240988495161476033313796107536512663280794332045579302109906525918376981", "price":"0.96", "size":"780.73", "side":"BUY", "hash":"ab4382637f706435e91eeb73a7aaf259df0f678f", "best_bid":"0.98", "best_ask":"0.99"}, {"asset_id":"81916206347121459497221114766050949090435061493822476265356047392175668050706", "price":"0.04", "size":"780.73", "side":"SELL", "hash":"715e4cd13fab4db8628720c0d4b528531c8f0ba6", "best_bid":"0.01", "best_ask":"0.02"}], "timestamp":"1770241472417", "event_type":"price_change"}
{"market":"0x38f3050258345e9cf363d1c8cc302f08c65b96ba1a4669d81e07ed69708344df", "price_changes":[{"asset_id":"96888240988495161476033313796107536512663280794332045579302109906525918376981", "price":"0.98", "size":"148.98", "side":"BUY", "hash":"0498a5d2ac180140cd52c35397c7e53b0a204842", "best_bid":"0.98", "best_ask":"0.99"}, {"asset_id":"81916206347121459497221114766050949090435061493822476265356047392175668050706", "price":"0.02", "size":"148.98", "side":"SELL", "hash":"4664e4bb0a65114d0b67326b6e426368906bb797", "best_bid":"0.01", "best_ask":"0.02"}], "timestamp":"1770241472450", "event_type":"price_change"}
{"market":"0x38f3050258345e9cf363d1c8cc302f08c65b96ba1a4669d81e07ed69708344df", "price_changes":[{"asset_id":"96888240988495161476033313796107536512663280794332045579302109906525918376981", "price":"0.97", "size":"450.32", "side":"BUY", "hash":"71fa8f85ab290f4ab72e042a4368f778f944e2bf", "best_bid":"0.98", "best_ask":"0.99"}, {"asset_id":"81916206347121459497221114766050949090435061493822476265356047392175668050706", "price":"0.03", "size":"450.32", "side":"SELL", "hash":"6da95090964f57a1c5b2becf8fedcaa7856a09bc", "best_bid":"0.01", "best_ask":"0.02"}], "timestamp":"1770241472456", "event_type":"price_change"}
{"market":"0x38f3050258345e9cf363d1c8cc302f08c65b96ba1a4669d81e07ed69708344df", "price_changes":[{"asset_id":"96888240988495161476033313796107536512663280794332045579302109906525918376981", "price":"0.96", "size":"754.73", "side":"BUY", "hash":"2f0787698ab3333b906a23a0b33b7fc1aaab7f6a", "best_bid":"0.98", "best_ask":"0.99"}, {"asset_id":"81916206347121459497221114766050949090435061493822476265356047392175668050706", "price":"0.04", "size":"754.73", "side":"SELL", "hash":"93573aea85e99bb63fc3fa39575547e3fd2a6507", "best_bid":"0.01", "best_ask":"0.02"}], "timestamp":"1770241472463", "event_type":"price_change"}
{"market":"0x38f3050258345e9cf363d1c8cc302f08c65b96ba1a4669d81e07ed69708344df", "price_changes":[{"asset_id":"96888240988495161476033313796107536512663280794332045579302109906525918376981", "price":"0.96", "size":"728.73", "side":"BUY", "hash":"7002dde14bb8bef9e07a610cbe71bfa8c4e7488d", "best_bid":"0.98", "best_ask":"0.99"}, {"asset_id":"81916206347121459497221114766050949090435061493822476265356047392175668050706", "price":"0.04", "size":"728.73", "side":"SELL", "hash":"2a2c709595e1aa151d4203e08c59d7be2167287e", "best_bid":"0.01", "best_ask":"0.02"}], "timestamp":"1770241472465", "event_type":"price_change"}
{"market":"0x38f3050258345e9cf363d1c8cc302f08c65b96ba1a4669d81e07ed69708344df", "price_changes":[{"asset_id":"96888240988495161476033313796107536512663280794332045579302109906525918376981", "price":"0.96", "size":"702.73", "side":"BUY", "hash":"a4a2a90ecdcbc5da90fd1f8a30beefd1eb8af113", "best_bid":"0.98", "best_ask":"0.99"}, {"asset_id":"81916206347121459497221114766050949090435061493822476265356047392175668050706", "price":"0.04", "size":"702.73", "side":"SELL", "hash":"cf5535c7c903b531d887515de3435f771f87d8f6", "best_bid":"0.01", "best_ask":"0.02"}], "timestamp":"1770241472469", "event_type":"price_change"}
{"market":"0x38f3050258345e9cf363d1c8cc302f08c65b96ba1a4669d81e07ed69708344df", "price_changes":[{"asset_id":"96888240988495161476033313796107536512663280794332045579302109906525918376981", "price":"0.95", "size":"653", "side":"BUY", "hash":"8fdd30c5080bad549e5dd4214362a4a87a83f0ae", "best_bid":"0.98", "best_ask":"0.99"}, {"asset_id":"81916206347121459497221114766050949090435061493822476265356047392175668050706", "price":"0.05", "size":"653", "side":"SELL", "hash":"c78eb157258b7c8391e2b1f3f489075fc31bda52", "best_bid":"0.01", "best_ask":"0.02"}], "timestamp":"1770241472488", "event_type":"price_change"}
{"market":"0x38f3050258345e9cf363d1c8cc302f08c65b96ba1a4669d81e07ed69708344df", "price_changes":[{"asset_id":"96888240988495161476033313796107536512663280794332045579302109906525918376981", "price":"0.95", "size":"680", "side":"BUY", "hash":"5a0194421894bd0c9ca25f94865d32ce0f64d607", "best_bid":"0.98", "best_ask":"0.99"}, {"asset_id":"81916206347121459497221114766050949090435061493822476265356047392175668050706", "price":"0.05", "size":"680", "side":"SELL", "hash":"1a3e7c8cb711c50e5dc4502eb1ec8ba10d151038", "best_bid":"0.01", "best_ask":"0.02"}], "timestamp":"1770241472493", "event_type":"price_change"}
{"market":"0x38f3050258345e9cf363d1c8cc302f08c65b96ba1a4669d81e07ed69708344df", "price_changes":[{"asset_id":"96888240988495161476033313796107536512663280794332045579302109906525918376981", "price":"0.94", "size":"753", "side":"BUY", "hash":"f9a7b56c9dc9f88001e21fe5b4360d98b347798a", "best_bid":"0.98", "best_ask":"0.99"}, {"asset_id":"81916206347121459497221114766050949090435061493822476265356047392175668050706", "price":"0.06", "size":"753", "side":"SELL", "hash":"670648d565e2102839ad2f66c700893ef7a4d7ac", "best_bid":"0.01", "best_ask":"0.02"}], "timestamp":"1770241472498", "event_type":"price_change"}
{"market":"0x38f3050258345e9cf363d1c8cc302f08c65b96ba1a4669d81e07ed69708344df", "price_changes":[{"asset_id":"96888240988495161476033313796107536512663280794332045579302109906525918376981", "price":"0.94", "size":"726", "side":"BUY", "hash":"208a6b329362f939c3835016edeacac291a757ec", "best_bid":"0.98", "best_ask":"0.99"}, {"asset_id":"81916206347121459497221114766050949090435061493822476265356047392175668050706", "price":"0.06", "size":"726", "side":"SELL", "hash":"29e7c35637e47025b77b2825fceffab5ddb34688", "best_bid":"0.01", "best_ask":"0.02"}], "timestamp":"1770241472503", "event_type":"price_change"}
{"market":"0x38f3050258345e9cf363d1c8cc302f08c65b96ba1a4669d81e07ed69708344df", "price_changes":[{"asset_id":"96888240988495161476033313796107536512663280794332045579302109906525918376981", "price":"0.97", "size":"476.32", "side":"BUY", "hash":"38c290807e26ef01ab177e38c0da9ffacf09bc86", "best_bid":"0.98", "best_ask":"0.99"}, {"asset_id":"81916206347121459497221114766050949090435061493822476265356047392175668050706", "price":"0.03", "size":"476.32", "side":"SELL", "hash":"d6d64471082446e57fdca0d13a8d1951a15569a7", "best_bid":"0.01", "best_ask":"0.02"}], "timestamp":"1770241472503", "event_type":"price_change"}
{"market":"0x38f3050258345e9cf363d1c8cc302f08c65b96ba1a4669d81e07ed69708344df", "price_changes":[{"asset_id":"81916206347121459497221114766050949090435061493822476265356047392175668050706", "price":"0.01", "size":"4127.07", "side":"BUY", "hash":"8a6d90214fe40e5bcc6a953a8bf8a2bb7cc529ab", "best_bid":"0.01", "best_ask":"0.02"}, {"asset_id":"96888240988495161476033313796107536512663280794332045579302109906525918376981", "price":"0.99", "size":"4127.07", "side":"SELL", "hash":"caccbbc50df07c44fc1e64a0796fa3dd5e908918", "best_bid":"0.98", "best_ask":"0.99"}], "timestamp":"1770241472511", "event_type":"price_change"}
{"market":"0x38f3050258345e9cf363d1c8cc302f08c65b96ba1a4669d81e07ed69708344df", "price_changes":[{"asset_id":"96888240988495161476033313796107536512663280794332045579302109906525918376981", "price":"0.97", "size":"502.32", "side":"BUY", "hash":"0bfaaec66d9ccd5e6b813ab06baec6cc1b8321ed", "best_bid":"0.98", "best_ask":"0.99"}, {"asset_id":"81916206347121459497221114766050949090435061493822476265356047392175668050706", "price":"0.03", "size":"502.32", "side":"SELL", "hash":"f3fa0a703ea455fe91c9f3cf549311753f9e381a", "best_bid":"0.01", "best_ask":"0.02"}], "timestamp":"1770241472515", "event_type":"price_change"}
{"market":"0x38f3050258345e9cf363d1c8cc302f08c65b96ba1a4669d81e07ed69708344df", "price_changes":[{"asset_id":"96888240988495161476033313796107536512663280794332045579302109906525918376981", "price":"0.97", "size":"528.32", "side":"BUY", "hash":"d71efca2bbe717cc9fe2da92c9ad2601777a2d04", "best_bid":"0.98", "best_ask":"0.99"}, {"asset_id":"81916206347121459497221114766050949090435061493822476265356047392175668050706", "price":"0.03", "size":"528.32", "side":"SELL", "hash":"0dad3ef54c68869970526e7c74212ecfe638b87c", "best_bid":"0.01", "best_ask":"0.02"}], "timestamp":"1770241472516", "event_type":"price_change"}
{"market":"0x38f3050258345e9cf363d1c8cc302f08c65b96ba1a4669d81e07ed69708344df", "price_changes":[{"asset_id":"96888240988495161476033313796107536512663280794332045579302109906525918376981", "price":"0.96", "size":"675.73", "side":"BUY", "hash":"82a41bd4d0fcc300b3b3c87592c0793db6546470", "best_bid":"0.98", "best_ask":"0.99"}, {"asset_id":"81916206347121459497221114766050949090435061493822476265356047392175668050706", "price":"0.04", "size":"675.73", "side":"SELL", "hash":"753760422b0ad3813f1a6ef2e194b03b4714f915", "best_bid":"0.01", "best_ask":"0.02"}], "timestamp":"1770241472516", "event_type":"price_change"}
{"market":"0x38f3050258345e9cf363d1c8cc302f08c65b96ba1a4669d81e07ed69708344df", "price_changes":[{"asset_id":"96888240988495161476033313796107536512663280794332045579302109906525918376981", "price":"0.96", "size":"702.73", "side":"BUY", "hash":"a9a6039d42503ccce647c6a0a9972395c9bfa6c6", "best_bid":"0.98", "best_ask":"0.99"}, {"asset_id":"81916206347121459497221114766050949090435061493822476265356047392175668050706", "price":"0.04", "size":"702.73", "side":"SELL", "hash":"1d7f45d7c559d00fbfc6b3c9d56266b6bbfa3638", "best_bid":"0.01", "best_ask":"0.02"}], "timestamp":"1770241472518", "event_type":"price_change"}
{"market":"0x38f3050258345e9cf363d1c8cc302f08c65b96ba1a4669d81e07ed69708344df", "price_changes":[{"asset_id":"96888240988495161476033313796107536512663280794332045579302109906525918376981", "price":"0.99", "size":"4167.07", "side":"SELL", "hash":"02f58d802458b59942d7b03e14159edc14f0b7c6", "best_bid":"0.98", "best_ask":"0.99"}, {"asset_id":"81916206347121459497221114766050949090435061493822476265356047392175668050706", "price":"0.01", "size":"4167.07", "side":"BUY", "hash":"b9da0c522047a24fa3eff3313fdf2e9f61668544", "best_bid":"0.01", "best_ask":"0.02"}], "timestamp":"1770241472521", "event_type":"price_change"}
{"market":"0x38f3050258345e9cf363d1c8cc302f08c65b96ba1a4669d81e07ed69708344df", "price_changes":[{"asset_id":"81916206347121459497221114766050949090435061493822476265356047392175668050706", "price":"0.01", "size":"4141.07", "side":"BUY", "hash":"49676c43b6792e2c3f6721ef6944e97f7961a79f", "best_bid":"0.01", "best_ask":"0.02"}, {"asset_id":"96888240988495161476033313796107536512663280794332045579302109906525918376981", "price":"0.99", "size":"4141.07", "side":"SELL", "hash":"07d079ce594a255527a562d1dba8c0c95466d3cb", "best_bid":"0.98", "best_ask":"0.99"}], "timestamp":"1770241472551", "event_type":"price_change"}
{"market":"0x38f3050258345e9cf363d1c8cc302f08c65b96ba1a4669d81e07ed69708344df", "price_changes":[{"asset_id":"96888240988495161476033313796107536512663280794332045579302109906525918376981", "price":"0.94", "size":"753", "side":"BUY", "hash":"84be9c60e3fd113661122abc32bcc466a49184c8", "best_bid":"0.98", "best_ask":"0.99"}, {"asset_id":"81916206347121459497221114766050949090435061493822476265356047392175668050706", "price":"0.06", "size":"753", "side":"SELL", "hash":"90d5b7074d904472b5f3f54bc76a090b0306eeac", "best_bid":"0.01", "best_ask":"0.02"}], "timestamp":"1770241472639", "event_type":"price_change"}
{"market":"0x38f3050258345e9cf363d1c8cc302f08c65b96ba1a4669d81e07ed69708344df", "price_changes":[{"asset_id":"96888240988495161476033313796107536512663280794332045579302109906525918376981", "price":"0.95", "size":"653", "side":"BUY", "hash":"364e131c4ebfe53d265e0e26aad629cc563b64b8", "best_bid":"0.98", "best_ask":"0.99"}, {"asset_id":"81916206347121459497221114766050949090435061493822476265356047392175668050706", "price":"0.05", "size":"653", "side":"SELL", "hash":"1927625472748bd15ec1231c576f27eee7818017", "best_bid":"0.01", "best_ask":"0.02"}], "timestamp":"1770241472640", "event_type":"price_change"}
{"market":"0x38f3050258345e9cf363d1c8cc302f08c65b96ba1a4669d81e07ed69708344df", "price_changes":[{"asset_id":"96888240988495161476033313796107536512663280794332045579302109906525918376981", "price":"0.94", "size":"780", "side":"BUY", "hash":"af48423b7e9293f54c024bb31a4468eff87be801", "best_bid":"0.98", "best_ask":"0.99"}, {"asset_id":"81916206347121459497221114766050949090435061493822476265356047392175668050706", "price":"0.06", "size":"780", "side":"SELL", "hash":"d5ac424993776b9864701568d3e64d0cef20ef78", "best_bid":"0.01", "best_ask":"0.02"}], "timestamp":"1770241472649", "event_type":"price_change"}
{"market":"0x38f3050258345e9cf363d1c8cc302f08c65b96ba1a4669d81e07ed69708344df", "price_changes":[{"asset_id":"96888240988495161476033313796107536512663280794332045579302109906525918376981", "price":"0.96", "size":"675.73", "side":"BUY", "hash":"a7f259689df3c9f2563be378a1ee87fc352a0cfe", "best_bid":"0.98", "best_ask":"0.99"}, {"asset_id":"81916206347121459497221114766050949090435061493822476265356047392175668050706", "price":"0.04", "size":"675.73", "side":"SELL", "hash":"6b2dab5deac20f35cb16c362d3349ebad73a32d3", "best_bid":"0.01", "best_ask":"0.02"}], "timestamp":"1770241472659", "event_type":"price_change"}
{"market":"0x38f3050258345e9cf363d1c8cc302f08c65b96ba1a4669d81e07ed69708344df", "price_changes":[{"asset_id":"96888240988495161476033313796107536512663280794332045579302109906525918376981", "price":"0.95", "size":"680", "side":"BUY", "hash":"72cc35316b41f58aa046049a38adc38c8ee94f99", "best_bid":"0.98", "best_ask":"0.99"}, {"asset_id":"81916206347121459497221114766050949090435061493822476265356047392175668050706", "price":"0.05", "size":"680", "side":"SELL", "hash":"9efff3452922d31aa6430d202dcb47bb37972132", "best_bid":"0.01", "best_ask":"0.02"}], "timestamp":"1770241472660", "event_type":"price_change"}
{"market":"0x38f3050258345e9cf363d1c8cc302f08c65b96ba1a4669d81e07ed69708344df", "price_changes":[{"asset_id":"96888240988495161476033313796107536512663280794332045579302109906525918376981", "price":"0.95", "size":"653", "side":"BUY", "hash":"4aec4fe04115221de4d0d743d0ae15e6e1f75340", "best_bid":"0.98", "best_ask":"0.99"}, {"asset_id":"81916206347121459497221114766050949090435061493822476265356047392175668050706", "price":"0.05", "size":"653", "side":"SELL", "hash":"6d6877a3c398cf6fcad83f449b348aec3474fab0", "best_bid":"0.01", "best_ask":"0.02"}], "timestamp":"1770241472662", "event_type":"price_change"}
{"market":"0x38f3050258345e9cf363d1c8cc302f08c65b96ba1a4669d81e07ed69708344df", "price_changes":[{"asset_id":"96888240988495161476033313796107536512663280794332045579302109906525918376981", "price":"0.99", "size":"4101.07", "side":"SELL", "hash":"bb45fbcbf2260899f2608aed0cda3a3a865e983f", "best_bid":"0.98", "best_ask":"0.99"}, {"asset_id":"81916206347121459497221114766050949090435061493822476265356047392175668050706", "price":"0.01", "size":"4101.07", "side":"BUY", "hash":"7ebed7e91772fd2b12d57d08cf0b1ee4248c3367", "best_bid":"0.01", "best_ask":"0.02"}], "timestamp":"1770241472721", "event_type":"price_change"}
{"market":"0x38f3050258345e9cf363d1c8cc302f08c65b96ba1a4669d81e07ed69708344df", "price_changes":[{"asset_id":"96888240988495161476033313796107536512663280794332045579302109906525918376981", "price":"0.95", "size":"680", "side":"BUY", "hash":"d2c25067bd88462d68bfca5dea31d32f3a3d70c6", "best_bid":"0.98", "best_ask":"0.99"}, {"asset_id":"81916206347121459497221114766050949090435061493822476265356047392175668050706", "price":"0.05", "size":"680", "side":"SELL", "hash":"9194f76dc39219884c1ddcf909d2eab67c7c3e0d", "best_bid":"0.01", "best_ask":"0.02"}], "timestamp":"1770241472757", "event_type":"price_change"}
{"market":"0x38f3050258345e9cf363d1c8cc302f08c65b96ba1a4669d81e07ed69708344df", "price_changes":[{"asset_id":"96888240988495161476033313796107536512663280794332045579302109906525918376981", "price":"0.94", "size":"753", "side":"BUY", "hash":"b6c5fb061e64159b6e1d2e708f38907b9bd93001", "best_bid":"0.98", "best_ask":"0.99"}, {"asset_id":"81916206347121459497221114766050949090435061493822476265356047392175668050706", "price":"0.06", "size":"753", "side":"SELL", "hash":"114af388c894a23ac5a49835e55df41f1237e488", "best_bid":"0.01", "best_ask":"0.02"}], "timestamp":"1770241472764", "event_type":"price_change"}
{"market":"0x38f3050258345e9cf363d1c8cc302f08c65b96ba1a4669d81e07ed69708344df", "price_changes":[{"asset_id":"96888240988495161476033313796107536512663280794332045579302109906525918376981", "price":"0.94", "size":"726", "side":"BUY", "hash":"20e8f381cd60760a5b43382ae09aab22dffdb968", "best_bid":"0.98", "best_ask":"0.99"}, {"asset_id":"81916206347121459497221114766050949090435061493822476265356047392175668050706", "price":"0.06", "size":"726", "side":"SELL", "hash":"1d9a9905590b35419f88efcd839bc22a3ec5f93a", "best_bid":"0.01", "best_ask":"0.02"}], "timestamp":"1770241472768", "event_type":"price_change"}
{"market":"0x38f3050258345e9cf363d1c8cc302f08c65b96ba1a4669d81e07ed69708344df", "price_changes":[{"asset_id":"96888240988495161476033313796107536512663280794332045579302109906525918376981", "price":"0.95", "size":"707", "side":"BUY", "hash":"d150b09dbfc6e562789a2415d775b07a3ba03791", "best_bid":"0.98", "best_ask":"0.99"}, {"asset_id":"81916206347121459497221114766050949090435061493822476265356047392175668050706", "price":"0.05", "size":"707", "side":"SELL", "hash":"ae48bf6eb93583cd6fb21ae93c5d7c20a58552c3", "best_bid":"0.01", "best_ask":"0.02"}], "timestamp":"1770241472770", "event_type":"price_change"}
{"market":"0x38f3050258345e9cf363d1c8cc302f08c65b96ba1a4669d81e07ed69708344df", "price_changes":[{"asset_id":"96888240988495161476033313796107536512663280794332045579302109906525918376981", "price":"0.95", "size":"680", "side":"BUY", "hash":"ce9d9abc7283f16192cab4d13033cef8ec7d51a0", "best_bid":"0.98", "best_ask":"0.99"}, {"asset_id":"81916206347121459497221114766050949090435061493822476265356047392175668050706", "price":"0.05", "size":"680", "side":"SELL", "hash":"71d99b25a91b7768ccc3620dfb4b816390f9fc0b", "best_bid":"0.01", "best_ask":"0.02"}], "timestamp":"1770241472777", "event_type":"price_change"}
{"market":"0x38f3050258345e9cf363d1c8cc302f08c65b96ba1a4669d81e07ed69708344df", "price_changes":[{"asset_id":"96888240988495161476033313796107536512663280794332045579302109906525918376981", "price":"0.96", "size":"655.73", "side":"BUY", "hash":"edc29f51671651abb1187e80e345fb1bca139ab5", "best_bid":"0.98", "best_ask":"0.99"}, {"asset_id":"81916206347121459497221114766050949090435061493822476265356047392175668050706", "price":"0.04", "size":"655.73", "side":"SELL", "hash":"7f6bc479526582defa6ea239b772ade9715338f2", "best_bid":"0.01", "best_ask":"0.02"}], "timestamp":"1770241472786", "event_type":"price_change"}
{"market":"0x38f3050258345e9cf363d1c8cc302f08c65b96ba1a4669d81e07ed69708344df", "price_changes":[{"asset_id":"96888240988495161476033313796107536512663280794332045579302109906525918376981", "price":"0.96", "size":"682.73", "side":"BUY", "hash":"7d34c9ea67ea46cd27dcfdb9325ce03777f40a4c", "best_bid":"0.98", "best_ask":"0.99"}, {"asset_id":"81916206347121459497221114766050949090435061493822476265356047392175668050706", "price":"0.04", "size":"682.73", "side":"SELL", "hash":"9e775add1cd8f443990cb967416fe73c5f82dc2e", "best_bid":"0.01", "best_ask":"0.02"}], "timestamp":"1770241472787", "event_type":"price_change"}
{"market":"0x38f3050258345e9cf363d1c8cc302f08c65b96ba1a4669d81e07ed69708344df", "price_changes":[{"asset_id":"96888240988495161476033313796107536512663280794332045579302109906525918376981", "price":"0.98", "size":"143.98", "side":"BUY", "hash":"f437e5166b489d8e5cea0515c71b29f2511fbd6e", "best_bid":"0.98", "best_ask":"0.99"}, {"asset_id":"81916206347121459497221114766050949090435061493822476265356047392175668050706", "price":"0.02", "size":"143.98", "side":"SELL", "hash":"0dc1a3d8669a4b7508d0483e575a073d7cbac81c", "best_bid":"0.01", "best_ask":"0.02"}], "timestamp":"1770241472904", "event_type":"price_change"}
{"market":"0x38f3050258345e9cf363d1c8cc302f08c65b96ba1a4669d81e07ed69708344df", "asset_id":"81916206347121459497221114766050949090435061493822476265356047392175668050706", "bids":[{"price":"0.01", "size":"4101.07"}], "asks":[{"price":"0.99", "size":"5019.91"}, {"price":"0.98", "size":"3034.23"}, {"price":"0.97", "size":"3172"}, {"price":"0.96", "size":"3012"}, {"price":"0.95", "size":"3032"}, {"price":"0.94", "size":"3012"}, {"price":"0.93", "size":"3126.28"}, {"price":"0.92", "size":"3012"}, {"price":"0.91", "size":"3012"}, {"price":"0.9", "size":"3087"}, {"price":"0.89", "size":"12"}, {"price":"0.88", "size":"12"}, {"price":"0.87", "size":"12"}, {"price":"0.86", "size":"12"}, {"price":"0.85", "size":"12"}, {"price":"0.84", "size":"12"}, {"price":"0.83", "size":"12"}, {"price":"0.82", "size":"12"}, {"price":"0.81", "size":"12"}, {"price":"0.8", "size":"12"}, {"price":"0.79", "size":"12"}, {"price":"0.78", "size":"12"}, {"price":"0.77", "size":"12"}, {"price":"0.76", "size":"112"}, {"price":"0.75", "size":"40.57"}, {"price":"0.74", "size":"12"}, {"price":"0.73", "size":"293.25"}, {"price":"0.72", "size":"22"}, {"price":"0.71", "size":"12"}, {"price":"0.7", "size":"18"}, {"price":"0.69", "size":"12"}, {"price":"0.68", "size":"12"}, {"price":"0.67", "size":"12"}, {"price":"0.66", "size":"160.89"}, {"price":"0.65", "size":"12"}, {"price":"0.64", "size":"12"}, {"price":"0.63", "size":"12"}, {"price":"0.62", "size":"19.39"}, {"price":"0.61", "size":"18.04"}, {"price":"0.6", "size":"12"}, {"price":"0.59", "size":"94.31"}, {"price":"0.58", "size":"5450.54"}, {"price":"0.57", "size":"12"}, {"price":"0.56", "size":"12"}, {"price":"0.55", "size":"12"}, {"price":"0.54", "size":"22"}, {"price":"0.53", "size":"12"}, {"price":"0.52", "size":"12"}, {"price":"0.51", "size":"12"}, {"price":"0.5", "size":"12"}, {"price":"0.49", "size":"12"}, {"price":"0.48", "size":"12"}, {"price":"0.47", "size":"12"}, {"price":"0.46", "size":"485.56"}, {"price":"0.45", "size":"31"}, {"price":"0.44", "size":"17"}, {"price":"0.43", "size":"12"}, {"price":"0.42", "size":"12"}, {"price":"0.41", "size":"12"}, {"price":"0.4", "size":"127"}, {"price":"0.39", "size":"12"}, {"price":"0.38", "size":"94.51"}, {"price":"0.37", "size":"31.99"}, {"price":"0.36", "size":"12"}, {"price":"0.35", "size":"37"}, {"price":"0.34", "size":"12"}, {"price":"0.33", "size":"12"}, {"price":"0.32", "size":"12"}, {"price":"0.31", "size":"12"}, {"price":"0.3", "size":"31.9"}, {"price":"0.29", "size":"344"}, {"price":"0.28", "size":"3488.99"}, {"price":"0.27", "size":"212"}, {"price":"0.26", "size":"218"}, {"price":"0.25", "size":"212"}, {"price":"0.24", "size":"212"}, {"price":"0.23", "size":"212"}, {"price":"0.22", "size":"1223.14"}, {"price":"0.21", "size":"212"}, {"price":"0.2", "size":"272.99"}, {"price":"0.19", "size":"212"}, {"price":"0.18", "size":"212"}, {"price":"0.17", "size":"212"}, {"price":"0.16", "size":"812"}, {"price":"0.15", "size":"231.08"}, {"price":"0.14", "size":"283.65"}, {"price":"0.13", "size":"212"}, {"price":"0.12", "size":"252"}, {"price":"0.11", "size":"252"}, {"price":"0.1", "size":"737.71"}, {"price":"0.09", "size":"326"}, {"price":"0.08", "size":"844.68"}, {"price":"0.07", "size":"826"}, {"price":"0.06", "size":"726"}, {"price":"0.05", "size":"680"}, {"price":"0.04", "size":"682.73"}, {"price":"0.03", "size":"528.32"}, {"price":"0.02", "size":"143.98"}], "hash":"0dc1a3d8669a4b7508d0483e575a073d7cbac81c", "timestamp":"1770241472904", "event_type":"book"}
{"market":"0x38f3050258345e9cf363d1c8cc302f08c65b96ba1a4669d81e07ed69708344df", "price_changes":[{"asset_id":"96888240988495161476033313796107536512663280794332045579302109906525918376981", "price":"0.94", "size":"753", "side":"BUY", "hash":"01b6d3d0a07c94566c4ba82b7388962a9a39342c", "best_bid":"0.98", "best_ask":"0.99"}, {"asset_id":"81916206347121459497221114766050949090435061493822476265356047392175668050706", "price":"0.06", "size":"753", "side":"SELL", "hash":"ab3f6c56afc81f68d5dbfbdf981feb9c3f041339", "best_bid":"0.01", "best_ask":"0.02"}], "timestamp":"1770241472908", "event_type":"price_change"}
{"market":"0x38f3050258345e9cf363d1c8cc302f08c65b96ba1a4669d81e07ed69708344df", "price_changes":[{"asset_id":"96888240988495161476033313796107536512663280794332045579302109906525918376981", "price":"0.95", "size":"653", "side":"BUY", "hash":"aa92cbc7cd87b434022377b460b1dfc7cb7b5283", "best_bid":"0.98", "best_ask":"0.99"}, {"asset_id":"81916206347121459497221114766050949090435061493822476265356047392175668050706", "price":"0.05", "size":"653", "side":"SELL", "hash":"460bf1454f363f11acf5f2aefa44a24ad5308b21", "best_bid":"0.01", "best_ask":"0.02"}], "timestamp":"1770241472909", "event_type":"price_change"}
{"market":"0x38f3050258345e9cf363d1c8cc302f08c65b96ba1a4669d81e07ed69708344df", "price_changes":[{"asset_id":"96888240988495161476033313796107536512663280794332045579302109906525918376981", "price":"0.95", "size":"626", "side":"BUY", "hash":"1f599744d428fd53b293f7772510be6a1602cdb9", "best_bid":"0.98", "best_ask":"0.99"}, {"asset_id":"81916206347121459497221114766050949090435061493822476265356047392175668050706", "price":"0.05", "size":"626", "side":"SELL", "hash":"e1498f9a92e017a91843d1275fa852ef9d91c3f9", "best_bid":"0.01", "best_ask":"0.02"}], "timestamp":"1770241472918", "event_type":"price_change"}
{"market":"0x38f3050258345e9cf363d1c8cc302f08c65b96ba1a4669d81e07ed69708344df", "price_changes":[{"asset_id":"96888240988495161476033313796107536512663280794332045579302109906525918376981", "price":"0.94", "size":"780", "side":"BUY", "hash":"d527c7bc7e4b0e0dd5ac3208bf2f1f9a0ee8fc73", "best_bid":"0.98", "best_ask":"0.99"}, {"asset_id":"81916206347121459497221114766050949090435061493822476265356047392175668050706", "price":"0.06", "size":"780", "side":"SELL", "hash":"293c8680d7408d4577066d3286b90a6be38f6fd9", "best_bid":"0.01", "best_ask":"0.02"}], "timestamp":"1770241472920", "event_type":"price_change"}
{"market":"0x38f3050258345e9cf363d1c8cc302f08c65b96ba1a4669d81e07ed69708344df", "price_changes":[{"asset_id":"96888240988495161476033313796107536512663280794332045579302109906525918376981", "price":"0.96", "size":"655.73", "side":"BUY", "hash":"79fdbe13db982ca970a1927b514ea337db47918c", "best_bid":"0.98", "best_ask":"0.99"}, {"asset_id":"81916206347121459497221114766050949090435061493822476265356047392175668050706", "price":"0.04", "size":"655.73", "side":"SELL", "hash":"b1632463a1ec857f72307b21bf05591a15af3c48", "best_bid":"0.01", "best_ask":"0.02"}], "timestamp":"1770241472928", "event_type":"price_change"}
{"market":"0x38f3050258345e9cf363d1c8cc302f08c65b96ba1a4669d81e07ed69708344df", "price_changes":[{"asset_id":"96888240988495161476033313796107536512663280794332045579302109906525918376981", "price":"0.95", "size":"653", "side":"BUY", "hash":"c3dc338304582da825875afafc27e178c4204bcd", "best_bid":"0.98", "best_ask":"0.99"}, {"asset_id":"81916206347121459497221114766050949090435061493822476265356047392175668050706", "price":"0.05", "size":"653", "side":"SELL", "hash":"ac85fcb3804335b445262d70eaa692b0c8dae449", "best_bid":"0.01", "best_ask":"0.02"}], "timestamp":"1770241472931", "event_type":"price_change"}
{"market":"0x38f3050258345e9cf363d1c8cc302f08c65b96ba1a4669d81e07ed69708344df", "price_changes":[{"asset_id":"96888240988495161476033313796107536512663280794332045579302109906525918376981", "price":"0.72", "size":"3288.99", "side":"BUY", "hash":"390250d9c6004586d430e824876539a24034dd98", "best_bid":"0.98", "best_ask":"0.99"}, {"asset_id":"81916206347121459497221114766050949090435061493822476265356047392175668050706", "price":"0.28", "size":"3288.99", "side":"SELL", "hash":"bcf67439316dac7ef2d2dad2d2404bf770d9de30", "best_bid":"0.01", "best_ask":"0.02"}], "timestamp":"1770241472949", "event_type":"price_change"}
{"market":"0x38f3050258345e9cf363d1c8cc302f08c65b96ba1a4669d81e07ed69708344df", "price_changes":[{"asset_id":"96888240988495161476033313796107536512663280794332045579302109906525918376981", "price":"0.98", "size":"138.98", "side":"BUY", "hash":"4c4309abb32f6f37be0c5cbe1ed41afe9c43e6ac", "best_bid":"0.98", "best_ask":"0.99"}, {"asset_id":"81916206347121459497221114766050949090435061493822476265356047392175668050706", "price":"0.02", "size":"138.98", "side":"SELL", "hash":"d1569c89ba0de5985c89fe53fc9a23253a5cc177", "best_bid":"0.01", "best_ask":"0.02"}], "timestamp":"1770241472959", "event_type":"price_change"}
{"market":"0x38f3050258345e9cf363d1c8cc302f08c65b96ba1a4669d81e07ed69708344df", "asset_id":"81916206347121459497221114766050949090435061493822476265356047392175668050706", "bids":[{"price":"0.01", "size":"4101.07"}], "asks":[{"price":"0.99", "size":"5019.91"}, {"price":"0.98", "size":"3034.23"}, {"price":"0.97", "size":"3172"}, {"price":"0.96", "size":"3012"}, {"price":"0.95", "size":"3032"}, {"price":"0.94", "size":"3012"}, {"price":"0.93", "size":"3126.28"}, {"price":"0.92", "size":"3012"}, {"price":"0.91", "size":"3012"}, {"price":"0.9", "size":"3087"}, {"price":"0.89", "size":"12"}, {"price":"0.88", "size":"12"}, {"price":"0.87", "size":"12"}, {"price":"0.86", "size":"12"}, {"price":"0.85", "size":"12"}, {"price":"0.84", "size":"12"}, {"price":"0.83", "size":"12"}, {"price":"0.82", "size":"12"}, {"price":"0.81", "size":"12"}, {"price":"0.8", "size":"12"}, {"price":"0.79", "size":"12"}, {"price":"0.78", "size":"12"}, {"price":"0.77", "size":"12"}, {"price":"0.76", "size":"112"}, {"price":"0.75", "size":"40.57"}, {"price":"0.74", "size":"12"}, {"price":"0.73", "size":"293.25"}, {"price":"0.72", "size":"22"}, {"price":"0.71", "size":"12"}, {"price":"0.7", "size":"18"}, {"price":"0.69", "size":"12"}, {"price":"0.68", "size":"12"}, {"price":"0.67", "size":"12"}, {"price":"0.66", "size":"160.89"}, {"price":"0.65", "size":"12"}, {"price":"0.64", "size":"12"}, {"price":"0.63", "size":"12"}, {"price":"0.62", "size":"19.39"}, {"price":"0.61", "size":"18.04"}, {"price":"0.6", "size":"12"}, {"price":"0.59", "size":"94.31"}, {"price":"0.58", "size":"5450.54"}, {"price":"0.57", "size":"12"}, {"price":"0.56", "size":"12"}, {"price":"0.55", "size":"12"}, {"price":"0.54", "size":"22"}, {"price":"0.53", "size":"12"}, {"price":"0.52", "size":"12"}, {"price":"0.51", "size":"12"}, {"price":"0.5", "size":"12"}, {"price":"0.49", "size":"12"}, {"price":"0.48", "size":"12"}, {"price":"0.47", "size":"12"}, {"price":"0.46", "size":"485.56"}, {"price":"0.45", "size":"31"}, {"price":"0.44", "size":"17"}, {"price":"0.43", "size":"12"}, {"price":"0.42", "size":"12"}, {"price":"0.41", "size":"12"}, {"price":"0.4", "size":"127"}, {"price":"0.39", "size":"12"}, {"price":"0.38", "size":"94.51"}, {"price":"0.37", "size":"31.99"}, {"price":"0.36", "size":"12"}, {"price":"0.35", "size":"37"}, {"price":"0.34", "size":"12"}, {"price":"0.33", "size":"12"}, {"price":"0.32", "size":"12"}, {"price":"0.31", "size":"12"}, {"price":"0.3", "size":"31.9"}, {"price":"0.29", "size":"344"}, {"price":"0.28", "size":"3288.99"}, {"price":"0.27", "size":"212"}, {"price":"0.26", "size":"218"}, {"price":"0.25", "size":"212"}, {"price":"0.24", "size":"212"}, {"price":"0.23", "size":"212"}, {"price":"0.22", "size":"1223.14"}, {"price":"0.21", "size":"212"}, {"price":"0.2", "size":"272.99"}, {"price":"0.19", "size":"212"}, {"price":"0.18", "size":"212"}, {"price":"0.17", "size":"212"}, {"price":"0.16", "size":"812"}, {"price":"0.15", "size":"231.08"}, {"price":"0.14", "size":"283.65"}, {"price":"0.13", "size":"212"}, {"price":"0.12", "size":"252"}, {"price":"0.11", "size":"252"}, {"price":"0.1", "size":"737.71"}, {"price":"0.09", "size":"326"}, {"price":"0.08", "size":"844.68"}, {"price":"0.07", "size":"826"}, {"price":"0.06", "size":"780"}, {"price":"0.05", "size":"653"}, {"price":"0.04", "size":"655.73"}, {"price":"0.03", "size":"528.32"}, {"price":"0.02", "size":"138.98"}], "hash":"d1569c89ba0de5985c89fe53fc9a23253a5cc177", "timestamp":"1770241472959", "event_type":"book"}
{"market":"0x38f3050258345e9cf363d1c8cc302f08c65b96ba1a4669d81e07ed69708344df", "price_changes":[{"asset_id":"96888240988495161476033313796107536512663280794332045579302109906525918376981", "price":"0.94", "size":"753", "side":"BUY", "hash":"1689fdd5ae6d05559caf1128a98b453ae01b81f6", "best_bid":"0.98", "best_ask":"0.99"}, {"asset_id":"81916206347121459497221114766050949090435061493822476265356047392175668050706", "price":"0.06", "size":"753", "side":"SELL", "hash":"ebf4ccd907eaf924a774496b8807eeca0237f05a", "best_bid":"0.01", "best_ask":"0.02"}], "timestamp":"1770241473059", "event_type":"price_change"}
{"market":"0x38f3050258345e9cf363d1c8cc302f08c65b96ba1a4669d81e07ed69708344df", "price_changes":[{"asset_id":"96888240988495161476033313796107536512663280794332045579302109906525918376981", "price":"0.96", "size":"682.73", "side":"BUY", "hash":"b59f4ceca94a79144166e8104e5ff0821206ac11", "best_bid":"0.98", "best_ask":"0.99"}, {"asset_id":"81916206347121459497221114766050949090435061493822476265356047392175668050706", "price":"0.04", "size":"682.73", "side":"SELL", "hash":"b00fed1514e3451769f2ca1c66ac1adf2e90fc25", "best_bid":"0.01", "best_ask":"0.02"}], "timestamp":"1770241473065", "event_type":"price_change"}
{"market":"0x38f3050258345e9cf363d1c8cc302f08c65b96ba1a4669d81e07ed69708344df", "price_changes":[{"asset_id":"96888240988495161476033313796107536512663280794332045579302109906525918376981", "price":"0.95", "size":"626", "side":"BUY", "hash":"8ebe361d656460b5c794212a26a377b90670513a", "best_bid":"0.98", "best_ask":"0.99"}, {"asset_id":"81916206347121459497221114766050949090435061493822476265356047392175668050706", "price":"0.05", "size":"626", "side":"SELL", "hash":"bdfdd10a457d686f76781c7e4563d7decee384f7", "best_bid":"0.01", "best_ask":"0.02"}], "timestamp":"1770241473082", "event_type":"price_change"}
{"market":"0x38f3050258345e9cf363d1c8cc302f08c65b96ba1a4669d81e07ed69708344df", "price_changes":[{"asset_id":"96888240988495161476033313796107536512663280794332045579302109906525918376981", "price":"0.97", "size":"555.32", "side":"BUY", "hash":"3388a77587db1b082d60fb798d65c6c5e8de683b", "best_bid":"0.98", "best_ask":"0.99"}, {"asset_id":"81916206347121459497221114766050949090435061493822476265356047392175668050706", "price":"0.03", "size":"555.32", "side":"SELL", "hash":"fce7d25af5efae4250c99b756cbec892ec467a39", "best_bid":"0.01", "best_ask":"0.02"}], "timestamp":"1770241473083", "event_type":"price_change"}
{"market":"0x38f3050258345e9cf363d1c8cc302f08c65b96ba1a4669d81e07ed69708344df", "price_changes":[{"asset_id":"96888240988495161476033313796107536512663280794332045579302109906525918376981", "price":"0.96", "size":"709.73", "side":"BUY", "hash":"5ed316a01ed6acb4cd2d983f46314f73cf5e2a3f", "best_bid":"0.98", "best_ask":"0.99"}, {"asset_id":"81916206347121459497221114766050949090435061493822476265356047392175668050706", "price":"0.04", "size":"709.73", "side":"SELL", "hash":"5df11d212674e4edfdcf7c46e4afc8aae6be928e", "best_bid":"0.01", "best_ask":"0.02"}], "timestamp":"1770241473101", "event_type":"price_change"}
{"market":"0x38f3050258345e9cf363d1c8cc302f08c65b96ba1a4669d81e07ed69708344df", "price_changes":[{"asset_id":"96888240988495161476033313796107536512663280794332045579302109906525918376981", "price":"0.94", "size":"726", "side":"BUY", "hash":"8ad2ed7828b57d86706308240a2dba85a648c467", "best_bid":"0.98", "best_ask":"0.99"}, {"asset_id":"81916206347121459497221114766050949090435061493822476265356047392175668050706", "price":"0.06", "size":"726", "side":"SELL", "hash":"9c8f04623d99c0b3bdadc49cc839fae6d37e6cbc", "best_bid":"0.01", "best_ask":"0.02"}], "timestamp":"1770241473108", "event_type":"price_change"}
{"market":"0x38f3050258345e9cf363d1c8cc302f08c65b96ba1a4669d81e07ed69708344df", "price_changes":[{"asset_id":"96888240988495161476033313796107536512663280794332045579302109906525918376981", "price":"0.98", "size":"158.98", "side":"BUY", "hash":"5833fb90aa94b9fd8f8e3ca9ee056b36d48e4212", "best_bid":"0.98", "best_ask":"0.99"}, {"asset_id":"81916206347121459497221114766050949090435061493822476265356047392175668050706", "price":"0.02", "size":"158.98", "side":"SELL", "hash":"ddd76638627ab5877ba736ab3c05b74fd227e6fa", "best_bid":"0.01", "best_ask":"0.02"}], "timestamp":"1770241473128", "event_type":"price_change"}
{"market":"0x38f3050258345e9cf363d1c8cc302f08c65b96ba1a4669d81e07ed69708344df", "price_changes":[{"asset_id":"96888240988495161476033313796107536512663280794332045579302109906525918376981", "price":"0.94", "size":"753", "side":"BUY", "hash":"2596a1bf44501fecd7993a24612e2622f09c02ce", "best_bid":"0.98", "best_ask":"0.99"}, {"asset_id":"81916206347121459497221114766050949090435061493822476265356047392175668050706", "price":"0.06", "size":"753", "side":"SELL", "hash":"db23fbd8f1d02add3dc6e776dd9e397394aafb38", "best_bid":"0.01", "best_ask":"0.02"}], "timestamp":"1770241473185", "event_type":"price_change"}
{"market":"0x38f3050258345e9cf363d1c8cc302f08c65b96ba1a4669d81e07ed69708344df", "price_changes":[{"asset_id":"96888240988495161476033313796107536512663280794332045579302109906525918376981", "price":"0.96", "size":"682.73", "side":"BUY", "hash":"a11d25a4a9f99f4a5cb21d03d5c907d4e8cbe1ae", "best_bid":"0.98", "best_ask":"0.99"}, {"asset_id":"81916206347121459497221114766050949090435061493822476265356047392175668050706", "price":"0.04", "size":"682.73", "side":"SELL", "hash":"db22b86dbdaac0b215442fed64c15a0cfce4b143", "best_bid":"0.01", "best_ask":"0.02"}], "timestamp":"1770241473188", "event_type":"price_change"}
{"market":"0x38f3050258345e9cf363d1c8cc302f08c65b96ba1a4669d81e07ed69708344df", "price_changes":[{"asset_id":"96888240988495161476033313796107536512663280794332045579302109906525918376981", "price":"0.96", "size":"655.73", "side":"BUY", "hash":"7dcef71ef4ebce331adc5593f4db1b19844bccd6", "best_bid":"0.98", "best_ask":"0.99"}, {"asset_id":"81916206347121459497221114766050949090435061493822476265356047392175668050706", "price":"0.04", "size":"655.73", "side":"SELL", "hash":"396c0025714a735ad9b393737fc0e074efb3670d", "best_bid":"0.01", "best_ask":"0.02"}], "timestamp":"1770241473191", "event_type":"price_change"}
{"market":"0x38f3050258345e9cf363d1c8cc302f08c65b96ba1a4669d81e07ed69708344df", "price_changes":[{"asset_id":"96888240988495161476033313796107536512663280794332045579302109906525918376981", "price":"0.94", "size":"780", "side":"BUY", "hash":"d705bd4a7c9b6505ebc6f1d05aa1f27a4ece1468", "best_bid":"0.98", "best_ask":"0.99"}, {"asset_id":"81916206347121459497221114766050949090435061493822476265356047392175668050706", "price":"0.06", "size":"780", "side":"SELL", "hash":"1796b282d7ce6d59ac1691c1a3c3abf80088cf32", "best_bid":"0.01", "best_ask":"0.02"}], "timestamp":"1770241473193", "event_type":"price_change"}
{"market":"0x38f3050258345e9cf363d1c8cc302f08c65b96ba1a4669d81e07ed69708344df", "price_changes":[{"asset_id":"96888240988495161476033313796107536512663280794332045579302109906525918376981", "price":"0.97", "size":"528.32", "side":"BUY", "hash":"cb66d795606dab94c8e926698e380615c4047f9b", "best_bid":"0.98", "best_ask":"0.99"}, {"asset_id":"81916206347121459497221114766050949090435061493822476265356047392175668050706", "price":"0.03", "size":"528.32", "side":"SELL", "hash":"4e2dd01a0ca2b0952a70f077f691c1007345602a", "best_bid":"0.01", "best_ask":"0.02"}], "timestamp":"1770241473199", "event_type":"price_change"}
{"market":"0x38f3050258345e9cf363d1c8cc302f08c65b96ba1a4669d81e07ed69708344df", "price_changes":[{"asset_id":"96888240988495161476033313796107536512663280794332045579302109906525918376981", "price":"0.95", "size":"653", "side":"BUY", "hash":"4857ee04ce0d73fab8d6d9299895b82a36ee98d8", "best_bid":"0.98", "best_ask":"0.99"}, {"asset_id":"81916206347121459497221114766050949090435061493822476265356047392175668050706", "price":"0.05", "size":"653", "side":"SELL", "hash":"4acc7d27d28d24fbd75615c7dbd35502dfcc3190", "best_bid":"0.01", "best_ask":"0.02"}], "timestamp":"1770241473200", "event_type":"price_change"}
{"market":"0x38f3050258345e9cf363d1c8cc302f08c65b96ba1a4669d81e07ed69708344df", "price_changes":[{"asset_id":"96888240988495161476033313796107536512663280794332045579302109906525918376981", "price":"0.77", "size":"712", "side":"BUY", "hash":"07f321550de410369dd9a28c9c737362c565912a", "best_bid":"0.98", "best_ask":"0.99"}, {"asset_id":"81916206347121459497221114766050949090435061493822476265356047392175668050706", "price":"0.23", "size":"712", "side":"SELL", "hash":"c6c8387dea7c2640a57b8812d7d7fbce9edc9d38", "best_bid":"0.01", "best_ask":"0.02"}], "timestamp":"1770241473264", "event_type":"price_change"}
{"market":"0x38f3050258345e9cf363d1c8cc302f08c65b96ba1a4669d81e07ed69708344df", "price_changes":[{"asset_id":"96888240988495161476033313796107536512663280794332045579302109906525918376981", "price":"0.78", "size":"1423.14", "side":"BUY", "hash":"7a85ebb82339433cccc69016464f86bf5ec02ddb", "best_bid":"0.98", "best_ask":"0.99"}, {"asset_id":"81916206347121459497221114766050949090435061493822476265356047392175668050706", "price":"0.22", "size":"1423.14", "side":"SELL", "hash":"942cb388a268b59d14875e1b0718ffb8f59cfc1f", "best_bid":"0.01", "best_ask":"0.02"}], "timestamp":"1770241473265", "event_type":"price_change"}
{"market":"0x38f3050258345e9cf363d1c8cc302f08c65b96ba1a4669d81e07ed69708344df", "price_changes":[{"asset_id":"96888240988495161476033313796107536512663280794332045579302109906525918376981", "price":"0.94", "size":"753", "side":"BUY", "hash":"eb162159cb8a00ed3fa4df5aad363a4ceef55a76", "best_bid":"0.98", "best_ask":"0.99"}, {"asset_id":"81916206347121459497221114766050949090435061493822476265356047392175668050706", "price":"0.06", "size":"753", "side":"SELL", "hash":"829109944ece218bee626a580b37e902b83cc07a", "best_bid":"0.01", "best_ask":"0.02"}], "timestamp":"1770241473302", "event_type":"price_change"}
{"market":"0x38f3050258345e9cf363d1c8cc302f08c65b96ba1a4669d81e07ed69708344df", "price_changes":[{"asset_id":"96888240988495161476033313796107536512663280794332045579302109906525918376981", "price":"0.95", "size":"680", "side":"BUY", "hash":"1c15732c5a0a176abfae10508b5338b1647acb31", "best_bid":"0.98", "best_ask":"0.99"}, {"asset_id":"81916206347121459497221114766050949090435061493822476265356047392175668050706", "price":"0.05", "size":"680", "side":"SELL", "hash":"2f0ef69ee82978abe948b42e1e5eb7f54d40326c", "best_bid":"0.01", "best_ask":"0.02"}], "timestamp":"1770241473304", "event_type":"price_change"}
{"market":"0x38f3050258345e9cf363d1c8cc302f08c65b96ba1a4669d81e07ed69708344df", "price_changes":[{"asset_id":"96888240988495161476033313796107536512663280794332045579302109906525918376981", "price":"0.94", "size":"726", "side":"BUY", "hash":"cf86050cd8bcb58742a19a5099678eb677d4f127", "best_bid":"0.98", "best_ask":"0.99"}, {"asset_id":"81916206347121459497221114766050949090435061493822476265356047392175668050706", "price":"0.06", "size":"726", "side":"SELL", "hash":"1513035638148f52a6f3b944e3f635490ab3b2b2", "best_bid":"0.01", "best_ask":"0.02"}], "timestamp":"1770241473314", "event_type":"price_change"}
{"market":"0x38f3050258345e9cf363d1c8cc302f08c65b96ba1a4669d81e07ed69708344df", "price_changes":[{"asset_id":"96888240988495161476033313796107536512663280794332045579302109906525918376981", "price":"0.95", "size":"707", "side":"BUY", "hash":"27547e4349eaa05df1795ff1f3b5b89b1e87447a", "best_bid":"0.98", "best_ask":"0.99"}, {"asset_id":"81916206347121459497221114766050949090435061493822476265356047392175668050706", "price":"0.05", "size":"707", "side":"SELL", "hash":"704ba173148d65f1379e991ec8d60caa5f6361a1", "best_bid":"0.01", "best_ask":"0.02"}], "timestamp":"1770241473315", "event_type":"price_change"}
{"market":"0x38f3050258345e9cf363d1c8cc302f08c65b96ba1a4669d81e07ed69708344df", "price_changes":[{"asset_id":"96888240988495161476033313796107536512663280794332045579302109906525918376981", "price":"0.95", "size":"680", "side":"BUY", "hash":"ea83fc85e413d2b03abf628fdad847351108c4fb", "best_bid":"0.98", "best_ask":"0.99"}, {"asset_id":"81916206347121459497221114766050949090435061493822476265356047392175668050706", "price":"0.05", "size":"680", "side":"SELL", "hash":"9555d8705a5d15aa447638f24c78bcb3e2afeabe", "best_bid":"0.01", "best_ask":"0.02"}], "timestamp":"1770241473324", "event_type":"price_change"}
{"market":"0x38f3050258345e9cf363d1c8cc302f08c65b96ba1a4669d81e07ed69708344df", "price_changes":[{"asset_id":"96888240988495161476033313796107536512663280794332045579302109906525918376981", "price":"0.96", "size":"682.73", "side":"BUY", "hash":"ac5e1f85a0b2520e187d49e5b6634a8b2a9a68fc", "best_bid":"0.98", "best_ask":"0.99"}, {"asset_id":"81916206347121459497221114766050949090435061493822476265356047392175668050706", "price":"0.04", "size":"682.73", "side":"SELL", "hash":"fc623f58abdfbacfe0417b6c763ad633934bcce7", "best_bid":"0.01", "best_ask":"0.02"}], "timestamp":"1770241473325", "event_type":"price_change"}
PONG
{"market":"0x38f3050258345e9cf363d1c8cc302f08c65b96ba1a4669d81e07ed69708344df", "price_changes":[{"asset_id":"96888240988495161476033313796107536512663280794332045579302109906525918376981", "price":"0.97", "size":"505.32", "side":"BUY", "hash":"166d7f7f9819ef4e7edcc2b82963b2a393920177", "best_bid":"0.98", "best_ask":"0.99"}, {"asset_id":"81916206347121459497221114766050949090435061493822476265356047392175668050706", "price":"0.03", "size":"505.32", "side":"SELL", "hash":"1194e3413569b8edbab45f8b8c15beb44ff75317", "best_bid":"0.01", "best_ask":"0.02"}], "timestamp":"1770241473741", "event_type":"price_change"}
{"market":"0x38f3050258345e9cf363d1c8cc302f08c65b96ba1a4669d81e07ed69708344df", "price_changes":[{"asset_id":"96888240988495161476033313796107536512663280794332045579302109906525918376981", "price":"0.96", "size":"705.73", "side":"BUY", "hash":"b22d0429e21c6a3271f4d85a72367d8d98e3f4a9", "best_bid":"0.98", "best_ask":"0.99"}, {"asset_id":"81916206347121459497221114766050949090435061493822476265356047392175668050706", "price":"0.04", "size":"705.73", "side":"SELL", "hash":"5ffd78489967499757d4d98871a775813ca2def4", "best_bid":"0.01", "best_ask":"0.02"}], "timestamp":"1770241473742", "event_type":"price_change"}
{"market":"0x38f3050258345e9cf363d1c8cc302f08c65b96ba1a4669d81e07ed69708344df", "price_changes":[{"asset_id":"96888240988495161476033313796107536512663280794332045579302109906525918376981", "price":"0.98", "size":"138.98", "side":"BUY", "hash":"c1bd6370116222b2ab4f8b41614068e24c67d168", "best_bid":"0.98", "best_ask":"0.99"}, {"asset_id":"81916206347121459497221114766050949090435061493822476265356047392175668050706", "price":"0.02", "size":"138.98", "side":"SELL", "hash":"4508c86a171c933676bf8e51162818532eb4e952", "best_bid":"0.01", "best_ask":"0.02"}], "timestamp":"1770241473789", "event_type":"price_change"}
{"market":"0x38f3050258345e9cf363d1c8cc302f08c65b96ba1a4669d81e07ed69708344df", "price_changes":[{"asset_id":"96888240988495161476033313796107536512663280794332045579302109906525918376981", "price":"0.78", "size":"1223.14", "side":"BUY", "hash":"8a69faf5455840b15fe45cb0cdc6b62fd2236016", "best_bid":"0.98", "best_ask":"0.99"}, {"asset_id":"81916206347121459497221114766050949090435061493822476265356047392175668050706", "price":"0.22", "size":"1223.14", "side":"SELL", "hash":"c1cee9c27d7c62b3eb2b8b180acceea1087fcc4e", "best_bid":"0.01", "best_ask":"0.02"}], "timestamp":"1770241473882", "event_type":"price_change"}
{"market":"0x38f3050258345e9cf363d1c8cc302f08c65b96ba1a4669d81e07ed69708344df", "price_changes":[{"asset_id":"81916206347121459497221114766050949090435061493822476265356047392175668050706", "price":"0.01", "size":"4096.02", "side":"BUY", "hash":"febce3ad8e40294db9bb05fddeeca22812101590", "best_bid":"0.01", "best_ask":"0.02"}, {"asset_id":"96888240988495161476033313796107536512663280794332045579302109906525918376981", "price":"0.99", "size":"4096.02", "side":"SELL", "hash":"9ee6ba3d4672c0762c6cae2afbb213f518c829d6", "best_bid":"0.98", "best_ask":"0.99"}], "timestamp":"1770241473908", "event_type":"price_change"}
{"market":"0x38f3050258345e9cf363d1c8cc302f08c65b96ba1a4669d81e07ed69708344df", "asset_id":"81916206347121459497221114766050949090435061493822476265356047392175668050706", "bids":[{"price":"0.01", "size":"4096.02"}], "asks":[{"price":"0.99", "size":"5019.91"}, {"price":"0.98", "size":"3034.23"}, {"price":"0.97", "size":"3172"}, {"price":"0.96", "size":"3012"}, {"price":"0.95", "size":"3032"}, {"price":"0.94", "size":"3012"}, {"price":"0.93", "size":"3126.28"}, {"price":"0.92", "size":"3012"}, {"price":"0.91", "size":"3012"}, {"price":"0.9", "size":"3087"}, {"price":"0.89", "size":"12"}, {"price":"0.88", "size":"12"}, {"price":"0.87", "size":"12"}, {"price":"0.86", "size":"12"}, {"price":"0.85", "size":"12"}, {"price":"0.84", "size":"12"}, {"price":"0.83", "size":"12"}, {"price":"0.82", "size":"12"}, {"price":"0.81", "size":"12"}, {"price":"0.8", "size":"12"}, {"price":"0.79", "size":"12"}, {"price":"0.78", "size":"12"}, {"price":"0.77", "size":"12"}, {"price":"0.76", "size":"112"}, {"price":"0.75", "size":"40.57"}, {"price":"0.74", "size":"12"}, {"price":"0.73", "size":"293.25"}, {"price":"0.72", "size":"22"}, {"price":"0.71", "size":"12"}, {"price":"0.7", "size":"18"}, {"price":"0.69", "size":"12"}, {"price":"0.68", "size":"12"}, {"price":"0.67", "size":"12"}, {"price":"0.66", "size":"160.89"}, {"price":"0.65", "size":"12"}, {"price":"0.64", "size":"12"}, {"price":"0.63", "size":"12"}, {"price":"0.62", "size":"19.39"}, {"price":"0.61", "size":"18.04"}, {"price":"0.6", "size":"12"}, {"price":"0.59", "size":"94.31"}, {"price":"0.58", "size":"5450.54"}, {"price":"0.57", "size":"12"}, {"price":"0.56", "size":"12"}, {"price":"0.55", "size":"12"}, {"price":"0.54", "size":"22"}, {"price":"0.53", "size":"12"}, {"price":"0.52", "size":"12"}, {"price":"0.51", "size":"12"}, {"price":"0.5", "size":"12"}, {"price":"0.49", "size":"12"}, {"price":"0.48", "size":"12"}, {"price":"0.47", "size":"12"}, {"price":"0.46", "size":"485.56"}, {"price":"0.45", "size":"31"}, {"price":"0.44", "size":"17"}, {"price":"0.43", "size":"12"}, {"price":"0.42", "size":"12"}, {"price":"0.41", "size":"12"}, {"price":"0.4", "size":"127"}, {"price":"0.39", "size":"12"}, {"price":"0.38", "size":"94.51"}, {"price":"0.37", "size":"31.99"}, {"price":"0.36", "size":"12"}, {"price":"0.35", "size":"37"}, {"price":"0.34", "size":"12"}, {"price":"0.33", "size":"12"}, {"price":"0.32", "size":"12"}, {"price":"0.31", "size":"12"}, {"price":"0.3", "size":"31.9"}, {"price":"0.29", "size":"344"}, {"price":"0.28", "size":"3288.99"}, {"price":"0.27", "size":"212"}, {"price":"0.26", "size":"218"}, {"price":"0.25", "size":"212"}, {"price":"0.24", "size":"212"}, {"price":"0.23", "size":"712"}, {"price":"0.22", "size":"1223.14"}, {"price":"0.21", "size":"212"}, {"price":"0.2", "size":"272.99"}, {"price":"0.19", "size":"212"}, {"price":"0.18", "size":"212"}, {"price":"0.17", "size":"212"}, {"price":"0.16", "size":"812"}, {"price":"0.15", "size":"231.08"}, {"price":"0.14", "size":"283.65"}, {"price":"0.13", "size":"212"}, {"price":"0.12", "size":"252"}, {"price":"0.11", "size":"252"}, {"price":"0.1", "size":"737.71"}, {"price":"0.09", "size":"326"}, {"price":"0.08", "size":"844.68"}, {"price":"0.07", "size":"826"}, {"price":"0.06", "size":"726"}, {"price":"0.05", "size":"680"}, {"price":"0.04", "size":"705.73"}, {"price":"0.03", "size":"505.32"}, {"price":"0.02", "size":"138.98"}], "hash":"febce3ad8e40294db9bb05fddeeca22812101590", "timestamp":"1770241473908", "event_type":"book"}
{"market":"0x38f3050258345e9cf363d1c8cc302f08c65b96ba1a4669d81e07ed69708344df", "price_changes":[{"asset_id":"81916206347121459497221114766050949090435061493822476265356047392175668050706", "price":"0.01", "size":"4123.02", "side":"BUY", "hash":"f2a41ae37b9461ab352eb67de4e34e0904d84093", "best_bid":"0.01", "best_ask":"0.02"}, {"asset_id":"96888240988495161476033313796107536512663280794332045579302109906525918376981", "price":"0.99", "size":"4123.02", "side":"SELL", "hash":"f3245151d17aee4994843d7d2749a930bc3c9bba", "best_bid":"0.98", "best_ask":"0.99"}], "timestamp":"1770241473925", "event_type":"price_change"}
{"market":"0x38f3050258345e9cf363d1c8cc302f08c65b96ba1a4669d81e07ed69708344df", "price_changes":[{"asset_id":"81916206347121459497221114766050949090435061493822476265356047392175668050706", "price":"0.01", "size":"4146.02", "side":"BUY", "hash":"df4cf1fcc96fd6b45f33f847fece3675de363631", "best_bid":"0.01", "best_ask":"0.02"}, {"asset_id":"96888240988495161476033313796107536512663280794332045579302109906525918376981", "price":"0.99", "size":"4146.02", "side":"SELL", "hash":"e838452d0b61918ec92d7e86ce3014e2eb99b0dd", "best_bid":"0.98", "best_ask":"0.99"}], "timestamp":"1770241473936", "event_type":"price_change"}
{"market":"0x38f3050258345e9cf363d1c8cc302f08c65b96ba1a4669d81e07ed69708344df", "price_changes":[{"asset_id":"81916206347121459497221114766050949090435061493822476265356047392175668050706", "price":"0.01", "size":"4173.02", "side":"BUY", "hash":"8a9dfbe16f1c71058bee87289e17381ba9506c43", "best_bid":"0.01", "best_ask":"0.02"}, {"asset_id":"96888240988495161476033313796107536512663280794332045579302109906525918376981", "price":"0.99", "size":"4173.02", "side":"SELL", "hash":"4abcea28397855eda4053de99f12743d06920c7f", "best_bid":"0.98", "best_ask":"0.99"}], "timestamp":"1770241473943", "event_type":"price_change"}
{"market":"0x38f3050258345e9cf363d1c8cc302f08c65b96ba1a4669d81e07ed69708344df", "price_changes":[{"asset_id":"81916206347121459497221114766050949090435061493822476265356047392175668050706", "price":"0.01", "size":"4200.02", "side":"BUY", "hash":"396c45c9d571dbc4d149c6035c4d602aff26afe2", "best_bid":"0.01", "best_ask":"0.02"}, {"asset_id":"96888240988495161476033313796107536512663280794332045579302109906525918376981", "price":"0.99", "size":"4200.02", "side":"SELL", "hash":"18a4326e3d90df2c1c6cc4e6d763dbc537884aad", "best_bid":"0.98", "best_ask":"0.99"}], "timestamp":"1770241473953", "event_type":"price_change"}
{"market":"0x38f3050258345e9cf363d1c8cc302f08c65b96ba1a4669d81e07ed69708344df", "price_changes":[{"asset_id":"81916206347121459497221114766050949090435061493822476265356047392175668050706", "price":"0.01", "size":"4099", "side":"BUY", "hash":"ef34b2fd56c6923bce71605b5ce19b6ab5210425", "best_bid":"0.01", "best_ask":"0.02"}, {"asset_id":"96888240988495161476033313796107536512663280794332045579302109906525918376981", "price":"0.99", "size":"4099", "side":"SELL", "hash":"4f77603db877b576d042e0082c9a609989b8be95", "best_bid":"0.98", "best_ask":"0.99"}], "timestamp":"1770241473983", "event_type":"price_change"}
