{"market":"0x38f3050258345e9cf363d1c8cc302f08c65b96ba1a4669d81e07ed69708344df", "asset_id":"81916206347121459497221114766050949090435061493822476265356047392175668050706", "bids":[{"price":"0.01", "size":"3866.89"}], "asks":[{"price":"0.99", "size":"5019.91"}, {"price":"0.98", "size":"3034.23"}, {"price":"0.97", "size":"3172"}, {"price":"0.96", "size":"3012"}, {"price":"0.95", "size":"3032"}, {"price":"0.94", "size":"3012"}, {"price":"0.93", "size":"3126.28"}, {"price":"0.92", "size":"3012"}, {"price":"0.91", "size":"3012"}, {"price":"0.9", "size":"3087"}, {"price":"0.89", "size":"12"}, {"price":"0.88", "size":"12"}, {"price":"0.87", "size":"12"}, {"price":"0.86", "size":"12"}, {"price":"0.85", "size":"12"}, {"price":"0.84", "size":"12"}, {"price":"0.83", "size":"12"}, {"price":"0.82", "size":"12"}, {"price":"0.81", "size":"12"}, {"price":"0.8", "size":"12"}, {"price":"0.79", "size":"12"}, {"price":"0.78", "size":"12"}, {"price":"0.77", "size":"12"}, {"price":"0.76", "size":"112"}, {"price":"0.75", "size":"40.57"}, {"price":"0.74", "size":"12"}, {"price":"0.73", "size":"293.25"}, {"price":"0.72", "size":"22"}, {"price":"0.71", "size":"12"}, {"price":"0.7", "size":"18"}, {"price":"0.69", "size":"12"}, {"price":"0.68", "size":"12"}, {"price":"0.67", "size":"12"}, {"price":"0.66", "size":"160.89"}, {"price":"0.65", "size":"12"}, {"price":"0.64", "size":"12"}, {"price":"0.63", "size":"12"}, {"price":"0.62", "size":"19.39"}, {"price":"0.61", "size":"18.04"}, {"price":"0.6", "size":"12"}, {"price":"0.59", "size":"94.31"}, {"price":"0.58", "size":"5450.54"}, {"price":"0.57", "size":"12"}, {"price":"0.56", "size":"12"}, {"price":"0.55", "size":"12"}, {"price":"0.54", "size":"22"}, {"price":"0.53", "size":"12"}, {"price":"0.52", "size":"12"}, {"price":"0.51", "size":"12"}, {"price":"0.5", "size":"12"}, {"price":"0.49", "size":"12"}, {"price":"0.48", "size":"12"}, {"price":"0.47", "size":"12"}, {"price":"0.46", "size":"485.56"}, {"price":"0.45", "size":"31"}, {"price":"0.44", "size":"17"}, {"price":"0.43", "size":"12"}, {"price":"0.42", "size":"12"}, {"price":"0.41", "size":"12"}, {"price":"0.4", "size":"127"}, {"price":"0.39", "size":"12"}, {"price":"0.38", "size":"94.51"}, {"price":"0.37", "size":"31.99"}, {"price":"0.36", "size":"12"}, {"price":"0.35", "size":"37"}, {"price":"0.34", "size":"12"}, {"price":"0.33", "size":"12"}, {"price":"0.32", "size":"12"}, {"price":"0.31", "size":"12"}, {"price":"0.3", "size":"31.9"}, {"price":"0.29", "size":"344"}, {"price":"0.28", "size":"3288.99"}, {"price":"0.27", "size":"212"}, {"price":"0.26", "size":"218"}, {"price":"0.25", "size":"212"}, {"price":"0.24", "size":"212"}, {"price":"0.23", "size":"212"}, {"price":"0.22", "size":"1723.14"}, {"price":"0.21", "size":"212"}, {"price":"0.2", "size":"472.99"}, {"price":"0.19", "size":"212"}, {"price":"0.18", "size":"212"}, {"price":"0.17", "size":"212"}, {"price":"0.16", "size":"812"}, {"price":"0.15", "size":"231.08"}, {"price":"0.14", "size":"283.65"}, {"price":"0.13", "size":"212"}, {"price":"0.12", "size":"252"}, {"price":"0.11", "size":"252"}, {"price":"0.1", "size":"737.71"}, {"price":"0.09", "size":"261"}, {"price":"0.08", "size":"844.68"}, {"price":"0.07", "size":"326"}, {"price":"0.06", "size":"926"}, {"price":"0.05", "size":"680"}, {"price":"0.04", "size":"650.73"}, {"price":"0.03", "size":"645.32"}, {"price":"0.02", "size":"588.97"}], "hash":"83b1fdcd9be7814fe959e107f5fdddf49f93fa8c", "timestamp":"1770241478347", "event_type":"book"}
{"market":"0x38f3050258345e9cf363d1c8cc302f08c65b96ba1a4669d81e07ed69708344df", "price_changes":[{"asset_id":"96888240988495161476033313796107536512663280794332045579302109906525918376981", "price":"0.97", "size":"622.32", "side":"BUY", "hash":"3603f1126594a5874e932dd0f3ebcfcbbc26e965", "best_bid":"0.98", "best_ask":"0.99"}, {"asset_id":"81916206347121459497221114766050949090435061493822476265356047392175668050706", "price":"0.03", "size":"622.32", "side":"SELL", "hash":"b9cb2213d2b6f0c7151cb16e717fd9a4f78d6be0", "best_bid":"0.01", "best_ask":"0.02"}], "timestamp":"1770241478589", "event_type":"price_change"}
{"market":"0x38f3050258345e9cf363d1c8cc302f08c65b96ba1a4669d81e07ed69708344df", "price_changes":[{"asset_id":"96888240988495161476033313796107536512663280794332045579302109906525918376981", "price":"0.96", "size":"673.73", "side":"BUY", "hash":"383dc802c02d44116878ff1f5f2630a9192e6011", "best_bid":"0.98", "best_ask":"0.99"}, {"asset_id":"81916206347121459497221114766050949090435061493822476265356047392175668050706", "price":"0.04", "size":"673.73", "side":"SELL", "hash":"a94d7aba5ecd7565351025118b46fd1f46da499d", "best_bid":"0.01", "best_ask":"0.02"}], "timestamp":"1770241478591", "event_type":"price_change"}
{"market":"0x38f3050258345e9cf363d1c8cc302f08c65b96ba1a4669d81e07ed69708344df", "price_changes":[{"asset_id":"81916206347121459497221114766050949090435061493822476265356047392175668050706", "price":"0.01", "size":"3893.89", "side":"BUY", "hash":"751d323312ce67146726f16bb300b6c39a9c3889", "best_bid":"0.01", "best_ask":"0.02"}, {"asset_id":"96888240988495161476033313796107536512663280794332045579302109906525918376981", "price":"0.99", "size":"3893.89", "side":"SELL", "hash":"7e9617c577500053f696addc6093e50894361733", "best_bid":"0.98", "best_ask":"0.99"}], "timestamp":"1770241478891", "event_type":"price_change"}
{"market":"0x38f3050258345e9cf363d1c8cc302f08c65b96ba1a4669d81e07ed69708344df", "price_changes":[{"asset_id":"81916206347121459497221114766050949090435061493822476265356047392175668050706", "price":"0.01", "size":"3866.89", "side":"BUY", "hash":"1f564326caadd8fdaf09dc79e7f4c4c01ac2db60", "best_bid":"0.01", "best_ask":"0.02"}, {"asset_id":"96888240988495161476033313796107536512663280794332045579302109906525918376981", "price":"0.99", "size":"3866.89", "side":"SELL", "hash":"b8e159c645a8eb029ad089b492bb5813a3e3d3f9", "best_bid":"0.98", "best_ask":"0.99"}], "timestamp":"1770241478891", "event_type":"price_change"}
{"market":"0x38f3050258345e9cf363d1c8cc302f08c65b96ba1a4669d81e07ed69708344df", "price_changes":[{"asset_id":"96888240988495161476033313796107536512663280794332045579302109906525918376981", "price":"0.95", "size":"707", "side":"BUY", "hash":"d66f50b642ff49f436e5fc3eda36d67879b4ecaa", "best_bid":"0.98", "best_ask":"0.99"}, {"asset_id":"81916206347121459497221114766050949090435061493822476265356047392175668050706", "price":"0.05", "size":"707", "side":"SELL", "hash":"5ab435bd1f6d89e62f48d78698b7d414311ba41d", "best_bid":"0.01", "best_ask":"0.02"}], "timestamp":"1770241478893", "event_type":"price_change"}
{"market":"0x38f3050258345e9cf363d1c8cc302f08c65b96ba1a4669d81e07ed69708344df", "price_changes":[{"asset_id":"96888240988495161476033313796107536512663280794332045579302109906525918376981", "price":"0.95", "size":"680", "side":"BUY", "hash":"6650d02ecb52db47698724f820c2f1a90a3e3b33", "best_bid":"0.98", "best_ask":"0.99"}, {"asset_id":"81916206347121459497221114766050949090435061493822476265356047392175668050706", "price":"0.05", "size":"680", "side":"SELL", "hash":"98a8ba47059ea5bab70c4be87779ffe96eccc98b", "best_bid":"0.01", "best_ask":"0.02"}], "timestamp":"1770241478894", "event_type":"price_change"}
{"market":"0x38f3050258345e9cf363d1c8cc302f08c65b96ba1a4669d81e07ed69708344df", "price_changes":[{"asset_id":"96888240988495161476033313796107536512663280794332045579302109906525918376981", "price":"0.95", "size":"653", "side":"BUY", "hash":"469c4612c9eaf145755f72dd6cbfa8a5afba938e", "best_bid":"0.98", "best_ask":"0.99"}, {"asset_id":"81916206347121459497221114766050949090435061493822476265356047392175668050706", "price":"0.05", "size":"653", "side":"SELL", "hash":"35a9331bdfb9eb25bf535a3a24e596c2058db06b", "best_bid":"0.01", "best_ask":"0.02"}], "timestamp":"1770241478900", "event_type":"price_change"}
{"market":"0x38f3050258345e9cf363d1c8cc302f08c65b96ba1a4669d81e07ed69708344df", "price_changes":[{"asset_id":"81916206347121459497221114766050949090435061493822476265356047392175668050706", "price":"0.01", "size":"3893.89", "side":"BUY", "hash":"8b36719a19179f274bc5af3b042ce9149f5292ab", "best_bid":"0.01", "best_ask":"0.02"}, {"asset_id":"96888240988495161476033313796107536512663280794332045579302109906525918376981", "price":"0.99", "size":"3893.89", "side":"SELL", "hash":"bf959713818d77c92fb126603a96bc3555d2f519", "best_bid":"0.98", "best_ask":"0.99"}], "timestamp":"1770241478901", "event_type":"price_change"}
{"market":"0x38f3050258345e9cf363d1c8cc302f08c65b96ba1a4669d81e07ed69708344df", "price_changes":[{"asset_id":"81916206347121459497221114766050949090435061493822476265356047392175668050706", "price":"0.01", "size":"3866.89", "side":"BUY", "hash":"ce767040882d6392ba74ed33c511a2c30cbf9d9f", "best_bid":"0.01", "best_ask":"0.02"}, {"asset_id":"96888240988495161476033313796107536512663280794332045579302109906525918376981", "price":"0.99", "size":"3866.89", "side":"SELL", "hash":"8c836596a2b93eadaf97d5624a3cadff16914b8d", "best_bid":"0.98", "best_ask":"0.99"}], "timestamp":"1770241478902", "event_type":"price_change"}
{"market":"0x38f3050258345e9cf363d1c8cc302f08c65b96ba1a4669d81e07ed69708344df", "price_changes":[{"asset_id":"96888240988495161476033313796107536512663280794332045579302109906525918376981", "price":"0.95", "size":"680", "side":"BUY", "hash":"bd36ebbd2d8fc4b29552f55eae6a3f25e194090f", "best_bid":"0.98", "best_ask":"0.99"}, {"asset_id":"81916206347121459497221114766050949090435061493822476265356047392175668050706", "price":"0.05", "size":"680", "side":"SELL", "hash":"b578a07f85760de05e3728914f2c4fba584a7a43", "best_bid":"0.01", "best_ask":"0.02"}], "timestamp":"1770241478902", "event_type":"price_change"}
{"market":"0x38f3050258345e9cf363d1c8cc302f08c65b96ba1a4669d81e07ed69708344df", "price_changes":[{"asset_id":"96888240988495161476033313796107536512663280794332045579302109906525918376981", "price":"0.96", "size":"700.73", "side":"BUY", "hash":"02211046bbcb835340f536ac27bc8edbfad56f19", "best_bid":"0.98", "best_ask":"0.99"}, {"asset_id":"81916206347121459497221114766050949090435061493822476265356047392175668050706", "price":"0.04", "size":"700.73", "side":"SELL", "hash":"e51d796a9bda9bf3394eb59300973d9b64686d94", "best_bid":"0.01", "best_ask":"0.02"}], "timestamp":"1770241478910", "event_type":"price_change"}
{"market":"0x38f3050258345e9cf363d1c8cc302f08c65b96ba1a4669d81e07ed69708344df", "price_changes":[{"asset_id":"81916206347121459497221114766050949090435061493822476265356047392175668050706", "price":"0.01", "size":"3893.89", "side":"BUY", "hash":"a43bfd61a767f5662b10b9a0880e0c8ee07d2629", "best_bid":"0.01", "best_ask":"0.02"}, {"asset_id":"96888240988495161476033313796107536512663280794332045579302109906525918376981", "price":"0.99", "size":"3893.89", "side":"SELL", "hash":"db8428bb5c164caa875f58bc22264028b900c430", "best_bid":"0.98", "best_ask":"0.99"}], "timestamp":"1770241478911", "event_type":"price_change"}
{"market":"0x38f3050258345e9cf363d1c8cc302f08c65b96ba1a4669d81e07ed69708344df", "price_changes":[{"asset_id":"81916206347121459497221114766050949090435061493822476265356047392175668050706", "price":"0.01", "size":"3866.89", "side":"BUY", "hash":"f20a424af154fabef1a5bf197a7bcef277cb0da7", "best_bid":"0.01", "best_ask":"0.02"}, {"asset_id":"96888240988495161476033313796107536512663280794332045579302109906525918376981", "price":"0.99", "size":"3866.89", "side":"SELL", "hash":"3244ed08dc8932b114821422b0f50fa8118917dd", "best_bid":"0.98", "best_ask":"0.99"}], "timestamp":"1770241478912", "event_type":"price_change"}
{"market":"0x38f3050258345e9cf363d1c8cc302f08c65b96ba1a4669d81e07ed69708344df", "price_changes":[{"asset_id":"96888240988495161476033313796107536512663280794332045579302109906525918376981", "price":"0.96", "size":"673.73", "side":"BUY", "hash":"a36377a87854275389fed7b6cf84c26fcf311317", "best_bid":"0.98", "best_ask":"0.99"}, {"asset_id":"81916206347121459497221114766050949090435061493822476265356047392175668050706", "price":"0.04", "size":"673.73", "side":"SELL", "hash":"f932ff6db11c859c71c0988095ffb08cdad2467e", "best_bid":"0.01", "best_ask":"0.02"}], "timestamp":"1770241478914", "event_type":"price_change"}
{"market":"0x38f3050258345e9cf363d1c8cc302f08c65b96ba1a4669d81e07ed69708344df", "price_changes":[{"asset_id":"81916206347121459497221114766050949090435061493822476265356047392175668050706", "price":"0.01", "size":"3839.89", "side":"BUY", "hash":"af48cf1c4ff794c85f32bd9ff6e6fc40439ac312", "best_bid":"0.01", "best_ask":"0.02"}, {"asset_id":"96888240988495161476033313796107536512663280794332045579302109906525918376981", "price":"0.99", "size":"3839.89", "side":"SELL", "hash":"fc93df76498fa9c0d5f2279e45e88cb0a5c2a480", "best_bid":"0.98", "best_ask":"0.99"}], "timestamp":"1770241479009", "event_type":"price_change"}
{"market":"0x38f3050258345e9cf363d1c8cc302f08c65b96ba1a4669d81e07ed69708344df", "price_changes":[{"asset_id":"96888240988495161476033313796107536512663280794332045579302109906525918376981", "price":"0.95", "size":"653", "side":"BUY", "hash":"47b90b3c262317f69676ff352ed230ce25d76272", "best_bid":"0.98", "best_ask":"0.99"}, {"asset_id":"81916206347121459497221114766050949090435061493822476265356047392175668050706", "price":"0.05", "size":"653", "side":"SELL", "hash":"009532f3963d2100c93a08a32a1680180208a5ec", "best_bid":"0.01", "best_ask":"0.02"}], "timestamp":"1770241479009", "event_type":"price_change"}
{"market":"0x38f3050258345e9cf363d1c8cc302f08c65b96ba1a4669d81e07ed69708344df", "price_changes":[{"asset_id":"81916206347121459497221114766050949090435061493822476265356047392175668050706", "price":"0.01", "size":"3866.89", "side":"BUY", "hash":"adf85ed299e07c2c83406243ed2f4c5707a3e590", "best_bid":"0.01", "best_ask":"0.02"}, {"asset_id":"96888240988495161476033313796107536512663280794332045579302109906525918376981", "price":"0.99", "size":"3866.89", "side":"SELL", "hash":"d8c8cc556244ba45f88f1a634c9144b4841ab142", "best_bid":"0.98", "best_ask":"0.99"}], "timestamp":"1770241479011", "event_type":"price_change"}
{"market":"0x38f3050258345e9cf363d1c8cc302f08c65b96ba1a4669d81e07ed69708344df", "price_changes":[{"asset_id":"96888240988495161476033313796107536512663280794332045579302109906525918376981", "price":"0.94", "size":"953", "side":"BUY", "hash":"e0bde3890907a47e7650b9a577b2015cf5570c25", "best_bid":"0.98", "best_ask":"0.99"}, {"asset_id":"81916206347121459497221114766050949090435061493822476265356047392175668050706", "price":"0.06", "size":"953", "side":"SELL", "hash":"f537ff07e81feeab1f006a8acab66b79fef3c261", "best_bid":"0.01", "best_ask":"0.02"}], "timestamp":"1770241479012", "event_type":"price_change"}
{"market":"0x38f3050258345e9cf363d1c8cc302f08c65b96ba1a4669d81e07ed69708344df", "price_changes":[{"asset_id":"96888240988495161476033313796107536512663280794332045579302109906525918376981", "price":"0.94", "size":"980", "side":"BUY", "hash":"4180869a48d38cbd37f38d9bdd5bd887c71be23f", "best_bid":"0.98", "best_ask":"0.99"}, {"asset_id":"81916206347121459497221114766050949090435061493822476265356047392175668050706", "price":"0.06", "size":"980", "side":"SELL", "hash":"7dbff6c26b761547a46923c432058c15985c4b8a", "best_bid":"0.01", "best_ask":"0.02"}], "timestamp":"1770241479020", "event_type":"price_change"}
{"market":"0x38f3050258345e9cf363d1c8cc302f08c65b96ba1a4669d81e07ed69708344df", "price_changes":[{"asset_id":"81916206347121459497221114766050949090435061493822476265356047392175668050706", "price":"0.01", "size":"3839.89", "side":"BUY", "hash":"9de6a1bbfb6be919e0adcaf57477d7a2429ddcfe", "best_bid":"0.01", "best_ask":"0.02"}, {"asset_id":"96888240988495161476033313796107536512663280794332045579302109906525918376981", "price":"0.99", "size":"3839.89", "side":"SELL", "hash":"521bfafd789d18623b7b8f76908e072194d71122", "best_bid":"0.98", "best_ask":"0.99"}], "timestamp":"1770241479021", "event_type":"price_change"}
{"market":"0x38f3050258345e9cf363d1c8cc302f08c65b96ba1a4669d81e07ed69708344df", "price_changes":[{"asset_id":"81916206347121459497221114766050949090435061493822476265356047392175668050706", "price":"0.01", "size":"3866.89", "side":"BUY", "hash":"4ec7382a9706ad69c0751c957d8101fff6860de9", "best_bid":"0.01", "best_ask":"0.02"}, {"asset_id":"96888240988495161476033313796107536512663280794332045579302109906525918376981", "price":"0.99", "size":"3866.89", "side":"SELL", "hash":"eb4b4bac636b6c34bf4d323003e7074b4c346071", "best_bid":"0.98", "best_ask":"0.99"}], "timestamp":"1770241479021", "event_type":"price_change"}
{"market":"0x38f3050258345e9cf363d1c8cc302f08c65b96ba1a4669d81e07ed69708344df", "price_changes":[{"asset_id":"96888240988495161476033313796107536512663280794332045579302109906525918376981", "price":"0.95", "size":"626", "side":"BUY", "hash":"4edc0d8faaa32f5039c64d8ab2aed36c3d8e344c", "best_bid":"0.98", "best_ask":"0.99"}, {"asset_id":"81916206347121459497221114766050949090435061493822476265356047392175668050706", "price":"0.05", "size":"626", "side":"SELL", "hash":"019bb84290000a52c97a9fdd08887654c2d8423f", "best_bid":"0.01", "best_ask":"0.02"}], "timestamp":"1770241479029", "event_type":"price_change"}
{"market":"0x38f3050258345e9cf363d1c8cc302f08c65b96ba1a4669d81e07ed69708344df", "price_changes":[{"asset_id":"81916206347121459497221114766050949090435061493822476265356047392175668050706", "price":"0.01", "size":"3839.89", "side":"BUY", "hash":"e71dc974b0e74e4f0458a9c533bd2ff94f8ac05d", "best_bid":"0.01", "best_ask":"0.02"}, {"asset_id":"96888240988495161476033313796107536512663280794332045579302109906525918376981", "price":"0.99", "size":"3839.89", "side":"SELL", "hash":"bc1621f8d394ba3cc46cd9eaae52bc30418c83ca", "best_bid":"0.98", "best_ask":"0.99"}], "timestamp":"1770241479032", "event_type":"price_change"}
{"market":"0x38f3050258345e9cf363d1c8cc302f08c65b96ba1a4669d81e07ed69708344df", "price_changes":[{"asset_id":"96888240988495161476033313796107536512663280794332045579302109906525918376981", "price":"0.96", "size":"646.73", "side":"BUY", "hash":"ac9f4f3564d9ab8d05777e524b8f42bd5d519aef", "best_bid":"0.98", "best_ask":"0.99"}, {"asset_id":"81916206347121459497221114766050949090435061493822476265356047392175668050706", "price":"0.04", "size":"646.73", "side":"SELL", "hash":"bc019fbcfe66a54a51278bf9836ad23d6df32781", "best_bid":"0.01", "best_ask":"0.02"}], "timestamp":"1770241479032", "event_type":"price_change"}
{"market":"0x38f3050258345e9cf363d1c8cc302f08c65b96ba1a4669d81e07ed69708344df", "price_changes":[{"asset_id":"96888240988495161476033313796107536512663280794332045579302109906525918376981", "price":"0.95", "size":"653", "side":"BUY", "hash":"a9f2b1e3f0561aba228882aa15136da53a11fc0c", "best_bid":"0.98", "best_ask":"0.99"}, {"asset_id":"81916206347121459497221114766050949090435061493822476265356047392175668050706", "price":"0.05", "size":"653", "side":"SELL", "hash":"7404c3b07d4dedb65f35308e0ca844a55698a0ae", "best_bid":"0.01", "best_ask":"0.02"}], "timestamp":"1770241479033", "event_type":"price_change"}
{"market":"0x38f3050258345e9cf363d1c8cc302f08c65b96ba1a4669d81e07ed69708344df", "price_changes":[{"asset_id":"81916206347121459497221114766050949090435061493822476265356047392175668050706", "price":"0.01", "size":"3866.89", "side":"BUY", "hash":"013ed530556cb9bb1bb3fea5d958b4d23832e957", "best_bid":"0.01", "best_ask":"0.02"}, {"asset_id":"96888240988495161476033313796107536512663280794332045579302109906525918376981", "price":"0.99", "size":"3866.89", "side":"SELL", "hash":"492db4d0b891c01a33614a299ce759c2bc4884f9", "best_bid":"0.98", "best_ask":"0.99"}], "timestamp":"1770241479041", "event_type":"price_change"}
{"market":"0x38f3050258345e9cf363d1c8cc302f08c65b96ba1a4669d81e07ed69708344df", "price_changes":[{"asset_id":"96888240988495161476033313796107536512663280794332045579302109906525918376981", "price":"0.96", "size":"626.73", "side":"BUY", "hash":"de14511bfd288b19ba282d89edce225803496f59", "best_bid":"0.98", "best_ask":"0.99"}, {"asset_id":"81916206347121459497221114766050949090435061493822476265356047392175668050706", "price":"0.04", "size":"626.73", "side":"SELL", "hash":"cbc4dd967b824211a830e2409ded96bc94781ce0", "best_bid":"0.01", "best_ask":"0.02"}], "timestamp":"1770241479060", "event_type":"price_change"}
{"market":"0x38f3050258345e9cf363d1c8cc302f08c65b96ba1a4669d81e07ed69708344df", "price_changes":[{"asset_id":"96888240988495161476033313796107536512663280794332045579302109906525918376981", "price":"0.96", "size":"603.73", "side":"BUY", "hash":"37cf94d44ccddffa4968ce5e80a731265363a2cf", "best_bid":"0.98", "best_ask":"0.99"}, {"asset_id":"81916206347121459497221114766050949090435061493822476265356047392175668050706", "price":"0.04", "size":"603.73", "side":"SELL", "hash":"2f2b20dc50e8b8015db54b05d969f6fc11f3a885", "best_bid":"0.01", "best_ask":"0.02"}], "timestamp":"1770241479088", "event_type":"price_change"}
{"market":"0x38f3050258345e9cf363d1c8cc302f08c65b96ba1a4669d81e07ed69708344df", "price_changes":[{"asset_id":"96888240988495161476033313796107536512663280794332045579302109906525918376981", "price":"0.97", "size":"645.32", "side":"BUY", "hash":"bf5cf3a36cfa469f1295d29196f78e2a48cf567a", "best_bid":"0.98", "best_ask":"0.99"}, {"asset_id":"81916206347121459497221114766050949090435061493822476265356047392175668050706", "price":"0.03", "size":"645.32", "side":"SELL", "hash":"4cbc6183e93ec5e45deb3e3ef13b23890146ade9", "best_bid":"0.01", "best_ask":"0.02"}], "timestamp":"1770241479092", "event_type":"price_change"}
{"market":"0x38f3050258345e9cf363d1c8cc302f08c65b96ba1a4669d81e07ed69708344df", "price_changes":[{"asset_id":"81916206347121459497221114766050949090435061493822476265356047392175668050706", "price":"0.01", "size":"3893.89", "side":"BUY", "hash":"29f35f02133a15cec29aba988f3b1566427a535c", "best_bid":"0.01", "best_ask":"0.02"}, {"asset_id":"96888240988495161476033313796107536512663280794332045579302109906525918376981", "price":"0.99", "size":"3893.89", "side":"SELL", "hash":"6c629c0674b05a553a1d77151c0a28066ce9a76b", "best_bid":"0.98", "best_ask":"0.99"}], "timestamp":"1770241479131", "event_type":"price_change"}
{"market":"0x38f3050258345e9cf363d1c8cc302f08c65b96ba1a4669d81e07ed69708344df", "price_changes":[{"asset_id":"81916206347121459497221114766050949090435061493822476265356047392175668050706", "price":"0.01", "size":"3866.89", "side":"BUY", "hash":"710347590d573b09d676b745e50bf3db5d04eeeb", "best_bid":"0.01", "best_ask":"0.02"}, {"asset_id":"96888240988495161476033313796107536512663280794332045579302109906525918376981", "price":"0.99", "size":"3866.89", "side":"SELL", "hash":"0320d1c25f2561b1dd2e0225da0b1ee6b7bc5334", "best_bid":"0.98", "best_ask":"0.99"}], "timestamp":"1770241479131", "event_type":"price_change"}
{"market":"0x38f3050258345e9cf363d1c8cc302f08c65b96ba1a4669d81e07ed69708344df", "price_changes":[{"asset_id":"96888240988495161476033313796107536512663280794332045579302109906525918376981", "price":"0.94", "size":"953", "side":"BUY", "hash":"1ea9ba25f7a8ba5851f81ac8f700107d0281f19e", "best_bid":"0.98", "best_ask":"0.99"}, {"asset_id":"81916206347121459497221114766050949090435061493822476265356047392175668050706", "price":"0.06", "size":"953", "side":"SELL", "hash":"f61725f6c6be80fe0b09fa1d02cd332be5c0673b", "best_bid":"0.01", "best_ask":"0.02"}], "timestamp":"1770241479132", "event_type":"price_change"}
{"market":"0x38f3050258345e9cf363d1c8cc302f08c65b96ba1a4669d81e07ed69708344df", "price_changes":[{"asset_id":"96888240988495161476033313796107536512663280794332045579302109906525918376981", "price":"0.95", "size":"680", "side":"BUY", "hash":"83e4c09844b5ca19d8bc8c2d1701219362b67537", "best_bid":"0.98", "best_ask":"0.99"}, {"asset_id":"81916206347121459497221114766050949090435061493822476265356047392175668050706", "price":"0.05", "size":"680", "side":"SELL", "hash":"46c34090baa20a9148ac9e4b0faef0d39293f5a9", "best_bid":"0.01", "best_ask":"0.02"}], "timestamp":"1770241479134", "event_type":"price_change"}
{"market":"0x38f3050258345e9cf363d1c8cc302f08c65b96ba1a4669d81e07ed69708344df", "price_changes":[{"asset_id":"81916206347121459497221114766050949090435061493822476265356047392175668050706", "price":"0.01", "size":"3839.89", "side":"BUY", "hash":"eec0db23755c362d85815c13cefca5e560170f69", "best_bid":"0.01", "best_ask":"0.02"}, {"asset_id":"96888240988495161476033313796107536512663280794332045579302109906525918376981", "price":"0.99", "size":"3839.89", "side":"SELL", "hash":"f90ee9b9ba5af3772dd187ca9716977b63b01276", "best_bid":"0.98", "best_ask":"0.99"}], "timestamp":"1770241479143", "event_type":"price_change"}
{"market":"0x38f3050258345e9cf363d1c8cc302f08c65b96ba1a4669d81e07ed69708344df", "price_changes":[{"asset_id":"96888240988495161476033313796107536512663280794332045579302109906525918376981", "price":"0.94", "size":"926", "side":"BUY", "hash":"8958058ea08426ab7d89098d323b2a1d1a39f244", "best_bid":"0.98", "best_ask":"0.99"}, {"asset_id":"81916206347121459497221114766050949090435061493822476265356047392175668050706", "price":"0.06", "size":"926", "side":"SELL", "hash":"e647fb4f4f192e1ff64ca03fbcc99bfd04b37abb", "best_bid":"0.01", "best_ask":"0.02"}], "timestamp":"1770241479143", "event_type":"price_change"}
{"market":"0x38f3050258345e9cf363d1c8cc302f08c65b96ba1a4669d81e07ed69708344df", "price_changes":[{"asset_id":"96888240988495161476033313796107536512663280794332045579302109906525918376981", "price":"0.95", "size":"707", "side":"BUY", "hash":"f2370fecd0c8101d25131cff8c97b9edff9f4bf6", "best_bid":"0.98", "best_ask":"0.99"}, {"asset_id":"81916206347121459497221114766050949090435061493822476265356047392175668050706", "price":"0.05", "size":"707", "side":"SELL", "hash":"a8910bf412b4b928e897d7f8965adc588638bc36", "best_bid":"0.01", "best_ask":"0.02"}], "timestamp":"1770241479144", "event_type":"price_change"}
{"market":"0x38f3050258345e9cf363d1c8cc302f08c65b96ba1a4669d81e07ed69708344df", "price_changes":[{"asset_id":"81916206347121459497221114766050949090435061493822476265356047392175668050706", "price":"0.01", "size":"3866.89", "side":"BUY", "hash":"7a485056604a27566a0523194fbb7da825e03591", "best_bid":"0.01", "best_ask":"0.02"}, {"asset_id":"96888240988495161476033313796107536512663280794332045579302109906525918376981", "price":"0.99", "size":"3866.89", "side":"SELL", "hash":"a4b1769b830603d0bc074518b66a2789a871fd94", "best_bid":"0.98", "best_ask":"0.99"}], "timestamp":"1770241479146", "event_type":"price_change"}
{"market":"0x38f3050258345e9cf363d1c8cc302f08c65b96ba1a4669d81e07ed69708344df", "price_changes":[{"asset_id":"81916206347121459497221114766050949090435061493822476265356047392175668050706", "price":"0.01", "size":"3893.89", "side":"BUY", "hash":"f09b390a4769af21aa2447b5370abc865202568f", "best_bid":"0.01", "best_ask":"0.02"}, {"asset_id":"96888240988495161476033313796107536512663280794332045579302109906525918376981", "price":"0.99", "size":"3893.89", "side":"SELL", "hash":"ad0cbb6696957a7c9c73a55fed15fa4c54b520a1", "best_bid":"0.98", "best_ask":"0.99"}], "timestamp":"1770241479151", "event_type":"price_change"}
{"market":"0x38f3050258345e9cf363d1c8cc302f08c65b96ba1a4669d81e07ed69708344df", "price_changes":[{"asset_id":"96888240988495161476033313796107536512663280794332045579302109906525918376981", "price":"0.95", "size":"680", "side":"BUY", "hash":"ee804202e250a24fdf146c93c30a8a7b88c14fa8", "best_bid":"0.98", "best_ask":"0.99"}, {"asset_id":"81916206347121459497221114766050949090435061493822476265356047392175668050706", "price":"0.05", "size":"680", "side":"SELL", "hash":"f99e9dde40d8845dd63a79db1b513ea412984c45", "best_bid":"0.01", "best_ask":"0.02"}], "timestamp":"1770241479152", "event_type":"price_change"}
{"market":"0x38f3050258345e9cf363d1c8cc302f08c65b96ba1a4669d81e07ed69708344df", "price_changes":[{"asset_id":"81916206347121459497221114766050949090435061493822476265356047392175668050706", "price":"0.01", "size":"3866.89", "side":"BUY", "hash":"1e1544fc442b3100f5015a33ae69d6ebdda58bc6", "best_bid":"0.01", "best_ask":"0.02"}, {"asset_id":"96888240988495161476033313796107536512663280794332045579302109906525918376981", "price":"0.99", "size":"3866.89", "side":"SELL", "hash":"35e2d0bf7db052e0c4f144f4a7b4f0f5716bf470", "best_bid":"0.98", "best_ask":"0.99"}], "timestamp":"1770241479153", "event_type":"price_change"}
{"market":"0x38f3050258345e9cf363d1c8cc302f08c65b96ba1a4669d81e07ed69708344df", "price_changes":[{"asset_id":"96888240988495161476033313796107536512663280794332045579302109906525918376981", "price":"0.96", "size":"630.73", "side":"BUY", "hash":"671818abe89178b680b1ae65db81a686294d497f", "best_bid":"0.98", "best_ask":"0.99"}, {"asset_id":"81916206347121459497221114766050949090435061493822476265356047392175668050706", "price":"0.04", "size":"630.73", "side":"SELL", "hash":"2aa89304f525acb055d89aa1823b2e89880bab50", "best_bid":"0.01", "best_ask":"0.02"}], "timestamp":"1770241479156", "event_type":"price_change"}
{"market":"0x38f3050258345e9cf363d1c8cc302f08c65b96ba1a4669d81e07ed69708344df", "price_changes":[{"asset_id":"96888240988495161476033313796107536512663280794332045579302109906525918376981", "price":"0.97", "size":"622.32", "side":"BUY", "hash":"eb9d00c64139a2547fd570e38010be40b82602a5", "best_bid":"0.98", "best_ask":"0.99"}, {"asset_id":"81916206347121459497221114766050949090435061493822476265356047392175668050706", "price":"0.03", "size":"622.32", "side":"SELL", "hash":"748bb4404a467f8123dbb14e547c2a6f9fdb772f", "best_bid":"0.01", "best_ask":"0.02"}], "timestamp":"1770241479160", "event_type":"price_change"}
{"market":"0x38f3050258345e9cf363d1c8cc302f08c65b96ba1a4669d81e07ed69708344df", "price_changes":[{"asset_id":"96888240988495161476033313796107536512663280794332045579302109906525918376981", "price":"0.94", "size":"953", "side":"BUY", "hash":"496466a6e7992f5202127472ec61895923051703", "best_bid":"0.98", "best_ask":"0.99"}, {"asset_id":"81916206347121459497221114766050949090435061493822476265356047392175668050706", "price":"0.06", "size":"953", "side":"SELL", "hash":"2385a41e68cac5ae2f37671e44ef1aa0776010c8", "best_bid":"0.01", "best_ask":"0.02"}], "timestamp":"1770241479263", "event_type":"price_change"}
{"market":"0x38f3050258345e9cf363d1c8cc302f08c65b96ba1a4669d81e07ed69708344df", "price_changes":[{"asset_id":"96888240988495161476033313796107536512663280794332045579302109906525918376981", "price":"0.95", "size":"653", "side":"BUY", "hash":"153702e2214dcaf52a2e766d6e625a208ca7d9bb", "best_bid":"0.98", "best_ask":"0.99"}, {"asset_id":"81916206347121459497221114766050949090435061493822476265356047392175668050706", "price":"0.05", "size":"653", "side":"SELL", "hash":"828dbd011ac6f400d34dfc5144d94ce8a46fd015", "best_bid":"0.01", "best_ask":"0.02"}], "timestamp":"1770241479264", "event_type":"price_change"}
{"market":"0x38f3050258345e9cf363d1c8cc302f08c65b96ba1a4669d81e07ed69708344df", "price_changes":[{"asset_id":"96888240988495161476033313796107536512663280794332045579302109906525918376981", "price":"0.95", "size":"626", "side":"BUY", "hash":"0d92cd7d86f4cceab32078287f2677e1adb226b5", "best_bid":"0.98", "best_ask":"0.99"}, {"asset_id":"81916206347121459497221114766050949090435061493822476265356047392175668050706", "price":"0.05", "size":"626", "side":"SELL", "hash":"3a6dec727d58f0059f1f67ea7821f783e8a84a30", "best_bid":"0.01", "best_ask":"0.02"}], "timestamp":"1770241479267", "event_type":"price_change"}
{"market":"0x38f3050258345e9cf363d1c8cc302f08c65b96ba1a4669d81e07ed69708344df", "price_changes":[{"asset_id":"81916206347121459497221114766050949090435061493822476265356047392175668050706", "price":"0.01", "size":"3839.89", "side":"BUY", "hash":"24a6688247a07c805e319c7ebfc355299c6c885c", "best_bid":"0.01", "best_ask":"0.02"}, {"asset_id":"96888240988495161476033313796107536512663280794332045579302109906525918376981", "price":"0.99", "size":"3839.89", "side":"SELL", "hash":"5a2aba200f6ce2b3afebd4684563af0aa273e7d9", "best_bid":"0.98", "best_ask":"0.99"}], "timestamp":"1770241479267", "event_type":"price_change"}
{"market":"0x38f3050258345e9cf363d1c8cc302f08c65b96ba1a4669d81e07ed69708344df", "price_changes":[{"asset_id":"81916206347121459497221114766050949090435061493822476265356047392175668050706", "price":"0.01", "size":"3866.89", "side":"BUY", "hash":"bb98b1545ad873c973c582b964f9755d3a7d8a7f", "best_bid":"0.01", "best_ask":"0.02"}, {"asset_id":"96888240988495161476033313796107536512663280794332045579302109906525918376981", "price":"0.99", "size":"3866.89", "side":"SELL", "hash":"97d6c61e6321f1e3e8b2c9cd9f11b98459c33df0", "best_bid":"0.98", "best_ask":"0.99"}], "timestamp":"1770241479268", "event_type":"price_change"}
{"market":"0x38f3050258345e9cf363d1c8cc302f08c65b96ba1a4669d81e07ed69708344df", "price_changes":[{"asset_id":"81916206347121459497221114766050949090435061493822476265356047392175668050706", "price":"0.01", "size":"3839.89", "side":"BUY", "hash":"0133c3f121f14604fdd671c43d284562bebb4842", "best_bid":"0.01", "best_ask":"0.02"}, {"asset_id":"96888240988495161476033313796107536512663280794332045579302109906525918376981", "price":"0.99", "size":"3839.89", "side":"SELL", "hash":"2b87796ef0c5c3aafa82df6828358bef01038678", "best_bid":"0.98", "best_ask":"0.99"}], "timestamp":"1770241479268", "event_type":"price_change"}
{"market":"0x38f3050258345e9cf363d1c8cc302f08c65b96ba1a4669d81e07ed69708344df", "price_changes":[{"asset_id":"96888240988495161476033313796107536512663280794332045579302109906525918376981", "price":"0.94", "size":"980", "side":"BUY", "hash":"145acfcc735d7a5cb98104be2e6ee4bcd853902f", "best_bid":"0.98", "best_ask":"0.99"}, {"asset_id":"81916206347121459497221114766050949090435061493822476265356047392175668050706", "price":"0.06", "size":"980", "side":"SELL", "hash":"fbbee81bbe347671f63e318bc35aa1768a2d8e3f", "best_bid":"0.01", "best_ask":"0.02"}], "timestamp":"1770241479269", "event_type":"price_change"}
{"market":"0x38f3050258345e9cf363d1c8cc302f08c65b96ba1a4669d81e07ed69708344df", "price_changes":[{"asset_id":"81916206347121459497221114766050949090435061493822476265356047392175668050706", "price":"0.01", "size":"3866.89", "side":"BUY", "hash":"0f514781824f14b66b0cda9f6b674c6c90d6fd38", "best_bid":"0.01", "best_ask":"0.02"}, {"asset_id":"96888240988495161476033313796107536512663280794332045579302109906525918376981", "price":"0.99", "size":"3866.89", "side":"SELL", "hash":"52aecc0bc428a51b411152726b739e213a2ffee2", "best_bid":"0.98", "best_ask":"0.99"}], "timestamp":"1770241479270", "event_type":"price_change"}
{"market":"0x38f3050258345e9cf363d1c8cc302f08c65b96ba1a4669d81e07ed69708344df", "price_changes":[{"asset_id":"96888240988495161476033313796107536512663280794332045579302109906525918376981", "price":"0.96", "size":"603.73", "side":"BUY", "hash":"b9f787f2e789dc285f4aa597e8a68055befab233", "best_bid":"0.98", "best_ask":"0.99"}, {"asset_id":"81916206347121459497221114766050949090435061493822476265356047392175668050706", "price":"0.04", "size":"603.73", "side":"SELL", "hash":"35d36d0f9ef0118dbdf9138fd765b9c847e4760e", "best_bid":"0.01", "best_ask":"0.02"}], "timestamp":"1770241479281", "event_type":"price_change"}
{"market":"0x38f3050258345e9cf363d1c8cc302f08c65b96ba1a4669d81e07ed69708344df", "price_changes":[{"asset_id":"81916206347121459497221114766050949090435061493822476265356047392175668050706", "price":"0.01", "size":"3893.89", "side":"BUY", "hash":"0dbecd1a3120e80f4788e978e183374c26d51983", "best_bid":"0.01", "best_ask":"0.02"}, {"asset_id":"96888240988495161476033313796107536512663280794332045579302109906525918376981", "price":"0.99", "size":"3893.89", "side":"SELL", "hash":"892d38f76b2c1806500308a2fabaf7a9da25b19e", "best_bid":"0.98", "best_ask":"0.99"}], "timestamp":"1770241479282", "event_type":"price_change"}
{"market":"0x38f3050258345e9cf363d1c8cc302f08c65b96ba1a4669d81e07ed69708344df", "price_changes":[{"asset_id":"81916206347121459497221114766050949090435061493822476265356047392175668050706", "price":"0.01", "size":"3866.89", "side":"BUY", "hash":"5ac37ce8c1f07199ee8527cddb47db435c901d39", "best_bid":"0.01", "best_ask":"0.02"}, {"asset_id":"96888240988495161476033313796107536512663280794332045579302109906525918376981", "price":"0.99", "size":"3866.89", "side":"SELL", "hash":"44c374f616cb5ada9a5fa17d6b9fc41e8cf5bcd7", "best_bid":"0.98", "best_ask":"0.99"}], "timestamp":"1770241479282", "event_type":"price_change"}
{"market":"0x38f3050258345e9cf363d1c8cc302f08c65b96ba1a4669d81e07ed69708344df", "price_changes":[{"asset_id":"96888240988495161476033313796107536512663280794332045579302109906525918376981", "price":"0.95", "size":"653", "side":"BUY", "hash":"9f6c1274efff44669fb097c4debabbf132004251", "best_bid":"0.98", "best_ask":"0.99"}, {"asset_id":"81916206347121459497221114766050949090435061493822476265356047392175668050706", "price":"0.05", "size":"653", "side":"SELL", "hash":"57b41dc172644682a4f84d59c65d42629a832996", "best_bid":"0.01", "best_ask":"0.02"}], "timestamp":"1770241479284", "event_type":"price_change"}
{"market":"0x38f3050258345e9cf363d1c8cc302f08c65b96ba1a4669d81e07ed69708344df", "price_changes":[{"asset_id":"96888240988495161476033313796107536512663280794332045579302109906525918376981", "price":"0.99", "size":"3875.89", "side":"SELL", "hash":"c26e88eebb8abea7555a5b84185301ea436722d9", "best_bid":"0.98", "best_ask":"0.99"}, {"asset_id":"81916206347121459497221114766050949090435061493822476265356047392175668050706", "price":"0.01", "size":"3875.89", "side":"BUY", "hash":"df680e50f7c2e89b9b661e453e336133236cb49e", "best_bid":"0.01", "best_ask":"0.02"}], "timestamp":"1770241479332", "event_type":"price_change"}
{"market":"0x38f3050258345e9cf363d1c8cc302f08c65b96ba1a4669d81e07ed69708344df", "price_changes":[{"asset_id":"81916206347121459497221114766050949090435061493822476265356047392175668050706", "price":"0.01", "size":"3848.89", "side":"BUY", "hash":"6e26c29a437adcd8946664ef658c96b8733f5da4", "best_bid":"0.01", "best_ask":"0.02"}, {"asset_id":"96888240988495161476033313796107536512663280794332045579302109906525918376981", "price":"0.99", "size":"3848.89", "side":"SELL", "hash":"932288fdb3b005b7ccaf590fc3e77bf2aef6667d", "best_bid":"0.98", "best_ask":"0.99"}], "timestamp":"1770241479394", "event_type":"price_change"}
{"market":"0x38f3050258345e9cf363d1c8cc302f08c65b96ba1a4669d81e07ed69708344df", "price_changes":[{"asset_id":"96888240988495161476033313796107536512663280794332045579302109906525918376981", "price":"0.94", "size":"953", "side":"BUY", "hash":"3b5a7565695fe28184c2ff25c2fa3e54828fc4a0", "best_bid":"0.98", "best_ask":"0.99"}, {"asset_id":"81916206347121459497221114766050949090435061493822476265356047392175668050706", "price":"0.06", "size":"953", "side":"SELL", "hash":"a56d618c76659b9bca2595b5d00796ea93534e52", "best_bid":"0.01", "best_ask":"0.02"}], "timestamp":"1770241479394", "event_type":"price_change"}
{"market":"0x38f3050258345e9cf363d1c8cc302f08c65b96ba1a4669d81e07ed69708344df", "price_changes":[{"asset_id":"81916206347121459497221114766050949090435061493822476265356047392175668050706", "price":"0.01", "size":"3875.89", "side":"BUY", "hash":"9adbd87d139fbd58cfc1976acaa8a6ee48e7d67a", "best_bid":"0.01", "best_ask":"0.02"}, {"asset_id":"96888240988495161476033313796107536512663280794332045579302109906525918376981", "price":"0.99", "size":"3875.89", "side":"SELL", "hash":"e24a74d7383fac3ecde255bd1e1f75b82a06b193", "best_bid":"0.98", "best_ask":"0.99"}], "timestamp":"1770241479395", "event_type":"price_change"}
{"market":"0x38f3050258345e9cf363d1c8cc302f08c65b96ba1a4669d81e07ed69708344df", "price_changes":[{"asset_id":"96888240988495161476033313796107536512663280794332045579302109906525918376981", "price":"0.95", "size":"680", "side":"BUY", "hash":"ec0e06383f644ed4a6f4c5698437ce1f3ff43d71", "best_bid":"0.98", "best_ask":"0.99"}, {"asset_id":"81916206347121459497221114766050949090435061493822476265356047392175668050706", "price":"0.05", "size":"680", "side":"SELL", "hash":"cec53fe97c0dd33288deeae79a084c36bcc2e94a", "best_bid":"0.01", "best_ask":"0.02"}], "timestamp":"1770241479396", "event_type":"price_change"}
{"market":"0x38f3050258345e9cf363d1c8cc302f08c65b96ba1a4669d81e07ed69708344df", "price_changes":[{"asset_id":"81916206347121459497221114766050949090435061493822476265356047392175668050706", "price":"0.01", "size":"3848.89", "side":"BUY", "hash":"5c92d2d6634bae27895b673cad650faedba8917b", "best_bid":"0.01", "best_ask":"0.02"}, {"asset_id":"96888240988495161476033313796107536512663280794332045579302109906525918376981", "price":"0.99", "size":"3848.89", "side":"SELL", "hash":"27c63f6dbe401e093c6d32ada1290b49fcf7fa0b", "best_bid":"0.98", "best_ask":"0.99"}], "timestamp":"1770241479404", "event_type":"price_change"}
{"market":"0x38f3050258345e9cf363d1c8cc302f08c65b96ba1a4669d81e07ed69708344df", "price_changes":[{"asset_id":"96888240988495161476033313796107536512663280794332045579302109906525918376981", "price":"0.94", "size":"926", "side":"BUY", "hash":"56d96b152c8e0139705016600d3eb6da93f32b8e", "best_bid":"0.98", "best_ask":"0.99"}, {"asset_id":"81916206347121459497221114766050949090435061493822476265356047392175668050706", "price":"0.06", "size":"926", "side":"SELL", "hash":"a8a7f5ef3b1418a65488f8af7711580bb21aa6f9", "best_bid":"0.01", "best_ask":"0.02"}], "timestamp":"1770241479405", "event_type":"price_change"}
{"market":"0x38f3050258345e9cf363d1c8cc302f08c65b96ba1a4669d81e07ed69708344df", "price_changes":[{"asset_id":"96888240988495161476033313796107536512663280794332045579302109906525918376981", "price":"0.95", "size":"707", "side":"BUY", "hash":"f3476bced03fcc7117ee576d2b1d18565aaf9927", "best_bid":"0.98", "best_ask":"0.99"}, {"asset_id":"81916206347121459497221114766050949090435061493822476265356047392175668050706", "price":"0.05", "size":"707", "side":"SELL", "hash":"a99221221b7a42e364d50f38bbd56883aea0ad30", "best_bid":"0.01", "best_ask":"0.02"}], "timestamp":"1770241479406", "event_type":"price_change"}
{"market":"0x38f3050258345e9cf363d1c8cc302f08c65b96ba1a4669d81e07ed69708344df", "price_changes":[{"asset_id":"81916206347121459497221114766050949090435061493822476265356047392175668050706", "price":"0.01", "size":"3875.89", "side":"BUY", "hash":"87fec980ab8196acf8f9d69f5d2dfb3f30425b7f", "best_bid":"0.01", "best_ask":"0.02"}, {"asset_id":"96888240988495161476033313796107536512663280794332045579302109906525918376981", "price":"0.99", "size":"3875.89", "side":"SELL", "hash":"3b70822206cfc433a1c0e8f0274c5c47e7b0d814", "best_bid":"0.98", "best_ask":"0.99"}], "timestamp":"1770241479407", "event_type":"price_change"}
{"market":"0x38f3050258345e9cf363d1c8cc302f08c65b96ba1a4669d81e07ed69708344df", "price_changes":[{"asset_id":"81916206347121459497221114766050949090435061493822476265356047392175668050706", "price":"0.01", "size":"3848.89", "side":"BUY", "hash":"6c135f8cd0b4ba427bfc3864041110a34dd0636a", "best_bid":"0.01", "best_ask":"0.02"}, {"asset_id":"96888240988495161476033313796107536512663280794332045579302109906525918376981", "price":"0.99", "size":"3848.89", "side":"SELL", "hash":"25108b1a41822358138dd6c3be47a3c9e9b14d75", "best_bid":"0.98", "best_ask":"0.99"}], "timestamp":"1770241479414", "event_type":"price_change"}
{"market":"0x38f3050258345e9cf363d1c8cc302f08c65b96ba1a4669d81e07ed69708344df", "price_changes":[{"asset_id":"81916206347121459497221114766050949090435061493822476265356047392175668050706", "price":"0.01", "size":"3875.89", "side":"BUY", "hash":"f01a1e74918d32a9ced4726592bdd84241262162", "best_bid":"0.01", "best_ask":"0.02"}, {"asset_id":"96888240988495161476033313796107536512663280794332045579302109906525918376981", "price":"0.99", "size":"3875.89", "side":"SELL", "hash":"98b75ec0a45e0dff81740987500390812ca157f2", "best_bid":"0.98", "best_ask":"0.99"}], "timestamp":"1770241479414", "event_type":"price_change"}
{"market":"0x38f3050258345e9cf363d1c8cc302f08c65b96ba1a4669d81e07ed69708344df", "price_changes":[{"asset_id":"96888240988495161476033313796107536512663280794332045579302109906525918376981", "price":"0.96", "size":"630.73", "side":"BUY", "hash":"9c6a2b2462c3fa13ca1ba3aff70a186cc4141ada", "best_bid":"0.98", "best_ask":"0.99"}, {"asset_id":"81916206347121459497221114766050949090435061493822476265356047392175668050706", "price":"0.04", "size":"630.73", "side":"SELL", "hash":"9364d08d069cbaa74249a3c549eec65488f5471b", "best_bid":"0.01", "best_ask":"0.02"}], "timestamp":"1770241479417", "event_type":"price_change"}
{"market":"0x38f3050258345e9cf363d1c8cc302f08c65b96ba1a4669d81e07ed69708344df", "price_changes":[{"asset_id":"96888240988495161476033313796107536512663280794332045579302109906525918376981", "price":"0.95", "size":"680", "side":"BUY", "hash":"b9d90eb6f8720cb11249704fc97f463bca5edc48", "best_bid":"0.98", "best_ask":"0.99"}, {"asset_id":"81916206347121459497221114766050949090435061493822476265356047392175668050706", "price":"0.05", "size":"680", "side":"SELL", "hash":"15a02402536827ea0a6e5c2f65923f8c6ef5c6da", "best_bid":"0.01", "best_ask":"0.02"}], "timestamp":"1770241479420", "event_type":"price_change"}
{"market":"0x38f3050258345e9cf363d1c8cc302f08c65b96ba1a4669d81e07ed69708344df", "price_changes":[{"asset_id":"96888240988495161476033313796107536512663280794332045579302109906525918376981", "price":"0.96", "size":"650.73", "side":"BUY", "hash":"7110f06129af9d77964fa65bc8aa92c0993cff71", "best_bid":"0.98", "best_ask":"0.99"}, {"asset_id":"81916206347121459497221114766050949090435061493822476265356047392175668050706", "price":"0.04", "size":"650.73", "side":"SELL", "hash":"176fb09949a6a6d14b9024ddd93161749394914f", "best_bid":"0.01", "best_ask":"0.02"}], "timestamp":"1770241479450", "event_type":"price_change"}
{"market":"0x38f3050258345e9cf363d1c8cc302f08c65b96ba1a4669d81e07ed69708344df", "price_changes":[{"asset_id":"81916206347121459497221114766050949090435061493822476265356047392175668050706", "price":"0.01", "size":"3848.89", "side":"BUY", "hash":"719a526ae885fe15de72ec471785d97dd230bf98", "best_bid":"0.01", "best_ask":"0.02"}, {"asset_id":"96888240988495161476033313796107536512663280794332045579302109906525918376981", "price":"0.99", "size":"3848.89", "side":"SELL", "hash":"34ac82b584bf705e3a4f54601cdee07db9818654", "best_bid":"0.98", "best_ask":"0.99"}], "timestamp":"1770241479947", "event_type":"price_change"}
{"market":"0x38f3050258345e9cf363d1c8cc302f08c65b96ba1a4669d81e07ed69708344df", "price_changes":[{"asset_id":"81916206347121459497221114766050949090435061493822476265356047392175668050706", "price":"0.01", "size":"3875.89", "side":"BUY", "hash":"bdc770c45403b56e8f78de05d674edb9dc167ca2", "best_bid":"0.01", "best_ask":"0.02"}, {"asset_id":"96888240988495161476033313796107536512663280794332045579302109906525918376981", "price":"0.99", "size":"3875.89", "side":"SELL", "hash":"671561cf1cc8d61f2f06aaeb0872e8e83b78d4e0", "best_bid":"0.98", "best_ask":"0.99"}], "timestamp":"1770241479948", "event_type":"price_change"}
{"market":"0x38f3050258345e9cf363d1c8cc302f08c65b96ba1a4669d81e07ed69708344df", "price_changes":[{"asset_id":"96888240988495161476033313796107536512663280794332045579302109906525918376981", "price":"0.95", "size":"653", "side":"BUY", "hash":"caf0b7567a0f8a1e465839465c2d178f93be9a9c", "best_bid":"0.98", "best_ask":"0.99"}, {"asset_id":"81916206347121459497221114766050949090435061493822476265356047392175668050706", "price":"0.05", "size":"653", "side":"SELL", "hash":"be972b1af572673e78dcfdfb645877f448295b3e", "best_bid":"0.01", "best_ask":"0.02"}], "timestamp":"1770241479949", "event_type":"price_change"}
{"market":"0x38f3050258345e9cf363d1c8cc302f08c65b96ba1a4669d81e07ed69708344df", "price_changes":[{"asset_id":"96888240988495161476033313796107536512663280794332045579302109906525918376981", "price":"0.95", "size":"680", "side":"BUY", "hash":"4c6d68c2ea6eec8afa4074d11124d3ceb2647d77", "best_bid":"0.98", "best_ask":"0.99"}, {"asset_id":"81916206347121459497221114766050949090435061493822476265356047392175668050706", "price":"0.05", "size":"680", "side":"SELL", "hash":"c0054330c7bab4f027c3222ab6b699cbd41df6f4", "best_bid":"0.01", "best_ask":"0.02"}], "timestamp":"1770241479951", "event_type":"price_change"}
{"market":"0x38f3050258345e9cf363d1c8cc302f08c65b96ba1a4669d81e07ed69708344df", "price_changes":[{"asset_id":"81916206347121459497221114766050949090435061493822476265356047392175668050706", "price":"0.01", "size":"3848.89", "side":"BUY", "hash":"0858bb05c658964622a2098b6b42d66e96f9436c", "best_bid":"0.01", "best_ask":"0.02"}, {"asset_id":"96888240988495161476033313796107536512663280794332045579302109906525918376981", "price":"0.99", "size":"3848.89", "side":"SELL", "hash":"3e92d652aa2b2f8c0336b1ad814bed820c81d87f", "best_bid":"0.98", "best_ask":"0.99"}], "timestamp":"1770241479959", "event_type":"price_change"}
{"market":"0x38f3050258345e9cf363d1c8cc302f08c65b96ba1a4669d81e07ed69708344df", "price_changes":[{"asset_id":"96888240988495161476033313796107536512663280794332045579302109906525918376981", "price":"0.95", "size":"707", "side":"BUY", "hash":"16fbdf3d27aa9b30030e8f7acecf2b3f4d93fe24", "best_bid":"0.98", "best_ask":"0.99"}, {"asset_id":"81916206347121459497221114766050949090435061493822476265356047392175668050706", "price":"0.05", "size":"707", "side":"SELL", "hash":"99338b6de0c27987ef26d3596341dd4b1db4b9c0", "best_bid":"0.01", "best_ask":"0.02"}], "timestamp":"1770241479959", "event_type":"price_change"}
{"market":"0x38f3050258345e9cf363d1c8cc302f08c65b96ba1a4669d81e07ed69708344df", "price_changes":[{"asset_id":"81916206347121459497221114766050949090435061493822476265356047392175668050706", "price":"0.01", "size":"3875.89", "side":"BUY", "hash":"d81cfdbcb39cd05f8c34bd5654cf2c6c808b3224", "best_bid":"0.01", "best_ask":"0.02"}, {"asset_id":"96888240988495161476033313796107536512663280794332045579302109906525918376981", "price":"0.99", "size":"3875.89", "side":"SELL", "hash":"68971e65879389cc55f6e0fe39bf40853eb1afa1", "best_bid":"0.98", "best_ask":"0.99"}], "timestamp":"1770241479962", "event_type":"price_change"}
{"market":"0x38f3050258345e9cf363d1c8cc302f08c65b96ba1a4669d81e07ed69708344df", "price_changes":[{"asset_id":"96888240988495161476033313796107536512663280794332045579302109906525918376981", "price":"0.95", "size":"680", "side":"BUY", "hash":"4a94478f38d107a383c954343b4c25e0e20327d5", "best_bid":"0.98", "best_ask":"0.99"}, {"asset_id":"81916206347121459497221114766050949090435061493822476265356047392175668050706", "price":"0.05", "size":"680", "side":"SELL", "hash":"e68ebd671854b396c32f338bb739e5016d117fc8", "best_bid":"0.01", "best_ask":"0.02"}], "timestamp":"1770241479962", "event_type":"price_change"}
{"market":"0x38f3050258345e9cf363d1c8cc302f08c65b96ba1a4669d81e07ed69708344df", "price_changes":[{"asset_id":"96888240988495161476033313796107536512663280794332045579302109906525918376981", "price":"0.96", "size":"677.73", "side":"BUY", "hash":"56f7fbb998abe7bbd8fea4043849a764a24ff53c", "best_bid":"0.98", "best_ask":"0.99"}, {"asset_id":"81916206347121459497221114766050949090435061493822476265356047392175668050706", "price":"0.04", "size":"677.73", "side":"SELL", "hash":"b5d2b8359ea054d76e87418003dbe5e95a56fa25", "best_bid":"0.01", "best_ask":"0.02"}], "timestamp":"1770241479972", "event_type":"price_change"}
{"market":"0x38f3050258345e9cf363d1c8cc302f08c65b96ba1a4669d81e07ed69708344df", "price_changes":[{"asset_id":"81916206347121459497221114766050949090435061493822476265356047392175668050706", "price":"0.01", "size":"3848.89", "side":"BUY", "hash":"56ac88b366427c355c60834fa8abc0cd8808825a", "best_bid":"0.01", "best_ask":"0.02"}, {"asset_id":"96888240988495161476033313796107536512663280794332045579302109906525918376981", "price":"0.99", "size":"3848.89", "side":"SELL", "hash":"cf1b046de7528beb42270e437d89b92cd7c7c69e", "best_bid":"0.98", "best_ask":"0.99"}], "timestamp":"1770241479973", "event_type":"price_change"}
{"market":"0x38f3050258345e9cf363d1c8cc302f08c65b96ba1a4669d81e07ed69708344df", "price_changes":[{"asset_id":"96888240988495161476033313796107536512663280794332045579302109906525918376981", "price":"0.96", "size":"650.73", "side":"BUY", "hash":"1023a015694b8606f750fe001b5dca169a046ec8", "best_bid":"0.98", "best_ask":"0.99"}, {"asset_id":"81916206347121459497221114766050949090435061493822476265356047392175668050706", "price":"0.04", "size":"650.73", "side":"SELL", "hash":"cf22d38fdd3a5b13dccbd1413e893f492c441440", "best_bid":"0.01", "best_ask":"0.02"}], "timestamp":"1770241479979", "event_type":"price_change"}
{"market":"0x38f3050258345e9cf363d1c8cc302f08c65b96ba1a4669d81e07ed69708344df", "price_changes":[{"asset_id":"81916206347121459497221114766050949090435061493822476265356047392175668050706", "price":"0.01", "size":"3875.89", "side":"BUY", "hash":"be80e932ac3459b5e04ba7ed4af1322876d5cebf", "best_bid":"0.01", "best_ask":"0.02"}, {"asset_id":"96888240988495161476033313796107536512663280794332045579302109906525918376981", "price":"0.99", "size":"3875.89", "side":"SELL", "hash":"ced4546448889058c5e9877612ed2650a4df8d99", "best_bid":"0.98", "best_ask":"0.99"}], "timestamp":"1770241479982", "event_type":"price_change"}
{"market":"0x38f3050258345e9cf363d1c8cc302f08c65b96ba1a4669d81e07ed69708344df", "price_changes":[{"asset_id":"96888240988495161476033313796107536512663280794332045579302109906525918376981", "price":"0.99", "size":"3866.89", "side":"SELL", "hash":"f5ede419488b838ad15ab805d8dbfbb530324dc0", "best_bid":"0.98", "best_ask":"0.99"}, {"asset_id":"81916206347121459497221114766050949090435061493822476265356047392175668050706", "price":"0.01", "size":"3866.89", "side":"BUY", "hash":"f9de6ad266a8fb453ace04a24015df0292c6af06", "best_bid":"0.01", "best_ask":"0.02"}], "timestamp":"1770241480043", "event_type":"price_change"}
{"market":"0x38f3050258345e9cf363d1c8cc302f08c65b96ba1a4669d81e07ed69708344df", "price_changes":[{"asset_id":"96888240988495161476033313796107536512663280794332045579302109906525918376981", "price":"0.99", "size":"3875.89", "side":"SELL", "hash":"acf2bd78fe2659805c0967802e3c0a31def69b19", "best_bid":"0.98", "best_ask":"0.99"}, {"asset_id":"81916206347121459497221114766050949090435061493822476265356047392175668050706", "price":"0.01", "size":"3875.89", "side":"BUY", "hash":"cf043019eaa10de00ef964576aa6f9dc21258ddb", "best_bid":"0.01", "best_ask":"0.02"}], "timestamp":"1770241480313", "event_type":"price_change"}
{"market":"0x38f3050258345e9cf363d1c8cc302f08c65b96ba1a4669d81e07ed69708344df", "price_changes":[{"asset_id":"96888240988495161476033313796107536512663280794332045579302109906525918376981", "price":"0.97", "size":"645.32", "side":"BUY", "hash":"5d4bfc065c2bda150ab7d2f611aeda72aae039cd", "best_bid":"0.98", "best_ask":"0.99"}, {"asset_id":"81916206347121459497221114766050949090435061493822476265356047392175668050706", "price":"0.03", "size":"645.32", "side":"SELL", "hash":"47f09542b6f870a22ecef589e1b83f68b15fa40b", "best_bid":"0.01", "best_ask":"0.02"}], "timestamp":"1770241480384", "event_type":"price_change"}
{"market":"0x38f3050258345e9cf363d1c8cc302f08c65b96ba1a4669d81e07ed69708344df", "price_changes":[{"asset_id":"96888240988495161476033313796107536512663280794332045579302109906525918376981", "price":"0.99", "size":"3866.89", "side":"SELL", "hash":"6a58593d54d76b9a367b3b74d068ec7e9c03708d", "best_bid":"0.98", "best_ask":"0.99"}, {"asset_id":"81916206347121459497221114766050949090435061493822476265356047392175668050706", "price":"0.01", "size":"3866.89", "side":"BUY", "hash":"df7d8b83b8fb97ef92b16e2240143ab0cc9478d4", "best_bid":"0.01", "best_ask":"0.02"}], "timestamp":"1770241480498", "event_type":"price_change"}
{"market":"0x38f3050258345e9cf363d1c8cc302f08c65b96ba1a4669d81e07ed69708344df", "price_changes":[{"asset_id":"81916206347121459497221114766050949090435061493822476265356047392175668050706", "price":"0.01", "size":"3893.89", "side":"BUY", "hash":"3966d5ddc495a0c78a7088ad29a671f590df680c", "best_bid":"0.01", "best_ask":"0.02"}, {"asset_id":"96888240988495161476033313796107536512663280794332045579302109906525918376981", "price":"0.99", "size":"3893.89", "side":"SELL", "hash":"803a0817477e503c1a07ce1d0422d4003247486d", "best_bid":"0.98", "best_ask":"0.99"}], "timestamp":"1770241480655", "event_type":"price_change"}
{"market":"0x38f3050258345e9cf363d1c8cc302f08c65b96ba1a4669d81e07ed69708344df", "price_changes":[{"asset_id":"81916206347121459497221114766050949090435061493822476265356047392175668050706", "price":"0.01", "size":"3866.89", "side":"BUY", "hash":"2b3caab49530df1b3a0c9905f2c20161a88b4cd9", "best_bid":"0.01", "best_ask":"0.02"}, {"asset_id":"96888240988495161476033313796107536512663280794332045579302109906525918376981", "price":"0.99", "size":"3866.89", "side":"SELL", "hash":"0228caf4c85c36ca0db4a24584565a02e675ae2c", "best_bid":"0.98", "best_ask":"0.99"}], "timestamp":"1770241480655", "event_type":"price_change"}
{"market":"0x38f3050258345e9cf363d1c8cc302f08c65b96ba1a4669d81e07ed69708344df", "price_changes":[{"asset_id":"96888240988495161476033313796107536512663280794332045579302109906525918376981", "price":"0.95", "size":"707", "side":"BUY", "hash":"153fff760940e313fa4d7765608b42d51fd06fbe", "best_bid":"0.98", "best_ask":"0.99"}, {"asset_id":"81916206347121459497221114766050949090435061493822476265356047392175668050706", "price":"0.05", "size":"707", "side":"SELL", "hash":"5f9b7acbd2e15bf849fafebce82beec28787a759", "best_bid":"0.01", "best_ask":"0.02"}], "timestamp":"1770241480656", "event_type":"price_change"}
{"market":"0x38f3050258345e9cf363d1c8cc302f08c65b96ba1a4669d81e07ed69708344df", "price_changes":[{"asset_id":"96888240988495161476033313796107536512663280794332045579302109906525918376981", "price":"0.95", "size":"680", "side":"BUY", "hash":"6c2a8979ba1320d018ba1e4f79321f7bac2c2a42", "best_bid":"0.98", "best_ask":"0.99"}, {"asset_id":"81916206347121459497221114766050949090435061493822476265356047392175668050706", "price":"0.05", "size":"680", "side":"SELL", "hash":"106ac675c755875ee58501824216979dfc98fab4", "best_bid":"0.01", "best_ask":"0.02"}], "timestamp":"1770241480658", "event_type":"price_change"}
{"market":"0x38f3050258345e9cf363d1c8cc302f08c65b96ba1a4669d81e07ed69708344df", "price_changes":[{"asset_id":"81916206347121459497221114766050949090435061493822476265356047392175668050706", "price":"0.01", "size":"3893.89", "side":"BUY", "hash":"ae4c7c4a696d1eafff8c171755ab92e4dbcd4b92", "best_bid":"0.01", "best_ask":"0.02"}, {"asset_id":"96888240988495161476033313796107536512663280794332045579302109906525918376981", "price":"0.99", "size":"3893.89", "side":"SELL", "hash":"172e743f32ffd952d65fcb188368a92fd2478b3d", "best_bid":"0.98", "best_ask":"0.99"}], "timestamp":"1770241480666", "event_type":"price_change"}
{"market":"0x38f3050258345e9cf363d1c8cc302f08c65b96ba1a4669d81e07ed69708344df", "price_changes":[{"asset_id":"96888240988495161476033313796107536512663280794332045579302109906525918376981", "price":"0.95", "size":"707", "side":"BUY", "hash":"80760a7924f9d03ea281a012f5b8d9024887a7fc", "best_bid":"0.98", "best_ask":"0.99"}, {"asset_id":"81916206347121459497221114766050949090435061493822476265356047392175668050706", "price":"0.05", "size":"707", "side":"SELL", "hash":"3054617fb74f47228f76742a422d1ff0f9956445", "best_bid":"0.01", "best_ask":"0.02"}], "timestamp":"1770241480667", "event_type":"price_change"}
{"market":"0x38f3050258345e9cf363d1c8cc302f08c65b96ba1a4669d81e07ed69708344df", "price_changes":[{"asset_id":"96888240988495161476033313796107536512663280794332045579302109906525918376981", "price":"0.95", "size":"680", "side":"BUY", "hash":"b127b1fe878db88692252051dfe5d288f8d1dd07", "best_bid":"0.98", "best_ask":"0.99"}, {"asset_id":"81916206347121459497221114766050949090435061493822476265356047392175668050706", "price":"0.05", "size":"680", "side":"SELL", "hash":"14f037421a82803009d714ca1894948bff799a96", "best_bid":"0.01", "best_ask":"0.02"}], "timestamp":"1770241480667", "event_type":"price_change"}
{"market":"0x38f3050258345e9cf363d1c8cc302f08c65b96ba1a4669d81e07ed69708344df", "price_changes":[{"asset_id":"81916206347121459497221114766050949090435061493822476265356047392175668050706", "price":"0.01", "size":"3866.89", "side":"BUY", "hash":"c08d57690143d881a6bd1069f3442e7b60219211", "best_bid":"0.01", "best_ask":"0.02"}, {"asset_id":"96888240988495161476033313796107536512663280794332045579302109906525918376981", "price":"0.99", "size":"3866.89", "side":"SELL", "hash":"af2f8fa03add2f179f505c921f6b4374cfc94c18", "best_bid":"0.98", "best_ask":"0.99"}], "timestamp":"1770241480668", "event_type":"price_change"}
{"market":"0x38f3050258345e9cf363d1c8cc302f08c65b96ba1a4669d81e07ed69708344df", "price_changes":[{"asset_id":"96888240988495161476033313796107536512663280794332045579302109906525918376981", "price":"0.96", "size":"623.73", "side":"BUY", "hash":"dfd6186a46651fd75d1cae1debd75a83d3ddce09", "best_bid":"0.98", "best_ask":"0.99"}, {"asset_id":"81916206347121459497221114766050949090435061493822476265356047392175668050706", "price":"0.04", "size":"623.73", "side":"SELL", "hash":"d3fed160bb5d2f4565477c7ee1fd9073326c91aa", "best_bid":"0.01", "best_ask":"0.02"}], "timestamp":"1770241480674", "event_type":"price_change"}
{"market":"0x38f3050258345e9cf363d1c8cc302f08c65b96ba1a4669d81e07ed69708344df", "price_changes":[{"asset_id":"81916206347121459497221114766050949090435061493822476265356047392175668050706", "price":"0.01", "size":"3893.89", "side":"BUY", "hash":"9bc7f93e73df5fdff3b2b98b0159a9b84e7c613c", "best_bid":"0.01", "best_ask":"0.02"}, {"asset_id":"96888240988495161476033313796107536512663280794332045579302109906525918376981", "price":"0.99", "size":"3893.89", "side":"SELL", "hash":"e6571d237c6f212df3518948c49219e6128ad84d", "best_bid":"0.98", "best_ask":"0.99"}], "timestamp":"1770241480675", "event_type":"price_change"}
{"market":"0x38f3050258345e9cf363d1c8cc302f08c65b96ba1a4669d81e07ed69708344df", "price_changes":[{"asset_id":"81916206347121459497221114766050949090435061493822476265356047392175668050706", "price":"0.01", "size":"3866.89", "side":"BUY", "hash":"ffdcc808c87f5876b22848c5eac09feda38b6f36", "best_bid":"0.01", "best_ask":"0.02"}, {"asset_id":"96888240988495161476033313796107536512663280794332045579302109906525918376981", "price":"0.99", "size":"3866.89", "side":"SELL", "hash":"66d9355ef2de12a553fee36985ab475746013ad3", "best_bid":"0.98", "best_ask":"0.99"}], "timestamp":"1770241480679", "event_type":"price_change"}
{"market":"0x38f3050258345e9cf363d1c8cc302f08c65b96ba1a4669d81e07ed69708344df", "price_changes":[{"asset_id":"96888240988495161476033313796107536512663280794332045579302109906525918376981", "price":"0.96", "size":"650.73", "side":"BUY", "hash":"109665fc9c5f0e6a2b8ff8e886b98f9e4c8ef172", "best_bid":"0.98", "best_ask":"0.99"}, {"asset_id":"81916206347121459497221114766050949090435061493822476265356047392175668050706", "price":"0.04", "size":"650.73", "side":"SELL", "hash":"193fd70df368e2e2a62d2684f5bdb675f447dce1", "best_bid":"0.01", "best_ask":"0.02"}], "timestamp":"1770241480680", "event_type":"price_change"}
{"market":"0x38f3050258345e9cf363d1c8cc302f08c65b96ba1a4669d81e07ed69708344df", "price_changes":[{"asset_id":"96888240988495161476033313796107536512663280794332045579302109906525918376981", "price":"0.96", "size":"673.73", "side":"BUY", "hash":"3abfab6741eefe57ae54055703bbd37239eb568b", "best_bid":"0.98", "best_ask":"0.99"}, {"asset_id":"81916206347121459497221114766050949090435061493822476265356047392175668050706", "price":"0.04", "size":"673.73", "side":"SELL", "hash":"790f569783ec1a4deb4f4ffd0678fd1883cc9707", "best_bid":"0.01", "best_ask":"0.02"}], "timestamp":"1770241481090", "event_type":"price_change"}
{"market":"0x38f3050258345e9cf363d1c8cc302f08c65b96ba1a4669d81e07ed69708344df", "price_changes":[{"asset_id":"96888240988495161476033313796107536512663280794332045579302109906525918376981", "price":"0.97", "size":"622.32", "side":"BUY", "hash":"3a1684bf19cf7dc507a61c10e5a03dd684d1b011", "best_bid":"0.98", "best_ask":"0.99"}, {"asset_id":"81916206347121459497221114766050949090435061493822476265356047392175668050706", "price":"0.03", "size":"622.32", "side":"SELL", "hash":"8f93fa955b3177b5fe088c1dbc9f639891efa1d2", "best_bid":"0.01", "best_ask":"0.02"}], "timestamp":"1770241481091", "event_type":"price_change"}
{"market":"0x38f3050258345e9cf363d1c8cc302f08c65b96ba1a4669d81e07ed69708344df", "price_changes":[{"asset_id":"96888240988495161476033313796107536512663280794332045579302109906525918376981", "price":"0.96", "size":"646.73", "side":"BUY", "hash":"8ca0b2f3b0725c5d4cc6dcc8947cc22aa0b086ef", "best_bid":"0.98", "best_ask":"0.99"}, {"asset_id":"81916206347121459497221114766050949090435061493822476265356047392175668050706", "price":"0.04", "size":"646.73", "side":"SELL", "hash":"3f21b8e0faae32dbc4f1c88b888b3ca634520fee", "best_bid":"0.01", "best_ask":"0.02"}], "timestamp":"1770241481122", "event_type":"price_change"}
{"market":"0x38f3050258345e9cf363d1c8cc302f08c65b96ba1a4669d81e07ed69708344df", "price_changes":[{"asset_id":"81916206347121459497221114766050949090435061493822476265356047392175668050706", "price":"0.01", "size":"3839.89", "side":"BUY", "hash":"5e3ef912dd3a00960c0c81e76d24d92958ecbc21", "best_bid":"0.01", "best_ask":"0.02"}, {"asset_id":"96888240988495161476033313796107536512663280794332045579302109906525918376981", "price":"0.99", "size":"3839.89", "side":"SELL", "hash":"47338e538b3db8ad86497d8e1d83cad6d2e37adc", "best_bid":"0.98", "best_ask":"0.99"}], "timestamp":"1770241481123", "event_type":"price_change"}
{"market":"0x38f3050258345e9cf363d1c8cc302f08c65b96ba1a4669d81e07ed69708344df", "price_changes":[{"asset_id":"96888240988495161476033313796107536512663280794332045579302109906525918376981", "price":"0.96", "size":"673.73", "side":"BUY", "hash":"e426f2ba160eee43a0d6f41bbaafa6190417c01a", "best_bid":"0.98", "best_ask":"0.99"}, {"asset_id":"81916206347121459497221114766050949090435061493822476265356047392175668050706", "price":"0.04", "size":"673.73", "side":"SELL", "hash":"83b13242f37b8e7fd036765aa42f83f9b9ebd57c", "best_bid":"0.01", "best_ask":"0.02"}], "timestamp":"1770241481125", "event_type":"price_change"}
{"market":"0x38f3050258345e9cf363d1c8cc302f08c65b96ba1a4669d81e07ed69708344df", "price_changes":[{"asset_id":"81916206347121459497221114766050949090435061493822476265356047392175668050706", "price":"0.01", "size":"3812.89", "side":"BUY", "hash":"04eab74d3f9a3e8a311c757a105e8222ed6f0803", "best_bid":"0.01", "best_ask":"0.02"}, {"asset_id":"96888240988495161476033313796107536512663280794332045579302109906525918376981", "price":"0.99", "size":"3812.89", "side":"SELL", "hash":"2448de915d69ade9f1cea5c8c32d5b11c4307be4", "best_bid":"0.98", "best_ask":"0.99"}], "timestamp":"1770241481125", "event_type":"price_change"}
{"market":"0x38f3050258345e9cf363d1c8cc302f08c65b96ba1a4669d81e07ed69708344df", "price_changes":[{"asset_id":"81916206347121459497221114766050949090435061493822476265356047392175668050706", "price":"0.01", "size":"3839.89", "side":"BUY", "hash":"4ed5a00f69605b6f36fd2e7de98f9d1b02570a59", "best_bid":"0.01", "best_ask":"0.02"}, {"asset_id":"96888240988495161476033313796107536512663280794332045579302109906525918376981", "price":"0.99", "size":"3839.89", "side":"SELL", "hash":"b2da92ba9547a4f9fcba7780f48a0c3e5ca1516a", "best_bid":"0.98", "best_ask":"0.99"}], "timestamp":"1770241481126", "event_type":"price_change"}
{"market":"0x38f3050258345e9cf363d1c8cc302f08c65b96ba1a4669d81e07ed69708344df", "price_changes":[{"asset_id":"96888240988495161476033313796107536512663280794332045579302109906525918376981", "price":"0.95", "size":"707", "side":"BUY", "hash":"ff57d26a39cbac06309562b7b1ae8085cf873c6d", "best_bid":"0.98", "best_ask":"0.99"}, {"asset_id":"81916206347121459497221114766050949090435061493822476265356047392175668050706", "price":"0.05", "size":"707", "side":"SELL", "hash":"694de53aeaea1bc44b3f5a291338b50a48197374", "best_bid":"0.01", "best_ask":"0.02"}], "timestamp":"1770241481127", "event_type":"price_change"}
{"market":"0x38f3050258345e9cf363d1c8cc302f08c65b96ba1a4669d81e07ed69708344df", "price_changes":[{"asset_id":"96888240988495161476033313796107536512663280794332045579302109906525918376981", "price":"0.95", "size":"680", "side":"BUY", "hash":"87b61b4ffafd481bd8ce30ab03899f44c8f92767", "best_bid":"0.98", "best_ask":"0.99"}, {"asset_id":"81916206347121459497221114766050949090435061493822476265356047392175668050706", "price":"0.05", "size":"680", "side":"SELL", "hash":"9ceef7d651294ad35e39819597163dd4f5b358ca", "best_bid":"0.01", "best_ask":"0.02"}], "timestamp":"1770241481127", "event_type":"price_change"}
{"market":"0x38f3050258345e9cf363d1c8cc302f08c65b96ba1a4669d81e07ed69708344df", "price_changes":[{"asset_id":"81916206347121459497221114766050949090435061493822476265356047392175668050706", "price":"0.01", "size":"3866.89", "side":"BUY", "hash":"a499727cb7e0f80003601c550a2ef6387fee1d8c", "best_bid":"0.01", "best_ask":"0.02"}, {"asset_id":"96888240988495161476033313796107536512663280794332045579302109906525918376981", "price":"0.99", "size":"3866.89", "side":"SELL", "hash":"45688b73673bd8f19682a647bd4c41388198ef85", "best_bid":"0.98", "best_ask":"0.99"}], "timestamp":"1770241481128", "event_type":"price_change"}
{"market":"0x38f3050258345e9cf363d1c8cc302f08c65b96ba1a4669d81e07ed69708344df", "price_changes":[{"asset_id":"81916206347121459497221114766050949090435061493822476265356047392175668050706", "price":"0.01", "size":"3893.89", "side":"BUY", "hash":"53edb390edf94425aa5a25818ef78755fae568f2", "best_bid":"0.01", "best_ask":"0.02"}, {"asset_id":"96888240988495161476033313796107536512663280794332045579302109906525918376981", "price":"0.99", "size":"3893.89", "side":"SELL", "hash":"ac12e5a4284b3e8cbb7f463441eefdff6d18f70b", "best_bid":"0.98", "best_ask":"0.99"}], "timestamp":"1770241481129", "event_type":"price_change"}
{"market":"0x38f3050258345e9cf363d1c8cc302f08c65b96ba1a4669d81e07ed69708344df", "price_changes":[{"asset_id":"96888240988495161476033313796107536512663280794332045579302109906525918376981", "price":"0.95", "size":"653", "side":"BUY", "hash":"166292f6de85377bbb10428f04efb6681236eb7d", "best_bid":"0.98", "best_ask":"0.99"}, {"asset_id":"81916206347121459497221114766050949090435061493822476265356047392175668050706", "price":"0.05", "size":"653", "side":"SELL", "hash":"3a638dd1f2969d6470e8f381e35efab892b85961", "best_bid":"0.01", "best_ask":"0.02"}], "timestamp":"1770241481129", "event_type":"price_change"}
{"market":"0x38f3050258345e9cf363d1c8cc302f08c65b96ba1a4669d81e07ed69708344df", "price_changes":[{"asset_id":"81916206347121459497221114766050949090435061493822476265356047392175668050706", "price":"0.01", "size":"3866.89", "side":"BUY", "hash":"78be65004ae0a6b02576b92ccbbc4f0c647f8826", "best_bid":"0.01", "best_ask":"0.02"}, {"asset_id":"96888240988495161476033313796107536512663280794332045579302109906525918376981", "price":"0.99", "size":"3866.89", "side":"SELL", "hash":"102fabefa30d38f3c32be862fd4014aaddf68308", "best_bid":"0.98", "best_ask":"0.99"}], "timestamp":"1770241481132", "event_type":"price_change"}
{"market":"0x38f3050258345e9cf363d1c8cc302f08c65b96ba1a4669d81e07ed69708344df", "price_changes":[{"asset_id":"96888240988495161476033313796107536512663280794332045579302109906525918376981", "price":"0.95", "size":"680", "side":"BUY", "hash":"e2bce83fd227086d68dc9ca7d8d3018557d5b1c3", "best_bid":"0.98", "best_ask":"0.99"}, {"asset_id":"81916206347121459497221114766050949090435061493822476265356047392175668050706", "price":"0.05", "size":"680", "side":"SELL", "hash":"6c6a6b19e17c8b6592dbb7e09e494d36c5cd6ad7", "best_bid":"0.01", "best_ask":"0.02"}], "timestamp":"1770241481133", "event_type":"price_change"}
{"market":"0x38f3050258345e9cf363d1c8cc302f08c65b96ba1a4669d81e07ed69708344df", "price_changes":[{"asset_id":"96888240988495161476033313796107536512663280794332045579302109906525918376981", "price":"0.95", "size":"707", "side":"BUY", "hash":"8e8189924b9a85da7a1f8670500674afcdcb2cfd", "best_bid":"0.98", "best_ask":"0.99"}, {"asset_id":"81916206347121459497221114766050949090435061493822476265356047392175668050706", "price":"0.05", "size":"707", "side":"SELL", "hash":"49cf6fba39e33de5d1bfa4c095da38e32975fe5d", "best_bid":"0.01", "best_ask":"0.02"}], "timestamp":"1770241481853", "event_type":"price_change"}
{"market":"0x38f3050258345e9cf363d1c8cc302f08c65b96ba1a4669d81e07ed69708344df", "price_changes":[{"asset_id":"96888240988495161476033313796107536512663280794332045579302109906525918376981", "price":"0.96", "size":"646.73", "side":"BUY", "hash":"6f0fba119564f834d9a1692eae943d5c7be97b76", "best_bid":"0.98", "best_ask":"0.99"}, {"asset_id":"81916206347121459497221114766050949090435061493822476265356047392175668050706", "price":"0.04", "size":"646.73", "side":"SELL", "hash":"730eb232adc2dc97723fdc1679b7bf1f153022c2", "best_bid":"0.01", "best_ask":"0.02"}], "timestamp":"1770241481857", "event_type":"price_change"}
{"market":"0x38f3050258345e9cf363d1c8cc302f08c65b96ba1a4669d81e07ed69708344df", "price_changes":[{"asset_id":"96888240988495161476033313796107536512663280794332045579302109906525918376981", "price":"0.96", "size":"673.73", "side":"BUY", "hash":"28a83f1db7f0fb885b8c6a0e2eac3760d7d144ef", "best_bid":"0.98", "best_ask":"0.99"}, {"asset_id":"81916206347121459497221114766050949090435061493822476265356047392175668050706", "price":"0.04", "size":"673.73", "side":"SELL", "hash":"0779bd5ef52fbcbb76bbbcf90a8495683735b622", "best_bid":"0.01", "best_ask":"0.02"}], "timestamp":"1770241482000", "event_type":"price_change"}
{"market":"0x38f3050258345e9cf363d1c8cc302f08c65b96ba1a4669d81e07ed69708344df", "price_changes":[{"asset_id":"96888240988495161476033313796107536512663280794332045579302109906525918376981", "price":"0.95", "size":"680", "side":"BUY", "hash":"4d5105382fc2f63d5234d19491f682e3a26622fc", "best_bid":"0.98", "best_ask":"0.99"}, {"asset_id":"81916206347121459497221114766050949090435061493822476265356047392175668050706", "price":"0.05", "size":"680", "side":"SELL", "hash":"c5c356ead34b489fad9aea67f728776bcc876922", "best_bid":"0.01", "best_ask":"0.02"}], "timestamp":"1770241482002", "event_type":"price_change"}
{"market":"0x38f3050258345e9cf363d1c8cc302f08c65b96ba1a4669d81e07ed69708344df", "price_changes":[{"asset_id":"96888240988495161476033313796107536512663280794332045579302109906525918376981", "price":"0.97", "size":"645.32", "side":"BUY", "hash":"f736c50ef13af8951f69685ea34947f40f90dd6d", "best_bid":"0.98", "best_ask":"0.99"}, {"asset_id":"81916206347121459497221114766050949090435061493822476265356047392175668050706", "price":"0.03", "size":"645.32", "side":"SELL", "hash":"4dcc723f522461828fd851280776ac3d92058a91", "best_bid":"0.01", "best_ask":"0.02"}], "timestamp":"1770241482090", "event_type":"price_change"}
{"market":"0x38f3050258345e9cf363d1c8cc302f08c65b96ba1a4669d81e07ed69708344df", "price_changes":[{"asset_id":"96888240988495161476033313796107536512663280794332045579302109906525918376981", "price":"0.96", "size":"650.73", "side":"BUY", "hash":"0d62cf74c2b9ea107fd9e5f9d7a573636127be69", "best_bid":"0.98", "best_ask":"0.99"}, {"asset_id":"81916206347121459497221114766050949090435061493822476265356047392175668050706", "price":"0.04", "size":"650.73", "side":"SELL", "hash":"3ec479aed2c990946cad527e1f4fc192d61fb7d5", "best_bid":"0.01", "best_ask":"0.02"}], "timestamp":"1770241482094", "event_type":"price_change"}
{"market":"0x38f3050258345e9cf363d1c8cc302f08c65b96ba1a4669d81e07ed69708344df", "price_changes":[{"asset_id":"96888240988495161476033313796107536512663280794332045579302109906525918376981", "price":"0.96", "size":"623.73", "side":"BUY", "hash":"bf34c0bd733091038246fd2966e99c2b8d82a238", "best_bid":"0.98", "best_ask":"0.99"}, {"asset_id":"81916206347121459497221114766050949090435061493822476265356047392175668050706", "price":"0.04", "size":"623.73", "side":"SELL", "hash":"52d04c90a94356992b9c3ef7a6810c296af5ea41", "best_bid":"0.01", "best_ask":"0.02"}], "timestamp":"1770241482195", "event_type":"price_change"}
{"market":"0x38f3050258345e9cf363d1c8cc302f08c65b96ba1a4669d81e07ed69708344df", "price_changes":[{"asset_id":"96888240988495161476033313796107536512663280794332045579302109906525918376981", "price":"0.96", "size":"650.73", "side":"BUY", "hash":"9c84dc3d805159a59503906bb36e7b56c28cf0f3", "best_bid":"0.98", "best_ask":"0.99"}, {"asset_id":"81916206347121459497221114766050949090435061493822476265356047392175668050706", "price":"0.04", "size":"650.73", "side":"SELL", "hash":"1daa312278e8d688d914f3c0cba9e433e5e833e4", "best_bid":"0.01", "best_ask":"0.02"}], "timestamp":"1770241482197", "event_type":"price_change"}
{"market":"0x38f3050258345e9cf363d1c8cc302f08c65b96ba1a4669d81e07ed69708344df", "price_changes":[{"asset_id":"96888240988495161476033313796107536512663280794332045579302109906525918376981", "price":"0.96", "size":"677.73", "side":"BUY", "hash":"8a05cb7e093b3e4292526a5a627a85d5ed43da17", "best_bid":"0.98", "best_ask":"0.99"}, {"asset_id":"81916206347121459497221114766050949090435061493822476265356047392175668050706", "price":"0.04", "size":"677.73", "side":"SELL", "hash":"51123f1f152b62cb7259fddf6fafd9ede5ee12c0", "best_bid":"0.01", "best_ask":"0.02"}], "timestamp":"1770241482329", "event_type":"price_change"}
{"market":"0x38f3050258345e9cf363d1c8cc302f08c65b96ba1a4669d81e07ed69708344df", "price_changes":[{"asset_id":"96888240988495161476033313796107536512663280794332045579302109906525918376981", "price":"0.96", "size":"650.73", "side":"BUY", "hash":"18b54b6f8aedd8666d5ae883f8e70c66371bbaf7", "best_bid":"0.98", "best_ask":"0.99"}, {"asset_id":"81916206347121459497221114766050949090435061493822476265356047392175668050706", "price":"0.04", "size":"650.73", "side":"SELL", "hash":"6a61ea576c3520d70c0e0341f6578b7cc390f1c3", "best_bid":"0.01", "best_ask":"0.02"}], "timestamp":"1770241482330", "event_type":"price_change"}
{"market":"0x38f3050258345e9cf363d1c8cc302f08c65b96ba1a4669d81e07ed69708344df", "price_changes":[{"asset_id":"81916206347121459497221114766050949090435061493822476265356047392175668050706", "price":"0.01", "size":"3839.89", "side":"BUY", "hash":"fb66550f38200cac72c0f6e0f1cf1344d7e339cb", "best_bid":"0.01", "best_ask":"0.02"}, {"asset_id":"96888240988495161476033313796107536512663280794332045579302109906525918376981", "price":"0.99", "size":"3839.89", "side":"SELL", "hash":"28b62e6094e1d15a94443cc3ff339e36a75280d5", "best_bid":"0.98", "best_ask":"0.99"}], "timestamp":"1770241482468", "event_type":"price_change"}
{"market":"0x38f3050258345e9cf363d1c8cc302f08c65b96ba1a4669d81e07ed69708344df", "price_changes":[{"asset_id":"96888240988495161476033313796107536512663280794332045579302109906525918376981", "price":"0.96", "size":"677.73", "side":"BUY", "hash":"1cb30e810a77b62aedd95578950bf363dd6aee7b", "best_bid":"0.98", "best_ask":"0.99"}, {"asset_id":"81916206347121459497221114766050949090435061493822476265356047392175668050706", "price":"0.04", "size":"677.73", "side":"SELL", "hash":"d2c4234e57f8100f070faf182e4cd12d6b00879b", "best_bid":"0.01", "best_ask":"0.02"}], "timestamp":"1770241482471", "event_type":"price_change"}
{"market":"0x38f3050258345e9cf363d1c8cc302f08c65b96ba1a4669d81e07ed69708344df", "price_changes":[{"asset_id":"81916206347121459497221114766050949090435061493822476265356047392175668050706", "price":"0.01", "size":"3866.89", "side":"BUY", "hash":"3a11dd352a0490db605ed1bd7f7a6b758258e181", "best_bid":"0.01", "best_ask":"0.02"}, {"asset_id":"96888240988495161476033313796107536512663280794332045579302109906525918376981", "price":"0.99", "size":"3866.89", "side":"SELL", "hash":"bb24ebc48d90ce52b75a442ad3d17378f4c51c83", "best_bid":"0.98", "best_ask":"0.99"}], "timestamp":"1770241482472", "event_type":"price_change"}
{"market":"0x38f3050258345e9cf363d1c8cc302f08c65b96ba1a4669d81e07ed69708344df", "price_changes":[{"asset_id":"96888240988495161476033313796107536512663280794332045579302109906525918376981", "price":"0.95", "size":"653", "side":"BUY", "hash":"1aad63cafb161def090e34f850862788e371a795", "best_bid":"0.98", "best_ask":"0.99"}, {"asset_id":"81916206347121459497221114766050949090435061493822476265356047392175668050706", "price":"0.05", "size":"653", "side":"SELL", "hash":"ed3f1764d173d9767a924aad1f255170a8868b09", "best_bid":"0.01", "best_ask":"0.02"}], "timestamp":"1770241482472", "event_type":"price_change"}
{"market":"0x38f3050258345e9cf363d1c8cc302f08c65b96ba1a4669d81e07ed69708344df", "price_changes":[{"asset_id":"81916206347121459497221114766050949090435061493822476265356047392175668050706", "price":"0.01", "size":"3893.89", "side":"BUY", "hash":"1df39810e91015213a0bcc8457bba04b6e8ea94b", "best_bid":"0.01", "best_ask":"0.02"}, {"asset_id":"96888240988495161476033313796107536512663280794332045579302109906525918376981", "price":"0.99", "size":"3893.89", "side":"SELL", "hash":"2cd40dd711da5ff26be59c756bfbac66700b672d", "best_bid":"0.98", "best_ask":"0.99"}], "timestamp":"1770241482481", "event_type":"price_change"}
{"market":"0x38f3050258345e9cf363d1c8cc302f08c65b96ba1a4669d81e07ed69708344df", "price_changes":[{"asset_id":"96888240988495161476033313796107536512663280794332045579302109906525918376981", "price":"0.95", "size":"626", "side":"BUY", "hash":"2ff58d8658c0f0958039e11aeca01bf9a2b53dc3", "best_bid":"0.98", "best_ask":"0.99"}, {"asset_id":"81916206347121459497221114766050949090435061493822476265356047392175668050706", "price":"0.05", "size":"626", "side":"SELL", "hash":"d32b82aebbad0a4d3cb811e010e6c04d4000c7bb", "best_bid":"0.01", "best_ask":"0.02"}], "timestamp":"1770241482482", "event_type":"price_change"}
{"market":"0x38f3050258345e9cf363d1c8cc302f08c65b96ba1a4669d81e07ed69708344df", "price_changes":[{"asset_id":"96888240988495161476033313796107536512663280794332045579302109906525918376981", "price":"0.96", "size":"704.73", "side":"BUY", "hash":"4462d45f56d4852ab7e65b8b6e6ccf07533fa8b8", "best_bid":"0.98", "best_ask":"0.99"}, {"asset_id":"81916206347121459497221114766050949090435061493822476265356047392175668050706", "price":"0.04", "size":"704.73", "side":"SELL", "hash":"2c00e9c19e3fbbe4b78b88e34704c646ef86c37e", "best_bid":"0.01", "best_ask":"0.02"}], "timestamp":"1770241482483", "event_type":"price_change"}
{"market":"0x38f3050258345e9cf363d1c8cc302f08c65b96ba1a4669d81e07ed69708344df", "price_changes":[{"asset_id":"81916206347121459497221114766050949090435061493822476265356047392175668050706", "price":"0.01", "size":"3866.89", "side":"BUY", "hash":"1c1cecbf2f0eae599c2732f11ce3a04185c4a43e", "best_bid":"0.01", "best_ask":"0.02"}, {"asset_id":"96888240988495161476033313796107536512663280794332045579302109906525918376981", "price":"0.99", "size":"3866.89", "side":"SELL", "hash":"6386851daa159a1139bbc6ed122d563bdaa5f973", "best_bid":"0.98", "best_ask":"0.99"}], "timestamp":"1770241482485", "event_type":"price_change"}
{"market":"0x38f3050258345e9cf363d1c8cc302f08c65b96ba1a4669d81e07ed69708344df", "price_changes":[{"asset_id":"81916206347121459497221114766050949090435061493822476265356047392175668050706", "price":"0.01", "size":"3839.89", "side":"BUY", "hash":"991e3f597ceef3b5554a99b0784b79710feca5d0", "best_bid":"0.01", "best_ask":"0.02"}, {"asset_id":"96888240988495161476033313796107536512663280794332045579302109906525918376981", "price":"0.99", "size":"3839.89", "side":"SELL", "hash":"3476bdf41d83907a8e82b889a51a949b6cff575b", "best_bid":"0.98", "best_ask":"0.99"}], "timestamp":"1770241482490", "event_type":"price_change"}
{"market":"0x38f3050258345e9cf363d1c8cc302f08c65b96ba1a4669d81e07ed69708344df", "price_changes":[{"asset_id":"81916206347121459497221114766050949090435061493822476265356047392175668050706", "price":"0.01", "size":"3866.89", "side":"BUY", "hash":"034938815b9c4ff6d0713c002f5a378cad0d52b2", "best_bid":"0.01", "best_ask":"0.02"}, {"asset_id":"96888240988495161476033313796107536512663280794332045579302109906525918376981", "price":"0.99", "size":"3866.89", "side":"SELL", "hash":"7500a97822ff8c29928e1585f5b399619ad7cddb", "best_bid":"0.98", "best_ask":"0.99"}], "timestamp":"1770241482490", "event_type":"price_change"}
{"market":"0x38f3050258345e9cf363d1c8cc302f08c65b96ba1a4669d81e07ed69708344df", "price_changes":[{"asset_id":"96888240988495161476033313796107536512663280794332045579302109906525918376981", "price":"0.97", "size":"672.32", "side":"BUY", "hash":"5c8e4f03bc9ac622fb4fd1634249606d8d117b62", "best_bid":"0.98", "best_ask":"0.99"}, {"asset_id":"81916206347121459497221114766050949090435061493822476265356047392175668050706", "price":"0.03", "size":"672.32", "side":"SELL", "hash":"456341d0ee2790dc3614f092a63ee39032292d23", "best_bid":"0.01", "best_ask":"0.02"}], "timestamp":"1770241482492", "event_type":"price_change"}
{"market":"0x38f3050258345e9cf363d1c8cc302f08c65b96ba1a4669d81e07ed69708344df", "price_changes":[{"asset_id":"96888240988495161476033313796107536512663280794332045579302109906525918376981", "price":"0.96", "size":"677.73", "side":"BUY", "hash":"153fe394ebf1482b3a4763d4862e8fbea22a1e92", "best_bid":"0.98", "best_ask":"0.99"}, {"asset_id":"81916206347121459497221114766050949090435061493822476265356047392175668050706", "price":"0.04", "size":"677.73", "side":"SELL", "hash":"92da5b86db1513c757095e3e49c3db13a13651e4", "best_bid":"0.01", "best_ask":"0.02"}], "timestamp":"1770241482493", "event_type":"price_change"}
{"market":"0x38f3050258345e9cf363d1c8cc302f08c65b96ba1a4669d81e07ed69708344df", "price_changes":[{"asset_id":"81916206347121459497221114766050949090435061493822476265356047392175668050706", "price":"0.01", "size":"3839.89", "side":"BUY", "hash":"9770c8820bfdfc609e7876f6a17e9c17d198adf2", "best_bid":"0.01", "best_ask":"0.02"}, {"asset_id":"96888240988495161476033313796107536512663280794332045579302109906525918376981", "price":"0.99", "size":"3839.89", "side":"SELL", "hash":"ced673cf8b40db4edc7ee4e2d05e7a3ef76f04a1", "best_bid":"0.98", "best_ask":"0.99"}], "timestamp":"1770241482825", "event_type":"price_change"}
{"market":"0x38f3050258345e9cf363d1c8cc302f08c65b96ba1a4669d81e07ed69708344df", "price_changes":[{"asset_id":"96888240988495161476033313796107536512663280794332045579302109906525918376981", "price":"0.99", "size":"3799.89", "side":"SELL", "hash":"cd0d7781e24f1fd30ad899a849eaf87aad8dbd66", "best_bid":"0.98", "best_ask":"0.99"}, {"asset_id":"81916206347121459497221114766050949090435061493822476265356047392175668050706", "price":"0.01", "size":"3799.89", "side":"BUY", "hash":"f51767ad0e7c9f75bf2954ba7c15ee990d834512", "best_bid":"0.01", "best_ask":"0.02"}], "timestamp":"1770241482826", "event_type":"price_change"}
{"market":"0x38f3050258345e9cf363d1c8cc302f08c65b96ba1a4669d81e07ed69708344df", "price_changes":[{"asset_id":"96888240988495161476033313796107536512663280794332045579302109906525918376981", "price":"0.96", "size":"704.73", "side":"BUY", "hash":"7425032d8c11a2d2265cf7dd238e026b736801ad", "best_bid":"0.98", "best_ask":"0.99"}, {"asset_id":"81916206347121459497221114766050949090435061493822476265356047392175668050706", "price":"0.04", "size":"704.73", "side":"SELL", "hash":"d9423bb01000d79fe53d650b5df43dccd813fa0e", "best_bid":"0.01", "best_ask":"0.02"}], "timestamp":"1770241482827", "event_type":"price_change"}
{"market":"0x38f3050258345e9cf363d1c8cc302f08c65b96ba1a4669d81e07ed69708344df", "price_changes":[{"asset_id":"96888240988495161476033313796107536512663280794332045579302109906525918376981", "price":"0.96", "size":"677.73", "side":"BUY", "hash":"01d5a0620ba760c775c9c04a85a942b44be4cce0", "best_bid":"0.98", "best_ask":"0.99"}, {"asset_id":"81916206347121459497221114766050949090435061493822476265356047392175668050706", "price":"0.04", "size":"677.73", "side":"SELL", "hash":"4b1852bee728a9822840dbbead4c26b94967c3cc", "best_bid":"0.01", "best_ask":"0.02"}], "timestamp":"1770241482828", "event_type":"price_change"}
{"market":"0x38f3050258345e9cf363d1c8cc302f08c65b96ba1a4669d81e07ed69708344df", "price_changes":[{"asset_id":"81916206347121459497221114766050949090435061493822476265356047392175668050706", "price":"0.01", "size":"3772.89", "side":"BUY", "hash":"e3daac8eec268dbf8ffa160d551fc29b7ba677ed", "best_bid":"0.01", "best_ask":"0.02"}, {"asset_id":"96888240988495161476033313796107536512663280794332045579302109906525918376981", "price":"0.99", "size":"3772.89", "side":"SELL", "hash":"d7a1a350fd6e40018055bd6a5afb99488d15f752", "best_bid":"0.98", "best_ask":"0.99"}], "timestamp":"1770241482837", "event_type":"price_change"}
{"market":"0x38f3050258345e9cf363d1c8cc302f08c65b96ba1a4669d81e07ed69708344df", "price_changes":[{"asset_id":"96888240988495161476033313796107536512663280794332045579302109906525918376981", "price":"0.96", "size":"650.73", "side":"BUY", "hash":"bcfaae4d3ce96e6aa002d90244fbdb003dae923b", "best_bid":"0.98", "best_ask":"0.99"}, {"asset_id":"81916206347121459497221114766050949090435061493822476265356047392175668050706", "price":"0.04", "size":"650.73", "side":"SELL", "hash":"3f88841794424eab8b9bf0b517dedd1f32b664ed", "best_bid":"0.01", "best_ask":"0.02"}], "timestamp":"1770241482838", "event_type":"price_change"}
{"market":"0x38f3050258345e9cf363d1c8cc302f08c65b96ba1a4669d81e07ed69708344df", "price_changes":[{"asset_id":"96888240988495161476033313796107536512663280794332045579302109906525918376981", "price":"0.96", "size":"677.73", "side":"BUY", "hash":"f911fc6d7722d3160159ee6a23399aed890c17dd", "best_bid":"0.98", "best_ask":"0.99"}, {"asset_id":"81916206347121459497221114766050949090435061493822476265356047392175668050706", "price":"0.04", "size":"677.73", "side":"SELL", "hash":"cef166631f3d67a7d6b664578d4e65d6bdcf0578", "best_bid":"0.01", "best_ask":"0.02"}], "timestamp":"1770241482839", "event_type":"price_change"}
{"market":"0x38f3050258345e9cf363d1c8cc302f08c65b96ba1a4669d81e07ed69708344df", "price_changes":[{"asset_id":"81916206347121459497221114766050949090435061493822476265356047392175668050706", "price":"0.01", "size":"3799.89", "side":"BUY", "hash":"28f31a4466deb2b10547d8614ca8ec21dc3237d4", "best_bid":"0.01", "best_ask":"0.02"}, {"asset_id":"96888240988495161476033313796107536512663280794332045579302109906525918376981", "price":"0.99", "size":"3799.89", "side":"SELL", "hash":"264fd3d7b488bf62b50ff9ebe5d66292c7b5203c", "best_bid":"0.98", "best_ask":"0.99"}], "timestamp":"1770241482839", "event_type":"price_change"}
{"market":"0x38f3050258345e9cf363d1c8cc302f08c65b96ba1a4669d81e07ed69708344df", "price_changes":[{"asset_id":"96888240988495161476033313796107536512663280794332045579302109906525918376981", "price":"0.97", "size":"649.32", "side":"BUY", "hash":"dd311a6471756f588ed7f5db83ac808f3244a378", "best_bid":"0.98", "best_ask":"0.99"}, {"asset_id":"81916206347121459497221114766050949090435061493822476265356047392175668050706", "price":"0.03", "size":"649.32", "side":"SELL", "hash":"e4a62d0cb8f8f0202dc01ec90c2aa74315824eba", "best_bid":"0.01", "best_ask":"0.02"}], "timestamp":"1770241482840", "event_type":"price_change"}
{"market":"0x38f3050258345e9cf363d1c8cc302f08c65b96ba1a4669d81e07ed69708344df", "price_changes":[{"asset_id":"96888240988495161476033313796107536512663280794332045579302109906525918376981", "price":"0.96", "size":"700.73", "side":"BUY", "hash":"3b03e3bbb1521a684d185339af7ec5ac56fb613a", "best_bid":"0.98", "best_ask":"0.99"}, {"asset_id":"81916206347121459497221114766050949090435061493822476265356047392175668050706", "price":"0.04", "size":"700.73", "side":"SELL", "hash":"0f9a16e3ec9e4202d655cf548d225b3e148259a0", "best_bid":"0.01", "best_ask":"0.02"}], "timestamp":"1770241482840", "event_type":"price_change"}
{"market":"0x38f3050258345e9cf363d1c8cc302f08c65b96ba1a4669d81e07ed69708344df", "price_changes":[{"asset_id":"81916206347121459497221114766050949090435061493822476265356047392175668050706", "price":"0.01", "size":"3826.89", "side":"BUY", "hash":"aeb3f57d487327aa8920008e93746ada779fb21a", "best_bid":"0.01", "best_ask":"0.02"}, {"asset_id":"96888240988495161476033313796107536512663280794332045579302109906525918376981", "price":"0.99", "size":"3826.89", "side":"SELL", "hash":"a40475a17906b16f3c4d8c81e150cba1fd7e35f4", "best_bid":"0.98", "best_ask":"0.99"}], "timestamp":"1770241482841", "event_type":"price_change"}
{"market":"0x38f3050258345e9cf363d1c8cc302f08c65b96ba1a4669d81e07ed69708344df", "price_changes":[{"asset_id":"81916206347121459497221114766050949090435061493822476265356047392175668050706", "price":"0.01", "size":"3799.89", "side":"BUY", "hash":"e998ffc22e79886b4d6923534426ac77a546c62c", "best_bid":"0.01", "best_ask":"0.02"}, {"asset_id":"96888240988495161476033313796107536512663280794332045579302109906525918376981", "price":"0.99", "size":"3799.89", "side":"SELL", "hash":"9c270bcd4628f09c79e0a03ee662ef98efdb952c", "best_bid":"0.98", "best_ask":"0.99"}], "timestamp":"1770241482844", "event_type":"price_change"}
{"market":"0x38f3050258345e9cf363d1c8cc302f08c65b96ba1a4669d81e07ed69708344df", "price_changes":[{"asset_id":"81916206347121459497221114766050949090435061493822476265356047392175668050706", "price":"0.01", "size":"3826.89", "side":"BUY", "hash":"7677b4a7c96a0b831515a3b5e394798624968abc", "best_bid":"0.01", "best_ask":"0.02"}, {"asset_id":"96888240988495161476033313796107536512663280794332045579302109906525918376981", "price":"0.99", "size":"3826.89", "side":"SELL", "hash":"7b863719992bae116adf03b0a242f7b692be0540", "best_bid":"0.98", "best_ask":"0.99"}], "timestamp":"1770241482845", "event_type":"price_change"}
{"market":"0x38f3050258345e9cf363d1c8cc302f08c65b96ba1a4669d81e07ed69708344df", "price_changes":[{"asset_id":"96888240988495161476033313796107536512663280794332045579302109906525918376981", "price":"0.97", "size":"622.32", "side":"BUY", "hash":"e405c5a948fb013a4e46444743935741849fb3d0", "best_bid":"0.98", "best_ask":"0.99"}, {"asset_id":"81916206347121459497221114766050949090435061493822476265356047392175668050706", "price":"0.03", "size":"622.32", "side":"SELL", "hash":"c4ac710bc0abbc411b2b2f57ad44bd9ecc960aba", "best_bid":"0.01", "best_ask":"0.02"}], "timestamp":"1770241482846", "event_type":"price_change"}
{"market":"0x38f3050258345e9cf363d1c8cc302f08c65b96ba1a4669d81e07ed69708344df", "price_changes":[{"asset_id":"96888240988495161476033313796107536512663280794332045579302109906525918376981", "price":"0.96", "size":"727.73", "side":"BUY", "hash":"ea3b04a91b24bb77b861c604505b65a79768da28", "best_bid":"0.98", "best_ask":"0.99"}, {"asset_id":"81916206347121459497221114766050949090435061493822476265356047392175668050706", "price":"0.04", "size":"727.73", "side":"SELL", "hash":"cf2985a269cdb74283ae552c08b9d8f2f3058af5", "best_bid":"0.01", "best_ask":"0.02"}], "timestamp":"1770241482847", "event_type":"price_change"}
{"market":"0x38f3050258345e9cf363d1c8cc302f08c65b96ba1a4669d81e07ed69708344df", "price_changes":[{"asset_id":"96888240988495161476033313796107536512663280794332045579302109906525918376981", "price":"0.98", "size":"583.97", "side":"BUY", "hash":"714aa7ec394ce518df01f8c7c4d33345b208f698", "best_bid":"0.98", "best_ask":"0.99"}, {"asset_id":"81916206347121459497221114766050949090435061493822476265356047392175668050706", "price":"0.02", "size":"583.97", "side":"SELL", "hash":"61d7291cd12227c6b500dc30ad6beaff377e4df6", "best_bid":"0.01", "best_ask":"0.02"}], "timestamp":"1770241482904", "event_type":"price_change"}
{"market":"0x38f3050258345e9cf363d1c8cc302f08c65b96ba1a4669d81e07ed69708344df", "asset_id":"81916206347121459497221114766050949090435061493822476265356047392175668050706", "bids":[{"price":"0.01", "size":"3826.89"}], "asks":[{"price":"0.99", "size":"5019.91"}, {"price":"0.98", "size":"3034.23"}, {"price":"0.97", "size":"3172"}, {"price":"0.96", "size":"3012"}, {"price":"0.95", "size":"3032"}, {"price":"0.94", "size":"3012"}, {"price":"0.93", "size":"3126.28"}, {"price":"0.92", "size":"3012"}, {"price":"0.91", "size":"3012"}, {"price":"0.9", "size":"3087"}, {"price":"0.89", "size":"12"}, {"price":"0.88", "size":"12"}, {"price":"0.87", "size":"12"}, {"price":"0.86", "size":"12"}, {"price":"0.85", "size":"12"}, {"price":"0.84", "size":"12"}, {"price":"0.83", "size":"12"}, {"price":"0.82", "size":"12"}, {"price":"0.81", "size":"12"}, {"price":"0.8", "size":"12"}, {"price":"0.79", "size":"12"}, {"price":"0.78", "size":"12"}, {"price":"0.77", "size":"12"}, {"price":"0.76", "size":"112"}, {"price":"0.75", "size":"40.57"}, {"price":"0.74", "size":"12"}, {"price":"0.73", "size":"293.25"}, {"price":"0.72", "size":"22"}, {"price":"0.71", "size":"12"}, {"price":"0.7", "size":"18"}, {"price":"0.69", "size":"12"}, {"price":"0.68", "size":"12"}, {"price":"0.67", "size":"12"}, {"price":"0.66", "size":"160.89"}, {"price":"0.65", "size":"12"}, {"price":"0.64", "size":"12"}, {"price":"0.63", "size":"12"}, {"price":"0.62", "size":"19.39"}, {"price":"0.61", "size":"18.04"}, {"price":"0.6", "size":"12"}, {"price":"0.59", "size":"94.31"}, {"price":"0.58", "size":"5450.54"}, {"price":"0.57", "size":"12"}, {"price":"0.56", "size":"12"}, {"price":"0.55", "size":"12"}, {"price":"0.54", "size":"22"}, {"price":"0.53", "size":"12"}, {"price":"0.52", "size":"12"}, {"price":"0.51", "size":"12"}, {"price":"0.5", "size":"12"}, {"price":"0.49", "size":"12"}, {"price":"0.48", "size":"12"}, {"price":"0.47", "size":"12"}, {"price":"0.46", "size":"485.56"}, {"price":"0.45", "size":"31"}, {"price":"0.44", "size":"17"}, {"price":"0.43", "size":"12"}, {"price":"0.42", "size":"12"}, {"price":"0.41", "size":"12"}, {"price":"0.4", "size":"127"}, {"price":"0.39", "size":"12"}, {"price":"0.38", "size":"94.51"}, {"price":"0.37", "size":"31.99"}, {"price":"0.36", "size":"12"}, {"price":"0.35", "size":"37"}, {"price":"0.34", "size":"12"}, {"price":"0.33", "size":"12"}, {"price":"0.32", "size":"12"}, {"price":"0.31", "size":"12"}, {"price":"0.3", "size":"31.9"}, {"price":"0.29", "size":"344"}, {"price":"0.28", "size":"3288.99"}, {"price":"0.27", "size":"212"}, {"price":"0.26", "size":"218"}, {"price":"0.25", "size":"212"}, {"price":"0.24", "size":"212"}, {"price":"0.23", "size":"212"}, {"price":"0.22", "size":"1723.14"}, {"price":"0.21", "size":"212"}, {"price":"0.2", "size":"472.99"}, {"price":"0.19", "size":"212"}, {"price":"0.18", "size":"212"}, {"price":"0.17", "size":"212"}, {"price":"0.16", "size":"812"}, {"price":"0.15", "size":"231.08"}, {"price":"0.14", "size":"283.65"}, {"price":"0.13", "size":"212"}, {"price":"0.12", "size":"252"}, {"price":"0.11", "size":"252"}, {"price":"0.1", "size":"737.71"}, {"price":"0.09", "size":"261"}, {"price":"0.08", "size":"844.68"}, {"price":"0.07", "size":"326"}, {"price":"0.06", "size":"926"}, {"price":"0.05", "size":"626"}, {"price":"0.04", "size":"727.73"}, {"price":"0.03", "size":"622.32"}, {"price":"0.02", "size":"583.97"}], "hash":"61d7291cd12227c6b500dc30ad6beaff377e4df6", "timestamp":"1770241482904", "event_type":"book"}
{"market":"0x38f3050258345e9cf363d1c8cc302f08c65b96ba1a4669d81e07ed69708344df", "price_changes":[{"asset_id":"81916206347121459497221114766050949090435061493822476265356047392175668050706", "price":"0.01", "size":"3799.89", "side":"BUY", "hash":"c48833c3d7fe45e35c40a803b2bb95cbeb95aa2c", "best_bid":"0.01", "best_ask":"0.02"}, {"asset_id":"96888240988495161476033313796107536512663280794332045579302109906525918376981", "price":"0.99", "size":"3799.89", "side":"SELL", "hash":"e34c7544ab15ba6a3114846354bfe4a0938865a8", "best_bid":"0.98", "best_ask":"0.99"}], "timestamp":"1770241482958", "event_type":"price_change"}
{"market":"0x38f3050258345e9cf363d1c8cc302f08c65b96ba1a4669d81e07ed69708344df", "price_changes":[{"asset_id":"81916206347121459497221114766050949090435061493822476265356047392175668050706", "price":"0.01", "size":"3826.89", "side":"BUY", "hash":"18f56c9cefe2501aaad0d75b5f66892d14676cd7", "best_bid":"0.01", "best_ask":"0.02"}, {"asset_id":"96888240988495161476033313796107536512663280794332045579302109906525918376981", "price":"0.99", "size":"3826.89", "side":"SELL", "hash":"ef9e7c2101fbcb675017c5b5dc4cccb61904f9e8", "best_bid":"0.98", "best_ask":"0.99"}], "timestamp":"1770241482960", "event_type":"price_change"}
{"market":"0x38f3050258345e9cf363d1c8cc302f08c65b96ba1a4669d81e07ed69708344df", "price_changes":[{"asset_id":"96888240988495161476033313796107536512663280794332045579302109906525918376981", "price":"0.96", "size":"754.73", "side":"BUY", "hash":"8c25f61b4df91cb4293e204528f8f139bb017c4c", "best_bid":"0.98", "best_ask":"0.99"}, {"asset_id":"81916206347121459497221114766050949090435061493822476265356047392175668050706", "price":"0.04", "size":"754.73", "side":"SELL", "hash":"3cf15e8ac8b3ca7d135c56760f9976fdec8669f2", "best_bid":"0.01", "best_ask":"0.02"}], "timestamp":"1770241482962", "event_type":"price_change"}
{"market":"0x38f3050258345e9cf363d1c8cc302f08c65b96ba1a4669d81e07ed69708344df", "price_changes":[{"asset_id":"96888240988495161476033313796107536512663280794332045579302109906525918376981", "price":"0.95", "size":"631", "side":"BUY", "hash":"51692c2f101b4341c3b5af6e935e0cc8f9cb65a4", "best_bid":"0.98", "best_ask":"0.99"}, {"asset_id":"81916206347121459497221114766050949090435061493822476265356047392175668050706", "price":"0.05", "size":"631", "side":"SELL", "hash":"66f73ee2865d09903f4f3993b0a4179227e5ccd4", "best_bid":"0.01", "best_ask":"0.02"}], "timestamp":"1770241482963", "event_type":"price_change"}
{"market":"0x38f3050258345e9cf363d1c8cc302f08c65b96ba1a4669d81e07ed69708344df", "price_changes":[{"asset_id":"96888240988495161476033313796107536512663280794332045579302109906525918376981", "price":"0.96", "size":"727.73", "side":"BUY", "hash":"12e4f8aca65e7d8c5b94dfa9792a72825c5e619e", "best_bid":"0.98", "best_ask":"0.99"}, {"asset_id":"81916206347121459497221114766050949090435061493822476265356047392175668050706", "price":"0.04", "size":"727.73", "side":"SELL", "hash":"6e5a1a35d2b3c1334a167dd8912583162b7605f5", "best_bid":"0.01", "best_ask":"0.02"}], "timestamp":"1770241482964", "event_type":"price_change"}
{"market":"0x38f3050258345e9cf363d1c8cc302f08c65b96ba1a4669d81e07ed69708344df", "price_changes":[{"asset_id":"81916206347121459497221114766050949090435061493822476265356047392175668050706", "price":"0.01", "size":"3853.89", "side":"BUY", "hash":"3fe539355a6dc27c44d0a3513595904d5afdf6e8", "best_bid":"0.01", "best_ask":"0.02"}, {"asset_id":"96888240988495161476033313796107536512663280794332045579302109906525918376981", "price":"0.99", "size":"3853.89", "side":"SELL", "hash":"8c2643625fd9aad3fca3fdcf90fd93abcc5cae95", "best_bid":"0.98", "best_ask":"0.99"}], "timestamp":"1770241482968", "event_type":"price_change"}
{"market":"0x38f3050258345e9cf363d1c8cc302f08c65b96ba1a4669d81e07ed69708344df", "price_changes":[{"asset_id":"81916206347121459497221114766050949090435061493822476265356047392175668050706", "price":"0.01", "size":"3826.89", "side":"BUY", "hash":"c3371bbb0679b9d223bdc329bfb49b2974271804", "best_bid":"0.01", "best_ask":"0.02"}, {"asset_id":"96888240988495161476033313796107536512663280794332045579302109906525918376981", "price":"0.99", "size":"3826.89", "side":"SELL", "hash":"248ea92f8584f73e13cc8f688616a224e5024a05", "best_bid":"0.98", "best_ask":"0.99"}], "timestamp":"1770241482968", "event_type":"price_change"}
{"market":"0x38f3050258345e9cf363d1c8cc302f08c65b96ba1a4669d81e07ed69708344df", "price_changes":[{"asset_id":"81916206347121459497221114766050949090435061493822476265356047392175668050706", "price":"0.01", "size":"3799.89", "side":"BUY", "hash":"4b710b51c4c12b0b739760327a9fb14d5034c373", "best_bid":"0.01", "best_ask":"0.02"}, {"asset_id":"96888240988495161476033313796107536512663280794332045579302109906525918376981", "price":"0.99", "size":"3799.89", "side":"SELL", "hash":"4a55dc29ff5f7869abebe7f90d3ff7823da7e69e", "best_bid":"0.98", "best_ask":"0.99"}], "timestamp":"1770241482970", "event_type":"price_change"}
{"market":"0x38f3050258345e9cf363d1c8cc302f08c65b96ba1a4669d81e07ed69708344df", "price_changes":[{"asset_id":"96888240988495161476033313796107536512663280794332045579302109906525918376981", "price":"0.96", "size":"700.73", "side":"BUY", "hash":"8cb33b4ec15e80ca7b8b05a15506057b11c35749", "best_bid":"0.98", "best_ask":"0.99"}, {"asset_id":"81916206347121459497221114766050949090435061493822476265356047392175668050706", "price":"0.04", "size":"700.73", "side":"SELL", "hash":"573afa4832ddb3726f2b72cc983761cbee767e6b", "best_bid":"0.01", "best_ask":"0.02"}], "timestamp":"1770241482970", "event_type":"price_change"}
{"market":"0x38f3050258345e9cf363d1c8cc302f08c65b96ba1a4669d81e07ed69708344df", "price_changes":[{"asset_id":"96888240988495161476033313796107536512663280794332045579302109906525918376981", "price":"0.97", "size":"649.32", "side":"BUY", "hash":"6824abfc745af83a134dd7627b96e82f3c774417", "best_bid":"0.98", "best_ask":"0.99"}, {"asset_id":"81916206347121459497221114766050949090435061493822476265356047392175668050706", "price":"0.03", "size":"649.32", "side":"SELL", "hash":"68c287de0b7797bfc4caacb591f0eb43085e110e", "best_bid":"0.01", "best_ask":"0.02"}], "timestamp":"1770241482971", "event_type":"price_change"}
{"market":"0x38f3050258345e9cf363d1c8cc302f08c65b96ba1a4669d81e07ed69708344df", "price_changes":[{"asset_id":"81916206347121459497221114766050949090435061493822476265356047392175668050706", "price":"0.01", "size":"3826.89", "side":"BUY", "hash":"9a3e24b8817dbaffda3eda40e9a4c7f1af213f9e", "best_bid":"0.01", "best_ask":"0.02"}, {"asset_id":"96888240988495161476033313796107536512663280794332045579302109906525918376981", "price":"0.99", "size":"3826.89", "side":"SELL", "hash":"3b545df4a30a5b077eda14031c063b79a53d0137", "best_bid":"0.98", "best_ask":"0.99"}], "timestamp":"1770241482972", "event_type":"price_change"}
{"market":"0x38f3050258345e9cf363d1c8cc302f08c65b96ba1a4669d81e07ed69708344df", "price_changes":[{"asset_id":"96888240988495161476033313796107536512663280794332045579302109906525918376981", "price":"0.96", "size":"727.73", "side":"BUY", "hash":"f944b1d759ff2d7e33bff39a3aef109e86185e32", "best_bid":"0.98", "best_ask":"0.99"}, {"asset_id":"81916206347121459497221114766050949090435061493822476265356047392175668050706", "price":"0.04", "size":"727.73", "side":"SELL", "hash":"5fcc5153bc6240d10061da4bed0d7c545f509ce9", "best_bid":"0.01", "best_ask":"0.02"}], "timestamp":"1770241482974", "event_type":"price_change"}
{"market":"0x38f3050258345e9cf363d1c8cc302f08c65b96ba1a4669d81e07ed69708344df", "price_changes":[{"asset_id":"96888240988495161476033313796107536512663280794332045579302109906525918376981", "price":"0.94", "size":"931", "side":"BUY", "hash":"fee4290c966560bb9f7050348450a2eae7fbbe74", "best_bid":"0.98", "best_ask":"0.99"}, {"asset_id":"81916206347121459497221114766050949090435061493822476265356047392175668050706", "price":"0.06", "size":"931", "side":"SELL", "hash":"9cd0e1856f2c82b9c578d908a1d1800963865f5c", "best_bid":"0.01", "best_ask":"0.02"}], "timestamp":"1770241482976", "event_type":"price_change"}
{"market":"0x38f3050258345e9cf363d1c8cc302f08c65b96ba1a4669d81e07ed69708344df", "price_changes":[{"asset_id":"96888240988495161476033313796107536512663280794332045579302109906525918376981", "price":"0.96", "size":"700.73", "side":"BUY", "hash":"9c3f3dd2a05aeeba2e58624bcd40ddf9186606d3", "best_bid":"0.98", "best_ask":"0.99"}, {"asset_id":"81916206347121459497221114766050949090435061493822476265356047392175668050706", "price":"0.04", "size":"700.73", "side":"SELL", "hash":"0f16fc51b1a51e0e0607d3839d06dad23ca288a2", "best_bid":"0.01", "best_ask":"0.02"}], "timestamp":"1770241482977", "event_type":"price_change"}
{"market":"0x38f3050258345e9cf363d1c8cc302f08c65b96ba1a4669d81e07ed69708344df", "price_changes":[{"asset_id":"81916206347121459497221114766050949090435061493822476265356047392175668050706", "price":"0.01", "size":"3817.89", "side":"BUY", "hash":"ac8c9f2ee3fd94a862bd69e7edeb663429df4c1b", "best_bid":"0.01", "best_ask":"0.02"}, {"asset_id":"96888240988495161476033313796107536512663280794332045579302109906525918376981", "price":"0.99", "size":"3817.89", "side":"SELL", "hash":"9c359e487c54daec38e6020d4222fd95d3c0f8c9", "best_bid":"0.98", "best_ask":"0.99"}], "timestamp":"1770241483055", "event_type":"price_change"}
{"market":"0x38f3050258345e9cf363d1c8cc302f08c65b96ba1a4669d81e07ed69708344df", "asset_id":"81916206347121459497221114766050949090435061493822476265356047392175668050706", "bids":[{"price":"0.01", "size":"3817.89"}], "asks":[{"price":"0.99", "size":"5019.91"}, {"price":"0.98", "size":"3034.23"}, {"price":"0.97", "size":"3172"}, {"price":"0.96", "size":"3012"}, {"price":"0.95", "size":"3032"}, {"price":"0.94", "size":"3012"}, {"price":"0.93", "size":"3126.28"}, {"price":"0.92", "size":"3012"}, {"price":"0.91", "size":"3012"}, {"price":"0.9", "size":"3087"}, {"price":"0.89", "size":"12"}, {"price":"0.88", "size":"12"}, {"price":"0.87", "size":"12"}, {"price":"0.86", "size":"12"}, {"price":"0.85", "size":"12"}, {"price":"0.84", "size":"12"}, {"price":"0.83", "size":"12"}, {"price":"0.82", "size":"12"}, {"price":"0.81", "size":"12"}, {"price":"0.8", "size":"12"}, {"price":"0.79", "size":"12"}, {"price":"0.78", "size":"12"}, {"price":"0.77", "size":"12"}, {"price":"0.76", "size":"112"}, {"price":"0.75", "size":"40.57"}, {"price":"0.74", "size":"12"}, {"price":"0.73", "size":"293.25"}, {"price":"0.72", "size":"22"}, {"price":"0.71", "size":"12"}, {"price":"0.7", "size":"18"}, {"price":"0.69", "size":"12"}, {"price":"0.68", "size":"12"}, {"price":"0.67", "size":"12"}, {"price":"0.66", "size":"160.89"}, {"price":"0.65", "size":"12"}, {"price":"0.64", "size":"12"}, {"price":"0.63", "size":"12"}, {"price":"0.62", "size":"19.39"}, {"price":"0.61", "size":"18.04"}, {"price":"0.6", "size":"12"}, {"price":"0.59", "size":"94.31"}, {"price":"0.58", "size":"5450.54"}, {"price":"0.57", "size":"12"}, {"price":"0.56", "size":"12"}, {"price":"0.55", "size":"12"}, {"price":"0.54", "size":"22"}, {"price":"0.53", "size":"12"}, {"price":"0.52", "size":"12"}, {"price":"0.51", "size":"12"}, {"price":"0.5", "size":"12"}, {"price":"0.49", "size":"12"}, {"price":"0.48", "size":"12"}, {"price":"0.47", "size":"12"}, {"price":"0.46", "size":"485.56"}, {"price":"0.45", "size":"31"}, {"price":"0.44", "size":"17"}, {"price":"0.43", "size":"12"}, {"price":"0.42", "size":"12"}, {"price":"0.41", "size":"12"}, {"price":"0.4", "size":"127"}, {"price":"0.39", "size":"12"}, {"price":"0.38", "size":"94.51"}, {"price":"0.37", "size":"31.99"}, {"price":"0.36", "size":"12"}, {"price":"0.35", "size":"37"}, {"price":"0.34", "size":"12"}, {"price":"0.33", "size":"12"}, {"price":"0.32", "size":"12"}, {"price":"0.31", "size":"12"}, {"price":"0.3", "size":"31.9"}, {"price":"0.29", "size":"344"}, {"price":"0.28", "size":"3288.99"}, {"price":"0.27", "size":"212"}, {"price":"0.26", "size":"218"}, {"price":"0.25", "size":"212"}, {"price":"0.24", "size":"212"}, {"price":"0.23", "size":"212"}, {"price":"0.22", "size":"1723.14"}, {"price":"0.21", "size":"212"}, {"price":"0.2", "size":"472.99"}, {"price":"0.19", "size":"212"}, {"price":"0.18", "size":"212"}, {"price":"0.17", "size":"212"}, {"price":"0.16", "size":"812"}, {"price":"0.15", "size":"231.08"}, {"price":"0.14", "size":"283.65"}, {"price":"0.13", "size":"212"}, {"price":"0.12", "size":"252"}, {"price":"0.11", "size":"252"}, {"price":"0.1", "size":"737.71"}, {"price":"0.09", "size":"261"}, {"price":"0.08", "size":"844.68"}, {"price":"0.07", "size":"326"}, {"price":"0.06", "size":"931"}, {"price":"0.05", "size":"631"}, {"price":"0.04", "size":"700.73"}, {"price":"0.03", "size":"649.32"}, {"price":"0.02", "size":"583.97"}], "hash":"ac8c9f2ee3fd94a862bd69e7edeb663429df4c1b", "timestamp":"1770241483055", "event_type":"book"}
{"market":"0x38f3050258345e9cf363d1c8cc302f08c65b96ba1a4669d81e07ed69708344df", "price_changes":[{"asset_id":"81916206347121459497221114766050949090435061493822476265356047392175668050706", "price":"0.01", "size":"3812.89", "side":"BUY", "hash":"e77e552d90c1b11cdf0f4a401b090b2630ad97e7", "best_bid":"0.01", "best_ask":"0.02"}, {"asset_id":"96888240988495161476033313796107536512663280794332045579302109906525918376981", "price":"0.99", "size":"3812.89", "side":"SELL", "hash":"adf82048593d686b9e3db35311581e649d5e58ec", "best_bid":"0.98", "best_ask":"0.99"}], "timestamp":"1770241483060", "event_type":"price_change"}
{"market":"0x38f3050258345e9cf363d1c8cc302f08c65b96ba1a4669d81e07ed69708344df", "asset_id":"81916206347121459497221114766050949090435061493822476265356047392175668050706", "bids":[{"price":"0.01", "size":"3812.89"}], "asks":[{"price":"0.99", "size":"5019.91"}, {"price":"0.98", "size":"3034.23"}, {"price":"0.97", "size":"3172"}, {"price":"0.96", "size":"3012"}, {"price":"0.95", "size":"3032"}, {"price":"0.94", "size":"3012"}, {"price":"0.93", "size":"3126.28"}, {"price":"0.92", "size":"3012"}, {"price":"0.91", "size":"3012"}, {"price":"0.9", "size":"3087"}, {"price":"0.89", "size":"12"}, {"price":"0.88", "size":"12"}, {"price":"0.87", "size":"12"}, {"price":"0.86", "size":"12"}, {"price":"0.85", "size":"12"}, {"price":"0.84", "size":"12"}, {"price":"0.83", "size":"12"}, {"price":"0.82", "size":"12"}, {"price":"0.81", "size":"12"}, {"price":"0.8", "size":"12"}, {"price":"0.79", "size":"12"}, {"price":"0.78", "size":"12"}, {"price":"0.77", "size":"12"}, {"price":"0.76", "size":"112"}, {"price":"0.75", "size":"40.57"}, {"price":"0.74", "size":"12"}, {"price":"0.73", "size":"293.25"}, {"price":"0.72", "size":"22"}, {"price":"0.71", "size":"12"}, {"price":"0.7", "size":"18"}, {"price":"0.69", "size":"12"}, {"price":"0.68", "size":"12"}, {"price":"0.67", "size":"12"}, {"price":"0.66", "size":"160.89"}, {"price":"0.65", "size":"12"}, {"price":"0.64", "size":"12"}, {"price":"0.63", "size":"12"}, {"price":"0.62", "size":"19.39"}, {"price":"0.61", "size":"18.04"}, {"price":"0.6", "size":"12"}, {"price":"0.59", "size":"94.31"}, {"price":"0.58", "size":"5450.54"}, {"price":"0.57", "size":"12"}, {"price":"0.56", "size":"12"}, {"price":"0.55", "size":"12"}, {"price":"0.54", "size":"22"}, {"price":"0.53", "size":"12"}, {"price":"0.52", "size":"12"}, {"price":"0.51", "size":"12"}, {"price":"0.5", "size":"12"}, {"price":"0.49", "size":"12"}, {"price":"0.48", "size":"12"}, {"price":"0.47", "size":"12"}, {"price":"0.46", "size":"485.56"}, {"price":"0.45", "size":"31"}, {"price":"0.44", "size":"17"}, {"price":"0.43", "size":"12"}, {"price":"0.42", "size":"12"}, {"price":"0.41", "size":"12"}, {"price":"0.4", "size":"127"}, {"price":"0.39", "size":"12"}, {"price":"0.38", "size":"94.51"}, {"price":"0.37", "size":"31.99"}, {"price":"0.36", "size":"12"}, {"price":"0.35", "size":"37"}, {"price":"0.34", "size":"12"}, {"price":"0.33", "size":"12"}, {"price":"0.32", "size":"12"}, {"price":"0.31", "size":"12"}, {"price":"0.3", "size":"31.9"}, {"price":"0.29", "size":"344"}, {"price":"0.28", "size":"3288.99"}, {"price":"0.27", "size":"212"}, {"price":"0.26", "size":"218"}, {"price":"0.25", "size":"212"}, {"price":"0.24", "size":"212"}, {"price":"0.23", "size":"212"}, {"price":"0.22", "size":"1723.14"}, {"price":"0.21", "size":"212"}, {"price":"0.2", "size":"472.99"}, {"price":"0.19", "size":"212"}, {"price":"0.18", "size":"212"}, {"price":"0.17", "size":"212"}, {"price":"0.16", "size":"812"}, {"price":"0.15", "size":"231.08"}, {"price":"0.14", "size":"283.65"}, {"price":"0.13", "size":"212"}, {"price":"0.12", "size":"252"}, {"price":"0.11", "size":"252"}, {"price":"0.1", "size":"737.71"}, {"price":"0.09", "size":"261"}, {"price":"0.08", "size":"844.68"}, {"price":"0.07", "size":"326"}, {"price":"0.06", "size":"931"}, {"price":"0.05", "size":"631"}, {"price":"0.04", "size":"700.73"}, {"price":"0.03", "size":"649.32"}, {"price":"0.02", "size":"583.97"}], "hash":"e77e552d90c1b11cdf0f4a401b090b2630ad97e7", "timestamp":"1770241483060", "event_type":"book"}
{"market":"0x38f3050258345e9cf363d1c8cc302f08c65b96ba1a4669d81e07ed69708344df", "price_changes":[{"asset_id":"96888240988495161476033313796107536512663280794332045579302109906525918376981", "price":"0.96", "size":"677.73", "side":"BUY", "hash":"dd4e8dbcb6963eb2db60cd7d3ffd100819d9e5cf", "best_bid":"0.98", "best_ask":"0.99"}, {"asset_id":"81916206347121459497221114766050949090435061493822476265356047392175668050706", "price":"0.04", "size":"677.73", "side":"SELL", "hash":"7a5c65c1c9ff091a6522075c8a1ad613f15332aa", "best_bid":"0.01", "best_ask":"0.02"}], "timestamp":"1770241483089", "event_type":"price_change"}
{"market":"0x38f3050258345e9cf363d1c8cc302f08c65b96ba1a4669d81e07ed69708344df", "price_changes":[{"asset_id":"96888240988495161476033313796107536512663280794332045579302109906525918376981", "price":"0.97", "size":"672.32", "side":"BUY", "hash":"8c4c390231f95e7156a0c9748f4f1fd513c60408", "best_bid":"0.98", "best_ask":"0.99"}, {"asset_id":"81916206347121459497221114766050949090435061493822476265356047392175668050706", "price":"0.03", "size":"672.32", "side":"SELL", "hash":"2aa96b9b4a56d0936e7e1ebf88ac96f093c2f102", "best_bid":"0.01", "best_ask":"0.02"}], "timestamp":"1770241483090", "event_type":"price_change"}
{"market":"0x38f3050258345e9cf363d1c8cc302f08c65b96ba1a4669d81e07ed69708344df", "price_changes":[{"asset_id":"81916206347121459497221114766050949090435061493822476265356047392175668050706", "price":"0.01", "size":"3767.43", "side":"BUY", "hash":"c779b17f7a968efa19e825e080fead913265d47b", "best_bid":"0.01", "best_ask":"0.02"}, {"asset_id":"96888240988495161476033313796107536512663280794332045579302109906525918376981", "price":"0.99", "size":"3767.43", "side":"SELL", "hash":"a90d54c8a21a3893ccb76ce538d4d4ce5e70ded2", "best_bid":"0.98", "best_ask":"0.99"}], "timestamp":"1770241483196", "event_type":"price_change"}
{"market":"0x38f3050258345e9cf363d1c8cc302f08c65b96ba1a4669d81e07ed69708344df", "asset_id":"81916206347121459497221114766050949090435061493822476265356047392175668050706", "bids":[{"price":"0.01", "size":"3767.43"}], "asks":[{"price":"0.99", "size":"5019.91"}, {"price":"0.98", "size":"3034.23"}, {"price":"0.97", "size":"3172"}, {"price":"0.96", "size":"3012"}, {"price":"0.95", "size":"3032"}, {"price":"0.94", "size":"3012"}, {"price":"0.93", "size":"3126.28"}, {"price":"0.92", "size":"3012"}, {"price":"0.91", "size":"3012"}, {"price":"0.9", "size":"3087"}, {"price":"0.89", "size":"12"}, {"price":"0.88", "size":"12"}, {"price":"0.87", "size":"12"}, {"price":"0.86", "size":"12"}, {"price":"0.85", "size":"12"}, {"price":"0.84", "size":"12"}, {"price":"0.83", "size":"12"}, {"price":"0.82", "size":"12"}, {"price":"0.81", "size":"12"}, {"price":"0.8", "size":"12"}, {"price":"0.79", "size":"12"}, {"price":"0.78", "size":"12"}, {"price":"0.77", "size":"12"}, {"price":"0.76", "size":"112"}, {"price":"0.75", "size":"40.57"}, {"price":"0.74", "size":"12"}, {"price":"0.73", "size":"293.25"}, {"price":"0.72", "size":"22"}, {"price":"0.71", "size":"12"}, {"price":"0.7", "size":"18"}, {"price":"0.69", "size":"12"}, {"price":"0.68", "size":"12"}, {"price":"0.67", "size":"12"}, {"price":"0.66", "size":"160.89"}, {"price":"0.65", "size":"12"}, {"price":"0.64", "size":"12"}, {"price":"0.63", "size":"12"}, {"price":"0.62", "size":"19.39"}, {"price":"0.61", "size":"18.04"}, {"price":"0.6", "size":"12"}, {"price":"0.59", "size":"94.31"}, {"price":"0.58", "size":"5450.54"}, {"price":"0.57", "size":"12"}, {"price":"0.56", "size":"12"}, {"price":"0.55", "size":"12"}, {"price":"0.54", "size":"22"}, {"price":"0.53", "size":"12"}, {"price":"0.52", "size":"12"}, {"price":"0.51", "size":"12"}, {"price":"0.5", "size":"12"}, {"price":"0.49", "size":"12"}, {"price":"0.48", "size":"12"}, {"price":"0.47", "size":"12"}, {"price":"0.46", "size":"485.56"}, {"price":"0.45", "size":"31"}, {"price":"0.44", "size":"17"}, {"price":"0.43", "size":"12"}, {"price":"0.42", "size":"12"}, {"price":"0.41", "size":"12"}, {"price":"0.4", "size":"127"}, {"price":"0.39", "size":"12"}, {"price":"0.38", "size":"94.51"}, {"price":"0.37", "size":"31.99"}, {"price":"0.36", "size":"12"}, {"price":"0.35", "size":"37"}, {"price":"0.34", "size":"12"}, {"price":"0.33", "size":"12"}, {"price":"0.32", "size":"12"}, {"price":"0.31", "size":"12"}, {"price":"0.3", "size":"31.9"}, {"price":"0.29", "size":"344"}, {"price":"0.28", "size":"3288.99"}, {"price":"0.27", "size":"212"}, {"price":"0.26", "size":"218"}, {"price":"0.25", "size":"212"}, {"price":"0.24", "size":"212"}, {"price":"0.23", "size":"212"}, {"price":"0.22", "size":"1723.14"}, {"price":"0.21", "size":"212"}, {"price":"0.2", "size":"472.99"}, {"price":"0.19", "size":"212"}, {"price":"0.18", "size":"212"}, {"price":"0.17", "size":"212"}, {"price":"0.16", "size":"812"}, {"price":"0.15", "size":"231.08"}, {"price":"0.14", "size":"283.65"}, {"price":"0.13", "size":"212"}, {"price":"0.12", "size":"252"}, {"price":"0.11", "size":"252"}, {"price":"0.1", "size":"737.71"}, {"price":"0.09", "size":"261"}, {"price":"0.08", "size":"844.68"}, {"price":"0.07", "size":"326"}, {"price":"0.06", "size":"931"}, {"price":"0.05", "size":"631"}, {"price":"0.04", "size":"677.73"}, {"price":"0.03", "size":"672.32"}, {"price":"0.02", "size":"583.97"}], "hash":"c779b17f7a968efa19e825e080fead913265d47b", "timestamp":"1770241483196", "event_type":"book"}
{"market":"0x38f3050258345e9cf363d1c8cc302f08c65b96ba1a4669d81e07ed69708344df", "price_changes":[{"asset_id":"96888240988495161476033313796107536512663280794332045579302109906525918376981", "price":"0.96", "size":"650.73", "side":"BUY", "hash":"10c830f29cf31ff783b58822fcf05759b96afcb9", "best_bid":"0.98", "best_ask":"0.99"}, {"asset_id":"81916206347121459497221114766050949090435061493822476265356047392175668050706", "price":"0.04", "size":"650.73", "side":"SELL", "hash":"e8288d1317900b428cf8f379f2e1251d0453c16e", "best_bid":"0.01", "best_ask":"0.02"}], "timestamp":"1770241483232", "event_type":"price_change"}
{"market":"0x38f3050258345e9cf363d1c8cc302f08c65b96ba1a4669d81e07ed69708344df", "price_changes":[{"asset_id":"81916206347121459497221114766050949090435061493822476265356047392175668050706", "price":"0.01", "size":"3794.43", "side":"BUY", "hash":"ccd96ffa576e046367ce876a0c90ee5b1b4c0a09", "best_bid":"0.01", "best_ask":"0.02"}, {"asset_id":"96888240988495161476033313796107536512663280794332045579302109906525918376981", "price":"0.99", "size":"3794.43", "side":"SELL", "hash":"cc23d7ac4e723fddec639cb4872d30adf6e2132e", "best_bid":"0.98", "best_ask":"0.99"}], "timestamp":"1770241483237", "event_type":"price_change"}
{"market":"0x38f3050258345e9cf363d1c8cc302f08c65b96ba1a4669d81e07ed69708344df", "price_changes":[{"asset_id":"96888240988495161476033313796107536512663280794332045579302109906525918376981", "price":"0.95", "size":"658", "side":"BUY", "hash":"5bc3041313aa388c433473f7d86d49115c23f5ef", "best_bid":"0.98", "best_ask":"0.99"}, {"asset_id":"81916206347121459497221114766050949090435061493822476265356047392175668050706", "price":"0.05", "size":"658", "side":"SELL", "hash":"6d970d57308e40b4b701e8a55a7050f6a6a29c13", "best_bid":"0.01", "best_ask":"0.02"}], "timestamp":"1770241483238", "event_type":"price_change"}
{"market":"0x38f3050258345e9cf363d1c8cc302f08c65b96ba1a4669d81e07ed69708344df", "price_changes":[{"asset_id":"81916206347121459497221114766050949090435061493822476265356047392175668050706", "price":"0.01", "size":"3767.43", "side":"BUY", "hash":"9e50b0e72caf2da7b2b926f090e02a90c51d205f", "best_bid":"0.01", "best_ask":"0.02"}, {"asset_id":"96888240988495161476033313796107536512663280794332045579302109906525918376981", "price":"0.99", "size":"3767.43", "side":"SELL", "hash":"fd7c2ccdc8e66375ab71834e6968775b08142903", "best_bid":"0.98", "best_ask":"0.99"}], "timestamp":"1770241483240", "event_type":"price_change"}
{"market":"0x38f3050258345e9cf363d1c8cc302f08c65b96ba1a4669d81e07ed69708344df", "price_changes":[{"asset_id":"96888240988495161476033313796107536512663280794332045579302109906525918376981", "price":"0.95", "size":"685", "side":"BUY", "hash":"64e6cd013849641c595d931177d0a7d5d86c8e6c", "best_bid":"0.98", "best_ask":"0.99"}, {"asset_id":"81916206347121459497221114766050949090435061493822476265356047392175668050706", "price":"0.05", "size":"685", "side":"SELL", "hash":"c389529f11772bb1a71b641533f84888e7ef39aa", "best_bid":"0.01", "best_ask":"0.02"}], "timestamp":"1770241483246", "event_type":"price_change"}
{"market":"0x38f3050258345e9cf363d1c8cc302f08c65b96ba1a4669d81e07ed69708344df", "price_changes":[{"asset_id":"96888240988495161476033313796107536512663280794332045579302109906525918376981", "price":"0.96", "size":"623.73", "side":"BUY", "hash":"d2f7ce8b174f64f9349010562b4993bbe51abb14", "best_bid":"0.98", "best_ask":"0.99"}, {"asset_id":"81916206347121459497221114766050949090435061493822476265356047392175668050706", "price":"0.04", "size":"623.73", "side":"SELL", "hash":"747da4d0149b4f725f0b402443899a6ad2ec1e04", "best_bid":"0.01", "best_ask":"0.02"}], "timestamp":"1770241483246", "event_type":"price_change"}
{"market":"0x38f3050258345e9cf363d1c8cc302f08c65b96ba1a4669d81e07ed69708344df", "price_changes":[{"asset_id":"81916206347121459497221114766050949090435061493822476265356047392175668050706", "price":"0.01", "size":"3740.43", "side":"BUY", "hash":"f65a1c8aaaa2f33deb80ff9a10e233d9e2bfc2e8", "best_bid":"0.01", "best_ask":"0.02"}, {"asset_id":"96888240988495161476033313796107536512663280794332045579302109906525918376981", "price":"0.99", "size":"3740.43", "side":"SELL", "hash":"edfdf22e02dff2eaef4804b4cef306cef05e25a4", "best_bid":"0.98", "best_ask":"0.99"}], "timestamp":"1770241483247", "event_type":"price_change"}
{"market":"0x38f3050258345e9cf363d1c8cc302f08c65b96ba1a4669d81e07ed69708344df", "price_changes":[{"asset_id":"81916206347121459497221114766050949090435061493822476265356047392175668050706", "price":"0.01", "size":"3767.43", "side":"BUY", "hash":"9b225e04df92e839967fca995577452b8fbdd656", "best_bid":"0.01", "best_ask":"0.02"}, {"asset_id":"96888240988495161476033313796107536512663280794332045579302109906525918376981", "price":"0.99", "size":"3767.43", "side":"SELL", "hash":"2ea6ab9de35d03c0b3c818328be4bd7d0fc27557", "best_bid":"0.98", "best_ask":"0.99"}], "timestamp":"1770241483247", "event_type":"price_change"}
{"market":"0x38f3050258345e9cf363d1c8cc302f08c65b96ba1a4669d81e07ed69708344df", "price_changes":[{"asset_id":"96888240988495161476033313796107536512663280794332045579302109906525918376981", "price":"0.97", "size":"645.32", "side":"BUY", "hash":"edd71e684e7d72e7b2f7c8f11d5197b902d0b375", "best_bid":"0.98", "best_ask":"0.99"}, {"asset_id":"81916206347121459497221114766050949090435061493822476265356047392175668050706", "price":"0.03", "size":"645.32", "side":"SELL", "hash":"b8e2ccd7fb4a2549bae67f85ec19f8e15f401626", "best_bid":"0.01", "best_ask":"0.02"}], "timestamp":"1770241483252", "event_type":"price_change"}
{"market":"0x38f3050258345e9cf363d1c8cc302f08c65b96ba1a4669d81e07ed69708344df", "price_changes":[{"asset_id":"81916206347121459497221114766050949090435061493822476265356047392175668050706", "price":"0.01", "size":"3740.43", "side":"BUY", "hash":"92ca827af454e7424a1960a89af3b16a851232cb", "best_bid":"0.01", "best_ask":"0.02"}, {"asset_id":"96888240988495161476033313796107536512663280794332045579302109906525918376981", "price":"0.99", "size":"3740.43", "side":"SELL", "hash":"9187ad8d38aaf8e5dd0942d2288c9685297506a8", "best_bid":"0.98", "best_ask":"0.99"}], "timestamp":"1770241483253", "event_type":"price_change"}
{"market":"0x38f3050258345e9cf363d1c8cc302f08c65b96ba1a4669d81e07ed69708344df", "price_changes":[{"asset_id":"81916206347121459497221114766050949090435061493822476265356047392175668050706", "price":"0.01", "size":"3767.43", "side":"BUY", "hash":"49fa3e1ce6175a491676b311256c816d9b53deb8", "best_bid":"0.01", "best_ask":"0.02"}, {"asset_id":"96888240988495161476033313796107536512663280794332045579302109906525918376981", "price":"0.99", "size":"3767.43", "side":"SELL", "hash":"32908c52a04b83b1234bef19b61e2f1304fa11a3", "best_bid":"0.98", "best_ask":"0.99"}], "timestamp":"1770241483254", "event_type":"price_change"}
{"market":"0x38f3050258345e9cf363d1c8cc302f08c65b96ba1a4669d81e07ed69708344df", "price_changes":[{"asset_id":"96888240988495161476033313796107536512663280794332045579302109906525918376981", "price":"0.96", "size":"650.73", "side":"BUY", "hash":"18b0a89f3b274f9b20817277f357b4c5f141e2f9", "best_bid":"0.98", "best_ask":"0.99"}, {"asset_id":"81916206347121459497221114766050949090435061493822476265356047392175668050706", "price":"0.04", "size":"650.73", "side":"SELL", "hash":"4380167307b668f2001779372e8b82810be8b9fb", "best_bid":"0.01", "best_ask":"0.02"}], "timestamp":"1770241483268", "event_type":"price_change"}
{"market":"0x38f3050258345e9cf363d1c8cc302f08c65b96ba1a4669d81e07ed69708344df", "price_changes":[{"asset_id":"96888240988495161476033313796107536512663280794332045579302109906525918376981", "price":"0.96", "size":"630.73", "side":"BUY", "hash":"66b534fc7377fd23df7dd895636a4c6a690859fc", "best_bid":"0.98", "best_ask":"0.99"}, {"asset_id":"81916206347121459497221114766050949090435061493822476265356047392175668050706", "price":"0.04", "size":"630.73", "side":"SELL", "hash":"fc524087a99b0d2108906c02a6b6fd129c55e083", "best_bid":"0.01", "best_ask":"0.02"}], "timestamp":"1770241483280", "event_type":"price_change"}
PONG
{"market":"0x38f3050258345e9cf363d1c8cc302f08c65b96ba1a4669d81e07ed69708344df", "price_changes":[{"asset_id":"96888240988495161476033313796107536512663280794332045579302109906525918376981", "price":"0.95", "size":"658", "side":"BUY", "hash":"b6715b6d81004c0ad8ae7e10af5468f76b12cfdb", "best_bid":"0.98", "best_ask":"0.99"}, {"asset_id":"81916206347121459497221114766050949090435061493822476265356047392175668050706", "price":"0.05", "size":"658", "side":"SELL", "hash":"312241d048fcc74534804375c13a9db4703a7d88", "best_bid":"0.01", "best_ask":"0.02"}], "timestamp":"1770241483550", "event_type":"price_change"}
{"market":"0x38f3050258345e9cf363d1c8cc302f08c65b96ba1a4669d81e07ed69708344df", "price_changes":[{"asset_id":"81916206347121459497221114766050949090435061493822476265356047392175668050706", "price":"0.01", "size":"3740.43", "side":"BUY", "hash":"b07c55f75048f75d607531b3265eee89589f4752", "best_bid":"0.01", "best_ask":"0.02"}, {"asset_id":"96888240988495161476033313796107536512663280794332045579302109906525918376981", "price":"0.99", "size":"3740.43", "side":"SELL", "hash":"c32233bca5086d51d67714c9c1cd68ea37c35248", "best_bid":"0.98", "best_ask":"0.99"}], "timestamp":"1770241483551", "event_type":"price_change"}
{"market":"0x38f3050258345e9cf363d1c8cc302f08c65b96ba1a4669d81e07ed69708344df", "price_changes":[{"asset_id":"81916206347121459497221114766050949090435061493822476265356047392175668050706", "price":"0.01", "size":"3767.43", "side":"BUY", "hash":"34abe1e6754cbe37583a850cbb4ff19ec1fec9fa", "best_bid":"0.01", "best_ask":"0.02"}, {"asset_id":"96888240988495161476033313796107536512663280794332045579302109906525918376981", "price":"0.99", "size":"3767.43", "side":"SELL", "hash":"68deb04d400cb6de3dd2cc14be1170c05179c21a", "best_bid":"0.98", "best_ask":"0.99"}], "timestamp":"1770241483555", "event_type":"price_change"}
{"market":"0x38f3050258345e9cf363d1c8cc302f08c65b96ba1a4669d81e07ed69708344df", "price_changes":[{"asset_id":"96888240988495161476033313796107536512663280794332045579302109906525918376981", "price":"0.96", "size":"657.73", "side":"BUY", "hash":"60c39b1eb8855a1f36312ff285f0aa8f952a8797", "best_bid":"0.98", "best_ask":"0.99"}, {"asset_id":"81916206347121459497221114766050949090435061493822476265356047392175668050706", "price":"0.04", "size":"657.73", "side":"SELL", "hash":"d491af9767bc3fdf151590dcdada4754a3b550c5", "best_bid":"0.01", "best_ask":"0.02"}], "timestamp":"1770241483557", "event_type":"price_change"}
{"market":"0x38f3050258345e9cf363d1c8cc302f08c65b96ba1a4669d81e07ed69708344df", "price_changes":[{"asset_id":"81916206347121459497221114766050949090435061493822476265356047392175668050706", "price":"0.01", "size":"3740.43", "side":"BUY", "hash":"470604d7814a38ea65f07f7419817a2648c63dfd", "best_bid":"0.01", "best_ask":"0.02"}, {"asset_id":"96888240988495161476033313796107536512663280794332045579302109906525918376981", "price":"0.99", "size":"3740.43", "side":"SELL", "hash":"a71bfee273c932f22665fd7ad7ab2537bc3d2ab3", "best_bid":"0.98", "best_ask":"0.99"}], "timestamp":"1770241483559", "event_type":"price_change"}
{"market":"0x38f3050258345e9cf363d1c8cc302f08c65b96ba1a4669d81e07ed69708344df", "price_changes":[{"asset_id":"81916206347121459497221114766050949090435061493822476265356047392175668050706", "price":"0.01", "size":"3767.43", "side":"BUY", "hash":"18c0d24438468cfb6ce29af02f11c7c7d21d39e6", "best_bid":"0.01", "best_ask":"0.02"}, {"asset_id":"96888240988495161476033313796107536512663280794332045579302109906525918376981", "price":"0.99", "size":"3767.43", "side":"SELL", "hash":"f8bdcc14035e98faf27694b72a10c10dac8b10d5", "best_bid":"0.98", "best_ask":"0.99"}], "timestamp":"1770241483561", "event_type":"price_change"}
{"market":"0x38f3050258345e9cf363d1c8cc302f08c65b96ba1a4669d81e07ed69708344df", "price_changes":[{"asset_id":"96888240988495161476033313796107536512663280794332045579302109906525918376981", "price":"0.95", "size":"631", "side":"BUY", "hash":"23e971cf269727c7e186e08f3c94c4d20e508928", "best_bid":"0.98", "best_ask":"0.99"}, {"asset_id":"81916206347121459497221114766050949090435061493822476265356047392175668050706", "price":"0.05", "size":"631", "side":"SELL", "hash":"45e5578ddc826a924be6128b6a123f120a2c290c", "best_bid":"0.01", "best_ask":"0.02"}], "timestamp":"1770241483562", "event_type":"price_change"}
{"market":"0x38f3050258345e9cf363d1c8cc302f08c65b96ba1a4669d81e07ed69708344df", "price_changes":[{"asset_id":"96888240988495161476033313796107536512663280794332045579302109906525918376981", "price":"0.96", "size":"684.73", "side":"BUY", "hash":"d29c7976f7e00a884a4d2a95d0819076e82df66b", "best_bid":"0.98", "best_ask":"0.99"}, {"asset_id":"81916206347121459497221114766050949090435061493822476265356047392175668050706", "price":"0.04", "size":"684.73", "side":"SELL", "hash":"a654d9c23ffefe8225371ffdb2f29989e4b1a6d1", "best_bid":"0.01", "best_ask":"0.02"}], "timestamp":"1770241483563", "event_type":"price_change"}
{"market":"0x38f3050258345e9cf363d1c8cc302f08c65b96ba1a4669d81e07ed69708344df", "price_changes":[{"asset_id":"81916206347121459497221114766050949090435061493822476265356047392175668050706", "price":"0.01", "size":"3740.43", "side":"BUY", "hash":"ff6117fc0418cbdcbbc7bde87a43c45859cc7cc1", "best_bid":"0.01", "best_ask":"0.02"}, {"asset_id":"96888240988495161476033313796107536512663280794332045579302109906525918376981", "price":"0.99", "size":"3740.43", "side":"SELL", "hash":"6b17f7f2a14c538586594f8a4ddcfb580f059f61", "best_bid":"0.98", "best_ask":"0.99"}], "timestamp":"1770241483569", "event_type":"price_change"}
{"market":"0x38f3050258345e9cf363d1c8cc302f08c65b96ba1a4669d81e07ed69708344df", "price_changes":[{"asset_id":"96888240988495161476033313796107536512663280794332045579302109906525918376981", "price":"0.96", "size":"657.73", "side":"BUY", "hash":"cffbf60973a0051de97f5bf6a2546be14c50ab0b", "best_bid":"0.98", "best_ask":"0.99"}, {"asset_id":"81916206347121459497221114766050949090435061493822476265356047392175668050706", "price":"0.04", "size":"657.73", "side":"SELL", "hash":"b4dbd1fdab64d39cf002d354ab761ff406121103", "best_bid":"0.01", "best_ask":"0.02"}], "timestamp":"1770241483569", "event_type":"price_change"}
{"market":"0x38f3050258345e9cf363d1c8cc302f08c65b96ba1a4669d81e07ed69708344df", "price_changes":[{"asset_id":"81916206347121459497221114766050949090435061493822476265356047392175668050706", "price":"0.01", "size":"3767.43", "side":"BUY", "hash":"25eb51d3899d01f35441f4381e4ca5944dc4da67", "best_bid":"0.01", "best_ask":"0.02"}, {"asset_id":"96888240988495161476033313796107536512663280794332045579302109906525918376981", "price":"0.99", "size":"3767.43", "side":"SELL", "hash":"cf7ff95c197b0cbfdb59ad62d4b9421373211b01", "best_bid":"0.98", "best_ask":"0.99"}], "timestamp":"1770241483570", "event_type":"price_change"}
{"market":"0x38f3050258345e9cf363d1c8cc302f08c65b96ba1a4669d81e07ed69708344df", "price_changes":[{"asset_id":"96888240988495161476033313796107536512663280794332045579302109906525918376981", "price":"0.97", "size":"672.32", "side":"BUY", "hash":"8a225b46c99ad3d41fd95e50a7f9f4df59ad19d8", "best_bid":"0.98", "best_ask":"0.99"}, {"asset_id":"81916206347121459497221114766050949090435061493822476265356047392175668050706", "price":"0.03", "size":"672.32", "side":"SELL", "hash":"3330c5ffe094324622c77393b3aff1980ffc2a9b", "best_bid":"0.01", "best_ask":"0.02"}], "timestamp":"1770241483570", "event_type":"price_change"}
{"market":"0x38f3050258345e9cf363d1c8cc302f08c65b96ba1a4669d81e07ed69708344df", "price_changes":[{"asset_id":"96888240988495161476033313796107536512663280794332045579302109906525918376981", "price":"0.98", "size":"603.97", "side":"BUY", "hash":"4e3db9a44c5a9b5c5f2ebd10d2be2ca8d33beb89", "best_bid":"0.98", "best_ask":"0.99"}, {"asset_id":"81916206347121459497221114766050949090435061493822476265356047392175668050706", "price":"0.02", "size":"603.97", "side":"SELL", "hash":"c5f41a6777f3fced8c5796adf703eb1f957f711a", "best_bid":"0.01", "best_ask":"0.02"}], "timestamp":"1770241483646", "event_type":"price_change"}
{"market":"0x38f3050258345e9cf363d1c8cc302f08c65b96ba1a4669d81e07ed69708344df", "price_changes":[{"asset_id":"96888240988495161476033313796107536512663280794332045579302109906525918376981", "price":"0.78", "size":"1223.14", "side":"BUY", "hash":"f2a96753229c7faa210540e1fe41298a38b5ee3a", "best_bid":"0.98", "best_ask":"0.99"}, {"asset_id":"81916206347121459497221114766050949090435061493822476265356047392175668050706", "price":"0.22", "size":"1223.14", "side":"SELL", "hash":"8be69d87bc29dcea4db25dd9ab6e8e531c640f4d", "best_bid":"0.01", "best_ask":"0.02"}], "timestamp":"1770241483764", "event_type":"price_change"}
{"market":"0x38f3050258345e9cf363d1c8cc302f08c65b96ba1a4669d81e07ed69708344df", "price_changes":[{"asset_id":"81916206347121459497221114766050949090435061493822476265356047392175668050706", "price":"0.01", "size":"3740.43", "side":"BUY", "hash":"704eb3974214b9d114b3e84bfa986f2ac34bca42", "best_bid":"0.01", "best_ask":"0.02"}, {"asset_id":"96888240988495161476033313796107536512663280794332045579302109906525918376981", "price":"0.99", "size":"3740.43", "side":"SELL", "hash":"0051c63b359bffbe745c01c6108cc7f8f34fdcb5", "best_bid":"0.98", "best_ask":"0.99"}], "timestamp":"1770241483832", "event_type":"price_change"}
{"market":"0x38f3050258345e9cf363d1c8cc302f08c65b96ba1a4669d81e07ed69708344df", "price_changes":[{"asset_id":"96888240988495161476033313796107536512663280794332045579302109906525918376981", "price":"0.96", "size":"630.73", "side":"BUY", "hash":"498aaa644bc3f2d26b34fe17cbcb85c7b0b80bf3", "best_bid":"0.98", "best_ask":"0.99"}, {"asset_id":"81916206347121459497221114766050949090435061493822476265356047392175668050706", "price":"0.04", "size":"630.73", "side":"SELL", "hash":"3a33a326de0752a710d16ca36b280c3605f87167", "best_bid":"0.01", "best_ask":"0.02"}], "timestamp":"1770241483833", "event_type":"price_change"}
{"market":"0x38f3050258345e9cf363d1c8cc302f08c65b96ba1a4669d81e07ed69708344df", "price_changes":[{"asset_id":"81916206347121459497221114766050949090435061493822476265356047392175668050706", "price":"0.01", "size":"3767.43", "side":"BUY", "hash":"c84344ec7b9629fcb7e2d53291718816ec1ed543", "best_bid":"0.01", "best_ask":"0.02"}, {"asset_id":"96888240988495161476033313796107536512663280794332045579302109906525918376981", "price":"0.99", "size":"3767.43", "side":"SELL", "hash":"896e54f4fe265a16601ffaaf07b9f4442285142a", "best_bid":"0.98", "best_ask":"0.99"}], "timestamp":"1770241483834", "event_type":"price_change"}
{"market":"0x38f3050258345e9cf363d1c8cc302f08c65b96ba1a4669d81e07ed69708344df", "price_changes":[{"asset_id":"96888240988495161476033313796107536512663280794332045579302109906525918376981", "price":"0.95", "size":"658", "side":"BUY", "hash":"0ee1c07a156822c2215635010fc097eaf0b340ad", "best_bid":"0.98", "best_ask":"0.99"}, {"asset_id":"81916206347121459497221114766050949090435061493822476265356047392175668050706", "price":"0.05", "size":"658", "side":"SELL", "hash":"e6349b4d600c3b96df58b88691226816139cb9b1", "best_bid":"0.01", "best_ask":"0.02"}], "timestamp":"1770241483834", "event_type":"price_change"}
{"market":"0x38f3050258345e9cf363d1c8cc302f08c65b96ba1a4669d81e07ed69708344df", "price_changes":[{"asset_id":"81916206347121459497221114766050949090435061493822476265356047392175668050706", "price":"0.01", "size":"3740.43", "side":"BUY", "hash":"d5e77c01474dc2208b1ae10d289da7d3916fe5e0", "best_bid":"0.01", "best_ask":"0.02"}, {"asset_id":"96888240988495161476033313796107536512663280794332045579302109906525918376981", "price":"0.99", "size":"3740.43", "side":"SELL", "hash":"ed0af0b480f86f6a870c370e01998067296aa659", "best_bid":"0.98", "best_ask":"0.99"}], "timestamp":"1770241483842", "event_type":"price_change"}
{"market":"0x38f3050258345e9cf363d1c8cc302f08c65b96ba1a4669d81e07ed69708344df", "price_changes":[{"asset_id":"96888240988495161476033313796107536512663280794332045579302109906525918376981", "price":"0.95", "size":"685", "side":"BUY", "hash":"3a47f95e3fa6f7e264e36c5fa23c29ee104597f0", "best_bid":"0.98", "best_ask":"0.99"}, {"asset_id":"81916206347121459497221114766050949090435061493822476265356047392175668050706", "price":"0.05", "size":"685", "side":"SELL", "hash":"b9283b34afcf377af9570810a9bcc21e4f019ab4", "best_bid":"0.01", "best_ask":"0.02"}], "timestamp":"1770241483844", "event_type":"price_change"}
{"market":"0x38f3050258345e9cf363d1c8cc302f08c65b96ba1a4669d81e07ed69708344df", "price_changes":[{"asset_id":"96888240988495161476033313796107536512663280794332045579302109906525918376981", "price":"0.96", "size":"603.73", "side":"BUY", "hash":"c7972ca1b63deaada3ba03a306a27784252d5907", "best_bid":"0.98", "best_ask":"0.99"}, {"asset_id":"81916206347121459497221114766050949090435061493822476265356047392175668050706", "price":"0.04", "size":"603.73", "side":"SELL", "hash":"0c17b17f8d9cf3e3982ecfba435193bcdc85b1e1", "best_bid":"0.01", "best_ask":"0.02"}], "timestamp":"1770241483845", "event_type":"price_change"}
{"market":"0x38f3050258345e9cf363d1c8cc302f08c65b96ba1a4669d81e07ed69708344df", "price_changes":[{"asset_id":"81916206347121459497221114766050949090435061493822476265356047392175668050706", "price":"0.01", "size":"3767.43", "side":"BUY", "hash":"bf91d9087fd7945f53d267ce4ff9f6547431f10c", "best_bid":"0.01", "best_ask":"0.02"}, {"asset_id":"96888240988495161476033313796107536512663280794332045579302109906525918376981", "price":"0.99", "size":"3767.43", "side":"SELL", "hash":"ab3b43d40c61f483a29ffb09b730d3c9a8e43eae", "best_bid":"0.98", "best_ask":"0.99"}], "timestamp":"1770241483848", "event_type":"price_change"}
{"market":"0x38f3050258345e9cf363d1c8cc302f08c65b96ba1a4669d81e07ed69708344df", "price_changes":[{"asset_id":"81916206347121459497221114766050949090435061493822476265356047392175668050706", "price":"0.01", "size":"3794.43", "side":"BUY", "hash":"0b9cf23490dda86a9e141e2fb01ca83d1a215d79", "best_bid":"0.01", "best_ask":"0.02"}, {"asset_id":"96888240988495161476033313796107536512663280794332045579302109906525918376981", "price":"0.99", "size":"3794.43", "side":"SELL", "hash":"c1e8801dec0a1fadbcd93833c83a08c3e37aa3e5", "best_bid":"0.98", "best_ask":"0.99"}], "timestamp":"1770241483853", "event_type":"price_change"}
{"market":"0x38f3050258345e9cf363d1c8cc302f08c65b96ba1a4669d81e07ed69708344df", "price_changes":[{"asset_id":"96888240988495161476033313796107536512663280794332045579302109906525918376981", "price":"0.96", "size":"630.73", "side":"BUY", "hash":"a87fdc5f048bc3107484f569543bbf850cd6e9c8", "best_bid":"0.98", "best_ask":"0.99"}, {"asset_id":"81916206347121459497221114766050949090435061493822476265356047392175668050706", "price":"0.04", "size":"630.73", "side":"SELL", "hash":"ec73dfa3c90eb6fc4a119d3474f60b061f9f8544", "best_bid":"0.01", "best_ask":"0.02"}], "timestamp":"1770241483853", "event_type":"price_change"}
{"market":"0x38f3050258345e9cf363d1c8cc302f08c65b96ba1a4669d81e07ed69708344df", "price_changes":[{"asset_id":"96888240988495161476033313796107536512663280794332045579302109906525918376981", "price":"0.97", "size":"645.32", "side":"BUY", "hash":"8afec4771812d0e56c45225f367efd776d8c37e4", "best_bid":"0.98", "best_ask":"0.99"}, {"asset_id":"81916206347121459497221114766050949090435061493822476265356047392175668050706", "price":"0.03", "size":"645.32", "side":"SELL", "hash":"62add641996146d7e1174c121ada8d3c6715414c", "best_bid":"0.01", "best_ask":"0.02"}], "timestamp":"1770241483854", "event_type":"price_change"}
{"market":"0x38f3050258345e9cf363d1c8cc302f08c65b96ba1a4669d81e07ed69708344df", "price_changes":[{"asset_id":"81916206347121459497221114766050949090435061493822476265356047392175668050706", "price":"0.01", "size":"3767.43", "side":"BUY", "hash":"d6a87e9543ee4d2f733d51e88f59d07a1d6782f3", "best_bid":"0.01", "best_ask":"0.02"}, {"asset_id":"96888240988495161476033313796107536512663280794332045579302109906525918376981", "price":"0.99", "size":"3767.43", "side":"SELL", "hash":"e7f1cfed647a033a31163e53dcc9d2ce6a84b8ba", "best_bid":"0.98", "best_ask":"0.99"}], "timestamp":"1770241483854", "event_type":"price_change"}
{"market":"0x38f3050258345e9cf363d1c8cc302f08c65b96ba1a4669d81e07ed69708344df", "price_changes":[{"asset_id":"96888240988495161476033313796107536512663280794332045579302109906525918376981", "price":"0.97", "size":"622.32", "side":"BUY", "hash":"2b7cac473e0b3994e988a11b94a0430498e04cac", "best_bid":"0.98", "best_ask":"0.99"}, {"asset_id":"81916206347121459497221114766050949090435061493822476265356047392175668050706", "price":"0.03", "size":"622.32", "side":"SELL", "hash":"ffa03262ee5a18b3344f240302552ba281cff245", "best_bid":"0.01", "best_ask":"0.02"}], "timestamp":"1770241484109", "event_type":"price_change"}
{"market":"0x38f3050258345e9cf363d1c8cc302f08c65b96ba1a4669d81e07ed69708344df", "price_changes":[{"asset_id":"96888240988495161476033313796107536512663280794332045579302109906525918376981", "price":"0.96", "size":"653.73", "side":"BUY", "hash":"accd5e654a0b68a890019f5ce57a491e7017a674", "best_bid":"0.98", "best_ask":"0.99"}, {"asset_id":"81916206347121459497221114766050949090435061493822476265356047392175668050706", "price":"0.04", "size":"653.73", "side":"SELL", "hash":"7f30850a9b2dec2ec9e0874f6767a357117bcea3", "best_bid":"0.01", "best_ask":"0.02"}], "timestamp":"1770241484117", "event_type":"price_change"}
{"market":"0x38f3050258345e9cf363d1c8cc302f08c65b96ba1a4669d81e07ed69708344df", "price_changes":[{"asset_id":"81916206347121459497221114766050949090435061493822476265356047392175668050706", "price":"0.01", "size":"3794.43", "side":"BUY", "hash":"d99cc6ec644e9ba476da57d72b27b72630494935", "best_bid":"0.01", "best_ask":"0.02"}, {"asset_id":"96888240988495161476033313796107536512663280794332045579302109906525918376981", "price":"0.99", "size":"3794.43", "side":"SELL", "hash":"42e99644b7c3f0a29bedca705d234771bb1b3928", "best_bid":"0.98", "best_ask":"0.99"}], "timestamp":"1770241484121", "event_type":"price_change"}
{"market":"0x38f3050258345e9cf363d1c8cc302f08c65b96ba1a4669d81e07ed69708344df", "price_changes":[{"asset_id":"96888240988495161476033313796107536512663280794332045579302109906525918376981", "price":"0.94", "size":"958", "side":"BUY", "hash":"dde1cecea40e387f371262501a516eaf967dfac5", "best_bid":"0.98", "best_ask":"0.99"}, {"asset_id":"81916206347121459497221114766050949090435061493822476265356047392175668050706", "price":"0.06", "size":"958", "side":"SELL", "hash":"d233dbb6ded9094d4da0fb6300ad37ab891453ae", "best_bid":"0.01", "best_ask":"0.02"}], "timestamp":"1770241484122", "event_type":"price_change"}
{"market":"0x38f3050258345e9cf363d1c8cc302f08c65b96ba1a4669d81e07ed69708344df", "price_changes":[{"asset_id":"81916206347121459497221114766050949090435061493822476265356047392175668050706", "price":"0.01", "size":"3767.43", "side":"BUY", "hash":"1272120a377f72414e2fe64036970b3102efd4b7", "best_bid":"0.01", "best_ask":"0.02"}, {"asset_id":"96888240988495161476033313796107536512663280794332045579302109906525918376981", "price":"0.99", "size":"3767.43", "side":"SELL", "hash":"6f0e115f297cb83627cff6019c8014495aa701bc", "best_bid":"0.98", "best_ask":"0.99"}], "timestamp":"1770241484123", "event_type":"price_change"}
{"market":"0x38f3050258345e9cf363d1c8cc302f08c65b96ba1a4669d81e07ed69708344df", "price_changes":[{"asset_id":"96888240988495161476033313796107536512663280794332045579302109906525918376981", "price":"0.95", "size":"658", "side":"BUY", "hash":"8453268b3da043a8a2aad87e1dcaf4a1a5a5b421", "best_bid":"0.98", "best_ask":"0.99"}, {"asset_id":"81916206347121459497221114766050949090435061493822476265356047392175668050706", "price":"0.05", "size":"658", "side":"SELL", "hash":"141b2581c199ae25e7d0f07df52a30073ae3a17b", "best_bid":"0.01", "best_ask":"0.02"}], "timestamp":"1770241484126", "event_type":"price_change"}
{"market":"0x38f3050258345e9cf363d1c8cc302f08c65b96ba1a4669d81e07ed69708344df", "price_changes":[{"asset_id":"96888240988495161476033313796107536512663280794332045579302109906525918376981", "price":"0.94", "size":"985", "side":"BUY", "hash":"340d9fa65b0a652ce488901c440c5ebf1a82ae1d", "best_bid":"0.98", "best_ask":"0.99"}, {"asset_id":"81916206347121459497221114766050949090435061493822476265356047392175668050706", "price":"0.06", "size":"985", "side":"SELL", "hash":"380221f8687bc1810f6957945afd853611ccad2c", "best_bid":"0.01", "best_ask":"0.02"}], "timestamp":"1770241484135", "event_type":"price_change"}
{"market":"0x38f3050258345e9cf363d1c8cc302f08c65b96ba1a4669d81e07ed69708344df", "price_changes":[{"asset_id":"81916206347121459497221114766050949090435061493822476265356047392175668050706", "price":"0.01", "size":"3740.43", "side":"BUY", "hash":"ebf6dd89bd331fa0069351195630a6a56b97413a", "best_bid":"0.01", "best_ask":"0.02"}, {"asset_id":"96888240988495161476033313796107536512663280794332045579302109906525918376981", "price":"0.99", "size":"3740.43", "side":"SELL", "hash":"90c85b8e45dd6d126dc15a6b8467485da3a6cf59", "best_bid":"0.98", "best_ask":"0.99"}], "timestamp":"1770241484138", "event_type":"price_change"}
{"market":"0x38f3050258345e9cf363d1c8cc302f08c65b96ba1a4669d81e07ed69708344df", "price_changes":[{"asset_id":"96888240988495161476033313796107536512663280794332045579302109906525918376981", "price":"0.95", "size":"631", "side":"BUY", "hash":"b285f97c6293e59dccfe9a29ffac2ff6e8a5729a", "best_bid":"0.98", "best_ask":"0.99"}, {"asset_id":"81916206347121459497221114766050949090435061493822476265356047392175668050706", "price":"0.05", "size":"631", "side":"SELL", "hash":"61320872fa56cb4070be5a153cba3b870a2048a2", "best_bid":"0.01", "best_ask":"0.02"}], "timestamp":"1770241484139", "event_type":"price_change"}
{"market":"0x38f3050258345e9cf363d1c8cc302f08c65b96ba1a4669d81e07ed69708344df", "price_changes":[{"asset_id":"81916206347121459497221114766050949090435061493822476265356047392175668050706", "price":"0.01", "size":"3767.43", "side":"BUY", "hash":"82febc6fef205ca6bc955830349f546f8d98246b", "best_bid":"0.01", "best_ask":"0.02"}, {"asset_id":"96888240988495161476033313796107536512663280794332045579302109906525918376981", "price":"0.99", "size":"3767.43", "side":"SELL", "hash":"827be1bbdbcae701b89e6ce1c600958f5d5ea108", "best_bid":"0.98", "best_ask":"0.99"}], "timestamp":"1770241484140", "event_type":"price_change"}
{"market":"0x38f3050258345e9cf363d1c8cc302f08c65b96ba1a4669d81e07ed69708344df", "price_changes":[{"asset_id":"96888240988495161476033313796107536512663280794332045579302109906525918376981", "price":"0.95", "size":"658", "side":"BUY", "hash":"1aba6bf854d1580c337925bb04f77e42b12827bc", "best_bid":"0.98", "best_ask":"0.99"}, {"asset_id":"81916206347121459497221114766050949090435061493822476265356047392175668050706", "price":"0.05", "size":"658", "side":"SELL", "hash":"ad6fe810b46bcee943b427d1fb73fb78c4059e3f", "best_bid":"0.01", "best_ask":"0.02"}], "timestamp":"1770241484186", "event_type":"price_change"}
{"market":"0x38f3050258345e9cf363d1c8cc302f08c65b96ba1a4669d81e07ed69708344df", "price_changes":[{"asset_id":"96888240988495161476033313796107536512663280794332045579302109906525918376981", "price":"0.96", "size":"626.73", "side":"BUY", "hash":"7ce241f45a44f250b7ae83d2acec15d53809ccc3", "best_bid":"0.98", "best_ask":"0.99"}, {"asset_id":"81916206347121459497221114766050949090435061493822476265356047392175668050706", "price":"0.04", "size":"626.73", "side":"SELL", "hash":"11b0d719c8a2195446cb4b9632ffb04c54834613", "best_bid":"0.01", "best_ask":"0.02"}], "timestamp":"1770241484186", "event_type":"price_change"}
{"market":"0x38f3050258345e9cf363d1c8cc302f08c65b96ba1a4669d81e07ed69708344df", "price_changes":[{"asset_id":"81916206347121459497221114766050949090435061493822476265356047392175668050706", "price":"0.01", "size":"3794.43", "side":"BUY", "hash":"66a2a885c2a457b0dca34a3996895567bdcef0a3", "best_bid":"0.01", "best_ask":"0.02"}, {"asset_id":"96888240988495161476033313796107536512663280794332045579302109906525918376981", "price":"0.99", "size":"3794.43", "side":"SELL", "hash":"ec8c48b480dba3186c95e7d6ef853bd05873b0ef", "best_bid":"0.98", "best_ask":"0.99"}], "timestamp":"1770241484187", "event_type":"price_change"}
{"market":"0x38f3050258345e9cf363d1c8cc302f08c65b96ba1a4669d81e07ed69708344df", "price_changes":[{"asset_id":"81916206347121459497221114766050949090435061493822476265356047392175668050706", "price":"0.01", "size":"3767.43", "side":"BUY", "hash":"1035fa4a8fc90df4cc9d07d1552c5858c3b15267", "best_bid":"0.01", "best_ask":"0.02"}, {"asset_id":"96888240988495161476033313796107536512663280794332045579302109906525918376981", "price":"0.99", "size":"3767.43", "side":"SELL", "hash":"b5de0a4ee10f87a76dfafee7306482d023c4d780", "best_bid":"0.98", "best_ask":"0.99"}], "timestamp":"1770241484187", "event_type":"price_change"}
{"market":"0x38f3050258345e9cf363d1c8cc302f08c65b96ba1a4669d81e07ed69708344df", "price_changes":[{"asset_id":"96888240988495161476033313796107536512663280794332045579302109906525918376981", "price":"0.94", "size":"958", "side":"BUY", "hash":"fd6a2eb6e0829cd8dfe345f6843ddd2b8a1ff84e", "best_bid":"0.98", "best_ask":"0.99"}, {"asset_id":"81916206347121459497221114766050949090435061493822476265356047392175668050706", "price":"0.06", "size":"958", "side":"SELL", "hash":"ff950660ab27f517d9e0f6d8882bd84c721450ab", "best_bid":"0.01", "best_ask":"0.02"}], "timestamp":"1770241484523", "event_type":"price_change"}
{"market":"0x38f3050258345e9cf363d1c8cc302f08c65b96ba1a4669d81e07ed69708344df", "price_changes":[{"asset_id":"81916206347121459497221114766050949090435061493822476265356047392175668050706", "price":"0.01", "size":"3794.43", "side":"BUY", "hash":"aed931f530a6f0eb73710384cb041369678df2f7", "best_bid":"0.01", "best_ask":"0.02"}, {"asset_id":"96888240988495161476033313796107536512663280794332045579302109906525918376981", "price":"0.99", "size":"3794.43", "side":"SELL", "hash":"d29629f7c5a13549e25093ecad4025a8c1442315", "best_bid":"0.98", "best_ask":"0.99"}], "timestamp":"1770241484524", "event_type":"price_change"}
{"market":"0x38f3050258345e9cf363d1c8cc302f08c65b96ba1a4669d81e07ed69708344df", "price_changes":[{"asset_id":"81916206347121459497221114766050949090435061493822476265356047392175668050706", "price":"0.01", "size":"3767.43", "side":"BUY", "hash":"d442b931dea77faebe5ef91ef29f45f0e4046559", "best_bid":"0.01", "best_ask":"0.02"}, {"asset_id":"96888240988495161476033313796107536512663280794332045579302109906525918376981", "price":"0.99", "size":"3767.43", "side":"SELL", "hash":"55d22e0bdd386d836496159dc5fb80096eff7e23", "best_bid":"0.98", "best_ask":"0.99"}], "timestamp":"1770241484525", "event_type":"price_change"}
{"market":"0x38f3050258345e9cf363d1c8cc302f08c65b96ba1a4669d81e07ed69708344df", "price_changes":[{"asset_id":"96888240988495161476033313796107536512663280794332045579302109906525918376981", "price":"0.95", "size":"685", "side":"BUY", "hash":"da5d508328dd6901587a6a106995b508ea9d5718", "best_bid":"0.98", "best_ask":"0.99"}, {"asset_id":"81916206347121459497221114766050949090435061493822476265356047392175668050706", "price":"0.05", "size":"685", "side":"SELL", "hash":"55ca89242a7f07dd76bc588aa507ce4e74e4383c", "best_bid":"0.01", "best_ask":"0.02"}], "timestamp":"1770241484526", "event_type":"price_change"}
{"market":"0x38f3050258345e9cf363d1c8cc302f08c65b96ba1a4669d81e07ed69708344df", "price_changes":[{"asset_id":"96888240988495161476033313796107536512663280794332045579302109906525918376981", "price":"0.94", "size":"931", "side":"BUY", "hash":"b59ff2ed352c74e30292b5cef725f1a784c811dc", "best_bid":"0.98", "best_ask":"0.99"}, {"asset_id":"81916206347121459497221114766050949090435061493822476265356047392175668050706", "price":"0.06", "size":"931", "side":"SELL", "hash":"0c69e09ac6181478fc895b883e8bff109aa85911", "best_bid":"0.01", "best_ask":"0.02"}], "timestamp":"1770241484534", "event_type":"price_change"}
{"market":"0x38f3050258345e9cf363d1c8cc302f08c65b96ba1a4669d81e07ed69708344df", "price_changes":[{"asset_id":"81916206347121459497221114766050949090435061493822476265356047392175668050706", "price":"0.01", "size":"3794.43", "side":"BUY", "hash":"01ecea88981070f7ad30d78126c826d44e88bdcc", "best_bid":"0.01", "best_ask":"0.02"}, {"asset_id":"96888240988495161476033313796107536512663280794332045579302109906525918376981", "price":"0.99", "size":"3794.43", "side":"SELL", "hash":"b7d12949f599b213ae747e3c8361682ad658825b", "best_bid":"0.98", "best_ask":"0.99"}], "timestamp":"1770241484535", "event_type":"price_change"}
{"market":"0x38f3050258345e9cf363d1c8cc302f08c65b96ba1a4669d81e07ed69708344df", "price_changes":[{"asset_id":"96888240988495161476033313796107536512663280794332045579302109906525918376981", "price":"0.95", "size":"712", "side":"BUY", "hash":"3f5f7f615c6a84c6b36ec0b9b49a4922b2614437", "best_bid":"0.98", "best_ask":"0.99"}, {"asset_id":"81916206347121459497221114766050949090435061493822476265356047392175668050706", "price":"0.05", "size":"712", "side":"SELL", "hash":"523abebc82b56d2bdaffbbed060f20af1fde2bda", "best_bid":"0.01", "best_ask":"0.02"}], "timestamp":"1770241484537", "event_type":"price_change"}
{"market":"0x38f3050258345e9cf363d1c8cc302f08c65b96ba1a4669d81e07ed69708344df", "price_changes":[{"asset_id":"81916206347121459497221114766050949090435061493822476265356047392175668050706", "price":"0.01", "size":"3767.43", "side":"BUY", "hash":"8ebb1f448439e3c1538266101542961c16ad857f", "best_bid":"0.01", "best_ask":"0.02"}, {"asset_id":"96888240988495161476033313796107536512663280794332045579302109906525918376981", "price":"0.99", "size":"3767.43", "side":"SELL", "hash":"bdfa3b662d3e3d101fc74ab3fa430fa0bdb92d12", "best_bid":"0.98", "best_ask":"0.99"}], "timestamp":"1770241484540", "event_type":"price_change"}
{"market":"0x38f3050258345e9cf363d1c8cc302f08c65b96ba1a4669d81e07ed69708344df", "price_changes":[{"asset_id":"81916206347121459497221114766050949090435061493822476265356047392175668050706", "price":"0.01", "size":"3794.43", "side":"BUY", "hash":"7bfebae1f96b9cfa0b212e69639f0139a56df8be", "best_bid":"0.01", "best_ask":"0.02"}, {"asset_id":"96888240988495161476033313796107536512663280794332045579302109906525918376981", "price":"0.99", "size":"3794.43", "side":"SELL", "hash":"ece4fae1e55800a4ec12e44fe579e16c8a996377", "best_bid":"0.98", "best_ask":"0.99"}], "timestamp":"1770241484542", "event_type":"price_change"}
{"market":"0x38f3050258345e9cf363d1c8cc302f08c65b96ba1a4669d81e07ed69708344df", "price_changes":[{"asset_id":"81916206347121459497221114766050949090435061493822476265356047392175668050706", "price":"0.01", "size":"3767.43", "side":"BUY", "hash":"dad5e006a9f497534c96c763a822f1b5297ac5a6", "best_bid":"0.01", "best_ask":"0.02"}, {"asset_id":"96888240988495161476033313796107536512663280794332045579302109906525918376981", "price":"0.99", "size":"3767.43", "side":"SELL", "hash":"04e84e9c5a29923e758b9d15b0bcae00522233fa", "best_bid":"0.98", "best_ask":"0.99"}], "timestamp":"1770241484543", "event_type":"price_change"}
{"market":"0x38f3050258345e9cf363d1c8cc302f08c65b96ba1a4669d81e07ed69708344df", "price_changes":[{"asset_id":"96888240988495161476033313796107536512663280794332045579302109906525918376981", "price":"0.96", "size":"653.73", "side":"BUY", "hash":"7db097b8e4e2a8a31b838f949e1d3bf9c94e8c54", "best_bid":"0.98", "best_ask":"0.99"}, {"asset_id":"81916206347121459497221114766050949090435061493822476265356047392175668050706", "price":"0.04", "size":"653.73", "side":"SELL", "hash":"e03c4e2de6299f6dd5f8853829a43273b8300c1c", "best_bid":"0.01", "best_ask":"0.02"}], "timestamp":"1770241484544", "event_type":"price_change"}
{"market":"0x38f3050258345e9cf363d1c8cc302f08c65b96ba1a4669d81e07ed69708344df", "price_changes":[{"asset_id":"96888240988495161476033313796107536512663280794332045579302109906525918376981", "price":"0.95", "size":"685", "side":"BUY", "hash":"4f98446128227ee158b41625d9fda1aa8bdd60ae", "best_bid":"0.98", "best_ask":"0.99"}, {"asset_id":"81916206347121459497221114766050949090435061493822476265356047392175668050706", "price":"0.05", "size":"685", "side":"SELL", "hash":"7a9842924e2eacfd2708d14fe2859ebb3184b8a1", "best_bid":"0.01", "best_ask":"0.02"}], "timestamp":"1770241484551", "event_type":"price_change"}
{"market":"0x38f3050258345e9cf363d1c8cc302f08c65b96ba1a4669d81e07ed69708344df", "price_changes":[{"asset_id":"96888240988495161476033313796107536512663280794332045579302109906525918376981", "price":"0.96", "size":"630.73", "side":"BUY", "hash":"7900483a4e63e6b370ea9d4ce675b7332fff9c17", "best_bid":"0.98", "best_ask":"0.99"}, {"asset_id":"81916206347121459497221114766050949090435061493822476265356047392175668050706", "price":"0.04", "size":"630.73", "side":"SELL", "hash":"d72b5efb06fd29b095b320bc8f20dab15dd2c4bd", "best_bid":"0.01", "best_ask":"0.02"}], "timestamp":"1770241484636", "event_type":"price_change"}
{"market":"0x38f3050258345e9cf363d1c8cc302f08c65b96ba1a4669d81e07ed69708344df", "price_changes":[{"asset_id":"96888240988495161476033313796107536512663280794332045579302109906525918376981", "price":"0.97", "size":"645.32", "side":"BUY", "hash":"ab0d821af176739cea68777c54325c4ffae0b62d", "best_bid":"0.98", "best_ask":"0.99"}, {"asset_id":"81916206347121459497221114766050949090435061493822476265356047392175668050706", "price":"0.03", "size":"645.32", "side":"SELL", "hash":"0c1cdefb8c8de524bd36852d09543092dd0108a4", "best_bid":"0.01", "best_ask":"0.02"}], "timestamp":"1770241484638", "event_type":"price_change"}
{"market":"0x38f3050258345e9cf363d1c8cc302f08c65b96ba1a4669d81e07ed69708344df", "price_changes":[{"asset_id":"96888240988495161476033313796107536512663280794332045579302109906525918376981", "price":"0.99", "size":"3778.43", "side":"SELL", "hash":"7651ac55fffc44a0cdf12bce881f2bc1d42b7ee0", "best_bid":"0.98", "best_ask":"0.99"}, {"asset_id":"81916206347121459497221114766050949090435061493822476265356047392175668050706", "price":"0.01", "size":"3778.43", "side":"BUY", "hash":"0a71fbcc99a097653e0b9d652c75ee4712c59b06", "best_bid":"0.01", "best_ask":"0.02"}], "timestamp":"1770241484703", "event_type":"price_change"}
{"market":"0x38f3050258345e9cf363d1c8cc302f08c65b96ba1a4669d81e07ed69708344df", "price_changes":[{"asset_id":"81916206347121459497221114766050949090435061493822476265356047392175668050706", "price":"0.01", "size":"3578.43", "side":"BUY", "hash":"091b135576bf04ce58431e5f8e7d781e9e1a9695", "best_bid":"0.01", "best_ask":"0.02"}, {"asset_id":"96888240988495161476033313796107536512663280794332045579302109906525918376981", "price":"0.99", "size":"3578.43", "side":"SELL", "hash":"373de14c79cef64e1d16c5171b6eda271dfcfc87", "best_bid":"0.98", "best_ask":"0.99"}], "timestamp":"1770241484720", "event_type":"price_change"}
{"market":"0x38f3050258345e9cf363d1c8cc302f08c65b96ba1a4669d81e07ed69708344df", "asset_id":"81916206347121459497221114766050949090435061493822476265356047392175668050706", "bids":[{"price":"0.01", "size":"3578.43"}], "asks":[{"price":"0.99", "size":"5019.91"}, {"price":"0.98", "size":"3034.23"}, {"price":"0.97", "size":"3172"}, {"price":"0.96", "size":"3012"}, {"price":"0.95", "size":"3032"}, {"price":"0.94", "size":"3012"}, {"price":"0.93", "size":"3126.28"}, {"price":"0.92", "size":"3012"}, {"price":"0.91", "size":"3012"}, {"price":"0.9", "size":"3087"}, {"price":"0.89", "size":"12"}, {"price":"0.88", "size":"12"}, {"price":"0.87", "size":"12"}, {"price":"0.86", "size":"12"}, {"price":"0.85", "size":"12"}, {"price":"0.84", "size":"12"}, {"price":"0.83", "size":"12"}, {"price":"0.82", "size":"12"}, {"price":"0.81", "size":"12"}, {"price":"0.8", "size":"12"}, {"price":"0.79", "size":"12"}, {"price":"0.78", "size":"12"}, {"price":"0.77", "size":"12"}, {"price":"0.76", "size":"112"}, {"price":"0.75", "size":"40.57"}, {"price":"0.74", "size":"12"}, {"price":"0.73", "size":"293.25"}, {"price":"0.72", "size":"22"}, {"price":"0.71", "size":"12"}, {"price":"0.7", "size":"18"}, {"price":"0.69", "size":"12"}, {"price":"0.68", "size":"12"}, {"price":"0.67", "size":"12"}, {"price":"0.66", "size":"160.89"}, {"price":"0.65", "size":"12"}, {"price":"0.64", "size":"12"}, {"price":"0.63", "size":"12"}, {"price":"0.62", "size":"19.39"}, {"price":"0.61", "size":"18.04"}, {"price":"0.6", "size":"12"}, {"price":"0.59", "size":"94.31"}, {"price":"0.58", "size":"5450.54"}, {"price":"0.57", "size":"12"}, {"price":"0.56", "size":"12"}, {"price":"0.55", "size":"12"}, {"price":"0.54", "size":"22"}, {"price":"0.53", "size":"12"}, {"price":"0.52", "size":"12"}, {"price":"0.51", "size":"12"}, {"price":"0.5", "size":"12"}, {"price":"0.49", "size":"12"}, {"price":"0.48", "size":"12"}, {"price":"0.47", "size":"12"}, {"price":"0.46", "size":"485.56"}, {"price":"0.45", "size":"31"}, {"price":"0.44", "size":"17"}, {"price":"0.43", "size":"12"}, {"price":"0.42", "size":"12"}, {"price":"0.41", "size":"12"}, {"price":"0.4", "size":"127"}, {"price":"0.39", "size":"12"}, {"price":"0.38", "size":"94.51"}, {"price":"0.37", "size":"31.99"}, {"price":"0.36", "size":"12"}, {"price":"0.35", "size":"37"}, {"price":"0.34", "size":"12"}, {"price":"0.33", "size":"12"}, {"price":"0.32", "size":"12"}, {"price":"0.31", "size":"12"}, {"price":"0.3", "size":"31.9"}, {"price":"0.29", "size":"344"}, {"price":"0.28", "size":"3288.99"}, {"price":"0.27", "size":"212"}, {"price":"0.26", "size":"218"}, {"price":"0.25", "size":"212"}, {"price":"0.24", "size":"212"}, {"price":"0.23", "size":"212"}, {"price":"0.22", "size":"1223.14"}, {"price":"0.21", "size":"212"}, {"price":"0.2", "size":"472.99"}, {"price":"0.19", "size":"212"}, {"price":"0.18", "size":"212"}, {"price":"0.17", "size":"212"}, {"price":"0.16", "size":"812"}, {"price":"0.15", "size":"231.08"}, {"price":"0.14", "size":"283.65"}, {"price":"0.13", "size":"212"}, {"price":"0.12", "size":"252"}, {"price":"0.11", "size":"252"}, {"price":"0.1", "size":"737.71"}, {"price":"0.09", "size":"261"}, {"price":"0.08", "size":"844.68"}, {"price":"0.07", "size":"326"}, {"price":"0.06", "size":"931"}, {"price":"0.05", "size":"685"}, {"price":"0.04", "size":"630.73"}, {"price":"0.03", "size":"645.32"}, {"price":"0.02", "size":"603.97"}], "hash":"091b135576bf04ce58431e5f8e7d781e9e1a9695", "timestamp":"1770241484720", "event_type":"book"}
{"market":"0x38f3050258345e9cf363d1c8cc302f08c65b96ba1a4669d81e07ed69708344df", "price_changes":[{"asset_id":"81916206347121459497221114766050949090435061493822476265356047392175668050706", "price":"0.01", "size":"3551.43", "side":"BUY", "hash":"7749950826d60d481e61ba1269d9ed8ce6e1cd53", "best_bid":"0.01", "best_ask":"0.02"}, {"asset_id":"96888240988495161476033313796107536512663280794332045579302109906525918376981", "price":"0.99", "size":"3551.43", "side":"SELL", "hash":"096c9365e5ccac9e9c2d67513228eedff71dd55b", "best_bid":"0.98", "best_ask":"0.99"}], "timestamp":"1770241484730", "event_type":"price_change"}
{"market":"0x38f3050258345e9cf363d1c8cc302f08c65b96ba1a4669d81e07ed69708344df", "price_changes":[{"asset_id":"96888240988495161476033313796107536512663280794332045579302109906525918376981", "price":"0.95", "size":"658", "side":"BUY", "hash":"68de1dee40a2785d0bf5a1c80cc97d5e84836773", "best_bid":"0.98", "best_ask":"0.99"}, {"asset_id":"81916206347121459497221114766050949090435061493822476265356047392175668050706", "price":"0.05", "size":"658", "side":"SELL", "hash":"a2950446cd9024b0ba49a15665bc0466668c940a", "best_bid":"0.01", "best_ask":"0.02"}], "timestamp":"1770241484730", "event_type":"price_change"}
{"market":"0x38f3050258345e9cf363d1c8cc302f08c65b96ba1a4669d81e07ed69708344df", "price_changes":[{"asset_id":"81916206347121459497221114766050949090435061493822476265356047392175668050706", "price":"0.01", "size":"3578.43", "side":"BUY", "hash":"06ad7da48e8ef1a0b56a78f8a9883ab93d0b22ba", "best_bid":"0.01", "best_ask":"0.02"}, {"asset_id":"96888240988495161476033313796107536512663280794332045579302109906525918376981", "price":"0.99", "size":"3578.43", "side":"SELL", "hash":"0a6fcf26ddc1d714c6c319a7f0e99dbf392d8112", "best_bid":"0.98", "best_ask":"0.99"}], "timestamp":"1770241484731", "event_type":"price_change"}
{"market":"0x38f3050258345e9cf363d1c8cc302f08c65b96ba1a4669d81e07ed69708344df", "price_changes":[{"asset_id":"96888240988495161476033313796107536512663280794332045579302109906525918376981", "price":"0.95", "size":"685", "side":"BUY", "hash":"74a07441bcfbe9d1835ecc76f396ed592de27b12", "best_bid":"0.98", "best_ask":"0.99"}, {"asset_id":"81916206347121459497221114766050949090435061493822476265356047392175668050706", "price":"0.05", "size":"685", "side":"SELL", "hash":"85df3298283b44414b08aba5f31ded94320a6658", "best_bid":"0.01", "best_ask":"0.02"}], "timestamp":"1770241484732", "event_type":"price_change"}
{"market":"0x38f3050258345e9cf363d1c8cc302f08c65b96ba1a4669d81e07ed69708344df", "price_changes":[{"asset_id":"81916206347121459497221114766050949090435061493822476265356047392175668050706", "price":"0.01", "size":"3551.43", "side":"BUY", "hash":"bb3cfabfcb37581c82a1c9da30d0decea5e17870", "best_bid":"0.01", "best_ask":"0.02"}, {"asset_id":"96888240988495161476033313796107536512663280794332045579302109906525918376981", "price":"0.99", "size":"3551.43", "side":"SELL", "hash":"9b8fae860958474cb532958203ea7585b007ec98", "best_bid":"0.98", "best_ask":"0.99"}], "timestamp":"1770241484740", "event_type":"price_change"}
{"market":"0x38f3050258345e9cf363d1c8cc302f08c65b96ba1a4669d81e07ed69708344df", "price_changes":[{"asset_id":"96888240988495161476033313796107536512663280794332045579302109906525918376981", "price":"0.95", "size":"658", "side":"BUY", "hash":"6b3e78c89126ce020d3d63dd9074dfbe909a71bb", "best_bid":"0.98", "best_ask":"0.99"}, {"asset_id":"81916206347121459497221114766050949090435061493822476265356047392175668050706", "price":"0.05", "size":"658", "side":"SELL", "hash":"57b9e3d584176fd87a55cc3dffb9704dd25d3a1f", "best_bid":"0.01", "best_ask":"0.02"}], "timestamp":"1770241484742", "event_type":"price_change"}
{"market":"0x38f3050258345e9cf363d1c8cc302f08c65b96ba1a4669d81e07ed69708344df", "price_changes":[{"asset_id":"96888240988495161476033313796107536512663280794332045579302109906525918376981", "price":"0.95", "size":"685", "side":"BUY", "hash":"24003f956fcb37b4a8aa90ffd6d8bee0e0332d0c", "best_bid":"0.98", "best_ask":"0.99"}, {"asset_id":"81916206347121459497221114766050949090435061493822476265356047392175668050706", "price":"0.05", "size":"685", "side":"SELL", "hash":"13cf561bc32138fa3f5a7b60da0c6fb002402de1", "best_bid":"0.01", "best_ask":"0.02"}], "timestamp":"1770241484742", "event_type":"price_change"}
{"market":"0x38f3050258345e9cf363d1c8cc302f08c65b96ba1a4669d81e07ed69708344df", "price_changes":[{"asset_id":"81916206347121459497221114766050949090435061493822476265356047392175668050706", "price":"0.01", "size":"3578.43", "side":"BUY", "hash":"c5166b2ad726d99f02897704535e29f98116d3ec", "best_bid":"0.01", "best_ask":"0.02"}, {"asset_id":"96888240988495161476033313796107536512663280794332045579302109906525918376981", "price":"0.99", "size":"3578.43", "side":"SELL", "hash":"a7091fb87f9f50d74d0e21ad55215467189358c1", "best_bid":"0.98", "best_ask":"0.99"}], "timestamp":"1770241484746", "event_type":"price_change"}
{"market":"0x38f3050258345e9cf363d1c8cc302f08c65b96ba1a4669d81e07ed69708344df", "price_changes":[{"asset_id":"96888240988495161476033313796107536512663280794332045579302109906525918376981", "price":"0.96", "size":"603.73", "side":"BUY", "hash":"dc627711597936df94b609a63e39b630b7526375", "best_bid":"0.98", "best_ask":"0.99"}, {"asset_id":"81916206347121459497221114766050949090435061493822476265356047392175668050706", "price":"0.04", "size":"603.73", "side":"SELL", "hash":"04d19fa8edd7befa55f9e4c0ec0e0d0828c4b48c", "best_bid":"0.01", "best_ask":"0.02"}], "timestamp":"1770241484752", "event_type":"price_change"}
{"market":"0x38f3050258345e9cf363d1c8cc302f08c65b96ba1a4669d81e07ed69708344df", "price_changes":[{"asset_id":"96888240988495161476033313796107536512663280794332045579302109906525918376981", "price":"0.96", "size":"630.73", "side":"BUY", "hash":"f4363d8d3e8919322664f7802ccf3717d22eb28f", "best_bid":"0.98", "best_ask":"0.99"}, {"asset_id":"81916206347121459497221114766050949090435061493822476265356047392175668050706", "price":"0.04", "size":"630.73", "side":"SELL", "hash":"a66a208a54e56be3b647ab7f2594c2e2581c1b6d", "best_bid":"0.01", "best_ask":"0.02"}], "timestamp":"1770241484753", "event_type":"price_change"}
{"market":"0x38f3050258345e9cf363d1c8cc302f08c65b96ba1a4669d81e07ed69708344df", "asset_id":"81916206347121459497221114766050949090435061493822476265356047392175668050706", "price":"0.01", "size":"200", "fee_rate_bps":"0", "side":"SELL", "timestamp":"1770241484754", "event_type":"last_trade_price", "transaction_hash":"0xa45a8d2e0e3fbe28a61f09005a1c958c07dbbc62f6d0c3e3a95ad7f6bca15f0b"}
{"market":"0x38f3050258345e9cf363d1c8cc302f08c65b96ba1a4669d81e07ed69708344df", "price_changes":[{"asset_id":"81916206347121459497221114766050949090435061493822476265356047392175668050706", "price":"0.01", "size":"3605.43", "side":"BUY", "hash":"bbf1db079632b1d07eaba741bf7aea59248d63fe", "best_bid":"0.01", "best_ask":"0.02"}, {"asset_id":"96888240988495161476033313796107536512663280794332045579302109906525918376981", "price":"0.99", "size":"3605.43", "side":"SELL", "hash":"5f64757da1ad49f5409aa1e135a4db7f59133c7a", "best_bid":"0.98", "best_ask":"0.99"}], "timestamp":"1770241484755", "event_type":"price_change"}
{"market":"0x38f3050258345e9cf363d1c8cc302f08c65b96ba1a4669d81e07ed69708344df", "price_changes":[{"asset_id":"81916206347121459497221114766050949090435061493822476265356047392175668050706", "price":"0.01", "size":"3578.43", "side":"BUY", "hash":"7e3cffca80fe719dc710696ec5d6744dd767ec88", "best_bid":"0.01", "best_ask":"0.02"}, {"asset_id":"96888240988495161476033313796107536512663280794332045579302109906525918376981", "price":"0.99", "size":"3578.43", "side":"SELL", "hash":"7237457af11882241f037b2a4be96f52a97f6773", "best_bid":"0.98", "best_ask":"0.99"}], "timestamp":"1770241484756", "event_type":"price_change"}
{"market":"0x38f3050258345e9cf363d1c8cc302f08c65b96ba1a4669d81e07ed69708344df", "price_changes":[{"asset_id":"96888240988495161476033313796107536512663280794332045579302109906525918376981", "price":"0.79", "size":"712", "side":"BUY", "hash":"d7b5bf8b86a289042fafefcaf5f380a09039f606", "best_bid":"0.98", "best_ask":"0.99"}, {"asset_id":"81916206347121459497221114766050949090435061493822476265356047392175668050706", "price":"0.21", "size":"712", "side":"SELL", "hash":"2f61b45d97d82953fec8074cc6e8c16e3770eaae", "best_bid":"0.01", "best_ask":"0.02"}], "timestamp":"1770241484758", "event_type":"price_change"}
{"market":"0x38f3050258345e9cf363d1c8cc302f08c65b96ba1a4669d81e07ed69708344df", "price_changes":[{"asset_id":"96888240988495161476033313796107536512663280794332045579302109906525918376981", "price":"0.98", "size":"583.97", "side":"BUY", "hash":"6a86d462c9c7dbbbd7cd79558ffdda5204ed0732", "best_bid":"0.98", "best_ask":"0.99"}, {"asset_id":"81916206347121459497221114766050949090435061493822476265356047392175668050706", "price":"0.02", "size":"583.97", "side":"SELL", "hash":"04aa593567b0e299c2a4235fb52105255a782ffc", "best_bid":"0.01", "best_ask":"0.02"}], "timestamp":"1770241484839", "event_type":"price_change"}
{"market":"0x38f3050258345e9cf363d1c8cc302f08c65b96ba1a4669d81e07ed69708344df", "price_changes":[{"asset_id":"96888240988495161476033313796107536512663280794332045579302109906525918376981", "price":"0.99", "size":"3567.43", "side":"SELL", "hash":"84798c0822f0634b29f7e53b10c278e1db91eb99", "best_bid":"0.98", "best_ask":"0.99"}, {"asset_id":"81916206347121459497221114766050949090435061493822476265356047392175668050706", "price":"0.01", "size":"3567.43", "side":"BUY", "hash":"32cf3083369f98b8ff74bb0274985e3a63ebd2c2", "best_bid":"0.01", "best_ask":"0.02"}], "timestamp":"1770241484884", "event_type":"price_change"}
{"market":"0x38f3050258345e9cf363d1c8cc302f08c65b96ba1a4669d81e07ed69708344df", "price_changes":[{"asset_id":"96888240988495161476033313796107536512663280794332045579302109906525918376981", "price":"0.99", "size":"3575.7", "side":"SELL", "hash":"aa76f0cf0065b94d69165fdb7faab8ca076a9b7b", "best_bid":"0.98", "best_ask":"0.99"}, {"asset_id":"81916206347121459497221114766050949090435061493822476265356047392175668050706", "price":"0.01", "size":"3575.7", "side":"BUY", "hash":"47b25b2e3b336c3090a9c127889d21f754ce22ad", "best_bid":"0.01", "best_ask":"0.02"}], "timestamp":"1770241484905", "event_type":"price_change"}
{"market":"0x38f3050258345e9cf363d1c8cc302f08c65b96ba1a4669d81e07ed69708344df", "price_changes":[{"asset_id":"96888240988495161476033313796107536512663280794332045579302109906525918376981", "price":"0.97", "size":"622.32", "side":"BUY", "hash":"d157fd7a160286d6d1d09c6d48f48abf5b1745cb", "best_bid":"0.98", "best_ask":"0.99"}, {"asset_id":"81916206347121459497221114766050949090435061493822476265356047392175668050706", "price":"0.03", "size":"622.32", "side":"SELL", "hash":"f9476a69251ad0116d7c53739fe0553fd13e74bc", "best_bid":"0.01", "best_ask":"0.02"}], "timestamp":"1770241485134", "event_type":"price_change"}
{"market":"0x38f3050258345e9cf363d1c8cc302f08c65b96ba1a4669d81e07ed69708344df", "price_changes":[{"asset_id":"96888240988495161476033313796107536512663280794332045579302109906525918376981", "price":"0.96", "size":"653.73", "side":"BUY", "hash":"183c1af867ad082dafafec119c1e4cfd22f05336", "best_bid":"0.98", "best_ask":"0.99"}, {"asset_id":"81916206347121459497221114766050949090435061493822476265356047392175668050706", "price":"0.04", "size":"653.73", "side":"SELL", "hash":"bcd7c66f7b11414acad83333bb5b36bb0aae1a2b", "best_bid":"0.01", "best_ask":"0.02"}], "timestamp":"1770241485137", "event_type":"price_change"}
{"market":"0x38f3050258345e9cf363d1c8cc302f08c65b96ba1a4669d81e07ed69708344df", "price_changes":[{"asset_id":"96888240988495161476033313796107536512663280794332045579302109906525918376981", "price":"0.99", "size":"3615.7", "side":"SELL", "hash":"5e55d1105adbb82f044d6fb0ec1f07739af8b058", "best_bid":"0.98", "best_ask":"0.99"}, {"asset_id":"81916206347121459497221114766050949090435061493822476265356047392175668050706", "price":"0.01", "size":"3615.7", "side":"BUY", "hash":"80b6c8822c0c1aaf72aba769cf321756f961da43", "best_bid":"0.01", "best_ask":"0.02"}], "timestamp":"1770241485145", "event_type":"price_change"}
{"market":"0x38f3050258345e9cf363d1c8cc302f08c65b96ba1a4669d81e07ed69708344df", "price_changes":[{"asset_id":"96888240988495161476033313796107536512663280794332045579302109906525918376981", "price":"0.95", "size":"658", "side":"BUY", "hash":"ec9e957cbc787c7cb6602ed0a1b458487afe55d1", "best_bid":"0.98", "best_ask":"0.99"}, {"asset_id":"81916206347121459497221114766050949090435061493822476265356047392175668050706", "price":"0.05", "size":"658", "side":"SELL", "hash":"4c126481133ce749ab905b0bf6389d6bf23e1ace", "best_bid":"0.01", "best_ask":"0.02"}], "timestamp":"1770241485153", "event_type":"price_change"}
{"market":"0x38f3050258345e9cf363d1c8cc302f08c65b96ba1a4669d81e07ed69708344df", "price_changes":[{"asset_id":"81916206347121459497221114766050949090435061493822476265356047392175668050706", "price":"0.01", "size":"3588.7", "side":"BUY", "hash":"5888bec33f7dd96033ffd34dcf6776ba6fd6100f", "best_bid":"0.01", "best_ask":"0.02"}, {"asset_id":"96888240988495161476033313796107536512663280794332045579302109906525918376981", "price":"0.99", "size":"3588.7", "side":"SELL", "hash":"b87162138b997f24ff6b6c61c3162ad255949c68", "best_bid":"0.98", "best_ask":"0.99"}], "timestamp":"1770241485154", "event_type":"price_change"}
{"market":"0x38f3050258345e9cf363d1c8cc302f08c65b96ba1a4669d81e07ed69708344df", "price_changes":[{"asset_id":"81916206347121459497221114766050949090435061493822476265356047392175668050706", "price":"0.01", "size":"3615.7", "side":"BUY", "hash":"65f49e4b51d4892965277b5024e6852cc9c4641e", "best_bid":"0.01", "best_ask":"0.02"}, {"asset_id":"96888240988495161476033313796107536512663280794332045579302109906525918376981", "price":"0.99", "size":"3615.7", "side":"SELL", "hash":"3d0c23af620bd9ab71fb8aec43c327faa8345dc4", "best_bid":"0.98", "best_ask":"0.99"}], "timestamp":"1770241485154", "event_type":"price_change"}
{"market":"0x38f3050258345e9cf363d1c8cc302f08c65b96ba1a4669d81e07ed69708344df", "price_changes":[{"asset_id":"96888240988495161476033313796107536512663280794332045579302109906525918376981", "price":"0.96", "size":"680.73", "side":"BUY", "hash":"da67e42a3510b6daf9a3f94db60fa41db1d02837", "best_bid":"0.98", "best_ask":"0.99"}, {"asset_id":"81916206347121459497221114766050949090435061493822476265356047392175668050706", "price":"0.04", "size":"680.73", "side":"SELL", "hash":"7b394833c2d1d2f559df7aace512e8a691fac368", "best_bid":"0.01", "best_ask":"0.02"}], "timestamp":"1770241485155", "event_type":"price_change"}
{"market":"0x38f3050258345e9cf363d1c8cc302f08c65b96ba1a4669d81e07ed69708344df", "price_changes":[{"asset_id":"96888240988495161476033313796107536512663280794332045579302109906525918376981", "price":"0.96", "size":"707.73", "side":"BUY", "hash":"b064098697521fa7b30e2a131c931ebab2b488af", "best_bid":"0.98", "best_ask":"0.99"}, {"asset_id":"81916206347121459497221114766050949090435061493822476265356047392175668050706", "price":"0.04", "size":"707.73", "side":"SELL", "hash":"fb520419d551d34adc4fa017af9f41fd4ebf1644", "best_bid":"0.01", "best_ask":"0.02"}], "timestamp":"1770241485166", "event_type":"price_change"}
{"market":"0x38f3050258345e9cf363d1c8cc302f08c65b96ba1a4669d81e07ed69708344df", "price_changes":[{"asset_id":"81916206347121459497221114766050949090435061493822476265356047392175668050706", "price":"0.01", "size":"3642.7", "side":"BUY", "hash":"0110c0e1dbd757973a695ffc8aa0dc6a8cc16a42", "best_bid":"0.01", "best_ask":"0.02"}, {"asset_id":"96888240988495161476033313796107536512663280794332045579302109906525918376981", "price":"0.99", "size":"3642.7", "side":"SELL", "hash":"51dd3e5592de549ab9229fbcf76ff18efb05e238", "best_bid":"0.98", "best_ask":"0.99"}], "timestamp":"1770241485169", "event_type":"price_change"}
{"market":"0x38f3050258345e9cf363d1c8cc302f08c65b96ba1a4669d81e07ed69708344df", "price_changes":[{"asset_id":"96888240988495161476033313796107536512663280794332045579302109906525918376981", "price":"0.95", "size":"631", "side":"BUY", "hash":"bd7d11d850d3be271154f45c7955e79c88bc825d", "best_bid":"0.98", "best_ask":"0.99"}, {"asset_id":"81916206347121459497221114766050949090435061493822476265356047392175668050706", "price":"0.05", "size":"631", "side":"SELL", "hash":"e8a6e7bcaf37603e3a100865afca757aa61baa1f", "best_bid":"0.01", "best_ask":"0.02"}], "timestamp":"1770241485169", "event_type":"price_change"}
{"market":"0x38f3050258345e9cf363d1c8cc302f08c65b96ba1a4669d81e07ed69708344df", "price_changes":[{"asset_id":"81916206347121459497221114766050949090435061493822476265356047392175668050706", "price":"0.01", "size":"3615.7", "side":"BUY", "hash":"2b53c196e2c45d82308a377c605eb7f619cd3546", "best_bid":"0.01", "best_ask":"0.02"}, {"asset_id":"96888240988495161476033313796107536512663280794332045579302109906525918376981", "price":"0.99", "size":"3615.7", "side":"SELL", "hash":"1e1323bd21c4a731f4a4803e95c30597ecc1bb1c", "best_bid":"0.98", "best_ask":"0.99"}], "timestamp":"1770241485171", "event_type":"price_change"}
{"market":"0x38f3050258345e9cf363d1c8cc302f08c65b96ba1a4669d81e07ed69708344df", "price_changes":[{"asset_id":"81916206347121459497221114766050949090435061493822476265356047392175668050706", "price":"0.01", "size":"3588.7", "side":"BUY", "hash":"b62505c79b15d729eb07cb9c32dab794665c9f53", "best_bid":"0.01", "best_ask":"0.02"}, {"asset_id":"96888240988495161476033313796107536512663280794332045579302109906525918376981", "price":"0.99", "size":"3588.7", "side":"SELL", "hash":"776f23a125ed10a1152d7b9d167e13df94e14ade", "best_bid":"0.98", "best_ask":"0.99"}], "timestamp":"1770241485172", "event_type":"price_change"}
{"market":"0x38f3050258345e9cf363d1c8cc302f08c65b96ba1a4669d81e07ed69708344df", "price_changes":[{"asset_id":"81916206347121459497221114766050949090435061493822476265356047392175668050706", "price":"0.01", "size":"3615.7", "side":"BUY", "hash":"a4578c885db8be39279a85a1aed0caecc1f0e44e", "best_bid":"0.01", "best_ask":"0.02"}, {"asset_id":"96888240988495161476033313796107536512663280794332045579302109906525918376981", "price":"0.99", "size":"3615.7", "side":"SELL", "hash":"4fd311e96e5dca60906a23b0fdd651925e13e234", "best_bid":"0.98", "best_ask":"0.99"}], "timestamp":"1770241485173", "event_type":"price_change"}
{"market":"0x38f3050258345e9cf363d1c8cc302f08c65b96ba1a4669d81e07ed69708344df", "price_changes":[{"asset_id":"96888240988495161476033313796107536512663280794332045579302109906525918376981", "price":"0.96", "size":"680.73", "side":"BUY", "hash":"73d54f09c7931b77b8b4d42f9bcca21906dca211", "best_bid":"0.98", "best_ask":"0.99"}, {"asset_id":"81916206347121459497221114766050949090435061493822476265356047392175668050706", "price":"0.04", "size":"680.73", "side":"SELL", "hash":"2d93f48dccac515f1e58715033898f787b464d71", "best_bid":"0.01", "best_ask":"0.02"}], "timestamp":"1770241485174", "event_type":"price_change"}
{"market":"0x38f3050258345e9cf363d1c8cc302f08c65b96ba1a4669d81e07ed69708344df", "price_changes":[{"asset_id":"96888240988495161476033313796107536512663280794332045579302109906525918376981", "price":"0.96", "size":"700.73", "side":"BUY", "hash":"cc6275346ab900f9047e3c3ec9b9218f711627f1", "best_bid":"0.98", "best_ask":"0.99"}, {"asset_id":"81916206347121459497221114766050949090435061493822476265356047392175668050706", "price":"0.04", "size":"700.73", "side":"SELL", "hash":"51db6cdbb8759e28d44411d0d906a887932b3560", "best_bid":"0.01", "best_ask":"0.02"}], "timestamp":"1770241485177", "event_type":"price_change"}
{"market":"0x38f3050258345e9cf363d1c8cc302f08c65b96ba1a4669d81e07ed69708344df", "price_changes":[{"asset_id":"96888240988495161476033313796107536512663280794332045579302109906525918376981", "price":"0.99", "size":"3575.7", "side":"SELL", "hash":"da892db978e7ce9e31752c9842f27204a4a88691", "best_bid":"0.98", "best_ask":"0.99"}, {"asset_id":"81916206347121459497221114766050949090435061493822476265356047392175668050706", "price":"0.01", "size":"3575.7", "side":"BUY", "hash":"a642c0c0f84b228743182f23e13d27c3d68a7e65", "best_bid":"0.01", "best_ask":"0.02"}], "timestamp":"1770241485177", "event_type":"price_change"}
{"market":"0x38f3050258345e9cf363d1c8cc302f08c65b96ba1a4669d81e07ed69708344df", "price_changes":[{"asset_id":"96888240988495161476033313796107536512663280794332045579302109906525918376981", "price":"0.96", "size":"727.73", "side":"BUY", "hash":"f1a0c2c64b21a3b59f5f93d78322dc854cbcdd0d", "best_bid":"0.98", "best_ask":"0.99"}, {"asset_id":"81916206347121459497221114766050949090435061493822476265356047392175668050706", "price":"0.04", "size":"727.73", "side":"SELL", "hash":"8d6577e22af0e6192fb06ac3b1b7af3b80416f6d", "best_bid":"0.01", "best_ask":"0.02"}], "timestamp":"1770241485182", "event_type":"price_change"}
{"market":"0x38f3050258345e9cf363d1c8cc302f08c65b96ba1a4669d81e07ed69708344df", "price_changes":[{"asset_id":"81916206347121459497221114766050949090435061493822476265356047392175668050706", "price":"0.01", "size":"3602.7", "side":"BUY", "hash":"cb95ca6495074e99f36cfc824bf94631726dfbed", "best_bid":"0.01", "best_ask":"0.02"}, {"asset_id":"96888240988495161476033313796107536512663280794332045579302109906525918376981", "price":"0.99", "size":"3602.7", "side":"SELL", "hash":"a9cd648b85e9c4d4e01aac70047f04a5c9e4d40b", "best_bid":"0.98", "best_ask":"0.99"}], "timestamp":"1770241485283", "event_type":"price_change"}
{"market":"0x38f3050258345e9cf363d1c8cc302f08c65b96ba1a4669d81e07ed69708344df", "price_changes":[{"asset_id":"81916206347121459497221114766050949090435061493822476265356047392175668050706", "price":"0.01", "size":"3575.7", "side":"BUY", "hash":"62ffe1a6b38cc7ebbca777eadbff878ce94964a9", "best_bid":"0.01", "best_ask":"0.02"}, {"asset_id":"96888240988495161476033313796107536512663280794332045579302109906525918376981", "price":"0.99", "size":"3575.7", "side":"SELL", "hash":"0a275745091ac3b7c12eb6acbb6e40b0acb4dc98", "best_bid":"0.98", "best_ask":"0.99"}], "timestamp":"1770241485284", "event_type":"price_change"}
{"market":"0x38f3050258345e9cf363d1c8cc302f08c65b96ba1a4669d81e07ed69708344df", "price_changes":[{"asset_id":"96888240988495161476033313796107536512663280794332045579302109906525918376981", "price":"0.96", "size":"700.73", "side":"BUY", "hash":"7844e4228c2072dd64fe349262edf94700e185af", "best_bid":"0.98", "best_ask":"0.99"}, {"asset_id":"81916206347121459497221114766050949090435061493822476265356047392175668050706", "price":"0.04", "size":"700.73", "side":"SELL", "hash":"2b6223158d2ecf4671301cb3f983583fdbddf34b", "best_bid":"0.01", "best_ask":"0.02"}], "timestamp":"1770241485286", "event_type":"price_change"}
{"market":"0x38f3050258345e9cf363d1c8cc302f08c65b96ba1a4669d81e07ed69708344df", "price_changes":[{"asset_id":"81916206347121459497221114766050949090435061493822476265356047392175668050706", "price":"0.01", "size":"3548.7", "side":"BUY", "hash":"3c92137dca2ac95ece7a1f3299a27697ca3354a7", "best_bid":"0.01", "best_ask":"0.02"}, {"asset_id":"96888240988495161476033313796107536512663280794332045579302109906525918376981", "price":"0.99", "size":"3548.7", "side":"SELL", "hash":"88c65e554fcde4fb62b12d89008be69a71012b2f", "best_bid":"0.98", "best_ask":"0.99"}], "timestamp":"1770241485287", "event_type":"price_change"}
{"market":"0x38f3050258345e9cf363d1c8cc302f08c65b96ba1a4669d81e07ed69708344df", "price_changes":[{"asset_id":"81916206347121459497221114766050949090435061493822476265356047392175668050706", "price":"0.01", "size":"3575.7", "side":"BUY", "hash":"d24ef41e586f24d62c91874848f558aa95261b96", "best_bid":"0.01", "best_ask":"0.02"}, {"asset_id":"96888240988495161476033313796107536512663280794332045579302109906525918376981", "price":"0.99", "size":"3575.7", "side":"SELL", "hash":"cb3fc4f70b21c791d56a20d3a29f042ba4c19ffe", "best_bid":"0.98", "best_ask":"0.99"}], "timestamp":"1770241485287", "event_type":"price_change"}
{"market":"0x38f3050258345e9cf363d1c8cc302f08c65b96ba1a4669d81e07ed69708344df", "price_changes":[{"asset_id":"96888240988495161476033313796107536512663280794332045579302109906525918376981", "price":"0.96", "size":"673.73", "side":"BUY", "hash":"7c98eff33c3dfda04829860e4251f2e7bea841e0", "best_bid":"0.98", "best_ask":"0.99"}, {"asset_id":"81916206347121459497221114766050949090435061493822476265356047392175668050706", "price":"0.04", "size":"673.73", "side":"SELL", "hash":"66e4bd7c27498de7bbec92b82d2574f780150cdd", "best_bid":"0.01", "best_ask":"0.02"}], "timestamp":"1770241485291", "event_type":"price_change"}
{"market":"0x38f3050258345e9cf363d1c8cc302f08c65b96ba1a4669d81e07ed69708344df", "price_changes":[{"asset_id":"96888240988495161476033313796107536512663280794332045579302109906525918376981", "price":"0.95", "size":"658", "side":"BUY", "hash":"3a7cf306ecead3ce50294ba70004a62de5722836", "best_bid":"0.98", "best_ask":"0.99"}, {"asset_id":"81916206347121459497221114766050949090435061493822476265356047392175668050706", "price":"0.05", "size":"658", "side":"SELL", "hash":"4c7ca98366bc09873d0da30901d2889aa66de722", "best_bid":"0.01", "best_ask":"0.02"}], "timestamp":"1770241485291", "event_type":"price_change"}
{"market":"0x38f3050258345e9cf363d1c8cc302f08c65b96ba1a4669d81e07ed69708344df", "price_changes":[{"asset_id":"96888240988495161476033313796107536512663280794332045579302109906525918376981", "price":"0.95", "size":"685", "side":"BUY", "hash":"d7450aa530b8145c652027951a122f43661473b9", "best_bid":"0.98", "best_ask":"0.99"}, {"asset_id":"81916206347121459497221114766050949090435061493822476265356047392175668050706", "price":"0.05", "size":"685", "side":"SELL", "hash":"e74d1b94506831b8065c7cc237a88f14d536749f", "best_bid":"0.01", "best_ask":"0.02"}], "timestamp":"1770241485292", "event_type":"price_change"}
{"market":"0x38f3050258345e9cf363d1c8cc302f08c65b96ba1a4669d81e07ed69708344df", "price_changes":[{"asset_id":"96888240988495161476033313796107536512663280794332045579302109906525918376981", "price":"0.99", "size":"1693.08", "side":"SELL", "hash":"7c9152ce3038077fa09fbb58eaf34f2c342f2f2e", "best_bid":"0.98", "best_ask":"0.99"}, {"asset_id":"81916206347121459497221114766050949090435061493822476265356047392175668050706", "price":"0.01", "size":"1693.08", "side":"BUY", "hash":"bccd3d131fd601b840a50528398e5dd18843f150", "best_bid":"0.01", "best_ask":"0.02"}], "timestamp":"1770241485369", "event_type":"price_change"}
{"market":"0x38f3050258345e9cf363d1c8cc302f08c65b96ba1a4669d81e07ed69708344df", "price_changes":[{"asset_id":"81916206347121459497221114766050949090435061493822476265356047392175668050706", "price":"0.01", "size":"1693.08", "side":"BUY", "hash":"bccd3d131fd601b840a50528398e5dd18843f150", "best_bid":"0.01", "best_ask":"0.02"}, {"asset_id":"96888240988495161476033313796107536512663280794332045579302109906525918376981", "price":"0.99", "size":"1693.08", "side":"SELL", "hash":"7c9152ce3038077fa09fbb58eaf34f2c342f2f2e", "best_bid":"0.98", "best_ask":"0.99"}], "timestamp":"1770241485369", "event_type":"price_change"}
