PONG
[{"market":"0x38f3050258345e9cf363d1c8cc302f08c65b96ba1a4669d81e07ed69708344df","asset_id":"81916206347121459497221114766050949090435061493822476265356047392175668050706","timestamp":"1770241463354","hash":"cd6b70341d2ee0c64ecc272706809437411abd26","bids":[{"price":"0.01","size":"4257.07"},{"price":"0.02","size":"592.22"}],"asks":[{"price":"0.99","size":"5019.91"},{"price":"0.98","size":"3034.23"},{"price":"0.97","size":"3172"},{"price":"0.96","size":"3012"},{"price":"0.95","size":"3032"},{"price":"0.94","size":"3012"},{"price":"0.93","size":"3126.28"},{"price":"0.92","size":"3012"},{"price":"0.91","size":"3012"},{"price":"0.9","size":"3087"},{"price":"0.89","size":"12"},{"price":"0.88","size":"12"},{"price":"0.87","size":"12"},{"price":"0.86","size":"12"},{"price":"0.85","size":"12"},{"price":"0.84","size":"12"},{"price":"0.83","size":"12"},{"price":"0.82","size":"12"},{"price":"0.81","size":"12"},{"price":"0.8","size":"12"},{"price":"0.79","size":"12"},{"price":"0.78","size":"12"},{"price":"0.77","size":"12"},{"price":"0.76","size":"112"},{"price":"0.75","size":"40.57"},{"price":"0.74","size":"12"},{"price":"0.73","size":"293.25"},{"price":"0.72","size":"22"},{"price":"0.71","size":"12"},{"price":"0.7","size":"18"},{"price":"0.69","size":"12"},{"price":"0.68","size":"12"},{"price":"0.67","size":"12"},{"price":"0.66","size":"160.89"},{"price":"0.65","size":"12"},{"price":"0.64","size":"12"},{"price":"0.63","size":"12"},{"price":"0.62","size":"19.39"},{"price":"0.61","size":"18.04"},{"price":"0.6","size":"12"},{"price":"0.59","size":"94.31"},{"price":"0.58","size":"5450.54"},{"price":"0.57","size":"12"},{"price":"0.56","size":"12"},{"price":"0.55","size":"12"},{"price":"0.54","size":"22"},{"price":"0.53","size":"12"},{"price":"0.52","size":"12"},{"price":"0.51","size":"12"},{"price":"0.5","size":"12"},{"price":"0.49","size":"12"},{"price":"0.48","size":"12"},{"price":"0.47","size":"12"},{"price":"0.46","size":"485.56"},{"price":"0.45","size":"31"},{"price":"0.44","size":"17"},{"price":"0.43","size":"12"},{"price":"0.42","size":"12"},{"price":"0.41","size":"12"},{"price":"0.4","size":"127"},{"price":"0.39","size":"12"},{"price":"0.38","size":"94.51"},{"price":"0.37","size":"31.99"},{"price":"0.36","size":"12"},{"price":"0.35","size":"37"},{"price":"0.34","size":"12"},{"price":"0.33","size":"12"},{"price":"0.32","size":"12"},{"price":"0.31","size":"12"},{"price":"0.3","size":"31.9"},{"price":"0.29","size":"344"},{"price":"0.28","size":"3488.99"},{"price":"0.27","size":"212"},{"price":"0.26","size":"718"},{"price":"0.25","size":"212"},{"price":"0.24","size":"212"},{"price":"0.23","size":"212"},{"price":"0.22","size":"1223.14"},{"price":"0.21","size":"212"},{"price":"0.2","size":"272.99"},{"price":"0.19","size":"212"},{"price":"0.18","size":"212"},{"price":"0.17","size":"212"},{"price":"0.16","size":"812"},{"price":"0.15","size":"231.08"},{"price":"0.14","size":"283.65"},{"price":"0.13","size":"212"},{"price":"0.12","size":"252"},{"price":"0.11","size":"252"},{"price":"0.1","size":"746.71"},{"price":"0.09","size":"326"},{"price":"0.08","size":"844.68"},{"price":"0.07","size":"826"},{"price":"0.06","size":"726"},{"price":"0.05","size":"700"},{"price":"0.04","size":"800.73"},{"price":"0.03","size":"632"}],"event_type":"book","last_trade_price":"0.980"}]

{"market":"0x38f3050258345e9cf363d1c8cc302f08c65b96ba1a4669d81e07ed69708344df", "price_changes":[{"asset_id":"96888240988495161476033313796107536512663280794332045579302109906525918376981", "price":"0.95", "size":"673", "side":"BUY", "hash":"e8d00546bbbd6b32a73304b78bd372a2fd46a5bf", "best_bid":"0.97", "best_ask":"0.98"}, {"asset_id":"81916206347121459497221114766050949090435061493822476265356047392175668050706", "price":"0.05", "size":"673", "side":"SELL", "hash":"493573a67d8d47e643280d270be70a567853824f", "best_bid":"0.02", "best_ask":"0.03"}], "timestamp":"1770241463463", "event_type":"price_change"}
{"market":"0x38f3050258345e9cf363d1c8cc302f08c65b96ba1a4669d81e07ed69708344df", "price_changes":[{"asset_id":"96888240988495161476033313796107536512663280794332045579302109906525918376981", "price":"0.94", "size":"753", "side":"BUY", "hash":"42a3f8b59fce4ca03408bfaed213563fa7adb271", "best_bid":"0.97", "best_ask":"0.98"}, {"asset_id":"81916206347121459497221114766050949090435061493822476265356047392175668050706", "price":"0.06", "size":"753", "side":"SELL", "hash":"98259fda12205959561d49e50bed66393a8b0f27", "best_bid":"0.02", "best_ask":"0.03"}], "timestamp":"1770241463466", "event_type":"price_change"}
{"market":"0x38f3050258345e9cf363d1c8cc302f08c65b96ba1a4669d81e07ed69708344df", "price_changes":[{"asset_id":"96888240988495161476033313796107536512663280794332045579302109906525918376981", "price":"0.95", "size":"646", "side":"BUY", "hash":"34e2e40464ba1259c824ebb83eded40012265b48", "best_bid":"0.97", "best_ask":"0.98"}, {"asset_id":"81916206347121459497221114766050949090435061493822476265356047392175668050706", "price":"0.05", "size":"646", "side":"SELL", "hash":"22d15d057f9c192f226bd28b6e0ff88b1dbb59d2", "best_bid":"0.02", "best_ask":"0.03"}], "timestamp":"1770241463467", "event_type":"price_change"}
{"market":"0x38f3050258345e9cf363d1c8cc302f08c65b96ba1a4669d81e07ed69708344df", "price_changes":[{"asset_id":"96888240988495161476033313796107536512663280794332045579302109906525918376981", "price":"0.94", "size":"780", "side":"BUY", "hash":"b3e97c70d1673285c35f623eb53b51bf284fb02d", "best_bid":"0.97", "best_ask":"0.98"}, {"asset_id":"81916206347121459497221114766050949090435061493822476265356047392175668050706", "price":"0.06", "size":"780", "side":"SELL", "hash":"03490821e361e354b08ea294db6e554b48b9db9d", "best_bid":"0.02", "best_ask":"0.03"}], "timestamp":"1770241463469", "event_type":"price_change"}
{"market":"0x38f3050258345e9cf363d1c8cc302f08c65b96ba1a4669d81e07ed69708344df", "price_changes":[{"asset_id":"96888240988495161476033313796107536512663280794332045579302109906525918376981", "price":"0.95", "size":"623", "side":"BUY", "hash":"10d67d357d7a54212f5a7dcf6432bc8a344f9369", "best_bid":"0.97", "best_ask":"0.98"}, {"asset_id":"81916206347121459497221114766050949090435061493822476265356047392175668050706", "price":"0.05", "size":"623", "side":"SELL", "hash":"598b088fd0c159210030ce5b95b049339cff93da", "best_bid":"0.02", "best_ask":"0.03"}], "timestamp":"1770241463540", "event_type":"price_change"}
{"market":"0x38f3050258345e9cf363d1c8cc302f08c65b96ba1a4669d81e07ed69708344df", "price_changes":[{"asset_id":"81916206347121459497221114766050949090435061493822476265356047392175668050706", "price":"0.01", "size":"4234.07", "side":"BUY", "hash":"68cb5bae774900f1cbfe5265a6e2ad327569fbbb", "best_bid":"0.02", "best_ask":"0.03"}, {"asset_id":"96888240988495161476033313796107536512663280794332045579302109906525918376981", "price":"0.99", "size":"4234.07", "side":"SELL", "hash":"e6ea38038ee173299da0fbcf0dab0dca1185023d", "best_bid":"0.97", "best_ask":"0.98"}], "timestamp":"1770241463541", "event_type":"price_change"}
{"market":"0x38f3050258345e9cf363d1c8cc302f08c65b96ba1a4669d81e07ed69708344df", "price_changes":[{"asset_id":"81916206347121459497221114766050949090435061493822476265356047392175668050706", "price":"0.02", "size":"615.22", "side":"BUY", "hash":"83698af6a5464c4a445235fbd76a0833ed5c57e6", "best_bid":"0.02", "best_ask":"0.03"}, {"asset_id":"96888240988495161476033313796107536512663280794332045579302109906525918376981", "price":"0.98", "size":"615.22", "side":"SELL", "hash":"1b2afb8bcd42dedeffd8e0f7db1333dce2ccea8f", "best_bid":"0.97", "best_ask":"0.98"}], "timestamp":"1770241463541", "event_type":"price_change"}
{"market":"0x38f3050258345e9cf363d1c8cc302f08c65b96ba1a4669d81e07ed69708344df", "price_changes":[{"asset_id":"96888240988495161476033313796107536512663280794332045579302109906525918376981", "price":"0.96", "size":"823.73", "side":"BUY", "hash":"4cf4e622d7be92d8e42f1c3b4aa187f8976e9cbb", "best_bid":"0.97", "best_ask":"0.98"}, {"asset_id":"81916206347121459497221114766050949090435061493822476265356047392175668050706", "price":"0.04", "size":"823.73", "side":"SELL", "hash":"a6b7d21317271c82cf591e55e71cb8812f5843cf", "best_bid":"0.02", "best_ask":"0.03"}], "timestamp":"1770241463543", "event_type":"price_change"}
{"market":"0x38f3050258345e9cf363d1c8cc302f08c65b96ba1a4669d81e07ed69708344df", "price_changes":[{"asset_id":"81916206347121459497221114766050949090435061493822476265356047392175668050706", "price":"0.02", "size":"592.22", "side":"BUY", "hash":"b3378cb3a711aaf4fb874734b89cd48e6cb4a6e4", "best_bid":"0.02", "best_ask":"0.03"}, {"asset_id":"96888240988495161476033313796107536512663280794332045579302109906525918376981", "price":"0.98", "size":"592.22", "side":"SELL", "hash":"a66089c8a25fc183bd0cbc474c72467f413199bf", "best_bid":"0.97", "best_ask":"0.98"}], "timestamp":"1770241463790", "event_type":"price_change"}
{"market":"0x38f3050258345e9cf363d1c8cc302f08c65b96ba1a4669d81e07ed69708344df", "price_changes":[{"asset_id":"96888240988495161476033313796107536512663280794332045579302109906525918376981", "price":"0.96", "size":"800.73", "side":"BUY", "hash":"b1845189caceab203af6e84064b012e5c0550430", "best_bid":"0.97", "best_ask":"0.98"}, {"asset_id":"81916206347121459497221114766050949090435061493822476265356047392175668050706", "price":"0.04", "size":"800.73", "side":"SELL", "hash":"a13167c0be61416e1024fd28b8f4b2dd31682b0b", "best_bid":"0.02", "best_ask":"0.03"}], "timestamp":"1770241463790", "event_type":"price_change"}
{"market":"0x38f3050258345e9cf363d1c8cc302f08c65b96ba1a4669d81e07ed69708344df", "price_changes":[{"asset_id":"81916206347121459497221114766050949090435061493822476265356047392175668050706", "price":"0.01", "size":"4257.07", "side":"BUY", "hash":"0ddaec76fe7e6ad0fb7712d8ccaafdc4f70b6b30", "best_bid":"0.02", "best_ask":"0.03"}, {"asset_id":"96888240988495161476033313796107536512663280794332045579302109906525918376981", "price":"0.99", "size":"4257.07", "side":"SELL", "hash":"6eb81055a736a34355251b10ba861bff81462216", "best_bid":"0.97", "best_ask":"0.98"}], "timestamp":"1770241463791", "event_type":"price_change"}
{"market":"0x38f3050258345e9cf363d1c8cc302f08c65b96ba1a4669d81e07ed69708344df", "price_changes":[{"asset_id":"96888240988495161476033313796107536512663280794332045579302109906525918376981", "price":"0.95", "size":"646", "side":"BUY", "hash":"f568a7b3e14b8ef942dc0ac479efabafc12458d7", "best_bid":"0.97", "best_ask":"0.98"}, {"asset_id":"81916206347121459497221114766050949090435061493822476265356047392175668050706", "price":"0.05", "size":"646", "side":"SELL", "hash":"44ad84a6ffff175cccdda0ba175a5bf0d9fba0bf", "best_bid":"0.02", "best_ask":"0.03"}], "timestamp":"1770241463792", "event_type":"price_change"}
{"market":"0x38f3050258345e9cf363d1c8cc302f08c65b96ba1a4669d81e07ed69708344df", "price_changes":[{"asset_id":"81916206347121459497221114766050949090435061493822476265356047392175668050706", "price":"0.01", "size":"4230.07", "side":"BUY", "hash":"61f3884c9d2636d9f71e711bffd0b979c1d16e7b", "best_bid":"0.02", "best_ask":"0.03"}, {"asset_id":"96888240988495161476033313796107536512663280794332045579302109906525918376981", "price":"0.99", "size":"4230.07", "side":"SELL", "hash":"ed19141e4baecbb59b56e624658a3c9a443c9fbb", "best_bid":"0.97", "best_ask":"0.98"}], "timestamp":"1770241463850", "event_type":"price_change"}
{"market":"0x38f3050258345e9cf363d1c8cc302f08c65b96ba1a4669d81e07ed69708344df", "price_changes":[{"asset_id":"81916206347121459497221114766050949090435061493822476265356047392175668050706", "price":"0.01", "size":"4257.07", "side":"BUY", "hash":"5d35ce5ceb1a57ff436061e9a3d62528a288371b", "best_bid":"0.02", "best_ask":"0.03"}, {"asset_id":"96888240988495161476033313796107536512663280794332045579302109906525918376981", "price":"0.99", "size":"4257.07", "side":"SELL", "hash":"c502d2a7782141c7fec482267d9db20c277b1ac0", "best_bid":"0.97", "best_ask":"0.98"}], "timestamp":"1770241463851", "event_type":"price_change"}
{"market":"0x38f3050258345e9cf363d1c8cc302f08c65b96ba1a4669d81e07ed69708344df", "price_changes":[{"asset_id":"96888240988495161476033313796107536512663280794332045579302109906525918376981", "price":"0.94", "size":"753", "side":"BUY", "hash":"67f3abf779869b052e346d077d188878fbacd0f5", "best_bid":"0.97", "best_ask":"0.98"}, {"asset_id":"81916206347121459497221114766050949090435061493822476265356047392175668050706", "price":"0.06", "size":"753", "side":"SELL", "hash":"159cd52eaa0ee6be967fa72cd88c5edaff761498", "best_bid":"0.02", "best_ask":"0.03"}], "timestamp":"1770241463851", "event_type":"price_change"}
{"market":"0x38f3050258345e9cf363d1c8cc302f08c65b96ba1a4669d81e07ed69708344df", "price_changes":[{"asset_id":"96888240988495161476033313796107536512663280794332045579302109906525918376981", "price":"0.95", "size":"673", "side":"BUY", "hash":"c7adb6d361757c35438be6a474c0f134bad192cc", "best_bid":"0.97", "best_ask":"0.98"}, {"asset_id":"81916206347121459497221114766050949090435061493822476265356047392175668050706", "price":"0.05", "size":"673", "side":"SELL", "hash":"55399ee860b5d4511378f73bd25599c6c4a69614", "best_bid":"0.02", "best_ask":"0.03"}], "timestamp":"1770241463852", "event_type":"price_change"}
{"market":"0x38f3050258345e9cf363d1c8cc302f08c65b96ba1a4669d81e07ed69708344df", "price_changes":[{"asset_id":"96888240988495161476033313796107536512663280794332045579302109906525918376981", "price":"0.95", "size":"700", "side":"BUY", "hash":"e8d803bc8c437dea623d65fffd1d03a0809b058c", "best_bid":"0.97", "best_ask":"0.98"}, {"asset_id":"81916206347121459497221114766050949090435061493822476265356047392175668050706", "price":"0.05", "size":"700", "side":"SELL", "hash":"21c201ea054bf3ebc1dbb12f43855a9f166af488", "best_bid":"0.02", "best_ask":"0.03"}], "timestamp":"1770241463862", "event_type":"price_change"}
{"market":"0x38f3050258345e9cf363d1c8cc302f08c65b96ba1a4669d81e07ed69708344df", "price_changes":[{"asset_id":"81916206347121459497221114766050949090435061493822476265356047392175668050706", "price":"0.01", "size":"4230.07", "side":"BUY", "hash":"4794d9920f61ad66ce85dd08910ab07f7d3dfeca", "best_bid":"0.02", "best_ask":"0.03"}, {"asset_id":"96888240988495161476033313796107536512663280794332045579302109906525918376981", "price":"0.99", "size":"4230.07", "side":"SELL", "hash":"c1980a33f39c5c94aceab1aa4a9bf42137a7f0f5", "best_bid":"0.97", "best_ask":"0.98"}], "timestamp":"1770241463864", "event_type":"price_change"}
{"market":"0x38f3050258345e9cf363d1c8cc302f08c65b96ba1a4669d81e07ed69708344df", "price_changes":[{"asset_id":"81916206347121459497221114766050949090435061493822476265356047392175668050706", "price":"0.01", "size":"4257.07", "side":"BUY", "hash":"7b3f7a172dc384c1d749d9ec136ea4ae9ab27dfc", "best_bid":"0.02", "best_ask":"0.03"}, {"asset_id":"96888240988495161476033313796107536512663280794332045579302109906525918376981", "price":"0.99", "size":"4257.07", "side":"SELL", "hash":"369db9a7a9be1085f961ba11a2c539e5c2a6a9a5", "best_bid":"0.97", "best_ask":"0.98"}], "timestamp":"1770241463865", "event_type":"price_change"}
{"market":"0x38f3050258345e9cf363d1c8cc302f08c65b96ba1a4669d81e07ed69708344df", "price_changes":[{"asset_id":"81916206347121459497221114766050949090435061493822476265356047392175668050706", "price":"0.01", "size":"4284.07", "side":"BUY", "hash":"6c7f62d70096165adc5ce1fc24f0503404070839", "best_bid":"0.02", "best_ask":"0.03"}, {"asset_id":"96888240988495161476033313796107536512663280794332045579302109906525918376981", "price":"0.99", "size":"4284.07", "side":"SELL", "hash":"12973e0dfb7cf53d24099178361cccff552c7b93", "best_bid":"0.97", "best_ask":"0.98"}], "timestamp":"1770241463870", "event_type":"price_change"}
{"market":"0x38f3050258345e9cf363d1c8cc302f08c65b96ba1a4669d81e07ed69708344df", "price_changes":[{"asset_id":"81916206347121459497221114766050949090435061493822476265356047392175668050706", "price":"0.01", "size":"4257.07", "side":"BUY", "hash":"9e4785c496dc740b4927e4189c130a87ddd6ef8d", "best_bid":"0.02", "best_ask":"0.03"}, {"asset_id":"96888240988495161476033313796107536512663280794332045579302109906525918376981", "price":"0.99", "size":"4257.07", "side":"SELL", "hash":"5a02a8856cab7b5d2eb09fc1d0a760fc0124da86", "best_bid":"0.97", "best_ask":"0.98"}], "timestamp":"1770241463870", "event_type":"price_change"}
{"market":"0x38f3050258345e9cf363d1c8cc302f08c65b96ba1a4669d81e07ed69708344df", "price_changes":[{"asset_id":"96888240988495161476033313796107536512663280794332045579302109906525918376981", "price":"0.96", "size":"773.73", "side":"BUY", "hash":"d04e7ad8642f30e781d9a3ab0b6d56efc9ef6b41", "best_bid":"0.97", "best_ask":"0.98"}, {"asset_id":"81916206347121459497221114766050949090435061493822476265356047392175668050706", "price":"0.04", "size":"773.73", "side":"SELL", "hash":"6dbc490508329ff23ab09498b1e155c298408669", "best_bid":"0.02", "best_ask":"0.03"}], "timestamp":"1770241463871", "event_type":"price_change"}
{"market":"0x38f3050258345e9cf363d1c8cc302f08c65b96ba1a4669d81e07ed69708344df", "price_changes":[{"asset_id":"96888240988495161476033313796107536512663280794332045579302109906525918376981", "price":"0.96", "size":"800.73", "side":"BUY", "hash":"1f2efe9ab9e523e422d86f79e0bfc43b9cf3763b", "best_bid":"0.97", "best_ask":"0.98"}, {"asset_id":"81916206347121459497221114766050949090435061493822476265356047392175668050706", "price":"0.04", "size":"800.73", "side":"SELL", "hash":"ec753555ba5c1ebe4bd836e99d0d340e393f32fa", "best_bid":"0.02", "best_ask":"0.03"}], "timestamp":"1770241463873", "event_type":"price_change"}
{"market":"0x38f3050258345e9cf363d1c8cc302f08c65b96ba1a4669d81e07ed69708344df", "price_changes":[{"asset_id":"96888240988495161476033313796107536512663280794332045579302109906525918376981", "price":"0.94", "size":"726", "side":"BUY", "hash":"62b510e7024aab1de6c153ec9f519ea2aaaac0d6", "best_bid":"0.97", "best_ask":"0.98"}, {"asset_id":"81916206347121459497221114766050949090435061493822476265356047392175668050706", "price":"0.06", "size":"726", "side":"SELL", "hash":"97354cb9feed9895a5dfc820cce6ac1e4c18b271", "best_bid":"0.02", "best_ask":"0.03"}], "timestamp":"1770241463898", "event_type":"price_change"}
{"market":"0x38f3050258345e9cf363d1c8cc302f08c65b96ba1a4669d81e07ed69708344df", "price_changes":[{"asset_id":"81916206347121459497221114766050949090435061493822476265356047392175668050706", "price":"0.01", "size":"4230.07", "side":"BUY", "hash":"107b36f3902d57fbfa7490503d0c4c434b434e09", "best_bid":"0.02", "best_ask":"0.03"}, {"asset_id":"96888240988495161476033313796107536512663280794332045579302109906525918376981", "price":"0.99", "size":"4230.07", "side":"SELL", "hash":"bf76372b05fc74a361ea547da7e23877378f48a7", "best_bid":"0.97", "best_ask":"0.98"}], "timestamp":"1770241463984", "event_type":"price_change"}
{"market":"0x38f3050258345e9cf363d1c8cc302f08c65b96ba1a4669d81e07ed69708344df", "price_changes":[{"asset_id":"81916206347121459497221114766050949090435061493822476265356047392175668050706", "price":"0.01", "size":"4203.07", "side":"BUY", "hash":"839a14fde169f2d8a69d2150d4f836140322168e", "best_bid":"0.02", "best_ask":"0.03"}, {"asset_id":"96888240988495161476033313796107536512663280794332045579302109906525918376981", "price":"0.99", "size":"4203.07", "side":"SELL", "hash":"15291cd93f52093b23a1ee7c3bfd36197a8f1906", "best_bid":"0.97", "best_ask":"0.98"}], "timestamp":"1770241463986", "event_type":"price_change"}
{"market":"0x38f3050258345e9cf363d1c8cc302f08c65b96ba1a4669d81e07ed69708344df", "price_changes":[{"asset_id":"81916206347121459497221114766050949090435061493822476265356047392175668050706", "price":"0.01", "size":"4230.07", "side":"BUY", "hash":"8c6b7fae34e4c646dc47e8744a2cdceba256fb18", "best_bid":"0.02", "best_ask":"0.03"}, {"asset_id":"96888240988495161476033313796107536512663280794332045579302109906525918376981", "price":"0.99", "size":"4230.07", "side":"SELL", "hash":"304fd0c8c5b8a5860b811e24402bf9c4a00226ba", "best_bid":"0.97", "best_ask":"0.98"}], "timestamp":"1770241463987", "event_type":"price_change"}
{"market":"0x38f3050258345e9cf363d1c8cc302f08c65b96ba1a4669d81e07ed69708344df", "price_changes":[{"asset_id":"96888240988495161476033313796107536512663280794332045579302109906525918376981", "price":"0.95", "size":"727", "side":"BUY", "hash":"ec5759eec34cd30ff4384d90fa5cf1757445d365", "best_bid":"0.97", "best_ask":"0.98"}, {"asset_id":"81916206347121459497221114766050949090435061493822476265356047392175668050706", "price":"0.05", "size":"727", "side":"SELL", "hash":"0332dea4323f5386b85d4f28f93c37fece586a50", "best_bid":"0.02", "best_ask":"0.03"}], "timestamp":"1770241463988", "event_type":"price_change"}
{"market":"0x38f3050258345e9cf363d1c8cc302f08c65b96ba1a4669d81e07ed69708344df", "price_changes":[{"asset_id":"81916206347121459497221114766050949090435061493822476265356047392175668050706", "price":"0.01", "size":"4257.07", "side":"BUY", "hash":"56ee8a98a5655340bef5797950fa2752902e4621", "best_bid":"0.02", "best_ask":"0.03"}, {"asset_id":"96888240988495161476033313796107536512663280794332045579302109906525918376981", "price":"0.99", "size":"4257.07", "side":"SELL", "hash":"2f1712e3d8a416c0700350f554055a7a23a52b27", "best_bid":"0.97", "best_ask":"0.98"}], "timestamp":"1770241463989", "event_type":"price_change"}
{"market":"0x38f3050258345e9cf363d1c8cc302f08c65b96ba1a4669d81e07ed69708344df", "price_changes":[{"asset_id":"96888240988495161476033313796107536512663280794332045579302109906525918376981", "price":"0.95", "size":"700", "side":"BUY", "hash":"cf8250cbaa970cf665cbf9cebb452262d21977fa", "best_bid":"0.97", "best_ask":"0.98"}, {"asset_id":"81916206347121459497221114766050949090435061493822476265356047392175668050706", "price":"0.05", "size":"700", "side":"SELL", "hash":"fc65102e72ee81f3de77e83e7e1ab13859ee4408", "best_bid":"0.02", "best_ask":"0.03"}], "timestamp":"1770241463992", "event_type":"price_change"}
{"market":"0x38f3050258345e9cf363d1c8cc302f08c65b96ba1a4669d81e07ed69708344df", "price_changes":[{"asset_id":"96888240988495161476033313796107536512663280794332045579302109906525918376981", "price":"0.95", "size":"673", "side":"BUY", "hash":"9d5374e487c51bbd34a83bab21d50452775fa812", "best_bid":"0.97", "best_ask":"0.98"}, {"asset_id":"81916206347121459497221114766050949090435061493822476265356047392175668050706", "price":"0.05", "size":"673", "side":"SELL", "hash":"659f848759f58b1d3a25c4727229b76eb2570dd8", "best_bid":"0.02", "best_ask":"0.03"}], "timestamp":"1770241463993", "event_type":"price_change"}
{"market":"0x38f3050258345e9cf363d1c8cc302f08c65b96ba1a4669d81e07ed69708344df", "price_changes":[{"asset_id":"96888240988495161476033313796107536512663280794332045579302109906525918376981", "price":"0.94", "size":"753", "side":"BUY", "hash":"fbca6a6d3083efdfcf5f60c37cc8a5c7d2aecd12", "best_bid":"0.97", "best_ask":"0.98"}, {"asset_id":"81916206347121459497221114766050949090435061493822476265356047392175668050706", "price":"0.06", "size":"753", "side":"SELL", "hash":"4f129d53cc5c846380d7b40d0cfb6713ed8828ff", "best_bid":"0.02", "best_ask":"0.03"}], "timestamp":"1770241463994", "event_type":"price_change"}
{"market":"0x38f3050258345e9cf363d1c8cc302f08c65b96ba1a4669d81e07ed69708344df", "price_changes":[{"asset_id":"81916206347121459497221114766050949090435061493822476265356047392175668050706", "price":"0.01", "size":"4230.07", "side":"BUY", "hash":"90eae709cff6f696e21fbb284ad85ade7f968109", "best_bid":"0.02", "best_ask":"0.03"}, {"asset_id":"96888240988495161476033313796107536512663280794332045579302109906525918376981", "price":"0.99", "size":"4230.07", "side":"SELL", "hash":"592e287805e045b879f53ed3ade26d5701a43860", "best_bid":"0.97", "best_ask":"0.98"}], "timestamp":"1770241464001", "event_type":"price_change"}
{"market":"0x38f3050258345e9cf363d1c8cc302f08c65b96ba1a4669d81e07ed69708344df", "price_changes":[{"asset_id":"96888240988495161476033313796107536512663280794332045579302109906525918376981", "price":"0.96", "size":"827.73", "side":"BUY", "hash":"9f7e54eecec0fdfa53f8076dcf802943ee2b078b", "best_bid":"0.97", "best_ask":"0.98"}, {"asset_id":"81916206347121459497221114766050949090435061493822476265356047392175668050706", "price":"0.04", "size":"827.73", "side":"SELL", "hash":"1401b1a402d9c32f6d7ed15cd2d66261cc2198ac", "best_bid":"0.02", "best_ask":"0.03"}], "timestamp":"1770241464002", "event_type":"price_change"}
{"market":"0x38f3050258345e9cf363d1c8cc302f08c65b96ba1a4669d81e07ed69708344df", "price_changes":[{"asset_id":"81916206347121459497221114766050949090435061493822476265356047392175668050706", "price":"0.01", "size":"4257.07", "side":"BUY", "hash":"659e1cd1a08b69bf8a00ed2dbee595df32d0cc96", "best_bid":"0.02", "best_ask":"0.03"}, {"asset_id":"96888240988495161476033313796107536512663280794332045579302109906525918376981", "price":"0.99", "size":"4257.07", "side":"SELL", "hash":"79f83a9b93201aeae662a7dd274874843f02dad6", "best_bid":"0.97", "best_ask":"0.98"}], "timestamp":"1770241464003", "event_type":"price_change"}
{"market":"0x38f3050258345e9cf363d1c8cc302f08c65b96ba1a4669d81e07ed69708344df", "price_changes":[{"asset_id":"96888240988495161476033313796107536512663280794332045579302109906525918376981", "price":"0.96", "size":"800.73", "side":"BUY", "hash":"65f810c8d056b4c35242c8a5c7cd0951ac3c3cb2", "best_bid":"0.97", "best_ask":"0.98"}, {"asset_id":"81916206347121459497221114766050949090435061493822476265356047392175668050706", "price":"0.04", "size":"800.73", "side":"SELL", "hash":"8fb6e943e16b8d7d611dda150af6eada3144c793", "best_bid":"0.02", "best_ask":"0.03"}], "timestamp":"1770241464003", "event_type":"price_change"}
{"market":"0x38f3050258345e9cf363d1c8cc302f08c65b96ba1a4669d81e07ed69708344df", "price_changes":[{"asset_id":"96888240988495161476033313796107536512663280794332045579302109906525918376981", "price":"0.96", "size":"823.73", "side":"BUY", "hash":"ff044b869e90fd11b2b9da0c0e30dd457005bed1", "best_bid":"0.97", "best_ask":"0.98"}, {"asset_id":"81916206347121459497221114766050949090435061493822476265356047392175668050706", "price":"0.04", "size":"823.73", "side":"SELL", "hash":"7b66e95ad02006f4b4d7d19315704c93c3d7b361", "best_bid":"0.02", "best_ask":"0.03"}], "timestamp":"1770241464043", "event_type":"price_change"}
{"market":"0x38f3050258345e9cf363d1c8cc302f08c65b96ba1a4669d81e07ed69708344df", "price_changes":[{"asset_id":"96888240988495161476033313796107536512663280794332045579302109906525918376981", "price":"0.95", "size":"650", "side":"BUY", "hash":"8a1ac939a36d292c801a673c407d670170e6049b", "best_bid":"0.97", "best_ask":"0.98"}, {"asset_id":"81916206347121459497221114766050949090435061493822476265356047392175668050706", "price":"0.05", "size":"650", "side":"SELL", "hash":"72d97b21804dbe96d5befbeb85b8fc083b63d7f6", "best_bid":"0.02", "best_ask":"0.03"}], "timestamp":"1770241464044", "event_type":"price_change"}
{"market":"0x38f3050258345e9cf363d1c8cc302f08c65b96ba1a4669d81e07ed69708344df", "price_changes":[{"asset_id":"81916206347121459497221114766050949090435061493822476265356047392175668050706", "price":"0.01", "size":"4234.07", "side":"BUY", "hash":"45c7489f0a292ebb1bdab539d22390edb31cc094", "best_bid":"0.02", "best_ask":"0.03"}, {"asset_id":"96888240988495161476033313796107536512663280794332045579302109906525918376981", "price":"0.99", "size":"4234.07", "side":"SELL", "hash":"cf054fd9ebfa51eb9ae6bf275f4a2b74ea994172", "best_bid":"0.97", "best_ask":"0.98"}], "timestamp":"1770241464045", "event_type":"price_change"}
{"market":"0x38f3050258345e9cf363d1c8cc302f08c65b96ba1a4669d81e07ed69708344df", "price_changes":[{"asset_id":"81916206347121459497221114766050949090435061493822476265356047392175668050706", "price":"0.02", "size":"615.22", "side":"BUY", "hash":"c2b410ba0a425023ded2292bc46b7194863ea151", "best_bid":"0.02", "best_ask":"0.03"}, {"asset_id":"96888240988495161476033313796107536512663280794332045579302109906525918376981", "price":"0.98", "size":"615.22", "side":"SELL", "hash":"67803a2ea50f4668296f44c796cb521478cf6bc0", "best_bid":"0.97", "best_ask":"0.98"}], "timestamp":"1770241464053", "event_type":"price_change"}
{"market":"0x38f3050258345e9cf363d1c8cc302f08c65b96ba1a4669d81e07ed69708344df", "price_changes":[{"asset_id":"81916206347121459497221114766050949090435061493822476265356047392175668050706", "price":"0.01", "size":"4261.07", "side":"BUY", "hash":"7f70bf7a66dd11ed3bce524fff2b7dffd67298d2", "best_bid":"0.02", "best_ask":"0.03"}, {"asset_id":"96888240988495161476033313796107536512663280794332045579302109906525918376981", "price":"0.99", "size":"4261.07", "side":"SELL", "hash":"d860e845302afa79c1610d665f56720e43256539", "best_bid":"0.97", "best_ask":"0.98"}], "timestamp":"1770241464103", "event_type":"price_change"}
{"market":"0x38f3050258345e9cf363d1c8cc302f08c65b96ba1a4669d81e07ed69708344df", "price_changes":[{"asset_id":"96888240988495161476033313796107536512663280794332045579302109906525918376981", "price":"0.94", "size":"726", "side":"BUY", "hash":"8648e552005e9fcdbc16e62b9cc05747d772c164", "best_bid":"0.97", "best_ask":"0.98"}, {"asset_id":"81916206347121459497221114766050949090435061493822476265356047392175668050706", "price":"0.06", "size":"726", "side":"SELL", "hash":"f66c96502e3ec9444fd7869f6310a0093d620ad2", "best_bid":"0.02", "best_ask":"0.03"}], "timestamp":"1770241464105", "event_type":"price_change"}
{"market":"0x38f3050258345e9cf363d1c8cc302f08c65b96ba1a4669d81e07ed69708344df", "price_changes":[{"asset_id":"96888240988495161476033313796107536512663280794332045579302109906525918376981", "price":"0.95", "size":"677", "side":"BUY", "hash":"117b334d9b02602958c84fc2ca4b26b28c6e58cd", "best_bid":"0.97", "best_ask":"0.98"}, {"asset_id":"81916206347121459497221114766050949090435061493822476265356047392175668050706", "price":"0.05", "size":"677", "side":"SELL", "hash":"4593d56290acefb51b05201dc8a6d663c132ea2e", "best_bid":"0.02", "best_ask":"0.03"}], "timestamp":"1770241464106", "event_type":"price_change"}
{"market":"0x38f3050258345e9cf363d1c8cc302f08c65b96ba1a4669d81e07ed69708344df", "price_changes":[{"asset_id":"81916206347121459497221114766050949090435061493822476265356047392175668050706", "price":"0.01", "size":"4234.07", "side":"BUY", "hash":"a86f18d775404e8971e5207ed0da0b293578a094", "best_bid":"0.02", "best_ask":"0.03"}, {"asset_id":"96888240988495161476033313796107536512663280794332045579302109906525918376981", "price":"0.99", "size":"4234.07", "side":"SELL", "hash":"e0117dbcf8cbb06893bdb5a062e03926bd29dfc6", "best_bid":"0.97", "best_ask":"0.98"}], "timestamp":"1770241464112", "event_type":"price_change"}
{"market":"0x38f3050258345e9cf363d1c8cc302f08c65b96ba1a4669d81e07ed69708344df", "price_changes":[{"asset_id":"81916206347121459497221114766050949090435061493822476265356047392175668050706", "price":"0.01", "size":"4261.07", "side":"BUY", "hash":"ac0bb05b79614366b09eae3c1bc8cd56f460c499", "best_bid":"0.02", "best_ask":"0.03"}, {"asset_id":"96888240988495161476033313796107536512663280794332045579302109906525918376981", "price":"0.99", "size":"4261.07", "side":"SELL", "hash":"50c90395f5bc6f4ee8faba31e2a90560b2d2a6b5", "best_bid":"0.97", "best_ask":"0.98"}], "timestamp":"1770241464116", "event_type":"price_change"}
{"market":"0x38f3050258345e9cf363d1c8cc302f08c65b96ba1a4669d81e07ed69708344df", "price_changes":[{"asset_id":"96888240988495161476033313796107536512663280794332045579302109906525918376981", "price":"0.95", "size":"704", "side":"BUY", "hash":"18ad955d17dd83c1e89dc0910d488736ba358ddd", "best_bid":"0.97", "best_ask":"0.98"}, {"asset_id":"81916206347121459497221114766050949090435061493822476265356047392175668050706", "price":"0.05", "size":"704", "side":"SELL", "hash":"1bb0e7a295955b649ba9c607f07f24670750a9f7", "best_bid":"0.02", "best_ask":"0.03"}], "timestamp":"1770241464116", "event_type":"price_change"}
{"market":"0x38f3050258345e9cf363d1c8cc302f08c65b96ba1a4669d81e07ed69708344df", "price_changes":[{"asset_id":"81916206347121459497221114766050949090435061493822476265356047392175668050706", "price":"0.01", "size":"4234.07", "side":"BUY", "hash":"4b80b8c99eb3bbc3186d42f81d5c7d98e6d23d35", "best_bid":"0.02", "best_ask":"0.03"}, {"asset_id":"96888240988495161476033313796107536512663280794332045579302109906525918376981", "price":"0.99", "size":"4234.07", "side":"SELL", "hash":"cd229146d68046f419dff9799a12e82a3f58e7dd", "best_bid":"0.97", "best_ask":"0.98"}], "timestamp":"1770241464117", "event_type":"price_change"}
{"market":"0x38f3050258345e9cf363d1c8cc302f08c65b96ba1a4669d81e07ed69708344df", "price_changes":[{"asset_id":"96888240988495161476033313796107536512663280794332045579302109906525918376981", "price":"0.95", "size":"677", "side":"BUY", "hash":"8e3497c744f19c09356156ed4b9d38ef2f5417f6", "best_bid":"0.97", "best_ask":"0.98"}, {"asset_id":"81916206347121459497221114766050949090435061493822476265356047392175668050706", "price":"0.05", "size":"677", "side":"SELL", "hash":"78201c198152a872086b2b2a4de2bc558164930f", "best_bid":"0.02", "best_ask":"0.03"}], "timestamp":"1770241464117", "event_type":"price_change"}
{"market":"0x38f3050258345e9cf363d1c8cc302f08c65b96ba1a4669d81e07ed69708344df", "price_changes":[{"asset_id":"96888240988495161476033313796107536512663280794332045579302109906525918376981", "price":"0.96", "size":"850.73", "side":"BUY", "hash":"b4fb467e071171c8b451b1af58d032bdbf7e407d", "best_bid":"0.97", "best_ask":"0.98"}, {"asset_id":"81916206347121459497221114766050949090435061493822476265356047392175668050706", "price":"0.04", "size":"850.73", "side":"SELL", "hash":"f576d5d2b880b2d165cf54e99f1d4c106ca32b11", "best_bid":"0.02", "best_ask":"0.03"}], "timestamp":"1770241464125", "event_type":"price_change"}
{"market":"0x38f3050258345e9cf363d1c8cc302f08c65b96ba1a4669d81e07ed69708344df", "price_changes":[{"asset_id":"81916206347121459497221114766050949090435061493822476265356047392175668050706", "price":"0.01", "size":"4261.07", "side":"BUY", "hash":"6b7edb42b91b5eac2021927761b842d97c9f92c4", "best_bid":"0.02", "best_ask":"0.03"}, {"asset_id":"96888240988495161476033313796107536512663280794332045579302109906525918376981", "price":"0.99", "size":"4261.07", "side":"SELL", "hash":"ac49a6fc896f1e6093125762949e89d5680e3484", "best_bid":"0.97", "best_ask":"0.98"}], "timestamp":"1770241464128", "event_type":"price_change"}
{"market":"0x38f3050258345e9cf363d1c8cc302f08c65b96ba1a4669d81e07ed69708344df", "price_changes":[{"asset_id":"81916206347121459497221114766050949090435061493822476265356047392175668050706", "price":"0.01", "size":"4234.07", "side":"BUY", "hash":"24a484a09991666e83b251ef9baaafc63f3d8d1b", "best_bid":"0.02", "best_ask":"0.03"}, {"asset_id":"96888240988495161476033313796107536512663280794332045579302109906525918376981", "price":"0.99", "size":"4234.07", "side":"SELL", "hash":"23f56da4e70ac696ef98eb75b5add33a98e55a6b", "best_bid":"0.97", "best_ask":"0.98"}], "timestamp":"1770241464138", "event_type":"price_change"}
{"market":"0x38f3050258345e9cf363d1c8cc302f08c65b96ba1a4669d81e07ed69708344df", "price_changes":[{"asset_id":"96888240988495161476033313796107536512663280794332045579302109906525918376981", "price":"0.96", "size":"823.73", "side":"BUY", "hash":"420d145ff05d8145c62c01745a999f6fa174ff11", "best_bid":"0.97", "best_ask":"0.98"}, {"asset_id":"81916206347121459497221114766050949090435061493822476265356047392175668050706", "price":"0.04", "size":"823.73", "side":"SELL", "hash":"c6634c5aff72dbcb6acc990ee3e59a31f39cf186", "best_bid":"0.02", "best_ask":"0.03"}], "timestamp":"1770241464139", "event_type":"price_change"}
{"market":"0x38f3050258345e9cf363d1c8cc302f08c65b96ba1a4669d81e07ed69708344df", "price_changes":[{"asset_id":"96888240988495161476033313796107536512663280794332045579302109906525918376981", "price":"0.95", "size":"650", "side":"BUY", "hash":"f886df864d36b72d9576ab2dd3ffad7fd67fe9fa", "best_bid":"0.97", "best_ask":"0.98"}, {"asset_id":"81916206347121459497221114766050949090435061493822476265356047392175668050706", "price":"0.05", "size":"650", "side":"SELL", "hash":"7e4a49776b4daa2eb83683a74a5c8e0bc7302933", "best_bid":"0.02", "best_ask":"0.03"}], "timestamp":"1770241464225", "event_type":"price_change"}
{"market":"0x38f3050258345e9cf363d1c8cc302f08c65b96ba1a4669d81e07ed69708344df", "price_changes":[{"asset_id":"81916206347121459497221114766050949090435061493822476265356047392175668050706", "price":"0.01", "size":"4261.07", "side":"BUY", "hash":"84f8778c620f6869fb5bf92d60c3cc98a841164f", "best_bid":"0.02", "best_ask":"0.03"}, {"asset_id":"96888240988495161476033313796107536512663280794332045579302109906525918376981", "price":"0.99", "size":"4261.07", "side":"SELL", "hash":"1aa5512637d491ccadd6c3c8bcf774a36af353c2", "best_bid":"0.97", "best_ask":"0.98"}], "timestamp":"1770241464225", "event_type":"price_change"}
{"market":"0x38f3050258345e9cf363d1c8cc302f08c65b96ba1a4669d81e07ed69708344df", "price_changes":[{"asset_id":"96888240988495161476033313796107536512663280794332045579302109906525918376981", "price":"0.95", "size":"677", "side":"BUY", "hash":"e63a27810e9c92c28f34c4a017b4f5204d483bdd", "best_bid":"0.97", "best_ask":"0.98"}, {"asset_id":"81916206347121459497221114766050949090435061493822476265356047392175668050706", "price":"0.05", "size":"677", "side":"SELL", "hash":"0077ecc26127b0b01560bfb5439960a45b1f20df", "best_bid":"0.02", "best_ask":"0.03"}], "timestamp":"1770241464227", "event_type":"price_change"}
{"market":"0x38f3050258345e9cf363d1c8cc302f08c65b96ba1a4669d81e07ed69708344df", "price_changes":[{"asset_id":"81916206347121459497221114766050949090435061493822476265356047392175668050706", "price":"0.01", "size":"4234.07", "side":"BUY", "hash":"41e5fb1ebb8d8abaca35f87c874541a61f7242a3", "best_bid":"0.02", "best_ask":"0.03"}, {"asset_id":"96888240988495161476033313796107536512663280794332045579302109906525918376981", "price":"0.99", "size":"4234.07", "side":"SELL", "hash":"51527641431df5af5d200a6d0f2570459bc54791", "best_bid":"0.97", "best_ask":"0.98"}], "timestamp":"1770241464228", "event_type":"price_change"}
{"market":"0x38f3050258345e9cf363d1c8cc302f08c65b96ba1a4669d81e07ed69708344df", "price_changes":[{"asset_id":"81916206347121459497221114766050949090435061493822476265356047392175668050706", "price":"0.01", "size":"4207.07", "side":"BUY", "hash":"d9d9d492afccf3abea23101dc0b7556d8de03da9", "best_bid":"0.02", "best_ask":"0.03"}, {"asset_id":"96888240988495161476033313796107536512663280794332045579302109906525918376981", "price":"0.99", "size":"4207.07", "side":"SELL", "hash":"afe4260a3b838737ce295213d0a83961fd100e18", "best_bid":"0.97", "best_ask":"0.98"}], "timestamp":"1770241464242", "event_type":"price_change"}
{"market":"0x38f3050258345e9cf363d1c8cc302f08c65b96ba1a4669d81e07ed69708344df", "price_changes":[{"asset_id":"96888240988495161476033313796107536512663280794332045579302109906525918376981", "price":"0.95", "size":"650", "side":"BUY", "hash":"b34238da3f5ea7dbe9f8422f09b117517b2b787d", "best_bid":"0.97", "best_ask":"0.98"}, {"asset_id":"81916206347121459497221114766050949090435061493822476265356047392175668050706", "price":"0.05", "size":"650", "side":"SELL", "hash":"b0c01c5844052c02763d8152061e8e659ef865d4", "best_bid":"0.02", "best_ask":"0.03"}], "timestamp":"1770241464242", "event_type":"price_change"}
{"market":"0x38f3050258345e9cf363d1c8cc302f08c65b96ba1a4669d81e07ed69708344df", "price_changes":[{"asset_id":"81916206347121459497221114766050949090435061493822476265356047392175668050706", "price":"0.01", "size":"4234.07", "side":"BUY", "hash":"42b4bd063ee79e2d7c6d2cd5fe1b53087344d8a1", "best_bid":"0.02", "best_ask":"0.03"}, {"asset_id":"96888240988495161476033313796107536512663280794332045579302109906525918376981", "price":"0.99", "size":"4234.07", "side":"SELL", "hash":"ae70dc848bf473f914f5c27fe7daea5f998610fe", "best_bid":"0.97", "best_ask":"0.98"}], "timestamp":"1770241464244", "event_type":"price_change"}
{"market":"0x38f3050258345e9cf363d1c8cc302f08c65b96ba1a4669d81e07ed69708344df", "price_changes":[{"asset_id":"96888240988495161476033313796107536512663280794332045579302109906525918376981", "price":"0.95", "size":"677", "side":"BUY", "hash":"413d21bac8d4caa567336c67c7b5483089d64143", "best_bid":"0.97", "best_ask":"0.98"}, {"asset_id":"81916206347121459497221114766050949090435061493822476265356047392175668050706", "price":"0.05", "size":"677", "side":"SELL", "hash":"ed0a9855ba303fd4ea01d0b4f460b08212547860", "best_bid":"0.02", "best_ask":"0.03"}], "timestamp":"1770241464245", "event_type":"price_change"}
{"market":"0x38f3050258345e9cf363d1c8cc302f08c65b96ba1a4669d81e07ed69708344df", "price_changes":[{"asset_id":"81916206347121459497221114766050949090435061493822476265356047392175668050706", "price":"0.01", "size":"4207.07", "side":"BUY", "hash":"c639becede24673eb4785f767c7949881e91fa6c", "best_bid":"0.02", "best_ask":"0.03"}, {"asset_id":"96888240988495161476033313796107536512663280794332045579302109906525918376981", "price":"0.99", "size":"4207.07", "side":"SELL", "hash":"3de1ffd04ac7518af804d1f743af5fd8eabda1c1", "best_bid":"0.97", "best_ask":"0.98"}], "timestamp":"1770241464249", "event_type":"price_change"}
{"market":"0x38f3050258345e9cf363d1c8cc302f08c65b96ba1a4669d81e07ed69708344df", "price_changes":[{"asset_id":"81916206347121459497221114766050949090435061493822476265356047392175668050706", "price":"0.01", "size":"4234.07", "side":"BUY", "hash":"678885dfe57e96713e5c94193264164e9fb2b446", "best_bid":"0.02", "best_ask":"0.03"}, {"asset_id":"96888240988495161476033313796107536512663280794332045579302109906525918376981", "price":"0.99", "size":"4234.07", "side":"SELL", "hash":"233b8258fafa61494e7bdc60c90fd0e440d94040", "best_bid":"0.97", "best_ask":"0.98"}], "timestamp":"1770241464249", "event_type":"price_change"}
{"market":"0x38f3050258345e9cf363d1c8cc302f08c65b96ba1a4669d81e07ed69708344df", "price_changes":[{"asset_id":"96888240988495161476033313796107536512663280794332045579302109906525918376981", "price":"0.96", "size":"850.73", "side":"BUY", "hash":"e86d54cd91beb1bdca7a1754a178a5f11b009746", "best_bid":"0.97", "best_ask":"0.98"}, {"asset_id":"81916206347121459497221114766050949090435061493822476265356047392175668050706", "price":"0.04", "size":"850.73", "side":"SELL", "hash":"026843e8e36d566375681430689c107d1378b31a", "best_bid":"0.02", "best_ask":"0.03"}], "timestamp":"1770241464251", "event_type":"price_change"}
{"market":"0x38f3050258345e9cf363d1c8cc302f08c65b96ba1a4669d81e07ed69708344df", "price_changes":[{"asset_id":"96888240988495161476033313796107536512663280794332045579302109906525918376981", "price":"0.96", "size":"823.73", "side":"BUY", "hash":"8ec6da87edee3bdd0e4f72bf9251771eb546be16", "best_bid":"0.97", "best_ask":"0.98"}, {"asset_id":"81916206347121459497221114766050949090435061493822476265356047392175668050706", "price":"0.04", "size":"823.73", "side":"SELL", "hash":"b41b4df5fd39c9b527a0cea7b2ad21995f92abbb", "best_bid":"0.02", "best_ask":"0.03"}], "timestamp":"1770241464269", "event_type":"price_change"}
{"market":"0x38f3050258345e9cf363d1c8cc302f08c65b96ba1a4669d81e07ed69708344df", "price_changes":[{"asset_id":"96888240988495161476033313796107536512663280794332045579302109906525918376981", "price":"0.97", "size":"432", "side":"BUY", "hash":"a857f79158a274286ae2ab2092fbc177a60100ea", "best_bid":"0.97", "best_ask":"0.98"}, {"asset_id":"81916206347121459497221114766050949090435061493822476265356047392175668050706", "price":"0.03", "size":"432", "side":"SELL", "hash":"1adefdbbf275ec2b13d6b7108e4553c5bea9bf6d", "best_bid":"0.02", "best_ask":"0.03"}], "timestamp":"1770241464330", "event_type":"price_change"}
{"market":"0x38f3050258345e9cf363d1c8cc302f08c65b96ba1a4669d81e07ed69708344df", "asset_id":"81916206347121459497221114766050949090435061493822476265356047392175668050706", "bids":[{"price":"0.01", "size":"4234.07"}, {"price":"0.02", "size":"615.22"}], "asks":[{"price":"0.99", "size":"5019.91"}, {"price":"0.98", "size":"3034.23"}, {"price":"0.97", "size":"3172"}, {"price":"0.96", "size":"3012"}, {"price":"0.95", "size":"3032"}, {"price":"0.94", "size":"3012"}, {"price":"0.93", "size":"3126.28"}, {"price":"0.92", "size":"3012"}, {"price":"0.91", "size":"3012"}, {"price":"0.9", "size":"3087"}, {"price":"0.89", "size":"12"}, {"price":"0.88", "size":"12"}, {"price":"0.87", "size":"12"}, {"price":"0.86", "size":"12"}, {"price":"0.85", "size":"12"}, {"price":"0.84", "size":"12"}, {"price":"0.83", "size":"12"}, {"price":"0.82", "size":"12"}, {"price":"0.81", "size":"12"}, {"price":"0.8", "size":"12"}, {"price":"0.79", "size":"12"}, {"price":"0.78", "size":"12"}, {"price":"0.77", "size":"12"}, {"price":"0.76", "size":"112"}, {"price":"0.75", "size":"40.57"}, {"price":"0.74", "size":"12"}, {"price":"0.73", "size":"293.25"}, {"price":"0.72", "size":"22"}, {"price":"0.71", "size":"12"}, {"price":"0.7", "size":"18"}, {"price":"0.69", "size":"12"}, {"price":"0.68", "size":"12"}, {"price":"0.67", "size":"12"}, {"price":"0.66", "size":"160.89"}, {"price":"0.65", "size":"12"}, {"price":"0.64", "size":"12"}, {"price":"0.63", "size":"12"}, {"price":"0.62", "size":"19.39"}, {"price":"0.61", "size":"18.04"}, {"price":"0.6", "size":"12"}, {"price":"0.59", "size":"94.31"}, {"price":"0.58", "size":"5450.54"}, {"price":"0.57", "size":"12"}, {"price":"0.56", "size":"12"}, {"price":"0.55", "size":"12"}, {"price":"0.54", "size":"22"}, {"price":"0.53", "size":"12"}, {"price":"0.52", "size":"12"}, {"price":"0.51", "size":"12"}, {"price":"0.5", "size":"12"}, {"price":"0.49", "size":"12"}, {"price":"0.48", "size":"12"}, {"price":"0.47", "size":"12"}, {"price":"0.46", "size":"485.56"}, {"price":"0.45", "size":"31"}, {"price":"0.44", "size":"17"}, {"price":"0.43", "size":"12"}, {"price":"0.42", "size":"12"}, {"price":"0.41", "size":"12"}, {"price":"0.4", "size":"127"}, {"price":"0.39", "size":"12"}, {"price":"0.38", "size":"94.51"}, {"price":"0.37", "size":"31.99"}, {"price":"0.36", "size":"12"}, {"price":"0.35", "size":"37"}, {"price":"0.34", "size":"12"}, {"price":"0.33", "size":"12"}, {"price":"0.32", "size":"12"}, {"price":"0.31", "size":"12"}, {"price":"0.3", "size":"31.9"}, {"price":"0.29", "size":"344"}, {"price":"0.28", "size":"3488.99"}, {"price":"0.27", "size":"212"}, {"price":"0.26", "size":"718"}, {"price":"0.25", "size":"212"}, {"price":"0.24", "size":"212"}, {"price":"0.23", "size":"212"}, {"price":"0.22", "size":"1223.14"}, {"price":"0.21", "size":"212"}, {"price":"0.2", "size":"272.99"}, {"price":"0.19", "size":"212"}, {"price":"0.18", "size":"212"}, {"price":"0.17", "size":"212"}, {"price":"0.16", "size":"812"}, {"price":"0.15", "size":"231.08"}, {"price":"0.14", "size":"283.65"}, {"price":"0.13", "size":"212"}, {"price":"0.12", "size":"252"}, {"price":"0.11", "size":"252"}, {"price":"0.1", "size":"746.71"}, {"price":"0.09", "size":"326"}, {"price":"0.08", "size":"844.68"}, {"price":"0.07", "size":"826"}, {"price":"0.06", "size":"726"}, {"price":"0.05", "size":"677"}, {"price":"0.04", "size":"823.73"}, {"price":"0.03", "size":"432"}], "hash":"1adefdbbf275ec2b13d6b7108e4553c5bea9bf6d", "timestamp":"1770241464330", "event_type":"book"}
{"market":"0x38f3050258345e9cf363d1c8cc302f08c65b96ba1a4669d81e07ed69708344df", "price_changes":[{"asset_id":"96888240988495161476033313796107536512663280794332045579302109906525918376981", "price":"0.76", "size":"412", "side":"BUY", "hash":"d74a426306cebc7f2d5c5d8efec6da7567d1a93a", "best_bid":"0.97", "best_ask":"0.98"}, {"asset_id":"81916206347121459497221114766050949090435061493822476265356047392175668050706", "price":"0.24", "size":"412", "side":"SELL", "hash":"c5490a6204e738e04a51711868d32a3d4611e279", "best_bid":"0.02", "best_ask":"0.03"}], "timestamp":"1770241464332", "event_type":"price_change"}
{"market":"0x38f3050258345e9cf363d1c8cc302f08c65b96ba1a4669d81e07ed69708344df", "price_changes":[{"asset_id":"81916206347121459497221114766050949090435061493822476265356047392175668050706", "price":"0.01", "size":"4207.07", "side":"BUY", "hash":"f6ebf835edf7da7504b01998bdbfccdca1ae55a8", "best_bid":"0.02", "best_ask":"0.03"}, {"asset_id":"96888240988495161476033313796107536512663280794332045579302109906525918376981", "price":"0.99", "size":"4207.07", "side":"SELL", "hash":"1db07295e6b7b6d021612d905cd2477eb5ca524d", "best_bid":"0.97", "best_ask":"0.98"}], "timestamp":"1770241464345", "event_type":"price_change"}
{"market":"0x38f3050258345e9cf363d1c8cc302f08c65b96ba1a4669d81e07ed69708344df", "price_changes":[{"asset_id":"96888240988495161476033313796107536512663280794332045579302109906525918376981", "price":"0.95", "size":"704", "side":"BUY", "hash":"df66ef9681cee31bf19b711b318b29790d53d063", "best_bid":"0.97", "best_ask":"0.98"}, {"asset_id":"81916206347121459497221114766050949090435061493822476265356047392175668050706", "price":"0.05", "size":"704", "side":"SELL", "hash":"bc3ff76a9f47a045430b3cb162d99380fb47ba08", "best_bid":"0.02", "best_ask":"0.03"}], "timestamp":"1770241464346", "event_type":"price_change"}
{"market":"0x38f3050258345e9cf363d1c8cc302f08c65b96ba1a4669d81e07ed69708344df", "price_changes":[{"asset_id":"81916206347121459497221114766050949090435061493822476265356047392175668050706", "price":"0.01", "size":"4234.07", "side":"BUY", "hash":"4bec2db009efd2264183ca5950bef2efdbd59167", "best_bid":"0.02", "best_ask":"0.03"}, {"asset_id":"96888240988495161476033313796107536512663280794332045579302109906525918376981", "price":"0.99", "size":"4234.07", "side":"SELL", "hash":"507b074a60575c090a200964fbbfc561b5b1917a", "best_bid":"0.97", "best_ask":"0.98"}], "timestamp":"1770241464346", "event_type":"price_change"}
{"market":"0x38f3050258345e9cf363d1c8cc302f08c65b96ba1a4669d81e07ed69708344df", "price_changes":[{"asset_id":"96888240988495161476033313796107536512663280794332045579302109906525918376981", "price":"0.95", "size":"677", "side":"BUY", "hash":"77cea6a35efc44874475be7ff983a820e8ae629c", "best_bid":"0.97", "best_ask":"0.98"}, {"asset_id":"81916206347121459497221114766050949090435061493822476265356047392175668050706", "price":"0.05", "size":"677", "side":"SELL", "hash":"46cd3a0ebadf4242cc717d5183aca9cfa086d208", "best_bid":"0.02", "best_ask":"0.03"}], "timestamp":"1770241464347", "event_type":"price_change"}
{"market":"0x38f3050258345e9cf363d1c8cc302f08c65b96ba1a4669d81e07ed69708344df", "asset_id":"81916206347121459497221114766050949090435061493822476265356047392175668050706", "price":"0.03", "size":"200", "fee_rate_bps":"0", "side":"BUY", "timestamp":"1770241464362", "event_type":"last_trade_price", "transaction_hash":"0x3023669df42248084dedfebaa17717b785d979f7e3c3723140ef10f7f40ab3fd"}
{"market":"0x38f3050258345e9cf363d1c8cc302f08c65b96ba1a4669d81e07ed69708344df", "price_changes":[{"asset_id":"96888240988495161476033313796107536512663280794332045579302109906525918376981", "price":"0.98", "size":"613.72", "side":"SELL", "hash":"1b49619cd7c4ecd8babfdbd5334266510717e058", "best_bid":"0.97", "best_ask":"0.98"}, {"asset_id":"81916206347121459497221114766050949090435061493822476265356047392175668050706", "price":"0.02", "size":"613.72", "side":"BUY", "hash":"27cb2b97f0bc2ce49b5d9b40ea69baad3d8bb7da", "best_bid":"0.02", "best_ask":"0.03"}], "timestamp":"1770241464373", "event_type":"price_change"}
{"market":"0x38f3050258345e9cf363d1c8cc302f08c65b96ba1a4669d81e07ed69708344df", "asset_id":"81916206347121459497221114766050949090435061493822476265356047392175668050706", "bids":[{"price":"0.01", "size":"4234.07"}, {"price":"0.02", "size":"613.72"}], "asks":[{"price":"0.99", "size":"5019.91"}, {"price":"0.98", "size":"3034.23"}, {"price":"0.97", "size":"3172"}, {"price":"0.96", "size":"3012"}, {"price":"0.95", "size":"3032"}, {"price":"0.94", "size":"3012"}, {"price":"0.93", "size":"3126.28"}, {"price":"0.92", "size":"3012"}, {"price":"0.91", "size":"3012"}, {"price":"0.9", "size":"3087"}, {"price":"0.89", "size":"12"}, {"price":"0.88", "size":"12"}, {"price":"0.87", "size":"12"}, {"price":"0.86", "size":"12"}, {"price":"0.85", "size":"12"}, {"price":"0.84", "size":"12"}, {"price":"0.83", "size":"12"}, {"price":"0.82", "size":"12"}, {"price":"0.81", "size":"12"}, {"price":"0.8", "size":"12"}, {"price":"0.79", "size":"12"}, {"price":"0.78", "size":"12"}, {"price":"0.77", "size":"12"}, {"price":"0.76", "size":"112"}, {"price":"0.75", "size":"40.57"}, {"price":"0.74", "size":"12"}, {"price":"0.73", "size":"293.25"}, {"price":"0.72", "size":"22"}, {"price":"0.71", "size":"12"}, {"price":"0.7", "size":"18"}, {"price":"0.69", "size":"12"}, {"price":"0.68", "size":"12"}, {"price":"0.67", "size":"12"}, {"price":"0.66", "size":"160.89"}, {"price":"0.65", "size":"12"}, {"price":"0.64", "size":"12"}, {"price":"0.63", "size":"12"}, {"price":"0.62", "size":"19.39"}, {"price":"0.61", "size":"18.04"}, {"price":"0.6", "size":"12"}, {"price":"0.59", "size":"94.31"}, {"price":"0.58", "size":"5450.54"}, {"price":"0.57", "size":"12"}, {"price":"0.56", "size":"12"}, {"price":"0.55", "size":"12"}, {"price":"0.54", "size":"22"}, {"price":"0.53", "size":"12"}, {"price":"0.52", "size":"12"}, {"price":"0.51", "size":"12"}, {"price":"0.5", "size":"12"}, {"price":"0.49", "size":"12"}, {"price":"0.48", "size":"12"}, {"price":"0.47", "size":"12"}, {"price":"0.46", "size":"485.56"}, {"price":"0.45", "size":"31"}, {"price":"0.44", "size":"17"}, {"price":"0.43", "size":"12"}, {"price":"0.42", "size":"12"}, {"price":"0.41", "size":"12"}, {"price":"0.4", "size":"127"}, {"price":"0.39", "size":"12"}, {"price":"0.38", "size":"94.51"}, {"price":"0.37", "size":"31.99"}, {"price":"0.36", "size":"12"}, {"price":"0.35", "size":"37"}, {"price":"0.34", "size":"12"}, {"price":"0.33", "size":"12"}, {"price":"0.32", "size":"12"}, {"price":"0.31", "size":"12"}, {"price":"0.3", "size":"31.9"}, {"price":"0.29", "size":"344"}, {"price":"0.28", "size":"3488.99"}, {"price":"0.27", "size":"212"}, {"price":"0.26", "size":"718"}, {"price":"0.25", "size":"212"}, {"price":"0.24", "size":"412"}, {"price":"0.23", "size":"212"}, {"price":"0.22", "size":"1223.14"}, {"price":"0.21", "size":"212"}, {"price":"0.2", "size":"272.99"}, {"price":"0.19", "size":"212"}, {"price":"0.18", "size":"212"}, {"price":"0.17", "size":"212"}, {"price":"0.16", "size":"812"}, {"price":"0.15", "size":"231.08"}, {"price":"0.14", "size":"283.65"}, {"price":"0.13", "size":"212"}, {"price":"0.12", "size":"252"}, {"price":"0.11", "size":"252"}, {"price":"0.1", "size":"746.71"}, {"price":"0.09", "size":"326"}, {"price":"0.08", "size":"844.68"}, {"price":"0.07", "size":"826"}, {"price":"0.06", "size":"726"}, {"price":"0.05", "size":"677"}, {"price":"0.04", "size":"823.73"}, {"price":"0.03", "size":"432"}], "hash":"27cb2b97f0bc2ce49b5d9b40ea69baad3d8bb7da", "timestamp":"1770241464373", "event_type":"book"}
{"market":"0x38f3050258345e9cf363d1c8cc302f08c65b96ba1a4669d81e07ed69708344df", "price_changes":[{"asset_id":"81916206347121459497221114766050949090435061493822476265356047392175668050706", "price":"0.01", "size":"4207.07", "side":"BUY", "hash":"adbd51b305396a286a4c5f6465a6a0bc5ef6b97d", "best_bid":"0.02", "best_ask":"0.03"}, {"asset_id":"96888240988495161476033313796107536512663280794332045579302109906525918376981", "price":"0.99", "size":"4207.07", "side":"SELL", "hash":"eb82b92d3749262439ab42d0b12042b1fcd16938", "best_bid":"0.97", "best_ask":"0.98"}], "timestamp":"1770241464435", "event_type":"price_change"}
{"market":"0x38f3050258345e9cf363d1c8cc302f08c65b96ba1a4669d81e07ed69708344df", "price_changes":[{"asset_id":"81916206347121459497221114766050949090435061493822476265356047392175668050706", "price":"0.02", "size":"590.72", "side":"BUY", "hash":"55ab3a6528af7b185f47d2b33ab38ec86cb16711", "best_bid":"0.02", "best_ask":"0.03"}, {"asset_id":"96888240988495161476033313796107536512663280794332045579302109906525918376981", "price":"0.98", "size":"590.72", "side":"SELL", "hash":"4b9ad9f2e671a3e43d0f6a2540cea911ff762172", "best_bid":"0.97", "best_ask":"0.98"}], "timestamp":"1770241464437", "event_type":"price_change"}
{"market":"0x38f3050258345e9cf363d1c8cc302f08c65b96ba1a4669d81e07ed69708344df", "price_changes":[{"asset_id":"81916206347121459497221114766050949090435061493822476265356047392175668050706", "price":"0.01", "size":"4234.07", "side":"BUY", "hash":"a76a31d698c6910ea9574c50168a39fd34b39711", "best_bid":"0.02", "best_ask":"0.03"}, {"asset_id":"96888240988495161476033313796107536512663280794332045579302109906525918376981", "price":"0.99", "size":"4234.07", "side":"SELL", "hash":"27330e82ab101a7f7dc63eba10d1527b60f67f23", "best_bid":"0.97", "best_ask":"0.98"}], "timestamp":"1770241464438", "event_type":"price_change"}
{"market":"0x38f3050258345e9cf363d1c8cc302f08c65b96ba1a4669d81e07ed69708344df", "price_changes":[{"asset_id":"96888240988495161476033313796107536512663280794332045579302109906525918376981", "price":"0.97", "size":"455", "side":"BUY", "hash":"a4e55ff14b62228df61c65549ec799dbe6341fb6", "best_bid":"0.97", "best_ask":"0.98"}, {"asset_id":"81916206347121459497221114766050949090435061493822476265356047392175668050706", "price":"0.03", "size":"455", "side":"SELL", "hash":"ee0aa121fd565e4fefc2ec13be358250613df351", "best_bid":"0.02", "best_ask":"0.03"}], "timestamp":"1770241464439", "event_type":"price_change"}
{"market":"0x38f3050258345e9cf363d1c8cc302f08c65b96ba1a4669d81e07ed69708344df", "price_changes":[{"asset_id":"96888240988495161476033313796107536512663280794332045579302109906525918376981", "price":"0.95", "size":"704", "side":"BUY", "hash":"dc27b1f4563ecc975d5616cccbb4176f9b16d3d1", "best_bid":"0.97", "best_ask":"0.98"}, {"asset_id":"81916206347121459497221114766050949090435061493822476265356047392175668050706", "price":"0.05", "size":"704", "side":"SELL", "hash":"1f6329b551cfccbf52e95cc05cb57547d8509cde", "best_bid":"0.02", "best_ask":"0.03"}], "timestamp":"1770241464440", "event_type":"price_change"}
{"market":"0x38f3050258345e9cf363d1c8cc302f08c65b96ba1a4669d81e07ed69708344df", "price_changes":[{"asset_id":"96888240988495161476033313796107536512663280794332045579302109906525918376981", "price":"0.95", "size":"677", "side":"BUY", "hash":"4481f07bffa311929bf99939771e607f024b86fc", "best_bid":"0.97", "best_ask":"0.98"}, {"asset_id":"81916206347121459497221114766050949090435061493822476265356047392175668050706", "price":"0.05", "size":"677", "side":"SELL", "hash":"63d70f607b555b69a4c6d8b8fca3d428315fb6ab", "best_bid":"0.02", "best_ask":"0.03"}], "timestamp":"1770241464440", "event_type":"price_change"}
{"market":"0x38f3050258345e9cf363d1c8cc302f08c65b96ba1a4669d81e07ed69708344df", "price_changes":[{"asset_id":"96888240988495161476033313796107536512663280794332045579302109906525918376981", "price":"0.96", "size":"800.73", "side":"BUY", "hash":"f83e3018343758f82eb65a6019517cf0ea4a0cbf", "best_bid":"0.97", "best_ask":"0.98"}, {"asset_id":"81916206347121459497221114766050949090435061493822476265356047392175668050706", "price":"0.04", "size":"800.73", "side":"SELL", "hash":"98f107ec080523dfa9d066a6bfdfcffbd7d83b1e", "best_bid":"0.02", "best_ask":"0.03"}], "timestamp":"1770241464441", "event_type":"price_change"}
{"market":"0x38f3050258345e9cf363d1c8cc302f08c65b96ba1a4669d81e07ed69708344df", "price_changes":[{"asset_id":"81916206347121459497221114766050949090435061493822476265356047392175668050706", "price":"0.01", "size":"4257.07", "side":"BUY", "hash":"15f881fb3589e2c82a21d39d6fa2daae3d058824", "best_bid":"0.02", "best_ask":"0.03"}, {"asset_id":"96888240988495161476033313796107536512663280794332045579302109906525918376981", "price":"0.99", "size":"4257.07", "side":"SELL", "hash":"623da36c68d0791e8f4c4ee7cbf38d675e7d8b4f", "best_bid":"0.97", "best_ask":"0.98"}], "timestamp":"1770241464443", "event_type":"price_change"}
{"market":"0x38f3050258345e9cf363d1c8cc302f08c65b96ba1a4669d81e07ed69708344df", "price_changes":[{"asset_id":"96888240988495161476033313796107536512663280794332045579302109906525918376981", "price":"0.96", "size":"773.73", "side":"BUY", "hash":"6c08974c09731e931f07e011f111577895721703", "best_bid":"0.97", "best_ask":"0.98"}, {"asset_id":"81916206347121459497221114766050949090435061493822476265356047392175668050706", "price":"0.04", "size":"773.73", "side":"SELL", "hash":"3546181b0588ae42894c590d0bea90625ca455b7", "best_bid":"0.02", "best_ask":"0.03"}], "timestamp":"1770241464444", "event_type":"price_change"}
{"market":"0x38f3050258345e9cf363d1c8cc302f08c65b96ba1a4669d81e07ed69708344df", "price_changes":[{"asset_id":"81916206347121459497221114766050949090435061493822476265356047392175668050706", "price":"0.01", "size":"4284.07", "side":"BUY", "hash":"657c4fbd5a288c4a8b0f14119052e493c6a975fd", "best_bid":"0.02", "best_ask":"0.03"}, {"asset_id":"96888240988495161476033313796107536512663280794332045579302109906525918376981", "price":"0.99", "size":"4284.07", "side":"SELL", "hash":"1250727bee9ad1adac535ffbb8ba09d924321320", "best_bid":"0.97", "best_ask":"0.98"}], "timestamp":"1770241464445", "event_type":"price_change"}
{"market":"0x38f3050258345e9cf363d1c8cc302f08c65b96ba1a4669d81e07ed69708344df", "price_changes":[{"asset_id":"96888240988495161476033313796107536512663280794332045579302109906525918376981", "price":"0.97", "size":"482", "side":"BUY", "hash":"e01d069564b61a34cffc9a2c0eb825360fb15536", "best_bid":"0.97", "best_ask":"0.98"}, {"asset_id":"81916206347121459497221114766050949090435061493822476265356047392175668050706", "price":"0.03", "size":"482", "side":"SELL", "hash":"8bc96417a6aa6b9fa4f179f8775e68e417e4caf8", "best_bid":"0.02", "best_ask":"0.03"}], "timestamp":"1770241464447", "event_type":"price_change"}
{"market":"0x38f3050258345e9cf363d1c8cc302f08c65b96ba1a4669d81e07ed69708344df", "price_changes":[{"asset_id":"81916206347121459497221114766050949090435061493822476265356047392175668050706", "price":"0.01", "size":"4257.07", "side":"BUY", "hash":"a6f8be0960ab905ea98bb3e6368cb89a34e1acce", "best_bid":"0.02", "best_ask":"0.03"}, {"asset_id":"96888240988495161476033313796107536512663280794332045579302109906525918376981", "price":"0.99", "size":"4257.07", "side":"SELL", "hash":"4c0a4f31c11c4a8d437b4ca163339de1878076f7", "best_bid":"0.97", "best_ask":"0.98"}], "timestamp":"1770241464453", "event_type":"price_change"}
{"market":"0x38f3050258345e9cf363d1c8cc302f08c65b96ba1a4669d81e07ed69708344df", "price_changes":[{"asset_id":"96888240988495161476033313796107536512663280794332045579302109906525918376981", "price":"0.95", "size":"650", "side":"BUY", "hash":"403371a0a4b11264466fe91294201d72c7585e28", "best_bid":"0.97", "best_ask":"0.98"}, {"asset_id":"81916206347121459497221114766050949090435061493822476265356047392175668050706", "price":"0.05", "size":"650", "side":"SELL", "hash":"2d1176375c759de1339717a563bb7fdc18a83ac4", "best_bid":"0.02", "best_ask":"0.03"}], "timestamp":"1770241464465", "event_type":"price_change"}
{"market":"0x38f3050258345e9cf363d1c8cc302f08c65b96ba1a4669d81e07ed69708344df", "price_changes":[{"asset_id":"96888240988495161476033313796107536512663280794332045579302109906525918376981", "price":"0.95", "size":"677", "side":"BUY", "hash":"32f548a903b7ac0dd8f1675349d1f59564ba3a83", "best_bid":"0.97", "best_ask":"0.98"}, {"asset_id":"81916206347121459497221114766050949090435061493822476265356047392175668050706", "price":"0.05", "size":"677", "side":"SELL", "hash":"f84e4e3bb89dcb86eef4b722d91b64240c66dfce", "best_bid":"0.02", "best_ask":"0.03"}], "timestamp":"1770241464466", "event_type":"price_change"}
{"market":"0x38f3050258345e9cf363d1c8cc302f08c65b96ba1a4669d81e07ed69708344df", "price_changes":[{"asset_id":"81916206347121459497221114766050949090435061493822476265356047392175668050706", "price":"0.01", "size":"4230.07", "side":"BUY", "hash":"619efbb01b43e0c3f0030f04309f6ed5f9e8e1d5", "best_bid":"0.02", "best_ask":"0.03"}, {"asset_id":"96888240988495161476033313796107536512663280794332045579302109906525918376981", "price":"0.99", "size":"4230.07", "side":"SELL", "hash":"3650b2c8bdec1a3be8aeba57fc3f6148ee23c14a", "best_bid":"0.97", "best_ask":"0.98"}], "timestamp":"1770241464466", "event_type":"price_change"}
{"market":"0x38f3050258345e9cf363d1c8cc302f08c65b96ba1a4669d81e07ed69708344df", "price_changes":[{"asset_id":"81916206347121459497221114766050949090435061493822476265356047392175668050706", "price":"0.01", "size":"4257.07", "side":"BUY", "hash":"390734c8e7fa488c0676783ffad43d7c6119c680", "best_bid":"0.02", "best_ask":"0.03"}, {"asset_id":"96888240988495161476033313796107536512663280794332045579302109906525918376981", "price":"0.99", "size":"4257.07", "side":"SELL", "hash":"49a8458c15ffff9f68e6ddf5547c8c535cf8d481", "best_bid":"0.97", "best_ask":"0.98"}], "timestamp":"1770241464469", "event_type":"price_change"}
{"market":"0x38f3050258345e9cf363d1c8cc302f08c65b96ba1a4669d81e07ed69708344df", "price_changes":[{"asset_id":"96888240988495161476033313796107536512663280794332045579302109906525918376981", "price":"0.95", "size":"650", "side":"BUY", "hash":"6be4ca018c54a559923323969249fbac18b86eb2", "best_bid":"0.97", "best_ask":"0.98"}, {"asset_id":"81916206347121459497221114766050949090435061493822476265356047392175668050706", "price":"0.05", "size":"650", "side":"SELL", "hash":"844e9f5cf8872cfad58c6d51c1040e00f7e68da4", "best_bid":"0.02", "best_ask":"0.03"}], "timestamp":"1770241464566", "event_type":"price_change"}
{"market":"0x38f3050258345e9cf363d1c8cc302f08c65b96ba1a4669d81e07ed69708344df", "price_changes":[{"asset_id":"81916206347121459497221114766050949090435061493822476265356047392175668050706", "price":"0.01", "size":"4230.07", "side":"BUY", "hash":"7f3056ae54f79ad0f209df63d4b1da6690489fca", "best_bid":"0.02", "best_ask":"0.03"}, {"asset_id":"96888240988495161476033313796107536512663280794332045579302109906525918376981", "price":"0.99", "size":"4230.07", "side":"SELL", "hash":"35801784f0d27010a4b4f7bbabc04f62223ab09c", "best_bid":"0.97", "best_ask":"0.98"}], "timestamp":"1770241464567", "event_type":"price_change"}
{"market":"0x38f3050258345e9cf363d1c8cc302f08c65b96ba1a4669d81e07ed69708344df", "price_changes":[{"asset_id":"81916206347121459497221114766050949090435061493822476265356047392175668050706", "price":"0.01", "size":"4257.07", "side":"BUY", "hash":"9d596cbc684b4fb366e80a24fad9157bf9bdeb78", "best_bid":"0.02", "best_ask":"0.03"}, {"asset_id":"96888240988495161476033313796107536512663280794332045579302109906525918376981", "price":"0.99", "size":"4257.07", "side":"SELL", "hash":"d841ce1851ad01de41d9fcad0292295ab14b2c4d", "best_bid":"0.97", "best_ask":"0.98"}], "timestamp":"1770241464567", "event_type":"price_change"}
{"market":"0x38f3050258345e9cf363d1c8cc302f08c65b96ba1a4669d81e07ed69708344df", "price_changes":[{"asset_id":"96888240988495161476033313796107536512663280794332045579302109906525918376981", "price":"0.95", "size":"677", "side":"BUY", "hash":"5bb3f172dd4eea1280664bd8798695099cb58c59", "best_bid":"0.97", "best_ask":"0.98"}, {"asset_id":"81916206347121459497221114766050949090435061493822476265356047392175668050706", "price":"0.05", "size":"677", "side":"SELL", "hash":"2206daa63e7420928224644cc0d1cad8fd829884", "best_bid":"0.02", "best_ask":"0.03"}], "timestamp":"1770241464569", "event_type":"price_change"}
{"market":"0x38f3050258345e9cf363d1c8cc302f08c65b96ba1a4669d81e07ed69708344df", "price_changes":[{"asset_id":"96888240988495161476033313796107536512663280794332045579302109906525918376981", "price":"0.97", "size":"455", "side":"BUY", "hash":"b8453fb7e6e2426474a6f19c986591d1b3dc3cb8", "best_bid":"0.97", "best_ask":"0.98"}, {"asset_id":"81916206347121459497221114766050949090435061493822476265356047392175668050706", "price":"0.03", "size":"455", "side":"SELL", "hash":"6ea4f8bfc0269d68f9e5308fe7b38334cd358501", "best_bid":"0.02", "best_ask":"0.03"}], "timestamp":"1770241464570", "event_type":"price_change"}
{"market":"0x38f3050258345e9cf363d1c8cc302f08c65b96ba1a4669d81e07ed69708344df", "price_changes":[{"asset_id":"81916206347121459497221114766050949090435061493822476265356047392175668050706", "price":"0.01", "size":"4230.07", "side":"BUY", "hash":"553053b421ffba27c83530b838203c1b33c63fc0", "best_bid":"0.02", "best_ask":"0.03"}, {"asset_id":"96888240988495161476033313796107536512663280794332045579302109906525918376981", "price":"0.99", "size":"4230.07", "side":"SELL", "hash":"5088ff273b8d862da318cf0074273c97743366e0", "best_bid":"0.97", "best_ask":"0.98"}], "timestamp":"1770241464571", "event_type":"price_change"}
{"market":"0x38f3050258345e9cf363d1c8cc302f08c65b96ba1a4669d81e07ed69708344df", "price_changes":[{"asset_id":"96888240988495161476033313796107536512663280794332045579302109906525918376981", "price":"0.96", "size":"800.73", "side":"BUY", "hash":"0aea1db3298853ced1405dda277f9b2dfc3d8088", "best_bid":"0.97", "best_ask":"0.98"}, {"asset_id":"81916206347121459497221114766050949090435061493822476265356047392175668050706", "price":"0.04", "size":"800.73", "side":"SELL", "hash":"4227db0ff6cc0ab17e7f8602acb2844c11be1d1a", "best_bid":"0.02", "best_ask":"0.03"}], "timestamp":"1770241464574", "event_type":"price_change"}
{"market":"0x38f3050258345e9cf363d1c8cc302f08c65b96ba1a4669d81e07ed69708344df", "price_changes":[{"asset_id":"81916206347121459497221114766050949090435061493822476265356047392175668050706", "price":"0.01", "size":"4257.07", "side":"BUY", "hash":"4a142c11ed90242b4d7c8f1f856daa89759ff1b3", "best_bid":"0.02", "best_ask":"0.03"}, {"asset_id":"96888240988495161476033313796107536512663280794332045579302109906525918376981", "price":"0.99", "size":"4257.07", "side":"SELL", "hash":"16e84c3240aaa60cc1525c8a463332760102445c", "best_bid":"0.97", "best_ask":"0.98"}], "timestamp":"1770241464575", "event_type":"price_change"}
{"market":"0x38f3050258345e9cf363d1c8cc302f08c65b96ba1a4669d81e07ed69708344df", "price_changes":[{"asset_id":"96888240988495161476033313796107536512663280794332045579302109906525918376981", "price":"0.95", "size":"650", "side":"BUY", "hash":"822cada789b60afcd96d0e508a0bf7258c7e98f1", "best_bid":"0.97", "best_ask":"0.98"}, {"asset_id":"81916206347121459497221114766050949090435061493822476265356047392175668050706", "price":"0.05", "size":"650", "side":"SELL", "hash":"87f3787e5dd7ea85e9cfbedc354ec623b73edb29", "best_bid":"0.02", "best_ask":"0.03"}], "timestamp":"1770241464583", "event_type":"price_change"}
{"market":"0x38f3050258345e9cf363d1c8cc302f08c65b96ba1a4669d81e07ed69708344df", "price_changes":[{"asset_id":"96888240988495161476033313796107536512663280794332045579302109906525918376981", "price":"0.94", "size":"753", "side":"BUY", "hash":"9433275d53e14415af83b68ffde710495e948cb7", "best_bid":"0.97", "best_ask":"0.98"}, {"asset_id":"81916206347121459497221114766050949090435061493822476265356047392175668050706", "price":"0.06", "size":"753", "side":"SELL", "hash":"92acf3b232bad117ea163cc2d301d359cc984d78", "best_bid":"0.02", "best_ask":"0.03"}], "timestamp":"1770241464588", "event_type":"price_change"}
{"market":"0x38f3050258345e9cf363d1c8cc302f08c65b96ba1a4669d81e07ed69708344df", "price_changes":[{"asset_id":"96888240988495161476033313796107536512663280794332045579302109906525918376981", "price":"0.96", "size":"823.73", "side":"BUY", "hash":"84c5528aea5537970d09fca01b37f32058e56d33", "best_bid":"0.97", "best_ask":"0.98"}, {"asset_id":"81916206347121459497221114766050949090435061493822476265356047392175668050706", "price":"0.04", "size":"823.73", "side":"SELL", "hash":"6dcf813ef045345784490185465fe29cd2674c9b", "best_bid":"0.02", "best_ask":"0.03"}], "timestamp":"1770241464591", "event_type":"price_change"}
{"market":"0x38f3050258345e9cf363d1c8cc302f08c65b96ba1a4669d81e07ed69708344df", "price_changes":[{"asset_id":"96888240988495161476033313796107536512663280794332045579302109906525918376981", "price":"0.97", "size":"432", "side":"BUY", "hash":"4a29ebb66d3faf60e77ccff79de4d0e00c8e1d0c", "best_bid":"0.97", "best_ask":"0.98"}, {"asset_id":"81916206347121459497221114766050949090435061493822476265356047392175668050706", "price":"0.03", "size":"432", "side":"SELL", "hash":"07bff60a0c12fcc85a38593b86a303f4a6fcae96", "best_bid":"0.02", "best_ask":"0.03"}], "timestamp":"1770241464603", "event_type":"price_change"}
{"market":"0x38f3050258345e9cf363d1c8cc302f08c65b96ba1a4669d81e07ed69708344df", "price_changes":[{"asset_id":"96888240988495161476033313796107536512663280794332045579302109906525918376981", "price":"0.98", "size":"488.67", "side":"SELL", "hash":"b014df314b12eaf4ead7d60f4e8b2e89a7470a41", "best_bid":"0.97", "best_ask":"0.98"}, {"asset_id":"81916206347121459497221114766050949090435061493822476265356047392175668050706", "price":"0.02", "size":"488.67", "side":"BUY", "hash":"d3ca9ddc9650b61ba9d650fe64fc7fb382b24354", "best_bid":"0.02", "best_ask":"0.03"}], "timestamp":"1770241464616", "event_type":"price_change"}
{"market":"0x38f3050258345e9cf363d1c8cc302f08c65b96ba1a4669d81e07ed69708344df", "asset_id":"81916206347121459497221114766050949090435061493822476265356047392175668050706", "bids":[{"price":"0.01", "size":"4257.07"}, {"price":"0.02", "size":"488.67"}], "asks":[{"price":"0.99", "size":"5019.91"}, {"price":"0.98", "size":"3034.23"}, {"price":"0.97", "size":"3172"}, {"price":"0.96", "size":"3012"}, {"price":"0.95", "size":"3032"}, {"price":"0.94", "size":"3012"}, {"price":"0.93", "size":"3126.28"}, {"price":"0.92", "size":"3012"}, {"price":"0.91", "size":"3012"}, {"price":"0.9", "size":"3087"}, {"price":"0.89", "size":"12"}, {"price":"0.88", "size":"12"}, {"price":"0.87", "size":"12"}, {"price":"0.86", "size":"12"}, {"price":"0.85", "size":"12"}, {"price":"0.84", "size":"12"}, {"price":"0.83", "size":"12"}, {"price":"0.82", "size":"12"}, {"price":"0.81", "size":"12"}, {"price":"0.8", "size":"12"}, {"price":"0.79", "size":"12"}, {"price":"0.78", "size":"12"}, {"price":"0.77", "size":"12"}, {"price":"0.76", "size":"112"}, {"price":"0.75", "size":"40.57"}, {"price":"0.74", "size":"12"}, {"price":"0.73", "size":"293.25"}, {"price":"0.72", "size":"22"}, {"price":"0.71", "size":"12"}, {"price":"0.7", "size":"18"}, {"price":"0.69", "size":"12"}, {"price":"0.68", "size":"12"}, {"price":"0.67", "size":"12"}, {"price":"0.66", "size":"160.89"}, {"price":"0.65", "size":"12"}, {"price":"0.64", "size":"12"}, {"price":"0.63", "size":"12"}, {"price":"0.62", "size":"19.39"}, {"price":"0.61", "size":"18.04"}, {"price":"0.6", "size":"12"}, {"price":"0.59", "size":"94.31"}, {"price":"0.58", "size":"5450.54"}, {"price":"0.57", "size":"12"}, {"price":"0.56", "size":"12"}, {"price":"0.55", "size":"12"}, {"price":"0.54", "size":"22"}, {"price":"0.53", "size":"12"}, {"price":"0.52", "size":"12"}, {"price":"0.51", "size":"12"}, {"price":"0.5", "size":"12"}, {"price":"0.49", "size":"12"}, {"price":"0.48", "size":"12"}, {"price":"0.47", "size":"12"}, {"price":"0.46", "size":"485.56"}, {"price":"0.45", "size":"31"}, {"price":"0.44", "size":"17"}, {"price":"0.43", "size":"12"}, {"price":"0.42", "size":"12"}, {"price":"0.41", "size":"12"}, {"price":"0.4", "size":"127"}, {"price":"0.39", "size":"12"}, {"price":"0.38", "size":"94.51"}, {"price":"0.37", "size":"31.99"}, {"price":"0.36", "size":"12"}, {"price":"0.35", "size":"37"}, {"price":"0.34", "size":"12"}, {"price":"0.33", "size":"12"}, {"price":"0.32", "size":"12"}, {"price":"0.31", "size":"12"}, {"price":"0.3", "size":"31.9"}, {"price":"0.29", "size":"344"}, {"price":"0.28", "size":"3488.99"}, {"price":"0.27", "size":"212"}, {"price":"0.26", "size":"718"}, {"price":"0.25", "size":"212"}, {"price":"0.24", "size":"412"}, {"price":"0.23", "size":"212"}, {"price":"0.22", "size":"1223.14"}, {"price":"0.21", "size":"212"}, {"price":"0.2", "size":"272.99"}, {"price":"0.19", "size":"212"}, {"price":"0.18", "size":"212"}, {"price":"0.17", "size":"212"}, {"price":"0.16", "size":"812"}, {"price":"0.15", "size":"231.08"}, {"price":"0.14", "size":"283.65"}, {"price":"0.13", "size":"212"}, {"price":"0.12", "size":"252"}, {"price":"0.11", "size":"252"}, {"price":"0.1", "size":"746.71"}, {"price":"0.09", "size":"326"}, {"price":"0.08", "size":"844.68"}, {"price":"0.07", "size":"826"}, {"price":"0.06", "size":"753"}, {"price":"0.05", "size":"650"}, {"price":"0.04", "size":"823.73"}, {"price":"0.03", "size":"432"}], "hash":"d3ca9ddc9650b61ba9d650fe64fc7fb382b24354", "timestamp":"1770241464616", "event_type":"book"}
{"market":"0x38f3050258345e9cf363d1c8cc302f08c65b96ba1a4669d81e07ed69708344df", "price_changes":[{"asset_id":"81916206347121459497221114766050949090435061493822476265356047392175668050706", "price":"0.01", "size":"4230.07", "side":"BUY", "hash":"06253dc6cac4864ea91cfc20b772e90023631d10", "best_bid":"0.02", "best_ask":"0.03"}, {"asset_id":"96888240988495161476033313796107536512663280794332045579302109906525918376981", "price":"0.99", "size":"4230.07", "side":"SELL", "hash":"d48ab03decf453b3c692fd0e94fb93e7a5512cba", "best_bid":"0.97", "best_ask":"0.98"}], "timestamp":"1770241464631", "event_type":"price_change"}
{"market":"0x38f3050258345e9cf363d1c8cc302f08c65b96ba1a4669d81e07ed69708344df", "price_changes":[{"asset_id":"81916206347121459497221114766050949090435061493822476265356047392175668050706", "price":"0.01", "size":"4257.07", "side":"BUY", "hash":"5f36a97fb6d1d8939bcc5f10c07bde13396d7ed7", "best_bid":"0.02", "best_ask":"0.03"}, {"asset_id":"96888240988495161476033313796107536512663280794332045579302109906525918376981", "price":"0.99", "size":"4257.07", "side":"SELL", "hash":"0ac2e0dfe008443d825d5244967ba6c951616a16", "best_bid":"0.97", "best_ask":"0.98"}], "timestamp":"1770241464633", "event_type":"price_change"}
{"market":"0x38f3050258345e9cf363d1c8cc302f08c65b96ba1a4669d81e07ed69708344df", "price_changes":[{"asset_id":"96888240988495161476033313796107536512663280794332045579302109906525918376981", "price":"0.95", "size":"623", "side":"BUY", "hash":"cbb193d97aa2cb3145fe2f42f444eadd9b9a380f", "best_bid":"0.97", "best_ask":"0.98"}, {"asset_id":"81916206347121459497221114766050949090435061493822476265356047392175668050706", "price":"0.05", "size":"623", "side":"SELL", "hash":"4cf3cc1580c2f603432f985a9e19b5e5ce26ff98", "best_bid":"0.02", "best_ask":"0.03"}], "timestamp":"1770241464685", "event_type":"price_change"}
{"market":"0x38f3050258345e9cf363d1c8cc302f08c65b96ba1a4669d81e07ed69708344df", "price_changes":[{"asset_id":"81916206347121459497221114766050949090435061493822476265356047392175668050706", "price":"0.01", "size":"4230.07", "side":"BUY", "hash":"8428c5268b4acbffc7572ee9f25c23bdd24c7059", "best_bid":"0.02", "best_ask":"0.03"}, {"asset_id":"96888240988495161476033313796107536512663280794332045579302109906525918376981", "price":"0.99", "size":"4230.07", "side":"SELL", "hash":"b8faddaa98cba2455af5bc9468dc4bc1fabf17fc", "best_bid":"0.97", "best_ask":"0.98"}], "timestamp":"1770241464689", "event_type":"price_change"}
{"market":"0x38f3050258345e9cf363d1c8cc302f08c65b96ba1a4669d81e07ed69708344df", "price_changes":[{"asset_id":"96888240988495161476033313796107536512663280794332045579302109906525918376981", "price":"0.96", "size":"796.73", "side":"BUY", "hash":"a8378eaaf47756d3fc12633c5dc15f245432d39e", "best_bid":"0.97", "best_ask":"0.98"}, {"asset_id":"81916206347121459497221114766050949090435061493822476265356047392175668050706", "price":"0.04", "size":"796.73", "side":"SELL", "hash":"635050edb33b64cf10ae6314ef972f4d5148c5e3", "best_bid":"0.02", "best_ask":"0.03"}], "timestamp":"1770241464690", "event_type":"price_change"}
{"market":"0x38f3050258345e9cf363d1c8cc302f08c65b96ba1a4669d81e07ed69708344df", "price_changes":[{"asset_id":"81916206347121459497221114766050949090435061493822476265356047392175668050706", "price":"0.01", "size":"4257.07", "side":"BUY", "hash":"834ac49fed0be22cea8d89fa130fa4329e3d2450", "best_bid":"0.02", "best_ask":"0.03"}, {"asset_id":"96888240988495161476033313796107536512663280794332045579302109906525918376981", "price":"0.99", "size":"4257.07", "side":"SELL", "hash":"d7b139babbc2dfe4b3f7c9ae9f0af974bf773d90", "best_bid":"0.97", "best_ask":"0.98"}], "timestamp":"1770241464690", "event_type":"price_change"}
{"market":"0x38f3050258345e9cf363d1c8cc302f08c65b96ba1a4669d81e07ed69708344df", "price_changes":[{"asset_id":"96888240988495161476033313796107536512663280794332045579302109906525918376981", "price":"0.97", "size":"459", "side":"BUY", "hash":"a0b327f51e90381ee7a6e9a349520cc404695a88", "best_bid":"0.97", "best_ask":"0.98"}, {"asset_id":"81916206347121459497221114766050949090435061493822476265356047392175668050706", "price":"0.03", "size":"459", "side":"SELL", "hash":"e25dacbe7177ea24d6de99694cffc78602886d76", "best_bid":"0.02", "best_ask":"0.03"}], "timestamp":"1770241464693", "event_type":"price_change"}
{"market":"0x38f3050258345e9cf363d1c8cc302f08c65b96ba1a4669d81e07ed69708344df", "price_changes":[{"asset_id":"96888240988495161476033313796107536512663280794332045579302109906525918376981", "price":"0.94", "size":"780", "side":"BUY", "hash":"235fd78ae7ebad9a23b58cc2f7272922cc7bf59b", "best_bid":"0.97", "best_ask":"0.98"}, {"asset_id":"81916206347121459497221114766050949090435061493822476265356047392175668050706", "price":"0.06", "size":"780", "side":"SELL", "hash":"81743d959b67abb3fea36cb1739046936fefb16b", "best_bid":"0.02", "best_ask":"0.03"}], "timestamp":"1770241464733", "event_type":"price_change"}
{"market":"0x38f3050258345e9cf363d1c8cc302f08c65b96ba1a4669d81e07ed69708344df", "price_changes":[{"asset_id":"81916206347121459497221114766050949090435061493822476265356047392175668050706", "price":"0.01", "size":"4284.07", "side":"BUY", "hash":"0a35ba2db4d93adf5b51961533143d42dfd66496", "best_bid":"0.02", "best_ask":"0.03"}, {"asset_id":"96888240988495161476033313796107536512663280794332045579302109906525918376981", "price":"0.99", "size":"4284.07", "side":"SELL", "hash":"41c72a607c60c1555d661c5561d97a01ffb6dfe4", "best_bid":"0.97", "best_ask":"0.98"}], "timestamp":"1770241464765", "event_type":"price_change"}
{"market":"0x38f3050258345e9cf363d1c8cc302f08c65b96ba1a4669d81e07ed69708344df", "price_changes":[{"asset_id":"81916206347121459497221114766050949090435061493822476265356047392175668050706", "price":"0.01", "size":"4257.07", "side":"BUY", "hash":"d16d93f3afd4a15a07128703bc6265706e1aef49", "best_bid":"0.02", "best_ask":"0.03"}, {"asset_id":"96888240988495161476033313796107536512663280794332045579302109906525918376981", "price":"0.99", "size":"4257.07", "side":"SELL", "hash":"024be69030e584f288881f63a86d3e9cfce600fd", "best_bid":"0.97", "best_ask":"0.98"}], "timestamp":"1770241464766", "event_type":"price_change"}
{"market":"0x38f3050258345e9cf363d1c8cc302f08c65b96ba1a4669d81e07ed69708344df", "price_changes":[{"asset_id":"96888240988495161476033313796107536512663280794332045579302109906525918376981", "price":"0.94", "size":"753", "side":"BUY", "hash":"2dacbf2d58aa25efd351468b148a8771fa13d141", "best_bid":"0.97", "best_ask":"0.98"}, {"asset_id":"81916206347121459497221114766050949090435061493822476265356047392175668050706", "price":"0.06", "size":"753", "side":"SELL", "hash":"bad016d8109873ad42abd1ad7761b7453f529156", "best_bid":"0.02", "best_ask":"0.03"}], "timestamp":"1770241464773", "event_type":"price_change"}
{"market":"0x38f3050258345e9cf363d1c8cc302f08c65b96ba1a4669d81e07ed69708344df", "price_changes":[{"asset_id":"96888240988495161476033313796107536512663280794332045579302109906525918376981", "price":"0.94", "size":"780", "side":"BUY", "hash":"69da859af8094439c03c07de1d7c65325c9098f0", "best_bid":"0.97", "best_ask":"0.98"}, {"asset_id":"81916206347121459497221114766050949090435061493822476265356047392175668050706", "price":"0.06", "size":"780", "side":"SELL", "hash":"84e910d78c608b0cf08c8e268bef0d8c7f4341c2", "best_bid":"0.02", "best_ask":"0.03"}], "timestamp":"1770241464774", "event_type":"price_change"}
{"market":"0x38f3050258345e9cf363d1c8cc302f08c65b96ba1a4669d81e07ed69708344df", "price_changes":[{"asset_id":"81916206347121459497221114766050949090435061493822476265356047392175668050706", "price":"0.01", "size":"4230.07", "side":"BUY", "hash":"8a7737973fc844ebeebc74ef7ca858f3128cfd45", "best_bid":"0.02", "best_ask":"0.03"}, {"asset_id":"96888240988495161476033313796107536512663280794332045579302109906525918376981", "price":"0.99", "size":"4230.07", "side":"SELL", "hash":"8d220550d9a51ec3a997def6aa0845333b1755c3", "best_bid":"0.97", "best_ask":"0.98"}], "timestamp":"1770241464783", "event_type":"price_change"}
{"market":"0x38f3050258345e9cf363d1c8cc302f08c65b96ba1a4669d81e07ed69708344df", "price_changes":[{"asset_id":"81916206347121459497221114766050949090435061493822476265356047392175668050706", "price":"0.01", "size":"4257.07", "side":"BUY", "hash":"b999f67a475c626eb07b2ef3d3541e78e99c6d9c", "best_bid":"0.02", "best_ask":"0.03"}, {"asset_id":"96888240988495161476033313796107536512663280794332045579302109906525918376981", "price":"0.99", "size":"4257.07", "side":"SELL", "hash":"e05442e1d1989f9c2bbea0a605324bca46012a86", "best_bid":"0.97", "best_ask":"0.98"}], "timestamp":"1770241464784", "event_type":"price_change"}
{"market":"0x38f3050258345e9cf363d1c8cc302f08c65b96ba1a4669d81e07ed69708344df", "price_changes":[{"asset_id":"96888240988495161476033313796107536512663280794332045579302109906525918376981", "price":"0.94", "size":"807", "side":"BUY", "hash":"e1fb23589fbeb18c1cb89aecfbddb52c23810ac5", "best_bid":"0.97", "best_ask":"0.98"}, {"asset_id":"81916206347121459497221114766050949090435061493822476265356047392175668050706", "price":"0.06", "size":"807", "side":"SELL", "hash":"97667341488d6e1ce6e3aabde4a4e5f3b9c83a24", "best_bid":"0.02", "best_ask":"0.03"}], "timestamp":"1770241464807", "event_type":"price_change"}
{"market":"0x38f3050258345e9cf363d1c8cc302f08c65b96ba1a4669d81e07ed69708344df", "price_changes":[{"asset_id":"96888240988495161476033313796107536512663280794332045579302109906525918376981", "price":"0.96", "size":"776.73", "side":"BUY", "hash":"1b0cb32c33ea2d1b62e99fb920c9f2630d69cfe9", "best_bid":"0.97", "best_ask":"0.98"}, {"asset_id":"81916206347121459497221114766050949090435061493822476265356047392175668050706", "price":"0.04", "size":"776.73", "side":"SELL", "hash":"fcae37b0a00709e69d039f0d4b8fc6c9ff45eb6a", "best_bid":"0.02", "best_ask":"0.03"}], "timestamp":"1770241464809", "event_type":"price_change"}
{"market":"0x38f3050258345e9cf363d1c8cc302f08c65b96ba1a4669d81e07ed69708344df", "price_changes":[{"asset_id":"96888240988495161476033313796107536512663280794332045579302109906525918376981", "price":"0.94", "size":"780", "side":"BUY", "hash":"1c77992f2eafed7bf844b5399c2dd3b3827c256d", "best_bid":"0.97", "best_ask":"0.98"}, {"asset_id":"81916206347121459497221114766050949090435061493822476265356047392175668050706", "price":"0.06", "size":"780", "side":"SELL", "hash":"2d6a231d8fe7041fb50ff28eee88e16fb2aab6ab", "best_bid":"0.02", "best_ask":"0.03"}], "timestamp":"1770241464811", "event_type":"price_change"}
{"market":"0x38f3050258345e9cf363d1c8cc302f08c65b96ba1a4669d81e07ed69708344df", "price_changes":[{"asset_id":"96888240988495161476033313796107536512663280794332045579302109906525918376981", "price":"0.97", "size":"432", "side":"BUY", "hash":"c236cb5365a7d891ccdea952290f36f1c83c0369", "best_bid":"0.97", "best_ask":"0.98"}, {"asset_id":"81916206347121459497221114766050949090435061493822476265356047392175668050706", "price":"0.03", "size":"432", "side":"SELL", "hash":"c8089119949e973cd3637166ddbe1fb7a01aaea6", "best_bid":"0.02", "best_ask":"0.03"}], "timestamp":"1770241464814", "event_type":"price_change"}
{"market":"0x38f3050258345e9cf363d1c8cc302f08c65b96ba1a4669d81e07ed69708344df", "price_changes":[{"asset_id":"81916206347121459497221114766050949090435061493822476265356047392175668050706", "price":"0.01", "size":"4284.07", "side":"BUY", "hash":"283d077786610942594a53050985e132289ab069", "best_bid":"0.02", "best_ask":"0.03"}, {"asset_id":"96888240988495161476033313796107536512663280794332045579302109906525918376981", "price":"0.99", "size":"4284.07", "side":"SELL", "hash":"d3103f6249a6e35ce6edecb70e29a1cd1c1aabc2", "best_bid":"0.97", "best_ask":"0.98"}], "timestamp":"1770241464816", "event_type":"price_change"}
{"market":"0x38f3050258345e9cf363d1c8cc302f08c65b96ba1a4669d81e07ed69708344df", "price_changes":[{"asset_id":"81916206347121459497221114766050949090435061493822476265356047392175668050706", "price":"0.01", "size":"4257.07", "side":"BUY", "hash":"2b655a36152a76d789e4e2afb5aac59b49670430", "best_bid":"0.02", "best_ask":"0.03"}, {"asset_id":"96888240988495161476033313796107536512663280794332045579302109906525918376981", "price":"0.99", "size":"4257.07", "side":"SELL", "hash":"c805ac486fc3d48e5741b339e76813899bd70415", "best_bid":"0.97", "best_ask":"0.98"}], "timestamp":"1770241464816", "event_type":"price_change"}
{"market":"0x38f3050258345e9cf363d1c8cc302f08c65b96ba1a4669d81e07ed69708344df", "price_changes":[{"asset_id":"96888240988495161476033313796107536512663280794332045579302109906525918376981", "price":"0.96", "size":"803.73", "side":"BUY", "hash":"6f25f823724cd06073855c84448e6e168d565c8c", "best_bid":"0.97", "best_ask":"0.98"}, {"asset_id":"81916206347121459497221114766050949090435061493822476265356047392175668050706", "price":"0.04", "size":"803.73", "side":"SELL", "hash":"5edb383ba3423a5c87dd5f24e72119414dbb237f", "best_bid":"0.02", "best_ask":"0.03"}], "timestamp":"1770241464817", "event_type":"price_change"}
{"market":"0x38f3050258345e9cf363d1c8cc302f08c65b96ba1a4669d81e07ed69708344df", "price_changes":[{"asset_id":"81916206347121459497221114766050949090435061493822476265356047392175668050706", "price":"0.01", "size":"4234.07", "side":"BUY", "hash":"1f4a247d474a2f60bb36118c8d755cbc26341fcc", "best_bid":"0.02", "best_ask":"0.03"}, {"asset_id":"96888240988495161476033313796107536512663280794332045579302109906525918376981", "price":"0.99", "size":"4234.07", "side":"SELL", "hash":"821951cbbb87e6ec22bf5e12e23da9bb553cfe92", "best_bid":"0.97", "best_ask":"0.98"}], "timestamp":"1770241464832", "event_type":"price_change"}
{"market":"0x38f3050258345e9cf363d1c8cc302f08c65b96ba1a4669d81e07ed69708344df", "price_changes":[{"asset_id":"81916206347121459497221114766050949090435061493822476265356047392175668050706", "price":"0.02", "size":"511.67", "side":"BUY", "hash":"cdea19dd8510fa98b3a3876a8f7eac82eb0a940c", "best_bid":"0.02", "best_ask":"0.03"}, {"asset_id":"96888240988495161476033313796107536512663280794332045579302109906525918376981", "price":"0.98", "size":"511.67", "side":"SELL", "hash":"e7656f690a0815f197a70facacbe7d6e93dff7cd", "best_bid":"0.97", "best_ask":"0.98"}], "timestamp":"1770241464834", "event_type":"price_change"}
{"market":"0x38f3050258345e9cf363d1c8cc302f08c65b96ba1a4669d81e07ed69708344df", "price_changes":[{"asset_id":"81916206347121459497221114766050949090435061493822476265356047392175668050706", "price":"0.01", "size":"4207.07", "side":"BUY", "hash":"0655db06771a0d7bb75f2fc74729df63d02244ef", "best_bid":"0.02", "best_ask":"0.03"}, {"asset_id":"96888240988495161476033313796107536512663280794332045579302109906525918376981", "price":"0.99", "size":"4207.07", "side":"SELL", "hash":"a277ee0b085089f22e24a9e279221fcd2ae949b2", "best_bid":"0.97", "best_ask":"0.98"}], "timestamp":"1770241464933", "event_type":"price_change"}
{"market":"0x38f3050258345e9cf363d1c8cc302f08c65b96ba1a4669d81e07ed69708344df", "price_changes":[{"asset_id":"81916206347121459497221114766050949090435061493822476265356047392175668050706", "price":"0.01", "size":"4234.07", "side":"BUY", "hash":"97d35f68e7324906644352f2696d8fa0c65e2f9a", "best_bid":"0.02", "best_ask":"0.03"}, {"asset_id":"96888240988495161476033313796107536512663280794332045579302109906525918376981", "price":"0.99", "size":"4234.07", "side":"SELL", "hash":"9f1b491a8f44791d2aac689e962bd091cfb5785e", "best_bid":"0.97", "best_ask":"0.98"}], "timestamp":"1770241464935", "event_type":"price_change"}
{"market":"0x38f3050258345e9cf363d1c8cc302f08c65b96ba1a4669d81e07ed69708344df", "price_changes":[{"asset_id":"81916206347121459497221114766050949090435061493822476265356047392175668050706", "price":"0.01", "size":"4257.07", "side":"BUY", "hash":"7a0f12afb1e23382ac85fc58ebbb154533f7615d", "best_bid":"0.02", "best_ask":"0.03"}, {"asset_id":"96888240988495161476033313796107536512663280794332045579302109906525918376981", "price":"0.99", "size":"4257.07", "side":"SELL", "hash":"75dfb5c96b35cc1f91ef646ad54e619190b806c4", "best_bid":"0.97", "best_ask":"0.98"}], "timestamp":"1770241465085", "event_type":"price_change"}
{"market":"0x38f3050258345e9cf363d1c8cc302f08c65b96ba1a4669d81e07ed69708344df", "price_changes":[{"asset_id":"81916206347121459497221114766050949090435061493822476265356047392175668050706", "price":"0.02", "size":"488.67", "side":"BUY", "hash":"6b7a4f35dddcada0e892e155404bd8807bbced9e", "best_bid":"0.02", "best_ask":"0.03"}, {"asset_id":"96888240988495161476033313796107536512663280794332045579302109906525918376981", "price":"0.98", "size":"488.67", "side":"SELL", "hash":"9dd44b95bb79258b78d6c1d0b2fa1deebeb38848", "best_bid":"0.97", "best_ask":"0.98"}], "timestamp":"1770241465086", "event_type":"price_change"}
{"market":"0x38f3050258345e9cf363d1c8cc302f08c65b96ba1a4669d81e07ed69708344df", "price_changes":[{"asset_id":"96888240988495161476033313796107536512663280794332045579302109906525918376981", "price":"0.97", "size":"452", "side":"BUY", "hash":"294d349f351d9ce81c5b299af21e8bdb3ba1908e", "best_bid":"0.97", "best_ask":"0.98"}, {"asset_id":"81916206347121459497221114766050949090435061493822476265356047392175668050706", "price":"0.03", "size":"452", "side":"SELL", "hash":"4e06c3f55036666ea74bbdd8965a24421b91f0f2", "best_bid":"0.02", "best_ask":"0.03"}], "timestamp":"1770241465206", "event_type":"price_change"}
{"market":"0x38f3050258345e9cf363d1c8cc302f08c65b96ba1a4669d81e07ed69708344df", "price_changes":[{"asset_id":"81916206347121459497221114766050949090435061493822476265356047392175668050706", "price":"0.01", "size":"4284.07", "side":"BUY", "hash":"58e6210674aa3a5e86aaf843328957538b7fd8a8", "best_bid":"0.02", "best_ask":"0.03"}, {"asset_id":"96888240988495161476033313796107536512663280794332045579302109906525918376981", "price":"0.99", "size":"4284.07", "side":"SELL", "hash":"d3c99b0067ff4ee025ba8c137e564c0e18247ce9", "best_bid":"0.97", "best_ask":"0.98"}], "timestamp":"1770241465288", "event_type":"price_change"}
{"market":"0x38f3050258345e9cf363d1c8cc302f08c65b96ba1a4669d81e07ed69708344df", "price_changes":[{"asset_id":"96888240988495161476033313796107536512663280794332045579302109906525918376981", "price":"0.96", "size":"830.73", "side":"BUY", "hash":"5bfc6aab5bd0ae2b724506ae66176a43d5a0ddbd", "best_bid":"0.97", "best_ask":"0.98"}, {"asset_id":"81916206347121459497221114766050949090435061493822476265356047392175668050706", "price":"0.04", "size":"830.73", "side":"SELL", "hash":"cf0085535c165765c76e417f123a41627cce41ba", "best_bid":"0.02", "best_ask":"0.03"}], "timestamp":"1770241465290", "event_type":"price_change"}
{"market":"0x38f3050258345e9cf363d1c8cc302f08c65b96ba1a4669d81e07ed69708344df", "price_changes":[{"asset_id":"81916206347121459497221114766050949090435061493822476265356047392175668050706", "price":"0.01", "size":"4257.07", "side":"BUY", "hash":"c91bc6890f503deb88d029eb1e5de39a201ed3c4", "best_bid":"0.02", "best_ask":"0.03"}, {"asset_id":"96888240988495161476033313796107536512663280794332045579302109906525918376981", "price":"0.99", "size":"4257.07", "side":"SELL", "hash":"23436d811ed208fb3da2137171a9f5cc06bfd3a4", "best_bid":"0.97", "best_ask":"0.98"}], "timestamp":"1770241465291", "event_type":"price_change"}
{"market":"0x38f3050258345e9cf363d1c8cc302f08c65b96ba1a4669d81e07ed69708344df", "price_changes":[{"asset_id":"96888240988495161476033313796107536512663280794332045579302109906525918376981", "price":"0.96", "size":"803.73", "side":"BUY", "hash":"cf6bcef23c8a38d371c66943efc1f978ea679be0", "best_bid":"0.97", "best_ask":"0.98"}, {"asset_id":"81916206347121459497221114766050949090435061493822476265356047392175668050706", "price":"0.04", "size":"803.73", "side":"SELL", "hash":"79ac27b38e101fa92cd58d9072aeb6d7258820de", "best_bid":"0.02", "best_ask":"0.03"}], "timestamp":"1770241465291", "event_type":"price_change"}
{"market":"0x38f3050258345e9cf363d1c8cc302f08c65b96ba1a4669d81e07ed69708344df", "price_changes":[{"asset_id":"81916206347121459497221114766050949090435061493822476265356047392175668050706", "price":"0.01", "size":"4284.07", "side":"BUY", "hash":"37bf389fbc86bcd597b01065f38baa93d3fc6736", "best_bid":"0.02", "best_ask":"0.03"}, {"asset_id":"96888240988495161476033313796107536512663280794332045579302109906525918376981", "price":"0.99", "size":"4284.07", "side":"SELL", "hash":"2fccd947480a8b8caa12c1dc3f225412b9ec79d5", "best_bid":"0.97", "best_ask":"0.98"}], "timestamp":"1770241465295", "event_type":"price_change"}
{"market":"0x38f3050258345e9cf363d1c8cc302f08c65b96ba1a4669d81e07ed69708344df", "price_changes":[{"asset_id":"81916206347121459497221114766050949090435061493822476265356047392175668050706", "price":"0.01", "size":"4257.07", "side":"BUY", "hash":"3343c8219ba52a507edb7e25d03cb249b76a2cee", "best_bid":"0.02", "best_ask":"0.03"}, {"asset_id":"96888240988495161476033313796107536512663280794332045579302109906525918376981", "price":"0.99", "size":"4257.07", "side":"SELL", "hash":"496b4827a6378d131c0a80f72a6faff8b5cc1e34", "best_bid":"0.97", "best_ask":"0.98"}], "timestamp":"1770241465295", "event_type":"price_change"}
{"market":"0x38f3050258345e9cf363d1c8cc302f08c65b96ba1a4669d81e07ed69708344df", "price_changes":[{"asset_id":"96888240988495161476033313796107536512663280794332045579302109906525918376981", "price":"0.94", "size":"807", "side":"BUY", "hash":"61087c75360c9f81d0c03e9ef541453abdc611d4", "best_bid":"0.97", "best_ask":"0.98"}, {"asset_id":"81916206347121459497221114766050949090435061493822476265356047392175668050706", "price":"0.06", "size":"807", "side":"SELL", "hash":"5104e5cf69320f92f51b5fb3bc71ba97faf528bc", "best_bid":"0.02", "best_ask":"0.03"}], "timestamp":"1770241465306", "event_type":"price_change"}
{"market":"0x38f3050258345e9cf363d1c8cc302f08c65b96ba1a4669d81e07ed69708344df", "price_changes":[{"asset_id":"96888240988495161476033313796107536512663280794332045579302109906525918376981", "price":"0.94", "size":"780", "side":"BUY", "hash":"08abc9f597481b2139075cee27469c990f632a80", "best_bid":"0.97", "best_ask":"0.98"}, {"asset_id":"81916206347121459497221114766050949090435061493822476265356047392175668050706", "price":"0.06", "size":"780", "side":"SELL", "hash":"6f2a2a592041e8a81138999416d94bce8edfb3ca", "best_bid":"0.02", "best_ask":"0.03"}], "timestamp":"1770241465309", "event_type":"price_change"}
{"market":"0x38f3050258345e9cf363d1c8cc302f08c65b96ba1a4669d81e07ed69708344df", "price_changes":[{"asset_id":"81916206347121459497221114766050949090435061493822476265356047392175668050706", "price":"0.02", "size":"511.67", "side":"BUY", "hash":"32fbea942669164d06ad418a10fbfe3fb8cb71ee", "best_bid":"0.02", "best_ask":"0.03"}, {"asset_id":"96888240988495161476033313796107536512663280794332045579302109906525918376981", "price":"0.98", "size":"511.67", "side":"SELL", "hash":"a0ccb3716c16d0ca144aa9ec7ac8a96a1edc1fa6", "best_bid":"0.97", "best_ask":"0.98"}], "timestamp":"1770241465334", "event_type":"price_change"}
{"market":"0x38f3050258345e9cf363d1c8cc302f08c65b96ba1a4669d81e07ed69708344df", "price_changes":[{"asset_id":"81916206347121459497221114766050949090435061493822476265356047392175668050706", "price":"0.01", "size":"4234.07", "side":"BUY", "hash":"5f077c853ebb5c38b45eecf87e9148e780ed6cf8", "best_bid":"0.02", "best_ask":"0.03"}, {"asset_id":"96888240988495161476033313796107536512663280794332045579302109906525918376981", "price":"0.99", "size":"4234.07", "side":"SELL", "hash":"15d0c90ff94108a3cc00f4df525e5b1fe1fb3425", "best_bid":"0.97", "best_ask":"0.98"}], "timestamp":"1770241465335", "event_type":"price_change"}
{"market":"0x38f3050258345e9cf363d1c8cc302f08c65b96ba1a4669d81e07ed69708344df", "price_changes":[{"asset_id":"81916206347121459497221114766050949090435061493822476265356047392175668050706", "price":"0.01", "size":"4261.07", "side":"BUY", "hash":"c2b51d90bf9d2a753657db8ba2df29c357663916", "best_bid":"0.02", "best_ask":"0.03"}, {"asset_id":"96888240988495161476033313796107536512663280794332045579302109906525918376981", "price":"0.99", "size":"4261.07", "side":"SELL", "hash":"2cf36602d47fc06ccf46ce1ba36e4d52e835c223", "best_bid":"0.97", "best_ask":"0.98"}], "timestamp":"1770241465369", "event_type":"price_change"}
{"market":"0x38f3050258345e9cf363d1c8cc302f08c65b96ba1a4669d81e07ed69708344df", "price_changes":[{"asset_id":"96888240988495161476033313796107536512663280794332045579302109906525918376981", "price":"0.74", "size":"218", "side":"BUY", "hash":"cc4929128ea8a0e56274447249aa21012baec1f1", "best_bid":"0.97", "best_ask":"0.98"}, {"asset_id":"81916206347121459497221114766050949090435061493822476265356047392175668050706", "price":"0.26", "size":"218", "side":"SELL", "hash":"31974964b97855f516193e4ba6b3a3b9e69bf607", "best_bid":"0.02", "best_ask":"0.03"}], "timestamp":"1770241465377", "event_type":"price_change"}
{"market":"0x38f3050258345e9cf363d1c8cc302f08c65b96ba1a4669d81e07ed69708344df", "price_changes":[{"asset_id":"81916206347121459497221114766050949090435061493822476265356047392175668050706", "price":"0.01", "size":"4234.07", "side":"BUY", "hash":"28cdb5515dfeec2fcab9054e3fa4b2b455e05c8a", "best_bid":"0.02", "best_ask":"0.03"}, {"asset_id":"96888240988495161476033313796107536512663280794332045579302109906525918376981", "price":"0.99", "size":"4234.07", "side":"SELL", "hash":"8b9f000afa964da65f54b2caa81ec1f44e69a48f", "best_bid":"0.97", "best_ask":"0.98"}], "timestamp":"1770241465378", "event_type":"price_change"}
{"market":"0x38f3050258345e9cf363d1c8cc302f08c65b96ba1a4669d81e07ed69708344df", "price_changes":[{"asset_id":"96888240988495161476033313796107536512663280794332045579302109906525918376981", "price":"0.94", "size":"753", "side":"BUY", "hash":"139ce8bb1b2f74214ddc8b28567091de10806c49", "best_bid":"0.97", "best_ask":"0.98"}, {"asset_id":"81916206347121459497221114766050949090435061493822476265356047392175668050706", "price":"0.06", "size":"753", "side":"SELL", "hash":"06894c1e579bf01e6758d126b37ffc4c51708fbd", "best_bid":"0.02", "best_ask":"0.03"}], "timestamp":"1770241465389", "event_type":"price_change"}
{"market":"0x38f3050258345e9cf363d1c8cc302f08c65b96ba1a4669d81e07ed69708344df", "price_changes":[{"asset_id":"96888240988495161476033313796107536512663280794332045579302109906525918376981", "price":"0.94", "size":"780", "side":"BUY", "hash":"8d64b52718fd06be2ed43fdea89a443dd1bb81f7", "best_bid":"0.97", "best_ask":"0.98"}, {"asset_id":"81916206347121459497221114766050949090435061493822476265356047392175668050706", "price":"0.06", "size":"780", "side":"SELL", "hash":"55989fbd3c7b8eed12ee7008d756af08cad5bcfc", "best_bid":"0.02", "best_ask":"0.03"}], "timestamp":"1770241465391", "event_type":"price_change"}
{"market":"0x38f3050258345e9cf363d1c8cc302f08c65b96ba1a4669d81e07ed69708344df", "price_changes":[{"asset_id":"96888240988495161476033313796107536512663280794332045579302109906525918376981", "price":"0.97", "size":"432", "side":"BUY", "hash":"eb9cc2a091d247eb7d8605365ca6df9e395aa3d5", "best_bid":"0.97", "best_ask":"0.98"}, {"asset_id":"81916206347121459497221114766050949090435061493822476265356047392175668050706", "price":"0.03", "size":"432", "side":"SELL", "hash":"884a600bf7e06cfe6814d4a76ae23c11ba645c9b", "best_bid":"0.02", "best_ask":"0.03"}], "timestamp":"1770241465573", "event_type":"price_change"}
{"market":"0x38f3050258345e9cf363d1c8cc302f08c65b96ba1a4669d81e07ed69708344df", "price_changes":[{"asset_id":"81916206347121459497221114766050949090435061493822476265356047392175668050706", "price":"0.01", "size":"4257.07", "side":"BUY", "hash":"4d2a4a55946a3d14514b46fd5a10cacdf04d09c7", "best_bid":"0.02", "best_ask":"0.03"}, {"asset_id":"96888240988495161476033313796107536512663280794332045579302109906525918376981", "price":"0.99", "size":"4257.07", "side":"SELL", "hash":"45f7c9c74ff8d7c2e579a271c33a168575e504e1", "best_bid":"0.97", "best_ask":"0.98"}], "timestamp":"1770241465590", "event_type":"price_change"}
{"market":"0x38f3050258345e9cf363d1c8cc302f08c65b96ba1a4669d81e07ed69708344df", "price_changes":[{"asset_id":"96888240988495161476033313796107536512663280794332045579302109906525918376981", "price":"0.95", "size":"646", "side":"BUY", "hash":"bd3c133707297f1e51dbb1c7f1b8ce88c5706d41", "best_bid":"0.97", "best_ask":"0.98"}, {"asset_id":"81916206347121459497221114766050949090435061493822476265356047392175668050706", "price":"0.05", "size":"646", "side":"SELL", "hash":"656989fe431a97c4447066961ea9c1b24526f27a", "best_bid":"0.02", "best_ask":"0.03"}], "timestamp":"1770241465590", "event_type":"price_change"}
{"market":"0x38f3050258345e9cf363d1c8cc302f08c65b96ba1a4669d81e07ed69708344df", "price_changes":[{"asset_id":"81916206347121459497221114766050949090435061493822476265356047392175668050706", "price":"0.02", "size":"488.67", "side":"BUY", "hash":"dc5d84a69eb3d89ec34ab209559722056724d7f0", "best_bid":"0.02", "best_ask":"0.03"}, {"asset_id":"96888240988495161476033313796107536512663280794332045579302109906525918376981", "price":"0.98", "size":"488.67", "side":"SELL", "hash":"664c14d937273a095262b4662d423202e47553a0", "best_bid":"0.97", "best_ask":"0.98"}], "timestamp":"1770241465591", "event_type":"price_change"}
{"market":"0x38f3050258345e9cf363d1c8cc302f08c65b96ba1a4669d81e07ed69708344df", "price_changes":[{"asset_id":"96888240988495161476033313796107536512663280794332045579302109906525918376981", "price":"0.96", "size":"780.73", "side":"BUY", "hash":"8c2ed5180fe506ddcca89b830e9d4d64bddebcb1", "best_bid":"0.97", "best_ask":"0.98"}, {"asset_id":"81916206347121459497221114766050949090435061493822476265356047392175668050706", "price":"0.04", "size":"780.73", "side":"SELL", "hash":"7cd8262a05bfcf726d11f63f62dbc70ac977f94a", "best_bid":"0.02", "best_ask":"0.03"}], "timestamp":"1770241465591", "event_type":"price_change"}
{"market":"0x38f3050258345e9cf363d1c8cc302f08c65b96ba1a4669d81e07ed69708344df", "price_changes":[{"asset_id":"96888240988495161476033313796107536512663280794332045579302109906525918376981", "price":"0.96", "size":"753.73", "side":"BUY", "hash":"c3aa17edf8ae0fc6b27fed29b07b4bac6b85268a", "best_bid":"0.97", "best_ask":"0.98"}, {"asset_id":"81916206347121459497221114766050949090435061493822476265356047392175668050706", "price":"0.04", "size":"753.73", "side":"SELL", "hash":"cb47997cf92f9d83da84bf3781d79ece3172382e", "best_bid":"0.02", "best_ask":"0.03"}], "timestamp":"1770241466058", "event_type":"price_change"}
{"market":"0x38f3050258345e9cf363d1c8cc302f08c65b96ba1a4669d81e07ed69708344df", "price_changes":[{"asset_id":"96888240988495161476033313796107536512663280794332045579302109906525918376981", "price":"0.95", "size":"673", "side":"BUY", "hash":"bd3eaf7e6585c3d5aedab647bc8aaea3169f3671", "best_bid":"0.97", "best_ask":"0.98"}, {"asset_id":"81916206347121459497221114766050949090435061493822476265356047392175668050706", "price":"0.05", "size":"673", "side":"SELL", "hash":"dfe3e2060024f095d412a9d142cd67c7b9344a3b", "best_bid":"0.02", "best_ask":"0.03"}], "timestamp":"1770241466065", "event_type":"price_change"}
{"market":"0x38f3050258345e9cf363d1c8cc302f08c65b96ba1a4669d81e07ed69708344df", "price_changes":[{"asset_id":"81916206347121459497221114766050949090435061493822476265356047392175668050706", "price":"0.01", "size":"4234.07", "side":"BUY", "hash":"efb81db1e646efd168473509739fb02231ee7ae9", "best_bid":"0.02", "best_ask":"0.03"}, {"asset_id":"96888240988495161476033313796107536512663280794332045579302109906525918376981", "price":"0.99", "size":"4234.07", "side":"SELL", "hash":"3403b24ef046f820feba715992892e1660b4de96", "best_bid":"0.97", "best_ask":"0.98"}], "timestamp":"1770241466089", "event_type":"price_change"}
{"market":"0x38f3050258345e9cf363d1c8cc302f08c65b96ba1a4669d81e07ed69708344df", "price_changes":[{"asset_id":"81916206347121459497221114766050949090435061493822476265356047392175668050706", "price":"0.02", "size":"511.67", "side":"BUY", "hash":"3d832696169686d0f39cce4b2f3712f518aa25ba", "best_bid":"0.02", "best_ask":"0.03"}, {"asset_id":"96888240988495161476033313796107536512663280794332045579302109906525918376981", "price":"0.98", "size":"511.67", "side":"SELL", "hash":"635b201f8adb85230dbb6d260617096f6805b8c5", "best_bid":"0.97", "best_ask":"0.98"}], "timestamp":"1770241466090", "event_type":"price_change"}
{"market":"0x38f3050258345e9cf363d1c8cc302f08c65b96ba1a4669d81e07ed69708344df", "price_changes":[{"asset_id":"96888240988495161476033313796107536512663280794332045579302109906525918376981", "price":"0.96", "size":"776.73", "side":"BUY", "hash":"c1e1d9a24d7b1ee4f92cdf3bf58c20f0ffa4e75b", "best_bid":"0.97", "best_ask":"0.98"}, {"asset_id":"81916206347121459497221114766050949090435061493822476265356047392175668050706", "price":"0.04", "size":"776.73", "side":"SELL", "hash":"c81ab6d309de067f9a63bdd79d616fca5caf5f32", "best_bid":"0.02", "best_ask":"0.03"}], "timestamp":"1770241466092", "event_type":"price_change"}
{"market":"0x38f3050258345e9cf363d1c8cc302f08c65b96ba1a4669d81e07ed69708344df", "price_changes":[{"asset_id":"96888240988495161476033313796107536512663280794332045579302109906525918376981", "price":"0.95", "size":"650", "side":"BUY", "hash":"7af0b86582c0d79d417fe6df0bba80dc347a9edb", "best_bid":"0.97", "best_ask":"0.98"}, {"asset_id":"81916206347121459497221114766050949090435061493822476265356047392175668050706", "price":"0.05", "size":"650", "side":"SELL", "hash":"b4ba6bd4fe0e2d23893230ac39c9dec211c33bc8", "best_bid":"0.02", "best_ask":"0.03"}], "timestamp":"1770241466093", "event_type":"price_change"}
{"market":"0x38f3050258345e9cf363d1c8cc302f08c65b96ba1a4669d81e07ed69708344df", "price_changes":[{"asset_id":"96888240988495161476033313796107536512663280794332045579302109906525918376981", "price":"0.96", "size":"796.73", "side":"BUY", "hash":"60606a9ec96cdb06434bf6b75502be6d75e3ca39", "best_bid":"0.97", "best_ask":"0.98"}, {"asset_id":"81916206347121459497221114766050949090435061493822476265356047392175668050706", "price":"0.04", "size":"796.73", "side":"SELL", "hash":"c72f03451aa1d92acc1ac2f0b18e7eea6073cbd2", "best_bid":"0.02", "best_ask":"0.03"}], "timestamp":"1770241466106", "event_type":"price_change"}
{"market":"0x38f3050258345e9cf363d1c8cc302f08c65b96ba1a4669d81e07ed69708344df", "price_changes":[{"asset_id":"96888240988495161476033313796107536512663280794332045579302109906525918376981", "price":"0.75", "size":"712", "side":"BUY", "hash":"20ee0d3e85d5cdfc33f090ffb3de5e196a04d0f8", "best_bid":"0.97", "best_ask":"0.98"}, {"asset_id":"81916206347121459497221114766050949090435061493822476265356047392175668050706", "price":"0.25", "size":"712", "side":"SELL", "hash":"e86027ef96cdaf30fd94a83fcdaa19176a77f56c", "best_bid":"0.02", "best_ask":"0.03"}], "timestamp":"1770241466184", "event_type":"price_change"}
{"market":"0x38f3050258345e9cf363d1c8cc302f08c65b96ba1a4669d81e07ed69708344df", "price_changes":[{"asset_id":"96888240988495161476033313796107536512663280794332045579302109906525918376981", "price":"0.96", "size":"823.73", "side":"BUY", "hash":"48dc7558bb6b346f51c74c47808982a86f5eca5a", "best_bid":"0.97", "best_ask":"0.98"}, {"asset_id":"81916206347121459497221114766050949090435061493822476265356047392175668050706", "price":"0.04", "size":"823.73", "side":"SELL", "hash":"24a1cc2793948422869626842e2896196c234158", "best_bid":"0.02", "best_ask":"0.03"}], "timestamp":"1770241466210", "event_type":"price_change"}
{"market":"0x38f3050258345e9cf363d1c8cc302f08c65b96ba1a4669d81e07ed69708344df", "price_changes":[{"asset_id":"96888240988495161476033313796107536512663280794332045579302109906525918376981", "price":"0.95", "size":"623", "side":"BUY", "hash":"742dc8df3f46fd11d623b79ef05f972185ed0f04", "best_bid":"0.97", "best_ask":"0.98"}, {"asset_id":"81916206347121459497221114766050949090435061493822476265356047392175668050706", "price":"0.05", "size":"623", "side":"SELL", "hash":"89aa8e10c52f4249098e47336503233dfe8f19d8", "best_bid":"0.02", "best_ask":"0.03"}], "timestamp":"1770241466215", "event_type":"price_change"}
{"market":"0x38f3050258345e9cf363d1c8cc302f08c65b96ba1a4669d81e07ed69708344df", "price_changes":[{"asset_id":"96888240988495161476033313796107536512663280794332045579302109906525918376981", "price":"0.98", "size":"506.67", "side":"SELL", "hash":"24caebe682b40a4b6bcfa739999e741a0b9ec783", "best_bid":"0.97", "best_ask":"0.98"}, {"asset_id":"81916206347121459497221114766050949090435061493822476265356047392175668050706", "price":"0.02", "size":"506.67", "side":"BUY", "hash":"21e32932ae476edecf598c7da2c9fca6134144a3", "best_bid":"0.02", "best_ask":"0.03"}], "timestamp":"1770241466269", "event_type":"price_change"}
{"market":"0x38f3050258345e9cf363d1c8cc302f08c65b96ba1a4669d81e07ed69708344df", "asset_id":"81916206347121459497221114766050949090435061493822476265356047392175668050706", "bids":[{"price":"0.01", "size":"4234.07"}, {"price":"0.02", "size":"506.67"}], "asks":[{"price":"0.99", "size":"5019.91"}, {"price":"0.98", "size":"3034.23"}, {"price":"0.97", "size":"3172"}, {"price":"0.96", "size":"3012"}, {"price":"0.95", "size":"3032"}, {"price":"0.94", "size":"3012"}, {"price":"0.93", "size":"3126.28"}, {"price":"0.92", "size":"3012"}, {"price":"0.91", "size":"3012"}, {"price":"0.9", "size":"3087"}, {"price":"0.89", "size":"12"}, {"price":"0.88", "size":"12"}, {"price":"0.87", "size":"12"}, {"price":"0.86", "size":"12"}, {"price":"0.85", "size":"12"}, {"price":"0.84", "size":"12"}, {"price":"0.83", "size":"12"}, {"price":"0.82", "size":"12"}, {"price":"0.81", "size":"12"}, {"price":"0.8", "size":"12"}, {"price":"0.79", "size":"12"}, {"price":"0.78", "size":"12"}, {"price":"0.77", "size":"12"}, {"price":"0.76", "size":"112"}, {"price":"0.75", "size":"40.57"}, {"price":"0.74", "size":"12"}, {"price":"0.73", "size":"293.25"}, {"price":"0.72", "size":"22"}, {"price":"0.71", "size":"12"}, {"price":"0.7", "size":"18"}, {"price":"0.69", "size":"12"}, {"price":"0.68", "size":"12"}, {"price":"0.67", "size":"12"}, {"price":"0.66", "size":"160.89"}, {"price":"0.65", "size":"12"}, {"price":"0.64", "size":"12"}, {"price":"0.63", "size":"12"}, {"price":"0.62", "size":"19.39"}, {"price":"0.61", "size":"18.04"}, {"price":"0.6", "size":"12"}, {"price":"0.59", "size":"94.31"}, {"price":"0.58", "size":"5450.54"}, {"price":"0.57", "size":"12"}, {"price":"0.56", "size":"12"}, {"price":"0.55", "size":"12"}, {"price":"0.54", "size":"22"}, {"price":"0.53", "size":"12"}, {"price":"0.52", "size":"12"}, {"price":"0.51", "size":"12"}, {"price":"0.5", "size":"12"}, {"price":"0.49", "size":"12"}, {"price":"0.48", "size":"12"}, {"price":"0.47", "size":"12"}, {"price":"0.46", "size":"485.56"}, {"price":"0.45", "size":"31"}, {"price":"0.44", "size":"17"}, {"price":"0.43", "size":"12"}, {"price":"0.42", "size":"12"}, {"price":"0.41", "size":"12"}, {"price":"0.4", "size":"127"}, {"price":"0.39", "size":"12"}, {"price":"0.38", "size":"94.51"}, {"price":"0.37", "size":"31.99"}, {"price":"0.36", "size":"12"}, {"price":"0.35", "size":"37"}, {"price":"0.34", "size":"12"}, {"price":"0.33", "size":"12"}, {"price":"0.32", "size":"12"}, {"price":"0.31", "size":"12"}, {"price":"0.3", "size":"31.9"}, {"price":"0.29", "size":"344"}, {"price":"0.28", "size":"3488.99"}, {"price":"0.27", "size":"212"}, {"price":"0.26", "size":"218"}, {"price":"0.25", "size":"712"}, {"price":"0.24", "size":"412"}, {"price":"0.23", "size":"212"}, {"price":"0.22", "size":"1223.14"}, {"price":"0.21", "size":"212"}, {"price":"0.2", "size":"272.99"}, {"price":"0.19", "size":"212"}, {"price":"0.18", "size":"212"}, {"price":"0.17", "size":"212"}, {"price":"0.16", "size":"812"}, {"price":"0.15", "size":"231.08"}, {"price":"0.14", "size":"283.65"}, {"price":"0.13", "size":"212"}, {"price":"0.12", "size":"252"}, {"price":"0.11", "size":"252"}, {"price":"0.1", "size":"746.71"}, {"price":"0.09", "size":"326"}, {"price":"0.08", "size":"844.68"}, {"price":"0.07", "size":"826"}, {"price":"0.06", "size":"780"}, {"price":"0.05", "size":"623"}, {"price":"0.04", "size":"823.73"}, {"price":"0.03", "size":"432"}], "hash":"21e32932ae476edecf598c7da2c9fca6134144a3", "timestamp":"1770241466269", "event_type":"book"}
{"market":"0x38f3050258345e9cf363d1c8cc302f08c65b96ba1a4669d81e07ed69708344df", "price_changes":[{"asset_id":"81916206347121459497221114766050949090435061493822476265356047392175668050706", "price":"0.02", "size":"483.67", "side":"BUY", "hash":"bce04f0d1238df898767f922c1bf35298caa01f7", "best_bid":"0.02", "best_ask":"0.03"}, {"asset_id":"96888240988495161476033313796107536512663280794332045579302109906525918376981", "price":"0.98", "size":"483.67", "side":"SELL", "hash":"5b4d91bb8dfcfc1735e88abc0215e4d3efe29bc7", "best_bid":"0.97", "best_ask":"0.98"}], "timestamp":"1770241466395", "event_type":"price_change"}
{"market":"0x38f3050258345e9cf363d1c8cc302f08c65b96ba1a4669d81e07ed69708344df", "price_changes":[{"asset_id":"81916206347121459497221114766050949090435061493822476265356047392175668050706", "price":"0.01", "size":"4257.07", "side":"BUY", "hash":"865efad4bdc0b6da375d8d80936bb4714a440256", "best_bid":"0.02", "best_ask":"0.03"}, {"asset_id":"96888240988495161476033313796107536512663280794332045579302109906525918376981", "price":"0.99", "size":"4257.07", "side":"SELL", "hash":"d57bce75b6995b783954547421ff8ef24d5847af", "best_bid":"0.97", "best_ask":"0.98"}], "timestamp":"1770241466396", "event_type":"price_change"}
{"market":"0x38f3050258345e9cf363d1c8cc302f08c65b96ba1a4669d81e07ed69708344df", "price_changes":[{"asset_id":"96888240988495161476033313796107536512663280794332045579302109906525918376981", "price":"0.98", "size":"472.67", "side":"SELL", "hash":"2466d82f2bc07bc44618a970e42d3cbf7a22e990", "best_bid":"0.97", "best_ask":"0.98"}, {"asset_id":"81916206347121459497221114766050949090435061493822476265356047392175668050706", "price":"0.02", "size":"472.67", "side":"BUY", "hash":"98dee70ab0e1e8826ff34aa60fad2241e5be81db", "best_bid":"0.02", "best_ask":"0.03"}], "timestamp":"1770241466540", "event_type":"price_change"}
{"market":"0x38f3050258345e9cf363d1c8cc302f08c65b96ba1a4669d81e07ed69708344df", "asset_id":"81916206347121459497221114766050949090435061493822476265356047392175668050706", "bids":[{"price":"0.01", "size":"4257.07"}, {"price":"0.02", "size":"472.67"}], "asks":[{"price":"0.99", "size":"5019.91"}, {"price":"0.98", "size":"3034.23"}, {"price":"0.97", "size":"3172"}, {"price":"0.96", "size":"3012"}, {"price":"0.95", "size":"3032"}, {"price":"0.94", "size":"3012"}, {"price":"0.93", "size":"3126.28"}, {"price":"0.92", "size":"3012"}, {"price":"0.91", "size":"3012"}, {"price":"0.9", "size":"3087"}, {"price":"0.89", "size":"12"}, {"price":"0.88", "size":"12"}, {"price":"0.87", "size":"12"}, {"price":"0.86", "size":"12"}, {"price":"0.85", "size":"12"}, {"price":"0.84", "size":"12"}, {"price":"0.83", "size":"12"}, {"price":"0.82", "size":"12"}, {"price":"0.81", "size":"12"}, {"price":"0.8", "size":"12"}, {"price":"0.79", "size":"12"}, {"price":"0.78", "size":"12"}, {"price":"0.77", "size":"12"}, {"price":"0.76", "size":"112"}, {"price":"0.75", "size":"40.57"}, {"price":"0.74", "size":"12"}, {"price":"0.73", "size":"293.25"}, {"price":"0.72", "size":"22"}, {"price":"0.71", "size":"12"}, {"price":"0.7", "size":"18"}, {"price":"0.69", "size":"12"}, {"price":"0.68", "size":"12"}, {"price":"0.67", "size":"12"}, {"price":"0.66", "size":"160.89"}, {"price":"0.65", "size":"12"}, {"price":"0.64", "size":"12"}, {"price":"0.63", "size":"12"}, {"price":"0.62", "size":"19.39"}, {"price":"0.61", "size":"18.04"}, {"price":"0.6", "size":"12"}, {"price":"0.59", "size":"94.31"}, {"price":"0.58", "size":"5450.54"}, {"price":"0.57", "size":"12"}, {"price":"0.56", "size":"12"}, {"price":"0.55", "size":"12"}, {"price":"0.54", "size":"22"}, {"price":"0.53", "size":"12"}, {"price":"0.52", "size":"12"}, {"price":"0.51", "size":"12"}, {"price":"0.5", "size":"12"}, {"price":"0.49", "size":"12"}, {"price":"0.48", "size":"12"}, {"price":"0.47", "size":"12"}, {"price":"0.46", "size":"485.56"}, {"price":"0.45", "size":"31"}, {"price":"0.44", "size":"17"}, {"price":"0.43", "size":"12"}, {"price":"0.42", "size":"12"}, {"price":"0.41", "size":"12"}, {"price":"0.4", "size":"127"}, {"price":"0.39", "size":"12"}, {"price":"0.38", "size":"94.51"}, {"price":"0.37", "size":"31.99"}, {"price":"0.36", "size":"12"}, {"price":"0.35", "size":"37"}, {"price":"0.34", "size":"12"}, {"price":"0.33", "size":"12"}, {"price":"0.32", "size":"12"}, {"price":"0.31", "size":"12"}, {"price":"0.3", "size":"31.9"}, {"price":"0.29", "size":"344"}, {"price":"0.28", "size":"3488.99"}, {"price":"0.27", "size":"212"}, {"price":"0.26", "size":"218"}, {"price":"0.25", "size":"712"}, {"price":"0.24", "size":"412"}, {"price":"0.23", "size":"212"}, {"price":"0.22", "size":"1223.14"}, {"price":"0.21", "size":"212"}, {"price":"0.2", "size":"272.99"}, {"price":"0.19", "size":"212"}, {"price":"0.18", "size":"212"}, {"price":"0.17", "size":"212"}, {"price":"0.16", "size":"812"}, {"price":"0.15", "size":"231.08"}, {"price":"0.14", "size":"283.65"}, {"price":"0.13", "size":"212"}, {"price":"0.12", "size":"252"}, {"price":"0.11", "size":"252"}, {"price":"0.1", "size":"746.71"}, {"price":"0.09", "size":"326"}, {"price":"0.08", "size":"844.68"}, {"price":"0.07", "size":"826"}, {"price":"0.06", "size":"780"}, {"price":"0.05", "size":"623"}, {"price":"0.04", "size":"823.73"}, {"price":"0.03", "size":"432"}], "hash":"98dee70ab0e1e8826ff34aa60fad2241e5be81db", "timestamp":"1770241466540", "event_type":"book"}
{"market":"0x38f3050258345e9cf363d1c8cc302f08c65b96ba1a4669d81e07ed69708344df", "asset_id":"81916206347121459497221114766050949090435061493822476265356047392175668050706", "price":"0.02", "size":"11", "fee_rate_bps":"0", "side":"SELL", "timestamp":"1770241466567", "event_type":"last_trade_price", "transaction_hash":"0xf150ebb97d80f2bae65fbb52499852109807138265abd0c0b80bc3556c2da92f"}
{"market":"0x38f3050258345e9cf363d1c8cc302f08c65b96ba1a4669d81e07ed69708344df", "price_changes":[{"asset_id":"96888240988495161476033313796107536512663280794332045579302109906525918376981", "price":"0.95", "size":"646", "side":"BUY", "hash":"ae52a873401fecac7bfdec4b69cc579eeb034f4b", "best_bid":"0.97", "best_ask":"0.98"}, {"asset_id":"81916206347121459497221114766050949090435061493822476265356047392175668050706", "price":"0.05", "size":"646", "side":"SELL", "hash":"844829ae6e575ad807d9b54cd49c88af84b1dc77", "best_bid":"0.02", "best_ask":"0.03"}], "timestamp":"1770241466891", "event_type":"price_change"}
{"market":"0x38f3050258345e9cf363d1c8cc302f08c65b96ba1a4669d81e07ed69708344df", "price_changes":[{"asset_id":"96888240988495161476033313796107536512663280794332045579302109906525918376981", "price":"0.96", "size":"800.73", "side":"BUY", "hash":"417b9da55b25a64aa8c5d64f2878de8962845d78", "best_bid":"0.97", "best_ask":"0.98"}, {"asset_id":"81916206347121459497221114766050949090435061493822476265356047392175668050706", "price":"0.04", "size":"800.73", "side":"SELL", "hash":"ea537c62c36e84469120f9e2dc91f17074c7dfd2", "best_bid":"0.02", "best_ask":"0.03"}], "timestamp":"1770241466920", "event_type":"price_change"}
{"market":"0x38f3050258345e9cf363d1c8cc302f08c65b96ba1a4669d81e07ed69708344df", "price_changes":[{"asset_id":"96888240988495161476033313796107536512663280794332045579302109906525918376981", "price":"0.96", "size":"773.73", "side":"BUY", "hash":"5b1ab3c466883f5da3126f74347a487db0fcf9f5", "best_bid":"0.97", "best_ask":"0.98"}, {"asset_id":"81916206347121459497221114766050949090435061493822476265356047392175668050706", "price":"0.04", "size":"773.73", "side":"SELL", "hash":"9e81af094e34dce1a70371d86107b6a4afcc1007", "best_bid":"0.02", "best_ask":"0.03"}], "timestamp":"1770241467340", "event_type":"price_change"}
{"market":"0x38f3050258345e9cf363d1c8cc302f08c65b96ba1a4669d81e07ed69708344df", "price_changes":[{"asset_id":"96888240988495161476033313796107536512663280794332045579302109906525918376981", "price":"0.95", "size":"673", "side":"BUY", "hash":"0ec701ad287a7caff1131cdd1dfb001f8d823c76", "best_bid":"0.97", "best_ask":"0.98"}, {"asset_id":"81916206347121459497221114766050949090435061493822476265356047392175668050706", "price":"0.05", "size":"673", "side":"SELL", "hash":"41a11de791a935d7b5865846ce0b6c6c23123f52", "best_bid":"0.02", "best_ask":"0.03"}], "timestamp":"1770241467341", "event_type":"price_change"}
{"market":"0x38f3050258345e9cf363d1c8cc302f08c65b96ba1a4669d81e07ed69708344df", "price_changes":[{"asset_id":"96888240988495161476033313796107536512663280794332045579302109906525918376981", "price":"0.94", "size":"753", "side":"BUY", "hash":"b9a1634875bffabba2a8e29c202ee08037223f6a", "best_bid":"0.97", "best_ask":"0.98"}, {"asset_id":"81916206347121459497221114766050949090435061493822476265356047392175668050706", "price":"0.06", "size":"753", "side":"SELL", "hash":"caf254189e82ad8306e2518fdfa273daeafb3702", "best_bid":"0.02", "best_ask":"0.03"}], "timestamp":"1770241467379", "event_type":"price_change"}
{"market":"0x38f3050258345e9cf363d1c8cc302f08c65b96ba1a4669d81e07ed69708344df", "price_changes":[{"asset_id":"96888240988495161476033313796107536512663280794332045579302109906525918376981", "price":"0.95", "size":"700", "side":"BUY", "hash":"31e87401f8229869a203b2abbfbb881ddf2b9c5d", "best_bid":"0.97", "best_ask":"0.98"}, {"asset_id":"81916206347121459497221114766050949090435061493822476265356047392175668050706", "price":"0.05", "size":"700", "side":"SELL", "hash":"afdc2947e40f9f47522cfe812ce0dfef4c3cd4c0", "best_bid":"0.02", "best_ask":"0.03"}], "timestamp":"1770241467384", "event_type":"price_change"}
{"market":"0x38f3050258345e9cf363d1c8cc302f08c65b96ba1a4669d81e07ed69708344df", "price_changes":[{"asset_id":"81916206347121459497221114766050949090435061493822476265356047392175668050706", "price":"0.02", "size":"495.67", "side":"BUY", "hash":"94e93097ed169269dc37d57960a55dc21d8ab364", "best_bid":"0.02", "best_ask":"0.03"}, {"asset_id":"96888240988495161476033313796107536512663280794332045579302109906525918376981", "price":"0.98", "size":"495.67", "side":"SELL", "hash":"604afa8becf93873641c681166e29e4bb60a042b", "best_bid":"0.97", "best_ask":"0.98"}], "timestamp":"1770241467391", "event_type":"price_change"}
{"market":"0x38f3050258345e9cf363d1c8cc302f08c65b96ba1a4669d81e07ed69708344df", "price_changes":[{"asset_id":"96888240988495161476033313796107536512663280794332045579302109906525918376981", "price":"0.96", "size":"796.73", "side":"BUY", "hash":"1a9524ae8c21b0117762e5d8cb68ac8f0926714b", "best_bid":"0.97", "best_ask":"0.98"}, {"asset_id":"81916206347121459497221114766050949090435061493822476265356047392175668050706", "price":"0.04", "size":"796.73", "side":"SELL", "hash":"3a183a24723cd7b82872be073465282305825ff1", "best_bid":"0.02", "best_ask":"0.03"}], "timestamp":"1770241467391", "event_type":"price_change"}
{"market":"0x38f3050258345e9cf363d1c8cc302f08c65b96ba1a4669d81e07ed69708344df", "price_changes":[{"asset_id":"81916206347121459497221114766050949090435061493822476265356047392175668050706", "price":"0.01", "size":"4234.07", "side":"BUY", "hash":"0d3120004e8e09a5123f07b7da7e339e7ee28d8f", "best_bid":"0.02", "best_ask":"0.03"}, {"asset_id":"96888240988495161476033313796107536512663280794332045579302109906525918376981", "price":"0.99", "size":"4234.07", "side":"SELL", "hash":"7ce5a8740e918e4ece935dbcd7c534483c92333a", "best_bid":"0.97", "best_ask":"0.98"}], "timestamp":"1770241467392", "event_type":"price_change"}
{"market":"0x38f3050258345e9cf363d1c8cc302f08c65b96ba1a4669d81e07ed69708344df", "price_changes":[{"asset_id":"96888240988495161476033313796107536512663280794332045579302109906525918376981", "price":"0.95", "size":"677", "side":"BUY", "hash":"bd32c4c4e6dd8d67b65a1c988b098025e6e6e444", "best_bid":"0.97", "best_ask":"0.98"}, {"asset_id":"81916206347121459497221114766050949090435061493822476265356047392175668050706", "price":"0.05", "size":"677", "side":"SELL", "hash":"88d732b55482b9d4a2c29b7c5189faf950ee455b", "best_bid":"0.02", "best_ask":"0.03"}], "timestamp":"1770241467393", "event_type":"price_change"}
{"market":"0x38f3050258345e9cf363d1c8cc302f08c65b96ba1a4669d81e07ed69708344df", "price_changes":[{"asset_id":"96888240988495161476033313796107536512663280794332045579302109906525918376981", "price":"0.96", "size":"776.73", "side":"BUY", "hash":"4c0db597be9350fe747affa9507f1e4ac2dc8cb5", "best_bid":"0.97", "best_ask":"0.98"}, {"asset_id":"81916206347121459497221114766050949090435061493822476265356047392175668050706", "price":"0.04", "size":"776.73", "side":"SELL", "hash":"03d300b7a2dd98b1aa8b2dc12ec6dbd62eda16c1", "best_bid":"0.02", "best_ask":"0.03"}], "timestamp":"1770241467415", "event_type":"price_change"}
{"market":"0x38f3050258345e9cf363d1c8cc302f08c65b96ba1a4669d81e07ed69708344df", "price_changes":[{"asset_id":"96888240988495161476033313796107536512663280794332045579302109906525918376981", "price":"0.96", "size":"803.73", "side":"BUY", "hash":"a5ded132fc4fca76565a24486985cfb9b11aa86c", "best_bid":"0.97", "best_ask":"0.98"}, {"asset_id":"81916206347121459497221114766050949090435061493822476265356047392175668050706", "price":"0.04", "size":"803.73", "side":"SELL", "hash":"445eac4ee14b6dd91c6a7206e8a0d4f4a5e71a9e", "best_bid":"0.02", "best_ask":"0.03"}], "timestamp":"1770241467489", "event_type":"price_change"}
{"market":"0x38f3050258345e9cf363d1c8cc302f08c65b96ba1a4669d81e07ed69708344df", "price_changes":[{"asset_id":"96888240988495161476033313796107536512663280794332045579302109906525918376981", "price":"0.95", "size":"650", "side":"BUY", "hash":"5e9765359fa76ace8046d040e48bf54571fab8b2", "best_bid":"0.97", "best_ask":"0.98"}, {"asset_id":"81916206347121459497221114766050949090435061493822476265356047392175668050706", "price":"0.05", "size":"650", "side":"SELL", "hash":"8c2446e32a0797d26641294f318c96549091683b", "best_bid":"0.02", "best_ask":"0.03"}], "timestamp":"1770241467490", "event_type":"price_change"}
{"market":"0x38f3050258345e9cf363d1c8cc302f08c65b96ba1a4669d81e07ed69708344df", "price_changes":[{"asset_id":"96888240988495161476033313796107536512663280794332045579302109906525918376981", "price":"0.94", "size":"726", "side":"BUY", "hash":"59d7b4a7b083c834b1523fc3dda1b6490674eae1", "best_bid":"0.97", "best_ask":"0.98"}, {"asset_id":"81916206347121459497221114766050949090435061493822476265356047392175668050706", "price":"0.06", "size":"726", "side":"SELL", "hash":"bd6189e91971d962fa718876d8dde944d859639f", "best_bid":"0.02", "best_ask":"0.03"}], "timestamp":"1770241467545", "event_type":"price_change"}
{"market":"0x38f3050258345e9cf363d1c8cc302f08c65b96ba1a4669d81e07ed69708344df", "price_changes":[{"asset_id":"96888240988495161476033313796107536512663280794332045579302109906525918376981", "price":"0.95", "size":"677", "side":"BUY", "hash":"7b0daa137f48ac3be75cd7f52fdce9c3013e799a", "best_bid":"0.97", "best_ask":"0.98"}, {"asset_id":"81916206347121459497221114766050949090435061493822476265356047392175668050706", "price":"0.05", "size":"677", "side":"SELL", "hash":"c269f1a1ef39fd7447b31d488910aec1c0ce0c37", "best_bid":"0.02", "best_ask":"0.03"}], "timestamp":"1770241467550", "event_type":"price_change"}
{"market":"0x38f3050258345e9cf363d1c8cc302f08c65b96ba1a4669d81e07ed69708344df", "price_changes":[{"asset_id":"81916206347121459497221114766050949090435061493822476265356047392175668050706", "price":"0.01", "size":"4207.07", "side":"BUY", "hash":"6f5cd5eeab67c3ad56f312f420f4b0545bca10e0", "best_bid":"0.02", "best_ask":"0.03"}, {"asset_id":"96888240988495161476033313796107536512663280794332045579302109906525918376981", "price":"0.99", "size":"4207.07", "side":"SELL", "hash":"6b06cc5ea30247d1d1d3eb30f2aa3695745ff467", "best_bid":"0.97", "best_ask":"0.98"}], "timestamp":"1770241467551", "event_type":"price_change"}
{"market":"0x38f3050258345e9cf363d1c8cc302f08c65b96ba1a4669d81e07ed69708344df", "price_changes":[{"asset_id":"81916206347121459497221114766050949090435061493822476265356047392175668050706", "price":"0.01", "size":"4234.07", "side":"BUY", "hash":"134ac89e42f3d5022d5b0915c61395f589bc6128", "best_bid":"0.02", "best_ask":"0.03"}, {"asset_id":"96888240988495161476033313796107536512663280794332045579302109906525918376981", "price":"0.99", "size":"4234.07", "side":"SELL", "hash":"f018d278dc99c527ca7bab3ded9ecc0bd5b57c54", "best_bid":"0.97", "best_ask":"0.98"}], "timestamp":"1770241467554", "event_type":"price_change"}
{"market":"0x38f3050258345e9cf363d1c8cc302f08c65b96ba1a4669d81e07ed69708344df", "price_changes":[{"asset_id":"96888240988495161476033313796107536512663280794332045579302109906525918376981", "price":"0.95", "size":"650", "side":"BUY", "hash":"286ee48cc5f65026d6a9f150a5d6e76918dc189c", "best_bid":"0.97", "best_ask":"0.98"}, {"asset_id":"81916206347121459497221114766050949090435061493822476265356047392175668050706", "price":"0.05", "size":"650", "side":"SELL", "hash":"eea4b7721c30ef3b8470a6bbd86d393f92bf5482", "best_bid":"0.02", "best_ask":"0.03"}], "timestamp":"1770241467560", "event_type":"price_change"}
{"market":"0x38f3050258345e9cf363d1c8cc302f08c65b96ba1a4669d81e07ed69708344df", "price_changes":[{"asset_id":"96888240988495161476033313796107536512663280794332045579302109906525918376981", "price":"0.94", "size":"753", "side":"BUY", "hash":"ebd7c41226c57a156c8457a328e086918b1c926a", "best_bid":"0.97", "best_ask":"0.98"}, {"asset_id":"81916206347121459497221114766050949090435061493822476265356047392175668050706", "price":"0.06", "size":"753", "side":"SELL", "hash":"fd2ed2e53891b55f5f9cc0587e6f0f207591f7e7", "best_bid":"0.02", "best_ask":"0.03"}], "timestamp":"1770241467561", "event_type":"price_change"}
{"market":"0x38f3050258345e9cf363d1c8cc302f08c65b96ba1a4669d81e07ed69708344df", "price_changes":[{"asset_id":"81916206347121459497221114766050949090435061493822476265356047392175668050706", "price":"0.01", "size":"4207.07", "side":"BUY", "hash":"88fbc5c0b5fc533168e5271b5f91b1fde08dc417", "best_bid":"0.02", "best_ask":"0.03"}, {"asset_id":"96888240988495161476033313796107536512663280794332045579302109906525918376981", "price":"0.99", "size":"4207.07", "side":"SELL", "hash":"d8a099963048d2a1c98e70a106e39bf27d632247", "best_bid":"0.97", "best_ask":"0.98"}], "timestamp":"1770241467562", "event_type":"price_change"}
{"market":"0x38f3050258345e9cf363d1c8cc302f08c65b96ba1a4669d81e07ed69708344df", "price_changes":[{"asset_id":"81916206347121459497221114766050949090435061493822476265356047392175668050706", "price":"0.01", "size":"4234.07", "side":"BUY", "hash":"bd51ebe6f7ef3bde12db9c237c54c1be2206c60f", "best_bid":"0.02", "best_ask":"0.03"}, {"asset_id":"96888240988495161476033313796107536512663280794332045579302109906525918376981", "price":"0.99", "size":"4234.07", "side":"SELL", "hash":"a0afcff51882ec5687a5ee56af06158b572ded60", "best_bid":"0.97", "best_ask":"0.98"}], "timestamp":"1770241467569", "event_type":"price_change"}
{"market":"0x38f3050258345e9cf363d1c8cc302f08c65b96ba1a4669d81e07ed69708344df", "price_changes":[{"asset_id":"81916206347121459497221114766050949090435061493822476265356047392175668050706", "price":"0.01", "size":"4261.07", "side":"BUY", "hash":"0a6f5868d2ea75023a04ca97170d8597fa654315", "best_bid":"0.02", "best_ask":"0.03"}, {"asset_id":"96888240988495161476033313796107536512663280794332045579302109906525918376981", "price":"0.99", "size":"4261.07", "side":"SELL", "hash":"56e2da62383e93d9d0804df2d3f0c92c95e1b978", "best_bid":"0.97", "best_ask":"0.98"}], "timestamp":"1770241467573", "event_type":"price_change"}
{"market":"0x38f3050258345e9cf363d1c8cc302f08c65b96ba1a4669d81e07ed69708344df", "price_changes":[{"asset_id":"81916206347121459497221114766050949090435061493822476265356047392175668050706", "price":"0.01", "size":"4234.07", "side":"BUY", "hash":"3ae231edaea461c02c2234dcdccc478199211874", "best_bid":"0.02", "best_ask":"0.03"}, {"asset_id":"96888240988495161476033313796107536512663280794332045579302109906525918376981", "price":"0.99", "size":"4234.07", "side":"SELL", "hash":"f1dcbc620482a1402f77cef44f6ca44877a7e67e", "best_bid":"0.97", "best_ask":"0.98"}], "timestamp":"1770241467573", "event_type":"price_change"}
{"market":"0x38f3050258345e9cf363d1c8cc302f08c65b96ba1a4669d81e07ed69708344df", "price_changes":[{"asset_id":"96888240988495161476033313796107536512663280794332045579302109906525918376981", "price":"0.95", "size":"623", "side":"BUY", "hash":"673f1b03650656a27e878a166bf64d91d5bda6bb", "best_bid":"0.97", "best_ask":"0.98"}, {"asset_id":"81916206347121459497221114766050949090435061493822476265356047392175668050706", "price":"0.05", "size":"623", "side":"SELL", "hash":"c4f8bd1bc1418e5a24754b21c3e6bb7f313a106b", "best_bid":"0.02", "best_ask":"0.03"}], "timestamp":"1770241467686", "event_type":"price_change"}
{"market":"0x38f3050258345e9cf363d1c8cc302f08c65b96ba1a4669d81e07ed69708344df", "price_changes":[{"asset_id":"96888240988495161476033313796107536512663280794332045579302109906525918376981", "price":"0.94", "size":"780", "side":"BUY", "hash":"83cf6b045673030d8be91e24ecbd4da763c96ed6", "best_bid":"0.97", "best_ask":"0.98"}, {"asset_id":"81916206347121459497221114766050949090435061493822476265356047392175668050706", "price":"0.06", "size":"780", "side":"SELL", "hash":"3acc16854bc4b454f92ef54b5f2dea6000f7627f", "best_bid":"0.02", "best_ask":"0.03"}], "timestamp":"1770241467687", "event_type":"price_change"}
{"market":"0x38f3050258345e9cf363d1c8cc302f08c65b96ba1a4669d81e07ed69708344df", "price_changes":[{"asset_id":"81916206347121459497221114766050949090435061493822476265356047392175668050706", "price":"0.01", "size":"4207.07", "side":"BUY", "hash":"64cdd1af18f375a93b42c1d02427b4069fc5e89f", "best_bid":"0.02", "best_ask":"0.03"}, {"asset_id":"96888240988495161476033313796107536512663280794332045579302109906525918376981", "price":"0.99", "size":"4207.07", "side":"SELL", "hash":"c77da67a1b2d6095a2d5330ed2c549afe6ff85a0", "best_bid":"0.97", "best_ask":"0.98"}], "timestamp":"1770241467688", "event_type":"price_change"}
{"market":"0x38f3050258345e9cf363d1c8cc302f08c65b96ba1a4669d81e07ed69708344df", "price_changes":[{"asset_id":"81916206347121459497221114766050949090435061493822476265356047392175668050706", "price":"0.01", "size":"4180.07", "side":"BUY", "hash":"42e835935f24d2a88094e860be4c6dee7f5e0d7e", "best_bid":"0.02", "best_ask":"0.03"}, {"asset_id":"96888240988495161476033313796107536512663280794332045579302109906525918376981", "price":"0.99", "size":"4180.07", "side":"SELL", "hash":"6eaf53f5afb1bd505a9e1b91f17d2fafb57e92c5", "best_bid":"0.97", "best_ask":"0.98"}], "timestamp":"1770241467688", "event_type":"price_change"}
{"market":"0x38f3050258345e9cf363d1c8cc302f08c65b96ba1a4669d81e07ed69708344df", "price_changes":[{"asset_id":"81916206347121459497221114766050949090435061493822476265356047392175668050706", "price":"0.01", "size":"4207.07", "side":"BUY", "hash":"6cecdadad68947bdb6494963d4a74c2808665235", "best_bid":"0.02", "best_ask":"0.03"}, {"asset_id":"96888240988495161476033313796107536512663280794332045579302109906525918376981", "price":"0.99", "size":"4207.07", "side":"SELL", "hash":"1ccfe72754dc3c9d98e6262817244428e00ef0da", "best_bid":"0.97", "best_ask":"0.98"}], "timestamp":"1770241467689", "event_type":"price_change"}
{"market":"0x38f3050258345e9cf363d1c8cc302f08c65b96ba1a4669d81e07ed69708344df", "price_changes":[{"asset_id":"81916206347121459497221114766050949090435061493822476265356047392175668050706", "price":"0.01", "size":"4234.07", "side":"BUY", "hash":"4dd62700b28ab8b63c04915e45131d481b663457", "best_bid":"0.02", "best_ask":"0.03"}, {"asset_id":"96888240988495161476033313796107536512663280794332045579302109906525918376981", "price":"0.99", "size":"4234.07", "side":"SELL", "hash":"bfd263644bd26fd353b0274b71188453c5d846ca", "best_bid":"0.97", "best_ask":"0.98"}], "timestamp":"1770241467696", "event_type":"price_change"}
{"market":"0x38f3050258345e9cf363d1c8cc302f08c65b96ba1a4669d81e07ed69708344df", "price_changes":[{"asset_id":"81916206347121459497221114766050949090435061493822476265356047392175668050706", "price":"0.01", "size":"4261.07", "side":"BUY", "hash":"21b109c2731ece19924d92947ab1dfcb75f0db47", "best_bid":"0.02", "best_ask":"0.03"}, {"asset_id":"96888240988495161476033313796107536512663280794332045579302109906525918376981", "price":"0.99", "size":"4261.07", "side":"SELL", "hash":"a0383d0a1f7a0bcecdc2b64500cd2870668db58d", "best_bid":"0.97", "best_ask":"0.98"}], "timestamp":"1770241467714", "event_type":"price_change"}
{"market":"0x38f3050258345e9cf363d1c8cc302f08c65b96ba1a4669d81e07ed69708344df", "price_changes":[{"asset_id":"81916206347121459497221114766050949090435061493822476265356047392175668050706", "price":"0.01", "size":"4234.07", "side":"BUY", "hash":"64b3fc0699eb80a754508e6bbab74d9fac36c898", "best_bid":"0.02", "best_ask":"0.03"}, {"asset_id":"96888240988495161476033313796107536512663280794332045579302109906525918376981", "price":"0.99", "size":"4234.07", "side":"SELL", "hash":"509794dde73e58985adce74c685b153b60d05bc0", "best_bid":"0.97", "best_ask":"0.98"}], "timestamp":"1770241467721", "event_type":"price_change"}
{"market":"0x38f3050258345e9cf363d1c8cc302f08c65b96ba1a4669d81e07ed69708344df", "price_changes":[{"asset_id":"96888240988495161476033313796107536512663280794332045579302109906525918376981", "price":"0.97", "size":"452", "side":"BUY", "hash":"97dbb7465ebfa235d301a6b951449dadc658d8c9", "best_bid":"0.97", "best_ask":"0.98"}, {"asset_id":"81916206347121459497221114766050949090435061493822476265356047392175668050706", "price":"0.03", "size":"452", "side":"SELL", "hash":"049b1dba01451c260edd5357b6e3285e7148fd5c", "best_bid":"0.02", "best_ask":"0.03"}], "timestamp":"1770241467789", "event_type":"price_change"}
{"market":"0x38f3050258345e9cf363d1c8cc302f08c65b96ba1a4669d81e07ed69708344df", "price_changes":[{"asset_id":"81916206347121459497221114766050949090435061493822476265356047392175668050706", "price":"0.02", "size":"472.67", "side":"BUY", "hash":"d722b9433ffcb1084c0d9ca888a48c51e7bf3fe2", "best_bid":"0.02", "best_ask":"0.03"}, {"asset_id":"96888240988495161476033313796107536512663280794332045579302109906525918376981", "price":"0.98", "size":"472.67", "side":"SELL", "hash":"46f05b73b0fb633389744cc1b9fa970a4dd41cd3", "best_bid":"0.97", "best_ask":"0.98"}], "timestamp":"1770241467891", "event_type":"price_change"}
{"market":"0x38f3050258345e9cf363d1c8cc302f08c65b96ba1a4669d81e07ed69708344df", "price_changes":[{"asset_id":"81916206347121459497221114766050949090435061493822476265356047392175668050706", "price":"0.01", "size":"4257.07", "side":"BUY", "hash":"faf495fd08c44f0e9eaad1b3a25929999fa97415", "best_bid":"0.02", "best_ask":"0.03"}, {"asset_id":"96888240988495161476033313796107536512663280794332045579302109906525918376981", "price":"0.99", "size":"4257.07", "side":"SELL", "hash":"e6808175da3f5430ccac22e982c36bc1f39a43a5", "best_bid":"0.97", "best_ask":"0.98"}], "timestamp":"1770241467893", "event_type":"price_change"}
{"market":"0x38f3050258345e9cf363d1c8cc302f08c65b96ba1a4669d81e07ed69708344df", "price_changes":[{"asset_id":"96888240988495161476033313796107536512663280794332045579302109906525918376981", "price":"0.95", "size":"650", "side":"BUY", "hash":"d0e4539315770c6942d27a35f982f8ac9824039d", "best_bid":"0.97", "best_ask":"0.98"}, {"asset_id":"81916206347121459497221114766050949090435061493822476265356047392175668050706", "price":"0.05", "size":"650", "side":"SELL", "hash":"13c3e7de293f8c6d3cb614964645e0caf9c7fd37", "best_bid":"0.02", "best_ask":"0.03"}], "timestamp":"1770241467979", "event_type":"price_change"}
{"market":"0x38f3050258345e9cf363d1c8cc302f08c65b96ba1a4669d81e07ed69708344df", "price_changes":[{"asset_id":"96888240988495161476033313796107536512663280794332045579302109906525918376981", "price":"0.94", "size":"753", "side":"BUY", "hash":"bf7b0acac065684f7079a8297ad2d6bbb2b91f88", "best_bid":"0.97", "best_ask":"0.98"}, {"asset_id":"81916206347121459497221114766050949090435061493822476265356047392175668050706", "price":"0.06", "size":"753", "side":"SELL", "hash":"bf22baccfb1063b9c737e6680f898fd57b38824b", "best_bid":"0.02", "best_ask":"0.03"}], "timestamp":"1770241467982", "event_type":"price_change"}
{"market":"0x38f3050258345e9cf363d1c8cc302f08c65b96ba1a4669d81e07ed69708344df", "price_changes":[{"asset_id":"96888240988495161476033313796107536512663280794332045579302109906525918376981", "price":"0.95", "size":"623", "side":"BUY", "hash":"3fb2cd75e24cbb0b94612f74a6d882018b8c96b2", "best_bid":"0.97", "best_ask":"0.98"}, {"asset_id":"81916206347121459497221114766050949090435061493822476265356047392175668050706", "price":"0.05", "size":"623", "side":"SELL", "hash":"97b943f1313ae3b8e891b36a577f7d422bc056f7", "best_bid":"0.02", "best_ask":"0.03"}], "timestamp":"1770241468100", "event_type":"price_change"}
{"market":"0x38f3050258345e9cf363d1c8cc302f08c65b96ba1a4669d81e07ed69708344df", "price_changes":[{"asset_id":"96888240988495161476033313796107536512663280794332045579302109906525918376981", "price":"0.94", "size":"780", "side":"BUY", "hash":"e5420f84fa6e13f384629c5e50905500ca2f6e44", "best_bid":"0.97", "best_ask":"0.98"}, {"asset_id":"81916206347121459497221114766050949090435061493822476265356047392175668050706", "price":"0.06", "size":"780", "side":"SELL", "hash":"b95f68784b07fa503fd2110de4774c12a94e7d81", "best_bid":"0.02", "best_ask":"0.03"}], "timestamp":"1770241468101", "event_type":"price_change"}
{"market":"0x38f3050258345e9cf363d1c8cc302f08c65b96ba1a4669d81e07ed69708344df", "price_changes":[{"asset_id":"96888240988495161476033313796107536512663280794332045579302109906525918376981", "price":"0.97", "size":"432", "side":"BUY", "hash":"a25713091d5d6af27d1b771840a2f61e29fb5230", "best_bid":"0.97", "best_ask":"0.98"}, {"asset_id":"81916206347121459497221114766050949090435061493822476265356047392175668050706", "price":"0.03", "size":"432", "side":"SELL", "hash":"5d1fa9f86f03f807375847717d10034d71ab4c2e", "best_bid":"0.02", "best_ask":"0.03"}], "timestamp":"1770241468134", "event_type":"price_change"}
{"market":"0x38f3050258345e9cf363d1c8cc302f08c65b96ba1a4669d81e07ed69708344df", "price_changes":[{"asset_id":"81916206347121459497221114766050949090435061493822476265356047392175668050706", "price":"0.01", "size":"4234.07", "side":"BUY", "hash":"25ab678998038518dea6e2d28c470bdc4c6a8c80", "best_bid":"0.02", "best_ask":"0.03"}, {"asset_id":"96888240988495161476033313796107536512663280794332045579302109906525918376981", "price":"0.99", "size":"4234.07", "side":"SELL", "hash":"77ea0ab5ea972a67b388c9c51cd09078fb4f514e", "best_bid":"0.97", "best_ask":"0.98"}], "timestamp":"1770241468174", "event_type":"price_change"}
{"market":"0x38f3050258345e9cf363d1c8cc302f08c65b96ba1a4669d81e07ed69708344df", "price_changes":[{"asset_id":"81916206347121459497221114766050949090435061493822476265356047392175668050706", "price":"0.02", "size":"495.67", "side":"BUY", "hash":"bbfb6f078748633140291306c9ead158eec741d9", "best_bid":"0.02", "best_ask":"0.03"}, {"asset_id":"96888240988495161476033313796107536512663280794332045579302109906525918376981", "price":"0.98", "size":"495.67", "side":"SELL", "hash":"abbdd8f2a09c3d654a9c705887540254a257b780", "best_bid":"0.97", "best_ask":"0.98"}], "timestamp":"1770241468178", "event_type":"price_change"}
{"market":"0x38f3050258345e9cf363d1c8cc302f08c65b96ba1a4669d81e07ed69708344df", "price_changes":[{"asset_id":"81916206347121459497221114766050949090435061493822476265356047392175668050706", "price":"0.02", "size":"472.67", "side":"BUY", "hash":"6638c0bc156678595df4860a3f996c405ded0f39", "best_bid":"0.02", "best_ask":"0.03"}, {"asset_id":"96888240988495161476033313796107536512663280794332045579302109906525918376981", "price":"0.98", "size":"472.67", "side":"SELL", "hash":"3f4e2eaa06eb439acfd163e55b4b1d63d3bf4b5f", "best_bid":"0.97", "best_ask":"0.98"}], "timestamp":"1770241468444", "event_type":"price_change"}
{"market":"0x38f3050258345e9cf363d1c8cc302f08c65b96ba1a4669d81e07ed69708344df", "price_changes":[{"asset_id":"81916206347121459497221114766050949090435061493822476265356047392175668050706", "price":"0.01", "size":"4257.07", "side":"BUY", "hash":"1051a3fba3447963e9fb0c612d3057919cbc2caf", "best_bid":"0.02", "best_ask":"0.03"}, {"asset_id":"96888240988495161476033313796107536512663280794332045579302109906525918376981", "price":"0.99", "size":"4257.07", "side":"SELL", "hash":"9a67a231056ed043aa4fef0d6d640bde058a9773", "best_bid":"0.97", "best_ask":"0.98"}], "timestamp":"1770241468445", "event_type":"price_change"}
{"market":"0x38f3050258345e9cf363d1c8cc302f08c65b96ba1a4669d81e07ed69708344df", "price_changes":[{"asset_id":"96888240988495161476033313796107536512663280794332045579302109906525918376981", "price":"0.96", "size":"780.73", "side":"BUY", "hash":"c9edf307c2f53236ef6c80abc446a17722d5a7b8", "best_bid":"0.97", "best_ask":"0.98"}, {"asset_id":"81916206347121459497221114766050949090435061493822476265356047392175668050706", "price":"0.04", "size":"780.73", "side":"SELL", "hash":"15962bf0a89a17378fc567eb629ded27981ad585", "best_bid":"0.02", "best_ask":"0.03"}], "timestamp":"1770241468446", "event_type":"price_change"}
{"market":"0x38f3050258345e9cf363d1c8cc302f08c65b96ba1a4669d81e07ed69708344df", "price_changes":[{"asset_id":"96888240988495161476033313796107536512663280794332045579302109906525918376981", "price":"0.95", "size":"646", "side":"BUY", "hash":"000836682dba1c1334baf810fd8f19bbfa68f804", "best_bid":"0.97", "best_ask":"0.98"}, {"asset_id":"81916206347121459497221114766050949090435061493822476265356047392175668050706", "price":"0.05", "size":"646", "side":"SELL", "hash":"d35c89e925ce0e768df3afd844a2d80cd76a3606", "best_bid":"0.02", "best_ask":"0.03"}], "timestamp":"1770241468448", "event_type":"price_change"}
{"market":"0x38f3050258345e9cf363d1c8cc302f08c65b96ba1a4669d81e07ed69708344df", "price_changes":[{"asset_id":"96888240988495161476033313796107536512663280794332045579302109906525918376981", "price":"0.96", "size":"800.73", "side":"BUY", "hash":"089fa3af4897ee30ed81f1d3d7a0d0318aa7386c", "best_bid":"0.97", "best_ask":"0.98"}, {"asset_id":"81916206347121459497221114766050949090435061493822476265356047392175668050706", "price":"0.04", "size":"800.73", "side":"SELL", "hash":"1be0683ea3c362a313fb15942d8948c5ae565d25", "best_bid":"0.02", "best_ask":"0.03"}], "timestamp":"1770241468487", "event_type":"price_change"}
{"market":"0x38f3050258345e9cf363d1c8cc302f08c65b96ba1a4669d81e07ed69708344df", "price_changes":[{"asset_id":"81916206347121459497221114766050949090435061493822476265356047392175668050706", "price":"0.01", "size":"4230.07", "side":"BUY", "hash":"12a2fc13bf62c3ad3f406e4402674aa01416d162", "best_bid":"0.02", "best_ask":"0.03"}, {"asset_id":"96888240988495161476033313796107536512663280794332045579302109906525918376981", "price":"0.99", "size":"4230.07", "side":"SELL", "hash":"e737dfcb237f2a429ef80351af35a2d45b7c43fb", "best_bid":"0.97", "best_ask":"0.98"}], "timestamp":"1770241468624", "event_type":"price_change"}
{"market":"0x38f3050258345e9cf363d1c8cc302f08c65b96ba1a4669d81e07ed69708344df", "price_changes":[{"asset_id":"81916206347121459497221114766050949090435061493822476265356047392175668050706", "price":"0.01", "size":"4257.07", "side":"BUY", "hash":"cf00d93ca4ab1f5585a2b29df42ecb1f26f2d762", "best_bid":"0.02", "best_ask":"0.03"}, {"asset_id":"96888240988495161476033313796107536512663280794332045579302109906525918376981", "price":"0.99", "size":"4257.07", "side":"SELL", "hash":"f771fecc06892cf5f40726d7de9e8a5cd49ca076", "best_bid":"0.97", "best_ask":"0.98"}], "timestamp":"1770241468625", "event_type":"price_change"}
{"market":"0x38f3050258345e9cf363d1c8cc302f08c65b96ba1a4669d81e07ed69708344df", "price_changes":[{"asset_id":"96888240988495161476033313796107536512663280794332045579302109906525918376981", "price":"0.95", "size":"673", "side":"BUY", "hash":"7ffd7f711ea474b5e92514513ec83e6a79275806", "best_bid":"0.97", "best_ask":"0.98"}, {"asset_id":"81916206347121459497221114766050949090435061493822476265356047392175668050706", "price":"0.05", "size":"673", "side":"SELL", "hash":"2f0c191d0a08e4bae5463b95644971a63694ae02", "best_bid":"0.02", "best_ask":"0.03"}], "timestamp":"1770241468626", "event_type":"price_change"}
{"market":"0x38f3050258345e9cf363d1c8cc302f08c65b96ba1a4669d81e07ed69708344df", "price_changes":[{"asset_id":"96888240988495161476033313796107536512663280794332045579302109906525918376981", "price":"0.94", "size":"753", "side":"BUY", "hash":"69962aaf4ddb2976b8ddea9dccd226387e549b61", "best_bid":"0.97", "best_ask":"0.98"}, {"asset_id":"81916206347121459497221114766050949090435061493822476265356047392175668050706", "price":"0.06", "size":"753", "side":"SELL", "hash":"26cb2c6af31b4917ff61313bf08b685b88913ccd", "best_bid":"0.02", "best_ask":"0.03"}], "timestamp":"1770241468628", "event_type":"price_change"}
{"market":"0x38f3050258345e9cf363d1c8cc302f08c65b96ba1a4669d81e07ed69708344df", "price_changes":[{"asset_id":"81916206347121459497221114766050949090435061493822476265356047392175668050706", "price":"0.01", "size":"4230.07", "side":"BUY", "hash":"1a0b459d17de5da3c3bfce0ff02369226b0c1d2d", "best_bid":"0.02", "best_ask":"0.03"}, {"asset_id":"96888240988495161476033313796107536512663280794332045579302109906525918376981", "price":"0.99", "size":"4230.07", "side":"SELL", "hash":"4ce67191c974a195e239d73f1f9f28d6952c7909", "best_bid":"0.97", "best_ask":"0.98"}], "timestamp":"1770241468634", "event_type":"price_change"}
{"market":"0x38f3050258345e9cf363d1c8cc302f08c65b96ba1a4669d81e07ed69708344df", "price_changes":[{"asset_id":"81916206347121459497221114766050949090435061493822476265356047392175668050706", "price":"0.01", "size":"4257.07", "side":"BUY", "hash":"5e1270f04a4f9a2492beb56cc83adf4d834765dc", "best_bid":"0.02", "best_ask":"0.03"}, {"asset_id":"96888240988495161476033313796107536512663280794332045579302109906525918376981", "price":"0.99", "size":"4257.07", "side":"SELL", "hash":"ce5f6d67f3e58754bcf71089da71bd086538d879", "best_bid":"0.97", "best_ask":"0.98"}], "timestamp":"1770241468635", "event_type":"price_change"}
{"market":"0x38f3050258345e9cf363d1c8cc302f08c65b96ba1a4669d81e07ed69708344df", "price_changes":[{"asset_id":"96888240988495161476033313796107536512663280794332045579302109906525918376981", "price":"0.95", "size":"700", "side":"BUY", "hash":"8f1c21daafe4f2811cba7726f478dde45ae722f1", "best_bid":"0.97", "best_ask":"0.98"}, {"asset_id":"81916206347121459497221114766050949090435061493822476265356047392175668050706", "price":"0.05", "size":"700", "side":"SELL", "hash":"baee484839fe57147b30dfa76ba63df09bdedc43", "best_bid":"0.02", "best_ask":"0.03"}], "timestamp":"1770241468636", "event_type":"price_change"}
{"market":"0x38f3050258345e9cf363d1c8cc302f08c65b96ba1a4669d81e07ed69708344df", "price_changes":[{"asset_id":"96888240988495161476033313796107536512663280794332045579302109906525918376981", "price":"0.94", "size":"726", "side":"BUY", "hash":"2f1e50a2dc1ecabe8d2c154b29a048c35d6bd9b0", "best_bid":"0.97", "best_ask":"0.98"}, {"asset_id":"81916206347121459497221114766050949090435061493822476265356047392175668050706", "price":"0.06", "size":"726", "side":"SELL", "hash":"49b506ff5624624bcbcfb80c0a474e8551ad160b", "best_bid":"0.02", "best_ask":"0.03"}], "timestamp":"1770241468645", "event_type":"price_change"}
{"market":"0x38f3050258345e9cf363d1c8cc302f08c65b96ba1a4669d81e07ed69708344df", "price_changes":[{"asset_id":"96888240988495161476033313796107536512663280794332045579302109906525918376981", "price":"0.96", "size":"773.73", "side":"BUY", "hash":"621d6927994c117385fa53c4767a074641cc9413", "best_bid":"0.97", "best_ask":"0.98"}, {"asset_id":"81916206347121459497221114766050949090435061493822476265356047392175668050706", "price":"0.04", "size":"773.73", "side":"SELL", "hash":"d2935f74d151d79387cc962477ca6ea4d899794f", "best_bid":"0.02", "best_ask":"0.03"}], "timestamp":"1770241468646", "event_type":"price_change"}
{"market":"0x38f3050258345e9cf363d1c8cc302f08c65b96ba1a4669d81e07ed69708344df", "price_changes":[{"asset_id":"96888240988495161476033313796107536512663280794332045579302109906525918376981", "price":"0.97", "size":"459", "side":"BUY", "hash":"bda3efd156d60fe1783a55eedfb3c34e64986eef", "best_bid":"0.97", "best_ask":"0.98"}, {"asset_id":"81916206347121459497221114766050949090435061493822476265356047392175668050706", "price":"0.03", "size":"459", "side":"SELL", "hash":"2c31176e4498061011dbe7d29b82fb1899b9c95e", "best_bid":"0.02", "best_ask":"0.03"}], "timestamp":"1770241468648", "event_type":"price_change"}
{"market":"0x38f3050258345e9cf363d1c8cc302f08c65b96ba1a4669d81e07ed69708344df", "price_changes":[{"asset_id":"81916206347121459497221114766050949090435061493822476265356047392175668050706", "price":"0.01", "size":"4230.07", "side":"BUY", "hash":"956d6a12f86ba864b4f406687bb1ecacaa282d5d", "best_bid":"0.02", "best_ask":"0.03"}, {"asset_id":"96888240988495161476033313796107536512663280794332045579302109906525918376981", "price":"0.99", "size":"4230.07", "side":"SELL", "hash":"a1d154dfc74f3a4a342ed044410e4331464f2e7f", "best_bid":"0.97", "best_ask":"0.98"}], "timestamp":"1770241468650", "event_type":"price_change"}
{"market":"0x38f3050258345e9cf363d1c8cc302f08c65b96ba1a4669d81e07ed69708344df", "price_changes":[{"asset_id":"81916206347121459497221114766050949090435061493822476265356047392175668050706", "price":"0.01", "size":"4257.07", "side":"BUY", "hash":"74a428531a8e67a4f35c07d3356a231230cf68ca", "best_bid":"0.02", "best_ask":"0.03"}, {"asset_id":"96888240988495161476033313796107536512663280794332045579302109906525918376981", "price":"0.99", "size":"4257.07", "side":"SELL", "hash":"56d2008227686099c19b7ef7ee3c44d25d80a3f4", "best_bid":"0.97", "best_ask":"0.98"}], "timestamp":"1770241468655", "event_type":"price_change"}
{"market":"0x38f3050258345e9cf363d1c8cc302f08c65b96ba1a4669d81e07ed69708344df", "price_changes":[{"asset_id":"81916206347121459497221114766050949090435061493822476265356047392175668050706", "price":"0.01", "size":"4234.07", "side":"BUY", "hash":"0580e41e0098e1c2b2fe60324a0d8a70969a6220", "best_bid":"0.02", "best_ask":"0.03"}, {"asset_id":"96888240988495161476033313796107536512663280794332045579302109906525918376981", "price":"0.99", "size":"4234.07", "side":"SELL", "hash":"72c354d74915058a3a3a4b38bb18253917b3dba8", "best_bid":"0.97", "best_ask":"0.98"}], "timestamp":"1770241468691", "event_type":"price_change"}
{"market":"0x38f3050258345e9cf363d1c8cc302f08c65b96ba1a4669d81e07ed69708344df", "price_changes":[{"asset_id":"96888240988495161476033313796107536512663280794332045579302109906525918376981", "price":"0.96", "size":"796.73", "side":"BUY", "hash":"23ae56c119b3dfceba55fee636b6d88df49f7663", "best_bid":"0.97", "best_ask":"0.98"}, {"asset_id":"81916206347121459497221114766050949090435061493822476265356047392175668050706", "price":"0.04", "size":"796.73", "side":"SELL", "hash":"64394e46db6f6ef96e20848aacd808de14e81870", "best_bid":"0.02", "best_ask":"0.03"}], "timestamp":"1770241468693", "event_type":"price_change"}
{"market":"0x38f3050258345e9cf363d1c8cc302f08c65b96ba1a4669d81e07ed69708344df", "price_changes":[{"asset_id":"96888240988495161476033313796107536512663280794332045579302109906525918376981", "price":"0.95", "size":"677", "side":"BUY", "hash":"549a76edf0d43f5441d03e404cd0364a2ac64e31", "best_bid":"0.97", "best_ask":"0.98"}, {"asset_id":"81916206347121459497221114766050949090435061493822476265356047392175668050706", "price":"0.05", "size":"677", "side":"SELL", "hash":"0a6fb2c3f9b3c899e2c6b62103b7b83e76f91450", "best_bid":"0.02", "best_ask":"0.03"}], "timestamp":"1770241468694", "event_type":"price_change"}
{"market":"0x38f3050258345e9cf363d1c8cc302f08c65b96ba1a4669d81e07ed69708344df", "price_changes":[{"asset_id":"81916206347121459497221114766050949090435061493822476265356047392175668050706", "price":"0.02", "size":"458.48", "side":"BUY", "hash":"1016e66bb4582bfc501742fa43145af163b87615", "best_bid":"0.02", "best_ask":"0.03"}, {"asset_id":"96888240988495161476033313796107536512663280794332045579302109906525918376981", "price":"0.98", "size":"458.48", "side":"SELL", "hash":"aab8551bf5f01303b0195657b0c5bdb3bb0a4565", "best_bid":"0.97", "best_ask":"0.98"}], "timestamp":"1770241468695", "event_type":"price_change"}
{"market":"0x38f3050258345e9cf363d1c8cc302f08c65b96ba1a4669d81e07ed69708344df", "price_changes":[{"asset_id":"81916206347121459497221114766050949090435061493822476265356047392175668050706", "price":"0.02", "size":"481.48", "side":"BUY", "hash":"5b386b163072d4e09e18cfa078e7a699f90b0827", "best_bid":"0.02", "best_ask":"0.03"}, {"asset_id":"96888240988495161476033313796107536512663280794332045579302109906525918376981", "price":"0.98", "size":"481.48", "side":"SELL", "hash":"acf691498c4f013169dcee5665b47c9794e8a2af", "best_bid":"0.97", "best_ask":"0.98"}], "timestamp":"1770241468701", "event_type":"price_change"}
{"market":"0x38f3050258345e9cf363d1c8cc302f08c65b96ba1a4669d81e07ed69708344df", "price_changes":[{"asset_id":"81916206347121459497221114766050949090435061493822476265356047392175668050706", "price":"0.01", "size":"4207.07", "side":"BUY", "hash":"1d367154521031eac04f2d1d181cf7237b6d34da", "best_bid":"0.02", "best_ask":"0.03"}, {"asset_id":"96888240988495161476033313796107536512663280794332045579302109906525918376981", "price":"0.99", "size":"4207.07", "side":"SELL", "hash":"1fc41403fded0a7f14d51d721b42e11b0218e83c", "best_bid":"0.97", "best_ask":"0.98"}], "timestamp":"1770241468744", "event_type":"price_change"}
{"market":"0x38f3050258345e9cf363d1c8cc302f08c65b96ba1a4669d81e07ed69708344df", "price_changes":[{"asset_id":"81916206347121459497221114766050949090435061493822476265356047392175668050706", "price":"0.01", "size":"4234.07", "side":"BUY", "hash":"b4d6a5b4998986a193d58cda09d06aca3ec16a33", "best_bid":"0.02", "best_ask":"0.03"}, {"asset_id":"96888240988495161476033313796107536512663280794332045579302109906525918376981", "price":"0.99", "size":"4234.07", "side":"SELL", "hash":"e94a1425962035bcd1bab94c3756d87783b0aa02", "best_bid":"0.97", "best_ask":"0.98"}], "timestamp":"1770241468746", "event_type":"price_change"}
{"market":"0x38f3050258345e9cf363d1c8cc302f08c65b96ba1a4669d81e07ed69708344df", "price_changes":[{"asset_id":"96888240988495161476033313796107536512663280794332045579302109906525918376981", "price":"0.94", "size":"753", "side":"BUY", "hash":"e8b708f658e13d5a4a50bc7d04dc0140e3967db5", "best_bid":"0.97", "best_ask":"0.98"}, {"asset_id":"81916206347121459497221114766050949090435061493822476265356047392175668050706", "price":"0.06", "size":"753", "side":"SELL", "hash":"989cfe43d1e44b9456f817056ef1692146c58129", "best_bid":"0.02", "best_ask":"0.03"}], "timestamp":"1770241468748", "event_type":"price_change"}
{"market":"0x38f3050258345e9cf363d1c8cc302f08c65b96ba1a4669d81e07ed69708344df", "price_changes":[{"asset_id":"96888240988495161476033313796107536512663280794332045579302109906525918376981", "price":"0.95", "size":"650", "side":"BUY", "hash":"5e11b5ba49c5cc9b1e2ecb2048c860326096c2e3", "best_bid":"0.97", "best_ask":"0.98"}, {"asset_id":"81916206347121459497221114766050949090435061493822476265356047392175668050706", "price":"0.05", "size":"650", "side":"SELL", "hash":"79b516cf4cc26a63c3a7405e6268a4d7bdaf1eb0", "best_bid":"0.02", "best_ask":"0.03"}], "timestamp":"1770241468750", "event_type":"price_change"}
{"market":"0x38f3050258345e9cf363d1c8cc302f08c65b96ba1a4669d81e07ed69708344df", "price_changes":[{"asset_id":"96888240988495161476033313796107536512663280794332045579302109906525918376981", "price":"0.95", "size":"623", "side":"BUY", "hash":"f64d22a048ba1f1a01e7430b8a869caf31db830c", "best_bid":"0.97", "best_ask":"0.98"}, {"asset_id":"81916206347121459497221114766050949090435061493822476265356047392175668050706", "price":"0.05", "size":"623", "side":"SELL", "hash":"8727350ddf6095a107f0b86d5f07324571bf9f04", "best_bid":"0.02", "best_ask":"0.03"}], "timestamp":"1770241468767", "event_type":"price_change"}
{"market":"0x38f3050258345e9cf363d1c8cc302f08c65b96ba1a4669d81e07ed69708344df", "price_changes":[{"asset_id":"81916206347121459497221114766050949090435061493822476265356047392175668050706", "price":"0.01", "size":"4261.07", "side":"BUY", "hash":"9fc39c236bd5fda9638d4d024aa24205a6e544c1", "best_bid":"0.02", "best_ask":"0.03"}, {"asset_id":"96888240988495161476033313796107536512663280794332045579302109906525918376981", "price":"0.99", "size":"4261.07", "side":"SELL", "hash":"5f1a7e2911a943506ed3349f6de8e1a7e814d3f9", "best_bid":"0.97", "best_ask":"0.98"}], "timestamp":"1770241468769", "event_type":"price_change"}
{"market":"0x38f3050258345e9cf363d1c8cc302f08c65b96ba1a4669d81e07ed69708344df", "price_changes":[{"asset_id":"81916206347121459497221114766050949090435061493822476265356047392175668050706", "price":"0.01", "size":"4234.07", "side":"BUY", "hash":"38577b54c46648864f3f1e966fc01b68688f7bd5", "best_bid":"0.02", "best_ask":"0.03"}, {"asset_id":"96888240988495161476033313796107536512663280794332045579302109906525918376981", "price":"0.99", "size":"4234.07", "side":"SELL", "hash":"c5bc163df530c73b04b29086ff1278b300274a27", "best_bid":"0.97", "best_ask":"0.98"}], "timestamp":"1770241468770", "event_type":"price_change"}
{"market":"0x38f3050258345e9cf363d1c8cc302f08c65b96ba1a4669d81e07ed69708344df", "price_changes":[{"asset_id":"96888240988495161476033313796107536512663280794332045579302109906525918376981", "price":"0.96", "size":"823.73", "side":"BUY", "hash":"b7193dfc55e57d958d4a0c43b1995942d40dbf71", "best_bid":"0.97", "best_ask":"0.98"}, {"asset_id":"81916206347121459497221114766050949090435061493822476265356047392175668050706", "price":"0.04", "size":"823.73", "side":"SELL", "hash":"9cbc1f37580474b89dc91ca7223da5c66551d4cd", "best_bid":"0.02", "best_ask":"0.03"}], "timestamp":"1770241468771", "event_type":"price_change"}
{"market":"0x38f3050258345e9cf363d1c8cc302f08c65b96ba1a4669d81e07ed69708344df", "price_changes":[{"asset_id":"81916206347121459497221114766050949090435061493822476265356047392175668050706", "price":"0.01", "size":"4261.07", "side":"BUY", "hash":"2dd026f96e0d32e5668a8e75d3973fde98b71ed0", "best_bid":"0.02", "best_ask":"0.03"}, {"asset_id":"96888240988495161476033313796107536512663280794332045579302109906525918376981", "price":"0.99", "size":"4261.07", "side":"SELL", "hash":"5dd046c5ce8bdb2c24720dadadb45c30e3aeb0b3", "best_bid":"0.97", "best_ask":"0.98"}], "timestamp":"1770241468772", "event_type":"price_change"}
{"market":"0x38f3050258345e9cf363d1c8cc302f08c65b96ba1a4669d81e07ed69708344df", "price_changes":[{"asset_id":"96888240988495161476033313796107536512663280794332045579302109906525918376981", "price":"0.97", "size":"432", "side":"BUY", "hash":"ed6c6618e949d2b5b4c5e30217111c266f3b1872", "best_bid":"0.97", "best_ask":"0.98"}, {"asset_id":"81916206347121459497221114766050949090435061493822476265356047392175668050706", "price":"0.03", "size":"432", "side":"SELL", "hash":"8cfd765cd28db454ae2e870b29190b97d6eacbd1", "best_bid":"0.02", "best_ask":"0.03"}], "timestamp":"1770241468773", "event_type":"price_change"}
{"market":"0x38f3050258345e9cf363d1c8cc302f08c65b96ba1a4669d81e07ed69708344df", "price_changes":[{"asset_id":"81916206347121459497221114766050949090435061493822476265356047392175668050706", "price":"0.01", "size":"4234.07", "side":"BUY", "hash":"fc568b64f8f0d29d96b5fdc4ff4fd3cf5aa45449", "best_bid":"0.02", "best_ask":"0.03"}, {"asset_id":"96888240988495161476033313796107536512663280794332045579302109906525918376981", "price":"0.99", "size":"4234.07", "side":"SELL", "hash":"6f60574e024da9ae5b9057dd02af41760d0215e5", "best_bid":"0.97", "best_ask":"0.98"}], "timestamp":"1770241468776", "event_type":"price_change"}
{"market":"0x38f3050258345e9cf363d1c8cc302f08c65b96ba1a4669d81e07ed69708344df", "price_changes":[{"asset_id":"96888240988495161476033313796107536512663280794332045579302109906525918376981", "price":"0.95", "size":"650", "side":"BUY", "hash":"9c2fcb6073fc57e835cdee18b2778bd4901190c3", "best_bid":"0.97", "best_ask":"0.98"}, {"asset_id":"81916206347121459497221114766050949090435061493822476265356047392175668050706", "price":"0.05", "size":"650", "side":"SELL", "hash":"b693e92e87b8c2782f5f2a2cb8c6f98bbe71eddc", "best_bid":"0.02", "best_ask":"0.03"}], "timestamp":"1770241468784", "event_type":"price_change"}
{"market":"0x38f3050258345e9cf363d1c8cc302f08c65b96ba1a4669d81e07ed69708344df", "price_changes":[{"asset_id":"81916206347121459497221114766050949090435061493822476265356047392175668050706", "price":"0.01", "size":"4207.07", "side":"BUY", "hash":"4b89ba4c89a54898fd3f1987e5d01ecdf3d0308e", "best_bid":"0.02", "best_ask":"0.03"}, {"asset_id":"96888240988495161476033313796107536512663280794332045579302109906525918376981", "price":"0.99", "size":"4207.07", "side":"SELL", "hash":"c00f7f19ec0ea5f7bd7da8dbb2a4851ceba0ad9f", "best_bid":"0.97", "best_ask":"0.98"}], "timestamp":"1770241468866", "event_type":"price_change"}
{"market":"0x38f3050258345e9cf363d1c8cc302f08c65b96ba1a4669d81e07ed69708344df", "price_changes":[{"asset_id":"81916206347121459497221114766050949090435061493822476265356047392175668050706", "price":"0.01", "size":"4234.07", "side":"BUY", "hash":"a22c1089232b24a2d431f23bfab562350945c138", "best_bid":"0.02", "best_ask":"0.03"}, {"asset_id":"96888240988495161476033313796107536512663280794332045579302109906525918376981", "price":"0.99", "size":"4234.07", "side":"SELL", "hash":"2671f70d10bf00a115bc469c78e36cce70e6fec5", "best_bid":"0.97", "best_ask":"0.98"}], "timestamp":"1770241468869", "event_type":"price_change"}
{"market":"0x38f3050258345e9cf363d1c8cc302f08c65b96ba1a4669d81e07ed69708344df", "price_changes":[{"asset_id":"96888240988495161476033313796107536512663280794332045579302109906525918376981", "price":"0.95", "size":"677", "side":"BUY", "hash":"f3f55cf6de04a0fbd2e2b5cf8e81e29887d66587", "best_bid":"0.97", "best_ask":"0.98"}, {"asset_id":"81916206347121459497221114766050949090435061493822476265356047392175668050706", "price":"0.05", "size":"677", "side":"SELL", "hash":"da5a049d96a28552fb1f0f76720a1c5d94de7135", "best_bid":"0.02", "best_ask":"0.03"}], "timestamp":"1770241468871", "event_type":"price_change"}
{"market":"0x38f3050258345e9cf363d1c8cc302f08c65b96ba1a4669d81e07ed69708344df", "price_changes":[{"asset_id":"96888240988495161476033313796107536512663280794332045579302109906525918376981", "price":"0.94", "size":"726", "side":"BUY", "hash":"9e51a5370da41ac03192136ac537e55362da3e49", "best_bid":"0.97", "best_ask":"0.98"}, {"asset_id":"81916206347121459497221114766050949090435061493822476265356047392175668050706", "price":"0.06", "size":"726", "side":"SELL", "hash":"9f3ee428b75386464922bc26be03953f98b9556c", "best_bid":"0.02", "best_ask":"0.03"}], "timestamp":"1770241468878", "event_type":"price_change"}
{"market":"0x38f3050258345e9cf363d1c8cc302f08c65b96ba1a4669d81e07ed69708344df", "price_changes":[{"asset_id":"81916206347121459497221114766050949090435061493822476265356047392175668050706", "price":"0.01", "size":"4261.07", "side":"BUY", "hash":"49231fd4586cb2eb07ef67b309bd231202773ac8", "best_bid":"0.02", "best_ask":"0.03"}, {"asset_id":"96888240988495161476033313796107536512663280794332045579302109906525918376981", "price":"0.99", "size":"4261.07", "side":"SELL", "hash":"b2ad39bf9f6e29d224ba1c70b569316a4e6ad59f", "best_bid":"0.97", "best_ask":"0.98"}], "timestamp":"1770241468890", "event_type":"price_change"}
{"market":"0x38f3050258345e9cf363d1c8cc302f08c65b96ba1a4669d81e07ed69708344df", "price_changes":[{"asset_id":"96888240988495161476033313796107536512663280794332045579302109906525918376981", "price":"0.95", "size":"650", "side":"BUY", "hash":"c48e74ebd9c1acf00d7b80e6b16c867797e297a8", "best_bid":"0.97", "best_ask":"0.98"}, {"asset_id":"81916206347121459497221114766050949090435061493822476265356047392175668050706", "price":"0.05", "size":"650", "side":"SELL", "hash":"ab79166982e3cc09ea5c776f33f4f8e5927b2b9b", "best_bid":"0.02", "best_ask":"0.03"}], "timestamp":"1770241468891", "event_type":"price_change"}
{"market":"0x38f3050258345e9cf363d1c8cc302f08c65b96ba1a4669d81e07ed69708344df", "price_changes":[{"asset_id":"96888240988495161476033313796107536512663280794332045579302109906525918376981", "price":"0.97", "size":"459", "side":"BUY", "hash":"d2b511eba621da95a6b4b58d6e8e94d5bee202b7", "best_bid":"0.97", "best_ask":"0.98"}, {"asset_id":"81916206347121459497221114766050949090435061493822476265356047392175668050706", "price":"0.03", "size":"459", "side":"SELL", "hash":"9c6087a45b10e7a8dc39bcf10036a5b98b76512f", "best_bid":"0.02", "best_ask":"0.03"}], "timestamp":"1770241468892", "event_type":"price_change"}
{"market":"0x38f3050258345e9cf363d1c8cc302f08c65b96ba1a4669d81e07ed69708344df", "price_changes":[{"asset_id":"96888240988495161476033313796107536512663280794332045579302109906525918376981", "price":"0.96", "size":"796.73", "side":"BUY", "hash":"1e963c7e4179ea0a1d396abfbbb514e53b55a894", "best_bid":"0.97", "best_ask":"0.98"}, {"asset_id":"81916206347121459497221114766050949090435061493822476265356047392175668050706", "price":"0.04", "size":"796.73", "side":"SELL", "hash":"ce2fe3620fe9b7b12566a2b73238e3f85835e1c0", "best_bid":"0.02", "best_ask":"0.03"}], "timestamp":"1770241468893", "event_type":"price_change"}
{"market":"0x38f3050258345e9cf363d1c8cc302f08c65b96ba1a4669d81e07ed69708344df", "price_changes":[{"asset_id":"81916206347121459497221114766050949090435061493822476265356047392175668050706", "price":"0.01", "size":"4234.07", "side":"BUY", "hash":"9091d9546a11d1998af93d0a16dda8ef7436e732", "best_bid":"0.02", "best_ask":"0.03"}, {"asset_id":"96888240988495161476033313796107536512663280794332045579302109906525918376981", "price":"0.99", "size":"4234.07", "side":"SELL", "hash":"939ad2bd0dad287e7142e29fd3fa83d9afa2369b", "best_bid":"0.97", "best_ask":"0.98"}], "timestamp":"1770241468893", "event_type":"price_change"}
{"market":"0x38f3050258345e9cf363d1c8cc302f08c65b96ba1a4669d81e07ed69708344df", "price_changes":[{"asset_id":"96888240988495161476033313796107536512663280794332045579302109906525918376981", "price":"0.94", "size":"753", "side":"BUY", "hash":"22f98f1e7b5eb0fea58c81da5153506cb345679b", "best_bid":"0.97", "best_ask":"0.98"}, {"asset_id":"81916206347121459497221114766050949090435061493822476265356047392175668050706", "price":"0.06", "size":"753", "side":"SELL", "hash":"84b2017d2835480e033a00d6a07496a2c5c63725", "best_bid":"0.02", "best_ask":"0.03"}], "timestamp":"1770241468894", "event_type":"price_change"}
{"market":"0x38f3050258345e9cf363d1c8cc302f08c65b96ba1a4669d81e07ed69708344df", "price_changes":[{"asset_id":"96888240988495161476033313796107536512663280794332045579302109906525918376981", "price":"0.95", "size":"623", "side":"BUY", "hash":"4db0ff39cd2e5682185b7aba21b7e3c500412d06", "best_bid":"0.97", "best_ask":"0.98"}, {"asset_id":"81916206347121459497221114766050949090435061493822476265356047392175668050706", "price":"0.05", "size":"623", "side":"SELL", "hash":"72178e5e6c59d52d04927c627a4a6bd6a5457ffa", "best_bid":"0.02", "best_ask":"0.03"}], "timestamp":"1770241469007", "event_type":"price_change"}
{"market":"0x38f3050258345e9cf363d1c8cc302f08c65b96ba1a4669d81e07ed69708344df", "price_changes":[{"asset_id":"96888240988495161476033313796107536512663280794332045579302109906525918376981", "price":"0.94", "size":"780", "side":"BUY", "hash":"2346076788dac028484edcd695e6b41ed959fd1c", "best_bid":"0.97", "best_ask":"0.98"}, {"asset_id":"81916206347121459497221114766050949090435061493822476265356047392175668050706", "price":"0.06", "size":"780", "side":"SELL", "hash":"ff5f7b3c6a9b5d7fa7104900b497c44aee1cc0ac", "best_bid":"0.02", "best_ask":"0.03"}], "timestamp":"1770241469010", "event_type":"price_change"}
{"market":"0x38f3050258345e9cf363d1c8cc302f08c65b96ba1a4669d81e07ed69708344df", "price_changes":[{"asset_id":"81916206347121459497221114766050949090435061493822476265356047392175668050706", "price":"0.01", "size":"4261.07", "side":"BUY", "hash":"2870312c6bb66da609df0b08a88639a59af43eb6", "best_bid":"0.02", "best_ask":"0.03"}, {"asset_id":"96888240988495161476033313796107536512663280794332045579302109906525918376981", "price":"0.99", "size":"4261.07", "side":"SELL", "hash":"bc59b2b60d95e9ebbaea629f70ffa4cceae959f7", "best_bid":"0.97", "best_ask":"0.98"}], "timestamp":"1770241469013", "event_type":"price_change"}
{"market":"0x38f3050258345e9cf363d1c8cc302f08c65b96ba1a4669d81e07ed69708344df", "price_changes":[{"asset_id":"81916206347121459497221114766050949090435061493822476265356047392175668050706", "price":"0.01", "size":"4234.07", "side":"BUY", "hash":"df32e34c02b24f301d37e4126de299e3cae9420e", "best_bid":"0.02", "best_ask":"0.03"}, {"asset_id":"96888240988495161476033313796107536512663280794332045579302109906525918376981", "price":"0.99", "size":"4234.07", "side":"SELL", "hash":"187de6cca9c8d125879c914831969a1b65a549e8", "best_bid":"0.97", "best_ask":"0.98"}], "timestamp":"1770241469013", "event_type":"price_change"}
{"market":"0x38f3050258345e9cf363d1c8cc302f08c65b96ba1a4669d81e07ed69708344df", "price_changes":[{"asset_id":"81916206347121459497221114766050949090435061493822476265356047392175668050706", "price":"0.01", "size":"4207.07", "side":"BUY", "hash":"a10dbc1923fe8eee5495af9561cb2bbf93646e1c", "best_bid":"0.02", "best_ask":"0.03"}, {"asset_id":"96888240988495161476033313796107536512663280794332045579302109906525918376981", "price":"0.99", "size":"4207.07", "side":"SELL", "hash":"00f2c51fb69f1090149fd141fab4d12ff156e926", "best_bid":"0.97", "best_ask":"0.98"}], "timestamp":"1770241469031", "event_type":"price_change"}
{"market":"0x38f3050258345e9cf363d1c8cc302f08c65b96ba1a4669d81e07ed69708344df", "price_changes":[{"asset_id":"96888240988495161476033313796107536512663280794332045579302109906525918376981", "price":"0.97", "size":"432", "side":"BUY", "hash":"563d5bcd7319c933b3ec53807fe2b5e7bc35ad84", "best_bid":"0.97", "best_ask":"0.98"}, {"asset_id":"81916206347121459497221114766050949090435061493822476265356047392175668050706", "price":"0.03", "size":"432", "side":"SELL", "hash":"314be599c1b75b7968f944643db313ab50662bb5", "best_bid":"0.02", "best_ask":"0.03"}], "timestamp":"1770241469031", "event_type":"price_change"}
{"market":"0x38f3050258345e9cf363d1c8cc302f08c65b96ba1a4669d81e07ed69708344df", "price_changes":[{"asset_id":"96888240988495161476033313796107536512663280794332045579302109906525918376981", "price":"0.96", "size":"823.73", "side":"BUY", "hash":"196295c0ce534631fb03d013ea753b5b453f7662", "best_bid":"0.97", "best_ask":"0.98"}, {"asset_id":"81916206347121459497221114766050949090435061493822476265356047392175668050706", "price":"0.04", "size":"823.73", "side":"SELL", "hash":"6666293b58bbeb1b45f02b14cb9e9eb41a3fa8da", "best_bid":"0.02", "best_ask":"0.03"}], "timestamp":"1770241469033", "event_type":"price_change"}
{"market":"0x38f3050258345e9cf363d1c8cc302f08c65b96ba1a4669d81e07ed69708344df", "price_changes":[{"asset_id":"81916206347121459497221114766050949090435061493822476265356047392175668050706", "price":"0.01", "size":"4234.07", "side":"BUY", "hash":"b973e4f513371509d5d581c289638ceb8bba9333", "best_bid":"0.02", "best_ask":"0.03"}, {"asset_id":"96888240988495161476033313796107536512663280794332045579302109906525918376981", "price":"0.99", "size":"4234.07", "side":"SELL", "hash":"f986818f4c9d09ff0b40351589b3611e44a1f7d2", "best_bid":"0.97", "best_ask":"0.98"}], "timestamp":"1770241469034", "event_type":"price_change"}
{"market":"0x38f3050258345e9cf363d1c8cc302f08c65b96ba1a4669d81e07ed69708344df", "price_changes":[{"asset_id":"96888240988495161476033313796107536512663280794332045579302109906525918376981", "price":"0.96", "size":"803.73", "side":"BUY", "hash":"c3b70681342004324c90ed448aeef6ac6fb993bf", "best_bid":"0.97", "best_ask":"0.98"}, {"asset_id":"81916206347121459497221114766050949090435061493822476265356047392175668050706", "price":"0.04", "size":"803.73", "side":"SELL", "hash":"e0e4c78143580ad3a4ec3f7bef62f533875c1295", "best_bid":"0.02", "best_ask":"0.03"}], "timestamp":"1770241469147", "event_type":"price_change"}
{"market":"0x38f3050258345e9cf363d1c8cc302f08c65b96ba1a4669d81e07ed69708344df", "price_changes":[{"asset_id":"81916206347121459497221114766050949090435061493822476265356047392175668050706", "price":"0.01", "size":"4207.07", "side":"BUY", "hash":"0d3c80197bd3664aceae521d8a11a9ac99943d40", "best_bid":"0.02", "best_ask":"0.03"}, {"asset_id":"96888240988495161476033313796107536512663280794332045579302109906525918376981", "price":"0.99", "size":"4207.07", "side":"SELL", "hash":"f9b092ce6688475b9a578c6ee33597e184c11869", "best_bid":"0.97", "best_ask":"0.98"}], "timestamp":"1770241469152", "event_type":"price_change"}
{"market":"0x38f3050258345e9cf363d1c8cc302f08c65b96ba1a4669d81e07ed69708344df", "price_changes":[{"asset_id":"96888240988495161476033313796107536512663280794332045579302109906525918376981", "price":"0.94", "size":"753", "side":"BUY", "hash":"3ec71cfd216f7fd72757e0af46072d733cd263a0", "best_bid":"0.97", "best_ask":"0.98"}, {"asset_id":"81916206347121459497221114766050949090435061493822476265356047392175668050706", "price":"0.06", "size":"753", "side":"SELL", "hash":"752625ed6b7f9605ee462bd93d4f96cc542b6df0", "best_bid":"0.02", "best_ask":"0.03"}], "timestamp":"1770241469152", "event_type":"price_change"}
{"market":"0x38f3050258345e9cf363d1c8cc302f08c65b96ba1a4669d81e07ed69708344df", "price_changes":[{"asset_id":"81916206347121459497221114766050949090435061493822476265356047392175668050706", "price":"0.01", "size":"4234.07", "side":"BUY", "hash":"f02b00775d945e2eca38784014632e30711ffdf3", "best_bid":"0.02", "best_ask":"0.03"}, {"asset_id":"96888240988495161476033313796107536512663280794332045579302109906525918376981", "price":"0.99", "size":"4234.07", "side":"SELL", "hash":"92d49e4b1b073db2b55852a6988f50a00ce218d4", "best_bid":"0.97", "best_ask":"0.98"}], "timestamp":"1770241469153", "event_type":"price_change"}
{"market":"0x38f3050258345e9cf363d1c8cc302f08c65b96ba1a4669d81e07ed69708344df", "price_changes":[{"asset_id":"96888240988495161476033313796107536512663280794332045579302109906525918376981", "price":"0.95", "size":"650", "side":"BUY", "hash":"a436aa8430719dd8400e2470eb5d648a9d779adf", "best_bid":"0.97", "best_ask":"0.98"}, {"asset_id":"81916206347121459497221114766050949090435061493822476265356047392175668050706", "price":"0.05", "size":"650", "side":"SELL", "hash":"d7f2f755a9b995d8d17a191f6e065b9b2cec7735", "best_bid":"0.02", "best_ask":"0.03"}], "timestamp":"1770241469154", "event_type":"price_change"}
{"market":"0x38f3050258345e9cf363d1c8cc302f08c65b96ba1a4669d81e07ed69708344df", "price_changes":[{"asset_id":"81916206347121459497221114766050949090435061493822476265356047392175668050706", "price":"0.01", "size":"4207.07", "side":"BUY", "hash":"6146fbb1020d62b3ac7daf2c6f985204ec557e98", "best_bid":"0.02", "best_ask":"0.03"}, {"asset_id":"96888240988495161476033313796107536512663280794332045579302109906525918376981", "price":"0.99", "size":"4207.07", "side":"SELL", "hash":"dfa7b0cf3c43216a8eaaac1e124d3a23147d1cf9", "best_bid":"0.97", "best_ask":"0.98"}], "timestamp":"1770241469161", "event_type":"price_change"}
{"market":"0x38f3050258345e9cf363d1c8cc302f08c65b96ba1a4669d81e07ed69708344df", "price_changes":[{"asset_id":"81916206347121459497221114766050949090435061493822476265356047392175668050706", "price":"0.01", "size":"4234.07", "side":"BUY", "hash":"9c5e6c50c3a6cf6a3cd6bba43c5800196b402493", "best_bid":"0.02", "best_ask":"0.03"}, {"asset_id":"96888240988495161476033313796107536512663280794332045579302109906525918376981", "price":"0.99", "size":"4234.07", "side":"SELL", "hash":"f8a0438bc140e1ad09ad6bdbee09f04333a91603", "best_bid":"0.97", "best_ask":"0.98"}], "timestamp":"1770241469162", "event_type":"price_change"}
{"market":"0x38f3050258345e9cf363d1c8cc302f08c65b96ba1a4669d81e07ed69708344df", "price_changes":[{"asset_id":"96888240988495161476033313796107536512663280794332045579302109906525918376981", "price":"0.94", "size":"726", "side":"BUY", "hash":"08e99ab7afe2dc4eac29839c91cd07e8b59a6a76", "best_bid":"0.97", "best_ask":"0.98"}, {"asset_id":"81916206347121459497221114766050949090435061493822476265356047392175668050706", "price":"0.06", "size":"726", "side":"SELL", "hash":"2d93d7bc5e9b891a0f9c096fe27dbda147c0d9d6", "best_bid":"0.02", "best_ask":"0.03"}], "timestamp":"1770241469166", "event_type":"price_change"}
{"market":"0x38f3050258345e9cf363d1c8cc302f08c65b96ba1a4669d81e07ed69708344df", "price_changes":[{"asset_id":"81916206347121459497221114766050949090435061493822476265356047392175668050706", "price":"0.01", "size":"4261.07", "side":"BUY", "hash":"341d4e303cf181d6958ba70b86cde1f7a3cba3bc", "best_bid":"0.02", "best_ask":"0.03"}, {"asset_id":"96888240988495161476033313796107536512663280794332045579302109906525918376981", "price":"0.99", "size":"4261.07", "side":"SELL", "hash":"8383e5c42f31c3442a684d4c33a74ac1dc1afd71", "best_bid":"0.97", "best_ask":"0.98"}], "timestamp":"1770241469172", "event_type":"price_change"}
{"market":"0x38f3050258345e9cf363d1c8cc302f08c65b96ba1a4669d81e07ed69708344df", "price_changes":[{"asset_id":"81916206347121459497221114766050949090435061493822476265356047392175668050706", "price":"0.01", "size":"4234.07", "side":"BUY", "hash":"034e070048aacfb38b099bfe14eabf7cd9d027ba", "best_bid":"0.02", "best_ask":"0.03"}, {"asset_id":"96888240988495161476033313796107536512663280794332045579302109906525918376981", "price":"0.99", "size":"4234.07", "side":"SELL", "hash":"796056ea18f2fe5f4dacad0165ed48aef60bfb5f", "best_bid":"0.97", "best_ask":"0.98"}], "timestamp":"1770241469174", "event_type":"price_change"}
{"market":"0x38f3050258345e9cf363d1c8cc302f08c65b96ba1a4669d81e07ed69708344df", "price_changes":[{"asset_id":"96888240988495161476033313796107536512663280794332045579302109906525918376981", "price":"0.96", "size":"776.73", "side":"BUY", "hash":"7eceda703832c85176f21751763390aa0d1b8917", "best_bid":"0.97", "best_ask":"0.98"}, {"asset_id":"81916206347121459497221114766050949090435061493822476265356047392175668050706", "price":"0.04", "size":"776.73", "side":"SELL", "hash":"a2cd857871b6ef9557344b07121b38aa8634734d", "best_bid":"0.02", "best_ask":"0.03"}], "timestamp":"1770241469175", "event_type":"price_change"}
{"market":"0x38f3050258345e9cf363d1c8cc302f08c65b96ba1a4669d81e07ed69708344df", "price_changes":[{"asset_id":"96888240988495161476033313796107536512663280794332045579302109906525918376981", "price":"0.97", "size":"459", "side":"BUY", "hash":"90ab37a025fe50159566c34d47cb1e44c10eb610", "best_bid":"0.97", "best_ask":"0.98"}, {"asset_id":"81916206347121459497221114766050949090435061493822476265356047392175668050706", "price":"0.03", "size":"459", "side":"SELL", "hash":"6e8e9b2ded778b0095982106f04c6d920835b410", "best_bid":"0.02", "best_ask":"0.03"}], "timestamp":"1770241469176", "event_type":"price_change"}
{"market":"0x38f3050258345e9cf363d1c8cc302f08c65b96ba1a4669d81e07ed69708344df", "price_changes":[{"asset_id":"96888240988495161476033313796107536512663280794332045579302109906525918376981", "price":"0.95", "size":"677", "side":"BUY", "hash":"c8b7abb9c8eb362a7ae53dc7d3e57d9e26fed79e", "best_bid":"0.97", "best_ask":"0.98"}, {"asset_id":"81916206347121459497221114766050949090435061493822476265356047392175668050706", "price":"0.05", "size":"677", "side":"SELL", "hash":"834b820db9a481636bb67bc5a90da237bba7c685", "best_bid":"0.02", "best_ask":"0.03"}], "timestamp":"1770241469180", "event_type":"price_change"}
{"market":"0x38f3050258345e9cf363d1c8cc302f08c65b96ba1a4669d81e07ed69708344df", "price_changes":[{"asset_id":"81916206347121459497221114766050949090435061493822476265356047392175668050706", "price":"0.01", "size":"4207.07", "side":"BUY", "hash":"e1301f272ff884a35b027b2199eb54e50a2ec4f1", "best_bid":"0.02", "best_ask":"0.03"}, {"asset_id":"96888240988495161476033313796107536512663280794332045579302109906525918376981", "price":"0.99", "size":"4207.07", "side":"SELL", "hash":"5cd056cbcf076c11973a3fa544a3f7466d5d3ef7", "best_bid":"0.97", "best_ask":"0.98"}], "timestamp":"1770241469292", "event_type":"price_change"}
{"market":"0x38f3050258345e9cf363d1c8cc302f08c65b96ba1a4669d81e07ed69708344df", "price_changes":[{"asset_id":"96888240988495161476033313796107536512663280794332045579302109906525918376981", "price":"0.95", "size":"650", "side":"BUY", "hash":"00d3a1763cc2a908d5ec251c98e5c0dd3a4ee23f", "best_bid":"0.97", "best_ask":"0.98"}, {"asset_id":"81916206347121459497221114766050949090435061493822476265356047392175668050706", "price":"0.05", "size":"650", "side":"SELL", "hash":"52d60a5e83d1b6ee1d526534449cdabfd84ab5c5", "best_bid":"0.02", "best_ask":"0.03"}], "timestamp":"1770241469292", "event_type":"price_change"}
{"market":"0x38f3050258345e9cf363d1c8cc302f08c65b96ba1a4669d81e07ed69708344df", "price_changes":[{"asset_id":"96888240988495161476033313796107536512663280794332045579302109906525918376981", "price":"0.95", "size":"677", "side":"BUY", "hash":"b0bd22af5346520aff0028be36f3894f2c870685", "best_bid":"0.97", "best_ask":"0.98"}, {"asset_id":"81916206347121459497221114766050949090435061493822476265356047392175668050706", "price":"0.05", "size":"677", "side":"SELL", "hash":"15ade2f1fd85c31258c009830734956292c025b8", "best_bid":"0.02", "best_ask":"0.03"}], "timestamp":"1770241469294", "event_type":"price_change"}
{"market":"0x38f3050258345e9cf363d1c8cc302f08c65b96ba1a4669d81e07ed69708344df", "price_changes":[{"asset_id":"81916206347121459497221114766050949090435061493822476265356047392175668050706", "price":"0.01", "size":"4234.07", "side":"BUY", "hash":"f0d00279e66599bd2929ccd41d871cbfdcb7424d", "best_bid":"0.02", "best_ask":"0.03"}, {"asset_id":"96888240988495161476033313796107536512663280794332045579302109906525918376981", "price":"0.99", "size":"4234.07", "side":"SELL", "hash":"d1dea9629fffc963eadab22722a106a9a3f34e15", "best_bid":"0.97", "best_ask":"0.98"}], "timestamp":"1770241469297", "event_type":"price_change"}
{"market":"0x38f3050258345e9cf363d1c8cc302f08c65b96ba1a4669d81e07ed69708344df", "price_changes":[{"asset_id":"81916206347121459497221114766050949090435061493822476265356047392175668050706", "price":"0.01", "size":"4261.07", "side":"BUY", "hash":"1fee220be1802aac2f38d213c2dcdea9ee0e790e", "best_bid":"0.02", "best_ask":"0.03"}, {"asset_id":"96888240988495161476033313796107536512663280794332045579302109906525918376981", "price":"0.99", "size":"4261.07", "side":"SELL", "hash":"c5b9008e8bda332e2b85e3b56c76a58e38b2928c", "best_bid":"0.97", "best_ask":"0.98"}], "timestamp":"1770241469303", "event_type":"price_change"}
{"market":"0x38f3050258345e9cf363d1c8cc302f08c65b96ba1a4669d81e07ed69708344df", "price_changes":[{"asset_id":"81916206347121459497221114766050949090435061493822476265356047392175668050706", "price":"0.01", "size":"4234.07", "side":"BUY", "hash":"ef0069bf19162b0bb5e98f508ac52cc52614686a", "best_bid":"0.02", "best_ask":"0.03"}, {"asset_id":"96888240988495161476033313796107536512663280794332045579302109906525918376981", "price":"0.99", "size":"4234.07", "side":"SELL", "hash":"7182bff5955d5994e53325fe4f95956e63ef3944", "best_bid":"0.97", "best_ask":"0.98"}], "timestamp":"1770241469304", "event_type":"price_change"}
{"market":"0x38f3050258345e9cf363d1c8cc302f08c65b96ba1a4669d81e07ed69708344df", "price_changes":[{"asset_id":"96888240988495161476033313796107536512663280794332045579302109906525918376981", "price":"0.95", "size":"704", "side":"BUY", "hash":"867bad734c54102a99566b08b0dce3b9ec95531a", "best_bid":"0.97", "best_ask":"0.98"}, {"asset_id":"81916206347121459497221114766050949090435061493822476265356047392175668050706", "price":"0.05", "size":"704", "side":"SELL", "hash":"e80cfe59de436dfe8331a636afad042d7e548ab8", "best_bid":"0.02", "best_ask":"0.03"}], "timestamp":"1770241469309", "event_type":"price_change"}
{"market":"0x38f3050258345e9cf363d1c8cc302f08c65b96ba1a4669d81e07ed69708344df", "price_changes":[{"asset_id":"81916206347121459497221114766050949090435061493822476265356047392175668050706", "price":"0.01", "size":"4207.07", "side":"BUY", "hash":"d7e19718e4d775ea5e8810f648dcc1e68b687abe", "best_bid":"0.02", "best_ask":"0.03"}, {"asset_id":"96888240988495161476033313796107536512663280794332045579302109906525918376981", "price":"0.99", "size":"4207.07", "side":"SELL", "hash":"8028b80bb9ccc0b79a537ca20d2d89da1c3fb94e", "best_bid":"0.97", "best_ask":"0.98"}], "timestamp":"1770241469310", "event_type":"price_change"}
{"market":"0x38f3050258345e9cf363d1c8cc302f08c65b96ba1a4669d81e07ed69708344df", "price_changes":[{"asset_id":"96888240988495161476033313796107536512663280794332045579302109906525918376981", "price":"0.97", "size":"432", "side":"BUY", "hash":"8f70e015be9539ec73aee25a55e7925541944e76", "best_bid":"0.97", "best_ask":"0.98"}, {"asset_id":"81916206347121459497221114766050949090435061493822476265356047392175668050706", "price":"0.03", "size":"432", "side":"SELL", "hash":"aa8116244de195984bc014037d6c80dce0b8537d", "best_bid":"0.02", "best_ask":"0.03"}], "timestamp":"1770241469310", "event_type":"price_change"}
{"market":"0x38f3050258345e9cf363d1c8cc302f08c65b96ba1a4669d81e07ed69708344df", "price_changes":[{"asset_id":"96888240988495161476033313796107536512663280794332045579302109906525918376981", "price":"0.95", "size":"677", "side":"BUY", "hash":"b82fe6e3f22ba25388dd4770bdd7560064549476", "best_bid":"0.97", "best_ask":"0.98"}, {"asset_id":"81916206347121459497221114766050949090435061493822476265356047392175668050706", "price":"0.05", "size":"677", "side":"SELL", "hash":"8fa548981c7ccf1d22eb44acc586c0dc8ee18deb", "best_bid":"0.02", "best_ask":"0.03"}], "timestamp":"1770241469311", "event_type":"price_change"}
{"market":"0x38f3050258345e9cf363d1c8cc302f08c65b96ba1a4669d81e07ed69708344df", "price_changes":[{"asset_id":"81916206347121459497221114766050949090435061493822476265356047392175668050706", "price":"0.01", "size":"4234.07", "side":"BUY", "hash":"e83012d6b19ec5eb0f4811f20be22bc85e4ec7ab", "best_bid":"0.02", "best_ask":"0.03"}, {"asset_id":"96888240988495161476033313796107536512663280794332045579302109906525918376981", "price":"0.99", "size":"4234.07", "side":"SELL", "hash":"5f4fe154fa163f096a3c6888a0ce95e8856ef88c", "best_bid":"0.97", "best_ask":"0.98"}], "timestamp":"1770241469314", "event_type":"price_change"}
{"market":"0x38f3050258345e9cf363d1c8cc302f08c65b96ba1a4669d81e07ed69708344df", "price_changes":[{"asset_id":"96888240988495161476033313796107536512663280794332045579302109906525918376981", "price":"0.96", "size":"803.73", "side":"BUY", "hash":"dbddc44e538fa5caa680d36250e375e0c3afd9af", "best_bid":"0.97", "best_ask":"0.98"}, {"asset_id":"81916206347121459497221114766050949090435061493822476265356047392175668050706", "price":"0.04", "size":"803.73", "side":"SELL", "hash":"de565f67f5773749881f0a6e120bb5b675a8578f", "best_bid":"0.02", "best_ask":"0.03"}], "timestamp":"1770241469324", "event_type":"price_change"}
{"market":"0x38f3050258345e9cf363d1c8cc302f08c65b96ba1a4669d81e07ed69708344df", "price_changes":[{"asset_id":"81916206347121459497221114766050949090435061493822476265356047392175668050706", "price":"0.01", "size":"4261.07", "side":"BUY", "hash":"4aa934eed8cbfd8d793e81e0d585c5170fde5ef8", "best_bid":"0.02", "best_ask":"0.03"}, {"asset_id":"96888240988495161476033313796107536512663280794332045579302109906525918376981", "price":"0.99", "size":"4261.07", "side":"SELL", "hash":"ebd3d7733bc64fa54bfaa9a674b374ba19398738", "best_bid":"0.97", "best_ask":"0.98"}], "timestamp":"1770241469426", "event_type":"price_change"}
{"market":"0x38f3050258345e9cf363d1c8cc302f08c65b96ba1a4669d81e07ed69708344df", "price_changes":[{"asset_id":"96888240988495161476033313796107536512663280794332045579302109906525918376981", "price":"0.95", "size":"650", "side":"BUY", "hash":"d2e333fa2ae344a0e55b2c135afc50c0acfb0d9a", "best_bid":"0.97", "best_ask":"0.98"}, {"asset_id":"81916206347121459497221114766050949090435061493822476265356047392175668050706", "price":"0.05", "size":"650", "side":"SELL", "hash":"c9cb6726839cbe1a91cc6dee1316e377c69c6df6", "best_bid":"0.02", "best_ask":"0.03"}], "timestamp":"1770241469427", "event_type":"price_change"}
{"market":"0x38f3050258345e9cf363d1c8cc302f08c65b96ba1a4669d81e07ed69708344df", "price_changes":[{"asset_id":"81916206347121459497221114766050949090435061493822476265356047392175668050706", "price":"0.01", "size":"4288.07", "side":"BUY", "hash":"b5b905e09c8d44ee549b0222f7b88cef35b6eea4", "best_bid":"0.02", "best_ask":"0.03"}, {"asset_id":"96888240988495161476033313796107536512663280794332045579302109906525918376981", "price":"0.99", "size":"4288.07", "side":"SELL", "hash":"043316d198aa56275b101714c6f68c2fc153fd1b", "best_bid":"0.97", "best_ask":"0.98"}], "timestamp":"1770241469428", "event_type":"price_change"}
{"market":"0x38f3050258345e9cf363d1c8cc302f08c65b96ba1a4669d81e07ed69708344df", "price_changes":[{"asset_id":"96888240988495161476033313796107536512663280794332045579302109906525918376981", "price":"0.95", "size":"623", "side":"BUY", "hash":"9db0b23d69d4b6e51b73ca1c48d347ad6dc896cd", "best_bid":"0.97", "best_ask":"0.98"}, {"asset_id":"81916206347121459497221114766050949090435061493822476265356047392175668050706", "price":"0.05", "size":"623", "side":"SELL", "hash":"2d156eaddc8d87c999e80b152dafa9245fb26c89", "best_bid":"0.02", "best_ask":"0.03"}], "timestamp":"1770241469428", "event_type":"price_change"}
{"market":"0x38f3050258345e9cf363d1c8cc302f08c65b96ba1a4669d81e07ed69708344df", "price_changes":[{"asset_id":"96888240988495161476033313796107536512663280794332045579302109906525918376981", "price":"0.95", "size":"650", "side":"BUY", "hash":"d7140bbcb0c0ce771e6282cb41683b3d68091d5e", "best_bid":"0.97", "best_ask":"0.98"}, {"asset_id":"81916206347121459497221114766050949090435061493822476265356047392175668050706", "price":"0.05", "size":"650", "side":"SELL", "hash":"800e2698d690854938ce70711fdf90ede44e0782", "best_bid":"0.02", "best_ask":"0.03"}], "timestamp":"1770241469429", "event_type":"price_change"}
{"market":"0x38f3050258345e9cf363d1c8cc302f08c65b96ba1a4669d81e07ed69708344df", "price_changes":[{"asset_id":"81916206347121459497221114766050949090435061493822476265356047392175668050706", "price":"0.01", "size":"4261.07", "side":"BUY", "hash":"cff04d81e344014807a25f6276ce56b5577e1a20", "best_bid":"0.02", "best_ask":"0.03"}, {"asset_id":"96888240988495161476033313796107536512663280794332045579302109906525918376981", "price":"0.99", "size":"4261.07", "side":"SELL", "hash":"033cd987b53a6bb8d84233d3a77660c749c62575", "best_bid":"0.97", "best_ask":"0.98"}], "timestamp":"1770241469430", "event_type":"price_change"}
{"market":"0x38f3050258345e9cf363d1c8cc302f08c65b96ba1a4669d81e07ed69708344df", "price_changes":[{"asset_id":"81916206347121459497221114766050949090435061493822476265356047392175668050706", "price":"0.01", "size":"4234.07", "side":"BUY", "hash":"29d73393cb217a56f016a64152f233bbcd90f3ac", "best_bid":"0.02", "best_ask":"0.03"}, {"asset_id":"96888240988495161476033313796107536512663280794332045579302109906525918376981", "price":"0.99", "size":"4234.07", "side":"SELL", "hash":"d773fc35f38146bb74b312ee0f50137176aee79f", "best_bid":"0.97", "best_ask":"0.98"}], "timestamp":"1770241469431", "event_type":"price_change"}
{"market":"0x38f3050258345e9cf363d1c8cc302f08c65b96ba1a4669d81e07ed69708344df", "price_changes":[{"asset_id":"96888240988495161476033313796107536512663280794332045579302109906525918376981", "price":"0.95", "size":"677", "side":"BUY", "hash":"284364538ba7711dd808df1ce04291a6fb1b6d16", "best_bid":"0.97", "best_ask":"0.98"}, {"asset_id":"81916206347121459497221114766050949090435061493822476265356047392175668050706", "price":"0.05", "size":"677", "side":"SELL", "hash":"2388f9f1f03270b0ca6ea498f9e6050860ece449", "best_bid":"0.02", "best_ask":"0.03"}], "timestamp":"1770241469433", "event_type":"price_change"}
{"market":"0x38f3050258345e9cf363d1c8cc302f08c65b96ba1a4669d81e07ed69708344df", "price_changes":[{"asset_id":"81916206347121459497221114766050949090435061493822476265356047392175668050706", "price":"0.02", "size":"458.48", "side":"BUY", "hash":"3593b953b4e5a5ba6c7d4d5cef82c05c52b64c9d", "best_bid":"0.02", "best_ask":"0.03"}, {"asset_id":"96888240988495161476033313796107536512663280794332045579302109906525918376981", "price":"0.98", "size":"458.48", "side":"SELL", "hash":"2912efd109c49577319a184b3974125dbdd66776", "best_bid":"0.97", "best_ask":"0.98"}], "timestamp":"1770241469440", "event_type":"price_change"}
{"market":"0x38f3050258345e9cf363d1c8cc302f08c65b96ba1a4669d81e07ed69708344df", "price_changes":[{"asset_id":"81916206347121459497221114766050949090435061493822476265356047392175668050706", "price":"0.01", "size":"4257.07", "side":"BUY", "hash":"674e2393e01b08496ce7c8b7a7b32697141aa3c5", "best_bid":"0.02", "best_ask":"0.03"}, {"asset_id":"96888240988495161476033313796107536512663280794332045579302109906525918376981", "price":"0.99", "size":"4257.07", "side":"SELL", "hash":"329cbc6ac306c0028a099bde5b58619341695210", "best_bid":"0.97", "best_ask":"0.98"}], "timestamp":"1770241469442", "event_type":"price_change"}
